{
    "registryname": "elysia_reactor",
    "localizedname": "§cELYSIA单元 - 大型反应单元",
    "requires-blueprint": false,
    "failure-action": "still",
    "color": "afafaf",
    "modifiers": [
        {
            "elements": "modularmachinery:blockcasing@1",
            "x": 0,
            "y": 1,
            "z": 0,
            "description": "将控制器上方紧挨着的方块换成此方块以降低配方制作时间至75%！",
            "modifier": {
                "io": "input",
                "target": "modularmachinery:duration",
                "operation": 1,
                "multiplier": 0.75
            }
        },
        {
            "elements": "modularmachinery:blockcasing@2",
            "x": 0,
            "y": 1,
            "z": 0,
            "description": "将控制器上方紧挨着的方块换成此方块以降低配方制作时间至66%！",
            "modifier": {
                "io": "input",
                "target": "modularmachinery:duration",
                "operation": 1,
                "multiplier": 0.66
            }
        },
        {
            "elements": "modularmachinery:blockcasing@3",
            "x": 0,
            "y": 1,
            "z": 0,
            "description": "将控制器上方紧挨着的方块换成此方块以降低配方制作时间至50%！",
            "modifier": {
                "io": "input",
                "target": "modularmachinery:duration",
                "operation": 1,
                "multiplier": 0.5
            }
        },
        {
            "elements": "modularmachinery:blockcasing@5",
            "x": 0,
            "y": 1,
            "z": 0,
            "description": "将控制器上方紧挨着的方块换成此方块以降低配方制作时间至33%！",
            "modifier": {
                "io": "input",
                "target": "modularmachinery:duration",
                "operation": 1,
                "multiplier": 0.33
            }
        }
    ],
    "parts": [
        {
            "x": 0,
            "y": 0,
            "z": 0,
            "elements": [
                "modularmachinery:blockcontroller@2"
            ]
        },
        {
            "x": -8,
            "y": 0,
            "z": 15,
            "elements": [
                "thermalfoundation:storage@7"
            ]
        },
        {
            "x": -5,
            "y": 4,
            "z": 10,
            "elements": [
                "jaopca:block.tough@0"
            ]
        },
        {
            "x": -1,
            "y": 2,
            "z": 0,
            "elements": [
                "mekanism:reinforcedplasticblock@7"
            ]
        },
        {
            "x": 6,
            "y": 4,
            "z": 7,
            "elements": [
                "minecraft:water@0"
            ]
        },
        {
            "x": 7,
            "y": 4,
            "z": 2,
            "elements": [
                "minecraft:water@0"
            ]
        },
        {
            "x": -7,
            "y": -1,
            "z": 11,
            "elements": [
                "mekanism:reinforcedplasticblock@8"
            ]
        },
        {
            "x": -6,
            "y": 0,
            "z": 10,
            "elements": [
                "minecraft:water@0"
            ]
        },
        {
            "x": -9,
            "y": 4,
            "z": 1,
            "elements": [
                "jaopca:block.tough@0"
            ]
        },
        {
            "x": -6,
            "y": 1,
            "z": -1,
            "elements": [
                "mekanism:reinforcedplasticblock@8"
            ]
        },
        {
            "x": 6,
            "y": 5,
            "z": 7,
            "elements": [
                "minecraft:hopper@0"
            ]
        },
        {
            "x": -5,
            "y": 2,
            "z": 10,
            "elements": [
                "jaopca:block.tough@0"
            ]
        },
        {
            "x": -6,
            "y": 0,
            "z": -1,
            "elements": [
                "mekanism:reinforcedplasticblock@8"
            ]
        },
        {
            "x": 7,
            "y": 5,
            "z": 2,
            "elements": [
                "thermalfoundation:glass_alloy@5"
            ]
        },
        {
            "x": 5,
            "y": -1,
            "z": 1,
            "elements": [
                "mekanism:reinforcedplasticblock@8"
            ]
        },
        {
            "x": 6,
            "y": 6,
            "z": 3,
            "elements": [
                "additions:durasteel_block@0"
            ]
        },
        {
            "x": -6,
            "y": 4,
            "z": 10,
            "elements": [
                "jaopca:block.tough@0"
            ]
        },
        {
            "x": 1,
            "y": 0,
            "z": 0,
            "elements": [
                "mekanism:reinforcedplasticblock@7"
            ]
        },
        {
            "x": -5,
            "y": 0,
            "z": 15,
            "elements": [
                "mekanism:reinforcedplasticblock@8"
            ]
        },
        {
            "x": -6,
            "y": 3,
            "z": -1,
            "elements": [
                "mekanism:reinforcedplasticblock@8"
            ]
        },
        {
            "x": -6,
            "y": 2,
            "z": 15,
            "elements": [
                "mekanism:reinforcedplasticblock@8"
            ]
        },
        {
            "x": 6,
            "y": 4,
            "z": 3,
            "elements": [
                "mekanism:reinforcedplasticblock@8"
            ]
        },
        {
            "x": -1,
            "y": 4,
            "z": 0,
            "elements": [
                "mekanism:reinforcedplasticblock@7"
            ]
        },
        {
            "x": -4,
            "y": 6,
            "z": 0,
            "elements": [
                "additions:durasteel_block@0"
            ]
        },
        {
            "x": 6,
            "y": 2,
            "z": 7,
            "elements": [
                "minecraft:water@0"
            ]
        },
        {
            "x": -6,
            "y": 2,
            "z": 10,
            "elements": [
                "jaopca:block.tough@0"
            ]
        },
        {
            "x": -6,
            "y": 2,
            "z": -1,
            "elements": [
                "mekanism:reinforcedplasticblock@8"
            ]
        },
        {
            "x": 6,
            "y": 3,
            "z": 7,
            "elements": [
                "minecraft:water@0"
            ]
        },
        {
            "x": -5,
            "y": 0,
            "z": 10,
            "elements": [
                "jaopca:block.tough@0"
            ]
        },
        {
            "x": -8,
            "y": 4,
            "z": 15,
            "elements": [
                "thermalfoundation:storage@7"
            ]
        },
        {
            "x": 6,
            "y": 3,
            "z": 4,
            "elements": [
                "minecraft:water@0"
            ]
        },
        {
            "x": -8,
            "y": -1,
            "z": 12,
            "elements": [
                "mekanism:reinforcedplasticblock@8"
            ]
        },
        {
            "x": 6,
            "y": 1,
            "z": 4,
            "elements": [
                "jaopca:block.tough@0"
            ]
        },
        {
            "x": 0,
            "y": 3,
            "z": 14,
            "elements": [
                "casings_all"
            ]
        },
        {
            "x": 9,
            "y": 3,
            "z": 2,
            "elements": [
                "jaopca:block.tough@0"
            ]
        },
        {
            "x": 2,
            "y": 0,
            "z": 0,
            "elements": [
                "minecraft:glass@0"
            ]
        },
        {
            "x": -6,
            "y": 0,
            "z": 15,
            "elements": [
                "mekanism:reinforcedplasticblock@8"
            ]
        },
        {
            "x": 6,
            "y": 3,
            "z": 1,
            "elements": [
                "minecraft:water@0"
            ]
        },
        {
            "x": -7,
            "y": 4,
            "z": 10,
            "elements": [
                "jaopca:block.tough@0"
            ]
        },
        {
            "x": -4,
            "y": 4,
            "z": 0,
            "elements": [
                "mekanism:reinforcedplasticblock@8"
            ]
        },
        {
            "x": 1,
            "y": 2,
            "z": 0,
            "elements": [
                "mekanism:reinforcedplasticblock@7"
            ]
        },
        {
            "x": -5,
            "y": 0,
            "z": 5,
            "elements": [
                "minecraft:glass@0"
            ]
        },
        {
            "x": 6,
            "y": 2,
            "z": -1,
            "elements": [
                "mekanism:reinforcedplasticblock@8"
            ]
        },
        {
            "x": -6,
            "y": 4,
            "z": 5,
            "elements": [
                "prefab:block_half_glass_slab@0"
            ]
        },
        {
            "x": -5,
            "y": -1,
            "z": 16,
            "elements": [
                "jaopca:block.tough@0"
            ]
        },
        {
            "x": -7,
            "y": 2,
            "z": 10,
            "elements": [
                "jaopca:block.tough@0"
            ]
        },
        {
            "x": 6,
            "y": 3,
            "z": -1,
            "elements": [
                "mekanism:reinforcedplasticblock@8"
            ]
        },
        {
            "x": 6,
            "y": 2,
            "z": 1,
            "elements": [
                "minecraft:water@0"
            ]
        },
        {
            "x": -9,
            "y": 1,
            "z": 1,
            "elements": [
                "casings_all"
            ]
        },
        {
            "x": -1,
            "y": 0,
            "z": 0,
            "elements": [
                "mekanism:reinforcedplasticblock@7"
            ]
        },
        {
            "x": -4,
            "y": 2,
            "z": 0,
            "elements": [
                "mekanism:reinforcedplasticblock@8"
            ]
        },
        {
            "x": -9,
            "y": 2,
            "z": 1,
            "elements": [
                "casings_upgrade"
            ]
        },
        {
            "x": -7,
            "y": 0,
            "z": 15,
            "elements": [
                "mekanism:reinforcedplasticblock@8"
            ]
        },
        {
            "x": -8,
            "y": 2,
            "z": 15,
            "elements": [
                "thermalfoundation:storage@7"
            ]
        },
        {
            "x": -7,
            "y": -1,
            "z": 1,
            "elements": [
                "mekanism:reinforcedplasticblock@8"
            ]
        },
        {
            "x": 6,
            "y": 1,
            "z": 1,
            "elements": [
                "minecraft:water@0"
            ]
        },
        {
            "x": 6,
            "y": 0,
            "z": 1,
            "elements": [
                "minecraft:water@0"
            ]
        },
        {
            "x": 6,
            "y": 0,
            "z": -1,
            "elements": [
                "mekanism:reinforcedplasticblock@8"
            ]
        },
        {
            "x": -7,
            "y": -1,
            "z": -1,
            "elements": [
                "mekanism:reinforcedplasticblock@8"
            ]
        },
        {
            "x": -7,
            "y": 0,
            "z": 10,
            "elements": [
                "jaopca:block.tough@0"
            ]
        },
        {
            "x": 1,
            "y": 4,
            "z": 0,
            "elements": [
                "mekanism:reinforcedplasticblock@7"
            ]
        },
        {
            "x": 5,
            "y": -1,
            "z": 4,
            "elements": [
                "jaopca:block.tough@0"
            ]
        },
        {
            "x": 8,
            "y": -1,
            "z": -1,
            "elements": [
                "thermalfoundation:storage@7"
            ]
        },
        {
            "x": -5,
            "y": 5,
            "z": 11,
            "elements": [
                "plustic:osgloglasblock@0"
            ]
        },
        {
            "x": 8,
            "y": -1,
            "z": 1,
            "elements": [
                "mekanism:reinforcedplasticblock@8"
            ]
        },
        {
            "x": -9,
            "y": 0,
            "z": 1,
            "elements": [
                "casings_all"
            ]
        },
        {
            "x": 6,
            "y": 1,
            "z": -1,
            "elements": [
                "mekanism:reinforcedplasticblock@8"
            ]
        },
        {
            "x": 6,
            "y": 6,
            "z": 7,
            "elements": [
                "minecraft:hopper@0"
            ]
        },
        {
            "x": -9,
            "y": 3,
            "z": 1,
            "elements": [
                "casings_all"
            ]
        },
        {
            "x": -5,
            "y": 2,
            "z": 0,
            "elements": [
                "minecraft:water@0"
            ]
        },
        {
            "x": -7,
            "y": 0,
            "z": 5,
            "elements": [
                "minecraft:glass@0"
            ]
        },
        {
            "x": 4,
            "y": 0,
            "z": 0,
            "elements": [
                "mekanism:reinforcedplasticblock@8"
            ]
        },
        {
            "x": -8,
            "y": 3,
            "z": 11,
            "elements": [
                "thermalfoundation:storage@7"
            ]
        },
        {
            "x": -1,
            "y": 6,
            "z": 12,
            "elements": [
                "minecraft:hopper@5"
            ]
        },
        {
            "x": 5,
            "y": -1,
            "z": 7,
            "elements": [
                "mekanism:reinforcedplasticblock@7"
            ]
        },
        {
            "x": 6,
            "y": 2,
            "z": 6,
            "elements": [
                "mekanism:reinforcedplasticblock@7"
            ]
        },
        {
            "x": 7,
            "y": 3,
            "z": 9,
            "elements": [
                "minecraft:glass@0"
            ]
        },
        {
            "x": 6,
            "y": 6,
            "z": 8,
            "elements": [
                "minecraft:hopper@2"
            ]
        },
        {
            "x": 6,
            "y": 6,
            "z": -1,
            "elements": [
                "additions:durasteel_block@0"
            ]
        },
        {
            "x": 2,
            "y": 0,
            "z": 12,
            "elements": [
                "minecraft:glass@0"
            ]
        },
        {
            "x": -6,
            "y": 5,
            "z": 11,
            "elements": [
                "plustic:osgloglasblock@0"
            ]
        },
        {
            "x": -5,
            "y": 3,
            "z": 11,
            "elements": [
                "mekanism:reinforcedplasticblock@8"
            ]
        },
        {
            "x": -8,
            "y": 0,
            "z": 3,
            "elements": [
                "thermalfoundation:storage@7"
            ]
        },
        {
            "x": -1,
            "y": 4,
            "z": 12,
            "elements": [
                "mekanism:reinforcedplasticblock@7"
            ]
        },
        {
            "x": 5,
            "y": 0,
            "z": 0,
            "elements": [
                "minecraft:water@0"
            ]
        },
        {
            "x": -8,
            "y": 1,
            "z": 11,
            "elements": [
                "thermalfoundation:storage@7"
            ]
        },
        {
            "x": -5,
            "y": 4,
            "z": 0,
            "elements": [
                "minecraft:water@0"
            ]
        },
        {
            "x": -8,
            "y": 6,
            "z": 0,
            "elements": [
                "additions:durasteel_block@0"
            ]
        },
        {
            "x": -6,
            "y": -1,
            "z": 11,
            "elements": [
                "mekanism:reinforcedplasticblock@8"
            ]
        },
        {
            "x": 6,
            "y": 4,
            "z": -1,
            "elements": [
                "mekanism:reinforcedplasticblock@8"
            ]
        },
        {
            "x": -6,
            "y": 3,
            "z": 4,
            "elements": [
                "minecraft:water@0"
            ]
        },
        {
            "x": 2,
            "y": 3,
            "z": 12,
            "elements": [
                "minecraft:glass@0"
            ]
        },
        {
            "x": 6,
            "y": 5,
            "z": -1,
            "elements": [
                "plustic:osgloglasblock@0"
            ]
        },
        {
            "x": -8,
            "y": 2,
            "z": 3,
            "elements": [
                "thermalfoundation:storage@7"
            ]
        },
        {
            "x": -2,
            "y": 0,
            "z": 0,
            "elements": [
                "minecraft:glass@0"
            ]
        },
        {
            "x": -8,
            "y": 4,
            "z": 0,
            "elements": [
                "mekanism:reinforcedplasticblock@8"
            ]
        },
        {
            "x": -5,
            "y": 1,
            "z": 11,
            "elements": [
                "mekanism:reinforcedplasticblock@8"
            ]
        },
        {
            "x": 6,
            "y": -1,
            "z": 9,
            "elements": [
                "prefab:block_half_glass_slab@8"
            ]
        },
        {
            "x": 6,
            "y": 2,
            "z": 3,
            "elements": [
                "mekanism:reinforcedplasticblock@8"
            ]
        },
        {
            "x": 4,
            "y": -1,
            "z": 12,
            "elements": [
                "mekanism:reinforcedplasticblock@8"
            ]
        },
        {
            "x": 6,
            "y": 0,
            "z": 7,
            "elements": [
                "minecraft:water@0"
            ]
        },
        {
            "x": 5,
            "y": 2,
            "z": 0,
            "elements": [
                "minecraft:water@0"
            ]
        },
        {
            "x": -5,
            "y": -1,
            "z": 11,
            "elements": [
                "mekanism:reinforcedplasticblock@8"
            ]
        },
        {
            "x": -5,
            "y": 6,
            "z": 15,
            "elements": [
                "additions:durasteel_block@0"
            ]
        },
        {
            "x": -6,
            "y": 2,
            "z": 1,
            "elements": [
                "minecraft:water@0"
            ]
        },
        {
            "x": -1,
            "y": 3,
            "z": 12,
            "elements": [
                "mekanism:reinforcedplasticblock@7"
            ]
        },
        {
            "x": 9,
            "y": 4,
            "z": 2,
            "elements": [
                "jaopca:block.tough@0"
            ]
        },
        {
            "x": -1,
            "y": 6,
            "z": 0,
            "elements": [
                "minecraft:hopper@5"
            ]
        },
        {
            "x": -7,
            "y": -1,
            "z": 4,
            "elements": [
                "jaopca:block.tough@0"
            ]
        },
        {
            "x": 6,
            "y": 0,
            "z": 3,
            "elements": [
                "minecraft:water@0"
            ]
        },
        {
            "x": -6,
            "y": 4,
            "z": -1,
            "elements": [
                "mekanism:reinforcedplasticblock@8"
            ]
        },
        {
            "x": -1,
            "y": 2,
            "z": 12,
            "elements": [
                "mekanism:reinforcedplasticblock@7"
            ]
        },
        {
            "x": -5,
            "y": 0,
            "z": 0,
            "elements": [
                "minecraft:water@0"
            ]
        },
        {
            "x": 6,
            "y": 1,
            "z": 7,
            "elements": [
                "minecraft:water@0"
            ]
        },
        {
            "x": -6,
            "y": 3,
            "z": 1,
            "elements": [
                "minecraft:water@0"
            ]
        },
        {
            "x": 5,
            "y": -1,
            "z": 6,
            "elements": [
                "mekanism:reinforcedplasticblock@7"
            ]
        },
        {
            "x": -5,
            "y": 4,
            "z": 15,
            "elements": [
                "mekanism:reinforcedplasticblock@8"
            ]
        },
        {
            "x": 6,
            "y": 0,
            "z": 6,
            "elements": [
                "minecraft:water@0"
            ]
        },
        {
            "x": 1,
            "y": -1,
            "z": 12,
            "elements": [
                "mekanism:reinforcedplasticblock@7"
            ]
        },
        {
            "x": -6,
            "y": 0,
            "z": 1,
            "elements": [
                "minecraft:water@0"
            ]
        },
        {
            "x": 5,
            "y": -1,
            "z": -1,
            "elements": [
                "mekanism:reinforcedplasticblock@8"
            ]
        },
        {
            "x": -6,
            "y": 1,
            "z": 11,
            "elements": [
                "mekanism:reinforcedplasticblock@8"
            ]
        },
        {
            "x": -1,
            "y": 1,
            "z": 12,
            "elements": [
                "mekanism:reinforcedplasticblock@7"
            ]
        },
        {
            "x": -4,
            "y": -1,
            "z": 11,
            "elements": [
                "thermalfoundation:storage@7"
            ]
        },
        {
            "x": -6,
            "y": 6,
            "z": 15,
            "elements": [
                "additions:durasteel_block@0"
            ]
        },
        {
            "x": 6,
            "y": 1,
            "z": 6,
            "elements": [
                "mekanism:reinforcedplasticblock@7"
            ]
        },
        {
            "x": 5,
            "y": 4,
            "z": 0,
            "elements": [
                "minecraft:water@0"
            ]
        },
        {
            "x": -4,
            "y": -1,
            "z": 1,
            "elements": [
                "mekanism:reinforcedplasticblock@8"
            ]
        },
        {
            "x": -6,
            "y": 1,
            "z": 1,
            "elements": [
                "minecraft:water@0"
            ]
        },
        {
            "x": -6,
            "y": 1,
            "z": 4,
            "elements": [
                "jaopca:block.tough@0"
            ]
        },
        {
            "x": -1,
            "y": 0,
            "z": 12,
            "elements": [
                "mekanism:reinforcedplasticblock@7"
            ]
        },
        {
            "x": -5,
            "y": 2,
            "z": 15,
            "elements": [
                "mekanism:reinforcedplasticblock@8"
            ]
        },
        {
            "x": -6,
            "y": 4,
            "z": 15,
            "elements": [
                "mekanism:reinforcedplasticblock@8"
            ]
        },
        {
            "x": -6,
            "y": 3,
            "z": 11,
            "elements": [
                "minecraft:water@0"
            ]
        },
        {
            "x": -5,
            "y": 3,
            "z": 9,
            "elements": [
                "minecraft:glass@0"
            ]
        },
        {
            "x": 5,
            "y": 2,
            "z": 12,
            "elements": [
                "minecraft:water@0"
            ]
        },
        {
            "x": 9,
            "y": 1,
            "z": 14,
            "elements": [
                "jaopca:block.tough@0"
            ]
        },
        {
            "x": 6,
            "y": 3,
            "z": 14,
            "elements": [
                "minecraft:water@0"
            ]
        },
        {
            "x": 9,
            "y": 3,
            "z": 13,
            "elements": [
                "casings_all"
            ]
        },
        {
            "x": 8,
            "y": 0,
            "z": 0,
            "elements": [
                "mekanism:reinforcedplasticblock@8"
            ]
        },
        {
            "x": -7,
            "y": 3,
            "z": 4,
            "elements": [
                "jaopca:block.tough@0"
            ]
        },
        {
            "x": 7,
            "y": 2,
            "z": 0,
            "elements": [
                "minecraft:water@0"
            ]
        },
        {
            "x": 5,
            "y": 0,
            "z": 5,
            "elements": [
                "minecraft:glass@0"
            ]
        },
        {
            "x": 4,
            "y": 2,
            "z": 3,
            "elements": [
                "thermalfoundation:storage@7"
            ]
        },
        {
            "x": 6,
            "y": 5,
            "z": 11,
            "elements": [
                "plustic:osgloglasblock@0"
            ]
        },
        {
            "x": 5,
            "y": 3,
            "z": 12,
            "elements": [
                "minecraft:water@0"
            ]
        },
        {
            "x": 4,
            "y": 0,
            "z": 3,
            "elements": [
                "thermalfoundation:storage@7"
            ]
        },
        {
            "x": -5,
            "y": -1,
            "z": 4,
            "elements": [
                "jaopca:block.tough@0"
            ]
        },
        {
            "x": 9,
            "y": 2,
            "z": 14,
            "elements": [
                "jaopca:block.tough@0"
            ]
        },
        {
            "x": 6,
            "y": 3,
            "z": 13,
            "elements": [
                "minecraft:water@0"
            ]
        },
        {
            "x": -6,
            "y": 6,
            "z": 8,
            "elements": [
                "minecraft:hopper@2"
            ]
        },
        {
            "x": 9,
            "y": 4,
            "z": 13,
            "elements": [
                "jaopca:block.tough@0"
            ]
        },
        {
            "x": -5,
            "y": 1,
            "z": 16,
            "elements": [
                "jaopca:block.tough@0"
            ]
        },
        {
            "x": -7,
            "y": 0,
            "z": 0,
            "elements": [
                "minecraft:water@0"
            ]
        },
        {
            "x": 6,
            "y": 4,
            "z": 14,
            "elements": [
                "minecraft:water@0"
            ]
        },
        {
            "x": 8,
            "y": -1,
            "z": 14,
            "elements": [
                "mekanism:reinforcedplasticblock@8"
            ]
        },
        {
            "x": -8,
            "y": 2,
            "z": 0,
            "elements": [
                "mekanism:reinforcedplasticblock@8"
            ]
        },
        {
            "x": -6,
            "y": 1,
            "z": 9,
            "elements": [
                "prefab:block_half_glass_slab@0"
            ]
        },
        {
            "x": 8,
            "y": 1,
            "z": 14,
            "elements": [
                "mekanism:reinforcedplasticblock@8"
            ]
        },
        {
            "x": 5,
            "y": -1,
            "z": 8,
            "elements": [
                "mekanism:reinforcedplasticblock@7"
            ]
        },
        {
            "x": 6,
            "y": 5,
            "z": 14,
            "elements": [
                "thermalfoundation:glass_alloy@5"
            ]
        },
        {
            "x": 7,
            "y": -1,
            "z": 12,
            "elements": [
                "mekanism:reinforcedplasticblock@8"
            ]
        },
        {
            "x": 6,
            "y": 2,
            "z": 5,
            "elements": [
                "prefab:block_half_glass_slab@8"
            ]
        },
        {
            "x": 5,
            "y": 1,
            "z": 12,
            "elements": [
                "minecraft:water@0"
            ]
        },
        {
            "x": 9,
            "y": 0,
            "z": 14,
            "elements": [
                "jaopca:block.tough@0"
            ]
        },
        {
            "x": -6,
            "y": -1,
            "z": 16,
            "elements": [
                "jaopca:block.tough@0"
            ]
        },
        {
            "x": 6,
            "y": 0,
            "z": 5,
            "elements": [
                "minecraft:water@0"
            ]
        },
        {
            "x": 7,
            "y": 4,
            "z": 0,
            "elements": [
                "minecraft:water@0"
            ]
        },
        {
            "x": 4,
            "y": 6,
            "z": 0,
            "elements": [
                "additions:durasteel_block@0"
            ]
        },
        {
            "x": 8,
            "y": 2,
            "z": 14,
            "elements": [
                "mekanism:reinforcedplasticblock@8"
            ]
        },
        {
            "x": -6,
            "y": 3,
            "z": 9,
            "elements": [
                "minecraft:water@0"
            ]
        },
        {
            "x": 6,
            "y": 0,
            "z": 8,
            "elements": [
                "minecraft:water@0"
            ]
        },
        {
            "x": 5,
            "y": 0,
            "z": 12,
            "elements": [
                "minecraft:water@0"
            ]
        },
        {
            "x": 6,
            "y": 0,
            "z": 13,
            "elements": [
                "minecraft:water@0"
            ]
        },
        {
            "x": 5,
            "y": 2,
            "z": 13,
            "elements": [
                "minecraft:water@0"
            ]
        },
        {
            "x": 6,
            "y": 1,
            "z": 8,
            "elements": [
                "mekanism:reinforcedplasticblock@7"
            ]
        },
        {
            "x": -6,
            "y": 0,
            "z": 8,
            "elements": [
                "minecraft:water@0"
            ]
        },
        {
            "x": 4,
            "y": 4,
            "z": 0,
            "elements": [
                "mekanism:reinforcedplasticblock@8"
            ]
        },
        {
            "x": -5,
            "y": 3,
            "z": 4,
            "elements": [
                "jaopca:block.tough@0"
            ]
        },
        {
            "x": -8,
            "y": 4,
            "z": 3,
            "elements": [
                "thermalfoundation:storage@7"
            ]
        },
        {
            "x": 5,
            "y": -1,
            "z": 13,
            "elements": [
                "mekanism:reinforcedplasticblock@8"
            ]
        },
        {
            "x": -6,
            "y": -1,
            "z": 9,
            "elements": [
                "prefab:block_half_glass_slab@8"
            ]
        },
        {
            "x": 8,
            "y": 1,
            "z": 12,
            "elements": [
                "mekanism:reinforcedplasticblock@8"
            ]
        },
        {
            "x": 5,
            "y": 1,
            "z": 13,
            "elements": [
                "minecraft:water@0"
            ]
        },
        {
            "x": -5,
            "y": 2,
            "z": 3,
            "elements": [
                "mekanism:reinforcedplasticblock@8"
            ]
        },
        {
            "x": 6,
            "y": 2,
            "z": 8,
            "elements": [
                "mekanism:reinforcedplasticblock@7"
            ]
        },
        {
            "x": 6,
            "y": 1,
            "z": 11,
            "elements": [
                "mekanism:reinforcedplasticblock@8"
            ]
        },
        {
            "x": -7,
            "y": -1,
            "z": 8,
            "elements": [
                "mekanism:reinforcedplasticblock@7"
            ]
        },
        {
            "x": 8,
            "y": 0,
            "z": 12,
            "elements": [
                "mekanism:reinforcedplasticblock@8"
            ]
        },
        {
            "x": 6,
            "y": 4,
            "z": 6,
            "elements": [
                "mekanism:reinforcedplasticblock@7"
            ]
        },
        {
            "x": -6,
            "y": 0,
            "z": 3,
            "elements": [
                "minecraft:water@0"
            ]
        },
        {
            "x": 8,
            "y": 2,
            "z": 12,
            "elements": [
                "mekanism:reinforcedplasticblock@8"
            ]
        },
        {
            "x": 5,
            "y": 0,
            "z": 13,
            "elements": [
                "minecraft:water@0"
            ]
        },
        {
            "x": 7,
            "y": 0,
            "z": 0,
            "elements": [
                "minecraft:water@0"
            ]
        },
        {
            "x": 6,
            "y": 4,
            "z": 8,
            "elements": [
                "mekanism:reinforcedplasticblock@7"
            ]
        },
        {
            "x": 5,
            "y": 4,
            "z": 12,
            "elements": [
                "minecraft:water@0"
            ]
        },
        {
            "x": -7,
            "y": 4,
            "z": 0,
            "elements": [
                "minecraft:water@0"
            ]
        },
        {
            "x": 6,
            "y": 3,
            "z": 6,
            "elements": [
                "minecraft:water@0"
            ]
        },
        {
            "x": 3,
            "y": 4,
            "z": 13,
            "elements": [
                "jaopca:block.tough@0"
            ]
        },
        {
            "x": 4,
            "y": 2,
            "z": 0,
            "elements": [
                "mekanism:reinforcedplasticblock@8"
            ]
        },
        {
            "x": 9,
            "y": 3,
            "z": 14,
            "elements": [
                "jaopca:block.tough@0"
            ]
        },
        {
            "x": -6,
            "y": 2,
            "z": 3,
            "elements": [
                "mekanism:reinforcedplasticblock@8"
            ]
        },
        {
            "x": 6,
            "y": 2,
            "z": 13,
            "elements": [
                "minecraft:water@0"
            ]
        },
        {
            "x": 8,
            "y": 3,
            "z": 12,
            "elements": [
                "mekanism:reinforcedplasticblock@8"
            ]
        },
        {
            "x": 6,
            "y": 3,
            "z": 11,
            "elements": [
                "minecraft:water@0"
            ]
        },
        {
            "x": 4,
            "y": -1,
            "z": 13,
            "elements": [
                "mekanism:reinforcedplasticblock@8"
            ]
        },
        {
            "x": -5,
            "y": 3,
            "z": 16,
            "elements": [
                "jaopca:block.tough@0"
            ]
        },
        {
            "x": 6,
            "y": 1,
            "z": 13,
            "elements": [
                "minecraft:water@0"
            ]
        },
        {
            "x": 6,
            "y": 3,
            "z": 8,
            "elements": [
                "minecraft:water@0"
            ]
        },
        {
            "x": -5,
            "y": 0,
            "z": 3,
            "elements": [
                "mekanism:reinforcedplasticblock@8"
            ]
        },
        {
            "x": 9,
            "y": 4,
            "z": 14,
            "elements": [
                "jaopca:block.tough@0"
            ]
        },
        {
            "x": 5,
            "y": 5,
            "z": 12,
            "elements": [
                "thermalfoundation:glass_alloy@5"
            ]
        },
        {
            "x": -4,
            "y": 0,
            "z": 0,
            "elements": [
                "mekanism:reinforcedplasticblock@8"
            ]
        },
        {
            "x": 8,
            "y": 5,
            "z": 13,
            "elements": [
                "plustic:osgloglasblock@0"
            ]
        },
        {
            "x": -7,
            "y": 2,
            "z": 0,
            "elements": [
                "minecraft:water@0"
            ]
        },
        {
            "x": 3,
            "y": 3,
            "z": 13,
            "elements": [
                "minecraft:water@0"
            ]
        },
        {
            "x": -9,
            "y": 2,
            "z": 2,
            "elements": [
                "jaopca:block.tough@0"
            ]
        },
        {
            "x": 9,
            "y": 1,
            "z": 1,
            "elements": [
                "casings_all"
            ]
        },
        {
            "x": -4,
            "y": 0,
            "z": 15,
            "elements": [
                "thermalfoundation:storage@7"
            ]
        },
        {
            "x": 8,
            "y": 0,
            "z": 13,
            "elements": [
                "mekanism:reinforcedplasticblock@8"
            ]
        },
        {
            "x": -7,
            "y": 2,
            "z": 15,
            "elements": [
                "mekanism:reinforcedplasticblock@8"
            ]
        },
        {
            "x": 9,
            "y": 2,
            "z": 12,
            "elements": [
                "jaopca:block.tough@0"
            ]
        },
        {
            "x": -6,
            "y": 6,
            "z": 3,
            "elements": [
                "additions:durasteel_block@0"
            ]
        },
        {
            "x": 8,
            "y": 4,
            "z": 12,
            "elements": [
                "mekanism:reinforcedplasticblock@8"
            ]
        },
        {
            "x": -7,
            "y": 6,
            "z": 15,
            "elements": [
                "additions:durasteel_block@0"
            ]
        },
        {
            "x": -9,
            "y": 3,
            "z": 2,
            "elements": [
                "jaopca:block.tough@0"
            ]
        },
        {
            "x": 1,
            "y": 6,
            "z": 0,
            "elements": [
                "minecraft:hopper@3"
            ]
        },
        {
            "x": 7,
            "y": -1,
            "z": 13,
            "elements": [
                "mekanism:reinforcedplasticblock@8"
            ]
        },
        {
            "x": -6,
            "y": 4,
            "z": 3,
            "elements": [
                "mekanism:reinforcedplasticblock@8"
            ]
        },
        {
            "x": 8,
            "y": 6,
            "z": 13,
            "elements": [
                "additions:durasteel_block@0"
            ]
        },
        {
            "x": 9,
            "y": 3,
            "z": 12,
            "elements": [
                "jaopca:block.tough@0"
            ]
        },
        {
            "x": 9,
            "y": 0,
            "z": 1,
            "elements": [
                "casings_all"
            ]
        },
        {
            "x": -4,
            "y": 2,
            "z": 15,
            "elements": [
                "thermalfoundation:storage@7"
            ]
        },
        {
            "x": -7,
            "y": 4,
            "z": 15,
            "elements": [
                "mekanism:reinforcedplasticblock@8"
            ]
        },
        {
            "x": 8,
            "y": 5,
            "z": 12,
            "elements": [
                "plustic:osgloglasblock@0"
            ]
        },
        {
            "x": 3,
            "y": 3,
            "z": 14,
            "elements": [
                "jaopca:block.tough@0"
            ]
        },
        {
            "x": -9,
            "y": 0,
            "z": 2,
            "elements": [
                "jaopca:block.tough@0"
            ]
        },
        {
            "x": 5,
            "y": 5,
            "z": 13,
            "elements": [
                "thermalfoundation:glass_alloy@5"
            ]
        },
        {
            "x": -6,
            "y": 0,
            "z": 5,
            "elements": [
                "minecraft:water@0"
            ]
        },
        {
            "x": 5,
            "y": 4,
            "z": 13,
            "elements": [
                "minecraft:water@0"
            ]
        },
        {
            "x": 6,
            "y": 5,
            "z": 1,
            "elements": [
                "thermalfoundation:glass_alloy@5"
            ]
        },
        {
            "x": 8,
            "y": 2,
            "z": 13,
            "elements": [
                "mekanism:reinforcedplasticblock@8"
            ]
        },
        {
            "x": 6,
            "y": 0,
            "z": 14,
            "elements": [
                "minecraft:water@0"
            ]
        },
        {
            "x": -5,
            "y": 1,
            "z": 4,
            "elements": [
                "jaopca:block.tough@0"
            ]
        },
        {
            "x": 9,
            "y": 3,
            "z": 1,
            "elements": [
                "casings_all"
            ]
        },
        {
            "x": 8,
            "y": 6,
            "z": 12,
            "elements": [
                "additions:durasteel_block@0"
            ]
        },
        {
            "x": 8,
            "y": 1,
            "z": 13,
            "elements": [
                "mekanism:reinforcedplasticblock@8"
            ]
        },
        {
            "x": -6,
            "y": 2,
            "z": 5,
            "elements": [
                "prefab:block_half_glass_slab@8"
            ]
        },
        {
            "x": 6,
            "y": 6,
            "z": 6,
            "elements": [
                "minecraft:hopper@3"
            ]
        },
        {
            "x": 9,
            "y": 2,
            "z": 1,
            "elements": [
                "casings_upgrade"
            ]
        },
        {
            "x": 9,
            "y": 1,
            "z": 12,
            "elements": [
                "jaopca:block.tough@0"
            ]
        },
        {
            "x": 6,
            "y": 3,
            "z": -2,
            "elements": [
                "jaopca:block.zirconium_molybdenum@0"
            ]
        },
        {
            "x": 8,
            "y": 4,
            "z": 13,
            "elements": [
                "mekanism:reinforcedplasticblock@8"
            ]
        },
        {
            "x": -7,
            "y": 3,
            "z": 16,
            "elements": [
                "jaopca:block.tough@0"
            ]
        },
        {
            "x": -9,
            "y": 1,
            "z": 2,
            "elements": [
                "jaopca:block.tough@0"
            ]
        },
        {
            "x": 3,
            "y": 4,
            "z": 14,
            "elements": [
                "jaopca:block.tough@0"
            ]
        },
        {
            "x": 5,
            "y": 3,
            "z": 13,
            "elements": [
                "minecraft:water@0"
            ]
        },
        {
            "x": 5,
            "y": -1,
            "z": 14,
            "elements": [
                "mekanism:reinforcedplasticblock@8"
            ]
        },
        {
            "x": -6,
            "y": 1,
            "z": 16,
            "elements": [
                "jaopca:block.porpezite@0"
            ]
        },
        {
            "x": 5,
            "y": -1,
            "z": 11,
            "elements": [
                "mekanism:reinforcedplasticblock@8"
            ]
        },
        {
            "x": 6,
            "y": 4,
            "z": 1,
            "elements": [
                "minecraft:water@0"
            ]
        },
        {
            "x": -4,
            "y": 4,
            "z": 15,
            "elements": [
                "thermalfoundation:storage@7"
            ]
        },
        {
            "x": 9,
            "y": 0,
            "z": 12,
            "elements": [
                "jaopca:block.tough@0"
            ]
        },
        {
            "x": 6,
            "y": 4,
            "z": -2,
            "elements": [
                "jaopca:block.tough@0"
            ]
        },
        {
            "x": 6,
            "y": 4,
            "z": 12,
            "elements": [
                "minecraft:water@0"
            ]
        },
        {
            "x": 6,
            "y": 5,
            "z": 13,
            "elements": [
                "thermalfoundation:glass_alloy@5"
            ]
        },
        {
            "x": 9,
            "y": 2,
            "z": 13,
            "elements": [
                "casings_parallel"
            ]
        },
        {
            "x": 3,
            "y": 0,
            "z": 14,
            "elements": [
                "jaopca:block.tough@0"
            ]
        },
        {
            "x": -5,
            "y": 4,
            "z": 3,
            "elements": [
                "mekanism:reinforcedplasticblock@8"
            ]
        },
        {
            "x": 0,
            "y": 4,
            "z": 14,
            "elements": [
                "mekanism:reinforcedplasticblock@7"
            ]
        },
        {
            "x": 8,
            "y": 3,
            "z": 13,
            "elements": [
                "mekanism:reinforcedplasticblock@8"
            ]
        },
        {
            "x": 6,
            "y": 5,
            "z": 12,
            "elements": [
                "thermalfoundation:glass_alloy@5"
            ]
        },
        {
            "x": 9,
            "y": 1,
            "z": 13,
            "elements": [
                "casings_all"
            ]
        },
        {
            "x": 9,
            "y": 4,
            "z": 1,
            "elements": [
                "jaopca:block.tough@0"
            ]
        },
        {
            "x": -7,
            "y": 1,
            "z": 16,
            "elements": [
                "jaopca:block.tough@0"
            ]
        },
        {
            "x": -7,
            "y": 3,
            "z": 9,
            "elements": [
                "minecraft:glass@0"
            ]
        },
        {
            "x": 5,
            "y": 0,
            "z": 15,
            "elements": [
                "mekanism:reinforcedplasticblock@8"
            ]
        },
        {
            "x": 6,
            "y": 2,
            "z": -2,
            "elements": [
                "jaopca:block.porpezite@0"
            ]
        },
        {
            "x": 6,
            "y": 1,
            "z": 14,
            "elements": [
                "minecraft:water@0"
            ]
        },
        {
            "x": 9,
            "y": 0,
            "z": 13,
            "elements": [
                "casings_all"
            ]
        },
        {
            "x": 9,
            "y": 4,
            "z": 12,
            "elements": [
                "jaopca:block.tough@0"
            ]
        },
        {
            "x": 6,
            "y": 1,
            "z": -2,
            "elements": [
                "jaopca:block.porpezite@0"
            ]
        },
        {
            "x": -5,
            "y": 6,
            "z": 3,
            "elements": [
                "additions:durasteel_block@0"
            ]
        },
        {
            "x": -4,
            "y": 4,
            "z": 3,
            "elements": [
                "thermalfoundation:storage@7"
            ]
        },
        {
            "x": 3,
            "y": 2,
            "z": 14,
            "elements": [
                "jaopca:block.tough@0"
            ]
        },
        {
            "x": -7,
            "y": -1,
            "z": 16,
            "elements": [
                "jaopca:block.tough@0"
            ]
        },
        {
            "x": -6,
            "y": -1,
            "z": 4,
            "elements": [
                "jaopca:block.tough@0"
            ]
        },
        {
            "x": 6,
            "y": 2,
            "z": 14,
            "elements": [
                "minecraft:water@0"
            ]
        },
        {
            "x": -7,
            "y": -1,
            "z": 2,
            "elements": [
                "mekanism:reinforcedplasticblock@8"
            ]
        },
        {
            "x": 6,
            "y": 4,
            "z": 13,
            "elements": [
                "minecraft:water@0"
            ]
        },
        {
            "x": 8,
            "y": -1,
            "z": 13,
            "elements": [
                "mekanism:reinforcedplasticblock@8"
            ]
        },
        {
            "x": 6,
            "y": 0,
            "z": -2,
            "elements": [
                "jaopca:block.porpezite@0"
            ]
        },
        {
            "x": 0,
            "y": 6,
            "z": 14,
            "elements": [
                "minecraft:hopper@2"
            ]
        },
        {
            "x": 3,
            "y": 1,
            "z": 14,
            "elements": [
                "jaopca:block.tough@0"
            ]
        },
        {
            "x": 3,
            "y": 3,
            "z": 2,
            "elements": [
                "jaopca:block.tough@0"
            ]
        },
        {
            "x": -8,
            "y": 2,
            "z": 1,
            "elements": [
                "mekanism:reinforcedplasticblock@8"
            ]
        },
        {
            "x": 7,
            "y": 2,
            "z": 11,
            "elements": [
                "mekanism:reinforcedplasticblock@8"
            ]
        },
        {
            "x": -3,
            "y": 3,
            "z": 12,
            "elements": [
                "jaopca:block.tough@0"
            ]
        },
        {
            "x": 5,
            "y": -1,
            "z": 15,
            "elements": [
                "mekanism:reinforcedplasticblock@8"
            ]
        },
        {
            "x": 6,
            "y": -1,
            "z": 4,
            "elements": [
                "jaopca:block.tough@0"
            ]
        },
        {
            "x": 6,
            "y": 1,
            "z": 12,
            "elements": [
                "minecraft:water@0"
            ]
        },
        {
            "x": 4,
            "y": 0,
            "z": 11,
            "elements": [
                "thermalfoundation:storage@7"
            ]
        },
        {
            "x": 7,
            "y": 0,
            "z": 4,
            "elements": [
                "jaopca:block.tough@0"
            ]
        },
        {
            "x": -7,
            "y": 1,
            "z": 7,
            "elements": [
                "mekanism:reinforcedplasticblock@7"
            ]
        },
        {
            "x": 7,
            "y": 3,
            "z": 11,
            "elements": [
                "mekanism:reinforcedplasticblock@8"
            ]
        },
        {
            "x": 8,
            "y": 3,
            "z": -1,
            "elements": [
                "thermalfoundation:storage@7"
            ]
        },
        {
            "x": -6,
            "y": 1,
            "z": 2,
            "elements": [
                "minecraft:water@0"
            ]
        },
        {
            "x": -4,
            "y": -1,
            "z": 2,
            "elements": [
                "mekanism:reinforcedplasticblock@8"
            ]
        },
        {
            "x": 4,
            "y": 1,
            "z": 11,
            "elements": [
                "thermalfoundation:storage@7"
            ]
        },
        {
            "x": 7,
            "y": 5,
            "z": -1,
            "elements": [
                "plustic:osgloglasblock@0"
            ]
        },
        {
            "x": 5,
            "y": -1,
            "z": 16,
            "elements": [
                "jaopca:block.tough@0"
            ]
        },
        {
            "x": 5,
            "y": 1,
            "z": -1,
            "elements": [
                "mekanism:reinforcedplasticblock@8"
            ]
        },
        {
            "x": 6,
            "y": 1,
            "z": 15,
            "elements": [
                "mekanism:reinforcedplasticblock@8"
            ]
        },
        {
            "x": 7,
            "y": 4,
            "z": 1,
            "elements": [
                "minecraft:water@0"
            ]
        },
        {
            "x": -9,
            "y": 2,
            "z": 13,
            "elements": [
                "casings_parallel"
            ]
        },
        {
            "x": -1,
            "y": 3,
            "z": 14,
            "elements": [
                "mekanism:reinforcedplasticblock@7"
            ]
        },
        {
            "x": 7,
            "y": 1,
            "z": 4,
            "elements": [
                "jaopca:block.tough@0"
            ]
        },
        {
            "x": -1,
            "y": -1,
            "z": 12,
            "elements": [
                "mekanism:reinforcedplasticblock@7"
            ]
        },
        {
            "x": 5,
            "y": 2,
            "z": 6,
            "elements": [
                "mekanism:reinforcedplasticblock@7"
            ]
        },
        {
            "x": -3,
            "y": 1,
            "z": 12,
            "elements": [
                "jaopca:block.tough@0"
            ]
        },
        {
            "x": -8,
            "y": 0,
            "z": 1,
            "elements": [
                "mekanism:reinforcedplasticblock@8"
            ]
        },
        {
            "x": 7,
            "y": -1,
            "z": -1,
            "elements": [
                "mekanism:reinforcedplasticblock@8"
            ]
        },
        {
            "x": 7,
            "y": 0,
            "z": 11,
            "elements": [
                "mekanism:reinforcedplasticblock@8"
            ]
        },
        {
            "x": 4,
            "y": 2,
            "z": 11,
            "elements": [
                "thermalfoundation:storage@7"
            ]
        },
        {
            "x": 3,
            "y": 1,
            "z": 2,
            "elements": [
                "jaopca:block.tough@0"
            ]
        },
        {
            "x": 6,
            "y": 0,
            "z": 16,
            "elements": [
                "jaopca:block.porpezite@0"
            ]
        },
        {
            "x": 6,
            "y": 1,
            "z": 16,
            "elements": [
                "jaopca:block.porpezite@0"
            ]
        },
        {
            "x": -6,
            "y": 3,
            "z": 2,
            "elements": [
                "minecraft:water@0"
            ]
        },
        {
            "x": -5,
            "y": 0,
            "z": 8,
            "elements": [
                "mekanism:reinforcedplasticblock@7"
            ]
        },
        {
            "x": 7,
            "y": 2,
            "z": 4,
            "elements": [
                "jaopca:block.tough@0"
            ]
        },
        {
            "x": 6,
            "y": 3,
            "z": 12,
            "elements": [
                "minecraft:water@0"
            ]
        },
        {
            "x": -9,
            "y": 0,
            "z": 13,
            "elements": [
                "casings_all"
            ]
        },
        {
            "x": -6,
            "y": 4,
            "z": -2,
            "elements": [
                "jaopca:block.tough@0"
            ]
        },
        {
            "x": 1,
            "y": -1,
            "z": 14,
            "elements": [
                "mekanism:reinforcedplasticblock@7"
            ]
        },
        {
            "x": -5,
            "y": -1,
            "z": 2,
            "elements": [
                "mekanism:reinforcedplasticblock@8"
            ]
        },
        {
            "x": 4,
            "y": 3,
            "z": 11,
            "elements": [
                "thermalfoundation:storage@7"
            ]
        },
        {
            "x": 7,
            "y": -1,
            "z": 7,
            "elements": [
                "mekanism:reinforcedplasticblock@7"
            ]
        },
        {
            "x": 5,
            "y": 4,
            "z": 6,
            "elements": [
                "mekanism:reinforcedplasticblock@7"
            ]
        },
        {
            "x": 7,
            "y": 1,
            "z": 11,
            "elements": [
                "mekanism:reinforcedplasticblock@8"
            ]
        },
        {
            "x": 8,
            "y": 1,
            "z": -1,
            "elements": [
                "thermalfoundation:storage@7"
            ]
        },
        {
            "x": 6,
            "y": 0,
            "z": 15,
            "elements": [
                "mekanism:reinforcedplasticblock@8"
            ]
        },
        {
            "x": 5,
            "y": 3,
            "z": -1,
            "elements": [
                "mekanism:reinforcedplasticblock@8"
            ]
        },
        {
            "x": 4,
            "y": 4,
            "z": 11,
            "elements": [
                "thermalfoundation:storage@7"
            ]
        },
        {
            "x": 0,
            "y": 1,
            "z": 12,
            "elements": [
                "mekanism:reinforcedplasticblock@7"
            ]
        },
        {
            "x": -6,
            "y": 5,
            "z": 2,
            "elements": [
                "thermalfoundation:glass_alloy@5"
            ]
        },
        {
            "x": -3,
            "y": 2,
            "z": 13,
            "elements": [
                "jaopca:block.tough@0"
            ]
        },
        {
            "x": 6,
            "y": 3,
            "z": 15,
            "elements": [
                "mekanism:reinforcedplasticblock@8"
            ]
        },
        {
            "x": 7,
            "y": 0,
            "z": 1,
            "elements": [
                "minecraft:water@0"
            ]
        },
        {
            "x": -6,
            "y": 2,
            "z": 16,
            "elements": [
                "jaopca:block.porpezite@0"
            ]
        },
        {
            "x": -8,
            "y": -1,
            "z": -1,
            "elements": [
                "thermalfoundation:storage@7"
            ]
        },
        {
            "x": -3,
            "y": 3,
            "z": 2,
            "elements": [
                "jaopca:block.tough@0"
            ]
        },
        {
            "x": 8,
            "y": -1,
            "z": 12,
            "elements": [
                "mekanism:reinforcedplasticblock@8"
            ]
        },
        {
            "x": -6,
            "y": 5,
            "z": 12,
            "elements": [
                "thermalfoundation:glass_alloy@5"
            ]
        },
        {
            "x": -5,
            "y": -1,
            "z": 7,
            "elements": [
                "mekanism:reinforcedplasticblock@7"
            ]
        },
        {
            "x": 0,
            "y": 1,
            "z": 2,
            "elements": [
                "mekanism:reinforcedplasticblock@7"
            ]
        },
        {
            "x": 3,
            "y": 3,
            "z": 12,
            "elements": [
                "jaopca:block.tough@0"
            ]
        },
        {
            "x": -6,
            "y": 2,
            "z": -2,
            "elements": [
                "jaopca:block.porpezite@0"
            ]
        },
        {
            "x": 6,
            "y": 2,
            "z": 15,
            "elements": [
                "mekanism:reinforcedplasticblock@8"
            ]
        },
        {
            "x": 5,
            "y": 6,
            "z": 6,
            "elements": [
                "minecraft:hopper@5"
            ]
        },
        {
            "x": -6,
            "y": 3,
            "z": 16,
            "elements": [
                "jaopca:block.zirconium_molybdenum@0"
            ]
        },
        {
            "x": 4,
            "y": 6,
            "z": 1,
            "elements": [
                "additions:durasteel_block@0"
            ]
        },
        {
            "x": 5,
            "y": 5,
            "z": -1,
            "elements": [
                "plustic:osgloglasblock@0"
            ]
        },
        {
            "x": 6,
            "y": -1,
            "z": 11,
            "elements": [
                "mekanism:reinforcedplasticblock@8"
            ]
        },
        {
            "x": 7,
            "y": 1,
            "z": -1,
            "elements": [
                "mekanism:reinforcedplasticblock@8"
            ]
        },
        {
            "x": -4,
            "y": 5,
            "z": 14,
            "elements": [
                "plustic:osgloglasblock@0"
            ]
        },
        {
            "x": 7,
            "y": 2,
            "z": 10,
            "elements": [
                "jaopca:block.tough@0"
            ]
        },
        {
            "x": -6,
            "y": 4,
            "z": 16,
            "elements": [
                "jaopca:block.tough@0"
            ]
        },
        {
            "x": -7,
            "y": 3,
            "z": 7,
            "elements": [
                "mekanism:reinforcedplasticblock@7"
            ]
        },
        {
            "x": 0,
            "y": 3,
            "z": 2,
            "elements": [
                "mekanism:reinforcedplasticblock@7"
            ]
        },
        {
            "x": 6,
            "y": 5,
            "z": 15,
            "elements": [
                "plustic:osgloglasblock@0"
            ]
        },
        {
            "x": -6,
            "y": 0,
            "z": -2,
            "elements": [
                "jaopca:block.porpezite@0"
            ]
        },
        {
            "x": 5,
            "y": -1,
            "z": 2,
            "elements": [
                "mekanism:reinforcedplasticblock@8"
            ]
        },
        {
            "x": 6,
            "y": 4,
            "z": 15,
            "elements": [
                "mekanism:reinforcedplasticblock@8"
            ]
        },
        {
            "x": 5,
            "y": -1,
            "z": 12,
            "elements": [
                "mekanism:reinforcedplasticblock@8"
            ]
        },
        {
            "x": 0,
            "y": 3,
            "z": 12,
            "elements": [
                "mekanism:reinforcedplasticblock@7"
            ]
        },
        {
            "x": -3,
            "y": 1,
            "z": 2,
            "elements": [
                "jaopca:block.tough@0"
            ]
        },
        {
            "x": 7,
            "y": 2,
            "z": 1,
            "elements": [
                "minecraft:water@0"
            ]
        },
        {
            "x": 8,
            "y": -1,
            "z": 15,
            "elements": [
                "thermalfoundation:storage@7"
            ]
        },
        {
            "x": 6,
            "y": 6,
            "z": 15,
            "elements": [
                "additions:durasteel_block@0"
            ]
        },
        {
            "x": 3,
            "y": 1,
            "z": 12,
            "elements": [
                "jaopca:block.tough@0"
            ]
        },
        {
            "x": 7,
            "y": 3,
            "z": -1,
            "elements": [
                "mekanism:reinforcedplasticblock@8"
            ]
        },
        {
            "x": 7,
            "y": 3,
            "z": 10,
            "elements": [
                "jaopca:block.tough@0"
            ]
        },
        {
            "x": 4,
            "y": 4,
            "z": 1,
            "elements": [
                "mekanism:reinforcedplasticblock@8"
            ]
        },
        {
            "x": 6,
            "y": 0,
            "z": 9,
            "elements": [
                "minecraft:water@0"
            ]
        },
        {
            "x": -1,
            "y": 1,
            "z": 14,
            "elements": [
                "mekanism:reinforcedplasticblock@7"
            ]
        },
        {
            "x": -3,
            "y": 0,
            "z": 13,
            "elements": [
                "minecraft:water@0"
            ]
        },
        {
            "x": 7,
            "y": 4,
            "z": 10,
            "elements": [
                "jaopca:block.tough@0"
            ]
        },
        {
            "x": -7,
            "y": 3,
            "z": -1,
            "elements": [
                "mekanism:reinforcedplasticblock@8"
            ]
        },
        {
            "x": 2,
            "y": 3,
            "z": 14,
            "elements": [
                "minecraft:glass@0"
            ]
        },
        {
            "x": -4,
            "y": 5,
            "z": 2,
            "elements": [
                "plustic:osgloglasblock@0"
            ]
        },
        {
            "x": 3,
            "y": 2,
            "z": 13,
            "elements": [
                "jaopca:block.tough@0"
            ]
        },
        {
            "x": 6,
            "y": 2,
            "z": 10,
            "elements": [
                "jaopca:block.tough@0"
            ]
        },
        {
            "x": -1,
            "y": 3,
            "z": 2,
            "elements": [
                "mekanism:reinforcedplasticblock@7"
            ]
        },
        {
            "x": 6,
            "y": 1,
            "z": 10,
            "elements": [
                "jaopca:block.tough@0"
            ]
        },
        {
            "x": 2,
            "y": 4,
            "z": 13,
            "elements": [
                "prefab:block_half_glass_slab@0"
            ]
        },
        {
            "x": -5,
            "y": 4,
            "z": 1,
            "elements": [
                "minecraft:water@0"
            ]
        },
        {
            "x": 1,
            "y": 0,
            "z": 1,
            "elements": [
                "minecraft:water@0"
            ]
        },
        {
            "x": 0,
            "y": -1,
            "z": 2,
            "elements": [
                "mekanism:reinforcedplasticblock@7"
            ]
        },
        {
            "x": 6,
            "y": 3,
            "z": 10,
            "elements": [
                "minecraft:water@0"
            ]
        },
        {
            "x": 4,
            "y": 2,
            "z": 1,
            "elements": [
                "mekanism:reinforcedplasticblock@8"
            ]
        },
        {
            "x": 4,
            "y": -1,
            "z": 14,
            "elements": [
                "mekanism:reinforcedplasticblock@8"
            ]
        },
        {
            "x": 0,
            "y": 0,
            "z": 13,
            "elements": [
                "minecraft:water@0"
            ]
        },
        {
            "x": 6,
            "y": 4,
            "z": 10,
            "elements": [
                "jaopca:block.tough@0"
            ]
        },
        {
            "x": 8,
            "y": -1,
            "z": 11,
            "elements": [
                "thermalfoundation:storage@7"
            ]
        },
        {
            "x": -7,
            "y": 4,
            "z": 8,
            "elements": [
                "mekanism:reinforcedplasticblock@7"
            ]
        },
        {
            "x": 6,
            "y": 0,
            "z": 10,
            "elements": [
                "minecraft:water@0"
            ]
        },
        {
            "x": 0,
            "y": 2,
            "z": 13,
            "elements": [
                "minecraft:water@0"
            ]
        },
        {
            "x": -3,
            "y": 4,
            "z": 13,
            "elements": [
                "jaopca:block.tough@0"
            ]
        },
        {
            "x": 3,
            "y": 0,
            "z": 13,
            "elements": [
                "minecraft:water@0"
            ]
        },
        {
            "x": -2,
            "y": 3,
            "z": 2,
            "elements": [
                "minecraft:glass@0"
            ]
        },
        {
            "x": -5,
            "y": 6,
            "z": 8,
            "elements": [
                "minecraft:hopper@4"
            ]
        },
        {
            "x": 8,
            "y": 5,
            "z": 0,
            "elements": [
                "plustic:osgloglasblock@0"
            ]
        },
        {
            "x": 4,
            "y": 0,
            "z": 1,
            "elements": [
                "minecraft:water@0"
            ]
        },
        {
            "x": -5,
            "y": -1,
            "z": -1,
            "elements": [
                "mekanism:reinforcedplasticblock@8"
            ]
        },
        {
            "x": 1,
            "y": 2,
            "z": 1,
            "elements": [
                "mekanism:reinforcedplasticblock@7"
            ]
        },
        {
            "x": 7,
            "y": 1,
            "z": 10,
            "elements": [
                "jaopca:block.tough@0"
            ]
        },
        {
            "x": -7,
            "y": 1,
            "z": -1,
            "elements": [
                "mekanism:reinforcedplasticblock@8"
            ]
        },
        {
            "x": -1,
            "y": 1,
            "z": 2,
            "elements": [
                "mekanism:reinforcedplasticblock@7"
            ]
        },
        {
            "x": -1,
            "y": -1,
            "z": 2,
            "elements": [
                "mekanism:reinforcedplasticblock@7"
            ]
        },
        {
            "x": -7,
            "y": 2,
            "z": 8,
            "elements": [
                "mekanism:reinforcedplasticblock@7"
            ]
        },
        {
            "x": -2,
            "y": 4,
            "z": 1,
            "elements": [
                "prefab:block_half_glass_slab@0"
            ]
        },
        {
            "x": 7,
            "y": 0,
            "z": 10,
            "elements": [
                "jaopca:block.tough@0"
            ]
        },
        {
            "x": 8,
            "y": 6,
            "z": 0,
            "elements": [
                "additions:durasteel_block@0"
            ]
        },
        {
            "x": -4,
            "y": 3,
            "z": 14,
            "elements": [
                "mekanism:reinforcedplasticblock@8"
            ]
        },
        {
            "x": 5,
            "y": 1,
            "z": 7,
            "elements": [
                "mekanism:reinforcedplasticblock@7"
            ]
        },
        {
            "x": -4,
            "y": 1,
            "z": -1,
            "elements": [
                "thermalfoundation:storage@7"
            ]
        },
        {
            "x": 5,
            "y": 1,
            "z": 14,
            "elements": [
                "minecraft:water@0"
            ]
        },
        {
            "x": 5,
            "y": 0,
            "z": 6,
            "elements": [
                "mekanism:reinforcedplasticblock@7"
            ]
        },
        {
            "x": 8,
            "y": 3,
            "z": 0,
            "elements": [
                "mekanism:reinforcedplasticblock@8"
            ]
        },
        {
            "x": 2,
            "y": 0,
            "z": 13,
            "elements": [
                "minecraft:water@0"
            ]
        },
        {
            "x": 4,
            "y": -1,
            "z": -1,
            "elements": [
                "thermalfoundation:storage@7"
            ]
        },
        {
            "x": -5,
            "y": 0,
            "z": 1,
            "elements": [
                "minecraft:water@0"
            ]
        },
        {
            "x": 1,
            "y": 3,
            "z": 2,
            "elements": [
                "mekanism:reinforcedplasticblock@7"
            ]
        },
        {
            "x": 5,
            "y": 5,
            "z": 14,
            "elements": [
                "thermalfoundation:glass_alloy@5"
            ]
        },
        {
            "x": -1,
            "y": 6,
            "z": 13,
            "elements": [
                "minecraft:hopper@5"
            ]
        },
        {
            "x": 7,
            "y": 4,
            "z": 4,
            "elements": [
                "jaopca:block.tough@0"
            ]
        },
        {
            "x": -4,
            "y": 1,
            "z": 2,
            "elements": [
                "mekanism:reinforcedplasticblock@8"
            ]
        },
        {
            "x": 0,
            "y": 4,
            "z": 13,
            "elements": [
                "minecraft:water@0"
            ]
        },
        {
            "x": 5,
            "y": 3,
            "z": 7,
            "elements": [
                "mekanism:reinforcedplasticblock@7"
            ]
        },
        {
            "x": 1,
            "y": 4,
            "z": 1,
            "elements": [
                "mekanism:reinforcedplasticblock@7"
            ]
        },
        {
            "x": 8,
            "y": 4,
            "z": 0,
            "elements": [
                "mekanism:reinforcedplasticblock@8"
            ]
        },
        {
            "x": 6,
            "y": -1,
            "z": 3,
            "elements": [
                "mekanism:reinforcedplasticblock@8"
            ]
        },
        {
            "x": -6,
            "y": 2,
            "z": 8,
            "elements": [
                "mekanism:reinforcedplasticblock@7"
            ]
        },
        {
            "x": -8,
            "y": 6,
            "z": 1,
            "elements": [
                "additions:durasteel_block@0"
            ]
        },
        {
            "x": 1,
            "y": -1,
            "z": 2,
            "elements": [
                "mekanism:reinforcedplasticblock@7"
            ]
        },
        {
            "x": -7,
            "y": 5,
            "z": -1,
            "elements": [
                "plustic:osgloglasblock@0"
            ]
        },
        {
            "x": 8,
            "y": 4,
            "z": 14,
            "elements": [
                "mekanism:reinforcedplasticblock@8"
            ]
        },
        {
            "x": 7,
            "y": 6,
            "z": 11,
            "elements": [
                "additions:durasteel_block@0"
            ]
        },
        {
            "x": 7,
            "y": 3,
            "z": 4,
            "elements": [
                "jaopca:block.tough@0"
            ]
        },
        {
            "x": -5,
            "y": 4,
            "z": -2,
            "elements": [
                "jaopca:block.tough@0"
            ]
        },
        {
            "x": -5,
            "y": 4,
            "z": 8,
            "elements": [
                "mekanism:reinforcedplasticblock@7"
            ]
        },
        {
            "x": 1,
            "y": 1,
            "z": 2,
            "elements": [
                "mekanism:reinforcedplasticblock@7"
            ]
        },
        {
            "x": -1,
            "y": 4,
            "z": 13,
            "elements": [
                "mekanism:reinforcedplasticblock@7"
            ]
        },
        {
            "x": -6,
            "y": 0,
            "z": 9,
            "elements": [
                "minecraft:water@0"
            ]
        },
        {
            "x": -5,
            "y": 5,
            "z": 2,
            "elements": [
                "thermalfoundation:glass_alloy@5"
            ]
        },
        {
            "x": 7,
            "y": 4,
            "z": 11,
            "elements": [
                "mekanism:reinforcedplasticblock@8"
            ]
        },
        {
            "x": 8,
            "y": 6,
            "z": 14,
            "elements": [
                "additions:durasteel_block@0"
            ]
        },
        {
            "x": 2,
            "y": 2,
            "z": 13,
            "elements": [
                "prefab:block_half_glass_slab@8"
            ]
        },
        {
            "x": 4,
            "y": 4,
            "z": 3,
            "elements": [
                "thermalfoundation:storage@7"
            ]
        },
        {
            "x": 5,
            "y": 3,
            "z": 14,
            "elements": [
                "minecraft:water@0"
            ]
        },
        {
            "x": -8,
            "y": 4,
            "z": 1,
            "elements": [
                "mekanism:reinforcedplasticblock@8"
            ]
        },
        {
            "x": -4,
            "y": 3,
            "z": -1,
            "elements": [
                "thermalfoundation:storage@7"
            ]
        },
        {
            "x": -4,
            "y": 3,
            "z": 2,
            "elements": [
                "mekanism:reinforcedplasticblock@8"
            ]
        },
        {
            "x": 5,
            "y": -1,
            "z": 10,
            "elements": [
                "jaopca:block.tough@0"
            ]
        },
        {
            "x": 7,
            "y": 5,
            "z": 11,
            "elements": [
                "plustic:osgloglasblock@0"
            ]
        },
        {
            "x": 0,
            "y": 6,
            "z": 13,
            "elements": [
                "minecraft:hopper@0"
            ]
        },
        {
            "x": -5,
            "y": 2,
            "z": 1,
            "elements": [
                "minecraft:water@0"
            ]
        },
        {
            "x": 8,
            "y": 2,
            "z": 0,
            "elements": [
                "mekanism:reinforcedplasticblock@8"
            ]
        },
        {
            "x": -5,
            "y": 2,
            "z": 8,
            "elements": [
                "mekanism:reinforcedplasticblock@7"
            ]
        },
        {
            "x": -8,
            "y": 0,
            "z": 0,
            "elements": [
                "mekanism:reinforcedplasticblock@8"
            ]
        },
        {
            "x": -7,
            "y": 6,
            "z": 8,
            "elements": [
                "minecraft:hopper@2"
            ]
        },
        {
            "x": -9,
            "y": -1,
            "z": 0,
            "elements": [
                "jaopca:block.tough@0"
            ]
        },
        {
            "x": 8,
            "y": 1,
            "z": 0,
            "elements": [
                "mekanism:reinforcedplasticblock@8"
            ]
        },
        {
            "x": 4,
            "y": 3,
            "z": 3,
            "elements": [
                "thermalfoundation:storage@7"
            ]
        },
        {
            "x": 7,
            "y": -1,
            "z": 14,
            "elements": [
                "mekanism:reinforcedplasticblock@8"
            ]
        },
        {
            "x": 1,
            "y": 6,
            "z": 1,
            "elements": [
                "minecraft:hopper@4"
            ]
        },
        {
            "x": -6,
            "y": 4,
            "z": 8,
            "elements": [
                "mekanism:reinforcedplasticblock@7"
            ]
        },
        {
            "x": 5,
            "y": 5,
            "z": 0,
            "elements": [
                "thermalfoundation:glass_alloy@5"
            ]
        },
        {
            "x": -3,
            "y": 0,
            "z": 1,
            "elements": [
                "minecraft:water@0"
            ]
        },
        {
            "x": -1,
            "y": 2,
            "z": 13,
            "elements": [
                "mekanism:reinforcedplasticblock@7"
            ]
        },
        {
            "x": 7,
            "y": 0,
            "z": 3,
            "elements": [
                "mekanism:reinforcedplasticblock@8"
            ]
        },
        {
            "x": -6,
            "y": 2,
            "z": 6,
            "elements": [
                "mekanism:reinforcedplasticblock@7"
            ]
        },
        {
            "x": -5,
            "y": 3,
            "z": 2,
            "elements": [
                "minecraft:water@0"
            ]
        },
        {
            "x": -7,
            "y": -1,
            "z": 7,
            "elements": [
                "mekanism:reinforcedplasticblock@7"
            ]
        },
        {
            "x": 0,
            "y": 2,
            "z": 1,
            "elements": [
                "minecraft:water@0"
            ]
        },
        {
            "x": -8,
            "y": -1,
            "z": 14,
            "elements": [
                "mekanism:reinforcedplasticblock@8"
            ]
        },
        {
            "x": -8,
            "y": 5,
            "z": 2,
            "elements": [
                "plustic:osgloglasblock@0"
            ]
        },
        {
            "x": -4,
            "y": 5,
            "z": 12,
            "elements": [
                "plustic:osgloglasblock@0"
            ]
        },
        {
            "x": -6,
            "y": 1,
            "z": 14,
            "elements": [
                "minecraft:water@0"
            ]
        },
        {
            "x": -7,
            "y": 4,
            "z": -2,
            "elements": [
                "jaopca:block.tough@0"
            ]
        },
        {
            "x": -9,
            "y": 3,
            "z": 14,
            "elements": [
                "jaopca:block.tough@0"
            ]
        },
        {
            "x": -1,
            "y": 4,
            "z": 1,
            "elements": [
                "mekanism:reinforcedplasticblock@7"
            ]
        },
        {
            "x": -4,
            "y": 0,
            "z": 13,
            "elements": [
                "minecraft:water@0"
            ]
        },
        {
            "x": -9,
            "y": -1,
            "z": 12,
            "elements": [
                "jaopca:block.tough@0"
            ]
        },
        {
            "x": -8,
            "y": 5,
            "z": 14,
            "elements": [
                "plustic:osgloglasblock@0"
            ]
        },
        {
            "x": -6,
            "y": 1,
            "z": 7,
            "elements": [
                "minecraft:water@0"
            ]
        },
        {
            "x": -6,
            "y": 4,
            "z": 6,
            "elements": [
                "mekanism:reinforcedplasticblock@7"
            ]
        },
        {
            "x": -4,
            "y": 2,
            "z": 13,
            "elements": [
                "mekanism:reinforcedplasticblock@8"
            ]
        },
        {
            "x": -7,
            "y": 4,
            "z": 13,
            "elements": [
                "minecraft:water@0"
            ]
        },
        {
            "x": 7,
            "y": 2,
            "z": 3,
            "elements": [
                "mekanism:reinforcedplasticblock@8"
            ]
        },
        {
            "x": -6,
            "y": 4,
            "z": 1,
            "elements": [
                "minecraft:water@0"
            ]
        },
        {
            "x": 7,
            "y": 6,
            "z": 8,
            "elements": [
                "minecraft:hopper@4"
            ]
        },
        {
            "x": -5,
            "y": 5,
            "z": 12,
            "elements": [
                "thermalfoundation:glass_alloy@5"
            ]
        },
        {
            "x": 3,
            "y": -1,
            "z": 2,
            "elements": [
                "jaopca:block.tough@0"
            ]
        },
        {
            "x": -3,
            "y": 2,
            "z": 1,
            "elements": [
                "jaopca:block.tough@0"
            ]
        },
        {
            "x": -7,
            "y": -1,
            "z": 14,
            "elements": [
                "mekanism:reinforcedplasticblock@8"
            ]
        },
        {
            "x": 0,
            "y": 0,
            "z": 1,
            "elements": [
                "minecraft:water@0"
            ]
        },
        {
            "x": -2,
            "y": 3,
            "z": 12,
            "elements": [
                "minecraft:glass@0"
            ]
        },
        {
            "x": -7,
            "y": 1,
            "z": 14,
            "elements": [
                "minecraft:water@0"
            ]
        },
        {
            "x": -5,
            "y": 1,
            "z": 2,
            "elements": [
                "minecraft:water@0"
            ]
        },
        {
            "x": -6,
            "y": 5,
            "z": -1,
            "elements": [
                "plustic:osgloglasblock@0"
            ]
        },
        {
            "x": -8,
            "y": 3,
            "z": 14,
            "elements": [
                "mekanism:reinforcedplasticblock@8"
            ]
        },
        {
            "x": -1,
            "y": 6,
            "z": 1,
            "elements": [
                "minecraft:hopper@5"
            ]
        },
        {
            "x": -1,
            "y": 0,
            "z": 13,
            "elements": [
                "minecraft:water@0"
            ]
        },
        {
            "x": 7,
            "y": 1,
            "z": 3,
            "elements": [
                "mekanism:reinforcedplasticblock@8"
            ]
        },
        {
            "x": 7,
            "y": 4,
            "z": 8,
            "elements": [
                "mekanism:reinforcedplasticblock@7"
            ]
        },
        {
            "x": -1,
            "y": 0,
            "z": 1,
            "elements": [
                "minecraft:water@0"
            ]
        },
        {
            "x": -8,
            "y": 1,
            "z": 12,
            "elements": [
                "mekanism:reinforcedplasticblock@8"
            ]
        },
        {
            "x": -4,
            "y": 4,
            "z": 13,
            "elements": [
                "mekanism:reinforcedplasticblock@8"
            ]
        },
        {
            "x": 0,
            "y": -1,
            "z": 12,
            "elements": [
                "mekanism:reinforcedplasticblock@7"
            ]
        },
        {
            "x": 7,
            "y": 4,
            "z": 3,
            "elements": [
                "mekanism:reinforcedplasticblock@8"
            ]
        },
        {
            "x": -2,
            "y": 2,
            "z": 1,
            "elements": [
                "prefab:block_half_glass_slab@8"
            ]
        },
        {
            "x": -5,
            "y": 3,
            "z": 12,
            "elements": [
                "minecraft:water@0"
            ]
        },
        {
            "x": -4,
            "y": 6,
            "z": 1,
            "elements": [
                "additions:durasteel_block@0"
            ]
        },
        {
            "x": -8,
            "y": 1,
            "z": 2,
            "elements": [
                "mekanism:reinforcedplasticblock@8"
            ]
        },
        {
            "x": -3,
            "y": 4,
            "z": 1,
            "elements": [
                "jaopca:block.tough@0"
            ]
        },
        {
            "x": -7,
            "y": 0,
            "z": 6,
            "elements": [
                "mekanism:reinforcedplasticblock@7"
            ]
        },
        {
            "x": 7,
            "y": 3,
            "z": 3,
            "elements": [
                "mekanism:reinforcedplasticblock@8"
            ]
        },
        {
            "x": -6,
            "y": -1,
            "z": 2,
            "elements": [
                "mekanism:reinforcedplasticblock@8"
            ]
        },
        {
            "x": 5,
            "y": 0,
            "z": -2,
            "elements": [
                "jaopca:block.tough@0"
            ]
        },
        {
            "x": -4,
            "y": 1,
            "z": 14,
            "elements": [
                "mekanism:reinforcedplasticblock@8"
            ]
        },
        {
            "x": -7,
            "y": 3,
            "z": 14,
            "elements": [
                "minecraft:water@0"
            ]
        },
        {
            "x": -2,
            "y": 0,
            "z": 1,
            "elements": [
                "minecraft:water@0"
            ]
        },
        {
            "x": -3,
            "y": -1,
            "z": 12,
            "elements": [
                "jaopca:block.tough@0"
            ]
        },
        {
            "x": -8,
            "y": 3,
            "z": 12,
            "elements": [
                "mekanism:reinforcedplasticblock@8"
            ]
        },
        {
            "x": 7,
            "y": 2,
            "z": 8,
            "elements": [
                "mekanism:reinforcedplasticblock@7"
            ]
        },
        {
            "x": -5,
            "y": 1,
            "z": 12,
            "elements": [
                "minecraft:water@0"
            ]
        },
        {
            "x": -1,
            "y": 2,
            "z": 1,
            "elements": [
                "mekanism:reinforcedplasticblock@7"
            ]
        },
        {
            "x": -9,
            "y": 1,
            "z": 14,
            "elements": [
                "jaopca:block.tough@0"
            ]
        },
        {
            "x": -4,
            "y": 4,
            "z": 1,
            "elements": [
                "mekanism:reinforcedplasticblock@8"
            ]
        },
        {
            "x": -5,
            "y": -1,
            "z": 14,
            "elements": [
                "mekanism:reinforcedplasticblock@8"
            ]
        },
        {
            "x": -8,
            "y": 3,
            "z": 2,
            "elements": [
                "mekanism:reinforcedplasticblock@8"
            ]
        },
        {
            "x": -7,
            "y": 0,
            "z": 8,
            "elements": [
                "mekanism:reinforcedplasticblock@7"
            ]
        },
        {
            "x": -4,
            "y": 6,
            "z": 13,
            "elements": [
                "additions:durasteel_block@0"
            ]
        },
        {
            "x": -3,
            "y": -1,
            "z": 2,
            "elements": [
                "jaopca:block.tough@0"
            ]
        },
        {
            "x": 7,
            "y": 5,
            "z": 3,
            "elements": [
                "plustic:osgloglasblock@0"
            ]
        },
        {
            "x": -6,
            "y": 0,
            "z": 6,
            "elements": [
                "minecraft:water@0"
            ]
        },
        {
            "x": -7,
            "y": 5,
            "z": 14,
            "elements": [
                "thermalfoundation:glass_alloy@5"
            ]
        },
        {
            "x": 5,
            "y": 2,
            "z": -2,
            "elements": [
                "jaopca:block.tough@0"
            ]
        },
        {
            "x": -6,
            "y": -1,
            "z": 12,
            "elements": [
                "mekanism:reinforcedplasticblock@8"
            ]
        },
        {
            "x": 7,
            "y": 6,
            "z": 3,
            "elements": [
                "additions:durasteel_block@0"
            ]
        },
        {
            "x": -6,
            "y": 1,
            "z": 12,
            "elements": [
                "minecraft:water@0"
            ]
        },
        {
            "x": -6,
            "y": 4,
            "z": 13,
            "elements": [
                "minecraft:water@0"
            ]
        },
        {
            "x": 6,
            "y": 1,
            "z": 2,
            "elements": [
                "minecraft:water@0"
            ]
        },
        {
            "x": 6,
            "y": 1,
            "z": 9,
            "elements": [
                "prefab:block_half_glass_slab@0"
            ]
        },
        {
            "x": -7,
            "y": 3,
            "z": 12,
            "elements": [
                "minecraft:water@0"
            ]
        },
        {
            "x": 6,
            "y": -1,
            "z": -1,
            "elements": [
                "mekanism:reinforcedplasticblock@8"
            ]
        },
        {
            "x": -7,
            "y": 0,
            "z": 1,
            "elements": [
                "minecraft:water@0"
            ]
        },
        {
            "x": 8,
            "y": -1,
            "z": 2,
            "elements": [
                "mekanism:reinforcedplasticblock@8"
            ]
        },
        {
            "x": -7,
            "y": 4,
            "z": 6,
            "elements": [
                "mekanism:reinforcedplasticblock@7"
            ]
        },
        {
            "x": -8,
            "y": 5,
            "z": 12,
            "elements": [
                "plustic:osgloglasblock@0"
            ]
        },
        {
            "x": -4,
            "y": 2,
            "z": 1,
            "elements": [
                "mekanism:reinforcedplasticblock@8"
            ]
        },
        {
            "x": -4,
            "y": -1,
            "z": 14,
            "elements": [
                "mekanism:reinforcedplasticblock@8"
            ]
