{
    "registryname": "elysia_alloyer",
    "localizedname": "§cELYSIA单元 - 大型合金单元",
    "requires-blueprint": false,
    "failure-action": "still",
    "color": "372c16",
    "modifiers": [
        {
            "elements": "modularmachinery:blockcasing@1",
            "x": -1,
            "y": 0,
            "z": 0,
            "description": "将控制器右方紧挨着的方块换成此方块以降低配方制作时间至75%！",
            "modifier": {
                "io": "input",
                "target": "duration",
                "operation": 1,
                "multiplier": 0.75
            }
        },
        {
            "elements": "modularmachinery:blockcasing@2",
            "x": -1,
            "y": 0,
            "z": 0,
            "description": "将控制器右方紧挨着的方块换成此方块以降低配方制作时间至66%！",
            "modifier": {
                "io": "input",
                "target": "duration",
                "operation": 1,
                "multiplier": 0.66
            }
        },
        {
            "elements": "modularmachinery:blockcasing@3",
            "x": -1,
            "y": 0,
            "z": 0,
            "description": "将控制器右方紧挨着的方块换成此方块以降低配方制作时间至50%！",
            "modifier": {
                "io": "input",
                "target": "duration",
                "operation": 1,
                "multiplier": 0.5
            }
        },
        {
            "elements": "modularmachinery:blockcasing@5",
            "x": -1,
            "y": 0,
            "z": 0,
            "description": "将控制器右方紧挨着的方块换成此方块以降低配方制作时间至33%！",
            "modifier": {
                "io": "input",
                "target": "duration",
                "operation": 1,
                "multiplier": 0.33
            }
        }
    ],
    "parts": [
        {
            "x": 0,
            "y": 0,
            "z": 0,
            "elements": [
                "modularmachinery:blockcontroller@2"
            ]
        },
        {
            "x": -3,
            "y": -2,
            "z": 5,
            "elements": [
                "minecraft:gold_block@0"
            ]
        },
        {
            "x": 0,
            "y": -2,
            "z": 0,
            "elements": [
                "tcomplement:scorched_block@10"
            ]
        },
        {
            "x": 4,
            "y": -1,
            "z": 17,
            "elements": [
                "tcomplement:scorched_block@10"
            ]
        },
        {
            "x": 6,
            "y": 4,
            "z": 7,
            "elements": [
                "forestry:fences.vanilla.fireproof.0@0"
            ]
        },
        {
            "x": -4,
            "y": -2,
            "z": 10,
            "elements": [
                "minecraft:lava@0"
            ]
        },
        {
            "x": -1,
            "y": 0,
            "z": 19,
            "elements": [
                "casings_all"
            ]
        },
        {
            "x": -9,
            "y": 4,
            "z": 1,
            "elements": [
                "thermalfoundation:fluid_pyrotheum@0"
            ]
        },
        {
            "x": 5,
            "y": -2,
            "z": 1,
            "elements": [
                "enderio:block_alloy@0"
            ]
        },
        {
            "x": 6,
            "y": 5,
            "z": 7,
            "elements": [
                "chisel:blockiron@1"
            ]
        },
        {
            "x": -5,
            "y": 2,
            "z": 10,
            "elements": [
                "tconstruct:slime_congealed@0"
            ]
        },
        {
            "x": -8,
            "y": -3,
            "z": 12,
            "elements": [
                "nuclearcraft:ingot_block@8"
            ]
        },
        {
            "x": 4,
            "y": -2,
            "z": 17,
            "elements": [
                "tconstruct:metal@5"
            ]
        },
        {
            "x": -6,
            "y": 2,
            "z": 15,
            "elements": [
                "tconstruct:slime_congealed@0"
            ]
        },
        {
            "x": -8,
            "y": -2,
            "z": 12,
            "elements": [
                "enderio:block_alloy@6"
            ]
        },
        {
            "x": -8,
            "y": -3,
            "z": 16,
            "elements": [
                "nuclearcraft:ingot_block@8"
            ]
        },
        {
            "x": -9,
            "y": -2,
            "z": 15,
            "elements": [
                "enderio:block_alloy@0"
            ]
        },
        {
            "x": -10,
            "y": -1,
            "z": 11,
            "elements": [
                "tcomplement:scorched_block@10"
            ]
        },
        {
            "x": 6,
            "y": 2,
            "z": 7,
            "elements": [
                "tconstruct:slime_congealed@0"
            ]
        },
        {
            "x": -2,
            "y": 2,
            "z": 5,
            "elements": [
                "tconstruct:slime_congealed@0"
            ]
        },
        {
            "x": 5,
            "y": 0,
            "z": 17,
            "elements": [
                "divinerpg:netherite_block@0"
            ]
        },
        {
            "x": -7,
            "y": -3,
            "z": 4,
            "elements": [
                "nuclearcraft:ingot_block@8"
            ]
        },
        {
            "x": -7,
            "y": -3,
            "z": 11,
            "elements": [
                "nuclearcraft:ingot_block@8"
            ]
        },
        {
            "x": 2,
            "y": 0,
            "z": 0,
            "elements": [
                "casings_all"
            ]
        },
        {
            "x": -1,
            "y": -2,
            "z": 5,
            "elements": [
                "minecraft:lava@0"
            ]
        },
        {
            "x": -2,
            "y": -2,
            "z": 0,
            "elements": [
                "tcomplement:scorched_block@10"
            ]
        },
        {
            "x": 3,
            "y": 3,
            "z": 4,
            "elements": [
                "forestry:slabs.vanilla.fireproof.0@0"
            ]
        },
        {
            "x": 7,
            "y": -3,
            "z": 17,
            "elements": [
                "nuclearcraft:ingot_block@8"
            ]
        },
        {
            "x": -2,
            "y": -2,
            "z": 10,
            "elements": [
                "minecraft:lava@0"
            ]
        },
        {
            "x": -7,
            "y": 2,
            "z": 10,
            "elements": [
                "tconstruct:slime_congealed@0"
            ]
        },
        {
            "x": -3,
            "y": 3,
            "z": 11,
            "elements": [
                "forestry:slabs.vanilla.fireproof.0@0"
            ]
        },
        {
            "x": -1,
            "y": -3,
            "z": 11,
            "elements": [
                "nuclearcraft:ingot_block@8"
            ]
        },
        {
            "x": 6,
            "y": 1,
            "z": 1,
            "elements": [
                "thermalfoundation:glass_alloy@6"
            ]
        },
        {
            "x": 0,
            "y": 2,
            "z": 5,
            "elements": [
                "tconstruct:slime_congealed@0"
            ]
        },
        {
            "x": -2,
            "y": -3,
            "z": 16,
            "elements": [
                "nuclearcraft:ingot_block@8"
            ]
        },
        {
            "x": -7,
            "y": -2,
            "z": 15,
            "elements": [
                "tconstruct:metal@5"
            ]
        },
        {
            "x": 7,
            "y": -2,
            "z": 18,
            "elements": [
                "enderio:block_alloy@0"
            ]
        },
        {
            "x": -9,
            "y": 0,
            "z": 1,
            "elements": [
                "minecraft:magma@0"
            ]
        },
        {
            "x": -7,
            "y": -2,
            "z": 1,
            "elements": [
                "enderio:block_alloy@0"
            ]
        },
        {
            "x": 5,
            "y": 1,
            "z": 18,
            "elements": [
                "thermalfoundation:glass_alloy@6"
            ]
        },
        {
            "x": -10,
            "y": -1,
            "z": 4,
            "elements": [
                "tcomplement:scorched_block@10"
            ]
        },
        {
            "x": 4,
            "y": 0,
            "z": 0,
            "elements": [
                "casings_all"
            ]
        },
        {
            "x": -6,
            "y": -2,
            "z": 3,
            "elements": [
                "tconstruct:metal@5"
            ]
        },
        {
            "x": 1,
            "y": -2,
            "z": 5,
            "elements": [
                "minecraft:lava@0"
            ]
        },
        {
            "x": -5,
            "y": -1,
            "z": 19,
            "elements": [
                "tcomplement:scorched_block@10"
            ]
        },
        {
            "x": -3,
            "y": 3,
            "z": 4,
            "elements": [
                "forestry:slabs.vanilla.fireproof.0@0"
            ]
        },
        {
            "x": -8,
            "y": -2,
            "z": 10,
            "elements": [
                "enderio:block_alloy@6"
            ]
        },
        {
            "x": 8,
            "y": 1,
            "z": 17,
            "elements": [
                "thermalfoundation:glass_alloy@6"
            ]
        },
        {
            "x": -10,
            "y": 0,
            "z": 10,
            "elements": [
                "casings_parallel"
            ]
        },
        {
            "x": 5,
            "y": -2,
            "z": 7,
            "elements": [
                "minecraft:lava@0"
            ]
        },
        {
            "x": -4,
            "y": 3,
            "z": 16,
            "elements": [
                "forestry:slabs.vanilla.fireproof.0@0"
            ]
        },
        {
            "x": 4,
            "y": -3,
            "z": 16,
            "elements": [
                "nuclearcraft:ingot_block@8"
            ]
        },
        {
            "x": -5,
            "y": 3,
            "z": 11,
            "elements": [
                "forestry:slabs.vanilla.fireproof.0@0"
            ]
        },
        {
            "x": -8,
            "y": 0,
            "z": 3,
            "elements": [
                "divinerpg:netherite_block@0"
            ]
        },
        {
            "x": 3,
            "y": 3,
            "z": 7,
            "elements": [
                "forestry:slabs.vanilla.fireproof.0@0"
            ]
        },
        {
            "x": -3,
            "y": -3,
            "z": 11,
            "elements": [
                "nuclearcraft:ingot_block@8"
            ]
        },
        {
            "x": -1,
            "y": 4,
            "z": 12,
            "elements": [
                "forestry:fences.vanilla.fireproof.0@0"
            ]
        },
        {
            "x": -2,
            "y": 3,
            "z": 9,
            "elements": [
                "forestry:slabs.vanilla.fireproof.0@0"
            ]
        },
        {
            "x": -4,
            "y": -3,
            "z": -3,
            "elements": [
                "tcomplement:scorched_stairs_brick_small@2"
            ]
        },
        {
            "x": -9,
            "y": 0,
            "z": 15,
            "elements": [
                "minecraft:magma@0"
            ]
        },
        {
            "x": 2,
            "y": 2,
            "z": 5,
            "elements": [
                "tconstruct:slime_congealed@0"
            ]
        },
        {
            "x": 3,
            "y": 2,
            "z": 3,
            "elements": [
                "tconstruct:slime_congealed@0"
            ]
        },
        {
            "x": -1,
            "y": 5,
            "z": 12,
            "elements": [
                "chisel:blockiron@1"
            ]
        },
        {
            "x": 0,
            "y": -3,
            "z": 9,
            "elements": [
                "nuclearcraft:ingot_block@8"
            ]
        },
        {
            "x": 2,
            "y": 3,
            "z": 12,
            "elements": [
                "forestry:slabs.vanilla.fireproof.0@0"
            ]
        },
        {
            "x": 5,
            "y": -3,
            "z": 4,
            "elements": [
                "nuclearcraft:ingot_block@8"
            ]
        },
        {
            "x": -2,
            "y": 0,
            "z": 0,
            "elements": [
                "casings_all"
            ]
        },
        {
            "x": -7,
            "y": 1,
            "z": 19,
            "elements": [
                "tcomplement:scorched_block@10"
            ]
        },
        {
            "x": -5,
            "y": -2,
            "z": 5,
            "elements": [
                "tconstruct:metal@5"
            ]
        },
        {
            "x": 5,
            "y": 0,
            "z": 19,
            "elements": [
                "casings_all"
            ]
        },
        {
            "x": 0,
            "y": 4,
            "z": 7,
            "elements": [
                "forestry:fences.vanilla.fireproof.0@0"
            ]
        },
        {
            "x": -2,
            "y": 3,
            "z": 16,
            "elements": [
                "forestry:slabs.vanilla.fireproof.0@0"
            ]
        },
        {
            "x": -3,
            "y": 2,
            "z": 10,
            "elements": [
                "tconstruct:slime_congealed@0"
            ]
        },
        {
            "x": 0,
            "y": 5,
            "z": 7,
            "elements": [
                "chisel:blockiron@1"
            ]
        },
        {
            "x": 4,
            "y": -2,
            "z": 12,
            "elements": [
                "minecraft:lava@0"
            ]
        },
        {
            "x": 2,
            "y": -2,
            "z": 10,
            "elements": [
                "minecraft:lava@0"
            ]
        },
        {
            "x": 8,
            "y": -2,
            "z": 3,
            "elements": [
                "enderio:block_alloy@0"
            ]
        },
        {
            "x": -1,
            "y": 2,
            "z": 12,
            "elements": [
                "tconstruct:slime_congealed@0"
            ]
        },
        {
            "x": -3,
            "y": -2,
            "z": 15,
            "elements": [
                "minecraft:lava@0"
            ]
        },
        {
            "x": -5,
            "y": -3,
            "z": 11,
            "elements": [
                "nuclearcraft:ingot_block@8"
            ]
        },
        {
            "x": 3,
            "y": 2,
            "z": 6,
            "elements": [
                "tconstruct:slime_congealed@0"
            ]
        },
        {
            "x": 5,
            "y": -3,
            "z": 7,
            "elements": [
                "nuclearcraft:ingot_block@8"
            ]
        },
        {
            "x": 4,
            "y": -3,
            "z": 12,
            "elements": [
                "nuclearcraft:ingot_block@8"
            ]
        },
        {
            "x": 9,
            "y": -1,
            "z": 9,
            "elements": [
                "tcomplement:scorched_block@10"
            ]
        },
        {
            "x": 0,
            "y": 2,
            "z": 7,
            "elements": [
                "tconstruct:slime_congealed@0"
            ]
        },
        {
            "x": 4,
            "y": 3,
            "z": 9,
            "elements": [
                "forestry:slabs.vanilla.fireproof.0@0"
            ]
        },
        {
            "x": -4,
            "y": 2,
            "z": 5,
            "elements": [
                "tconstruct:slime_congealed@0"
            ]
        },
        {
            "x": 8,
            "y": 5,
            "z": 17,
            "elements": [
                "tcomplement:scorched_block@10"
            ]
        },
        {
            "x": -6,
            "y": 1,
            "z": 1,
            "elements": [
                "thermalfoundation:glass_alloy@6"
            ]
        },
        {
            "x": 6,
            "y": -3,
            "z": 9,
            "elements": [
                "nuclearcraft:ingot_block@8"
            ]
        },
        {
            "x": 1,
            "y": -1,
            "z": 19,
            "elements": [
                "tcomplement:scorched_block@10"
            ]
        },
        {
            "x": -1,
            "y": 1,
            "z": 19,
            "elements": [
                "tcomplement:scorched_block@10"
            ]
        },
        {
            "x": 5,
            "y": -3,
            "z": 8,
            "elements": [
                "nuclearcraft:ingot_block@8"
            ]
        },
        {
            "x": 5,
            "y": 2,
            "z": 12,
            "elements": [
                "tconstruct:slime_congealed@0"
            ]
        },
        {
            "x": 8,
            "y": 0,
            "z": 0,
            "elements": [
                "enderio:block_alloy@2"
            ]
        },
        {
            "x": -7,
            "y": 3,
            "z": 4,
            "elements": [
                "forestry:slabs.vanilla.fireproof.0@0"
            ]
        },
        {
            "x": 4,
            "y": -3,
            "z": 13,
            "elements": [
                "nuclearcraft:ingot_block@8"
            ]
        },
        {
            "x": 5,
            "y": -2,
            "z": 5,
            "elements": [
                "minecraft:gold_block@0"
            ]
        },
        {
            "x": 0,
            "y": -3,
            "z": 16,
            "elements": [
                "nuclearcraft:ingot_block@8"
            ]
        },
        {
            "x": 6,
            "y": -2,
            "z": 3,
            "elements": [
                "tconstruct:metal@5"
            ]
        },
        {
            "x": 5,
            "y": -2,
            "z": 8,
            "elements": [
                "minecraft:lava@0"
            ]
        },
        {
            "x": 3,
            "y": 2,
            "z": 10,
            "elements": [
                "tconstruct:slime_congealed@0"
            ]
        },
        {
            "x": 6,
            "y": 3,
            "z": 13,
            "elements": [
                "forestry:slabs.vanilla.fireproof.0@0"
            ]
        },
        {
            "x": 4,
            "y": -2,
            "z": 13,
            "elements": [
                "minecraft:gold_block@0"
            ]
        },
        {
            "x": 0,
            "y": 2,
            "z": 8,
            "elements": [
                "tconstruct:slime_congealed@0"
            ]
        },
        {
            "x": 8,
            "y": 1,
            "z": 14,
            "elements": [
                "thermalfoundation:glass_alloy@6"
            ]
        },
        {
            "x": 0,
            "y": 3,
            "z": 8,
            "elements": [
                "forestry:slabs.vanilla.fireproof.0@0"
            ]
        },
        {
            "x": 6,
            "y": 2,
            "z": 5,
            "elements": [
                "tconstruct:slime_congealed@0"
            ]
        },
        {
            "x": 7,
            "y": -1,
            "z": 12,
            "elements": [
                "enderio:block_alloy@6"
            ]
        },
        {
            "x": -1,
            "y": -2,
            "z": 8,
            "elements": [
                "minecraft:lava@0"
            ]
        },
        {
            "x": 1,
            "y": -3,
            "z": 4,
            "elements": [
                "nuclearcraft:ingot_block@8"
            ]
        },
        {
            "x": -1,
            "y": 0,
            "z": 18,
            "elements": [
                "minecraft:magma@0"
            ]
        },
        {
            "x": 5,
            "y": 1,
            "z": 19,
            "elements": [
                "tcomplement:scorched_block@10"
            ]
        },
        {
            "x": -4,
            "y": -3,
            "z": 9,
            "elements": [
                "nuclearcraft:ingot_block@8"
            ]
        },
        {
            "x": -1,
            "y": -3,
            "z": 8,
            "elements": [
                "nuclearcraft:ingot_block@8"
            ]
        },
        {
            "x": -6,
            "y": 3,
            "z": 9,
            "elements": [
                "forestry:slabs.vanilla.fireproof.0@0"
            ]
        },
        {
            "x": 1,
            "y": -2,
            "z": 18,
            "elements": [
                "enderio:block_alloy@0"
            ]
        },
        {
            "x": 7,
            "y": -1,
            "z": 19,
            "elements": [
                "tcomplement:scorched_block@10"
            ]
        },
        {
            "x": -1,
            "y": 1,
            "z": 18,
            "elements": [
                "thermalfoundation:glass_alloy@6"
            ]
        },
        {
            "x": -6,
            "y": -3,
            "z": 9,
            "elements": [
                "nuclearcraft:ingot_block@8"
            ]
        },
        {
            "x": 5,
            "y": 2,
            "z": 13,
            "elements": [
                "tconstruct:slime_congealed@0"
            ]
        },
        {
            "x": -5,
            "y": 3,
            "z": 4,
            "elements": [
                "forestry:slabs.vanilla.fireproof.0@0"
            ]
        },
        {
            "x": 7,
            "y": -2,
            "z": 5,
            "elements": [
                "tconstruct:metal@5"
            ]
        },
        {
            "x": 6,
            "y": -2,
            "z": 10,
            "elements": [
                "minecraft:lava@0"
            ]
        },
        {
            "x": -5,
            "y": 2,
            "z": 3,
            "elements": [
                "tconstruct:slime_congealed@0"
            ]
        },
        {
            "x": 6,
            "y": 2,
            "z": 8,
            "elements": [
                "tconstruct:slime_congealed@0"
            ]
        },
        {
            "x": -4,
            "y": -2,
            "z": 3,
            "elements": [
                "tconstruct:metal@5"
            ]
        },
        {
            "x": 9,
            "y": 0,
            "z": 8,
            "elements": [
                "casings_all"
            ]
        },
        {
            "x": 1,
            "y": 2,
            "z": 10,
            "elements": [
                "tconstruct:slime_congealed@0"
            ]
        },
        {
            "x": 5,
            "y": 4,
            "z": 12,
            "elements": [
                "forestry:fences.vanilla.fireproof.0@0"
            ]
        },
        {
            "x": -7,
            "y": -2,
            "z": 8,
            "elements": [
                "minecraft:lava@0"
            ]
        },
        {
            "x": 1,
            "y": -2,
            "z": 15,
            "elements": [
                "tconstruct:metal@5"
            ]
        },
        {
            "x": 6,
            "y": 3,
            "z": 6,
            "elements": [
                "forestry:slabs.vanilla.fireproof.0@0"
            ]
        },
        {
            "x": -2,
            "y": -3,
            "z": -3,
            "elements": [
                "tcomplement:scorched_stairs_brick_small@2"
            ]
        },
        {
            "x": 1,
            "y": 2,
            "z": 3,
            "elements": [
                "tconstruct:slime_congealed@0"
            ]
        },
        {
            "x": 8,
            "y": -2,
            "z": 6,
            "elements": [
                "enderio:block_alloy@0"
            ]
        },
        {
            "x": 8,
            "y": 3,
            "z": 19,
            "elements": [
                "tcomplement:scorched_block@10"
            ]
        },
        {
            "x": -1,
            "y": -3,
            "z": 4,
            "elements": [
                "nuclearcraft:ingot_block@8"
            ]
        },
        {
            "x": -7,
            "y": -3,
            "z": 8,
            "elements": [
                "nuclearcraft:ingot_block@8"
            ]
        },
        {
            "x": 6,
            "y": 3,
            "z": 8,
            "elements": [
                "forestry:slabs.vanilla.fireproof.0@0"
            ]
        },
        {
            "x": 5,
            "y": 5,
            "z": 12,
            "elements": [
                "chisel:blockiron@1"
            ]
        },
        {
            "x": -4,
            "y": 0,
            "z": 0,
            "elements": [
                "casings_all"
            ]
        },
        {
            "x": 8,
            "y": -2,
            "z": 13,
            "elements": [
                "enderio:block_alloy@0"
            ]
        },
        {
            "x": 8,
            "y": 0,
            "z": 13,
            "elements": [
                "minecraft:magma@0"
            ]
        },
        {
            "x": -8,
            "y": -3,
            "z": 9,
            "elements": [
                "nuclearcraft:ingot_block@8"
            ]
        },
        {
            "x": 8,
            "y": 2,
            "z": 18,
            "elements": [
                "thermalfoundation:fluid_pyrotheum@0"
            ]
        },
        {
            "x": 2,
            "y": -3,
            "z": -3,
            "elements": [
                "tcomplement:scorched_stairs_brick_small@2"
            ]
        },
        {
            "x": -3,
            "y": 2,
            "z": 3,
            "elements": [
                "tconstruct:slime_congealed@0"
            ]
        },
        {
            "x": 0,
            "y": -2,
            "z": 10,
            "elements": [
                "minecraft:lava@0"
            ]
        },
        {
            "x": 3,
            "y": 3,
            "z": 11,
            "elements": [
                "forestry:slabs.vanilla.fireproof.0@0"
            ]
        },
        {
            "x": 9,
            "y": 0,
            "z": 1,
            "elements": [
                "enderio:block_alloy@2"
            ]
        },
        {
            "x": -4,
            "y": 2,
            "z": 15,
            "elements": [
                "tconstruct:slime_congealed@0"
            ]
        },
        {
            "x": -9,
            "y": 1,
            "z": 16,
            "elements": [
                "thermalfoundation:glass_alloy@6"
            ]
        },
        {
            "x": 2,
            "y": -2,
            "z": 3,
            "elements": [
                "minecraft:gold_block@0"
            ]
        },
        {
            "x": 8,
            "y": 7,
            "z": 19,
            "elements": [
                "tcomplement:scorched_block@10"
            ]
        },
        {
            "x": 3,
            "y": 3,
            "z": 14,
            "elements": [
                "forestry:slabs.vanilla.fireproof.0@0"
            ]
        },
        {
            "x": 5,
            "y": -3,
            "z": 11,
            "elements": [
                "nuclearcraft:ingot_block@8"
            ]
        },
        {
            "x": -9,
            "y": 0,
            "z": 8,
            "elements": [
                "minecraft:magma@0"
            ]
        },
        {
            "x": -4,
            "y": -3,
            "z": 16,
            "elements": [
                "nuclearcraft:ingot_block@8"
            ]
        },
        {
            "x": -5,
            "y": -2,
            "z": 15,
            "elements": [
                "minecraft:lava@0"
            ]
        },
        {
            "x": 9,
            "y": 1,
            "z": 12,
            "elements": [
                "tcomplement:scorched_block@10"
            ]
        },
        {
            "x": -9,
            "y": 1,
            "z": 2,
            "elements": [
                "thermalfoundation:glass_alloy@6"
            ]
        },
        {
            "x": -6,
            "y": 2,
            "z": 5,
            "elements": [
                "tconstruct:slime_congealed@0"
            ]
        },
        {
            "x": 5,
            "y": 3,
            "z": 13,
            "elements": [
                "forestry:slabs.vanilla.fireproof.0@0"
            ]
        },
        {
            "x": -7,
            "y": -2,
            "z": 5,
            "elements": [
                "tconstruct:metal@5"
            ]
        },
        {
            "x": -3,
            "y": -3,
            "z": 4,
            "elements": [
                "nuclearcraft:ingot_block@8"
            ]
        },
        {
            "x": -1,
            "y": 3,
            "z": 4,
            "elements": [
                "forestry:slabs.vanilla.fireproof.0@0"
            ]
        },
        {
            "x": -9,
            "y": 0,
            "z": 5,
            "elements": [
                "minecraft:magma@0"
            ]
        },
        {
            "x": 5,
            "y": -2,
            "z": 14,
            "elements": [
                "tconstruct:metal@5"
            ]
        },
        {
            "x": -8,
            "y": 0,
            "z": 10,
            "elements": [
                "enderio:block_alloy@6"
            ]
        },
        {
            "x": -6,
            "y": -2,
            "z": 10,
            "elements": [
                "minecraft:lava@0"
            ]
        },
        {
            "x": -1,
            "y": 2,
            "z": 3,
            "elements": [
                "tconstruct:slime_congealed@0"
            ]
        },
        {
            "x": 0,
            "y": -3,
            "z": -3,
            "elements": [
                "tcomplement:scorched_stairs_brick_small@2"
            ]
        },
        {
            "x": 5,
            "y": -3,
            "z": 14,
            "elements": [
                "nuclearcraft:ingot_block@8"
            ]
        },
        {
            "x": 8,
            "y": 6,
            "z": 18,
            "elements": [
                "thermalfoundation:fluid_pyrotheum@0"
            ]
        },
        {
            "x": 9,
            "y": 4,
            "z": 1,
            "elements": [
                "tcomplement:scorched_block@10"
            ]
        },
        {
            "x": 1,
            "y": 3,
            "z": 11,
            "elements": [
                "forestry:slabs.vanilla.fireproof.0@0"
            ]
        },
        {
            "x": 2,
            "y": 2,
            "z": 15,
            "elements": [
                "tconstruct:slime_congealed@0"
            ]
        },
        {
            "x": 0,
            "y": -2,
            "z": 3,
            "elements": [
                "tconstruct:metal@5"
            ]
        },
        {
            "x": -4,
            "y": 3,
            "z": 9,
            "elements": [
                "forestry:slabs.vanilla.fireproof.0@0"
            ]
        },
        {
            "x": -7,
            "y": -2,
            "z": 2,
            "elements": [
                "tconstruct:metal@5"
            ]
        },
        {
            "x": 3,
            "y": -3,
            "z": 11,
            "elements": [
                "nuclearcraft:ingot_block@8"
            ]
        },
        {
            "x": -6,
            "y": -3,
            "z": 16,
            "elements": [
                "nuclearcraft:ingot_block@8"
            ]
        },
        {
            "x": -2,
            "y": -3,
            "z": 9,
            "elements": [
                "nuclearcraft:ingot_block@8"
            ]
        },
        {
            "x": 5,
            "y": 0,
            "z": 18,
            "elements": [
                "minecraft:magma@0"
            ]
        },
        {
            "x": 6,
            "y": 2,
            "z": 14,
            "elements": [
                "tconstruct:slime_congealed@0"
            ]
        },
        {
            "x": -7,
            "y": -1,
            "z": 2,
            "elements": [
                "tcomplement:scorched_block@10"
            ]
        },
        {
            "x": 3,
            "y": -3,
            "z": 4,
            "elements": [
                "nuclearcraft:ingot_block@8"
            ]
        },
        {
            "x": 1,
            "y": 3,
            "z": 4,
            "elements": [
                "forestry:slabs.vanilla.fireproof.0@0"
            ]
        },
        {
            "x": 0,
            "y": 2,
            "z": 16,
            "elements": [
                "tconstruct:slime_congealed@0"
            ]
        },
        {
            "x": -8,
            "y": 2,
            "z": 1,
            "elements": [
                "tcomplement:scorched_block@10"
            ]
        },
        {
            "x": -1,
            "y": -1,
            "z": 19,
            "elements": [
                "tcomplement:scorched_block@10"
            ]
        },
        {
            "x": 5,
            "y": -2,
            "z": 16,
            "elements": [
                "tconstruct:metal@5"
            ]
        },
        {
            "x": -10,
            "y": 6,
            "z": 18,
            "elements": [
                "tcomplement:scorched_block@10"
            ]
        },
        {
            "x": 0,
            "y": 3,
            "z": 16,
            "elements": [
                "forestry:slabs.vanilla.fireproof.0@0"
            ]
        },
        {
            "x": 7,
            "y": 0,
            "z": 4,
            "elements": [
                "divinerpg:netherite_block@0"
            ]
        },
        {
            "x": -3,
            "y": -3,
            "z": 17,
            "elements": [
                "nuclearcraft:ingot_block@8"
            ]
        },
        {
            "x": -4,
            "y": -2,
            "z": 13,
            "elements": [
                "minecraft:lava@0"
            ]
        },
        {
            "x": -1,
            "y": 3,
            "z": 7,
            "elements": [
                "forestry:slabs.vanilla.fireproof.0@0"
            ]
        },
        {
            "x": 5,
            "y": -2,
            "z": 15,
            "elements": [
                "tconstruct:metal@5"
            ]
        },
        {
            "x": 8,
            "y": 1,
            "z": 7,
            "elements": [
                "thermalfoundation:glass_alloy@6"
            ]
        },
        {
            "x": -1,
            "y": 3,
            "z": 14,
            "elements": [
                "forestry:slabs.vanilla.fireproof.0@0"
            ]
        },
        {
            "x": 7,
            "y": 4,
            "z": 1,
            "elements": [
                "tcomplement:scorched_block@10"
            ]
        },
        {
            "x": -7,
            "y": -2,
            "z": 18,
            "elements": [
                "enderio:block_alloy@0"
            ]
        },
        {
            "x": 8,
            "y": 0,
            "z": 6,
            "elements": [
                "minecraft:magma@0"
            ]
        },
        {
            "x": 5,
            "y": 2,
            "z": 6,
            "elements": [
                "tconstruct:slime_congealed@0"
            ]
        },
        {
            "x": -9,
            "y": -2,
            "z": 8,
            "elements": [
                "enderio:block_alloy@0"
            ]
        },
        {
            "x": 7,
            "y": 0,
            "z": 11,
            "elements": [
                "enderio:block_alloy@6"
            ]
        },
        {
            "x": -8,
            "y": -1,
            "z": 7,
            "elements": [
                "enderio:block_alloy@6"
            ]
        },
        {
            "x": -5,
            "y": -3,
            "z": 7,
            "elements": [
                "nuclearcraft:ingot_block@8"
            ]
        },
        {
            "x": 3,
            "y": 5,
            "z": 12,
            "elements": [
                "chisel:blockiron@1"
            ]
        },
        {
            "x": -5,
            "y": -1,
            "z": 2,
            "elements": [
                "tcomplement:scorched_block@10"
            ]
        },
        {
            "x": 6,
            "y": 3,
            "z": 12,
            "elements": [
                "forestry:slabs.vanilla.fireproof.0@0"
            ]
        },
        {
            "x": -4,
            "y": -3,
            "z": 2,
            "elements": [
                "nuclearcraft:ingot_block@8"
            ]
        },
        {
            "x": -3,
            "y": 1,
            "z": 19,
            "elements": [
                "tcomplement:scorched_block@10"
            ]
        },
        {
            "x": -9,
            "y": 0,
            "z": 18,
            "elements": [
                "minecraft:magma@0"
            ]
        },
        {
            "x": -9,
            "y": -2,
            "z": 1,
            "elements": [
                "enderio:block_alloy@0"
            ]
        },
        {
            "x": 6,
            "y": -2,
            "z": 11,
            "elements": [
                "minecraft:lava@0"
            ]
        },
        {
            "x": -3,
            "y": -1,
            "z": 19,
            "elements": [
                "tcomplement:scorched_block@10"
            ]
        },
        {
            "x": -10,
            "y": 2,
            "z": 1,
            "elements": [
                "tcomplement:scorched_block@10"
            ]
        },
        {
            "x": -3,
            "y": 2,
            "z": 13,
            "elements": [
                "tconstruct:slime_congealed@0"
            ]
        },
        {
            "x": -6,
            "y": 2,
            "z": 16,
            "elements": [
                "tconstruct:slime_congealed@0"
            ]
        },
        {
            "x": 6,
            "y": 3,
            "z": 15,
            "elements": [
                "forestry:slabs.vanilla.fireproof.0@0"
            ]
        },
        {
            "x": 7,
            "y": 0,
            "z": 1,
            "elements": [
                "minecraft:magma@0"
            ]
        },
        {
            "x": 5,
            "y": -2,
            "z": 9,
            "elements": [
                "minecraft:lava@0"
            ]
        },
        {
            "x": 9,
            "y": 0,
            "z": 15,
            "elements": [
                "casings_all"
            ]
        },
        {
            "x": -2,
            "y": 2,
            "z": 8,
            "elements": [
                "tconstruct:slime_congealed@0"
            ]
        },
        {
            "x": 6,
            "y": 2,
            "z": 15,
            "elements": [
                "tconstruct:slime_congealed@0"
            ]
        },
        {
            "x": -6,
            "y": 3,
            "z": 16,
            "elements": [
                "forestry:slabs.vanilla.fireproof.0@0"
            ]
        },
        {
            "x": 0,
            "y": 2,
            "z": 9,
            "elements": [
                "tconstruct:slime_congealed@0"
            ]
        },
        {
            "x": 1,
            "y": -3,
            "z": 14,
            "elements": [
                "nuclearcraft:ingot_block@8"
            ]
        },
        {
            "x": -2,
            "y": -1,
            "z": 17,
            "elements": [
                "tcomplement:scorched_block@10"
            ]
        },
        {
            "x": -4,
            "y": 5,
            "z": 7,
            "elements": [
                "chisel:blockiron@1"
            ]
        },
        {
            "x": 0,
            "y": 3,
            "z": 9,
            "elements": [
                "forestry:slabs.vanilla.fireproof.0@0"
            ]
        },
        {
            "x": -7,
            "y": 3,
            "z": 7,
            "elements": [
                "forestry:slabs.vanilla.fireproof.0@0"
            ]
        },
        {
            "x": -9,
            "y": -2,
            "z": 18,
            "elements": [
                "enderio:block_alloy@0"
            ]
        },
        {
            "x": 5,
            "y": -1,
            "z": 2,
            "elements": [
                "tcomplement:scorched_block@10"
            ]
        },
        {
            "x": -1,
            "y": 2,
            "z": 6,
            "elements": [
                "tconstruct:slime_congealed@0"
            ]
        },
        {
            "x": 0,
            "y": 3,
            "z": 12,
            "elements": [
                "forestry:slabs.vanilla.fireproof.0@0"
            ]
        },
        {
            "x": -9,
            "y": 5,
            "z": 2,
            "elements": [
                "tcomplement:scorched_block@10"
            ]
        },
        {
            "x": 1,
            "y": -3,
            "z": 7,
            "elements": [
                "nuclearcraft:ingot_block@8"
            ]
        },
        {
            "x": 2,
            "y": -2,
            "z": -2,
            "elements": [
                "tcomplement:scorched_stairs_brick_small@2"
            ]
        },
        {
            "x": 2,
            "y": -3,
            "z": 9,
            "elements": [
                "nuclearcraft:ingot_block@8"
            ]
        },
        {
            "x": -9,
            "y": 4,
            "z": 18,
            "elements": [
                "thermalfoundation:fluid_pyrotheum@0"
            ]
        },
        {
            "x": -3,
            "y": 5,
            "z": 12,
            "elements": [
                "chisel:blockiron@1"
            ]
        },
        {
            "x": 2,
            "y": -3,
            "z": 2,
            "elements": [
                "nuclearcraft:ingot_block@8"
            ]
        },
        {
            "x": -10,
            "y": 2,
            "z": 18,
            "elements": [
                "tcomplement:scorched_block@10"
            ]
        },
        {
            "x": 6,
            "y": -2,
            "z": 4,
            "elements": [
                "tconstruct:metal@5"
            ]
        },
        {
            "x": -7,
            "y": 0,
            "z": 18,
            "elements": [
                "minecraft:magma@0"
            ]
        },
        {
            "x": -1,
            "y": -2,
            "z": 9,
            "elements": [
                "minecraft:lava@0"
            ]
        },
        {
            "x": 3,
            "y": 2,
            "z": 13,
            "elements": [
                "tconstruct:slime_congealed@0"
            ]
        },
        {
            "x": -9,
            "y": 3,
            "z": 17,
            "elements": [
                "tcomplement:scorched_block@10"
            ]
        },
        {
            "x": 8,
            "y": 7,
            "z": 0,
            "elements": [
                "tcomplement:scorched_block@10"
            ]
        },
        {
            "x": -2,
            "y": -1,
            "z": -1,
            "elements": [
                "tcomplement:scorched_stairs_brick_small@0"
            ]
        },
        {
            "x": 1,
            "y": 0,
            "z": 1,
            "elements": [
                "minecraft:magma@0"
            ]
        },
        {
            "x": -8,
            "y": -1,
            "z": 17,
            "elements": [
                "tcomplement:scorched_block@10"
            ]
        },
        {
            "x": 7,
            "y": -3,
            "z": 14,
            "elements": [
                "nuclearcraft:ingot_block@8"
            ]
        },
        {
            "x": -4,
            "y": 2,
            "z": 8,
            "elements": [
                "tconstruct:slime_congealed@0"
            ]
        },
        {
            "x": -7,
            "y": -3,
            "z": 17,
            "elements": [
                "nuclearcraft:ingot_block@8"
            ]
        },
        {
            "x": 2,
            "y": 5,
            "z": 7,
            "elements": [
                "chisel:blockiron@1"
            ]
        },
        {
            "x": 6,
            "y": 3,
            "z": 10,
            "elements": [
                "forestry:slabs.vanilla.fireproof.0@0"
            ]
        },
        {
            "x": 8,
            "y": -2,
            "z": 10,
            "elements": [
                "enderio:block_alloy@0"
            ]
        },
        {
            "x": 2,
            "y": -3,
            "z": 12,
            "elements": [
                "nuclearcraft:ingot_block@8"
            ]
        },
        {
            "x": 7,
            "y": -3,
            "z": 7,
            "elements": [
                "nuclearcraft:ingot_block@8"
            ]
        },
        {
            "x": 8,
            "y": 5,
            "z": 0,
            "elements": [
                "tcomplement:scorched_block@10"
            ]
        },
        {
            "x": -5,
            "y": -2,
            "z": 8,
            "elements": [
                "minecraft:lava@0"
            ]
        },
        {
            "x": -10,
            "y": 1,
            "z": 7,
            "elements": [
                "tcomplement:scorched_block@10"
            ]
        },
        {
            "x": 0,
            "y": -2,
            "z": -2,
            "elements": [
                "tcomplement:scorched_stairs_brick_small@2"
            ]
        },
        {
            "x": -9,
            "y": 1,
            "z": 9,
            "elements": [
                "thermalfoundation:glass_alloy@6"
            ]
        },
        {
            "x": -1,
            "y": -1,
            "z": 2,
            "elements": [
                "tcomplement:scorched_block@10"
            ]
        },
        {
            "x": 0,
            "y": -3,
            "z": 2,
            "elements": [
                "nuclearcraft:ingot_block@8"
            ]
        },
        {
            "x": 8,
            "y": 3,
            "z": 0,
            "elements": [
                "tcomplement:scorched_block@10"
            ]
        },
        {
            "x": 3,
            "y": -2,
            "z": 1,
            "elements": [
                "enderio:block_alloy@0"
            ]
        },
        {
            "x": -1,
            "y": -2,
            "z": 16,
            "elements": [
                "tconstruct:metal@5"
            ]
        },
        {
            "x": -5,
            "y": 0,
            "z": 1,
            "elements": [
                "minecraft:magma@0"
            ]
        },
        {
            "x": 5,
            "y": -3,
            "z": 10,
            "elements": [
                "nuclearcraft:ingot_block@8"
            ]
        },
        {
            "x": -7,
            "y": -2,
            "z": 9,
            "elements": [
                "minecraft:lava@0"
            ]
        },
        {
            "x": -9,
            "y": 7,
            "z": 17,
            "elements": [
                "tcomplement:scorched_block@10"
            ]
        },
        {
            "x": 5,
            "y": 3,
            "z": 7,
            "elements": [
                "forestry:slabs.vanilla.fireproof.0@0"
            ]
        },
        {
            "x": 8,
            "y": 4,
            "z": 0,
            "elements": [
                "tcomplement:scorched_block@10"
            ]
        },
        {
            "x": -5,
            "y": -3,
            "z": 17,
            "elements": [
                "nuclearcraft:ingot_block@8"
            ]
        },
        {
            "x": 2,
            "y": -3,
            "z": 16,
            "elements": [
                "nuclearcraft:ingot_block@8"
            ]
        },
        {
            "x": -6,
            "y": 2,
            "z": 8,
            "elements": [
                "tconstruct:slime_congealed@0"
            ]
        },
        {
            "x": -8,
            "y": 6,
            "z": 1,
            "elements": [
                "tcomplement:scorched_block@10"
            ]
        },
        {
            "x": -10,
            "y": 1,
            "z": 17,
            "elements": [
                "tcomplement:scorched_block@10"
            ]
        },
        {
            "x": -6,
            "y": -1,
            "z": 17,
            "elements": [
                "tcomplement:scorched_block@10"
            ]
        },
        {
            "x": 2,
            "y": -2,
            "z": 13,
            "elements": [
                "minecraft:lava@0"
            ]
        },
        {
            "x": -5,
            "y": -2,
            "z": 18,
            "elements": [
                "enderio:block_alloy@0"
            ]
        },
        {
            "x": 5,
            "y": 3,
            "z": 14,
            "elements": [
                "forestry:slabs.vanilla.fireproof.0@0"
            ]
        },
        {
            "x": -2,
            "y": -2,
            "z": -2,
            "elements": [
                "tcomplement:scorched_stairs_brick_small@2"
            ]
        },
        {
            "x": 4,
            "y": -2,
            "z": 6,
            "elements": [
                "minecraft:lava@0"
            ]
        },
        {
            "x": -3,
            "y": -2,
            "z": 8,
            "elements": [
                "minecraft:lava@0"
            ]
        },
        {
            "x": 1,
            "y": -1,
            "z": 2,
            "elements": [
                "tcomplement:scorched_block@10"
            ]
        },
        {
            "x": -10,
            "y": 0,
            "z": 6,
            "elements": [
                "casings_all"
            ]
        },
        {
            "x": -8,
            "y": 0,
            "z": 0,
            "elements": [
                "casings_all"
            ]
        },
        {
            "x": 8,
            "y": 1,
            "z": 0,
            "elements": [
                "tcomplement:scorched_block@10"
            ]
        },
        {
            "x": -3,
            "y": 0,
            "z": 18,
            "elements": [
                "minecraft:magma@0"
            ]
        },
        {
            "x": -2,
            "y": -3,
            "z": 2,
            "elements": [
                "nuclearcraft:ingot_block@8"
            ]
        },
        {
            "x": 0,
            "y": 3,
            "z": 15,
            "elements": [
                "forestry:slabs.vanilla.fireproof.0@0"
            ]
        },
        {
            "x": -3,
            "y": 0,
            "z": 1,
            "elements": [
                "minecraft:magma@0"
            ]
        },
        {
            "x": -3,
            "y": -2,
            "z": 1,
            "elements": [
                "enderio:block_alloy@0"
            ]
        },
        {
            "x": -1,
            "y": 2,
            "z": 13,
            "elements": [
                "tconstruct:slime_congealed@0"
            ]
        },
        {
            "x": -9,
            "y": 1,
            "z": 19,
            "elements": [
                "tcomplement:scorched_block@10"
            ]
        },
        {
            "x": -1,
            "y": -3,
            "z": -1,
            "elements": [
                "tcomplement:scorched_block@10"
            ]
        },
        {
            "x": -9,
            "y": -1,
            "z": 19,
            "elements": [
                "tcomplement:scorched_block@10"
            ]
        },
        {
            "x": -5,
            "y": -3,
            "z": 14,
            "elements": [
                "nuclearcraft:ingot_block@8"
            ]
        },
        {
            "x": -8,
            "y": -1,
            "z": 14,
            "elements": [
                "tcomplement:scorched_block@10"
            ]
        },
        {
            "x": 5,
            "y": -3,
            "z": 15,
            "elements": [
                "nuclearcraft:ingot_block@8"
            ]
        },
        {
            "x": -2,
            "y": 5,
            "z": 7,
            "elements": [
                "chisel:blockiron@1"
            ]
        },
        {
            "x": 6,
            "y": -3,
            "z": 5,
            "elements": [
                "nuclearcraft:ingot_block@8"
            ]
        },
        {
            "x": 0,
            "y": 2,
            "z": 15,
            "elements": [
                "tconstruct:slime_congealed@0"
            ]
        },
        {
            "x": 0,
            "y": -3,
            "z": 12,
            "elements": [
                "nuclearcraft:ingot_block@8"
            ]
        },
        {
            "x": -1,
            "y": -2,
            "z": 15,
            "elements": [
                "minecraft:gold_block@0"
            ]
        },
        {
            "x": 2,
            "y": -2,
            "z": 6,
            "elements": [
                "minecraft:lava@0"
            ]
        },
        {
            "x": -3,
            "y": 2,
            "z": 6,
            "elements": [
                "tconstruct:slime_congealed@0"
            ]
        },
        {
            "x": 3,
            "y": -3,
            "z": 7,
            "elements": [
                "nuclearcraft:ingot_block@8"
            ]
        },
        {
            "x": -5,
            "y": 5,
            "z": 12,
            "elements": [
                "chisel:blockiron@1"
            ]
        },
        {
            "x": 3,
            "y": -1,
            "z": 2,
            "elements": [
                "tcomplement:scorched_block@10"
            ]
        },
        {
            "x": -2,
            "y": 3,
            "z": 12,
            "elements": [
                "forestry:slabs.vanilla.fireproof.0@0"
            ]
        },
        {
            "x": 0,
            "y": -1,
            "z": -1,
            "elements": [
                "tcomplement:scorched_stairs_brick_small@2"
            ]
        },
        {
            "x": -1,
            "y": 0,
            "z": 1,
            "elements": [
                "minecraft:magma@0"
            ]
        },
        {
            "x": 6,
            "y": -1,
            "z": 17,
            "elements": [
                "tcomplement:scorched_block@10"
            ]
        },
        {
            "x": -1,
            "y": -2,
            "z": 1,
            "elements": [
                "enderio:block_alloy@0"
            ]
        },
        {
            "x": 1,
            "y": -3,
            "z": -1,
            "elements": [
                "tcomplement:scorched_block@10"
            ]
        },
        {
            "x": -10,
            "y": -1,
            "z": 14,
            "elements": [
                "tcomplement:scorched_block@10"
            ]
        },
        {
            "x": -7,
            "y": -3,
            "z": 14,
            "elements": [
                "nuclearcraft:ingot_block@8"
            ]
        },
        {
            "x": -10,
            "y": 0,
            "z": 13,
            "elements": [
                "casings_all"
            ]
        },
        {
            "x": -7,
            "y": 3,
            "z": 14,
            "elements": [
                "forestry:slabs.vanilla.fireproof.0@0"
            ]
        },
        {
            "x": -6,
            "y": -3,
            "z": 12,
            "elements": [
                "nuclearcraft:ingot_block@8"
            ]
        },
        {
            "x": -2,
            "y": -2,
            "z": 13,
            "elements": [
                "minecraft:lava@0"
            ]
        },
        {
            "x": 1,
            "y": 3,
            "z": 7,
            "elements": [
                "forestry:slabs.vanilla.fireproof.0@0"
            ]
        },
        {
            "x": -8,
            "y": 3,
            "z": 12,
            "elements": [
                "enderio:block_alloy@6"
            ]
        },
        {
            "x": -10,
            "y": -1,
            "z": 7,
            "elements": [
                "tcomplement:scorched_block@10"
            ]
        },
        {
            "x": -6,
            "y": -3,
            "z": 5,
            "elements": [
                "nuclearcraft:ingot_block@8"
            ]
        },
        {
            "x": -3,
            "y": -1,
            "z": 2,
            "elements": [
                "tcomplement:scorched_block@10"
            ]
        },
        {
            "x": -7,
            "y": -3,
            "z": 7,
            "elements": [
                "nuclearcraft:ingot_block@8"
            ]
        },
        {
            "x": 1,
            "y": 0,
            "z": 18,
            "elements": [
                "minecraft:magma@0"
            ]
        },
        {
            "x": -8,
            "y": -2,
            "z": 6,
            "elements": [
                "tconstruct:metal@5"
            ]
        },
        {
            "x": -9,
            "y": -2,
            "z": 5,
            "elements": [
                "enderio:block_alloy@0"
            ]
        },
        {
            "x": -6,
            "y": -3,
            "z": 2,
            "elements": [
                "nuclearcraft:ingot_block@8"
            ]
        },
        {
            "x": -5,
            "y": 1,
            "z": 19,
            "elements": [
                "tcomplement:scorched_block@10"
            ]
        },
        {
            "x": 1,
            "y": -2,
            "z": 1,
            "elements": [
                "enderio:block_alloy@0"
            ]
        },
        {
            "x": -7,
            "y": 0,
            "z": 1,
            "elements": [
                "minecraft:magma@0"
            ]
        },
        {
            "x": -1,
            "y": -3,
            "z": 14,
            "elements": [
                "nuclearcraft:ingot_block@8"
            ]
        },
        {
            "x": -10,
            "y": 6,
            "z": 1,
            "elements": [
                "tcomplement:scorched_block@10"
            ]
        },
        {
            "x": 3,
            "y": -3,
            "z": -1,
            "elements": [
                "tcomplement:scorched_stairs_brick_small@1"
            ]
        },
        {
            "x": -8,
            "y": -2,
            "z": 13,
            "elements": [
                "tconstruct:metal@5"
            ]
        },
        {
            "x": 1,
            "y": -2,
            "z": 8,
            "elements": [
                "minecraft:lava@0"
            ]
        },
        {
            "x": -10,
            "y": 1,
            "z": 14,
            "elements": [
                "tcomplement:scorched_block@10"
            ]
        },
        {
            "x": -8,
            "y": 0,
            "z": 13,
            "elements": [
                "divinerpg:netherite_block@0"
            ]
        },
        {
            "x": -6,
            "y": 5,
            "z": 7,
            "elements": [
                "chisel:blockiron@1"
            ]
        },
        {
            "x": -4,
            "y": -3,
            "z": 12,
            "elements": [
                "nuclearcraft:ingot_block@8"
            ]
        },
        {
            "x": -5,
            "y": 2,
            "z": 13,
            "elements": [
                "tconstruct:slime_congealed@0"
            ]
        },
        {
            "x": 0,
            "y": -1,
            "z": 17,
            "elements": [
                "tcomplement:scorched_block@10"
            ]
        },
        {
            "x": 4,
            "y": 2,
            "z": 8,
            "elements": [
                "tconstruct:slime_congealed@0"
            ]
        },
        {
            "x": 7,
            "y": 0,
            "z": 8,
            "elements": [
                "enderio:block_alloy@6"
            ]
        },
        {
            "x": 1,
            "y": -3,
            "z": 17,
            "elements": [
                "nuclearcraft:ingot_block@8"
            ]
        },
        {
            "x": 6,
            "y": 2,
            "z": 9,
            "elements": [
                "tconstruct:slime_congealed@0"
            ]
        },
        {
            "x": -5,
            "y": 3,
            "z": 7,
            "elements": [
                "forestry:slabs.vanilla.fireproof.0@0"
            ]
        },
        {
            "x": -1,
            "y": -3,
            "z": 7,
            "elements": [
                "nuclearcraft:ingot_block@8"
            ]
        },
        {
            "x": -7,
            "y": 2,
            "z": 6,
            "elements": [
                "tconstruct:slime_congealed@0"
            ]
        },
        {
            "x": -6,
            "y": 3,
            "z": 12,
            "elements": [
                "forestry:slabs.vanilla.fireproof.0@0"
            ]
        },
        {
            "x": 6,
            "y": 3,
            "z": 9,
            "elements": [
                "forestry:slabs.vanilla.fireproof.0@0"
            ]
        },
        {
            "x": -2,
            "y": -2,
            "z": 6,
            "elements": [
                "minecraft:lava@0"
            ]
        },
        {
            "x": -5,
            "y": -2,
            "z": 1,
            "elements": [
                "enderio:block_alloy@0"
            ]
        },
        {
            "x": -5,
            "y": 0,
            "z": 18,
            "elements": [
                "minecraft:magma@0"
            ]
        },
        {
            "x": -9,
            "y": 5,
            "z": 19,
            "elements": [
                "tcomplement:scorched_block@10"
            ]
        },
        {
            "x": -8,
            "y": 2,
            "z": 18,
            "elements": [
                "tcomplement:scorched_block@10"
            ]
        },
        {
            "x": -3,
            "y": -2,
            "z": 18,
            "elements": [
                "enderio:block_alloy@0"
            ]
        },
        {
            "x": -7,
            "y": -1,
            "z": 19,
            "elements": [
                "tcomplement:scorched_block@10"
            ]
        },
        {
            "x": -8,
            "y": 6,
            "z": 18,
            "elements": [
                "tcomplement:scorched_block@10"
            ]
        },
        {
            "x": 6,
            "y": 3,
            "z": 16,
            "elements": [
                "forestry:slabs.vanilla.fireproof.0@0"
            ]
        },
        {
            "x": 9,
            "y": 1,
            "z": 16,
            "elements": [
                "tcomplement:scorched_block@10"
            ]
        },
        {
            "x": 3,
            "y": -2,
            "z": 5,
            "elements": [
                "minecraft:lava@0"
            ]
        },
        {
            "x": 3,
            "y": 0,
            "z": 1,
            "elements": [
                "minecraft:magma@0"
            ]
        },
        {
            "x": 3,
            "y": -2,
            "z": 8,
            "elements": [
                "minecraft:lava@0"
            ]
        },
        {
            "x": 7,
            "y": 0,
            "z": 5,
            "elements": [
                "divinerpg:netherite_block@0"
            ]
        },
        {
            "x": -3,
            "y": -3,
            "z": -1,
            "elements": [
                "tcomplement:scorched_block@10"
            ]
        },
        {
            "x": -3,
            "y": 3,
            "z": 7,
            "elements": [
                "forestry:slabs.vanilla.fireproof.0@0"
            ]
        },
        {
            "x": -6,
            "y": -2,
            "z": 13,
            "elements": [
                "minecraft:lava@0"
            ]
        },
        {
            "x": -7,
            "y": 2,
            "z": 13,
            "elements": [
                "tconstruct:slime_congealed@0"
            ]
        },
        {
            "x": -2,
            "y": -3,
            "z": 12,
            "elements": [
                "nuclearcraft:ingot_block@8"
            ]
        },
        {
            "x": 2,
            "y": 2,
            "z": 8,
            "elements": [
                "tconstruct:slime_congealed@0"
            ]
        },
        {
            "x": 3,
            "y": -3,
            "z": 17,
            "elements": [
                "nuclearcraft:ingot_block@8"
            ]
        },
        {
            "x": 6,
            "y": 2,
            "z": 16,
            "elements": [
                "tconstruct:slime_congealed@0"
            ]
        },
        {
            "x": -3,
            "y": 3,
            "z": 14,
            "elements": [
                "forestry:slabs.vanilla.fireproof.0@0"
            ]
        },
        {
            "x": 9,
            "y": 1,
            "z": 2,
            "elements": [
                "tcomplement:scorched_block@10"
            ]
        },
        {
            "x": -9,
            "y": 1,
            "z": 12,
            "elements": [
                "thermalfoundation:glass_alloy@6"
            ]
        },
        {
            "x": 9,
            "y": -1,
            "z": 2,
            "elements": [
                "tcomplement:scorched_block@10"
            ]
        },
        {
            "x": -3,
            "y": -3,
            "z": 7,
            "elements": [
                "nuclearcraft:ingot_block@8"
            ]
        },
        {
            "x": -4,
            "y": 3,
            "z": 12,
            "elements": [
                "forestry:slabs.vanilla.fireproof.0@0"
            ]
        },
        {
            "x": 4,
            "y": 2,
            "z": 5,
            "elements": [
                "tconstruct:slime_congealed@0"
            ]
        },
        {
            "x": -5,
            "y": 2,
            "z": 6,
            "elements": [
                "tconstruct:slime_congealed@0"
            ]
        },
        {
            "x": 9,
            "y": 1,
            "z": 9,
            "elements": [
                "tcomplement:scorched_block@10"
            ]
        },
        {
            "x": -7,
            "y": 5,
            "z": 12,
            "elements": [
                "chisel:blockiron@1"
            ]
        },
        {
            "x": -4,
            "y": -2,
            "z": 6,
            "elements": [
                "minecraft:lava@0"
            ]
        },
        {
            "x": 6,
            "y": -3,
            "z": 2,
            "elements": [
                "nuclearcraft:ingot_block@8"
            ]
        },
        {
            "x": 1,
            "y": 3,
            "z": 5,
            "elements": [
                "forestry:slabs.vanilla.fireproof.0@0"
            ]
        },
        {
            "x": 3,
            "y": -2,
            "z": 18,
            "elements": [
                "enderio:block_alloy@0"
            ]
        },
        {
            "x": 7,
            "y": 4,
            "z": 18,
            "elements": [
                "tcomplement:scorched_block@10"
            ]
        },
        {
            "x": 3,
            "y": -2,
            "z": 14,
            "elements": [
                "minecraft:gold_block@0"
            ]
        },
        {
            "x": 5,
            "y": 0,
            "z": 1,
            "elements": [
                "minecraft:magma@0"
            ]
        },
        {
            "x": -5,
            "y": 3,
            "z": 10,
            "elements": [
                "forestry:slabs.vanilla.fireproof.0@0"
            ]
        },
        {
            "x": 3,
            "y": -2,
            "z": 9,
            "elements": [
                "minecraft:lava@0"
            ]
        },
        {
            "x": -2,
            "y": 3,
            "z": 13,
            "elements": [
                "forestry:slabs.vanilla.fireproof.0@0"
            ]
        },
        {
            "x": 0,
            "y": -1,
            "z": 0,
            "elements": [
                "tcomplement:scorched_block@10"
            ]
        },
        {
            "x": 1,
            "y": -3,
            "z": 0,
            "elements": [
                "tcomplement:scorched_block@10"
            ]
        },
        {
            "x": 6,
            "y": -2,
            "z": 18,
            "elements": [
                "enderio:block_alloy@0"
            ]
        },
        {
            "x": -3,
            "y": -3,
            "z": 15,
            "elements": [
                "nuclearcraft:ingot_block@8"
            ]
        },
        {
            "x": -5,
            "y": -3,
            "z": 10,
            "elements": [
                "nuclearcraft:ingot_block@8"
            ]
        },
        {
            "x": -5,
            "y": 3,
            "z": 5,
            "elements": [
                "forestry:slabs.vanilla.fireproof.0@0"
            ]
        },
        {
            "x": 8,
            "y": 1,
            "z": 1,
            "elements": [
                "thermalfoundation:fluid_pyrotheum@0"
            ]
        },
        {
            "x": 7,
            "y": 2,
            "z": 18,
            "elements": [
                "tcomplement:scorched_block@10"
            ]
        },
        {
            "x": -2,
            "y": 1,
            "z": 0,
            "elements": [
                "tcomplement:scorched_block@10"
            ]
        },
        {
            "x": 4,
            "y": 2,
            "z": 13,
            "elements": [
                "tconstruct:slime_congealed@0"
            ]
        },
        {
            "x": -7,
            "y": -2,
            "z": 4,
            "elements": [
                "tconstruct:metal@5"
            ]
        },
        {
            "x": -3,
            "y": -3,
            "z": 6,
            "elements": [
                "nuclearcraft:ingot_block@8"
            ]
        },
        {
            "x": -6,
            "y": -2,
            "z": 6,
            "elements": [
                "minecraft:gold_block@0"
            ]
        },
        {
            "x": -1,
            "y": -3,
            "z": 5,
            "elements": [
                "nuclearcraft:ingot_block@8"
            ]
        },
        {
            "x": 6,
            "y": 3,
            "z": 3,
            "elements": [
                "forestry:slabs.vanilla.fireproof.0@0"
            ]
        },
        {
            "x": 9,
            "y": -1,
            "z": 18,
            "elements": [
                "tcomplement:scorched_block@10"
            ]
        },
        {
            "x": 7,
            "y": 1,
            "z": 18,
            "elements": [
                "thermalfoundation:glass_alloy@6"
            ]
        },
        {
            "x": -7,
            "y": 3,
            "z": 10,
            "elements": [
                "forestry:slabs.vanilla.fireproof.0@0"
            ]
        },
        {
            "x": 7,
            "y": 0,
            "z": 18,
            "elements": [
                "minecraft:magma@0"
            ]
        },
        {
            "x": -3,
            "y": 2,
            "z": 11,
            "elements": [
                "tconstruct:slime_congealed@0"
            ]
        },
        {
            "x": 6,
            "y": -3,
            "z": 13,
            "elements": [
                "nuclearcraft:ingot_block@8"
            ]
        },
        {
            "x": -7,
            "y": -3,
            "z": 10,
            "elements": [
                "nuclearcraft:ingot_block@8"
            ]
        },
        {
            "x": -2,
            "y": -1,
            "z": 0,
            "elements": [
                "tcomplement:scorched_block@10"
            ]
        },
        {
            "x": 3,
            "y": -3,
            "z": 0,
            "elements": [
                "tcomplement:scorched_stairs_brick_small@1"
            ]
        },
        {
            "x": 6,
            "y": 2,
            "z": 4,
            "elements": [
                "tconstruct:slime_congealed@0"
            ]
        },
        {
            "x": 7,
            "y": -2,
            "z": 8,
            "elements": [
                "enderio:block_alloy@6"
            ]
        },
        {
            "x": -5,
            "y": -3,
            "z": 15,
            "elements": [
                "nuclearcraft:ingot_block@8"
            ]
        },
        {
            "x": -10,
            "y": 0,
            "z": 16,
            "elements": [
                "casings_all"
            ]
        },
        {
            "x": -8,
            "y": -1,
            "z": 15,
            "elements": [
                "tcomplement:scorched_block@10"
            ]
        },
        {
            "x": 4,
            "y": 3,
            "z": 13,
            "elements": [
                "forestry:slabs.vanilla.fireproof.0@0"
            ]
        },
        {
            "x": -9,
            "y": 0,
            "z": 4,
            "elements": [
                "minecraft:magma@0"
            ]
        },
        {
            "x": 1,
            "y": 3,
            "z": 14,
            "elements": [
                "forestry:slabs.vanilla.fireproof.0@0"
            ]
        },
        {
            "x": -2,
            "y": 2,
            "z": 13,
            "elements": [
                "tconstruct:slime_congealed@0"
            ]
        },
        {
            "x": 3,
            "y": -3,
            "z": 6,
            "elements": [
                "nuclearcraft:ingot_block@8"
            ]
        },
        {
            "x": -9,
            "y": -2,
            "z": 4,
            "elements": [
                "enderio:block_alloy@0"
            ]
        },
        {
            "x": -3,
            "y": -3,
            "z": 5,
            "elements": [
                "nuclearcraft:ingot_block@8"
            ]
        },
        {
            "x": 0,
            "y": -2,
            "z": 6,
            "elements": [
                "minecraft:lava@0"
            ]
        },
        {
            "x": -9,
            "y": -2,
            "z": 9,
            "elements": [
                "enderio:block_alloy@0"
            ]
        },
        {
            "x": 9,
            "y": 1,
            "z": 3,
            "elements": [
                "tcomplement:scorched_block@10"
            ]
        },
        {
            "x": 0,
            "y": -2,
            "z": 11,
            "elements": [
                "minecraft:lava@0"
            ]
        },
        {
            "x": 8,
            "y": 0,
            "z": 8,
            "elements": [
                "minecraft:magma@0"
            ]
        },
        {
            "x": -3,
            "y": 3,
            "z": 5,
            "elements": [
                "forestry:slabs.vanilla.fireproof.0@0"
            ]
        },
        {
            "x": 0,
            "y": 3,
            "z": 3,
            "elements": [
                "forestry:slabs.vanilla.fireproof.0@0"
            ]
        },
        {
            "x": 7,
            "y": 0,
            "z": 6,
            "elements": [
                "divinerpg:netherite_block@0"
            ]
        },
        {
            "x": 0,
            "y": -3,
            "z": 13,
            "elements": [
                "nuclearcraft:ingot_block@8"
            ]
        },
        {
            "x": -2,
            "y": 2,
            "z": 14,
            "elements": [
                "tconstruct:slime_congealed@0"
            ]
        },
        {
            "x": 1,
            "y": 3,
            "z": 12,
            "elements": [
                "forestry:planks.vanilla.fireproof.0@0"
            ]
        },
        {
            "x": -5,
            "y": -3,
            "z": 5,
            "elements": [
                "nuclearcraft:ingot_block@8"
            ]
        },
        {
            "x": -4,
            "y": 1,
            "z": 0,
            "elements": [
                "tcomplement:scorched_block@10"
            ]
        },
        {
            "x": 8,
            "y": -2,
            "z": 17,
            "elements": [
                "enderio:block_alloy@0"
            ]
        },
        {
            "x": -10,
            "y": -1,
            "z": 15,
            "elements": [
                "tcomplement:scorched_block@10"
            ]
        },
        {
            "x": -5,
            "y": 3,
            "z": 14,
            "elements": [
                "forestry:slabs.vanilla.fireproof.0@0"
            ]
        },
        {
            "x": 6,
            "y": 0,
            "z": 18,
            "elements": [
                "minecraft:magma@0"
            ]
        },
        {
            "x": -3,
            "y": -3,
            "z": 0,
            "elements": [
                "tcomplement:scorched_block@10"
            ]
        },
        {
            "x": -2,
            "y": 2,
            "z": 9,
            "elements": [
                "tconstruct:slime_congealed@0"
            ]
        },
        {
            "x": -9,
            "y": -2,
            "z": 14,
            "elements": [
                "enderio:block_alloy@0"
            ]
        },
        {
            "x": -6,
            "y": -3,
            "z": 3,
            "elements": [
                "nuclearcraft:ingot_block@8"
            ]
        },
        {
            "x": -7,
            "y": -3,
            "z": 15,
            "elements": [
                "nuclearcraft:ingot_block@8"
            ]
        },
        {
            "x": -10,
            "y": 1,
            "z": 10,
            "elements": [
                "tcomplement:scorched_block@10"
            ]
        },
        {
            "x": 5,
            "y": -2,
            "z": 4,
            "elements": [
                "tconstruct:metal@5"
            ]
        },
        {
            "x": -1,
            "y": -3,
            "z": 10,
            "elements": [
                "nuclearcraft:ingot_block@8"
            ]
        },
        {
            "x": 0,
            "y": 2,
            "z": 4,
            "elements": [
                "tconstruct:slime_congealed@0"
            ]
        },
        {
            "x": -8,
            "y": -1,
            "z": 10,
            "elements": [
                "enderio:block_alloy@6"
            ]
        },
        {
            "x": 1,
            "y": 2,
            "z": 6,
            "elements": [
                "tconstruct:slime_congealed@0"
            ]
        },
        {
            "x": 1,
            "y": 2,
            "z": 12,
            "elements": [
                "tconstruct:slime_congealed@0"
            ]
        },
        {
            "x": 1,
            "y": 2,
            "z": 16,
            "elements": [
                "tconstruct:slime_congealed@0"
            ]
        },
        {
            "x": -2,
            "y": -2,
            "z": 16,
            "elements": [
                "tconstruct:metal@5"
            ]
        },
        {
            "x": 9,
            "y": 1,
            "z": 17,
            "elements": [
                "tcomplement:scorched_block@10"
            ]
        },
        {
            "x": 9,
            "y": -1,
            "z": 8,
            "elements": [
                "tcomplement:scorched_block@10"
            ]
        },
        {
            "x": 6,
            "y": -2,
            "z": 6,
            "elements": [
                "minecraft:gold_block@0"
            ]
        },
        {
            "x": 4,
            "y": -1,
            "z": 0,
            "elements": [
                "tcomplement:scorched_block@10"
            ]
        },
        {
            "x": -6,
            "y": -2,
            "z": 11,
            "elements": [
                "minecraft:lava@0"
            ]
        },
        {
            "x": -8,
            "y": -1,
            "z": 5,
            "elements": [
                "tcomplement:scorched_block@10"
            ]
        },
        {
            "x": 4,
            "y": 2,
            "z": 14,
            "elements": [
                "tconstruct:slime_congealed@0"
            ]
        },
        {
            "x": 6,
            "y": -3,
            "z": 14,
            "elements": [
                "nuclearcraft:ingot_block@8"
            ]
        },
        {
            "x": 1,
            "y": 3,
            "z": 6,
            "elements": [
                "forestry:slabs.vanilla.fireproof.0@0"
            ]
        },
        {
            "x": 2,
            "y": 1,
            "z": 0,
            "elements": [
                "tcomplement:scorched_block@10"
            ]
        },
        {
            "x": 5,
            "y": -2,
            "z": 18,
            "elements": [
                "enderio:block_alloy@0"
            ]
        },
        {
            "x": -8,
            "y": 0,
            "z": 11,
            "elements": [
                "enderio:block_alloy@6"
            ]
        },
        {
            "x": -1,
            "y": 3,
            "z": 5,
            "elements": [
                "forestry:slabs.vanilla.fireproof.0@0"
            ]
        },
        {
            "x": 3,
            "y": 1,
            "z": 18,
            "elements": [
                "thermalfoundation:glass_alloy@6"
            ]
        },
        {
            "x": -3,
            "y": 3,
            "z": 10,
            "elements": [
                "forestry:slabs.vanilla.fireproof.0@0"
            ]
        },
        {
            "x": -9,
            "y": 1,
            "z": 3,
            "elements": [
                "thermalfoundation:glass_alloy@6"
            ]
        },
        {
            "x": 6,
            "y": 0,
            "z": 17,
            "elements": [
                "divinerpg:netherite_block@0"
            ]
        },
        {
            "x": 9,
            "y": 0,
            "z": 4,
            "elements": [
                "casings_all"
            ]
        },
        {
            "x": 4,
            "y": 2,
            "z": 9,
            "elements": [
                "tconstruct:slime_congealed@0"
            ]
        },
        {
            "x": 7,
            "y": 0,
            "z": 9,
            "elements": [
                "enderio:block_alloy@6"
            ]
        },
        {
            "x": -6,
            "y": -1,
            "z": 0,
            "elements": [
                "tcomplement:scorched_block@10"
            ]
        },
        {
            "x": -6,
            "y": 2,
            "z": 4,
            "elements": [
                "tconstruct:slime_congealed@0"
            ]
        },
        {
            "x": -1,
            "y": -3,
            "z": 15,
            "elements": [
                "nuclearcraft:ingot_block@8"
            ]
        },
        {
            "x": -3,
            "y": -2,
            "z": 14,
            "elements": [
                "minecraft:lava@0"
            ]
        },
        {
            "x": -7,
            "y": 3,
            "z": 5,
            "elements": [
                "forestry:slabs.vanilla.fireproof.0@0"
            ]
        },
        {
            "x": -1,
            "y": 2,
            "z": 16,
            "elements": [
                "tconstruct:slime_congealed@0"
            ]
        },
        {
            "x": 0,
            "y": -2,
            "z": 16,
            "elements": [
                "tconstruct:metal@5"
            ]
        },
        {
            "x": 0,
            "y": -3,
            "z": 14,
            "elements": [
                "nuclearcraft:ingot_block@8"
            ]
        },
        {
            "x": 8,
            "y": 5,
            "z": 1,
            "elements": [
                "thermalfoundation:fluid_pyrotheum@0"
            ]
        },
        {
            "x": -5,
            "y": 3,
            "z": 15,
            "elements": [
                "forestry:slabs.vanilla.fireproof.0@0"
            ]
        },
        {
            "x": -8,
            "y": 1,
            "z": 7,
            "elements": [
                "enderio:block_alloy@6"
            ]
        },
        {
            "x": -5,
            "y": 2,
            "z": 11,
            "elements": [
                "tconstruct:slime_congealed@0"
            ]
        },
        {
            "x": 7,
            "y": 5,
            "z": 18,
            "elements": [
                "tcomplement:scorched_block@10"
            ]
        },
        {
            "x": 1,
            "y": -3,
            "z": 5,
            "elements": [
                "nuclearcraft:ingot_block@8"
            ]
        },
        {
            "x": -4,
            "y": -2,
            "z": 11,
            "elements": [
                "minecraft:lava@0"
            ]
        },
        {
            "x": 1,
            "y": 5,
            "z": 12,
            "elements": [
                "chisel:blockiron@1"
            ]
        },
        {
            "x": 9,
            "y": 1,
            "z": 18,
            "elements": [
                "tcomplement:scorched_block@10"
            ]
        },
        {
            "x": -8,
            "y": 0,
            "z": 7,
            "elements": [
                "enderio:block_alloy@6"
            ]
        },
        {
            "x": 7,
            "y": 6,
            "z": 18,
            "elements": [
                "tcomplement:scorched_block@10"
            ]
        },
        {
            "x": 3,
            "y": -2,
            "z": 13,
            "elements": [
                "minecraft:lava@0"
            ]
        },
        {
            "x": 7,
            "y": 2,
            "z": 7,
            "elements": [
                "enderio:block_alloy@6"
            ]
        },
        {
            "x": -5,
            "y": -2,
            "z": 9,
            "elements": [
                "minecraft:lava@0"
            ]
        },
        {
            "x": 7,
            "y": 0,
            "z": 19,
            "elements": [
                "casings_all"
            ]
        },
        {
            "x": 3,
            "y": -3,
            "z": 10,
            "elements": [
                "nuclearcraft:ingot_block@8"
            ]
        },
        {
            "x": -10,
            "y": -1,
            "z": 5,
            "elements": [
                "tcomplement:scorched_block@10"
            ]
        },
        {
            "x": -6,
            "y": 2,
            "z": 9,
            "elements": [
                "tconstruct:slime_congealed@0"
            ]
        },
        {
            "x": -3,
            "y": -2,
            "z": -2,
            "elements": [
                "tcomplement:scorched_stairs_brick_small@0"
            ]
        },
        {
            "x": -8,
            "y": 1,
            "z": 0,
            "elements": [
                "tcomplement:scorched_block@10"
            ]
        },
        {
            "x": 6,
            "y": -3,
            "z": 3,
            "elements": [
                "nuclearcraft:ingot_block@8"
            ]
        },
        {
            "x": -4,
            "y": -2,
            "z": 17,
            "elements": [
                "tconstruct:metal@5"
            ]
        },
        {
            "x": 8,
            "y": 7,
            "z": 2,
            "elements": [
                "tcomplement:scorched_block@10"
            ]
        },
        {
            "x": 6,
            "y": -2,
            "z": 12,
            "elements": [
                "minecraft:lava@0"
            ]
        },
        {
            "x": -4,
            "y": 2,
            "z": 4,
            "elements": [
                "tconstruct:slime_congealed@0"
            ]
        },
        {
            "x": -8,
            "y": -1,
            "z": 0,
            "elements": [
                "tcomplement:scorched_block@10"
            ]
        },
        {
            "x": -4,
            "y": -1,
            "z": 17,
            "elements": [
                "tcomplement:scorched_block@10"
            ]
        },
        {
            "x": 4,
            "y": -2,
            "z": 2,
            "elements": [
                "tconstruct:metal@5"
            ]
        },
        {
            "x": -6,
            "y": -2,
            "z": 16,
            "elements": [
                "tconstruct:metal@5"
            ]
        },
        {
            "x": 2,
            "y": 0,
            "z": 2,
            "elements": [
                "divinerpg:netherite_block@0"
            ]
        },
        {
            "x": 6,
            "y": -3,
            "z": 12,
            "elements": [
                "nuclearcraft:ingot_block@8"
            ]
        },
        {
            "x": 1,
            "y": -2,
            "z": 4,
            "elements": [
                "minecraft:gold_block@0"
            ]
        },
        {
            "x": 8,
            "y": 4,
            "z": 2,
            "elements": [
                "tcomplement:scorched_block@10"
            ]
        },
        {
            "x": 7,
            "y": -3,
            "z": 5,
            "elements": [
                "nuclearcraft:ingot_block@8"
            ]
        },
        {
            "x": 3,
            "y": 3,
            "z": 5,
            "elements": [
                "forestry:slabs.vanilla.fireproof.0@0"
            ]
        },
        {
            "x": 8,
            "y": 5,
            "z": 2,
            "elements": [
                "tcomplement:scorched_block@10"
            ]
        },
        {
            "x": -2,
            "y": 3,
            "z": 3,
            "elements": [
                "forestry:slabs.vanilla.fireproof.0@0"
            ]
        },
        {
            "x": -3,
            "y": -2,
            "z": 9,
            "elements": [
                "minecraft:lava@0"
            ]
        },
        {
            "x": 4,
            "y": 4,
            "z": 7,
            "elements": [
                "forestry:fences.vanilla.fireproof.0@0"
            ]
        },
        {
            "x": 8,
            "y": 1,
            "z": 2,
            "elements": [
                "thermalfoundation:glass_alloy@6"
            ]
        },
        {
            "x": 1,
            "y": 3,
            "z": 10,
            "elements": [
                "forestry:slabs.vanilla.fireproof.0@0"
            ]
        },
        {
            "x": -6,
            "y": 0,
            "z": 17,
            "elements": [
                "divinerpg:netherite_block@0"
            ]
        },
        {
            "x": 7,
            "y": 0,
            "z": 14,
            "elements": [
                "divinerpg:netherite_block@0"
            ]
        },
        {
            "x": 8,
            "y": 0,
            "z": 2,
            "elements": [
                "minecraft:magma@0"
            ]
        },
        {
            "x": -10,
            "y": -1,
            "z": 17,
            "elements": [
                "tcomplement:scorched_block@10"
            ]
        },
        {
            "x": 4,
            "y": 5,
            "z": 7,
            "elements": [
                "chisel:blockiron@1"
            ]
        },
        {
            "x": -4,
            "y": -3,
            "z": 3,
            "elements": [
                "nuclearcraft:ingot_block@8"
            ]
        },
        {
            "x": 0,
            "y": 0,
            "z": 18,
            "elements": [
                "minecraft:magma@0"
            ]
        },
        {
            "x": 8,
            "y": -1,
            "z": 19,
            "elements": [
                "tcomplement:scorched_block@10"
            ]
        },
        {
            "x": 8,
            "y": 3,
            "z": 2,
            "elements": [
                "tcomplement:scorched_block@10"
            ]
        },
        {
            "x": -2,
            "y": 2,
            "z": 4,
            "elements": [
                "tconstruct:slime_congealed@0"
            ]
        },
        {
            "x": -1,
            "y": -2,
            "z": 4,
            "elements": [
                "minecraft:gold_block@0"
            ]
        },
        {
            "x": -5,
            "y": 2,
            "z": 16,
            "elements": [
                "tconstruct:slime_congealed@0"
            ]
        },
        {
            "x": 8,
            "y": 1,
            "z": 5,
            "elements": [
                "thermalfoundation:glass_alloy@6"
            ]
        },
        {
            "x": 6,
            "y": -1,
            "z": 0,
            "elements": [
                "tcomplement:scorched_block@10"
            ]
        },
        {
            "x": -1,
            "y": 3,
            "z": 15,
            "elements": [
                "forestry:slabs.vanilla.fireproof.0@0"
            ]
        },
        {
            "x": 4,
            "y": 3,
            "z": 7,
            "elements": [
                "forestry:planks.vanilla.fireproof.0@0"
            ]
        },
        {
            "x": -4,
            "y": -3,
            "z": 17,
            "elements": [
                "nuclearcraft:ingot_block@8"
            ]
        },
        {
            "x": 5,
            "y": -3,
            "z": 5,
            "elements": [
                "nuclearcraft:ingot_block@8"
            ]
        },
        {
            "x": 5,
