{
    "registryname": "fallen_star",
    "localizedname": "坠星天矛",
    "requires-blueprint": true,
    "color": "333332",
    "failure-action": "still",
    "parts": [
        {
            "x": -1,
            "y": 2,
            "z": 0,
            "elements": [
                "tconevo:metal_block@6"
            ]
        },
        {
            "x": -5,
            "y": -2,
            "z": -4,
            "elements": [
                "bloodmagic:decorative_brick@1"
            ]
        },
        {
            "x": 3,
            "y": -4,
            "z": -5,
            "elements": [
                "bloodmagic:ritual_stone@5"
            ]
        },
        {
            "x": 2,
            "y": -1,
            "z": -5,
            "elements": [
                "bloodarsenal:blood_stained_glass@0"
            ]
        },
        {
            "x": 5,
            "y": -1,
            "z": -2,
            "elements": [
                "bloodarsenal:blood_stained_glass@0"
            ]
        },
        {
            "x": 1,
            "y": -4,
            "z": 0,
            "elements": [
                "bloodmagic:blood_rune@5"
            ]
        },
        {
            "x": 6,
            "y": -2,
            "z": -3,
            "elements": [
                "bloodmagic:decorative_brick@1"
            ]
        },
        {
            "x": -2,
            "y": -4,
            "z": -4,
            "elements": [
                "bloodmagic:ritual_stone@4"
            ]
        },
        {
            "x": 0,
            "y": -3,
            "z": -7,
            "elements": [
                "bloodmagic:ritual_stone@3"
            ]
        },
        {
            "x": -6,
            "y": -1,
            "z": -1,
            "elements": [
                "bloodmagic:decorative_brick@1"
            ]
        },
        {
            "x": 0,
            "y": -3,
            "z": 6,
            "elements": [
                "bloodmagic:decorative_brick@1"
            ]
        },
        {
            "x": -5,
            "y": -4,
            "z": 2,
            "elements": [
                "bloodmagic:path@6"
            ]
        },
        {
            "x": 3,
            "y": 0,
            "z": -2,
            "elements": [
                "bloodmagic:ritual_stone@2"
            ]
        },
        {
            "x": 1,
            "y": 1,
            "z": -3,
            "elements": [
                "bloodarsenal:blood_stained_glass@0"
            ]
        },
        {
            "x": 1,
            "y": -4,
            "z": 3,
            "elements": [
                "bloodmagic:ritual_stone@4"
            ]
        },
        {
            "x": -1,
            "y": -4,
            "z": 5,
            "elements": [
                "bloodmagic:path@6"
            ]
        },
        {
            "x": 5,
            "y": -1,
            "z": 1,
            "elements": [
                "bloodarsenal:blood_stained_glass@0"
            ]
        },
        {
            "x": 0,
            "y": -4,
            "z": 6,
            "elements": [
                "bloodmagic:decorative_brick@1"
            ]
        },
        {
            "x": -4,
            "y": -2,
            "z": 5,
            "elements": [
                "bloodmagic:decorative_brick@1"
            ]
        },
        {
            "x": -2,
            "y": 2,
            "z": 0,
            "elements": [
                "bloodmagic:decorative_brick@1"
            ]
        },
        {
            "x": 5,
            "y": -4,
            "z": 1,
            "elements": [
                "bloodmagic:path@6"
            ]
        },
        {
            "x": -2,
            "y": -4,
            "z": 3,
            "elements": [
                "bloodmagic:blood_rune@9"
            ]
        },
        {
            "x": 0,
            "y": -4,
            "z": 8,
            "elements": [
                "bloodmagic:ritual_stone@3"
            ]
        },
        {
            "x": 3,
            "y": -1,
            "z": 4,
            "elements": [
                "bloodarsenal:blood_stained_glass@0"
            ]
        },
        {
            "x": 1,
            "y": -1,
            "z": -5,
            "elements": [
                "bloodarsenal:blood_stained_glass@0"
            ]
        },
        {
            "x": 0,
            "y": -4,
            "z": 0,
            "elements": [
                "bloodmagic:ritual_controller@0"
            ]
        },
        {
            "x": -4,
            "y": -4,
            "z": 2,
            "elements": [
                "bloodmagic:ritual_stone@4"
            ]
        },
        {
            "x": 5,
            "y": -4,
            "z": -2,
            "elements": [
                "bloodmagic:path@6"
            ]
        },
        {
            "x": -2,
            "y": 1,
            "z": 0,
            "elements": [
                "modularmachinery:blockcasing@0"
            ]
        },
        {
            "x": -5,
            "y": -1,
            "z": 2,
            "elements": [
                "bloodarsenal:blood_stained_glass@0"
            ]
        },
        {
            "x": 4,
            "y": 0,
            "z": -2,
            "elements": [
                "bloodmagic:ritual_stone@1"
            ]
        },
        {
            "x": -6,
            "y": -1,
            "z": 1,
            "elements": [
                "bloodmagic:decorative_brick@1"
            ]
        },
        {
            "x": -1,
            "y": 3,
            "z": 0,
            "elements": [
                "bloodmagic:decorative_brick@1"
            ]
        },
        {
            "x": 4,
            "y": -2,
            "z": 4,
            "elements": [
                "bloodmagic:decorative_brick@1"
            ]
        },
        {
            "x": 0,
            "y": -4,
            "z": 5,
            "elements": [
                "bloodmagic:decorative_brick@1"
            ]
        },
        {
            "x": -5,
            "y": -4,
            "z": 3,
            "elements": [
                "bloodmagic:ritual_stone@5"
            ]
        },
        {
            "x": 3,
            "y": 0,
            "z": 2,
            "elements": [
                "bloodmagic:ritual_stone@2"
            ]
        },
        {
            "x": 5,
            "y": -4,
            "z": 2,
            "elements": [
                "bloodmagic:path@6"
            ]
        },
        {
            "x": -4,
            "y": -4,
            "z": -4,
            "elements": [
                "bloodmagic:ritual_stone@5"
            ]
        },
        {
            "x": 3,
            "y": -4,
            "z": 0,
            "elements": [
                "bloodmagic:blood_rune@5"
            ]
        },
        {
            "x": 0,
            "y": -4,
            "z": -8,
            "elements": [
                "bloodmagic:ritual_stone@3"
            ]
        },
        {
            "x": 0,
            "y": -2,
            "z": -7,
            "elements": [
                "bloodmagic:ritual_stone@3"
            ]
        },
        {
            "x": -2,
            "y": 0,
            "z": -3,
            "elements": [
                "bloodmagic:ritual_stone@2"
            ]
        },
        {
            "x": 1,
            "y": 2,
            "z": 0,
            "elements": [
                "tconevo:metal_block@6"
            ]
        },
        {
            "x": 2,
            "y": -4,
            "z": -2,
            "elements": [
                "bloodmagic:blood_rune@9"
            ]
        },
        {
            "x": 0,
            "y": 1,
            "z": 2,
            "elements": [
                "modularmachinery:blockcasing@0"
            ]
        },
        {
            "x": -3,
            "y": 0,
            "z": -2,
            "elements": [
                "bloodmagic:ritual_stone@2"
            ]
        },
        {
            "x": -2,
            "y": -1,
            "z": -6,
            "elements": [
                "bloodmagic:decorative_brick@1"
            ]
        },
        {
            "x": 0,
            "y": 0,
            "z": -5,
            "elements": [
                "bloodmagic:ritual_stone@4"
            ]
        },
        {
            "x": -1,
            "y": -1,
            "z": 5,
            "elements": [
                "bloodarsenal:blood_stained_glass@0"
            ]
        },
        {
            "x": 2,
            "y": 0,
            "z": 3,
            "elements": [
                "bloodmagic:ritual_stone@2"
            ]
        },
        {
            "x": 0,
            "y": -3,
            "z": 8,
            "elements": [
                "bloodmagic:ritual_stone@3"
            ]
        },
        {
            "x": 1,
            "y": -1,
            "z": 6,
            "elements": [
                "bloodmagic:decorative_brick@1"
            ]
        },
        {
            "x": 4,
            "y": -2,
            "z": -5,
            "elements": [
                "bloodmagic:decorative_brick@1"
            ]
        },
        {
            "x": -2,
            "y": -2,
            "z": -6,
            "elements": [
                "bloodmagic:decorative_brick@1"
            ]
        },
        {
            "x": 0,
            "y": -4,
            "z": -3,
            "elements": [
                "bloodmagic:blood_rune@5"
            ]
        },
        {
            "x": -3,
            "y": -4,
            "z": 5,
            "elements": [
                "bloodmagic:ritual_stone@5"
            ]
        },
        {
            "x": -3,
            "y": 0,
            "z": 2,
            "elements": [
                "bloodmagic:ritual_stone@2"
            ]
        },
        {
            "x": -5,
            "y": -2,
            "z": 3,
            "elements": [
                "bloodmagic:decorative_brick@1"
            ]
        },
        {
            "x": -3,
            "y": 0,
            "z": -3,
            "elements": [
                "bloodmagic:ritual_stone@2"
            ]
        },
        {
            "x": 0,
            "y": 0,
            "z": 5,
            "elements": [
                "bloodmagic:ritual_stone@4"
            ]
        },
        {
            "x": 2,
            "y": -4,
            "z": 2,
            "elements": [
                "bloodmagic:blood_rune@9"
            ]
        },
        {
            "x": -1,
            "y": -4,
            "z": -2,
            "elements": [
                "bloodmagic:blood_rune@10"
            ]
        },
        {
            "x": 5,
            "y": -1,
            "z": 2,
            "elements": [
                "bloodarsenal:blood_stained_glass@0"
            ]
        },
        {
            "x": -1,
            "y": -1,
            "z": -5,
            "elements": [
                "bloodarsenal:blood_stained_glass@0"
            ]
        },
        {
            "x": 0,
            "y": -3,
            "z": -6,
            "elements": [
                "bloodmagic:decorative_brick@1"
            ]
        },
        {
            "x": -2,
            "y": -4,
            "z": 0,
            "elements": [
                "bloodmagic:ritual_stone@2"
            ]
        },
        {
            "x": 3,
            "y": 0,
            "z": 3,
            "elements": [
                "bloodmagic:ritual_stone@2"
            ]
        },
        {
            "x": 0,
            "y": -4,
            "z": -6,
            "elements": [
                "bloodmagic:decorative_brick@1"
            ]
        },
        {
            "x": 0,
            "y": -3,
            "z": -8,
            "elements": [
                "bloodmagic:ritual_stone@3"
            ]
        },
        {
            "x": -4,
            "y": -1,
            "z": -3,
            "elements": [
                "bloodarsenal:blood_stained_glass@0"
            ]
        },
        {
            "x": 0,
            "y": -2,
            "z": 6,
            "elements": [
                "bloodmagic:ritual_stone@2"
            ]
        },
        {
            "x": 0,
            "y": -1,
            "z": 6,
            "elements": [
                "bloodmagic:ritual_stone@1"
            ]
        },
        {
            "x": 4,
            "y": -4,
            "z": 3,
            "elements": [
                "bloodmagic:blood_rune@9"
            ]
        },
        {
            "x": 1,
            "y": 3,
            "z": 0,
            "elements": [
                "bloodmagic:decorative_brick@1"
            ]
        },
        {
            "x": 0,
            "y": 2,
            "z": 2,
            "elements": [
                "bloodmagic:decorative_brick@1"
            ]
        },
        {
            "x": 2,
            "y": -4,
            "z": -5,
            "elements": [
                "bloodmagic:path@6"
            ]
        },
        {
            "x": -3,
            "y": -2,
            "z": -6,
            "elements": [
                "bloodmagic:decorative_brick@1"
            ]
        },
        {
            "x": -1,
            "y": -4,
            "z": -3,
            "elements": [
                "bloodmagic:ritual_stone@4"
            ]
        },
        {
            "x": -5,
            "y": -4,
            "z": -1,
            "elements": [
                "bloodmagic:path@6"
            ]
        },
        {
            "x": -1,
            "y": 1,
            "z": -2,
            "elements": [
                "modularmachinery:blockcasing@0"
            ]
        },
        {
            "x": 4,
            "y": 0,
            "z": 0,
            "elements": [
                "bloodmagic:ritual_stone@4"
            ]
        },
        {
            "x": -6,
            "y": -2,
            "z": 3,
            "elements": [
                "bloodmagic:decorative_brick@1"
            ]
        },
        {
            "x": 0,
            "y": -4,
            "z": -2,
            "elements": [
                "bloodmagic:ritual_stone@2"
            ]
        },
        {
            "x": 3,
            "y": -2,
            "z": 6,
            "elements": [
                "bloodmagic:decorative_brick@1"
            ]
        },
        {
            "x": -2,
            "y": 1,
            "z": 2,
            "elements": [
                "bloodarsenal:blood_stained_glass@0"
            ]
        },
        {
            "x": -1,
            "y": -4,
            "z": 2,
            "elements": [
                "bloodmagic:blood_rune@10"
            ]
        },
        {
            "x": 2,
            "y": -4,
            "z": -4,
            "elements": [
                "bloodmagic:ritual_stone@4"
            ]
        },
        {
            "x": -3,
            "y": -4,
            "z": 0,
            "elements": [
                "bloodmagic:blood_rune@5"
            ]
        },
        {
            "x": -4,
            "y": 1,
            "z": 0,
            "elements": [
                "bloodmagic:decorative_brick@1"
            ]
        },
        {
            "x": 0,
            "y": 1,
            "z": 4,
            "elements": [
                "bloodmagic:decorative_brick@1"
            ]
        },
        {
            "x": 0,
            "y": 0,
            "z": -4,
            "elements": [
                "bloodmagic:ritual_stone@4"
            ]
        },
        {
            "x": 0,
            "y": 2,
            "z": -2,
            "elements": [
                "bloodmagic:decorative_brick@1"
            ]
        },
        {
            "x": -1,
            "y": 2,
            "z": 2,
            "elements": [
                "bloodmagic:decorative_brick@3"
            ]
        },
        {
            "x": 5,
            "y": -2,
            "z": 4,
            "elements": [
                "bloodmagic:decorative_brick@1"
            ]
        },
        {
            "x": 1,
            "y": -1,
            "z": 5,
            "elements": [
                "bloodarsenal:blood_stained_glass@0"
            ]
        },
        {
            "x": 2,
            "y": -4,
            "z": 4,
            "elements": [
                "bloodmagic:ritual_stone@4"
            ]
        },
        {
            "x": 5,
            "y": -4,
            "z": 3,
            "elements": [
                "bloodmagic:ritual_stone@5"
            ]
        },
        {
            "x": -1,
            "y": -4,
            "z": -5,
            "elements": [
                "bloodmagic:path@6"
            ]
        },
        {
            "x": 4,
            "y": -1,
            "z": 3,
            "elements": [
                "bloodarsenal:blood_stained_glass@0"
            ]
        },
        {
            "x": 0,
            "y": -4,
            "z": 2,
            "elements": [
                "bloodmagic:ritual_stone@2"
            ]
        },
        {
            "x": 1,
            "y": 2,
            "z": 1,
            "elements": [
                "tconevo:metal_block@6"
            ]
        },
        {
            "x": 0,
            "y": 1,
            "z": -2,
            "elements": [
                "modularmachinery:blockcasing@0"
            ]
        },
        {
            "x": 5,
            "y": 0,
            "z": 0,
            "elements": [
                "bloodmagic:ritual_stone@4"
            ]
        },
        {
            "x": 4,
            "y": -4,
            "z": 0,
            "elements": [
                "bloodmagic:ritual_stone@3"
            ]
        },
        {
            "x": -2,
            "y": -4,
            "z": -1,
            "elements": [
                "bloodmagic:blood_rune@10"
            ]
        },
        {
            "x": 2,
            "y": 2,
            "z": 0,
            "elements": [
                "bloodmagic:decorative_brick@1"
            ]
        },
        {
            "x": 4,
            "y": 0,
            "z": 1,
            "elements": [
                "bloodmagic:ritual_stone@4"
            ]
        },
        {
            "x": 1,
            "y": -4,
            "z": -2,
            "elements": [
                "bloodmagic:blood_rune@10"
            ]
        },
        {
            "x": -4,
            "y": -2,
            "z": -4,
            "elements": [
                "bloodmagic:decorative_brick@1"
            ]
        },
        {
            "x": -5,
            "y": -1,
            "z": -1,
            "elements": [
                "bloodarsenal:blood_stained_glass@0"
            ]
        },
        {
            "x": -1,
            "y": 1,
            "z": 2,
            "elements": [
                "modularmachinery:blockcasing@0"
            ]
        },
        {
            "x": 5,
            "y": -2,
            "z": 3,
            "elements": [
                "bloodmagic:decorative_brick@1"
            ]
        },
        {
            "x": 2,
            "y": 1,
            "z": 0,
            "elements": [
                "modularmachinery:blockcasing@0"
            ]
        },
        {
            "x": -1,
            "y": 2,
            "z": -2,
            "elements": [
                "bloodmagic:decorative_brick@3"
            ]
        },
        {
            "x": -3,
            "y": -4,
            "z": -3,
            "elements": [
                "bloodmagic:blood_rune@10"
            ]
        },
        {
            "x": 0,
            "y": 0,
            "z": 4,
            "elements": [
                "bloodmagic:ritual_stone@4"
            ]
        },
        {
            "x": 6,
            "y": -1,
            "z": 1,
            "elements": [
                "bloodmagic:decorative_brick@1"
            ]
        },
        {
            "x": -3,
            "y": -2,
            "z": -5,
            "elements": [
                "bloodmagic:decorative_brick@1"
            ]
        },
        {
            "x": 0,
            "y": -4,
            "z": -5,
            "elements": [
                "bloodmagic:decorative_brick@1"
            ]
        },
        {
            "x": -4,
            "y": -2,
            "z": 4,
            "elements": [
                "bloodmagic:decorative_brick@1"
            ]
        },
        {
            "x": -4,
            "y": 0,
            "z": 2,
            "elements": [
                "bloodmagic:ritual_stone@1"
            ]
        },
        {
            "x": -2,
            "y": -4,
            "z": -2,
            "elements": [
                "bloodmagic:blood_rune@9"
            ]
        },
        {
            "x": 1,
            "y": 1,
            "z": -2,
            "elements": [
                "modularmachinery:blockcasing@0"
            ]
        },
        {
            "x": 1,
            "y": -4,
            "z": 2,
            "elements": [
                "bloodmagic:blood_rune@10"
            ]
        },
        {
            "x": 2,
            "y": 2,
            "z": -1,
            "elements": [
                "bloodmagic:decorative_brick@3"
            ]
        },
        {
            "x": 0,
            "y": -1,
            "z": -5,
            "elements": [
                "bloodmagic:ritual_stone@1"
            ]
        },
        {
            "x": -6,
            "y": -2,
            "z": 0,
            "elements": [
                "bloodmagic:ritual_stone@2"
            ]
        },
        {
            "x": 7,
            "y": -3,
            "z": 0,
            "elements": [
                "bloodmagic:ritual_stone@3"
            ]
        },
        {
            "x": -6,
            "y": -1,
            "z": 0,
            "elements": [
                "bloodmagic:ritual_stone@1"
            ]
        },
        {
            "x": -4,
            "y": -4,
            "z": -3,
            "elements": [
                "bloodmagic:blood_rune@9"
            ]
        },
        {
            "x": 3,
            "y": 1,
            "z": -1,
            "elements": [
                "bloodarsenal:blood_stained_glass@0"
            ]
        },
        {
            "x": 1,
            "y": 2,
            "z": 2,
            "elements": [
                "bloodmagic:decorative_brick@3"
            ]
        },
        {
            "x": -5,
            "y": 0,
            "z": 0,
            "elements": [
                "bloodmagic:ritual_stone@4"
            ]
        },
        {
            "x": -3,
            "y": -4,
            "z": 1,
            "elements": [
                "bloodmagic:ritual_stone@4"
            ]
        },
        {
            "x": -4,
            "y": 0,
            "z": -1,
            "elements": [
                "bloodmagic:ritual_stone@4"
            ]
        },
        {
            "x": 5,
            "y": -4,
            "z": -1,
            "elements": [
                "bloodmagic:path@6"
            ]
        },
        {
            "x": -5,
            "y": -2,
            "z": 4,
            "elements": [
                "bloodmagic:decorative_brick@1"
            ]
        },
        {
            "x": 1,
            "y": -4,
            "z": 5,
            "elements": [
                "bloodmagic:path@6"
            ]
        },
        {
            "x": -2,
            "y": 1,
            "z": -2,
            "elements": [
                "bloodarsenal:blood_stained_glass@0"
            ]
        },
        {
            "x": 3,
            "y": -4,
            "z": 1,
            "elements": [
                "bloodmagic:ritual_stone@4"
            ]
        },
        {
            "x": 5,
            "y": -1,
            "z": -1,
            "elements": [
                "bloodarsenal:blood_stained_glass@0"
            ]
        },
        {
            "x": -1,
            "y": -4,
            "z": -4,
            "elements": [
                "tconevo:metal_block@5"
            ]
        },
        {
            "x": -4,
            "y": -4,
            "z": 4,
            "elements": [
                "bloodmagic:ritual_stone@5"
            ]
        },
        {
            "x": 1,
            "y": 1,
            "z": 2,
            "elements": [
                "modularmachinery:blockcasing@0"
            ]
        },
        {
            "x": -2,
            "y": -4,
            "z": 2,
            "elements": [
                "bloodmagic:blood_rune@9"
            ]
        },
        {
            "x": 3,
            "y": -4,
            "z": -2,
            "elements": [
                "bloodmagic:blood_rune@9"
            ]
        },
        {
            "x": -6,
            "y": -4,
            "z": 0,
            "elements": [
                "bloodmagic:decorative_brick@1"
            ]
        },
        {
            "x": 5,
            "y": -2,
            "z": -4,
            "elements": [
                "bloodmagic:decorative_brick@1"
            ]
        },
        {
            "x": -2,
            "y": -1,
            "z": 5,
            "elements": [
                "bloodarsenal:blood_stained_glass@0"
            ]
        },
        {
            "x": -2,
            "y": -4,
            "z": 5,
            "elements": [
                "bloodmagic:path@6"
            ]
        },
        {
            "x": 1,
            "y": 2,
            "z": -2,
            "elements": [
                "bloodmagic:decorative_brick@3"
            ]
        },
        {
            "x": 4,
            "y": -4,
            "z": -1,
            "elements": [
                "tconevo:metal_block@5"
            ]
        },
        {
            "x": -5,
            "y": -4,
            "z": -3,
            "elements": [
                "bloodmagic:ritual_stone@5"
            ]
        },
        {
            "x": 3,
            "y": -2,
            "z": -5,
            "elements": [
                "bloodmagic:decorative_brick@1"
            ]
        },
        {
            "x": -6,
            "y": -2,
            "z": -3,
            "elements": [
                "bloodmagic:decorative_brick@1"
            ]
        },
        {
            "x": -6,
            "y": -3,
            "z": 0,
            "elements": [
                "bloodmagic:decorative_brick@1"
            ]
        },
        {
            "x": -4,
            "y": -4,
            "z": 1,
            "elements": [
                "tconevo:metal_block@5"
            ]
        },
        {
            "x": 1,
            "y": -4,
            "z": 4,
            "elements": [
                "tconevo:metal_block@5"
            ]
        },
        {
            "x": 1,
            "y": 1,
            "z": 3,
            "elements": [
                "bloodarsenal:blood_stained_glass@0"
            ]
        },
        {
            "x": 3,
            "y": -1,
            "z": -4,
            "elements": [
                "bloodarsenal:blood_stained_glass@0"
            ]
        },
        {
            "x": 3,
            "y": -4,
            "z": 2,
            "elements": [
                "bloodmagic:blood_rune@9"
            ]
        },
        {
            "x": 0,
            "y": 3,
            "z": 1,
            "elements": [
                "bloodmagic:decorative_brick@1"
            ]
        },
        {
            "x": -1,
            "y": -4,
            "z": -1,
            "elements": [
                "bloodarsenal:blood_infused_iron_block@0"
            ]
        },
        {
            "x": 2,
            "y": 1,
            "z": -1,
            "elements": [
                "modularmachinery:blockcasing@0"
            ]
        },
        {
            "x": 2,
            "y": -4,
            "z": 1,
            "elements": [
                "bloodmagic:blood_rune@10"
            ]
        },
        {
            "x": 2,
            "y": 1,
            "z": 2,
            "elements": [
                "bloodarsenal:blood_stained_glass@0"
            ]
        },
        {
            "x": 4,
            "y": -4,
            "z": -2,
            "elements": [
                "bloodmagic:ritual_stone@4"
            ]
        },
        {
            "x": 0,
            "y": 2,
            "z": 1,
            "elements": [
                "tconevo:metal_block@6"
            ]
        },
        {
            "x": 8,
            "y": -3,
            "z": 0,
            "elements": [
                "bloodmagic:ritual_stone@3"
            ]
        },
        {
            "x": 6,
            "y": -2,
            "z": 3,
            "elements": [
                "bloodmagic:decorative_brick@1"
            ]
        },
        {
            "x": -1,
            "y": -1,
            "z": 6,
            "elements": [
                "bloodmagic:decorative_brick@1"
            ]
        },
        {
            "x": -1,
            "y": 0,
            "z": 4,
            "elements": [
                "bloodmagic:ritual_stone@4"
            ]
        },
        {
            "x": -3,
            "y": 1,
            "z": 1,
            "elements": [
                "bloodarsenal:blood_stained_glass@0"
            ]
        },
        {
            "x": -1,
            "y": -4,
            "z": 1,
            "elements": [
                "bloodarsenal:blood_infused_iron_block@0"
            ]
        },
        {
            "x": 0,
            "y": 3,
            "z": -1,
            "elements": [
                "bloodmagic:decorative_brick@1"
            ]
        },
        {
            "x": -5,
            "y": -2,
            "z": -3,
            "elements": [
                "bloodmagic:decorative_brick@1"
            ]
        },
        {
            "x": 7,
            "y": -2,
            "z": 0,
            "elements": [
                "bloodmagic:ritual_stone@3"
            ]
        },
        {
            "x": -7,
            "y": -3,
            "z": 0,
            "elements": [
                "bloodmagic:ritual_stone@3"
            ]
        },
        {
            "x": -2,
            "y": -4,
            "z": -3,
            "elements": [
                "bloodmagic:blood_rune@9"
            ]
        },
        {
            "x": 4,
            "y": -4,
            "z": 2,
            "elements": [
                "bloodmagic:ritual_stone@4"
            ]
        },
        {
            "x": 4,
            "y": -4,
            "z": -3,
            "elements": [
                "bloodmagic:blood_rune@9"
            ]
        },
        {
            "x": -3,
            "y": 1,
            "z": -1,
            "elements": [
                "bloodarsenal:blood_stained_glass@0"
            ]
        },
        {
            "x": 8,
            "y": -4,
            "z": 0,
            "elements": [
                "bloodmagic:ritual_stone@3"
            ]
        },
        {
            "x": 1,
            "y": -4,
            "z": -4,
            "elements": [
                "tconevo:metal_block@5"
            ]
        },
        {
            "x": -3,
            "y": -4,
            "z": -2,
            "elements": [
                "bloodmagic:blood_rune@9"
            ]
        },
        {
            "x": 2,
            "y": -2,
            "z": 6,
            "elements": [
                "bloodmagic:decorative_brick@1"
            ]
        },
        {
            "x": -1,
            "y": -1,
            "z": -6,
            "elements": [
                "bloodmagic:decorative_brick@1"
            ]
        },
        {
            "x": 4,
            "y": -2,
            "z": 5,
            "elements": [
                "bloodmagic:decorative_brick@1"
            ]
        },
        {
            "x": -7,
            "y": -2,
            "z": 0,
            "elements": [
                "bloodmagic:ritual_stone@3"
            ]
        },
        {
            "x": -2,
            "y": -4,
            "z": 4,
            "elements": [
                "bloodmagic:ritual_stone@4"
            ]
        },
        {
            "x": -4,
            "y": 0,
            "z": -2,
            "elements": [
                "bloodmagic:ritual_stone@1"
            ]
        },
        {
            "x": -8,
            "y": -4,
            "z": 0,
            "elements": [
                "bloodmagic:ritual_stone@3"
            ]
        },
        {
            "x": 2,
            "y": -4,
            "z": -1,
            "elements": [
                "bloodmagic:blood_rune@10"
            ]
        },
        {
            "x": 2,
            "y": -1,
            "z": 6,
            "elements": [
                "bloodmagic:decorative_brick@1"
            ]
        },
        {
            "x": 1,
            "y": -4,
            "z": -3,
            "elements": [
                "bloodmagic:ritual_stone@4"
            ]
        },
        {
            "x": 0,
            "y": -2,
            "z": 7,
            "elements": [
                "bloodmagic:ritual_stone@3"
            ]
        },
        {
            "x": -8,
            "y": -3,
            "z": 0,
            "elements": [
                "bloodmagic:ritual_stone@3"
            ]
        },
        {
            "x": -4,
            "y": -2,
            "z": -5,
            "elements": [
                "bloodmagic:decorative_brick@1"
            ]
        },
        {
            "x": -2,
            "y": 2,
            "z": 1,
            "elements": [
                "bloodmagic:decorative_brick@3"
            ]
        },
        {
            "x": 4,
            "y": -4,
            "z": -4,
            "elements": [
                "bloodmagic:ritual_stone@5"
            ]
        },
        {
            "x": -6,
            "y": -2,
            "z": 2,
            "elements": [
                "bloodmagic:decorative_brick@1"
            ]
        },
        {
            "x": -3,
            "y": -4,
            "z": 2,
            "elements": [
                "bloodmagic:blood_rune@9"
            ]
        },
        {
            "x": -5,
            "y": -4,
            "z": 0,
            "elements": [
                "bloodmagic:decorative_brick@1"
            ]
        },
        {
            "x": -1,
            "y": -4,
            "z": 4,
            "elements": [
                "tconevo:metal_block@5"
            ]
        },
        {
            "x": 2,
            "y": 0,
            "z": -4,
            "elements": [
                "bloodmagic:ritual_stone@1"
            ]
        },
        {
            "x": -3,
            "y": -1,
            "z": 4,
            "elements": [
                "bloodarsenal:blood_stained_glass@0"
            ]
        },
        {
            "x": -6,
            "y": -1,
            "z": 2,
            "elements": [
                "bloodmagic:decorative_brick@1"
            ]
        },
        {
            "x": -1,
            "y": 2,
            "z": -1,
            "elements": [
                "tconevo:metal_block@6"
            ]
        },
        {
            "x": 3,
            "y": -4,
            "z": 3,
            "elements": [
                "bloodmagic:blood_rune@10"
            ]
        },
        {
            "x": 1,
            "y": -4,
            "z": 1,
            "elements": [
                "bloodarsenal:blood_infused_iron_block@0"
            ]
        },
        {
            "x": -3,
            "y": -4,
            "z": -5,
            "elements": [
                "bloodmagic:ritual_stone@5"
            ]
        },
        {
            "x": 1,
            "y": -4,
            "z": -1,
            "elements": [
                "bloodarsenal:blood_infused_iron_block@0"
            ]
        },
        {
            "x": -4,
            "y": -4,
            "z": 3,
            "elements": [
                "bloodmagic:blood_rune@9"
            ]
        },
        {
            "x": -6,
            "y": -2,
            "z": -2,
            "elements": [
                "bloodmagic:decorative_brick@1"
            ]
        },
        {
            "x": 0,
            "y": 1,
            "z": -4,
            "elements": [
                "bloodmagic:decorative_brick@1"
            ]
        },
        {
            "x": 0,
            "y": -4,
            "z": -1,
            "elements": [
                "bloodmagic:blood_rune@5"
            ]
        },
        {
            "x": 6,
            "y": -4,
            "z": 0,
            "elements": [
                "bloodmagic:decorative_brick@1"
            ]
        },
        {
            "x": 2,
            "y": 1,
            "z": -2,
            "elements": [
                "bloodarsenal:blood_stained_glass@0"
            ]
        },
        {
            "x": -1,
            "y": 2,
            "z": 1,
            "elements": [
                "tconevo:metal_block@6"
            ]
        },
        {
            "x": 5,
            "y": -2,
            "z": -3,
            "elements": [
                "bloodmagic:decorative_brick@1"
            ]
        },
        {
            "x": 3,
            "y": -4,
            "z": -4,
            "elements": [
                "bloodmagic:blood_rune@9"
            ]
        },
        {
            "x": 6,
            "y": -1,
            "z": 0,
            "elements": [
                "bloodmagic:ritual_stone@1"
            ]
        },
        {
            "x": 0,
            "y": -4,
            "z": 4,
            "elements": [
                "bloodmagic:ritual_stone@3"
            ]
        },
        {
            "x": 1,
            "y": 0,
            "z": -4,
            "elements": [
                "bloodmagic:ritual_stone@4"
            ]
        },
        {
            "x": 6,
            "y": -3,
            "z": 0,
            "elements": [
                "bloodmagic:decorative_brick@1"
            ]
        },
        {
            "x": 2,
            "y": -1,
            "z": 5,
            "elements": [
                "bloodarsenal:blood_stained_glass@0"
            ]
        },
        {
            "x": 0,
            "y": 2,
            "z": -1,
            "elements": [
                "tconevo:metal_block@6"
            ]
        },
        {
            "x": -5,
            "y": -1,
            "z": 0,
            "elements": [
                "bloodmagic:ritual_stone@1"
            ]
        },
        {
            "x": 4,
            "y": 1,
            "z": 0,
            "elements": [
                "bloodmagic:decorative_brick@1"
            ]
        },
        {
            "x": -2,
            "y": 0,
            "z": 4,
            "elements": [
                "bloodmagic:ritual_stone@1"
            ]
        },
        {
            "x": 4,
            "y": -1,
            "z": -3,
            "elements": [
                "bloodarsenal:blood_stained_glass@0"
            ]
        },
        {
            "x": 0,
            "y": -4,
            "z": 1,
            "elements": [
                "bloodmagic:blood_rune@5"
            ]
        },
        {
            "x": -6,
            "y": -1,
            "z": -2,
            "elements": [
                "bloodmagic:decorative_brick@1"
            ]
        },
        {
            "x": -4,
            "y": 0,
            "z": 0,
            "elements": [
                "bloodmagic:ritual_stone@4"
            ]
        },
        {
            "x": 6,
            "y": -2,
            "z": 0,
            "elements": [
                "bloodmagic:ritual_stone@2"
            ]
        },
        {
            "x": -2,
            "y": 1,
            "z": 1,
            "elements": [
                "modularmachinery:blockcasing@0"
            ]
        },
        {
            "x": 5,
            "y": -4,
            "z": -3,
            "elements": [
                "bloodmagic:ritual_stone@5"
            ]
        },
        {
            "x": 2,
            "y": -4,
            "z": 5,
            "elements": [
                "bloodmagic:path@6"
            ]
        },
        {
            "x": -2,
            "y": 1,
            "z": -1,
            "elements": [
                "modularmachinery:blockcasing@0"
            ]
        },
        {
            "x": 5,
            "y": -4,
            "z": 0,
            "elements": [
                "bloodmagic:decorative_brick@1"
            ]
        },
        {
            "x": -3,
            "y": -4,
            "z": 3,
            "elements": [
                "bloodmagic:blood_rune@10"
            ]
        },
        {
            "x": 6,
            "y": -1,
            "z": -1,
            "elements": [
                "bloodmagic:decorative_brick@1"
            ]
        },
        {
            "x": -2,
            "y": -1,
            "z": -5,
            "elements": [
                "bloodarsenal:blood_stained_glass@0"
            ]
        },
        {
            "x": 3,
            "y": 2,
            "z": 0,
            "elements": [
                "bloodmagic:decorative_brick@1"
            ]
        },
        {
            "x": 0,
            "y": -1,
            "z": -6,
            "elements": [
                "bloodmagic:ritual_stone@1"
            ]
        },
        {
            "x": -3,
            "y": -4,
            "z": 4,
            "elements": [
                "bloodmagic:blood_rune@9"
            ]
        },
        {
            "x": 3,
            "y": 1,
            "z": 0,
            "elements": [
                "bloodmagic:decorative_brick@1"
            ]
        },
        {
            "x": 3,
            "y": -4,
            "z": -1,
            "elements": [
                "bloodmagic:ritual_stone@4"
            ]
        },
        {
            "x": 3,
            "y": -4,
            "z": 5,
            "elements": [
                "bloodmagic:ritual_stone@5"
            ]
        },
        {
            "x": 0,
            "y": 1,
            "z": 3,
            "elements": [
                "bloodmagic:decorative_brick@1"
            ]
        },
        {
            "x": -5,
            "y": -4,
            "z": 1,
            "elements": [
                "bloodmagic:path@6"
            ]
        },
        {
            "x": 0,
            "y": -2,
            "z": -6,
            "elements": [
                "bloodmagic:ritual_stone@2"
            ]
        },
        {
            "x": -3,
            "y": -4,
            "z": -4,
            "elements": [
                "bloodmagic:blood_rune@9"
            ]
        },
        {
            "x": -4,
            "y": 0,
            "z": 1,
            "elements": [
                "bloodmagic:ritual_stone@4"
            ]
        },
        {
            "x": -2,
            "y": -1,
            "z": 6,
            "elements": [
                "bloodmagic:decorative_brick@1"
            ]
        },
        {
            "x": 1,
            "y": 2,
            "z": -1,
            "elements": [
                "tconevo:metal_block@6"
            ]
        },
        {
            "x": 4,
            "y": -2,
            "z": -4,
            "elements": [
                "bloodmagic:decorative_brick@1"
            ]
        },
        {
            "x": -4,
            "y": -1,
            "z": 3,
            "elements": [
                "bloodarsenal:blood_stained_glass@0"
            ]
        },
        {
            "x": 3,
            "y": 0,
            "z": -3,
            "elements": [
                "bloodmagic:ritual_stone@2"
            ]
        },
        {
            "x": -4,
            "y": -4,
            "z": 0,
            "elements": [
                "bloodmagic:ritual_stone@3"
            ]
        },
        {
            "x": 0,
            "y": 2,
            "z": 3,
            "elements": [
                "bloodmagic:decorative_brick@1"
            ]
        },
        {
            "x": -2,
            "y": -2,
            "z": 6,
            "elements": [
                "bloodmagic:decorative_brick@1"
            ]
        },
        {
            "x": 0,
            "y": -1,
            "z": 5,
            "elements": [
                "bloodmagic:ritual_stone@1"
            ]
        },
        {
            "x": -2,
            "y": 2,
            "z": -1,
            "elements": [
                "bloodmagic:decorative_brick@3"
            ]
        },
        {
            "x": 3,
            "y": -2,
            "z": -6,
            "elements": [
                "bloodmagic:decorative_brick@1"
            ]
        },
        {
            "x": -3,
            "y": 0,
            "z": 3,
            "elements": [
                "bloodmagic:ritual_stone@2"
            ]
        },
        {
            "x": 2,
            "y": -4,
            "z": 3,
            "elements": [
                "bloodmagic:blood_rune@9"
            ]
        },
        {
            "x": -2,
            "y": -4,
            "z": 1,
            "elements": [
                "bloodmagic:blood_rune@10"
            ]
        },
        {
            "x": 3,
            "y": -2,
            "z": 5,
            "elements": [
                "bloodmagic:decorative_brick@1"
            ]
        },
        {
            "x": 3,
            "y": -4,
            "z": 4,
            "elements": [
                "bloodmagic:blood_rune@9"
            ]
        },
        {
            "x": 3,
            "y": -4,
            "z": -3,
            "elements": [
                "bloodmagic:blood_rune@10"
            ]
        },
        {
            "x": -3,
            "y": 2,
            "z": 0,
            "elements": [
                "bloodmagic:decorative_brick@1"
            ]
        },
        {
            "x": -1,
            "y": -4,
            "z": 3,
            "elements": [
                "bloodmagic:ritual_stone@4"
            ]
        },
        {
            "x": 4,
            "y": -4,
            "z": 1,
            "elements": [
                "tconevo:metal_block@5"
            ]
        },
        {
            "x": 0,
            "y": -4,
            "z": -4,
            "elements": [
                "bloodmagic:ritual_stone@3"
            ]
        },
        {
            "x": -3,
            "y": -4,
            "z": -1,
            "elements": [
                "bloodmagic:ritual_stone@4"
            ]
        },
        {
            "x": -1,
            "y": 1,
            "z": 3,
            "elements": [
                "bloodarsenal:blood_stained_glass@0"
            ]
        },
        {
            "x": 6,
            "y": -1,
            "z": 2,
            "elements": [
                "bloodmagic:decorative_brick@1"
            ]
        },
        {
            "x": 2,
            "y": 0,
            "z": -3,
            "elements": [
                "bloodmagic:ritual_stone@2"
            ]
        },
        {
            "x": -1,
            "y": -4,
            "z": 0,
            "elements": [
                "bloodmagic:blood_rune@5"
            ]
        },
        {
            "x": 2,
            "y": -1,
            "z": -6,
            "elements": [
                "bloodmagic:decorative_brick@1"
            ]
        },
        {
            "x": 5,
            "y": -1,
            "z": 0,
            "elements": [
                "bloodmagic:ritual_stone@1"
            ]
        },
        {
            "x": 0,
            "y": -3,
            "z": 7,
            "elements": [
                "bloodmagic:ritual_stone@3"
            ]
        },
        {
            "x": -1,
            "y": 0,
            "z": -4,
            "elements": [
                "bloodmagic:ritual_stone@4"
            ]
        },
        {
            "x": -3,
            "y": -2,
            "z": 6,
            "elements": [
                "bloodmagic:decorative_brick@1"
            ]
        },
        {
            "x": 1,
            "y": 0,
            "z": 4,
            "elements": [
                "bloodmagic:ritual_stone@4"
            ]
        },
        {
            "x": 4,
            "y": 0,
            "z": 2,
            "elements": [
                "bloodmagic:ritual_stone@1"
            ]
        },
        {
            "x": 2,
            "y": 2,
            "z": 1,
            "elements": [
                "bloodmagic:decorative_brick@3"
            ]
        },
        {
            "x": 3,
            "y": 1,
            "z": 1,
            "elements": [
                "bloodarsenal:blood_stained_glass@0"
            ]
        },
        {
            "x": 4,
            "y": 0,
            "z": -1,
            "elements": [
                "bloodmagic:ritual_stone@4"
            ]
        },
        {
            "x": -5,
            "y": -1,
            "z": 1,
            "elements": [
                "bloodarsenal:blood_stained_glass@0"
            ]
        },
        {
            "x": 0,
            "y": 3,
            "z": 0,
            "elements": [
                "minecraft:beacon@0"
            ]
        },
        {
            "x": 2,
            "y": -2,
            "z": -6,
            "elements": [
                "bloodmagic:decorative_brick@1"
            ]
        },
        {
            "x": -2,
            "y": 0,
            "z": 3,
            "elements": [
                "bloodmagic:ritual_stone@2"
            ]
        },
        {
            "x": -5,
            "y": -1,
            "z": -2,
            "elements": [
                "bloodarsenal:blood_stained_glass@0"
            ]
        },
        {
            "x": 6,
            "y": -2,
            "z": 2,
            "elements": [
                "bloodmagic:decorative_brick@1"
            ]
        },
        {
            "x": 1,
            "y": -4,
            "z": -5,
            "elements": [
                "bloodmagic:path@6"
            ]
        },
        {
            "x": -1,
            "y": 1,
            "z": -3,
            "elements": [
                "bloodarsenal:blood_stained_glass@0"
            ]
        },
        {
            "x": 4,
            "y": -4,
            "z": 4,
            "elements": [
                "bloodmagic:ritual_stone@5"
            ]
        },
        {
            "x": 0,
            "y": -4,
            "z": 3,
            "elements": [
                "bloodmagic:blood_rune@5"
            ]
        },
        {
            "x": -5,
            "y": -4,
            "z": -2,
            "elements": [
                "bloodmagic:path@6"
            ]
        },
        {
            "x": 2,
            "y": -4,
            "z": -3,
            "elements": [
                "bloodmagic:blood_rune@9"
            ]
        },
        {
            "x": 6,
            "y": -1,
            "z": -2,
            "elements": [
                "bloodmagic:decorative_brick@1"
            ]
        },
        {
            "x": 0,
            "y": 2,
            "z": 0,
            "elements": [
                "tconevo:metal_block@6"
            ]
        },
        {
            "x": -4,
            "y": -4,
            "z": -1,
            "elements": [
                "tconevo:metal_block@5"
            ]
        },
        {
            "x": 2,
            "y": -4,
            "z": 0,
            "elements": [
                "bloodmagic:ritual_stone@2"
            ]
        },
        {
            "x": 1,
            "y": -1,
            "z": -6,
            "elements": [
                "bloodmagic:decorative_brick@1"
            ]
        },
        {
            "x": 0,
            "y": 2,
            "z": -3,
            "elements": [
                "bloodmagic:decorative_brick@1"
            ]
        },
        {
            "x": -2,
            "y": 0,
            "z": -4,
            "elements": [
                "bloodmagic:ritual_stone@1"
            ]
        },
        {
            "x": -3,
            "y": 1,
            "z": 0,
            "elements": [
                "bloodmagic:decorative_brick@1"
            ]
        },
        {
            "x": 0,
            "y": 1,
            "z": 0,
            "elements": [
                "modularmachinery:blocklifeessenceproviderinput@0"
            ]
        },
        {
            "x": 6,
            "y": -2,
            "z": -2,
            "elements": [
                "bloodmagic:decorative_brick@1"
            ]
        },
        {
            "x": -2,
            "y": -4,
            "z": -5,
            "elements": [
                "bloodmagic:path@6"
            ]
        },
        {
            "x": 0,
            "y": 1,
            "z": -3,
            "elements": [
                "bloodmagic:decorative_brick@1"
            ]
        },
        {
            "x": 2,
            "y": 1,
            "z": 1,
            "elements": [
                "modularmachinery:blockcasing@0"
            ]
        },
        {
            "x": -3,
            "y": -1,
            "z": -4,
            "elements": [
                "bloodarsenal:blood_stained_glass@0"
            ]
        },
        {
            "x": 2,
            "y": 0,
            "z": 4,
            "elements": [
                "bloodmagic:ritual_stone@1"
            ]
        },
        {
            "x": -3,
            "y": -2,
            "z": 5,
            "elements": [
                "bloodmagic:decorative_brick@1"
            ]
        },
        {
            "x": -4,
            "y": -4,
            "z": -2,
            "elements": [
                "bloodmagic:ritual_stone@4"
            ]
        }
    ]}