{
    "registryname": "matrix_fusioner",
    "localizedname": "§3LV2 - 矩阵聚合仪",
    "requires-blueprint": false,
    "failure-action": "still",
    "color": "c5e26b",
    "modifiers": [
        {
            "elements": "modularmachinery:blockcasing@1",
            "x": 0,
            "y": 1,
            "z": 0,
            "description": "将控制器上方紧挨着的方块换成此方块以降低配方制作时间至75%！",
            "modifier": {
                "io": "input",
                "target": "duration",
                "operation": 1,
                "multiplier": 0.75
            }
        },
        {
            "elements": "modularmachinery:blockcasing@2",
            "x": 0,
            "y": 1,
            "z": 0,
            "description": "将控制器上方紧挨着的方块换成此方块以降低配方制作时间至66%！",
            "modifier": {
                "io": "input",
                "target": "duration",
                "operation": 1,
                "multiplier": 0.66
            }
        },
        {
            "elements": "modularmachinery:blockcasing@3",
            "x": 0,
            "y": 1,
            "z": 0,
            "description": "将控制器上方紧挨着的方块换成此方块以降低配方制作时间至50%！",
            "modifier": {
                "io": "input",
                "target": "duration",
                "operation": 1,
                "multiplier": 0.5
            }
        },
        {
            "elements": "modularmachinery:blockcasing@5",
            "x": 0,
            "y": 1,
            "z": 0,
            "description": "将控制器上方紧挨着的方块换成此方块以降低配方制作时间至33%！",
            "modifier": {
                "io": "input",
                "target": "duration",
                "operation": 1,
                "multiplier": 0.33
            }
        }
    ],
    "parts": [
        {
            "x": 3,
            "y": 14,
            "z": 6,
            "elements": [
                "taiga:prometheum_block@0"
            ]
        },
        {
            "x": -1,
            "y": 2,
            "z": 0,
            "elements": [
                "taiga:tiberium_block@0"
            ]
        },
        {
            "x": 2,
            "y": -1,
            "z": -5,
            "elements": [
                "taiga:dilithium_block@0"
            ]
        },
        {
            "x": 0,
            "y": 11,
            "z": 4,
            "elements": [
                "taiga:prometheum_block@0"
            ]
        },
        {
            "x": 5,
            "y": 35,
            "z": 3,
            "elements": [
                "taiga:tiberium_block@0"
            ]
        },
        {
            "x": 1,
            "y": 35,
            "z": 1,
            "elements": [
                "taiga:osram_block@0"
            ]
        },
        {
            "x": -3,
            "y": 12,
            "z": 3,
            "elements": [
                "taiga:prometheum_block@0"
            ]
        },
        {
            "x": 5,
            "y": 34,
            "z": 4,
            "elements": [
                "taiga:dilithium_block@0"
            ]
        },
        {
            "x": -4,
            "y": 17,
            "z": -3,
            "elements": [
                "taiga:prometheum_block@0"
            ]
        },
        {
            "x": 0,
            "y": 14,
            "z": 7,
            "elements": [
                "taiga:eezo_block@0"
            ]
        },
        {
            "x": -3,
            "y": 2,
            "z": 5,
            "elements": [
                "taiga:tiberium_block@0"
            ]
        },
        {
            "x": -6,
            "y": 16,
            "z": 3,
            "elements": [
                "taiga:eezo_block@0"
            ]
        },
        {
            "x": 3,
            "y": 20,
            "z": 6,
            "elements": [
                "taiga:prometheum_block@0"
            ]
        },
        {
            "x": -1,
            "y": 16,
            "z": -4,
            "elements": [
                "taiga:eezo_block@0"
            ]
        },
        {
            "x": 2,
            "y": 35,
            "z": 3,
            "elements": [
                "taiga:osram_block@0"
            ]
        },
        {
            "x": 2,
            "y": 35,
            "z": -4,
            "elements": [
                "taiga:tiberium_block@0"
            ]
        },
        {
            "x": 5,
            "y": -1,
            "z": 1,
            "elements": [
                "taiga:tiberium_block@0"
            ]
        },
        {
            "x": 3,
            "y": 21,
            "z": 6,
            "elements": [
                "taiga:eezo_block@0"
            ]
        },
        {
            "x": -8,
            "y": 16,
            "z": 0,
            "elements": [
                "taiga:duranite_block@0"
            ]
        },
        {
            "x": 1,
            "y": 0,
            "z": 0,
            "elements": [
                "casings_all"
            ]
        },
        {
            "x": -3,
            "y": 21,
            "z": -1,
            "elements": [
                "taiga:eezo_block@0"
            ]
        },
        {
            "x": 0,
            "y": 19,
            "z": 8,
            "elements": [
                "taiga:prometheum_block@0"
            ]
        },
        {
            "x": -2,
            "y": 2,
            "z": 0,
            "elements": [
                "casings_all"
            ]
        },
        {
            "x": -2,
            "y": 23,
            "z": 2,
            "elements": [
                "taiga:prometheum_block@0"
            ]
        },
        {
            "x": 2,
            "y": 16,
            "z": -4,
            "elements": [
                "taiga:prometheum_block@0"
            ]
        },
        {
            "x": -3,
            "y": 18,
            "z": 7,
            "elements": [
                "taiga:eezo_block@0"
            ]
        },
        {
            "x": -6,
            "y": 17,
            "z": 4,
            "elements": [
                "taiga:prometheum_block@0"
            ]
        },
        {
            "x": 1,
            "y": -1,
            "z": -5,
            "elements": [
                "taiga:dilithium_block@0"
            ]
        },
        {
            "x": 2,
            "y": 15,
            "z": -3,
            "elements": [
                "taiga:prometheum_block@0"
            ]
        },
        {
            "x": 0,
            "y": 35,
            "z": -2,
            "elements": [
                "taiga:tiberium_block@0"
            ]
        },
        {
            "x": 0,
            "y": 22,
            "z": 6,
            "elements": [
                "taiga:prometheum_block@0"
            ]
        },
        {
            "x": -6,
            "y": 18,
            "z": 3,
            "elements": [
                "taiga:prometheum_block@0"
            ]
        },
        {
            "x": 2,
            "y": 32,
            "z": 4,
            "elements": [
                "casings_all"
            ]
        },
        {
            "x": -1,
            "y": 13,
            "z": -3,
            "elements": [
                "taiga:prometheum_block@0"
            ]
        },
        {
            "x": -4,
            "y": 21,
            "z": 4,
            "elements": [
                "taiga:eezo_block@0"
            ]
        },
        {
            "x": -2,
            "y": 35,
            "z": 8,
            "elements": [
                "taiga:tiberium_block@0"
            ]
        },
        {
            "x": 4,
            "y": 12,
            "z": 2,
            "elements": [
                "taiga:prometheum_block@0"
            ]
        },
        {
            "x": 4,
            "y": 32,
            "z": 1,
            "elements": [
                "taiga:tiberium_block@0"
            ]
        },
        {
            "x": -3,
            "y": 19,
            "z": 7,
            "elements": [
                "taiga:prometheum_block@0"
            ]
        },
        {
            "x": 0,
            "y": 18,
            "z": 8,
            "elements": [
                "taiga:eezo_block@0"
            ]
        },
        {
            "x": 2,
            "y": 33,
            "z": 3,
            "elements": [
                "casings_all"
            ]
        },
        {
            "x": 0,
            "y": 8,
            "z": 3,
            "elements": [
                "taiga:tiberium_block@0"
            ]
        },
        {
            "x": 2,
            "y": 0,
            "z": 0,
            "elements": [
                "casings_all"
            ]
        },
        {
            "x": -3,
            "y": 21,
            "z": 6,
            "elements": [
                "taiga:prometheum_block@0"
            ]
        },
        {
            "x": 1,
            "y": 2,
            "z": 0,
            "elements": [
                "taiga:tiberium_block@0"
            ]
        },
        {
            "x": -3,
            "y": 16,
            "z": 7,
            "elements": [
                "taiga:eezo_block@0"
            ]
        },
        {
            "x": -10,
            "y": 18,
            "z": 5,
            "elements": [
                "taiga:duranite_block@0"
            ]
        },
        {
            "x": 0,
            "y": 17,
            "z": 8,
            "elements": [
                "taiga:eezo_block@0"
            ]
        },
        {
            "x": 3,
            "y": 12,
            "z": 3,
            "elements": [
                "taiga:eezo_block@0"
            ]
        },
        {
            "x": -7,
            "y": 13,
            "z": -5,
            "elements": [
                "taiga:duranite_block@0"
            ]
        },
        {
            "x": 3,
            "y": 35,
            "z": -2,
            "elements": [
                "taiga:terrax_block@0"
            ]
        },
        {
            "x": 4,
            "y": 35,
            "z": -4,
            "elements": [
                "taiga:dilithium_block@0"
            ]
        },
        {
            "x": -3,
            "y": 20,
            "z": 6,
            "elements": [
                "taiga:prometheum_block@0"
            ]
        },
        {
            "x": -1,
            "y": 21,
            "z": -3,
            "elements": [
                "taiga:prometheum_block@0"
            ]
        },
        {
            "x": -3,
            "y": 17,
            "z": 7,
            "elements": [
                "taiga:eezo_block@0"
            ]
        },
        {
            "x": 2,
            "y": 19,
            "z": -3,
            "elements": [
                "taiga:eezo_block@0"
            ]
        },
        {
            "x": 0,
            "y": 16,
            "z": 8,
            "elements": [
                "taiga:eezo_block@0"
            ]
        },
        {
            "x": -1,
            "y": 0,
            "z": 0,
            "elements": [
                "casings_all"
            ]
        },
        {
            "x": -4,
            "y": 2,
            "z": 0,
            "elements": [
                "taiga:tiberium_block@0"
            ]
        },
        {
            "x": -6,
            "y": 16,
            "z": 0,
            "elements": [
                "taiga:prometheum_block@0"
            ]
        },
        {
            "x": -1,
            "y": 11,
            "z": 4,
            "elements": [
                "taiga:eezo_block@0"
            ]
        },
        {
            "x": 4,
            "y": 35,
            "z": 1,
            "elements": [
                "taiga:terrax_block@0"
            ]
        },
        {
            "x": -7,
            "y": -1,
            "z": 1,
            "elements": [
                "taiga:dilithium_block@0"
            ]
        },
        {
            "x": 2,
            "y": 34,
            "z": 4,
            "elements": [
                "casings_all"
            ]
        },
        {
            "x": -1,
            "y": -1,
            "z": -5,
            "elements": [
                "taiga:dilithium_block@0"
            ]
        },
        {
            "x": 2,
            "y": 29,
            "z": 3,
            "elements": [
                "taiga:tiberium_block@0"
            ]
        },
        {
            "x": 5,
            "y": -1,
            "z": 4,
            "elements": [
                "taiga:tiberium_block@0"
            ]
        },
        {
            "x": -4,
            "y": -1,
            "z": -3,
            "elements": [
                "taiga:tiberium_block@0"
            ]
        },
        {
            "x": -1,
            "y": 18,
            "z": -4,
            "elements": [
                "taiga:prometheum_block@0"
            ]
        },
        {
            "x": 6,
            "y": 35,
            "z": 5,
            "elements": [
                "taiga:dilithium_block@0"
            ]
        },
        {
            "x": 0,
            "y": 15,
            "z": 8,
            "elements": [
                "taiga:prometheum_block@0"
            ]
        },
        {
            "x": -1,
            "y": 35,
            "z": 3,
            "elements": [
                "taiga:osram_block@0"
            ]
        },
        {
            "x": 3,
            "y": 13,
            "z": 6,
            "elements": [
                "taiga:prometheum_block@0"
            ]
        },
        {
            "x": 0,
            "y": 12,
            "z": -1,
            "elements": [
                "taiga:prometheum_block@0"
            ]
        },
        {
            "x": 0,
            "y": 16,
            "z": -4,
            "elements": [
                "taiga:eezo_block@0"
            ]
        },
        {
            "x": -9,
            "y": 19,
            "z": 7,
            "elements": [
                "taiga:duranite_block@0"
            ]
        },
        {
            "x": 0,
            "y": 13,
            "z": 7,
            "elements": [
                "taiga:eezo_block@0"
            ]
        },
        {
            "x": -3,
            "y": 12,
            "z": 0,
            "elements": [
                "taiga:prometheum_block@0"
            ]
        },
        {
            "x": -3,
            "y": 15,
            "z": 7,
            "elements": [
                "taiga:prometheum_block@0"
            ]
        },
        {
            "x": 5,
            "y": -1,
            "z": 7,
            "elements": [
                "taiga:dilithium_block@0"
            ]
        },
        {
            "x": -3,
            "y": 22,
            "z": 3,
            "elements": [
                "taiga:prometheum_block@0"
            ]
        },
        {
            "x": -6,
            "y": 18,
            "z": 0,
            "elements": [
                "taiga:prometheum_block@0"
            ]
        },
        {
            "x": 0,
            "y": 12,
            "z": 6,
            "elements": [
                "taiga:eezo_block@0"
            ]
        },
        {
            "x": 2,
            "y": -1,
            "z": 4,
            "elements": [
                "taiga:osram_block@0"
            ]
        },
        {
            "x": 0,
            "y": 1,
            "z": 4,
            "elements": [
                "casings_all"
            ]
        },
        {
            "x": 7,
            "y": 35,
            "z": 0,
            "elements": [
                "taiga:dilithium_block@0"
            ]
        },
        {
            "x": 5,
            "y": 35,
            "z": 5,
            "elements": [
                "taiga:tiberium_block@0"
            ]
        },
        {
            "x": -3,
            "y": 35,
            "z": -2,
            "elements": [
                "taiga:terrax_block@0"
            ]
        },
        {
            "x": -1,
            "y": -1,
            "z": 4,
            "elements": [
                "taiga:osram_block@0"
            ]
        },
        {
            "x": 3,
            "y": 21,
            "z": -2,
            "elements": [
                "taiga:prometheum_block@0"
            ]
        },
        {
            "x": -6,
            "y": 19,
            "z": 7,
            "elements": [
                "taiga:uru_block@0"
            ]
        },
        {
            "x": -5,
            "y": 33,
            "z": 2,
            "elements": [
                "taiga:dilithium_block@0"
            ]
        },
        {
            "x": 0,
            "y": -1,
            "z": 9,
            "elements": [
                "taiga:dilithium_block@0"
            ]
        },
        {
            "x": 1,
            "y": 26,
            "z": 2,
            "elements": [
                "taiga:tiberium_block@0"
            ]
        },
        {
            "x": -7,
            "y": 35,
            "z": 4,
            "elements": [
                "taiga:dilithium_block@0"
            ]
        },
        {
            "x": 5,
            "y": 0,
            "z": 0,
            "elements": [
                "taiga:dilithium_block@0"
            ]
        },
        {
            "x": 2,
            "y": 2,
            "z": 0,
            "elements": [
                "casings_all"
            ]
        },
        {
            "x": 9,
            "y": 19,
            "z": 7,
            "elements": [
                "taiga:duranite_block@0"
            ]
        },
        {
            "x": -1,
            "y": 4,
            "z": 5,
            "elements": [
                "taiga:dilithium_block@0"
            ]
        },
        {
            "x": -5,
            "y": 34,
            "z": 2,
            "elements": [
                "taiga:dilithium_block@0"
            ]
        },
        {
            "x": 0,
            "y": 32,
            "z": 6,
            "elements": [
                "taiga:tiberium_block@0"
            ]
        },
        {
            "x": 5,
            "y": 20,
            "z": 4,
            "elements": [
                "taiga:eezo_block@0"
            ]
        },
        {
            "x": -9,
            "y": 19,
            "z": 6,
            "elements": [
                "taiga:uru_block@0"
            ]
        },
        {
            "x": -2,
            "y": 29,
            "z": 2,
            "elements": [
                "taiga:tiberium_block@0"
            ]
        },
        {
            "x": -4,
            "y": -1,
            "z": 4,
            "elements": [
                "taiga:terrax_block@0"
            ]
        },
        {
            "x": -3,
            "y": 13,
            "z": 6,
            "elements": [
                "taiga:eezo_block@0"
            ]
        },
        {
            "x": 6,
            "y": 15,
            "z": 2,
            "elements": [
                "taiga:eezo_block@0"
            ]
        },
        {
            "x": -2,
            "y": 0,
            "z": 0,
            "elements": [
                "casings_all"
            ]
        },
        {
            "x": -5,
            "y": 35,
            "z": 2,
            "elements": [
                "taiga:tiberium_block@0"
            ]
        },
        {
            "x": 1,
            "y": 19,
            "z": 8,
            "elements": [
                "taiga:eezo_block@0"
            ]
        },
        {
            "x": 0,
            "y": -1,
            "z": -5,
            "elements": [
                "taiga:dilithium_block@0"
            ]
        },
        {
            "x": 1,
            "y": 23,
            "z": 2,
            "elements": [
                "taiga:eezo_block@0"
            ]
        },
        {
            "x": -3,
            "y": 13,
            "z": -1,
            "elements": [
                "taiga:prometheum_block@0"
            ]
        },
        {
            "x": 3,
            "y": 4,
            "z": 3,
            "elements": [
                "taiga:dilithium_block@0"
            ]
        },
        {
            "x": -3,
            "y": 14,
            "z": 6,
            "elements": [
                "taiga:eezo_block@0"
            ]
        },
        {
            "x": -1,
            "y": 34,
            "z": 4,
            "elements": [
                "casings_all"
            ]
        },
        {
            "x": -7,
            "y": -1,
            "z": 4,
            "elements": [
                "taiga:dilithium_block@0"
            ]
        },
        {
            "x": 1,
            "y": 18,
            "z": 8,
            "elements": [
                "taiga:prometheum_block@0"
            ]
        },
        {
            "x": -1,
            "y": 32,
            "z": 4,
            "elements": [
                "taiga:tiberium_block@0"
            ]
        },
        {
            "x": 7,
            "y": 35,
            "z": 1,
            "elements": [
                "taiga:dilithium_block@0"
            ]
        },
        {
            "x": 0,
            "y": 5,
            "z": 4,
            "elements": [
                "taiga:tiberium_block@0"
            ]
        },
        {
            "x": -5,
            "y": 0,
            "z": 0,
            "elements": [
                "taiga:dilithium_block@0"
            ]
        },
        {
            "x": 5,
            "y": -1,
            "z": 6,
            "elements": [
                "taiga:tiberium_block@0"
            ]
        },
        {
            "x": 2,
            "y": 18,
            "z": -4,
            "elements": [
                "taiga:eezo_block@0"
            ]
        },
        {
            "x": 0,
            "y": 35,
            "z": 6,
            "elements": [
                "taiga:tiberium_block@0"
            ]
        },
        {
            "x": 2,
            "y": -1,
            "z": 7,
            "elements": [
                "taiga:tiberium_block@0"
            ]
        },
        {
            "x": 5,
            "y": -1,
            "z": -1,
            "elements": [
                "taiga:tiberium_block@0"
            ]
        },
        {
            "x": -10,
            "y": 16,
            "z": 0,
            "elements": [
                "taiga:uru_block@0"
            ]
        },
        {
            "x": 2,
            "y": 35,
            "z": 5,
            "elements": [
                "taiga:terrax_block@0"
            ]
        },
        {
            "x": -6,
            "y": 35,
            "z": -2,
            "elements": [
                "taiga:dilithium_block@0"
            ]
        },
        {
            "x": 8,
            "y": 18,
            "z": 4,
            "elements": [
                "taiga:duranite_block@0"
            ]
        },
        {
            "x": 3,
            "y": 2,
            "z": -1,
            "elements": [
                "taiga:tiberium_block@0"
            ]
        },
        {
            "x": 4,
            "y": 12,
            "z": -6,
            "elements": [
                "taiga:uru_block@0"
            ]
        },
        {
            "x": -4,
            "y": -1,
            "z": 1,
            "elements": [
                "taiga:terrax_block@0"
            ]
        },
        {
            "x": 3,
            "y": 13,
            "z": -1,
            "elements": [
                "taiga:eezo_block@0"
            ]
        },
        {
            "x": 0,
            "y": 32,
            "z": -2,
            "elements": [
                "taiga:tiberium_block@0"
            ]
        },
        {
            "x": 4,
            "y": 22,
            "z": 2,
            "elements": [
                "taiga:eezo_block@0"
            ]
        },
        {
            "x": 5,
            "y": 14,
            "z": -4,
            "elements": [
                "taiga:duranite_block@0"
            ]
        },
        {
            "x": 9,
            "y": 19,
            "z": 6,
            "elements": [
                "taiga:uru_block@0"
            ]
        },
        {
            "x": 6,
            "y": 18,
            "z": 1,
            "elements": [
                "taiga:eezo_block@0"
            ]
        },
        {
            "x": 2,
            "y": -1,
            "z": 8,
            "elements": [
                "taiga:tiberium_block@0"
            ]
        },
        {
            "x": 6,
            "y": 19,
            "z": 7,
            "elements": [
                "taiga:uru_block@0"
            ]
        },
        {
            "x": 0,
            "y": 23,
            "z": 1,
            "elements": [
                "taiga:prometheum_block@0"
            ]
        },
        {
            "x": 1,
            "y": 35,
            "z": 5,
            "elements": [
                "taiga:tiberium_block@0"
            ]
        },
        {
            "x": -3,
            "y": 35,
            "z": 7,
            "elements": [
                "taiga:tiberium_block@0"
            ]
        },
        {
            "x": 4,
            "y": 2,
            "z": 3,
            "elements": [
                "taiga:tiberium_block@0"
            ]
        },
        {
            "x": 1,
            "y": 30,
            "z": -1,
            "elements": [
                "taiga:dilithium_block@0"
            ]
        },
        {
            "x": -2,
            "y": 33,
            "z": 1,
            "elements": [
                "casings_all"
            ]
        },
        {
            "x": -5,
            "y": -1,
            "z": -3,
            "elements": [
                "taiga:dilithium_block@0"
            ]
        },
        {
            "x": -1,
            "y": 12,
            "z": 5,
            "elements": [
                "taiga:prometheum_block@0"
            ]
        },
        {
            "x": -9,
            "y": 15,
            "z": -3,
            "elements": [
                "taiga:duranite_block@0"
            ]
        },
        {
            "x": -5,
            "y": -1,
            "z": 4,
            "elements": [
                "taiga:tiberium_block@0"
            ]
        },
        {
            "x": 6,
            "y": 19,
            "z": 1,
            "elements": [
                "taiga:prometheum_block@0"
            ]
        },
        {
            "x": 1,
            "y": 29,
            "z": 1,
            "elements": [
                "taiga:tiberium_block@0"
            ]
        },
        {
            "x": 1,
            "y": 29,
            "z": 2,
            "elements": [
                "taiga:tiberium_block@0"
            ]
        },
        {
            "x": -2,
            "y": 35,
            "z": -1,
            "elements": [
                "taiga:terrax_block@0"
            ]
        },
        {
            "x": 6,
            "y": 21,
            "z": 10,
            "elements": [
                "taiga:uru_block@0"
            ]
        },
        {
            "x": 3,
            "y": 35,
            "z": 0,
            "elements": [
                "taiga:terrax_block@0"
            ]
        },
        {
            "x": -2,
            "y": 34,
            "z": 1,
            "elements": [
                "casings_all"
            ]
        },
        {
            "x": -2,
            "y": 35,
            "z": 1,
            "elements": [
                "taiga:osram_block@0"
            ]
        },
        {
            "x": 1,
            "y": 6,
            "z": 3,
            "elements": [
                "taiga:dilithium_block@0"
            ]
        },
        {
            "x": 6,
            "y": 15,
            "z": 1,
            "elements": [
                "taiga:eezo_block@0"
            ]
        },
        {
            "x": -1,
            "y": 1,
            "z": 4,
            "elements": [
                "casings_all"
            ]
        },
        {
            "x": 0,
            "y": 22,
            "z": -2,
            "elements": [
                "taiga:prometheum_block@0"
            ]
        },
        {
            "x": -3,
            "y": 14,
            "z": -2,
            "elements": [
                "taiga:eezo_block@0"
            ]
        },
        {
            "x": 7,
            "y": 35,
            "z": 2,
            "elements": [
                "taiga:dilithium_block@0"
            ]
        },
        {
            "x": -5,
            "y": 35,
            "z": -1,
            "elements": [
                "taiga:tiberium_block@0"
            ]
        },
        {
            "x": -6,
            "y": 15,
            "z": -3,
            "elements": [
                "taiga:uru_block@0"
            ]
        },
        {
            "x": -2,
            "y": -1,
            "z": -3,
            "elements": [
                "taiga:tiberium_block@0"
            ]
        },
        {
            "x": 1,
            "y": 31,
            "z": -1,
            "elements": [
                "taiga:dilithium_block@0"
            ]
        },
        {
            "x": -3,
            "y": 13,
            "z": -2,
            "elements": [
                "taiga:prometheum_block@0"
            ]
        },
        {
            "x": -2,
            "y": 35,
            "z": 2,
            "elements": [
                "taiga:osram_block@0"
            ]
        },
        {
            "x": -3,
            "y": 21,
            "z": -2,
            "elements": [
                "taiga:eezo_block@0"
            ]
        },
        {
            "x": 7,
            "y": 35,
            "z": 3,
            "elements": [
                "taiga:dilithium_block@0"
            ]
        },
        {
            "x": -2,
            "y": 34,
            "z": 2,
            "elements": [
                "casings_all"
            ]
        },
        {
            "x": -3,
            "y": 35,
            "z": 6,
            "elements": [
                "taiga:terrax_block@0"
            ]
        },
        {
            "x": 1,
            "y": 31,
            "z": 5,
            "elements": [
                "taiga:dilithium_block@0"
            ]
        },
        {
            "x": -2,
            "y": 1,
            "z": 4,
            "elements": [
                "casings_all"
            ]
        },
        {
            "x": -3,
            "y": 15,
            "z": -3,
            "elements": [
                "taiga:prometheum_block@0"
            ]
        },
        {
            "x": 4,
            "y": 21,
            "z": -1,
            "elements": [
                "taiga:prometheum_block@0"
            ]
        },
        {
            "x": 6,
            "y": 17,
            "z": 1,
            "elements": [
                "taiga:eezo_block@0"
            ]
        },
        {
            "x": -5,
            "y": 35,
            "z": 1,
            "elements": [
                "taiga:tiberium_block@0"
            ]
        },
        {
            "x": 3,
            "y": 2,
            "z": 5,
            "elements": [
                "taiga:tiberium_block@0"
            ]
        },
        {
            "x": 0,
            "y": 33,
            "z": 7,
            "elements": [
                "taiga:dilithium_block@0"
            ]
        },
        {
            "x": 1,
            "y": 32,
            "z": 2,
            "elements": [
                "casings_all"
            ]
        },
        {
            "x": -8,
            "y": 14,
            "z": -4,
            "elements": [
                "taiga:uru_block@0"
            ]
        },
        {
            "x": -3,
            "y": -1,
            "z": 4,
            "elements": [
                "taiga:terrax_block@0"
            ]
        },
        {
            "x": 4,
            "y": 20,
            "z": -1,
            "elements": [
                "taiga:eezo_block@0"
            ]
        },
        {
            "x": 3,
            "y": 22,
            "z": 1,
            "elements": [
                "taiga:eezo_block@0"
            ]
        },
        {
            "x": -4,
            "y": 14,
            "z": 5,
            "elements": [
                "taiga:eezo_block@0"
            ]
        },
        {
            "x": 6,
            "y": 16,
            "z": 1,
            "elements": [
                "taiga:eezo_block@0"
            ]
        },
        {
            "x": -2,
            "y": 22,
            "z": 0,
            "elements": [
                "taiga:eezo_block@0"
            ]
        },
        {
            "x": 5,
            "y": -1,
            "z": -3,
            "elements": [
                "taiga:dilithium_block@0"
            ]
        },
        {
            "x": 3,
            "y": 14,
            "z": -2,
            "elements": [
                "taiga:eezo_block@0"
            ]
        },
        {
            "x": -1,
            "y": -1,
            "z": 8,
            "elements": [
                "taiga:tiberium_block@0"
            ]
        },
        {
            "x": 1,
            "y": 35,
            "z": 2,
            "elements": [
                "taiga:osram_block@0"
            ]
        },
        {
            "x": 6,
            "y": 35,
            "z": 3,
            "elements": [
                "taiga:tiberium_block@0"
            ]
        },
        {
            "x": 1,
            "y": 28,
            "z": 1,
            "elements": [
                "taiga:dilithium_block@0"
            ]
        },
        {
            "x": -2,
            "y": 35,
            "z": 5,
            "elements": [
                "taiga:terrax_block@0"
            ]
        },
        {
            "x": -4,
            "y": 12,
            "z": 3,
            "elements": [
                "taiga:eezo_block@0"
            ]
        },
        {
            "x": 9,
            "y": 15,
            "z": -2,
            "elements": [
                "taiga:uru_block@0"
            ]
        },
        {
            "x": 4,
            "y": 2,
            "z": 0,
            "elements": [
                "taiga:tiberium_block@0"
            ]
        },
        {
            "x": -2,
            "y": 32,
            "z": 2,
            "elements": [
                "taiga:tiberium_block@0"
            ]
        },
        {
            "x": 3,
            "y": 21,
            "z": -1,
            "elements": [
                "taiga:eezo_block@0"
            ]
        },
        {
            "x": -5,
            "y": 14,
            "z": 3,
            "elements": [
                "taiga:eezo_block@0"
            ]
        },
        {
            "x": 1,
            "y": 2,
            "z": 3,
            "elements": [
                "casings_all"
            ]
        },
        {
            "x": 0,
            "y": 26,
            "z": 1,
            "elements": [
                "taiga:tiberium_block@0"
            ]
        },
        {
            "x": 3,
            "y": 20,
            "z": -2,
            "elements": [
                "taiga:eezo_block@0"
            ]
        },
        {
            "x": 3,
            "y": 13,
            "z": -2,
            "elements": [
                "taiga:prometheum_block@0"
            ]
        },
        {
            "x": -2,
            "y": 29,
            "z": 1,
            "elements": [
                "taiga:tiberium_block@0"
            ]
        },
        {
            "x": -2,
            "y": -1,
            "z": 4,
            "elements": [
                "taiga:osram_block@0"
            ]
        },
        {
            "x": -3,
            "y": 35,
            "z": -1,
            "elements": [
                "taiga:terrax_block@0"
            ]
        },
        {
            "x": 4,
            "y": -1,
            "z": -3,
            "elements": [
                "taiga:tiberium_block@0"
            ]
        },
        {
            "x": 1,
            "y": 27,
            "z": 1,
            "elements": [
                "taiga:dilithium_block@0"
            ]
        },
        {
            "x": -2,
            "y": 32,
            "z": 1,
            "elements": [
                "taiga:tiberium_block@0"
            ]
        },
        {
            "x": -2,
            "y": 33,
            "z": 2,
            "elements": [
                "casings_all"
            ]
        },
        {
            "x": 3,
            "y": 16,
            "z": 7,
            "elements": [
                "taiga:eezo_block@0"
            ]
        },
        {
            "x": 4,
            "y": 35,
            "z": 2,
            "elements": [
                "taiga:tiberium_block@0"
            ]
        },
        {
            "x": -3,
            "y": 4,
            "z": 3,
            "elements": [
                "taiga:dilithium_block@0"
            ]
        },
        {
            "x": 4,
            "y": 32,
            "z": 4,
            "elements": [
                "taiga:tiberium_block@0"
            ]
        },
        {
            "x": -1,
            "y": -1,
            "z": -3,
            "elements": [
                "taiga:tiberium_block@0"
            ]
        },
        {
            "x": -6,
            "y": 35,
            "z": -1,
            "elements": [
                "taiga:dilithium_block@0"
            ]
        },
        {
            "x": 3,
            "y": 17,
            "z": 7,
            "elements": [
                "taiga:prometheum_block@0"
            ]
        },
        {
            "x": -5,
            "y": 20,
            "z": 2,
            "elements": [
                "taiga:eezo_block@0"
            ]
        },
        {
            "x": -4,
            "y": 13,
            "z": 4,
            "elements": [
                "taiga:eezo_block@0"
            ]
        },
        {
            "x": -6,
            "y": 35,
            "z": 6,
            "elements": [
                "taiga:dilithium_block@0"
            ]
        },
        {
            "x": -2,
            "y": 12,
            "z": 0,
            "elements": [
                "taiga:eezo_block@0"
            ]
        },
        {
            "x": 1,
            "y": 23,
            "z": 1,
            "elements": [
                "taiga:eezo_block@0"
            ]
        },
        {
            "x": -5,
            "y": 14,
            "z": 0,
            "elements": [
                "taiga:prometheum_block@0"
            ]
        },
        {
            "x": 0,
            "y": 33,
            "z": 0,
            "elements": [
                "casings_all"
            ]
        },
        {
            "x": -3,
            "y": 32,
            "z": -1,
            "elements": [
                "taiga:tiberium_block@0"
            ]
        },
        {
            "x": -5,
            "y": 1,
            "z": 4,
            "elements": [
                "taiga:dilithium_block@0"
            ]
        },
        {
            "x": 4,
            "y": 32,
            "z": 2,
            "elements": [
                "taiga:tiberium_block@0"
            ]
        },
        {
            "x": 5,
            "y": 19,
            "z": 5,
            "elements": [
                "taiga:eezo_block@0"
            ]
        },
        {
            "x": -5,
            "y": 21,
            "z": 2,
            "elements": [
                "taiga:prometheum_block@0"
            ]
        },
        {
            "x": 2,
            "y": 12,
            "z": 5,
            "elements": [
                "taiga:prometheum_block@0"
            ]
        },
        {
            "x": 0,
            "y": 2,
            "z": 3,
            "elements": [
                "casings_all"
            ]
        },
        {
            "x": 10,
            "y": 17,
            "z": 1,
            "elements": [
                "taiga:duranite_block@0"
            ]
        },
        {
            "x": 3,
            "y": 15,
            "z": 7,
            "elements": [
                "taiga:prometheum_block@0"
            ]
        },
        {
            "x": 4,
            "y": 22,
            "z": 1,
            "elements": [
                "taiga:eezo_block@0"
            ]
        },
        {
            "x": 4,
            "y": 35,
            "z": 5,
            "elements": [
                "taiga:terrax_block@0"
            ]
        },
        {
            "x": 0,
            "y": 35,
            "z": 0,
            "elements": [
                "taiga:osram_block@0"
            ]
        },
        {
            "x": -3,
            "y": 20,
            "z": -2,
            "elements": [
                "taiga:eezo_block@0"
            ]
        },
        {
            "x": 2,
            "y": 1,
            "z": -3,
            "elements": [
                "taiga:dilithium_block@0"
            ]
        },
        {
            "x": 2,
            "y": -1,
            "z": -3,
            "elements": [
                "taiga:tiberium_block@0"
            ]
        },
        {
            "x": 0,
            "y": -1,
            "z": 4,
            "elements": [
                "taiga:osram_block@0"
            ]
        },
        {
            "x": -2,
            "y": 23,
            "z": 1,
            "elements": [
                "taiga:prometheum_block@0"
            ]
        },
        {
            "x": -5,
            "y": 35,
            "z": 7,
            "elements": [
                "taiga:dilithium_block@0"
            ]
        },
        {
            "x": 4,
            "y": 12,
            "z": 1,
            "elements": [
                "taiga:prometheum_block@0"
            ]
        },
        {
            "x": 2,
            "y": 1,
            "z": 4,
            "elements": [
                "casings_all"
            ]
        },
        {
            "x": 0,
            "y": 35,
            "z": -1,
            "elements": [
                "taiga:tiberium_block@0"
            ]
        },
        {
            "x": -1,
            "y": 2,
            "z": 3,
            "elements": [
                "casings_all"
            ]
        },
        {
            "x": -1,
            "y": 22,
            "z": 5,
            "elements": [
                "taiga:eezo_block@0"
            ]
        },
        {
            "x": -5,
            "y": 20,
            "z": 0,
            "elements": [
                "taiga:prometheum_block@0"
            ]
        },
        {
            "x": 1,
            "y": 32,
            "z": 1,
            "elements": [
                "casings_all"
            ]
        },
        {
            "x": 1,
            "y": -1,
            "z": -3,
            "elements": [
                "taiga:tiberium_block@0"
            ]
        },
        {
            "x": -2,
            "y": 0,
            "z": 3,
            "elements": [
                "casings_all"
            ]
        },
        {
            "x": 10,
            "y": 17,
            "z": 2,
            "elements": [
                "taiga:uru_block@0"
            ]
        },
        {
            "x": -2,
            "y": -1,
            "z": 9,
            "elements": [
                "taiga:dilithium_block@0"
            ]
        },
        {
            "x": 0,
            "y": 21,
            "z": 10,
            "elements": [
                "taiga:uru_block@0"
            ]
        },
        {
            "x": -4,
            "y": 20,
            "z": 5,
            "elements": [
                "taiga:prometheum_block@0"
            ]
        },
        {
            "x": 0,
            "y": 21,
            "z": 7,
            "elements": [
                "taiga:eezo_block@0"
            ]
        },
        {
            "x": -1,
            "y": 5,
            "z": 4,
            "elements": [
                "taiga:tiberium_block@0"
            ]
        },
        {
            "x": 3,
            "y": 19,
            "z": 7,
            "elements": [
                "taiga:eezo_block@0"
            ]
        },
        {
            "x": 3,
            "y": 32,
            "z": -1,
            "elements": [
                "taiga:tiberium_block@0"
            ]
        },
        {
            "x": 1,
            "y": -1,
            "z": 4,
            "elements": [
                "taiga:osram_block@0"
            ]
        },
        {
            "x": 1,
            "y": 1,
            "z": 4,
            "elements": [
                "casings_all"
            ]
        },
        {
            "x": 3,
            "y": 12,
            "z": 1,
            "elements": [
                "taiga:eezo_block@0"
            ]
        },
        {
            "x": 1,
            "y": 35,
            "z": -1,
            "elements": [
                "taiga:tiberium_block@0"
            ]
        },
        {
            "x": 0,
            "y": 12,
            "z": -2,
            "elements": [
                "taiga:eezo_block@0"
            ]
        },
        {
            "x": -2,
            "y": 2,
            "z": 3,
            "elements": [
                "taiga:tiberium_block@0"
            ]
        },
        {
            "x": 6,
            "y": 35,
            "z": 0,
            "elements": [
                "taiga:tiberium_block@0"
            ]
        },
        {
            "x": -6,
            "y": -1,
            "z": 4,
            "elements": [
                "taiga:tiberium_block@0"
            ]
        },
        {
            "x": 3,
            "y": 18,
            "z": 7,
            "elements": [
                "taiga:prometheum_block@0"
            ]
        },
        {
            "x": -7,
            "y": -1,
            "z": 2,
            "elements": [
                "taiga:dilithium_block@0"
            ]
        },
        {
            "x": 0,
            "y": -1,
            "z": -3,
            "elements": [
                "taiga:tiberium_block@0"
            ]
        },
        {
            "x": 0,
            "y": 20,
            "z": 7,
            "elements": [
                "taiga:prometheum_block@0"
            ]
        },
        {
            "x": 0,
            "y": 22,
            "z": -1,
            "elements": [
                "taiga:prometheum_block@0"
            ]
        },
        {
            "x": 0,
            "y": 1,
            "z": -3,
            "elements": [
                "taiga:dilithium_block@0"
            ]
        },
        {
            "x": 1,
            "y": -1,
            "z": 9,
            "elements": [
                "taiga:dilithium_block@0"
            ]
        },
        {
            "x": -2,
            "y": 21,
            "z": 10,
            "elements": [
                "taiga:uru_block@0"
            ]
        },
        {
            "x": 2,
            "y": 2,
            "z": 6,
            "elements": [
                "taiga:tiberium_block@0"
            ]
        },
        {
            "x": -5,
            "y": 35,
            "z": 6,
            "elements": [
                "taiga:tiberium_block@0"
            ]
        },
        {
            "x": -4,
            "y": 35,
            "z": 0,
            "elements": [
                "taiga:terrax_block@0"
            ]
        },
        {
            "x": 1,
            "y": -1,
            "z": 7,
            "elements": [
                "taiga:tiberium_block@0"
            ]
        },
        {
            "x": -5,
            "y": 20,
            "z": 1,
            "elements": [
                "taiga:eezo_block@0"
            ]
        },
        {
            "x": 5,
            "y": 16,
            "z": 5,
            "elements": [
                "taiga:eezo_block@0"
            ]
        },
        {
            "x": 0,
            "y": 5,
            "z": 2,
            "elements": [
                "taiga:palladium_block@0"
            ]
        },
        {
            "x": 4,
            "y": 33,
            "z": 6,
            "elements": [
                "taiga:dilithium_block@0"
            ]
        },
        {
            "x": -1,
            "y": 29,
            "z": 0,
            "elements": [
                "taiga:tiberium_block@0"
            ]
        },
        {
            "x": -5,
            "y": 13,
            "z": 2,
            "elements": [
                "taiga:eezo_block@0"
            ]
        },
        {
            "x": 5,
            "y": 19,
            "z": 0,
            "elements": [
                "taiga:eezo_block@0"
            ]
        },
        {
            "x": 6,
            "y": -1,
            "z": 4,
            "elements": [
                "taiga:tiberium_block@0"
            ]
        },
        {
            "x": 4,
            "y": 2,
            "z": 4,
            "elements": [
                "taiga:tiberium_block@0"
            ]
        },
        {
            "x": 10,
            "y": 17,
            "z": 3,
            "elements": [
                "taiga:duranite_block@0"
            ]
        },
        {
            "x": 1,
            "y": 22,
            "z": 5,
            "elements": [
                "taiga:prometheum_block@0"
            ]
        },
        {
            "x": 5,
            "y": 15,
            "z": 5,
            "elements": [
                "taiga:eezo_block@0"
            ]
        },
        {
            "x": 1,
            "y": 35,
            "z": 8,
            "elements": [
                "taiga:tiberium_block@0"
            ]
        },
        {
            "x": -2,
            "y": 11,
            "z": 2,
            "elements": [
                "taiga:eezo_block@0"
            ]
        },
        {
            "x": -4,
            "y": -1,
            "z": 2,
            "elements": [
                "taiga:tiberium_block@0"
            ]
        },
        {
            "x": -5,
            "y": 19,
            "z": -1,
            "elements": [
                "taiga:prometheum_block@0"
            ]
        },
        {
            "x": 5,
            "y": 20,
            "z": 0,
            "elements": [
                "taiga:eezo_block@0"
            ]
        },
        {
            "x": -3,
            "y": 22,
            "z": 1,
            "elements": [
                "taiga:eezo_block@0"
            ]
        },
        {
            "x": -2,
            "y": 19,
            "z": 7,
            "elements": [
                "taiga:eezo_block@0"
            ]
        },
        {
            "x": 1,
            "y": 23,
            "z": 3,
            "elements": [
                "taiga:eezo_block@0"
            ]
        },
        {
            "x": -2,
            "y": 35,
            "z": 6,
            "elements": [
                "taiga:terrax_block@0"
            ]
        },
        {
            "x": -5,
            "y": 18,
            "z": -2,
            "elements": [
                "taiga:prometheum_block@0"
            ]
        },
        {
            "x": 1,
            "y": 27,
            "z": 3,
            "elements": [
                "taiga:dilithium_block@0"
            ]
        },
        {
            "x": 10,
            "y": 18,
            "z": 4,
            "elements": [
                "taiga:uru_block@0"
            ]
        },
        {
            "x": 2,
            "y": 22,
            "z": 0,
            "elements": [
                "taiga:eezo_block@0"
            ]
        },
        {
            "x": 4,
            "y": 22,
            "z": 3,
            "elements": [
                "taiga:prometheum_block@0"
            ]
        },
        {
            "x": 3,
            "y": -1,
            "z": 4,
            "elements": [
                "taiga:terrax_block@0"
            ]
        },
        {
            "x": 8,
            "y": 16,
            "z": 0,
            "elements": [
                "taiga:duranite_block@0"
            ]
        },
        {
            "x": 7,
            "y": 21,
            "z": 9,
            "elements": [
                "taiga:duranite_block@0"
            ]
        },
        {
            "x": 2,
            "y": 22,
            "z": 5,
            "elements": [
                "taiga:eezo_block@0"
            ]
        },
        {
            "x": 6,
            "y": 13,
            "z": -6,
            "elements": [
                "taiga:uru_block@0"
            ]
        },
        {
            "x": -1,
            "y": 32,
            "z": 0,
            "elements": [
                "taiga:tiberium_block@0"
            ]
        },
        {
            "x": -5,
            "y": 17,
            "z": -1,
            "elements": [
                "taiga:prometheum_block@0"
            ]
        },
        {
            "x": 4,
            "y": 0,
            "z": -2,
            "elements": [
                "taiga:dilithium_block@0"
            ]
        },
        {
            "x": -5,
            "y": -1,
            "z": 2,
            "elements": [
                "taiga:tiberium_block@0"
            ]
        },
        {
            "x": 5,
            "y": 17,
            "z": 5,
            "elements": [
                "taiga:eezo_block@0"
            ]
        },
        {
            "x": 6,
            "y": 35,
            "z": 1,
            "elements": [
                "taiga:tiberium_block@0"
            ]
        },
        {
            "x": 1,
            "y": 5,
            "z": 4,
            "elements": [
                "taiga:tiberium_block@0"
            ]
        },
        {
            "x": -1,
            "y": 33,
            "z": 0,
            "elements": [
                "casings_all"
            ]
        },
        {
            "x": 3,
            "y": 35,
            "z": 1,
            "elements": [
                "taiga:tiberium_block@0"
            ]
        },
        {
            "x": -5,
            "y": 16,
            "z": -2,
            "elements": [
                "taiga:prometheum_block@0"
            ]
        },
        {
            "x": 0,
            "y": 34,
            "z": -3,
            "elements": [
                "taiga:dilithium_block@0"
            ]
        },
        {
            "x": 1,
            "y": 12,
            "z": -2,
            "elements": [
                "taiga:eezo_block@0"
            ]
        },
        {
            "x": -1,
            "y": 30,
            "z": 5,
            "elements": [
                "taiga:dilithium_block@0"
            ]
        },
        {
            "x": 1,
            "y": 29,
            "z": 3,
            "elements": [
                "taiga:tiberium_block@0"
            ]
        },
        {
            "x": 0,
            "y": 35,
            "z": -5,
            "elements": [
                "taiga:dilithium_block@0"
            ]
        },
        {
            "x": -5,
            "y": -1,
            "z": 7,
            "elements": [
                "taiga:dilithium_block@0"
            ]
        },
        {
            "x": 2,
            "y": -1,
            "z": 2,
            "elements": [
                "taiga:osram_block@0"
            ]
        },
        {
            "x": -5,
            "y": 35,
            "z": 5,
            "elements": [
                "taiga:tiberium_block@0"
            ]
        },
        {
            "x": 4,
            "y": 14,
            "z": 5,
            "elements": [
                "taiga:eezo_block@0"
            ]
        },
        {
            "x": 4,
            "y": 18,
            "z": 7,
            "elements": [
                "taiga:prometheum_block@0"
            ]
        },
        {
            "x": 1,
            "y": 35,
            "z": 9,
            "elements": [
                "taiga:dilithium_block@0"
            ]
        },
        {
            "x": -1,
            "y": 34,
            "z": 0,
            "elements": [
                "casings_all"
            ]
        },
        {
            "x": -2,
            "y": 12,
            "z": 4,
            "elements": [
                "taiga:prometheum_block@0"
            ]
        },
        {
            "x": 2,
            "y": 1,
            "z": 7,
            "elements": [
                "taiga:dilithium_block@0"
            ]
        },
        {
            "x": 0,
            "y": 33,
            "z": -3,
            "elements": [
                "taiga:dilithium_block@0"
            ]
        },
        {
            "x": 2,
            "y": -1,
            "z": 9,
            "elements": [
                "taiga:dilithium_block@0"
            ]
        },
        {
            "x": 5,
            "y": 15,
            "z": 0,
            "elements": [
                "taiga:eezo_block@0"
            ]
        },
        {
            "x": 1,
            "y": 28,
            "z": 3,
            "elements": [
                "taiga:dilithium_block@0"
            ]
        },
        {
            "x": 4,
            "y": 13,
            "z": 5,
            "elements": [
                "taiga:prometheum_block@0"
            ]
        },
        {
            "x": 3,
            "y": 17,
            "z": -3,
            "elements": [
                "taiga:prometheum_block@0"
            ]
        },
        {
            "x": -5,
            "y": 20,
            "z": 4,
            "elements": [
                "taiga:prometheum_block@0"
            ]
        },
        {
            "x": 5,
            "y": 14,
            "z": 0,
            "elements": [
                "taiga:eezo_block@0"
            ]
        },
        {
            "x": 5,
            "y": -1,
            "z": 2,
            "elements": [
                "taiga:tiberium_block@0"
            ]
        },
        {
            "x": -2,
            "y": -1,
            "z": 7,
            "elements": [
                "taiga:tiberium_block@0"
            ]
        },
        {
            "x": 4,
            "y": 35,
            "z": 6,
            "elements": [
                "taiga:tiberium_block@0"
            ]
        },
        {
            "x": -1,
            "y": 2,
            "z": 6,
            "elements": [
                "taiga:tiberium_block@0"
            ]
        },
        {
            "x": -2,
            "y": 35,
            "z": 9,
            "elements": [
                "taiga:dilithium_block@0"
            ]
        },
        {
            "x": -8,
            "y": 17,
            "z": 2,
            "elements": [
                "taiga:duranite_block@0"
            ]
        },
        {
            "x": 4,
            "y": 12,
            "z": 3,
            "elements": [
                "taiga:prometheum_block@0"
            ]
        },
        {
            "x": -5,
            "y": 19,
            "z": 4,
            "elements": [
                "taiga:prometheum_block@0"
            ]
        },
        {
            "x": 0,
            "y": 35,
            "z": -3,
            "elements": [
                "taiga:tiberium_block@0"
            ]
        },
        {
            "x": 3,
            "y": 18,
            "z": -3,
            "elements": [
                "taiga:eezo_block@0"
            ]
        },
        {
            "x": 4,
            "y": 35,
            "z": 8,
            "elements": [
                "taiga:dilithium_block@0"
            ]
        },
        {
            "x": 0,
            "y": 13,
            "z": -6,
            "elements": [
                "taiga:uru_block@0"
            ]
        },
        {
            "x": -2,
            "y": 23,
            "z": 3,
            "elements": [
                "taiga:eezo_block@0"
            ]
        },
        {
            "x": 0,
            "y": 21,
            "z": -3,
            "elements": [
                "taiga:eezo_block@0"
            ]
        },
        {
            "x": 1,
            "y": 21,
            "z": 10,
            "elements": [
                "taiga:duranite_block@0"
            ]
        },
        {
            "x": 6,
            "y": 35,
            "z": -2,
            "elements": [
                "taiga:dilithium_block@0"
            ]
        },
        {
            "x": -3,
            "y": 35,
            "z": 1,
            "elements": [
                "taiga:tiberium_block@0"
            ]
        },
        {
            "x": 1,
            "y": 32,
            "z": 3,
            "elements": [
                "casings_all"
            ]
        },
        {
            "x": -1,
            "y": 31,
            "z": 5,
            "elements": [
                "taiga:dilithium_block@0"
            ]
        },
        {
            "x": -3,
            "y": 30,
            "z": 1,
            "elements": [
                "taiga:dilithium_block@0"
            ]
        },
        {
            "x": -3,
            "y": 19,
            "z": -3,
            "elements": [
                "taiga:prometheum_block@0"
            ]
        },
        {
            "x": 0,
            "y": 20,
            "z": -3,
            "elements": [
                "taiga:eezo_block@0"
            ]
        },
        {
            "x": -2,
            "y": 1,
            "z": 2,
            "elements": [
                "casings_all"
            ]
        },
        {
            "x": 3,
            "y": 31,
            "z": 1,
            "elements": [
                "taiga:dilithium_block@0"
            ]
        },
        {
            "x": -2,
            "y": -1,
            "z": -1,
            "elements": [
                "taiga:terrax_block@0"
            ]
        },
        {
            "x": 3,
            "y": 15,
            "z": -3,
            "elements": [
                "taiga:prometheum_block@0"
            ]
        },
        {
            "x": 3,
            "y": 16,
            "z": -3,
            "elements": [
                "taiga:prometheum_block@0"
            ]
        },
        {
            "x": 3,
            "y": 35,
            "z": -3,
            "elements": [
                "taiga:tiberium_block@0"
            ]
        },
        {
            "x": 0,
            "y": -1,
            "z": 2,
            "elements": [
                "taiga:vibranium_block@0"
            ]
        },
        {
            "x": 0,
            "y": 2,
            "z": -2,
            "elements": [
                "taiga:tiberium_block@0"
            ]
        },
        {
            "x": 4,
            "y": 2,
            "z": 1,
            "elements": [
                "taiga:tiberium_block@0"
            ]
        },
        {
            "x": -5,
            "y": 15,
            "z": 4,
            "elements": [
                "taiga:eezo_block@0"
            ]
        },
        {
            "x": 7,
            "y": 19,
            "z": 6,
            "elements": [
                "taiga:duranite_block@0"
            ]
        },
        {
            "x": -10,
            "y": 17,
            "z": 2,
            "elements": [
                "taiga:uru_block@0"
            ]
        },
        {
            "x": -1,
            "y": 13,
            "z": 7,
            "elements": [
                "taiga:eezo_block@0"
            ]
        },
        {
            "x": 4,
            "y": -1,
            "z": 7,
            "elements": [
                "taiga:tiberium_block@0"
            ]
        },
        {
            "x": 1,
            "y": 11,
            "z": 4,
            "elements": [
                "taiga:prometheum_block@0"
            ]
        },
        {
            "x": 4,
            "y": 35,
            "z": 3,
            "elements": [
                "taiga:terrax_block@0"
            ]
        },
        {
            "x": 1,
            "y": 2,
            "z": 1,
            "elements": [
                "casings_all"
            ]
        },
        {
            "x": -5,
            "y": -1,
            "z": -1,
            "elements": [
                "taiga:tiberium_block@0"
            ]
        },
        {
            "x": -4,
            "y": 35,
            "z": 5,
            "elements": [
                "taiga:terrax_block@0"
            ]
        },
        {
            "x": 4,
            "y": 13,
            "z": 4,
            "elements": [
                "taiga:prometheum_block@0"
            ]
        },
        {
            "x": -3,
            "y": 17,
            "z": -3,
            "elements": [
                "taiga:prometheum_block@0"
            ]
        },
        {
            "x": -1,
            "y": -1,
            "z": 2,
            "elements": [
                "taiga:osram_block@0"
            ]
        },
        {
            "x": -3,
            "y": 18,
            "z": -3,
            "elements": [
                "taiga:eezo_block@0"
            ]
        },
        {
            "x": -5,
            "y": 22,
            "z": 10,
            "elements": [
                "taiga:duranite_block@0"
            ]
        },
        {
            "x": -1,
            "y": 2,
            "z": -2,
            "elements": [
                "taiga:tiberium_block@0"
            ]
        },
        {
            "x": 1,
            "y": 30,
            "z": 5,
            "elements": [
                "taiga:dilithium_block@0"
            ]
        },
        {
            "x": -4,
            "y": 17,
            "z": 7,
            "elements": [
                "taiga:eezo_block@0"
            ]
        },
        {
            "x": 0,
            "y": 29,
            "z": 1,
            "elements": [
                "taiga:tiberium_block@0"
            ]
        },
        {
            "x": -4,
            "y": 20,
            "z": 6,
            "elements": [
                "taiga:prometheum_block@0"
            ]
        },
        {
            "x": 3,
            "y": 35,
            "z": -4,
            "elements": [
                "taiga:dilithium_block@0"
            ]
        },
        {
            "x": 1,
            "y": 35,
            "z": 3,
            "elements": [
                "taiga:osram_block@0"
            ]
        },
        {
            "x": 0,
            "y": 34,
            "z": 7,
            "elements": [
                "taiga:dilithium_block@0"
            ]
        },
        {
            "x": -2,
            "y": 22,
            "z": 5,
            "elements": [
                "taiga:eezo_block@0"
            ]
        },
        {
            "x": -1,
            "y": -1,
            "z": 9,
            "elements": [
                "taiga:dilithium_block@0"
            ]
        },
        {
            "x": 1,
            "y": 35,
            "z": 6,
            "elements": [
                "taiga:terrax_block@0"
            ]
        },
        {
            "x": 4,
            "y": -1,
            "z": -1,
            "elements": [
                "taiga:terrax_block@0"
            ]
        },
        {
            "x": -2,
            "y": 5,
            "z": 2,
            "elements": [
                "taiga:tiberium_block@0"
            ]
        },
        {
            "x": -5,
            "y": 14,
            "z": 1,
            "elements": [
                "taiga:eezo_block@0"
            ]
        },
        {
            "x": -1,
            "y": 35,
            "z": 5,
            "elements": [
                "taiga:tiberium_block@0"
            ]
        },
        {
            "x": -6,
            "y": 15,
            "z": 2,
            "elements": [
                "taiga:eezo_block@0"
            ]
        },
        {
            "x": 1,
            "y": 7,
            "z": 3,
            "elements": [
                "taiga:dilithium_block@0"
            ]
        },
        {
            "x": -2,
            "y": -1,
            "z": 2,
            "elements": [
                "taiga:osram_block@0"
            ]
        },
        {
            "x": 10,
            "y": 16,
            "z": -1,
            "elements": [
                "taiga:duranite_block@0"
            ]
        },
        {
            "x": -5,
            "y": 14,
            "z": 4,
            "elements": [
                "taiga:eezo_block@0"
            ]
        },
        {
            "x": 0,
            "y": 13,
            "z": -3,
            "elements": [
                "taiga:prometheum_block@0"
            ]
        },
        {
            "x": -2,
            "y": 2,
            "z": -2,
            "elements": [
                "taiga:tiberium_block@0"
            ]
        },
        {
            "x": 4,
            "y": 13,
            "z": -1,
            "elements": [
                "taiga:prometheum_block@0"
            ]
        },
        {
            "x": 0,
            "y": 14,
            "z": -3,
            "elements": [
                "taiga:eezo_block@0"
            ]
        },
        {
            "x": -2,
            "y": 15,
            "z": 7,
            "elements": [
                "taiga:prometheum_block@0"
            ]
        },
        {
            "x": -2,
            "y": 23,
            "z": 11,
            "elements": [
                "taiga:uru_block@0"
            ]
        },
        {
            "x": 0,
            "y": 35,
            "z": -4,
            "elements": [
                "taiga:tiberium_block@0"
            ]
        },
        {
            "x": 4,
            "y": 20,
            "z": 5,
            "elements": [
                "taiga:eezo_block@0"
            ]
        },
        {
            "x": 6,
            "y": -1,
            "z": 3,
            "elements": [
                "taiga:tiberium_block@0"
            ]
        },
        {
            "x": 0,
            "y": 35,
            "z": 1,
            "elements": [
                "taiga:osram_block@0"
            ]
        },
        {
            "x": 4,
            "y": 21,
            "z": 5,
            "elements": [
                "taiga:eezo_block@0"
            ]
        },
        {
            "x": -1,
            "y": 12,
            "z": 6,
            "elements": [
                "taiga:eezo_block@0"
            ]
        },
        {
            "x": -4,
            "y": 14,
            "z": 6,
            "elements": [
                "taiga:prometheum_block@0"
            ]
        },
        {
            "x": 1,
            "y": -1,
            "z": 2,
            "elements": [
                "taiga:osram_block@0"
            ]
        },
        {
            "x": 4,
            "y": 32,
            "z": 3,
            "elements": [
                "taiga:tiberium_block@0"
            ]
        },
        {
            "x": -2,
            "y": 22,
            "z": 4,
            "elements": [
                "taiga:prometheum_block@0"
            ]
        },
        {
            "x": 7,
            "y": 19,
            "z": 5,
            "elements": [
                "taiga:uru_block@0"
            ]
        },
        {
            "x": -5,
            "y": 21,
            "z": 3,
            "elements": [
                "taiga:prometheum_block@0"
            ]
        },
        {
            "x": 1,
            "y": 2,
            "z": -2,
            "elements": [
                "taiga:tiberium_block@0"
            ]
        },
        {
            "x": 1,
            "y": 11,
            "z": 3,
            "elements": [
                "taiga:prometheum_block@0"
            ]
        },
        {
            "x": -8,
            "y": 18,
            "z": 4,
            "elements": [
                "taiga:duranite_block@0"
            ]
        },
        {
            "x": -5,
            "y": 20,
            "z": 3,
            "elements": [
                "taiga:prometheum_block@0"
            ]
        },
        {
            "x": -2,
            "y": 34,
            "z": 7,
            "elements": [
                "taiga:dilithium_block@0"
            ]
        },
        {
            "x": 1,
            "y": 6,
            "z": 1,
            "elements": [
                "taiga:dilithium_block@0"
            ]
        },
        {
            "x": 10,
            "y": 18,
            "z": 5,
            "elements": [
                "taiga:duranite_block@0"
            ]
        },
        {
            "x": 4,
            "y": 21,
            "z": 4,
            "elements": [
                "taiga:prometheum_block@0"
            ]
        },
        {
            "x": -4,
            "y": 21,
            "z": 0,
            "elements": [
                "taiga:prometheum_block@0"
            ]
        },
        {
            "x": 2,
            "y": -1,
            "z": -1,
            "elements": [
                "taiga:terrax_block@0"
            ]
        },
        {
            "x": 1,
            "y": 23,
            "z": 4,
            "elements": [
                "taiga:prometheum_block@0"
            ]
        },
        {
            "x": -2,
            "y": 16,
            "z": 8,
            "elements": [
                "taiga:eezo_block@0"
            ]
        },
        {
            "x": -4,
            "y": 14,
            "z": -2,
            "elements": [
                "taiga:prometheum_block@0"
            ]
        },
        {
            "x": 0,
            "y": 2,
            "z": 1,
            "elements": [
                "casings_all"
            ]
        },
        {
            "x": 3,
            "y": 35,
            "z": 6,
            "elements": [
                "taiga:terrax_block@0"
            ]
        },
        {
            "x": -1,
            "y": 12,
            "z": -2,
            "elements": [
                "taiga:eezo_block@0"
            ]
        },
        {
            "x": -5,
            "y": 19,
            "z": 5,
            "elements": [
                "taiga:prometheum_block@0"
            ]
        },
        {
            "x": 1,
            "y": 35,
            "z": -2,
            "elements": [
                "taiga:terrax_block@0"
            ]
        },
        {
            "x": -8,
            "y": 20,
            "z": 8,
            "elements": [
                "taiga:uru_block@0"
            ]
        },
        {
            "x": 1,
            "y": 13,
            "z": -6,
            "elements": [
                "taiga:duranite_block@0"
            ]
        },
        {
            "x": 2,
            "y": 12,
            "z": 0,
            "elements": [
                "taiga:prometheum_block@0"
            ]
        },
        {
            "x": 0,
            "y": -1,
            "z": 7,
            "elements": [
                "taiga:tiberium_block@0"
            ]
        },
        {
            "x": -5,
            "y": 16,
            "z": 6,
            "elements": [
                "taiga:prometheum_block@0"
            ]
        },
        {
            "x": 6,
            "y": 35,
            "z": 6,
            "elements": [
                "taiga:dilithium_block@0"
            ]
        },
        {
            "x": -5,
            "y": 15,
            "z": -1,
            "elements": [
                "taiga:prometheum_block@0"
            ]
        },
        {
            "x": -4,
            "y": 0,
            "z": -2,
            "elements": [
                "taiga:dilithium_block@0"
            ]
        },
        {
            "x": -6,
            "y": 17,
            "z": 2,
            "elements": [
                "taiga:prometheum_block@0"
            ]
        },
        {
            "x": 3,
            "y": -1,
            "z": 2,
            "elements": [
                "taiga:tiberium_block@0"
            ]
        },
        {
            "x": -1,
            "y": -1,
            "z": -1,
            "elements": [
                "taiga:tiberium_block@0"
            ]
        },
        {
            "x": -5,
            "y": 20,
            "z": 8,
            "elements": [
                "taiga:duranite_block@0"
            ]
        },
        {
            "x": -5,
            "y": 1,
            "z": 2,
            "elements": [
                "taiga:dilithium_block@0"
            ]
        },
        {
            "x": -2,
            "y": 12,
            "z": 5,
            "elements": [
                "taiga:prometheum_block@0"
            ]
        },
        {
            "x": 1,
            "y": 16,
            "z": 8,
            "elements": [
                "taiga:eezo_block@0"
            ]
        },
        {
            "x": -2,
            "y": 13,
            "z": -6,
            "elements": [
                "taiga:uru_block@0"
            ]
        },
        {
            "x": 1,
            "y": 23,
            "z": 11,
            "elements": [
                "taiga:duranite_block@0"
            ]
        },
        {
            "x": -1,
            "y": 6,
            "z": 1,
            "elements": [
                "taiga:dilithium_block@0"
            ]
        },
        {
            "x": 0,
            "y": -1,
            "z": -1,
            "elements": [
                "taiga:tiberium_block@0"
            ]
        },
        {
            "x": 0,
            "y": 2,
            "z": 6,
            "elements": [
                "taiga:tiberium_block@0"
            ]
        },
        {
            "x": 6,
            "y": 16,
            "z": 2,
            "elements": [
                "taiga:eezo_block@0"
            ]
        },
        {
            "x": 3,
            "y": -1,
            "z": 7,
            "elements": [
                "taiga:tiberium_block@0"
            ]
        },
        {
            "x": 8,
            "y": 14,
            "z": -4,
            "elements": [
                "taiga:uru_block@0"
            ]
        },
        {
            "x": -5,
            "y": 33,
            "z": 4,
            "elements": [
                "taiga:dilithium_block@0"
            ]
        },
        {
            "x": 3,
            "y": 20,
            "z": 9,
            "elements": [
                "taiga:duranite_block@0"
            ]
        },
        {
            "x": -2,
            "y": 2,
            "z": 1,
            "elements": [
                "taiga:tiberium_block@0"
            ]
        },
        {
            "x": 2,
            "y": 34,
            "z": 0,
            "elements": [
                "casings_all"
            ]
        },
        {
            "x": -5,
            "y": 16,
            "z": 5,
            "elements": [
                "taiga:prometheum_block@0"
            ]
        },
        {
            "x": 4,
            "y": 22,
            "z": 10,
            "elements": [
                "taiga:uru_block@0"
            ]
        },
        {
            "x": 5,
            "y": 35,
            "z": 0,
            "elements": [
                "taiga:tiberium_block@0"
            ]
        },
        {
            "x": 1,
            "y": 12,
            "z": 5,
            "elements": [
                "taiga:prometheum_block@0"
            ]
        },
        {
            "x": -3,
            "y": 4,
            "z": 1,
            "elements": [
                "taiga:dilithium_block@0"
            ]
        },
        {
            "x": -6,
            "y": -1,
            "z": 2,
            "elements": [
                "taiga:tiberium_block@0"
            ]
        },
        {
            "x": 3,
            "y": 35,
            "z": 8,
            "elements": [
                "taiga:dilithium_block@0"
            ]
        },
        {
            "x": -5,
            "y": 15,
            "z": 5,
            "elements": [
                "taiga:eezo_block@0"
            ]
        },
        {
            "x": 2,
            "y": 2,
            "z": -2,
            "elements": [
                "taiga:tiberium_block@0"
            ]
        },
        {
            "x": -5,
            "y": 35,
            "z": 4,
            "elements": [
                "taiga:tiberium_block@0"
            ]
        },
        {
            "x": -5,
            "y": 18,
            "z": 5,
            "elements": [
                "taiga:prometheum_block@0"
            ]
        },
        {
            "x": -2,
            "y": 0,
            "z": 1,
            "elements": [
                "casings_all"
            ]
        },
        {
            "x": 1,
            "y": -1,
            "z": -1,
            "elements": [
                "taiga:tiberium_block@0"
            ]
        },
        {
            "x": 2,
            "y": 33,
            "z": 0,
            "elements": [
                "casings_all"
            ]
        },
        {
            "x": 0,
            "y": 23,
            "z": 2,
            "elements": [
                "taiga:eezo_block@0"
            ]
        },
        {
            "x": -1,
            "y": 2,
            "z": 1,
            "elements": [
                "casings_all"
            ]
        },
        {
            "x": -7,
            "y": 15,
            "z": -1,
            "elements": [
                "taiga:uru_block@0"
            ]
        },
        {
            "x": 5,
            "y": 34,
            "z": 0,
            "elements": [
                "taiga:dilithium_block@0"
            ]
        },
        {
            "x": 6,
            "y": 18,
            "z": 2,
            "elements": [
                "taiga:eezo_block@0"
            ]
        },
        {
            "x": -3,
            "y": -1,
            "z": 2,
            "elements": [
                "taiga:tiberium_block@0"
            ]
        },
        {
            "x": -5,
            "y": 34,
            "z": 4,
            "elements": [
                "taiga:dilithium_block@0"
            ]
        },
        {
            "x": -4,
            "y": 32,
            "z": 4,
            "elements": [
                "taiga:tiberium_block@0"
            ]
        },
        {
            "x": -2,
            "y": 35,
            "z": -2,
            "elements": [
                "taiga:terrax_block@0"
            ]
        },
        {
            "x": 5,
            "y": 33,
            "z": 0,
            "elements": [
                "taiga:dilithium_block@0"
            ]
        },
        {
            "x": -1,
            "y": 3,
            "z": -1,
            "elements": [
                "taiga:dilithium_block@0"
            ]
        },
        {
            "x": 2,
            "y": 35,
            "z": 0,
            "elements": [
                "taiga:osram_block@0"
            ]
        },
        {
            "x": -5,
            "y": 17,
            "z": 5,
            "elements": [
                "taiga:prometheum_block@0"
            ]
        },
        {
            "x": -3,
            "y": 35,
            "z": -4,
            "elements": [
                "taiga:dilithium_block@0"
            ]
        },
        {
            "x": -2,
            "y": 18,
            "z": 8,
            "elements": [
                "taiga:eezo_block@0"
            ]
        },
        {
            "x": 0,
            "y": 15,
            "z": 2,
            "elements": [
                "minecraft:glowstone@0"
            ]
        },
        {
            "x": 6,
            "y": -1,
            "z": -1,
            "elements": [
                "taiga:dilithium_block@0"
            ]
        },
        {
            "x": -2,
            "y": -1,
            "z": -5,
            "elements": [
                "taiga:dilithium_block@0"
            ]
        },
        {
            "x": 0,
            "y": 19,
            "z": -4,
            "elements": [
                "taiga:prometheum_block@0"
            ]
        },
        {
            "x": -3,
            "y": 20,
            "z": 9,
            "elements": [
                "taiga:duranite_block@0"
            ]
        },
        {
            "x": 1,
            "y": 34,
            "z": 4,
            "elements": [
                "casings_all"
            ]
        },
        {
            "x": -2,
            "y": 2,
            "z": 6,
            "elements": [
                "taiga:tiberium_block@0"
            ]
        },
        {
            "x": -2,
            "y": 34,
            "z": 3,
            "elements": [
                "casings_all"
            ]
        },
        {
            "x": -3,
            "y": -1,
            "z": 7,
            "elements": [
                "taiga:tiberium_block@0"
            ]
        },
        {
            "x": -4,
            "y": 2,
            "z": 1,
            "elements": [
                "taiga:tiberium_block@0"
            ]
        },
        {
            "x": 1,
            "y": 32,
            "z": 4,
            "elements": [
                "taiga:tiberium_block@0"
            ]
        },
        {
            "x": 3,
            "y": 4,
            "z": 1,
            "elements": [
                "taiga:dilithium_block@0"
            ]
        },
        {
            "x": 0,
            "y": 17,
            "z": -4,
            "elements": [
                "taiga:prometheum_block@0"
            ]
        },
        {
            "x": 2,
            "y": 32,
            "z": 0,
            "elements": [
                "casings_all"
            ]
        },
        {
            "x": 4,
            "y": 33,
            "z": -2,
            "elements": [
                "taiga:dilithium_block@0"
            ]
        },
        {
            "x": -3,
            "y": 35,
            "z": 8,
            "elements": [
                "taiga:dilithium_block@0"
            ]
        },
        {
            "x": 0,
            "y": 18,
            "z": -4,
            "elements": [
                "taiga:prometheum_block@0"
            ]
        },
        {
            "x": -1,
            "y": 35,
            "z": 0,
            "elements": [
                "taiga:osram_block@0"
            ]
        },
        {
            "x": 1,
            "y": 35,
            "z": 4,
            "elements": [
                "taiga:osram_block@0"
            ]
        },
        {
            "x": 5,
            "y": 35,
            "z": 1,
            "elements": [
                "taiga:tiberium_block@0"
            ]
        },
        {
            "x": -2,
            "y": 35,
            "z": 3,
            "elements": [
                "taiga:osram_block@0"
            ]
        },
        {
            "x": 6,
            "y": 15,
            "z": -3,
            "elements": [
                "taiga:uru_block@0"
            ]
        },
        {
            "x": -2,
            "y": 33,
            "z": 4,
            "elements": [
                "casings_all"
            ]
        },
        {
            "x": -2,
            "y": 1,
            "z": 7,
            "elements": [
                "taiga:dilithium_block@0"
            ]
        },
        {
            "x": 3,
            "y": -1,
            "z": -1,
            "elements": [
                "taiga:terrax_block@0"
            ]
        },
        {
            "x": 4,
            "y": 20,
            "z": 9,
            "elements": [
                "taiga:uru_block@0"
            ]
        },
        {
            "x": -2,
            "y": 32,
            "z": 3,
            "elements": [
                "taiga:tiberium_block@0"
            ]
        },
        {
            "x": -3,
            "y": 12,
            "z": 1,
            "elements": [
                "taiga:eezo_block@0"
            ]
        },
        {
            "x": -6,
            "y": 13,
            "z": -6,
            "elements": [
                "taiga:uru_block@0"
            ]
        },
        {
            "x": -7,
            "y": 35,
            "z": 0,
            "elements": [
                "taiga:dilithium_block@0"
            ]
        },
        {
            "x": 1,
            "y": 11,
            "z": 2,
            "elements": [
                "taiga:prometheum_block@0"
            ]
        },
        {
            "x": 0,
            "y": 13,
            "z": 2,
            "elements": [
                "minecraft:glowstone@0"
            ]
        },
        {
            "x": -4,
            "y": -1,
            "z": 7,
            "elements": [
                "taiga:tiberium_block@0"
            ]
        },
        {
            "x": -2,
            "y": 33,
            "z": 3,
            "elements": [
                "casings_all"
            ]
        },
        {
            "x": -1,
            "y": 23,
            "z": 0,
            "elements": [
                "taiga:eezo_block@0"
            ]
        },
        {
            "x": -4,
            "y": 0,
            "z": 6,
            "elements": [
                "taiga:dilithium_block@0"
            ]
        },
        {
            "x": -2,
            "y": 32,
            "z": 4,
            "elements": [
                "casings_all"
            ]
        },
        {
            "x": 3,
            "y": 19,
            "z": -3,
            "elements": [
                "taiga:eezo_block@0"
            ]
        },
        {
            "x": 1,
            "y": 3,
            "z": -1,
            "elements": [
                "taiga:dilithium_block@0"
            ]
        },
        {
            "x": 0,
            "y": -1,
            "z": 5,
            "elements": [
                "taiga:tiberium_block@0"
            ]
        },
        {
            "x": 1,
            "y": 33,
            "z": 4,
            "elements": [
                "casings_all"
            ]
        },
        {
            "x": 0,
            "y": 8,
            "z": 1,
            "elements": [
                "taiga:tiberium_block@0"
            ]
        },
        {
            "x": 4,
            "y": 35,
            "z": -2,
            "elements": [
                "taiga:tiberium_block@0"
            ]
        },
        {
            "x": -1,
            "y": -1,
            "z": 7,
            "elements": [
                "taiga:tiberium_block@0"
            ]
        },
        {
            "x": 9,
            "y": 15,
            "z": -3,
            "elements": [
                "taiga:duranite_block@0"
            ]
        },
        {
            "x": 0,
            "y": 11,
            "z": 2,
            "elements": [
                "taiga:eezo_block@0"
            ]
        },
        {
            "x": 6,
            "y": -1,
            "z": 2,
            "elements": [
                "taiga:tiberium_block@0"
            ]
        },
        {
            "x": -4,
            "y": -1,
            "z": -1,
            "elements": [
                "taiga:terrax_block@0"
            ]
        },
        {
            "x": -6,
            "y": 16,
            "z": 1,
            "elements": [
                "taiga:prometheum_block@0"
            ]
        },
        {
            "x": 2,
            "y": 34,
            "z": 2,
            "elements": [
                "casings_all"
            ]
        },
        {
            "x": 2,
            "y": 2,
            "z": 1,
            "elements": [
                "taiga:tiberium_block@0"
            ]
        },
        {
            "x": -3,
            "y": 35,
            "z": -3,
            "elements": [
                "taiga:tiberium_block@0"
            ]
        },
        {
            "x": -4,
            "y": 20,
            "z": -2,
            "elements": [
                "taiga:prometheum_block@0"
            ]
        },
        {
            "x": 3,
            "y": -1,
            "z": 5,
            "elements": [
                "taiga:terrax_block@0"
            ]
        },
        {
            "x": 1,
            "y": 5,
            "z": 2,
            "elements": [
                "taiga:tiberium_block@0"
            ]
        },
        {
            "x": -4,
            "y": 32,
            "z": 0,
            "elements": [
                "taiga:tiberium_block@0"
            ]
        },
        {
            "x": 0,
            "y": 1,
            "z": 7,
            "elements": [
                "taiga:dilithium_block@0"
            ]
        },
        {
            "x": 2,
            "y": 0,
            "z": 1,
            "elements": [
                "casings_all"
            ]
        },
        {
            "x": -4,
            "y": 13,
            "z": -1,
            "elements": [
                "taiga:prometheum_block@0"
            ]
        },
        {
            "x": 1,
            "y": 4,
            "z": 5,
            "elements": [
                "taiga:dilithium_block@0"
            ]
        },
        {
            "x": -2,
            "y": 34,
            "z": 4,
            "elements": [
                "casings_all"
            ]
        },
        {
            "x": -3,
            "y": -1,
            "z": -1,
            "elements": [
                "taiga:terrax_block@0"
            ]
        },
        {
            "x": 2,
            "y": 32,
            "z": 2,
            "elements": [
                "taiga:tiberium_block@0"
            ]
        },
        {
            "x": -2,
            "y": 29,
            "z": 3,
            "elements": [
                "taiga:tiberium_block@0"
            ]
        },
        {
            "x": -5,
            "y": 35,
            "z": 3,
            "elements": [
                "taiga:tiberium_block@0"
            ]
        },
        {
            "x": 0,
            "y": 9,
            "z": 2,
            "elements": [
                "taiga:solarium_block@0"
            ]
        },
        {
            "x": 5,
            "y": 34,
            "z": 2,
            "elements": [
                "taiga:dilithium_block@0"
            ]
        },
        {
            "x": -6,
            "y": 18,
            "z": 1,
            "elements": [
                "taiga:prometheum_block@0"
            ]
        },
        {
            "x": -6,
            "y": 19,
            "z": 2,
            "elements": [
                "taiga:prometheum_block@0"
            ]
        },
        {
            "x": 1,
            "y": 29,
            "z": 4,
            "elements": [
                "taiga:tiberium_block@0"
            ]
        },
        {
            "x": 1,
            "y": 3,
            "z": 5,
            "elements": [
                "taiga:dilithium_block@0"
            ]
        },
        {
            "x": 0,
            "y": 35,
            "z": 8,
