{
    "registryname": "matrix_balancer",
    "localizedname": "§6LV4 - 矩阵平衡仪",
    "requires-blueprint": false,
    "failure-action": "still",
    "color": "2f2f2f",
    "modifiers": [
        {
            "elements": "modularmachinery:blockcasing@1",
            "x": 0,
            "y": 1,
            "z": 0,
            "description": "将控制器上方紧挨着的方块换成此方块以降低配方制作时间至75%！",
            "modifier": {
                "io": "input",
                "target": "duration",
                "operation": 1,
                "multiplier": 0.75
            }
        },
        {
            "elements": "modularmachinery:blockcasing@2",
            "x": 0,
            "y": 1,
            "z": 0,
            "description": "将控制器上方紧挨着的方块换成此方块以降低配方制作时间至66%！",
            "modifier": {
                "io": "input",
                "target": "duration",
                "operation": 1,
                "multiplier": 0.66
            }
        },
        {
            "elements": "modularmachinery:blockcasing@3",
            "x": 0,
            "y": 1,
            "z": 0,
            "description": "将控制器上方紧挨着的方块换成此方块以降低配方制作时间至50%！",
            "modifier": {
                "io": "input",
                "target": "duration",
                "operation": 1,
                "multiplier": 0.5
            }
        },
        {
            "elements": "modularmachinery:blockcasing@5",
            "x": 0,
            "y": 1,
            "z": 0,
            "description": "将控制器上方紧挨着的方块换成此方块以降低配方制作时间至33%！",
            "modifier": {
                "io": "input",
                "target": "duration",
                "operation": 1,
                "multiplier": 0.33
            }
        }
    ],
    "parts": [
        {
            "x": 0,
            "y": 0,
            "z": 0,
            "elements": [
                "modularmachinery:blockcontroller@2"
            ]
        },
        {
            "x": 8,
            "y": 29,
            "z": -4,
            "elements": [
                "minecraft:quartz_block@0"
            ]
        },
        {
            "x": -3,
            "y": 0,
            "z": 5,
            "elements": [
                "chisel:arcane_stone1@10"
            ]
        },
        {
            "x": 7,
            "y": 4,
            "z": 2,
            "elements": [
                "minecraft:sea_lantern@0"
            ]
        },
        {
            "x": -3,
            "y": 2,
            "z": 5,
            "elements": [
                "casings_all"
            ]
        },
        {
            "x": -6,
            "y": 16,
            "z": 3,
            "elements": [
                "minecraft:stained_glass@3"
            ]
        },
        {
            "x": -3,
            "y": 7,
            "z": 7,
            "elements": [
                "thaumcraft:slab_arcane_brick@0"
            ]
        },
        {
            "x": -2,
            "y": 11,
            "z": 9,
            "elements": [
                "minecraft:quartz_block@0"
            ]
        },
        {
            "x": -2,
            "y": 7,
            "z": -5,
            "elements": [
                "minecraft:quartz_stairs@6"
            ]
        },
        {
            "x": -4,
            "y": 19,
            "z": 4,
            "elements": [
                "thaumcraft:slab_arcane_brick@0"
            ]
        },
        {
            "x": -2,
            "y": 5,
            "z": 11,
            "elements": [
                "minecraft:stone_slab@7"
            ]
        },
        {
            "x": -3,
            "y": 26,
            "z": 6,
            "elements": [
                "thaumcraft:slab_arcane_brick@0"
            ]
        },
        {
            "x": 6,
            "y": 5,
            "z": 4,
            "elements": [
                "betternether:bone_wall@0"
            ]
        },
        {
            "x": -1,
            "y": 5,
            "z": -5,
            "elements": [
                "minecraft:concrete@7"
            ]
        },
        {
            "x": 7,
            "y": 5,
            "z": 2,
            "elements": [
                "minecraft:stone_slab@7"
            ]
        },
        {
            "x": -9,
            "y": 19,
            "z": -5,
            "elements": [
                "minecraft:stained_glass_pane@11"
            ]
        },
        {
            "x": 6,
            "y": 6,
            "z": 3,
            "elements": [
                "minecraft:stone_slab@7"
            ]
        },
        {
            "x": 1,
            "y": 0,
            "z": 0,
            "elements": [
                "chisel:arcane_stone1@10"
            ]
        },
        {
            "x": 7,
            "y": 6,
            "z": 2,
            "elements": [
                "minecraft:quartz_stairs@5"
            ]
        },
        {
            "x": -6,
            "y": 12,
            "z": 3,
            "elements": [
                "minecraft:quartz_block@0"
            ]
        },
        {
            "x": -2,
            "y": 0,
            "z": 5,
            "elements": [
                "chisel:glass@0"
            ]
        },
        {
            "x": 5,
            "y": 32,
            "z": 4,
            "elements": [
                "minecraft:stained_glass@3"
            ]
        },
        {
            "x": 8,
            "y": 27,
            "z": -4,
            "elements": [
                "minecraft:quartz_block@0"
            ]
        },
        {
            "x": -9,
            "y": 21,
            "z": -5,
            "elements": [
                "minecraft:stained_glass_pane@11"
            ]
        },
        {
            "x": 7,
            "y": 7,
            "z": 2,
            "elements": [
                "minecraft:quartz_stairs@0"
            ]
        },
        {
            "x": 0,
            "y": 7,
            "z": 4,
            "elements": [
                "minecraft:stained_glass@3"
            ]
        },
        {
            "x": -2,
            "y": 7,
            "z": 11,
            "elements": [
                "minecraft:quartz_stairs@2"
            ]
        },
        {
            "x": -2,
            "y": 2,
            "z": 5,
            "elements": [
                "chisel:glass@0"
            ]
        },
        {
            "x": 0,
            "y": 5,
            "z": -5,
            "elements": [
                "minecraft:concrete@7"
            ]
        },
        {
            "x": -4,
            "y": 21,
            "z": 4,
            "elements": [
                "thaumcraft:slab_arcane_brick@8"
            ]
        },
        {
            "x": 9,
            "y": 6,
            "z": 3,
            "elements": [
                "minecraft:concrete@7"
            ]
        },
        {
            "x": 4,
            "y": 12,
            "z": 2,
            "elements": [
                "quark:dark_prismarine_wall@0"
            ]
        },
        {
            "x": -7,
            "y": 10,
            "z": 5,
            "elements": [
                "minecraft:quartz_stairs@0"
            ]
        },
        {
            "x": 10,
            "y": 6,
            "z": 2,
            "elements": [
                "minecraft:quartz_stairs@5"
            ]
        },
        {
            "x": -9,
            "y": 10,
            "z": 5,
            "elements": [
                "minecraft:quartz_stairs@5"
            ]
        },
        {
            "x": -9,
            "y": 23,
            "z": -5,
            "elements": [
                "minecraft:quartz_block@0"
            ]
        },
        {
            "x": -3,
            "y": 6,
            "z": 5,
            "elements": [
                "casings_all"
            ]
        },
        {
            "x": -3,
            "y": 21,
            "z": 6,
            "elements": [
                "thaumcraft:slab_arcane_brick@8"
            ]
        },
        {
            "x": 7,
            "y": 8,
            "z": 2,
            "elements": [
                "minecraft:quartz_stairs@4"
            ]
        },
        {
            "x": -5,
            "y": 0,
            "z": 5,
            "elements": [
                "thaumcraft:slab_arcane_brick@0"
            ]
        },
        {
            "x": 7,
            "y": 9,
            "z": 2,
            "elements": [
                "minecraft:quartz_stairs@1"
            ]
        },
        {
            "x": -2,
            "y": 15,
            "z": 9,
            "elements": [
                "minecraft:stone_slab@15"
            ]
        },
        {
            "x": -2,
            "y": 11,
            "z": -5,
            "elements": [
                "minecraft:quartz_stairs@2"
            ]
        },
        {
            "x": 1,
            "y": 13,
            "z": 2,
            "elements": [
                "minecraft:quartz_block@0"
            ]
        },
        {
            "x": -1,
            "y": 9,
            "z": -5,
            "elements": [
                "minecraft:concrete@7"
            ]
        },
        {
            "x": -8,
            "y": 21,
            "z": -5,
            "elements": [
                "minecraft:stained_glass_pane@11"
            ]
        },
        {
            "x": -1,
            "y": 11,
            "z": -3,
            "elements": [
                "minecraft:concrete@7"
            ]
        },
        {
            "x": 6,
            "y": 10,
            "z": 3,
            "elements": [
                "minecraft:concrete@7"
            ]
        },
        {
            "x": 10,
            "y": 7,
            "z": 2,
            "elements": [
                "minecraft:quartz_stairs@0"
            ]
        },
        {
            "x": -3,
            "y": 20,
            "z": 6,
            "elements": [
                "minecraft:quartz_block@0"
            ]
        },
        {
            "x": 4,
            "y": 10,
            "z": 2,
            "elements": [
                "quark:dark_prismarine_wall@0"
            ]
        },
        {
            "x": -7,
            "y": 12,
            "z": 5,
            "elements": [
                "minecraft:quartz_block@0"
            ]
        },
        {
            "x": 1,
            "y": 12,
            "z": 2,
            "elements": [
                "tconevo:metal_block@2"
            ]
        },
        {
            "x": -6,
            "y": 10,
            "z": 5,
            "elements": [
                "minecraft:quartz_block@0"
            ]
        },
        {
            "x": -1,
            "y": 0,
            "z": 0,
            "elements": [
                "casings_upgrade"
            ]
        },
        {
            "x": -6,
            "y": 16,
            "z": 0,
            "elements": [
                "minecraft:stained_glass_pane@11"
            ]
        },
        {
            "x": -9,
            "y": 25,
            "z": -5,
            "elements": [
                "minecraft:quartz_block@0"
            ]
        },
        {
            "x": 1,
            "y": 15,
            "z": 2,
            "elements": [
                "quark:dark_prismarine_wall@0"
            ]
        },
        {
            "x": -9,
            "y": 8,
            "z": 5,
            "elements": [
                "minecraft:quartz_stairs@0"
            ]
        },
        {
            "x": 0,
            "y": 0,
            "z": 5,
            "elements": [
                "chisel:laboratory@10"
            ]
        },
        {
            "x": -3,
            "y": 19,
            "z": 6,
            "elements": [
                "thaumcraft:slab_arcane_brick@0"
            ]
        },
        {
            "x": -6,
            "y": 16,
            "z": 7,
            "elements": [
                "minecraft:stained_glass_pane@11"
            ]
        },
        {
            "x": -3,
            "y": 4,
            "z": 5,
            "elements": [
                "casings_all"
            ]
        },
        {
            "x": 1,
            "y": 14,
            "z": 2,
            "elements": [
                "quark:dark_prismarine_wall@0"
            ]
        },
        {
            "x": 7,
            "y": 11,
            "z": 2,
            "elements": [
                "minecraft:quartz_stairs@4"
            ]
        },
        {
            "x": 3,
            "y": 0,
            "z": 3,
            "elements": [
                "chisel:arcane_stone1@10"
            ]
        },
        {
            "x": -1,
            "y": 7,
            "z": -5,
            "elements": [
                "minecraft:concrete@7"
            ]
        },
        {
            "x": -2,
            "y": 13,
            "z": 9,
            "elements": [
                "thaumcraft:slab_arcane_brick@0"
            ]
        },
        {
            "x": -6,
            "y": 16,
            "z": 6,
            "elements": [
                "minecraft:quartz_block@0"
            ]
        },
        {
            "x": 3,
            "y": 7,
            "z": 6,
            "elements": [
                "thaumcraft:slab_arcane_brick@0"
            ]
        },
        {
            "x": -3,
            "y": 11,
            "z": 6,
            "elements": [
                "betternether:bone_wall@0"
            ]
        },
        {
            "x": -1,
            "y": 6,
            "z": 12,
            "elements": [
                "minecraft:concrete@7"
            ]
        },
        {
            "x": -9,
            "y": 7,
            "z": 4,
            "elements": [
                "minecraft:concrete@7"
            ]
        },
        {
            "x": 9,
            "y": 9,
            "z": 2,
            "elements": [
                "minecraft:quartz_stairs@4"
            ]
        },
        {
            "x": 2,
            "y": -1,
            "z": 4,
            "elements": [
                "chisel:glass@0"
            ]
        },
        {
            "x": -3,
            "y": 3,
            "z": 4,
            "elements": [
                "chisel:glass@0"
            ]
        },
        {
            "x": -3,
            "y": 10,
            "z": 6,
            "elements": [
                "betternether:bone_wall@0"
            ]
        },
        {
            "x": 7,
            "y": 12,
            "z": 2,
            "elements": [
                "minecraft:quartz_stairs@1"
            ]
        },
        {
            "x": -1,
            "y": -1,
            "z": 4,
            "elements": [
                "minecraft:stained_glass@3"
            ]
        },
        {
            "x": -1,
            "y": 7,
            "z": 12,
            "elements": [
                "minecraft:concrete@7"
            ]
        },
        {
            "x": -4,
            "y": 10,
            "z": 5,
            "elements": [
                "minecraft:quartz_block@0"
            ]
        },
        {
            "x": -3,
            "y": 8,
            "z": 5,
            "elements": [
                "quark:dark_prismarine_wall@0"
            ]
        },
        {
            "x": -10,
            "y": 10,
            "z": 5,
            "elements": [
                "minecraft:quartz_stairs@0"
            ]
        },
        {
            "x": -3,
            "y": 5,
            "z": 4,
            "elements": [
                "chisel:glass@0"
            ]
        },
        {
            "x": -3,
            "y": 32,
            "z": 9,
            "elements": [
                "minecraft:quartz_block@0"
            ]
        },
        {
            "x": -4,
            "y": 27,
            "z": 4,
            "elements": [
                "extendedcrafting:storage@2"
            ]
        },
        {
            "x": -12,
            "y": 7,
            "z": 4,
            "elements": [
                "betternether:bone_wall@0"
            ]
        },
        {
            "x": -12,
            "y": 8,
            "z": 3,
            "elements": [
                "betternether:bone_wall@0"
            ]
        },
        {
            "x": 2,
            "y": 0,
            "z": 5,
            "elements": [
                "chisel:arcane_stone1@10"
            ]
        },
        {
            "x": 2,
            "y": 2,
            "z": 5,
            "elements": [
                "casings_all"
            ]
        },
        {
            "x": -3,
            "y": 12,
            "z": 6,
            "elements": [
                "minecraft:sea_lantern@0"
            ]
        },
        {
            "x": 10,
            "y": 9,
            "z": 2,
            "elements": [
                "minecraft:quartz_stairs@1"
            ]
        },
        {
            "x": -1,
            "y": 5,
            "z": 12,
            "elements": [
                "minecraft:concrete@7"
            ]
        },
        {
            "x": 1,
            "y": 7,
            "z": -5,
            "elements": [
                "minecraft:quartz_stairs@6"
            ]
        },
        {
            "x": 1,
            "y": 11,
            "z": 9,
            "elements": [
                "minecraft:quartz_block@0"
            ]
        },
        {
            "x": -6,
            "y": 12,
            "z": 5,
            "elements": [
                "minecraft:quartz_block@0"
            ]
        },
        {
            "x": -9,
            "y": 9,
            "z": 4,
            "elements": [
                "minecraft:concrete@7"
            ]
        },
        {
            "x": -3,
            "y": 13,
            "z": 6,
            "elements": [
                "quark:dark_prismarine_wall@0"
            ]
        },
        {
            "x": 10,
            "y": 8,
            "z": 2,
            "elements": [
                "minecraft:quartz_stairs@4"
            ]
        },
        {
            "x": -3,
            "y": 10,
            "z": 5,
            "elements": [
                "chisel:arcane_stone1@10"
            ]
        },
        {
            "x": -2,
            "y": 0,
            "z": 0,
            "elements": [
                "chisel:arcane_stone1@10"
            ]
        },
        {
            "x": 9,
            "y": 10,
            "z": 2,
            "elements": [
                "minecraft:quartz_stairs@1"
            ]
        },
        {
            "x": 5,
            "y": 31,
            "z": 5,
            "elements": [
                "betternether:bone_wall@0"
            ]
        },
        {
            "x": -7,
            "y": 6,
            "z": 5,
            "elements": [
                "minecraft:quartz_stairs@1"
            ]
        },
        {
            "x": -1,
            "y": 0,
            "z": 5,
            "elements": [
                "chisel:laboratory@10"
            ]
        },
        {
            "x": -3,
            "y": 14,
            "z": 6,
            "elements": [
                "quark:dark_prismarine_wall@0"
            ]
        },
        {
            "x": 0,
            "y": 32,
            "z": 9,
            "elements": [
                "minecraft:stained_glass@3"
            ]
        },
        {
            "x": 9,
            "y": 5,
            "z": 2,
            "elements": [
                "minecraft:quartz_stairs@5"
            ]
        },
        {
            "x": -3,
            "y": 32,
            "z": -2,
            "elements": [
                "minecraft:quartz_block@0"
            ]
        },
        {
            "x": -3,
            "y": 12,
            "z": 5,
            "elements": [
                "minecraft:quartz_block@0"
            ]
        },
        {
            "x": 8,
            "y": 25,
            "z": -4,
            "elements": [
                "minecraft:stained_glass_pane@11"
            ]
        },
        {
            "x": 1,
            "y": 5,
            "z": -5,
            "elements": [
                "minecraft:quartz_stairs@3"
            ]
        },
        {
            "x": 4,
            "y": 16,
            "z": 8,
            "elements": [
                "minecraft:stained_glass_pane@11"
            ]
        },
        {
            "x": 9,
            "y": 6,
            "z": 2,
            "elements": [
                "minecraft:quartz_stairs@0"
            ]
        },
        {
            "x": 2,
            "y": -1,
            "z": 7,
            "elements": [
                "chisel:glass@0"
            ]
        },
        {
            "x": -4,
            "y": 0,
            "z": 5,
            "elements": [
                "chisel:arcane_stone1@10"
            ]
        },
        {
            "x": -6,
            "y": 13,
            "z": 4,
            "elements": [
                "thaumcraft:slab_arcane_brick@0"
            ]
        },
        {
            "x": 5,
            "y": 33,
            "z": 5,
            "elements": [
                "betternether:bone_wall@0"
            ]
        },
        {
            "x": -6,
            "y": 16,
            "z": 5,
            "elements": [
                "minecraft:sea_lantern@0"
            ]
        },
        {
            "x": -10,
            "y": 6,
            "z": 5,
            "elements": [
                "minecraft:quartz_stairs@1"
            ]
        },
        {
            "x": -9,
            "y": 5,
            "z": 4,
            "elements": [
                "minecraft:concrete@7"
            ]
        },
        {
            "x": -7,
            "y": 4,
            "z": 5,
            "elements": [
                "thaumcraft:stairs_arcane_brick@5"
            ]
        },
        {
            "x": 8,
            "y": 23,
            "z": -4,
            "elements": [
                "minecraft:stained_glass_pane@11"
            ]
        },
        {
            "x": -4,
            "y": -1,
            "z": 1,
            "elements": [
                "chisel:glass@0"
            ]
        },
        {
            "x": -3,
            "y": 14,
            "z": 5,
            "elements": [
                "quark:dark_prismarine_wall@0"
            ]
        },
        {
            "x": 0,
            "y": 32,
            "z": -2,
            "elements": [
                "minecraft:stained_glass@3"
            ]
        },
        {
            "x": -2,
            "y": 5,
            "z": -5,
            "elements": [
                "minecraft:quartz_stairs@3"
            ]
        },
        {
            "x": 0,
            "y": 6,
            "z": 6,
            "elements": [
                "chisel:glass@0"
            ]
        },
        {
            "x": 3,
            "y": 16,
            "z": 8,
            "elements": [
                "minecraft:quartz_block@0"
            ]
        },
        {
            "x": 1,
            "y": 12,
            "z": 0,
            "elements": [
                "minecraft:quartz_block@0"
            ]
        },
        {
            "x": -8,
            "y": 10,
            "z": 3,
            "elements": [
                "minecraft:concrete@7"
            ]
        },
        {
            "x": -3,
            "y": 16,
            "z": -2,
            "elements": [
                "minecraft:quartz_block@0"
            ]
        },
        {
            "x": 0,
            "y": 9,
            "z": 11,
            "elements": [
                "minecraft:concrete@7"
            ]
        },
        {
            "x": 0,
            "y": 28,
            "z": 7,
            "elements": [
                "thaumcraft:slab_arcane_brick@8"
            ]
        },
        {
            "x": 8,
            "y": 30,
            "z": 11,
            "elements": [
                "minecraft:quartz_block@0"
            ]
        },
        {
            "x": -2,
            "y": 12,
            "z": 10,
            "elements": [
                "minecraft:quartz_block@0"
            ]
        },
        {
            "x": -5,
            "y": -1,
            "z": 4,
            "elements": [
                "chisel:glass@0"
            ]
        },
        {
            "x": -7,
            "y": 29,
            "z": -5,
            "elements": [
                "minecraft:quartz_block@0"
            ]
        },
        {
            "x": -8,
            "y": 9,
            "z": 4,
            "elements": [
                "minecraft:concrete@7"
            ]
        },
        {
            "x": -2,
            "y": 4,
            "z": -4,
            "elements": [
                "minecraft:sea_lantern@0"
            ]
        },
        {
            "x": 0,
            "y": 5,
            "z": -3,
            "elements": [
                "betternether:bone_wall@0"
            ]
        },
        {
            "x": -7,
            "y": 5,
            "z": 4,
            "elements": [
                "betternether:bone_wall@0"
            ]
        },
        {
            "x": 0,
            "y": 11,
            "z": 11,
            "elements": [
                "avaritia:block_resource@0"
            ]
        },
        {
            "x": 0,
            "y": 26,
            "z": 7,
            "elements": [
                "thaumcraft:slab_arcane_brick@0"
            ]
        },
        {
            "x": 0,
            "y": 6,
            "z": -4,
            "elements": [
                "minecraft:concrete@7"
            ]
        },
        {
            "x": 3,
            "y": 16,
            "z": -1,
            "elements": [
                "minecraft:quartz_block@0"
            ]
        },
        {
            "x": -9,
            "y": 25,
            "z": 12,
            "elements": [
                "minecraft:quartz_block@0"
            ]
        },
        {
            "x": -2,
            "y": 20,
            "z": 0,
            "elements": [
                "minecraft:quartz_block@0"
            ]
        },
        {
            "x": -1,
            "y": 8,
            "z": 15,
            "elements": [
                "betternether:bone_wall@0"
            ]
        },
        {
            "x": 0,
            "y": 11,
            "z": -3,
            "elements": [
                "minecraft:concrete@7"
            ]
        },
        {
            "x": 1,
            "y": 0,
            "z": 3,
            "elements": [
                "chisel:laboratory@10"
            ]
        },
        {
            "x": -2,
            "y": 10,
            "z": 10,
            "elements": [
                "minecraft:quartz_stairs@3"
            ]
        },
        {
            "x": -9,
            "y": 24,
            "z": 12,
            "elements": [
                "minecraft:quartz_block@0"
            ]
        },
        {
            "x": 0,
            "y": 27,
            "z": 7,
            "elements": [
                "extendedcrafting:storage@2"
            ]
        },
        {
            "x": 1,
            "y": 4,
            "z": -4,
            "elements": [
                "minecraft:sea_lantern@0"
            ]
        },
        {
            "x": 1,
            "y": 4,
            "z": 10,
            "elements": [
                "thaumcraft:stairs_arcane_brick@6"
            ]
        },
        {
            "x": 0,
            "y": 6,
            "z": 10,
            "elements": [
                "minecraft:stone_slab@7"
            ]
        },
        {
            "x": 3,
            "y": 16,
            "z": -2,
            "elements": [
                "minecraft:stained_glass_pane@11"
            ]
        },
        {
            "x": 0,
            "y": 8,
            "z": 5,
            "elements": [
                "actuallyadditions:block_misc@8"
            ]
        },
        {
            "x": -6,
            "y": 11,
            "z": 4,
            "elements": [
                "minecraft:quartz_block@0"
            ]
        },
        {
            "x": -2,
            "y": 8,
            "z": -4,
            "elements": [
                "minecraft:quartz_stairs@7"
            ]
        },
        {
            "x": -9,
            "y": 27,
            "z": 11,
            "elements": [
                "minecraft:quartz_block@0"
            ]
        },
        {
            "x": 2,
            "y": 4,
            "z": 5,
            "elements": [
                "casings_all"
            ]
        },
        {
            "x": -7,
            "y": 27,
            "z": -5,
            "elements": [
                "minecraft:quartz_block@0"
            ]
        },
        {
            "x": -12,
            "y": 8,
            "z": 5,
            "elements": [
                "thaumcraft:stairs_arcane_brick@0"
            ]
        },
        {
            "x": -11,
            "y": 8,
            "z": 3,
            "elements": [
                "minecraft:concrete@7"
            ]
        },
        {
            "x": -8,
            "y": 6,
            "z": 3,
            "elements": [
                "minecraft:concrete@7"
            ]
        },
        {
            "x": 0,
            "y": 9,
            "z": 13,
            "elements": [
                "avaritia:block_resource@0"
            ]
        },
        {
            "x": 0,
            "y": 12,
            "z": 10,
            "elements": [
                "thaumcraft:slab_arcane_brick@0"
            ]
        },
        {
            "x": 3,
            "y": 0,
            "z": 5,
            "elements": [
                "chisel:arcane_stone1@10"
            ]
        },
        {
            "x": -3,
            "y": -1,
            "z": 4,
            "elements": [
                "chisel:glass@0"
            ]
        },
        {
            "x": 2,
            "y": 10,
            "z": 5,
            "elements": [
                "chisel:arcane_stone1@10"
            ]
        },
        {
            "x": -1,
            "y": 8,
            "z": 5,
            "elements": [
                "actuallyadditions:block_misc@8"
            ]
        },
        {
            "x": 1,
            "y": 6,
            "z": 10,
            "elements": [
                "minecraft:quartz_stairs@2"
            ]
        },
        {
            "x": 2,
            "y": 6,
            "z": 5,
            "elements": [
                "casings_all"
            ]
        },
        {
            "x": -1,
            "y": -1,
            "z": 8,
            "elements": [
                "chisel:glass@0"
            ]
        },
        {
            "x": 8,
            "y": 28,
            "z": 11,
            "elements": [
                "minecraft:quartz_block@0"
            ]
        },
        {
            "x": -2,
            "y": 8,
            "z": 3,
            "elements": [
                "actuallyadditions:block_misc@8"
            ]
        },
        {
            "x": 0,
            "y": 7,
            "z": 13,
            "elements": [
                "minecraft:concrete@7"
            ]
        },
        {
            "x": 0,
            "y": 10,
            "z": 10,
            "elements": [
                "minecraft:concrete@7"
            ]
        },
        {
            "x": -1,
            "y": 8,
            "z": 12,
            "elements": [
                "minecraft:concrete@7"
            ]
        },
        {
            "x": -3,
            "y": 1,
            "z": 4,
            "elements": [
                "chisel:glass@0"
            ]
        },
        {
            "x": -9,
            "y": 6,
            "z": 3,
            "elements": [
                "minecraft:concrete@7"
            ]
        },
        {
            "x": 0,
            "y": 8,
            "z": 13,
            "elements": [
                "minecraft:concrete@7"
            ]
        },
        {
            "x": -2,
            "y": -1,
            "z": 4,
            "elements": [
                "chisel:laboratory@10"
            ]
        },
        {
            "x": -1,
            "y": 10,
            "z": 12,
            "elements": [
                "minecraft:sea_lantern@0"
            ]
        },
        {
            "x": -4,
            "y": 12,
            "z": 5,
            "elements": [
                "minecraft:quartz_block@0"
            ]
        },
        {
            "x": -2,
            "y": 6,
            "z": -4,
            "elements": [
                "minecraft:quartz_stairs@6"
            ]
        },
        {
            "x": -1,
            "y": 9,
            "z": 12,
            "elements": [
                "minecraft:concrete@7"
            ]
        },
        {
            "x": 2,
            "y": 8,
            "z": 5,
            "elements": [
                "quark:dark_prismarine_wall@0"
            ]
        },
        {
            "x": -8,
            "y": 11,
            "z": 4,
            "elements": [
                "avaritia:block_resource@0"
            ]
        },
        {
            "x": -2,
            "y": 6,
            "z": 10,
            "elements": [
                "minecraft:quartz_stairs@2"
            ]
        },
        {
            "x": 8,
            "y": 4,
            "z": 5,
            "elements": [
                "thaumcraft:stairs_arcane_brick@5"
            ]
        },
        {
            "x": -1,
            "y": 5,
            "z": -3,
            "elements": [
                "betternether:bone_wall@0"
            ]
        },
        {
            "x": -7,
            "y": 12,
            "z": 3,
            "elements": [
                "thaumcraft:slab_arcane_brick@0"
            ]
        },
        {
            "x": -1,
            "y": 6,
            "z": -4,
            "elements": [
                "minecraft:concrete@7"
            ]
        },
        {
            "x": 0,
            "y": 7,
            "z": 14,
            "elements": [
                "minecraft:concrete@7"
            ]
        },
        {
            "x": -9,
            "y": 8,
            "z": 3,
            "elements": [
                "minecraft:concrete@7"
            ]
        },
        {
            "x": -9,
            "y": 26,
            "z": -4,
            "elements": [
                "minecraft:quartz_block@0"
            ]
        },
        {
            "x": 2,
            "y": 14,
            "z": 5,
            "elements": [
                "quark:dark_prismarine_wall@0"
            ]
        },
        {
            "x": -3,
            "y": 4,
            "z": 3,
            "elements": [
                "chisel:glass@0"
            ]
        },
        {
            "x": -5,
            "y": 16,
            "z": 0,
            "elements": [
                "minecraft:quartz_block@0"
            ]
        },
        {
            "x": -7,
            "y": 30,
            "z": 12,
            "elements": [
                "minecraft:quartz_block@0"
            ]
        },
        {
            "x": -3,
            "y": 2,
            "z": 3,
            "elements": [
                "chisel:glass@0"
            ]
        },
        {
            "x": -1,
            "y": 7,
            "z": 4,
            "elements": [
                "minecraft:stained_glass@3"
            ]
        },
        {
            "x": -9,
            "y": 24,
            "z": -4,
            "elements": [
                "minecraft:quartz_stairs@7"
            ]
        },
        {
            "x": 2,
            "y": 5,
            "z": 4,
            "elements": [
                "chisel:glass@0"
            ]
        },
        {
            "x": -7,
            "y": 31,
            "z": 12,
            "elements": [
                "minecraft:quartz_block@0"
            ]
        },
        {
            "x": 0,
            "y": 13,
            "z": -2,
            "elements": [
                "thaumcraft:slab_arcane_brick@0"
            ]
        },
        {
            "x": -7,
            "y": 11,
            "z": 4,
            "elements": [
                "minecraft:concrete@7"
            ]
        },
        {
            "x": -9,
            "y": 25,
            "z": 11,
            "elements": [
                "minecraft:quartz_stairs@6"
            ]
        },
        {
            "x": 0,
            "y": 8,
            "z": 14,
            "elements": [
                "minecraft:concrete@7"
            ]
        },
        {
            "x": 0,
            "y": 16,
            "z": -2,
            "elements": [
                "minecraft:stained_glass@3"
            ]
        },
        {
            "x": 1,
            "y": 20,
            "z": 0,
            "elements": [
                "minecraft:quartz_block@0"
            ]
        },
        {
            "x": 8,
            "y": 24,
            "z": -5,
            "elements": [
                "betternether:bone_wall@0"
            ]
        },
        {
            "x": -12,
            "y": 7,
            "z": 2,
            "elements": [
                "thaumcraft:stairs_arcane_brick@4"
            ]
        },
        {
            "x": -9,
            "y": 10,
            "z": 3,
            "elements": [
                "minecraft:sea_lantern@0"
            ]
        },
        {
            "x": -2,
            "y": 12,
            "z": 0,
            "elements": [
                "minecraft:quartz_block@0"
            ]
        },
        {
            "x": -2,
            "y": 4,
            "z": 10,
            "elements": [
                "thaumcraft:stairs_arcane_brick@6"
            ]
        },
        {
            "x": -4,
            "y": 26,
            "z": 5,
            "elements": [
                "thaumcraft:slab_arcane_brick@0"
            ]
        },
        {
            "x": 2,
            "y": 3,
            "z": 4,
            "elements": [
                "chisel:glass@0"
            ]
        },
        {
            "x": -3,
            "y": 6,
            "z": 3,
            "elements": [
                "chisel:glass@0"
            ]
        },
        {
            "x": 2,
            "y": 12,
            "z": 5,
            "elements": [
                "minecraft:quartz_block@0"
            ]
        },
        {
            "x": -9,
            "y": 4,
            "z": 5,
            "elements": [
                "thaumcraft:stairs_arcane_brick@4"
            ]
        },
        {
            "x": 4,
            "y": 16,
            "z": 0,
            "elements": [
                "minecraft:quartz_block@0"
            ]
        },
        {
            "x": -7,
            "y": 28,
            "z": 12,
            "elements": [
                "minecraft:quartz_block@0"
            ]
        },
        {
            "x": 5,
            "y": 10,
            "z": 5,
            "elements": [
                "minecraft:quartz_block@0"
            ]
        },
        {
            "x": -5,
            "y": 32,
            "z": 7,
            "elements": [
                "minecraft:quartz_block@0"
            ]
        },
        {
            "x": 8,
            "y": 22,
            "z": -5,
            "elements": [
                "thaumcraft:pedestal_arcane@0"
            ]
        },
        {
            "x": -2,
            "y": 10,
            "z": 0,
            "elements": [
                "minecraft:quartz_block@0"
            ]
        },
        {
            "x": -3,
            "y": 0,
            "z": 3,
            "elements": [
                "chisel:glass@0"
            ]
        },
        {
            "x": -7,
            "y": 29,
            "z": 12,
            "elements": [
                "minecraft:quartz_block@0"
            ]
        },
        {
            "x": -9,
            "y": 22,
            "z": -4,
            "elements": [
                "minecraft:stained_glass@3"
            ]
        },
        {
            "x": -8,
            "y": 5,
            "z": 4,
            "elements": [
                "minecraft:concrete@7"
            ]
        },
        {
            "x": 0,
            "y": 19,
            "z": 7,
            "elements": [
                "thaumcraft:slab_arcane_brick@0"
            ]
        },
        {
            "x": 11,
            "y": 7,
            "z": 5,
            "elements": [
                "thaumcraft:stairs_arcane_brick@5"
            ]
        },
        {
            "x": -7,
            "y": 27,
            "z": 12,
            "elements": [
                "minecraft:quartz_block@0"
            ]
        },
        {
            "x": 0,
            "y": -1,
            "z": 4,
            "elements": [
                "minecraft:stained_glass@3"
            ]
        },
        {
            "x": -1,
            "y": 10,
            "z": -4,
            "elements": [
                "minecraft:concrete@7"
            ]
        },
        {
            "x": 8,
            "y": 26,
            "z": -5,
            "elements": [
                "minecraft:sea_lantern@0"
            ]
        },
        {
            "x": 2,
            "y": 1,
            "z": 4,
            "elements": [
                "chisel:glass@0"
            ]
        },
        {
            "x": -11,
            "y": 7,
            "z": 4,
            "elements": [
                "minecraft:concrete@7"
            ]
        },
        {
            "x": 5,
            "y": 12,
            "z": 5,
            "elements": [
                "minecraft:quartz_block@0"
            ]
        },
        {
            "x": 0,
            "y": 7,
            "z": -5,
            "elements": [
                "minecraft:concrete@7"
            ]
        },
        {
            "x": -10,
            "y": 9,
            "z": 4,
            "elements": [
                "avaritia:block_resource@0"
            ]
        },
        {
            "x": 0,
            "y": 5,
            "z": 11,
            "elements": [
                "minecraft:concrete@7"
            ]
        },
        {
            "x": -2,
            "y": 0,
            "z": 3,
            "elements": [
                "chisel:laboratory@10"
            ]
        },
        {
            "x": -2,
            "y": -1,
            "z": 9,
            "elements": [
                "thaumcraft:stairs_arcane_brick@3"
            ]
        },
        {
            "x": 1,
            "y": 10,
            "z": 0,
            "elements": [
                "minecraft:quartz_block@0"
            ]
        },
        {
            "x": -7,
            "y": 10,
            "z": 3,
            "elements": [
                "minecraft:concrete@7"
            ]
        },
        {
            "x": -2,
            "y": 5,
            "z": -3,
            "elements": [
                "minecraft:quartz_block@0"
            ]
        },
        {
            "x": -4,
            "y": 20,
            "z": 5,
            "elements": [
                "minecraft:quartz_block@0"
            ]
        },
        {
            "x": 0,
            "y": 21,
            "z": 7,
            "elements": [
                "thaumcraft:slab_arcane_brick@8"
            ]
        },
        {
            "x": 8,
            "y": 28,
            "z": -5,
            "elements": [
                "gct_ores:ordered_metal_block@0"
            ]
        },
        {
            "x": 3,
            "y": 32,
            "z": -1,
            "elements": [
                "minecraft:quartz_block@0"
            ]
        },
        {
            "x": -10,
            "y": 7,
            "z": 4,
            "elements": [
                "minecraft:concrete@7"
            ]
        },
        {
            "x": 1,
            "y": -1,
            "z": 4,
            "elements": [
                "chisel:laboratory@10"
            ]
        },
        {
            "x": 0,
            "y": 10,
            "z": -4,
            "elements": [
                "minecraft:concrete@7"
            ]
        },
        {
            "x": -6,
            "y": 32,
            "z": 6,
            "elements": [
                "minecraft:quartz_block@0"
            ]
        },
        {
            "x": -3,
            "y": 27,
            "z": 6,
            "elements": [
                "minecraft:quartz_block@0"
            ]
        },
        {
            "x": 0,
            "y": 9,
            "z": -5,
            "elements": [
                "minecraft:concrete@7"
            ]
        },
        {
            "x": 0,
            "y": 12,
            "z": -2,
            "elements": [
                "minecraft:quartz_block@0"
            ]
        },
        {
            "x": -9,
            "y": 23,
            "z": 11,
            "elements": [
                "minecraft:quartz_stairs@6"
            ]
        },
        {
            "x": 0,
            "y": 20,
            "z": 7,
            "elements": [
                "extendedcrafting:storage@2"
            ]
        },
        {
            "x": 1,
            "y": -1,
            "z": 9,
            "elements": [
                "thaumcraft:stairs_arcane_brick@3"
            ]
        },
        {
            "x": -3,
            "y": 28,
            "z": 6,
            "elements": [
                "thaumcraft:slab_arcane_brick@8"
            ]
        },
        {
            "x": 0,
            "y": 11,
            "z": -2,
            "elements": [
                "minecraft:quartz_block@0"
            ]
        },
        {
            "x": 8,
            "y": 11,
            "z": 5,
            "elements": [
                "minecraft:quartz_stairs@1"
            ]
        },
        {
            "x": 1,
            "y": 6,
            "z": 11,
            "elements": [
                "minecraft:quartz_stairs@7"
            ]
        },
        {
            "x": 2,
            "y": 2,
            "z": 6,
            "elements": [
                "chisel:arcane_stone1@10"
            ]
        },
        {
            "x": 5,
            "y": 16,
            "z": 5,
            "elements": [
                "minecraft:sea_lantern@0"
            ]
        },
        {
            "x": 1,
            "y": 26,
            "z": 7,
            "elements": [
                "thaumcraft:slab_arcane_brick@0"
            ]
        },
        {
            "x": -2,
            "y": 12,
            "z": 1,
            "elements": [
                "minecraft:quartz_block@0"
            ]
        },
        {
            "x": 1,
            "y": 7,
            "z": 11,
            "elements": [
                "minecraft:quartz_stairs@2"
            ]
        },
        {
            "x": 7,
            "y": 12,
            "z": 5,
            "elements": [
                "minecraft:quartz_stairs@1"
            ]
        },
        {
            "x": 1,
            "y": 14,
            "z": 1,
            "elements": [
                "quark:dark_prismarine_wall@0"
            ]
        },
        {
            "x": -2,
            "y": 10,
            "z": -2,
            "elements": [
                "minecraft:quartz_block@0"
            ]
        },
        {
            "x": 5,
            "y": 15,
            "z": 5,
            "elements": [
                "betternether:bone_wall@0"
            ]
        },
        {
            "x": -2,
            "y": 11,
            "z": 2,
            "elements": [
                "betternether:bone_wall@0"
            ]
        },
        {
            "x": -1,
            "y": 6,
            "z": 6,
            "elements": [
                "chisel:glass@0"
            ]
        },
        {
            "x": 10,
            "y": 6,
            "z": 5,
            "elements": [
                "minecraft:quartz_stairs@5"
            ]
        },
        {
            "x": -3,
            "y": 9,
            "z": 2,
            "elements": [
                "minecraft:quartz_block@0"
            ]
        },
        {
            "x": -2,
            "y": 19,
            "z": 7,
            "elements": [
                "thaumcraft:slab_arcane_brick@0"
            ]
        },
        {
            "x": 7,
            "y": 11,
            "z": 5,
            "elements": [
                "minecraft:quartz_stairs@4"
            ]
        },
        {
            "x": 0,
            "y": 7,
            "z": 2,
            "elements": [
                "chisel:arcane_stone1@10"
            ]
        },
        {
            "x": 1,
            "y": 32,
            "z": 9,
            "elements": [
                "minecraft:sea_lantern@0"
            ]
        },
        {
            "x": -2,
            "y": 21,
            "z": 7,
            "elements": [
                "thaumcraft:slab_arcane_brick@8"
            ]
        },
        {
            "x": 1,
            "y": 4,
            "z": 11,
            "elements": [
                "minecraft:sea_lantern@0"
            ]
        },
        {
            "x": 1,
            "y": 33,
            "z": 9,
            "elements": [
                "betternether:bone_wall@0"
            ]
        },
        {
            "x": 1,
            "y": 12,
            "z": 1,
            "elements": [
                "minecraft:quartz_block@0"
            ]
        },
        {
            "x": 8,
            "y": 26,
            "z": 12,
            "elements": [
                "minecraft:sea_lantern@0"
            ]
        },
        {
            "x": -2,
            "y": 12,
            "z": -2,
            "elements": [
                "minecraft:quartz_block@0"
            ]
        },
        {
            "x": 1,
            "y": 28,
            "z": 7,
            "elements": [
                "thaumcraft:slab_arcane_brick@8"
            ]
        },
        {
            "x": -2,
            "y": 14,
            "z": 1,
            "elements": [
                "quark:dark_prismarine_wall@0"
            ]
        },
        {
            "x": 1,
            "y": 5,
            "z": 11,
            "elements": [
                "minecraft:stone_slab@7"
            ]
        },
        {
            "x": -2,
            "y": 0,
            "z": 8,
            "elements": [
                "thaumcraft:slab_arcane_brick@0"
            ]
        },
        {
            "x": -2,
            "y": 9,
            "z": 2,
            "elements": [
                "chisel:arcane_stone1@10"
            ]
        },
        {
            "x": -3,
            "y": 11,
            "z": 2,
            "elements": [
                "chisel:arcane_stone1@10"
            ]
        },
        {
            "x": -5,
            "y": -1,
            "z": 2,
            "elements": [
                "chisel:glass@0"
            ]
        },
        {
            "x": 5,
            "y": 17,
            "z": 5,
            "elements": [
                "betternether:bone_wall@0"
            ]
        },
        {
            "x": 1,
            "y": 31,
            "z": 9,
            "elements": [
                "betternether:bone_wall@0"
            ]
        },
        {
            "x": 2,
            "y": 6,
            "z": 6,
            "elements": [
                "quark:dark_prismarine_wall@0"
            ]
        },
        {
            "x": 1,
            "y": 11,
            "z": 11,
            "elements": [
                "minecraft:quartz_stairs@6"
            ]
        },
        {
            "x": -2,
            "y": 15,
            "z": 2,
            "elements": [
                "quark:dark_prismarine_wall@0"
            ]
        },
        {
            "x": -3,
            "y": 20,
            "z": 1,
            "elements": [
                "minecraft:quartz_block@0"
            ]
        },
        {
            "x": 10,
            "y": 9,
            "z": 5,
            "elements": [
                "minecraft:quartz_stairs@1"
            ]
        },
        {
            "x": -4,
            "y": 28,
            "z": 5,
            "elements": [
                "thaumcraft:slab_arcane_brick@8"
            ]
        },
        {
            "x": -9,
            "y": 7,
            "z": 2,
            "elements": [
                "minecraft:quartz_stairs@4"
            ]
        },
        {
            "x": -2,
            "y": 28,
            "z": 7,
            "elements": [
                "thaumcraft:slab_arcane_brick@8"
            ]
        },
        {
            "x": 1,
            "y": 10,
            "z": 1,
            "elements": [
                "chisel:arcane_stone1@10"
            ]
        },
        {
            "x": -1,
            "y": 4,
            "z": 6,
            "elements": [
                "chisel:glass@0"
            ]
        },
        {
            "x": 1,
            "y": 12,
            "z": -2,
            "elements": [
                "minecraft:quartz_block@0"
            ]
        },
        {
            "x": 7,
            "y": 7,
            "z": 5,
            "elements": [
                "minecraft:quartz_stairs@0"
            ]
        },
        {
            "x": 2,
            "y": 12,
            "z": 6,
            "elements": [
                "minecraft:sea_lantern@0"
            ]
        },
        {
            "x": -3,
            "y": 3,
            "z": 2,
            "elements": [
                "casings_all"
            ]
        },
        {
            "x": 1,
            "y": 8,
            "z": 4,
            "elements": [
                "actuallyadditions:block_misc@8"
            ]
        },
        {
            "x": 1,
            "y": 7,
            "z": 4,
            "elements": [
                "chisel:arcane_stone1@10"
            ]
        },
        {
            "x": 7,
            "y": 8,
            "z": 5,
            "elements": [
                "minecraft:quartz_stairs@4"
            ]
        },
        {
            "x": 1,
            "y": 0,
            "z": 8,
            "elements": [
                "thaumcraft:slab_arcane_brick@0"
            ]
        },
        {
            "x": -4,
            "y": 27,
            "z": 5,
            "elements": [
                "minecraft:quartz_block@0"
            ]
        },
        {
            "x": 5,
            "y": 16,
            "z": 0,
            "elements": [
                "minecraft:stained_glass_pane@11"
            ]
        },
        {
            "x": 10,
            "y": 7,
            "z": 5,
            "elements": [
                "minecraft:quartz_stairs@0"
            ]
        },
        {
            "x": -2,
            "y": 26,
            "z": 7,
            "elements": [
                "thaumcraft:slab_arcane_brick@0"
            ]
        },
        {
            "x": -2,
            "y": 16,
            "z": -2,
            "elements": [
                "minecraft:sea_lantern@0"
            ]
        },
        {
            "x": 1,
            "y": 8,
            "z": 1,
            "elements": [
                "quark:dark_prismarine_wall@0"
            ]
        },
        {
            "x": 7,
            "y": 9,
            "z": 5,
            "elements": [
                "minecraft:quartz_stairs@1"
            ]
        },
        {
            "x": 2,
            "y": 10,
            "z": 6,
            "elements": [
                "betternether:bone_wall@0"
            ]
        },
        {
            "x": 1,
            "y": 9,
            "z": 11,
            "elements": [
                "minecraft:quartz_stairs@3"
            ]
        },
        {
            "x": 5,
            "y": -1,
            "z": 2,
            "elements": [
                "thaumcraft:stairs_arcane_brick@1"
            ]
        },
        {
            "x": -2,
            "y": 13,
            "z": 2,
            "elements": [
                "minecraft:quartz_block@0"
            ]
        },
        {
            "x": -3,
            "y": 1,
            "z": 2,
            "elements": [
                "casings_all"
            ]
        },
        {
            "x": 2,
            "y": 0,
            "z": 6,
            "elements": [
                "chisel:arcane_stone1@10"
            ]
        },
        {
            "x": -9,
            "y": 5,
            "z": 2,
            "elements": [
                "minecraft:quartz_stairs@1"
            ]
        },
        {
            "x": -1,
            "y": 2,
            "z": 6,
            "elements": [
                "chisel:glass@0"
            ]
        },
        {
            "x": 4,
            "y": 12,
            "z": 5,
            "elements": [
                "quark:dark_prismarine_wall@0"
            ]
        },
        {
            "x": 1,
            "y": 10,
            "z": -2,
            "elements": [
                "minecraft:quartz_block@0"
            ]
        },
        {
            "x": 10,
            "y": 8,
            "z": 5,
            "elements": [
                "minecraft:quartz_stairs@4"
            ]
        },
        {
            "x": 1,
            "y": 9,
            "z": 4,
            "elements": [
                "chisel:arcane_stone1@10"
            ]
        },
        {
            "x": 1,
            "y": 8,
            "z": 11,
            "elements": [
                "minecraft:quartz_stairs@6"
            ]
        },
        {
            "x": -3,
            "y": 7,
            "z": 2,
            "elements": [
                "thaumcraft:stairs_arcane_brick@0"
            ]
        },
        {
            "x": -9,
            "y": 11,
            "z": 2,
            "elements": [
                "minecraft:quartz_stairs@0"
            ]
        },
        {
            "x": 1,
            "y": 9,
            "z": 10,
            "elements": [
                "minecraft:quartz_stairs@6"
            ]
        },
        {
            "x": 7,
            "y": 9,
            "z": 4,
            "elements": [
                "minecraft:concrete@7"
            ]
        },
        {
            "x": 1,
            "y": 12,
            "z": 11,
            "elements": [
                "minecraft:quartz_stairs@3"
            ]
        },
        {
            "x": 7,
            "y": 10,
            "z": 4,
            "elements": [
                "minecraft:concrete@7"
            ]
        },
        {
            "x": 1,
            "y": 10,
            "z": 10,
            "elements": [
                "minecraft:quartz_stairs@3"
            ]
        },
        {
            "x": -2,
            "y": 1,
            "z": 2,
            "elements": [
                "chisel:glass@0"
            ]
        },
        {
            "x": -2,
            "y": -1,
            "z": -1,
            "elements": [
                "chisel:glass@0"
            ]
        },
        {
            "x": -1,
            "y": 8,
            "z": 13,
            "elements": [
                "minecraft:concrete@7"
            ]
        },
        {
            "x": -9,
            "y": 21,
            "z": 12,
            "elements": [
                "minecraft:stained_glass_pane@11"
            ]
        },
        {
            "x": 1,
            "y": 0,
            "z": 1,
            "elements": [
                "chisel:arcane_stone1@10"
            ]
        },
        {
            "x": 0,
            "y": 7,
            "z": -8,
            "elements": [
                "betternether:bone_wall@0"
            ]
        },
        {
            "x": -6,
            "y": 11,
            "z": 2,
            "elements": [
                "minecraft:quartz_block@0"
            ]
        },
        {
            "x": -2,
            "y": 6,
            "z": 1,
            "elements": [
                "casings_all"
            ]
        },
        {
            "x": 0,
            "y": -1,
            "z": 2,
            "elements": [
                "chisel:laboratory@10"
            ]
        },
        {
            "x": 0,
            "y": 5,
            "z": 12,
            "elements": [
                "minecraft:concrete@7"
            ]
        },
        {
            "x": 10,
            "y": 8,
            "z": 4,
            "elements": [
                "minecraft:concrete@7"
            ]
        },
        {
            "x": -7,
            "y": 9,
            "z": 2,
            "elements": [
                "minecraft:quartz_stairs@5"
            ]
        },
        {
            "x": 1,
            "y": 15,
            "z": 5,
            "elements": [
                "quark:dark_prismarine_wall@0"
            ]
        },
        {
            "x": 1,
            "y": 12,
            "z": 10,
            "elements": [
                "minecraft:quartz_block@0"
            ]
        },
        {
            "x": -2,
            "y": 11,
            "z": 7,
            "elements": [
                "minecraft:quartz_block@0"
            ]
        },
        {
            "x": -3,
            "y": 5,
            "z": 2,
            "elements": [
                "casings_all"
            ]
        },
        {
            "x": 1,
            "y": 9,
            "z": 7,
            "elements": [
                "minecraft:quartz_block@0"
            ]
        },
        {
            "x": -2,
            "y": 3,
            "z": 2,
            "elements": [
                "chisel:glass@0"
            ]
        },
        {
            "x": 1,
            "y": 2,
            "z": 1,
            "elements": [
                "casings_all"
            ]
        },
        {
            "x": -1,
            "y": -1,
            "z": 2,
            "elements": [
                "chisel:laboratory@10"
            ]
        },
        {
            "x": -2,
            "y": 4,
            "z": 1,
            "elements": [
                "casings_all"
            ]
        },
        {
            "x": -9,
            "y": 23,
            "z": 12,
            "elements": [
                "minecraft:quartz_block@0"
            ]
        },
        {
            "x": 0,
            "y": 7,
            "z": 12,
            "elements": [
                "minecraft:concrete@7"
            ]
        },
        {
            "x": -6,
            "y": 32,
            "z": 1,
            "elements": [
                "minecraft:quartz_block@0"
            ]
        },
        {
            "x": 1,
            "y": 3,
            "z": 2,
            "elements": [
                "chisel:glass@0"
            ]
        },
        {
            "x": 1,
            "y": 11,
            "z": 7,
            "elements": [
                "minecraft:quartz_block@0"
            ]
        },
        {
            "x": -2,
            "y": 5,
            "z": 2,
            "elements": [
                "chisel:glass@0"
            ]
        },
        {
            "x": -1,
            "y": 6,
            "z": 13,
            "elements": [
                "minecraft:concrete@7"
            ]
        },
        {
            "x": -3,
            "y": 26,
            "z": 1,
            "elements": [
                "thaumcraft:slab_arcane_brick@0"
            ]
        },
        {
            "x": -6,
            "y": 15,
            "z": 2,
            "elements": [
                "betternether:bone_wall@0"
            ]
        },
        {
            "x": 1,
            "y": 7,
            "z": 3,
            "elements": [
                "chisel:arcane_stone1@10"
            ]
        },
        {
            "x": -2,
            "y": 7,
            "z": -8,
            "elements": [
                "thaumcraft:stairs_arcane_brick@6"
            ]
        },
        {
            "x": -2,
            "y": -1,
            "z": 2,
            "elements": [
                "chisel:glass@0"
            ]
        },
        {
            "x": -8,
            "y": 11,
            "z": 2,
            "elements": [
                "minecraft:quartz_stairs@5"
            ]
        },
        {
            "x": 1,
            "y": 4,
            "z": 1,
            "elements": [
                "casings_all"
            ]
        },
        {
            "x": 1,
            "y": 13,
            "z": 10,
            "elements": [
                "thaumcraft:slab_arcane_brick@0"
            ]
        },
        {
            "x": 0,
            "y": 9,
            "z": 12,
            "elements": [
                "minecraft:concrete@7"
            ]
        },
        {
            "x": -2,
            "y": 7,
            "z": 2,
            "elements": [
                "chisel:arcane_stone1@10"
            ]
        },
        {
            "x": 2,
            "y": 4,
            "z": 6,
            "elements": [
                "betternether:bone_wall@0"
            ]
        },
        {
            "x": -2,
            "y": 9,
            "z": 4,
            "elements": [
                "chisel:arcane_stone1@10"
            ]
        },
        {
            "x": 4,
            "y": 32,
            "z": 7,
            "elements": [
                "minecraft:quartz_block@0"
            ]
        },
        {
            "x": 1,
            "y": 8,
            "z": 3,
            "elements": [
                "actuallyadditions:block_misc@8"
            ]
        },
        {
            "x": -2,
            "y": 10,
            "z": 1,
            "elements": [
                "chisel:arcane_stone1@10"
            ]
        },
        {
            "x": 7,
            "y": 6,
            "z": 4,
            "elements": [
                "minecraft:concrete@7"
            ]
        },
        {
            "x": -2,
            "y": 8,
            "z": 4,
            "elements": [
                "actuallyadditions:block_misc@8"
            ]
        },
        {
            "x": -3,
            "y": 28,
            "z": 1,
            "elements": [
                "thaumcraft:slab_arcane_brick@8"
            ]
        },
        {
            "x": 1,
            "y": 1,
            "z": 2,
            "elements": [
                "chisel:glass@0"
            ]
        },
        {
            "x": -6,
            "y": 13,
            "z": 2,
            "elements": [
                "thaumcraft:slab_arcane_brick@0"
            ]
        },
        {
            "x": -1,
            "y": 7,
            "z": 14,
            "elements": [
                "minecraft:concrete@7"
            ]
        },
        {
            "x": 1,
            "y": 9,
            "z": 3,
            "elements": [
                "chisel:arcane_stone1@10"
            ]
        },
        {
            "x": 0,
            "y": 6,
            "z": 13,
            "elements": [
                "minecraft:concrete@7"
            ]
        },
        {
            "x": 1,
            "y": -1,
            "z": 2,
            "elements": [
                "chisel:glass@0"
            ]
        },
        {
            "x": 2,
            "y": 7,
            "z": 7,
            "elements": [
                "thaumcraft:slab_arcane_brick@0"
            ]
        },
        {
            "x": -2,
            "y": 13,
            "z": 10,
            "elements": [
                "thaumcraft:slab_arcane_brick@0"
            ]
        },
        {
            "x": -1,
            "y": 7,
            "z": -8,
            "elements": [
                "betternether:bone_wall@0"
            ]
        },
        {
            "x": -2,
            "y": 7,
            "z": 4,
            "elements": [
                "chisel:arcane_stone1@10"
            ]
        },
        {
            "x": -8,
            "y": 9,
            "z": 2,
            "elements": [
                "minecraft:quartz_stairs@0"
            ]
        },
        {
            "x": -9,
            "y": 19,
            "z": 12,
            "elements": [
                "minecraft:stained_glass_pane@11"
            ]
        },
        {
            "x": -2,
            "y": 8,
            "z": 1,
            "elements": [
                "quark:dark_prismarine_wall@0"
            ]
        },
        {
            "x": 7,
            "y": 5,
            "z": 4,
            "elements": [
                "minecraft:concrete@7"
            ]
        },
        {
            "x": 1,
            "y": 6,
            "z": 1,
            "elements": [
                "casings_all"
            ]
        },
        {
            "x": -3,
            "y": 4,
            "z": 6,
            "elements": [
                "betternether:bone_wall@0"
            ]
        },
        {
            "x": -2,
            "y": 13,
            "z": 5,
            "elements": [
                "minecraft:quartz_block@0"
            ]
        },
        {
            "x": -3,
            "y": 0,
            "z": 1,
            "elements": [
                "chisel:arcane_stone1@10"
            ]
        },
        {
            "x": 1,
            "y": 17,
            "z": 9,
            "elements": [
                "betternether:bone_wall@0"
            ]
        },
        {
            "x": -2,
            "y": 14,
            "z": 5,
            "elements": [
                "quark:dark_prismarine_wall@0"
            ]
        },
        {
            "x": 0,
            "y": 2,
            "z": 1,
            "elements": [
                "chisel:glass@0"
            ]
        },
        {
            "x": -8,
            "y": 5,
            "z": 2,
            "elements": [
                "minecraft:stone_slab@7"
            ]
        },
        {
            "x": -8,
            "y": 29,
            "z": 11,
            "elements": [
                "minecraft:quartz_block@0"
            ]
        },
        {
            "x": -1,
            "y": 12,
            "z": -2,
            "elements": [
                "minecraft:quartz_block@0"
            ]
        },
        {
            "x": -6,
            "y": 31,
            "z": 2,
            "elements": [
                "betternether:bone_wall@0"
            ]
        },
        {
            "x": -1,
            "y": 4,
            "z": 1,
            "elements": [
                "chisel:glass@0"
            ]
        },
        {
            "x": -8,
            "y": 30,
            "z": 11,
            "elements": [
                "minecraft:quartz_block@0"
            ]
        },
        {
            "x": 1,
            "y": 8,
            "z": 5,
            "elements": [
                "quark:dark_prismarine_wall@0"
            ]
        },
        {
            "x": -4,
            "y": 16,
            "z": -2,
            "elements": [
                "minecraft:stained_glass_pane@11"
            ]
        },
        {
            "x": 1,
            "y": 9,
            "z": 5,
            "elements": [
                "chisel:arcane_stone1@10"
            ]
        },
        {
            "x": -8,
            "y": 7,
            "z": 2,
            "elements": [
                "minecraft:quartz_stairs@1"
            ]
        },
        {
            "x": 0,
            "y": 0,
            "z": 6,
            "elements": [
                "chisel:glass@0"
            ]
        },
        {
            "x": -2,
            "y": 11,
            "z": 5,
            "elements": [
                "betternether:bone_wall@0"
            ]
        },
        {
            "x": -3,
            "y": 2,
            "z": 1,
            "elements": [
                "chisel:arcane_stone1@10"
            ]
        },
        {
            "x": -8,
            "y": 31,
            "z": 11,
            "elements": [
                "minecraft:quartz_block@0"
            ]
        },
        {
            "x": 6,
            "y": 9,
            "z": 2,
            "elements": [
                "minecraft:quartz_stairs@4"
            ]
        },
        {
            "x": -3,
            "y": 2,
            "z": 6,
            "elements": [
                "chisel:arcane_stone1@10"
            ]
        },
        {
            "x": -6,
            "y": 17,
            "z": 2,
            "elements": [
                "betternether:bone_wall@0"
            ]
        },
        {
            "x": 0,
            "y": 0,
            "z": 1,
            "elements": [
                "chisel:glass@0"
            ]
        },
        {
            "x": -1,
            "y": -1,
            "z": -1,
            "elements": [
                "chisel:glass@0"
            ]
        },
        {
            "x": 1,
            "y": 7,
            "z": -8,
            "elements": [
                "thaumcraft:stairs_arcane_brick@6"
            ]
        },
        {
            "x": 1,
            "y": 7,
            "z": 5,
            "elements": [
                "chisel:arcane_stone1@10"
            ]
        },
        {
            "x": -2,
            "y": 12,
            "z": 5,
            "elements": [
                "tconevo:metal_block@2"
            ]
        },
        {
            "x": 3,
            "y": 16,
            "z": 9,
            "elements": [
                "minecraft:stained_glass_pane@11"
            ]
        },
        {
            "x": 1,
            "y": 33,
            "z": -2,
            "elements": [
                "betternether:bone_wall@0"
            ]
        },
        {
            "x": 1,
            "y": 10,
            "z": 5,
            "elements": [
                "betternether:bone_wall@0"
            ]
        },
        {
            "x": -1,
            "y": 6,
            "z": 1,
            "elements": [
                "chisel:glass@0"
            ]
        },
        {
            "x": 0,
            "y": 2,
            "z": 6,
            "elements": [
                "chisel:glass@0"
            ]
        },
        {
            "x": 1,
            "y": 31,
            "z": -2,
            "elements": [
                "betternether:bone_wall@0"
            ]
        },
        {
            "x": 0,
            "y": -1,
            "z": -1,
            "elements": [
                "chisel:glass@0"
            ]
        },
        {
            "x": -1,
            "y": 0,
            "z": 1,
            "elements": [
                "chisel:glass@0"
            ]
        },
        {
            "x": -1,
            "y": 19,
            "z": 0,
            "elements": [
                "thaumcraft:slab_arcane_brick@0"
            ]
        },
        {
            "x": 1,
            "y": 9,
            "z": -6,
            "elements": [
                "minecraft:quartz_stairs@7"
            ]
        },
        {
            "x": 1,
            "y": 11,
            "z": 5,
            "elements": [
                "betternether:bone_wall@0"
            ]
        },
        {
            "x": 1,
            "y": 13,
            "z": 9,
            "elements": [
                "thaumcraft:slab_arcane_brick@0"
            ]
        },
        {
            "x": -2,
            "y": 33,
            "z": -2,
            "elements": [
                "betternether:bone_wall@0"
            ]
        },
        {
            "x": -2,
            "y": 2,
            "z": 1,
            "elements": [
                "casings_all"
            ]
        },
        {
            "x": -2,
            "y": 9,
            "z": 7,
            "elements": [
                "minecraft:quartz_block@0"
            ]
        },
        {
            "x": -11,
            "y": 6,
            "z": 5,
            "elements": [
                "minecraft:quartz_stairs@4"
            ]
        },
        {
            "x": -1,
            "y": 20,
            "z": 0,
            "elements": [
                "extendedcrafting:storage@2"
            ]
        },
        {
            "x": -3,
            "y": 4,
            "z": 1,
            "elements": [
                "betternether:bone_wall@0"
            ]
        },
        {
            "x": 1,
            "y": 12,
            "z": 5,
            "elements": [
                "tconevo:metal_block@2"
            ]
        },
        {
            "x": 1,
            "y": 10,
            "z": 8,
            "elements": [
                "quark:dark_prismarine_wall@0"
            ]
        },
        {
            "x": -6,
            "y": -1,
            "z": 2,
            "elements": [
                "thaumcraft:stairs_arcane_brick@0"
            ]
        },
        {
            "x": -3,
            "y": 6,
            "z": 6,
            "elements": [
                "quark:dark_prismarine_wall@0"
            ]
        },
        {
            "x": 3,
            "y": 19,
            "z": 2,
            "elements": [
                "thaumcraft:slab_arcane_brick@0"
            ]
        },
        {
            "x": 1,
            "y": -1,
            "z": -1,
            "elements": [
                "chisel:glass@0"
            ]
        },
        {
            "x": -2,
            "y": 0,
            "z": 1,
            "elements": [
                "chisel:arcane_stone1@10"
            ]
        },
        {
            "x": 1,
            "y": 15,
            "z": 9,
            "elements": [
                "minecraft:stone_slab@15"
            ]
        },
        {
            "x": 6,
            "y": 13,
            "z": 2,
            "elements": [
                "thaumcraft:slab_arcane_brick@0"
            ]
        },
        {
            "x": 0,
            "y": 4,
            "z": 6,
            "elements": [
                "chisel:glass@0"
            ]
        },
        {
            "x": 0,
            "y": 8,
            "z": -7,
            "elements": [
                "minecraft:concrete@7"
            ]
        },
        {
            "x": 7,
            "y": 28,
            "z": 12,
            "elements": [
                "minecraft:quartz_block@0"
            ]
        },
        {
            "x": -8,
            "y": 27,
            "z": 11,
            "elements": [
                "minecraft:quartz_block@0"
            ]
        },
        {
            "x": -1,
            "y": 2,
            "z": 1,
            "elements": [
                "chisel:glass@0"
            ]
        },
        {
            "x": 1,
            "y": 14,
            "z": 5,
            "elements": [
                "quark:dark_prismarine_wall@0"
            ]
        },
        {
            "x": 7,
            "y": 11,
            "z": 4,
            "elements": [
                "avaritia:block_resource@0"
            ]
        },
        {
            "x": -8,
            "y": 28,
            "z": 11,
            "elements": [
                "minecraft:quartz_block@0"
            ]
        },
        {
            "x": 7,
            "y": 5,
            "z": 3,
            "elements": [
                "minecraft:concrete@7"
            ]
        },
        {
            "x": -3,
            "y": 6,
            "z": 1,
            "elements": [
                "quark:dark_prismarine_wall@0"
            ]
        },
        {
            "x": 1,
            "y": 16,
            "z": 9,
            "elements": [
                "minecraft:sea_lantern@0"
            ]
        },
        {
            "x": 1,
            "y": 12,
            "z": 8,
            "elements": [
                "quark:dark_prismarine_wall@0"
            ]
        },
        {
            "x": 7,
            "y": 30,
            "z": 12,
            "elements": [
                "minecraft:quartz_block@0"
            ]
        },
        {
            "x": 10,
            "y": 7,
            "z": 4,
            "elements": [
                "minecraft:concrete@7"
            ]
        },
        {
            "x": -2,
            "y": 15,
            "z": 5,
            "elements": [
                "quark:dark_prismarine_wall@0"
            ]
        },
        {
            "x": 1,
            "y": 13,
            "z": 5,
            "elements": [
                "minecraft:quartz_block@0"
            ]
        },
        {
            "x": 7,
            "y": 6,
            "z": 3,
            "elements": [
                "minecraft:concrete@7"
            ]
        },
        {
            "x": -2,
            "y": 8,
            "z": 5,
            "elements": [
                "quark:dark_prismarine_wall@0"
            ]
        },
        {
            "x": -11,
            "y": 7,
            "z": 2,
            "elements": [
                "minecraft:quartz_stairs@1"
            ]
        },
        {
            "x": 0,
            "y": 7,
            "z": -6,
            "elements": [
                "minecraft:concrete@7"
            ]
        },
        {
            "x": -2,
            "y": 7,
            "z": 5,
            "elements": [
                "chisel:arcane_stone1@10"
            ]
        },
        {
            "x": -1,
            "y": 8,
            "z": -7,
            "elements": [
                "minecraft:concrete@7"
            ]
        },
        {
            "x": -2,
            "y": 33,
            "z": 9,
            "elements": [
                "betternether:bone_wall@0"
            ]
        },
        {
            "x": -2,
            "y": 32,
            "z": 9,
            "elements": [
                "minecraft:sea_lantern@0"
            ]
        },
        {
            "x": 1,
            "y": 0,
            "z": 5,
            "elements": [
                "chisel:glass@0"
            ]
        },
        {
            "x": -1,
            "y": 0,
            "z": 6,
            "elements": [
                "chisel:glass@0"
            ]
        },
        {
            "x": 1,
            "y": 2,
            "z": 5,
            "elements": [
                "chisel:glass@0"
            ]
        },
        {
            "x": -3,
            "y": 14,
            "z": 1,
            "elements": [
                "quark:dark_prismarine_wall@0"
            ]
        },
        {
            "x": 1,
            "y": 9,
            "z": 2,
            "elements": [
                "chisel:arcane_stone1@10"
            ]
        },
        {
            "x": -3,
            "y": -1,
            "z": 7,
            "elements": [
                "chisel:glass@0"
            ]
        },
        {
            "x": -2,
            "y": 2,
            "z": 6,
            "elements": [
                "casings_all"
            ]
        },
        {
            "x": -2,
            "y": 5,
            "z": -6,
            "elements": [
                "minecraft:quartz_stairs@6"
            ]
        },
        {
            "x": -8,
            "y": 4,
            "z": 5,
            "elements": [
                "minecraft:sea_lantern@0"
            ]
        },
        {
            "x": 0,
            "y": 16,
            "z": 9,
            "elements": [
                "minecraft:stained_glass@3"
            ]
        },
        {
            "x": 7,
            "y": 5,
            "z": 5,
            "elements": [
                "minecraft:stone_slab@7"
            ]
        },
        {
            "x": -2,
            "y": 12,
            "z": 11,
            "elements": [
                "minecraft:quartz_stairs@3"
            ]
        },
        {
            "x": 4,
            "y": 10,
            "z": 5,
            "elements": [
                "quark:dark_prismarine_wall@0"
            ]
        },
        {
            "x": -11,
            "y": 9,
            "z": 5,
            "elements": [
                "minecraft:quartz_stairs@0"
            ]
        },
        {
            "x": -5,
            "y": 12,
            "z": 5,
            "elements": [
                "quark:dark_prismarine_wall@0"
            ]
        },
        {
            "x": 1,
            "y": 1,
            "z": 5,
            "elements": [
                "chisel:glass@0"
            ]
        },
        {
            "x": -2,
            "y": 31,
            "z": 9,
            "elements": [
                "betternether:bone_wall@0"
            ]
        },
        {
            "x": 0,
            "y": 9,
            "z": -6,
            "elements": [
                "avaritia:block_resource@0"
            ]
        },
        {
            "x": -2,
            "y": 8,
            "z": -7,
            "elements": [
                "minecraft:quartz_stairs@7"
            ]
        },
        {
            "x": 7,
            "y": 4,
            "z": 5,
            "elements": [
                "minecraft:sea_lantern@0"
            ]
        },
        {
            "x": -2,
            "y": 17,
            "z": 9,
            "elements": [
                "betternether:bone_wall@0"
            ]
        },
        {
            "x": -2,
            "y": 4,
            "z": 6,
            "elements": [
                "casings_all"
            ]
        },
        {
            "x": -3,
            "y": 12,
            "z": 1,
            "elements": [
                "minecraft:sea_lantern@0"
            ]
        },
        {
            "x": 7,
            "y": 9,
            "z": 3,
            "elements": [
                "minecraft:concrete@7"
            ]
        },
        {
            "x": -11,
            "y": 8,
            "z": 5,
            "elements": [
                "minecraft:quartz_stairs@5"
            ]
        },
        {
            "x": 1,
            "y": 11,
            "z": 2,
            "elements": [
                "betternether:bone_wall@0"
            ]
        },
        {
            "x": 0,
            "y": 13,
            "z": 9,
            "elements": [
                "thaumcraft:slab_arcane_brick@0"
            ]
        },
        {
            "x": -1,
            "y": 21,
            "z": 0,
            "elements": [
                "thaumcraft:slab_arcane_brick@8"
            ]
        },
        {
            "x": -8,
            "y": 6,
            "z": 5,
            "elements": [
                "minecraft:quartz_stairs@4"
            ]
        },
        {
            "x": -2,
            "y": 6,
            "z": -7,
            "elements": [
                "minecraft:quartz_stairs@6"
            ]
        },
        {
            "x": 7,
            "y": 10,
            "z": 3,
            "elements": [
                "minecraft:concrete@7"
            ]
        },
        {
            "x": 0,
            "y": 12,
            "z": 9,
            "elements": [
                "minecraft:quartz_block@0"
            ]
        },
        {
            "x": 7,
            "y": 6,
            "z": 5,
            "elements": [
                "minecraft:quartz_stairs@5"
            ]
        },
        {
            "x": 0,
            "y": -1,
            "z": 5,
            "elements": [
                "chisel:laboratory@10"
            ]
        },
        {
            "x": -11,
            "y": 7,
            "z": 5,
            "elements": [
                "minecraft:quartz_stairs@1"
            ]
        },
        {
            "x": -8,
            "y": 5,
            "z": 5,
            "elements": [
                "minecraft:stone_slab@7"
            ]
        },
        {
            "x": -1,
            "y": 16,
            "z": -2,
            "elements": [
                "minecraft:stained_glass@3"
            ]
        },
        {
            "x": 7,
            "y": 11,
            "z": 3,
            "elements": [
                "avaritia:block_resource@0"
            ]
        },
        {
            "x": -1,
            "y": 26,
            "z": 0,
            "elements": [
                "thaumcraft:slab_arcane_brick@0"
            ]
        },
        {
            "x": 1,
            "y": 6,
            "z": 5,
            "elements": [
                "chisel:glass@0"
            ]
        },
        {
            "x": 3,
            "y": 28,
            "z": 2,
            "elements": [
                "thaumcraft:slab_arcane_brick@8"
            ]
        },
        {
            "x": -3,
            "y": 10,
            "z": 1,
            "elements": [
                "betternether:bone_wall@0"
            ]
        },
        {
            "x": 0,
            "y": 7,
            "z": 15,
            "elements": [
                "betternether:bone_wall@0"
            ]
        },
        {
            "x": -8,
            "y": 8,
            "z": 5,
            "elements": [
                "minecraft:quartz_stairs@5"
            ]
        },
        {
            "x": 1,
            "y": 8,
            "z": -7,
            "elements": [
                "minecraft:quartz_stairs@7"
            ]
        },
        {
            "x": -2,
            "y": 9,
            "z": 11,
            "elements": [
                "minecraft:quartz_stairs@3"
            ]
        },
        {
            "x": 8,
            "y": 28,
            "z": 12,
            "elements": [
                "gct_ores:ordered_metal_block@0"
            ]
        },
        {
            "x": -3,
            "y": 0,
            "z": 6,
            "elements": [
                "chisel:arcane_stone1@10"
            ]
        },
        {
            "x": -2,
            "y": 4,
            "z": 5,
            "elements": [
                "chisel:glass@0"
            ]
        },
        {
            "x": -2,
            "y": 10,
            "z": 8,
            "elements": [
                "quark:dark_prismarine_wall@0"
            ]
        },
        {
            "x": -3,
            "y": 13,
            "z": 2,
            "elements": [
                "minecraft:quartz_block@0"
            ]
        },
        {
            "x": -2,
            "y": 9,
            "z": 5,
            "elements": [
                "chisel:arcane_stone1@10"
            ]
        },
        {
            "x": 0,
            "y": 11,
            "z": 9,
            "elements": [
                "minecraft:quartz_block@0"
            ]
        },
        {
            "x": 0,
            "y": 8,
            "z": 15,
            "elements": [
                "betternether:bone_wall@0"
            ]
        },
        {
            "x": -2,
            "y": 12,
            "z": 8,
            "elements": [
                "quark:dark_prismarine_wall@0"
            ]
        },
        {
            "x": -6,
            "y": 16,
            "z": 1,
            "elements": [
                "minecraft:quartz_block@0"
            ]
        },
        {
            "x": 5,
            "y": 32,
            "z": 2,
            "elements": [
                "minecraft:sea_lantern@0"
            ]
        },
        {
            "x": 2,
            "y": 2,
            "z": 1,
            "elements": [
                "chisel:arcane_stone1@10"
            ]
        },
        {
            "x": 1,
            "y": 5,
            "z": 5,
            "elements": [
                "chisel:glass@0"
            ]
        },
        {
            "x": 3,
            "y": 9,
            "z": 2,
            "elements": [
                "minecraft:quartz_block@0"
            ]
        },
        {
            "x": 1,
            "y": 5,
            "z": 2,
            "elements": [
                "chisel:glass@0"
            ]
        },
        {
            "x": -2,
            "y": 8,
            "z": 11,
            "elements": [
                "minecraft:quartz_stairs@6"
            ]
        },
        {
            "x": -2,
            "y": 10,
            "z": 5,
            "elements": [
                "betternether:bone_wall@0"
            ]
        },
        {
            "x": -8,
            "y": 7,
            "z": 5,
            "elements": [
                "minecraft:quartz_stairs@1"
            ]
        },
        {
            "x": -2,
            "y": 3,
            "z": 5,
            "elements": [
                "chisel:glass@0"
            ]
        },
        {
            "x": 0,
            "y": 6,
            "z": 1,
            "elements": [
                "chisel:glass@0"
            ]
        },
        {
            "x": 1,
            "y": 6,
            "z": -7,
            "elements": [
                "minecraft:quartz_stairs@6"
            ]
        },
        {
            "x": 2,
            "y": 16,
            "z": -2,
            "elements": [
                "minecraft:quartz_block@0"
            ]
        },
        {
            "x": 2,
            "y": 0,
            "z": 1,
            "elements": [
                "chisel:arcane_stone1@10"
            ]
        },
        {
            "x": -2,
            "y": 11,
            "z": 11,
            "elements": [
                "minecraft:quartz_stairs@6"
            ]
        },
        {
            "x": -11,
            "y": 9,
            "z": 2,
            "elements": [
                "minecraft:quartz_stairs@0"
            ]
        },
        {
            "x": -2,
            "y": 6,
            "z": 5,
            "elements": [
                "chisel:glass@0"
            ]
        },
        {
            "x": -5,
            "y": 16,
            "z": 8,
            "elements": [
                "minecraft:stained_glass_pane@11"
            ]
        },
        {
            "x": -1,
            "y": 28,
            "z": 0,
            "elements": [
                "thaumcraft:slab_arcane_brick@8"
            ]
        },
        {
            "x": -2,
            "y": 0,
            "z": 6,
            "elements": [
                "chisel:arcane_stone1@10"
            ]
        },
        {
            "x": 10,
            "y": 7,
            "z": 3,
            "elements": [
                "minecraft:concrete@7"
            ]
        },
        {
            "x": 3,
            "y": 11,
            "z": 2,
            "elements": [
                "minecraft:quartz_block@0"
            ]
        },
        {
            "x": 1,
            "y": 4,
            "z": 5,
            "elements": [
                "chisel:glass@0"
            ]
        },
        {
            "x": 4,
            "y": 0,
            "z": 5,
            "elements": [
                "thaumcraft:slab_arcane_brick@0"
            ]
        },
        {
            "x": -2,
            "y": 9,
            "z": -6,
            "elements": [
                "minecraft:quartz_stairs@7"
            ]
        },
        {
            "x": -8,
            "y": 11,
            "z": 5,
            "elements": [
                "minecraft:quartz_stairs@5"
            ]
        },
        {
            "x": 0,
            "y": 9,
            "z": 2,
            "elements": [
                "chisel:arcane_stone1@10"
            ]
        },
        {
            "x": -1,
            "y": 27,
            "z": 0,
            "elements": [
