{
    "parts": [
        {
            "x": 0,
            "y": 0,
            "z": 0,
            "elements": [
                "modularmachinery:blockcontroller@2"
            ]
        },
        {
            "x": -1,
            "y": 23,
            "z": 2,
            "elements": [
                "abyssalcraft:darkethaxiumbrick@0"
            ]
        },
        {
            "x": 0,
            "y": -2,
            "z": 0,
            "elements": [
                "abyssalcraft:cstonebrick@0"
            ]
        },
        {
            "x": 0,
            "y": 19,
            "z": 6,
            "elements": [
                "abyssalcraft:darkstone_brick@2"
            ]
        },
        {
            "x": 2,
            "y": 36,
            "z": 4,
            "elements": [
                "abyssalcraft:coraliumcobblestonestairs@2"
            ]
        },
        {
            "x": -1,
            "y": 32,
            "z": 2,
            "elements": [
                "abyssalcraft:coraliumcobblestonestairs@6"
            ]
        },
        {
            "x": -1,
            "y": 22,
            "z": 2,
            "elements": [
                "abyssalcraft:darkethaxiumbrick@0"
            ]
        },
        {
            "x": 0,
            "y": 9,
            "z": 3,
            "elements": [
                "abyssalcraft:darkstone_brick@2"
            ]
        },
        {
            "x": -3,
            "y": 24,
            "z": 8,
            "elements": [
                "abyssalcraft:coraliumcobblestoneslab1@0"
            ]
        },
        {
            "x": 0,
            "y": 14,
            "z": 7,
            "elements": [
                "abyssalcraft:darkstone_brick@2"
            ]
        },
        {
            "x": 0,
            "y": 12,
            "z": 4,
            "elements": [
                "abyssalcraft:darkstone_brick@2"
            ]
        },
        {
            "x": -3,
            "y": 2,
            "z": 5,
            "elements": [
                "modularmachinery:blockcasing@0"
            ]
        },
        {
            "x": 0,
            "y": -1,
            "z": 0,
            "elements": [
                "abyssalcraft:cstonebrick@0"
            ]
        },
        {
            "x": 2,
            "y": 37,
            "z": 4,
            "elements": [
                "abyssalcraft:monolithpillar@0"
            ]
        },
        {
            "x": 0,
            "y": 11,
            "z": 3,
            "elements": [
                "abyssalcraft:darkstone_brick@2"
            ]
        },
        {
            "x": 0,
            "y": 18,
            "z": 6,
            "elements": [
                "abyssalcraft:darkstone_brick@2"
            ]
        },
        {
            "x": -3,
            "y": 1,
            "z": 5,
            "elements": [
                "abyssalcraft:cstonebrick@0"
            ]
        },
        {
            "x": 0,
            "y": 10,
            "z": 3,
            "elements": [
                "abyssalcraft:darkstone_brick@2"
            ]
        },
        {
            "x": -3,
            "y": 23,
            "z": 6,
            "elements": [
                "abyssalcraft:ethaxiumbrick@0"
            ]
        },
        {
            "x": 0,
            "y": 23,
            "z": 8,
            "elements": [
                "abyssalcraft:ethaxiumbrick@0"
            ]
        },
        {
            "x": -1,
            "y": 33,
            "z": 2,
            "elements": [
                "abyssalcraft:darkethaxiumbrick@2"
            ]
        },
        {
            "x": 0,
            "y": 21,
            "z": 6,
            "elements": [
                "abyssalcraft:ethaxiumbrick@0"
            ]
        },
        {
            "x": 0,
            "y": 24,
            "z": 8,
            "elements": [
                "abyssalcraft:coraliumcobblestoneslab1@0"
            ]
        },
        {
            "x": 0,
            "y": 13,
            "z": 4,
            "elements": [
                "abyssalcraft:darkstone_brick@2"
            ]
        },
        {
            "x": -2,
            "y": 23,
            "z": 2,
            "elements": [
                "abyssalcraft:ethaxiumbrick@0"
            ]
        },
        {
            "x": -1,
            "y": 36,
            "z": 4,
            "elements": [
                "minecraft:stained_glass@14"
            ]
        },
        {
            "x": 0,
            "y": 14,
            "z": 3,
            "elements": [
                "abyssalcraft:darkstone_brick@2"
            ]
        },
        {
            "x": -1,
            "y": 33,
            "z": 7,
            "elements": [
                "minecraft:stained_glass@14"
            ]
        },
        {
            "x": -1,
            "y": 34,
            "z": 2,
            "elements": [
                "abyssalcraft:coraliumcobblestonestairs@3"
            ]
        },
        {
            "x": 0,
            "y": 22,
            "z": 6,
            "elements": [
                "abyssalcraft:ethaxiumbrick@0"
            ]
        },
        {
            "x": -1,
            "y": 32,
            "z": 7,
            "elements": [
                "abyssalcraft:cstonebrick@0"
            ]
        },
        {
            "x": 0,
            "y": 7,
            "z": 3,
            "elements": [
                "abyssalcraft:darkstone_brick@2"
            ]
        },
        {
            "x": 0,
            "y": 20,
            "z": 6,
            "elements": [
                "abyssalcraft:darkstone_brick@2"
            ]
        },
        {
            "x": -4,
            "y": -1,
            "z": 5,
            "elements": [
                "abyssalcraft:cstonebrick@0"
            ]
        },
        {
            "x": -3,
            "y": 23,
            "z": 8,
            "elements": [
                "abyssalcraft:dreadstonecobblestoneslab1@8"
            ]
        },
        {
            "x": -1,
            "y": 23,
            "z": -2,
            "elements": [
                "abyssalcraft:coraliumcobblestoneslab1@8"
            ]
        },
        {
            "x": 0,
            "y": 14,
            "z": 4,
            "elements": [
                "abyssalcraft:darkstone_brick@2"
            ]
        },
        {
            "x": 0,
            "y": 8,
            "z": 3,
            "elements": [
                "abyssalcraft:darkstone_brick@2"
            ]
        },
        {
            "x": 0,
            "y": 6,
            "z": 3,
            "elements": [
                "abyssalcraft:darkstone_brick@2"
            ]
        },
        {
            "x": -3,
            "y": 6,
            "z": 5,
            "elements": [
                "abyssalcraft:decorativestatue@4"
            ]
        },
        {
            "x": -1,
            "y": 32,
            "z": 3,
            "elements": [
                "abyssalcraft:cstonebrick@0"
            ]
        },
        {
            "x": -1,
            "y": -2,
            "z": 5,
            "elements": [
                "minecraft:magma@0"
            ]
        },
        {
            "x": -1,
            "y": 35,
            "z": 7,
            "elements": [
                "minecraft:stained_glass@14"
            ]
        },
        {
            "x": 2,
            "y": 25,
            "z": 2,
            "elements": [
                "abyssalcraft:darkethaxiumbrick@0"
            ]
        },
        {
            "x": 0,
            "y": 12,
            "z": 7,
            "elements": [
                "abyssalcraft:darkstone_brick@2"
            ]
        },
        {
            "x": -1,
            "y": 33,
            "z": 3,
            "elements": [
                "minecraft:stained_glass@14"
            ]
        },
        {
            "x": 0,
            "y": 5,
            "z": 3,
            "elements": [
                "abyssalcraft:darkstone_brick@2"
            ]
        },
        {
            "x": -3,
            "y": 5,
            "z": 5,
            "elements": [
                "abyssalcraft:monolithpillar@0"
            ]
        },
        {
            "x": -1,
            "y": 34,
            "z": 7,
            "elements": [
                "minecraft:stained_glass@14"
            ]
        },
        {
            "x": 2,
            "y": 33,
            "z": 4,
            "elements": [
                "abyssalcraft:cstonebrick@0"
            ]
        },
        {
            "x": 2,
            "y": -1,
            "z": 3,
            "elements": [
                "abyssalcraft:cstonebrick@0"
            ]
        },
        {
            "x": -2,
            "y": 24,
            "z": 16,
            "elements": [
                "abyssalcraft:dreadstonecobblestoneslab1@8"
            ]
        },
        {
            "x": 1,
            "y": 26,
            "z": 8,
            "elements": [
                "abyssalcraft:ethaxiumbrick@0"
            ]
        },
        {
            "x": -1,
            "y": 38,
            "z": 7,
            "elements": [
                "abyssalcraft:monolithpillar@0"
            ]
        },
        {
            "x": -6,
            "y": -2,
            "z": 5,
            "elements": [
                "abyssalcraft:cstonebrick@0"
            ]
        },
        {
            "x": -1,
            "y": 11,
            "z": 4,
            "elements": [
                "abyssalcraft:darkstone_brick@2"
            ]
        },
        {
            "x": 0,
            "y": 11,
            "z": 7,
            "elements": [
                "abyssalcraft:darkstone_brick@2"
            ]
        },
        {
            "x": -1,
            "y": 24,
            "z": -3,
            "elements": [
                "abyssalcraft:coraliumcobblestoneslab1@8"
            ]
        },
        {
            "x": 0,
            "y": 14,
            "z": 6,
            "elements": [
                "abyssalcraft:darkstone_brick@2"
            ]
        },
        {
            "x": 2,
            "y": 34,
            "z": 4,
            "elements": [
                "abyssalcraft:cstonebrick@0"
            ]
        },
        {
            "x": 0,
            "y": 4,
            "z": 3,
            "elements": [
                "abyssalcraft:darkstone_brick@2"
            ]
        },
        {
            "x": 0,
            "y": 19,
            "z": 3,
            "elements": [
                "abyssalcraft:darkstone_brick@2"
            ]
        },
        {
            "x": -1,
            "y": 34,
            "z": 3,
            "elements": [
                "minecraft:stained_glass@14"
            ]
        },
        {
            "x": 0,
            "y": 17,
            "z": 6,
            "elements": [
                "abyssalcraft:darkstone_brick@2"
            ]
        },
        {
            "x": -3,
            "y": 4,
            "z": 5,
            "elements": [
                "abyssalcraft:monolithpillar@0"
            ]
        },
        {
            "x": 0,
            "y": 15,
            "z": 6,
            "elements": [
                "abyssalcraft:darkstone_brick@2"
            ]
        },
        {
            "x": -1,
            "y": 23,
            "z": -3,
            "elements": [
                "abyssalcraft:dreadstonecobblestoneslab1@8"
            ]
        },
        {
            "x": 0,
            "y": -2,
            "z": 6,
            "elements": [
                "minecraft:magma@0"
            ]
        },
        {
            "x": 0,
            "y": 10,
            "z": 7,
            "elements": [
                "abyssalcraft:darkstone_brick@2"
            ]
        },
        {
            "x": 0,
            "y": 13,
            "z": 7,
            "elements": [
                "abyssalcraft:darkstone_brick@2"
            ]
        },
        {
            "x": 2,
            "y": 35,
            "z": 4,
            "elements": [
                "abyssalcraft:cstonebrick@0"
            ]
        },
        {
            "x": 0,
            "y": -2,
            "z": 11,
            "elements": [
                "abyssalcraft:cstonebrick@0"
            ]
        },
        {
            "x": -1,
            "y": 39,
            "z": 7,
            "elements": [
                "abyssalcraft:monolithpillar@0"
            ]
        },
        {
            "x": -1,
            "y": 35,
            "z": 3,
            "elements": [
                "minecraft:stained_glass@14"
            ]
        },
        {
            "x": -3,
            "y": 3,
            "z": 5,
            "elements": [
                "abyssalcraft:darkethaxiumbrick@1"
            ]
        },
        {
            "x": 0,
            "y": 16,
            "z": 6,
            "elements": [
                "abyssalcraft:darkstone_brick@2"
            ]
        },
        {
            "x": 0,
            "y": 3,
            "z": 3,
            "elements": [
                "abyssalcraft:darkstone_brick@2"
            ]
        },
        {
            "x": -1,
            "y": 35,
            "z": 6,
            "elements": [
                "minecraft:stained_glass@14"
            ]
        },
        {
            "x": 1,
            "y": 24,
            "z": 8,
            "elements": [
                "abyssalcraft:darkethaxiumbrick@0"
            ]
        },
        {
            "x": 1,
            "y": -2,
            "z": 5,
            "elements": [
                "minecraft:magma@0"
            ]
        },
        {
            "x": 0,
            "y": 33,
            "z": 6,
            "elements": [
                "minecraft:stained_glass@14"
            ]
        },
        {
            "x": -1,
            "y": 36,
            "z": 7,
            "elements": [
                "abyssalcraft:monolithpillar@0"
            ]
        },
        {
            "x": 1,
            "y": 4,
            "z": 6,
            "elements": [
                "abyssalcraft:darkstone_brick@2"
            ]
        },
        {
            "x": 3,
            "y": -2,
            "z": 6,
            "elements": [
                "abyssalcraft:cstonebrick@0"
            ]
        },
        {
            "x": 2,
            "y": 25,
            "z": 4,
            "elements": [
                "abyssalcraft:darkethaxiumbrick@0"
            ]
        },
        {
            "x": 0,
            "y": 12,
            "z": 6,
            "elements": [
                "abyssalcraft:darkstone_brick@2"
            ]
        },
        {
            "x": 0,
            "y": 9,
            "z": 7,
            "elements": [
                "abyssalcraft:darkstone_brick@2"
            ]
        },
        {
            "x": 2,
            "y": 37,
            "z": 6,
            "elements": [
                "abyssalcraft:monolithpillar@0"
            ]
        },
        {
            "x": 0,
            "y": 25,
            "z": 9,
            "elements": [
                "abyssalcraft:abyssalnitecobblestoneslab1@8"
            ]
        },
        {
            "x": -2,
            "y": 24,
            "z": -6,
            "elements": [
                "abyssalcraft:coraliumcobblestoneslab1@8"
            ]
        },
        {
            "x": 0,
            "y": 24,
            "z": 2,
            "elements": [
                "abyssalcraft:coraliumcobblestoneslab1@0"
            ]
        },
        {
            "x": -3,
            "y": 23,
            "z": 3,
            "elements": [
                "abyssalcraft:coraliumcobblestoneslab1@8"
            ]
        },
        {
            "x": 3,
            "y": 39,
            "z": 5,
            "elements": [
                "abyssalcraft:coraliumcobblestonestairs@1"
            ]
        },
        {
            "x": 0,
            "y": 13,
            "z": 6,
            "elements": [
                "abyssalcraft:darkstone_brick@2"
            ]
        },
        {
            "x": -4,
            "y": 24,
            "z": 1,
            "elements": [
                "abyssalcraft:dreadstonecobblestoneslab1@0"
            ]
        },
        {
            "x": -1,
            "y": 37,
            "z": 7,
            "elements": [
                "abyssalcraft:dreadstonecobblestonestairs@2"
            ]
        },
        {
            "x": 0,
            "y": -1,
            "z": 9,
            "elements": [
                "abyssalcraft:cstonebrick@0"
            ]
        },
        {
            "x": 2,
            "y": 26,
            "z": 4,
            "elements": [
                "abyssalcraft:darkethaxiumbrick@0"
            ]
        },
        {
            "x": 0,
            "y": 8,
            "z": 7,
            "elements": [
                "abyssalcraft:darkstone_brick@2"
            ]
        },
        {
            "x": 3,
            "y": -1,
            "z": 6,
            "elements": [
                "abyssalcraft:cstonebrick@0"
            ]
        },
        {
            "x": -1,
            "y": 36,
            "z": 6,
            "elements": [
                "minecraft:stained_glass@14"
            ]
        },
        {
            "x": 3,
            "y": 0,
            "z": 4,
            "elements": [
                "abyssalcraft:darkstone_brick@2"
            ]
        },
        {
            "x": 1,
            "y": 26,
            "z": 2,
            "elements": [
                "abyssalcraft:darkethaxiumbrick@0"
            ]
        },
        {
            "x": 2,
            "y": 41,
            "z": 5,
            "elements": [
                "abyssalcraft:monolithpillar@0"
            ]
        },
        {
            "x": 0,
            "y": 6,
            "z": 7,
            "elements": [
                "abyssalcraft:darkstone_brick@2"
            ]
        },
        {
            "x": -1,
            "y": 31,
            "z": 4,
            "elements": [
                "abyssalcraft:cstonebrick@0"
            ]
        },
        {
            "x": -1,
            "y": 40,
            "z": 6,
            "elements": [
                "abyssalcraft:coraliumcobblestoneslab1@0"
            ]
        },
        {
            "x": -3,
            "y": 0,
            "z": 4,
            "elements": [
                "abyssalcraft:darkstone_brick@2"
            ]
        },
        {
            "x": 1,
            "y": 5,
            "z": 6,
            "elements": [
                "abyssalcraft:darkstone_brick@2"
            ]
        },
        {
            "x": 2,
            "y": 35,
            "z": 6,
            "elements": [
                "abyssalcraft:cstonebrick@0"
            ]
        },
        {
            "x": 3,
            "y": 1,
            "z": 4,
            "elements": [
                "abyssalcraft:darkstone_brick@2"
            ]
        },
        {
            "x": 0,
            "y": 32,
            "z": 6,
            "elements": [
                "abyssalcraft:cstonebrick@0"
            ]
        },
        {
            "x": 2,
            "y": 40,
            "z": 5,
            "elements": [
                "abyssalcraft:monolithpillar@0"
            ]
        },
        {
            "x": 0,
            "y": 7,
            "z": 7,
            "elements": [
                "abyssalcraft:darkstone_brick@2"
            ]
        },
        {
            "x": 1,
            "y": 24,
            "z": 2,
            "elements": [
                "abyssalcraft:darkethaxiumbrick@0"
            ]
        },
        {
            "x": -4,
            "y": -1,
            "z": 4,
            "elements": [
                "abyssalcraft:cstonebrick@0"
            ]
        },
        {
            "x": 1,
            "y": 3,
            "z": 6,
            "elements": [
                "abyssalcraft:darkstone_brick@2"
            ]
        },
        {
            "x": 2,
            "y": 24,
            "z": 4,
            "elements": [
                "abyssalcraft:darkethaxiumbrick@2"
            ]
        },
        {
            "x": 0,
            "y": 31,
            "z": 6,
            "elements": [
                "abyssalcraft:cstonebrick@0"
            ]
        },
        {
            "x": 2,
            "y": 39,
            "z": 5,
            "elements": [
                "abyssalcraft:monolithpillar@0"
            ]
        },
        {
            "x": 0,
            "y": 11,
            "z": 6,
            "elements": [
                "abyssalcraft:darkstone_brick@2"
            ]
        },
        {
            "x": 2,
            "y": 36,
            "z": 6,
            "elements": [
                "abyssalcraft:abyssalnitecobblestonestairs@3"
            ]
        },
        {
            "x": 2,
            "y": 33,
            "z": 6,
            "elements": [
                "abyssalcraft:cstonebrick@0"
            ]
        },
        {
            "x": -4,
            "y": -2,
            "z": 4,
            "elements": [
                "abyssalcraft:cstonebrick@0"
            ]
        },
        {
            "x": -5,
            "y": -2,
            "z": 5,
            "elements": [
                "abyssalcraft:cstonebrick@0"
            ]
        },
        {
            "x": -1,
            "y": 33,
            "z": 4,
            "elements": [
                "minecraft:stained_glass@14"
            ]
        },
        {
            "x": 1,
            "y": 7,
            "z": 6,
            "elements": [
                "abyssalcraft:darkethaxiumbrick@1"
            ]
        },
        {
            "x": 0,
            "y": 4,
            "z": 7,
            "elements": [
                "abyssalcraft:darkstone_brick@2"
            ]
        },
        {
            "x": -1,
            "y": 34,
            "z": 4,
            "elements": [
                "minecraft:magma@0"
            ]
        },
        {
            "x": 2,
            "y": 38,
            "z": 5,
            "elements": [
                "abyssalcraft:cstonebrick@0"
            ]
        },
        {
            "x": -1,
            "y": 22,
            "z": 4,
            "elements": [
                "abyssalcraft:darkethaxiumbrick@0"
            ]
        },
        {
            "x": -5,
            "y": -1,
            "z": 5,
            "elements": [
                "abyssalcraft:cstonebrick@0"
            ]
        },
        {
            "x": 2,
            "y": 34,
            "z": 6,
            "elements": [
                "abyssalcraft:cstonebrick@0"
            ]
        },
        {
            "x": 2,
            "y": 37,
            "z": 5,
            "elements": [
                "abyssalcraft:cstonebrick@0"
            ]
        },
        {
            "x": -1,
            "y": 32,
            "z": 4,
            "elements": [
                "minecraft:stained_glass@14"
            ]
        },
        {
            "x": 0,
            "y": 5,
            "z": 7,
            "elements": [
                "abyssalcraft:darkstone_brick@2"
            ]
        },
        {
            "x": -1,
            "y": 35,
            "z": 4,
            "elements": [
                "minecraft:stained_glass@14"
            ]
        },
        {
            "x": -1,
            "y": 22,
            "z": 1,
            "elements": [
                "abyssalcraft:darkethaxiumbrick@0"
            ]
        },
        {
            "x": -2,
            "y": 23,
            "z": 8,
            "elements": [
                "abyssalcraft:ethaxiumbrick@0"
            ]
        },
        {
            "x": 1,
            "y": 9,
            "z": 6,
            "elements": [
                "abyssalcraft:darkstone_brick@2"
            ]
        },
        {
            "x": -1,
            "y": 21,
            "z": 4,
            "elements": [
                "abyssalcraft:darkethaxiumbrick@0"
            ]
        },
        {
            "x": 1,
            "y": 6,
            "z": 6,
            "elements": [
                "abyssalcraft:darkstone_brick@2"
            ]
        },
        {
            "x": -4,
            "y": 23,
            "z": 4,
            "elements": [
                "abyssalcraft:coraliumcobblestoneslab1@8"
            ]
        },
        {
            "x": 2,
            "y": 36,
            "z": 5,
            "elements": [
                "abyssalcraft:cstonebrick@0"
            ]
        },
        {
            "x": 2,
            "y": 28,
            "z": 4,
            "elements": [
                "abyssalcraft:abyssalnitecobblestonestairs@2"
            ]
        },
        {
            "x": 0,
            "y": 35,
            "z": 6,
            "elements": [
                "minecraft:stained_glass@14"
            ]
        },
        {
            "x": 2,
            "y": -1,
            "z": 7,
            "elements": [
                "abyssalcraft:cstonebrick@0"
            ]
        },
        {
            "x": -4,
            "y": 0,
            "z": 5,
            "elements": [
                "modularmachinery:blockcasing@0"
            ]
        },
        {
            "x": 2,
            "y": 26,
            "z": 7,
            "elements": [
                "abyssalcraft:ethaxiumbrick@0"
            ]
        },
        {
            "x": -1,
            "y": 23,
            "z": 1,
            "elements": [
                "abyssalcraft:darkethaxiumbrick@0"
            ]
        },
        {
            "x": 2,
            "y": 35,
            "z": 5,
            "elements": [
                "abyssalcraft:cstonebrick@0"
            ]
        },
        {
            "x": -1,
            "y": 20,
            "z": 4,
            "elements": [
                "abyssalcraft:darkethaxiumbrick@0"
            ]
        },
        {
            "x": -1,
            "y": 22,
            "z": 8,
            "elements": [
                "abyssalcraft:ethaxiumbrick@0"
            ]
        },
        {
            "x": -1,
            "y": 24,
            "z": -4,
            "elements": [
                "abyssalcraft:coraliumcobblestoneslab1@8"
            ]
        },
        {
            "x": 0,
            "y": 12,
            "z": 3,
            "elements": [
                "abyssalcraft:darkstone_brick@2"
            ]
        },
        {
            "x": 0,
            "y": 25,
            "z": -2,
            "elements": [
                "abyssalcraft:coraliumcobblestoneslab1@0"
            ]
        },
        {
            "x": 1,
            "y": 8,
            "z": 6,
            "elements": [
                "abyssalcraft:darkethaxiumbrick@1"
            ]
        },
        {
            "x": 2,
            "y": 27,
            "z": 4,
            "elements": [
                "abyssalcraft:darkethaxiumbrick@0"
            ]
        },
        {
            "x": 2,
            "y": -2,
            "z": 7,
            "elements": [
                "abyssalcraft:cstonebrick@0"
            ]
        },
        {
            "x": -1,
            "y": 24,
            "z": 1,
            "elements": [
                "abyssalcraft:abyssalnitecobblestoneslab1@0"
            ]
        },
        {
            "x": -1,
            "y": 19,
            "z": 4,
            "elements": [
                "abyssalcraft:ethaxiumbrick@0"
            ]
        },
        {
            "x": 0,
            "y": 13,
            "z": 3,
            "elements": [
                "abyssalcraft:darkstone_brick@2"
            ]
        },
        {
            "x": -4,
            "y": 1,
            "z": 5,
            "elements": [
                "modularmachinery:blockcasing@0"
            ]
        },
        {
            "x": -1,
            "y": 23,
            "z": 8,
            "elements": [
                "abyssalcraft:ethaxiumbrick@0"
            ]
        },
        {
            "x": 0,
            "y": 3,
            "z": 7,
            "elements": [
                "abyssalcraft:darkstone_brick@2"
            ]
        },
        {
            "x": -1,
            "y": 25,
            "z": -4,
            "elements": [
                "abyssalcraft:coraliumcobblestoneslab1@0"
            ]
        },
        {
            "x": 0,
            "y": 1,
            "z": 8,
            "elements": [
                "abyssalcraft:darkstone_brick@2"
            ]
        },
        {
            "x": 1,
            "y": 1,
            "z": 3,
            "elements": [
                "abyssalcraft:darkstone_brick@2"
            ]
        },
        {
            "x": 3,
            "y": 6,
            "z": 5,
            "elements": [
                "abyssalcraft:decorativestatue@2"
            ]
        },
        {
            "x": -1,
            "y": 11,
            "z": 5,
            "elements": [
                "abyssalcraft:darkstone_brick@2"
            ]
        },
        {
            "x": 0,
            "y": 25,
            "z": 12,
            "elements": [
                "abyssalcraft:coraliumcobblestoneslab1@0"
            ]
        },
        {
            "x": 1,
            "y": 36,
            "z": 5,
            "elements": [
                "abyssalcraft:monolithpillar@0"
            ]
        },
        {
            "x": 5,
            "y": -2,
            "z": 5,
            "elements": [
                "abyssalcraft:cstonebrick@0"
            ]
        },
        {
            "x": 1,
            "y": 35,
            "z": 5,
            "elements": [
                "minecraft:stained_glass@14"
            ]
        },
        {
            "x": 1,
            "y": 10,
            "z": 6,
            "elements": [
                "abyssalcraft:darkstone_brick@2"
            ]
        },
        {
            "x": -4,
            "y": 34,
            "z": 6,
            "elements": [
                "abyssalcraft:coraliumcobblestoneslab1@0"
            ]
        },
        {
            "x": 2,
            "y": 33,
            "z": 5,
            "elements": [
                "abyssalcraft:cstonebrick@0"
            ]
        },
        {
            "x": 0,
            "y": 24,
            "z": -2,
            "elements": [
                "abyssalcraft:ethaxiumbrick@0"
            ]
        },
        {
            "x": 0,
            "y": 24,
            "z": 1,
            "elements": [
                "abyssalcraft:darkethaxiumbrick@2"
            ]
        },
        {
            "x": 0,
            "y": 24,
            "z": 12,
            "elements": [
                "abyssalcraft:ethaxiumbrick@0"
            ]
        },
        {
            "x": 2,
            "y": 25,
            "z": 7,
            "elements": [
                "abyssalcraft:ethaxiumbrick@0"
            ]
        },
        {
            "x": -1,
            "y": 12,
            "z": 5,
            "elements": [
                "abyssalcraft:darkstone_brick@2"
            ]
        },
        {
            "x": 3,
            "y": 5,
            "z": 5,
            "elements": [
                "abyssalcraft:monolithpillar@0"
            ]
        },
        {
            "x": 2,
            "y": 24,
            "z": 6,
            "elements": [
                "abyssalcraft:ethaxiumbrick@0"
            ]
        },
        {
            "x": 2,
            "y": 34,
            "z": 5,
            "elements": [
                "abyssalcraft:cstonebrick@0"
            ]
        },
        {
            "x": 1,
            "y": 11,
            "z": 6,
            "elements": [
                "abyssalcraft:darkstone_brick@2"
            ]
        },
        {
            "x": 1,
            "y": 3,
            "z": 3,
            "elements": [
                "abyssalcraft:darkstone_brick@2"
            ]
        },
        {
            "x": -2,
            "y": 34,
            "z": 1,
            "elements": [
                "abyssalcraft:darkethaxiumbrick@2"
            ]
        },
        {
            "x": 0,
            "y": 2,
            "z": 8,
            "elements": [
                "abyssalcraft:darkstone_brick@2"
            ]
        },
        {
            "x": 5,
            "y": -1,
            "z": 5,
            "elements": [
                "abyssalcraft:cstonebrick@0"
            ]
        },
        {
            "x": -1,
            "y": 13,
            "z": 5,
            "elements": [
                "abyssalcraft:darkstone_brick@2"
            ]
        },
        {
            "x": 1,
            "y": 38,
            "z": 5,
            "elements": [
                "abyssalcraft:monolithpillar@0"
            ]
        },
        {
            "x": -2,
            "y": 35,
            "z": 1,
            "elements": [
                "abyssalcraft:dreadstonecobblestonestairs@2"
            ]
        },
        {
            "x": -2,
            "y": 3,
            "z": 4,
            "elements": [
                "abyssalcraft:darkstone_brick@2"
            ]
        },
        {
            "x": 3,
            "y": 4,
            "z": 5,
            "elements": [
                "abyssalcraft:monolithpillar@0"
            ]
        },
        {
            "x": 2,
            "y": 28,
            "z": 6,
            "elements": [
                "abyssalcraft:dreadstonecobblestonestairs@3"
            ]
        },
        {
            "x": -1,
            "y": 14,
            "z": 5,
            "elements": [
                "abyssalcraft:darkstone_brick@2"
            ]
        },
        {
            "x": 5,
            "y": 28,
            "z": 5,
            "elements": [
                "abyssalcraft:darkethaxiumbrick@0"
            ]
        },
        {
            "x": 0,
            "y": 3,
            "z": 8,
            "elements": [
                "abyssalcraft:darkstone_brick@2"
            ]
        },
        {
            "x": 2,
            "y": 25,
            "z": 6,
            "elements": [
                "abyssalcraft:ethaxiumbrick@0"
            ]
        },
        {
            "x": -1,
            "y": -2,
            "z": 8,
            "elements": [
                "abyssalcraft:cstonebrick@0"
            ]
        },
        {
            "x": 2,
            "y": 27,
            "z": 6,
            "elements": [
                "abyssalcraft:ethaxiumbrick@0"
            ]
        },
        {
            "x": 2,
            "y": -2,
            "z": 8,
            "elements": [
                "abyssalcraft:cstonebrick@0"
            ]
        },
        {
            "x": 1,
            "y": 37,
            "z": 5,
            "elements": [
                "abyssalcraft:monolithpillar@0"
            ]
        },
        {
            "x": 2,
            "y": 32,
            "z": 5,
            "elements": [
                "abyssalcraft:cstonebrick@0"
            ]
        },
        {
            "x": -2,
            "y": 36,
            "z": 2,
            "elements": [
                "abyssalcraft:monolithpillar@0"
            ]
        },
        {
            "x": 1,
            "y": 0,
            "z": 3,
            "elements": [
                "abyssalcraft:darkstone_brick@2"
            ]
        },
        {
            "x": 5,
            "y": 27,
            "z": 5,
            "elements": [
                "abyssalcraft:darkethaxiumbrick@0"
            ]
        },
        {
            "x": 0,
            "y": 4,
            "z": 8,
            "elements": [
                "abyssalcraft:darkstone_brick@2"
            ]
        },
        {
            "x": 3,
            "y": 3,
            "z": 5,
            "elements": [
                "abyssalcraft:darkethaxiumbrick@1"
            ]
        },
        {
            "x": -2,
            "y": 3,
            "z": 3,
            "elements": [
                "abyssalcraft:decorativestatue@6"
            ]
        },
        {
            "x": 4,
            "y": -1,
            "z": 5,
            "elements": [
                "abyssalcraft:cstonebrick@0"
            ]
        },
        {
            "x": 2,
            "y": 26,
            "z": 6,
            "elements": [
                "abyssalcraft:darkethaxiumbrick@0"
            ]
        },
        {
            "x": -4,
            "y": 23,
            "z": 6,
            "elements": [
                "abyssalcraft:dreadstonecobblestoneslab1@8"
            ]
        },
        {
            "x": 3,
            "y": 1,
            "z": 5,
            "elements": [
                "abyssalcraft:cstonebrick@0"
            ]
        },
        {
            "x": -1,
            "y": 21,
            "z": 7,
            "elements": [
                "abyssalcraft:darkethaxiumbrick@2"
            ]
        },
        {
            "x": 0,
            "y": -2,
            "z": 4,
            "elements": [
                "minecraft:magma@0"
            ]
        },
        {
            "x": 1,
            "y": 31,
            "z": 5,
            "elements": [
                "abyssalcraft:cstonebrick@0"
            ]
        },
        {
            "x": -2,
            "y": 19,
            "z": 6,
            "elements": [
                "abyssalcraft:darkethaxiumbrick@2"
            ]
        },
        {
            "x": -2,
            "y": 1,
            "z": 4,
            "elements": [
                "abyssalcraft:darkstone_brick@2"
            ]
        },
        {
            "x": 2,
            "y": 4,
            "z": 5,
            "elements": [
                "abyssalcraft:darkstone_brick@2"
            ]
        },
        {
            "x": 0,
            "y": 33,
            "z": 7,
            "elements": [
                "abyssalcraft:cstonebrick@0"
            ]
        },
        {
            "x": 1,
            "y": 26,
            "z": 1,
            "elements": [
                "abyssalcraft:darkethaxiumbrick@0"
            ]
        },
        {
            "x": 3,
            "y": 2,
            "z": 5,
            "elements": [
                "modularmachinery:blockcasing@0"
            ]
        },
        {
            "x": -1,
            "y": 32,
            "z": 6,
            "elements": [
                "minecraft:stained_glass@14"
            ]
        },
        {
            "x": 7,
            "y": -2,
            "z": 5,
            "elements": [
                "abyssalcraft:cstonebrick@0"
            ]
        },
        {
            "x": 0,
            "y": 32,
            "z": 7,
            "elements": [
                "abyssalcraft:cstonebrick@0"
            ]
        },
        {
            "x": 1,
            "y": 32,
            "z": 5,
            "elements": [
                "abyssalcraft:cstonebrick@0"
            ]
        },
        {
            "x": -3,
            "y": -1,
            "z": 4,
            "elements": [
                "abyssalcraft:cstonebrick@0"
            ]
        },
        {
            "x": 0,
            "y": 25,
            "z": 1,
            "elements": [
                "abyssalcraft:dreadstonecobblestoneslab1@8"
            ]
        },
        {
            "x": 2,
            "y": 3,
            "z": 5,
            "elements": [
                "abyssalcraft:darkstone_brick@2"
            ]
        },
        {
            "x": -1,
            "y": 31,
            "z": 6,
            "elements": [
                "abyssalcraft:cstonebrick@0"
            ]
        },
        {
            "x": -2,
            "y": 18,
            "z": 6,
            "elements": [
                "abyssalcraft:ethaxiumbrick@0"
            ]
        },
        {
            "x": -3,
            "y": 33,
            "z": 7,
            "elements": [
                "abyssalcraft:cstonebrick@0"
            ]
        },
        {
            "x": -2,
            "y": 2,
            "z": 4,
            "elements": [
                "abyssalcraft:darkstone_brick@2"
            ]
        },
        {
            "x": 4,
            "y": 27,
            "z": 5,
            "elements": [
                "abyssalcraft:darkethaxiumbrick@0"
            ]
        },
        {
            "x": 1,
            "y": 25,
            "z": 1,
            "elements": [
                "abyssalcraft:darkethaxiumbrick@0"
            ]
        },
        {
            "x": -1,
            "y": 8,
            "z": 5,
            "elements": [
                "abyssalcraft:darkstone_brick@2"
            ]
        },
        {
            "x": 2,
            "y": 6,
            "z": 5,
            "elements": [
                "abyssalcraft:darkstone_brick@2"
            ]
        },
        {
            "x": -1,
            "y": -1,
            "z": 8,
            "elements": [
                "abyssalcraft:cstonebrick@0"
            ]
        },
        {
            "x": -2,
            "y": 21,
            "z": 6,
            "elements": [
                "abyssalcraft:ethaxiumbrick@0"
            ]
        },
        {
            "x": -2,
            "y": 23,
            "z": 0,
            "elements": [
                "abyssalcraft:coraliumcobblestoneslab1@8"
            ]
        },
        {
            "x": -1,
            "y": 9,
            "z": 5,
            "elements": [
                "abyssalcraft:darkstone_brick@2"
            ]
        },
        {
            "x": -3,
            "y": 1,
            "z": 4,
            "elements": [
                "abyssalcraft:darkstone_brick@2"
            ]
        },
        {
            "x": -2,
            "y": 35,
            "z": 5,
            "elements": [
                "minecraft:stained_glass@14"
            ]
        },
        {
            "x": 2,
            "y": 7,
            "z": 5,
            "elements": [
                "abyssalcraft:darkstone_brick@2"
            ]
        },
        {
            "x": 1,
            "y": 2,
            "z": 3,
            "elements": [
                "abyssalcraft:darkstone_brick@2"
            ]
        },
        {
            "x": 1,
            "y": 33,
            "z": 5,
            "elements": [
                "minecraft:stained_glass@14"
            ]
        },
        {
            "x": -2,
            "y": 22,
            "z": 6,
            "elements": [
                "abyssalcraft:ethaxiumbrick@0"
            ]
        },
        {
            "x": 0,
            "y": 25,
            "z": -1,
            "elements": [
                "abyssalcraft:darkethaxiumbrick@0"
            ]
        },
        {
            "x": 2,
            "y": 25,
            "z": 8,
            "elements": [
                "abyssalcraft:ethaxiumbrick@0"
            ]
        },
        {
            "x": 7,
            "y": 30,
            "z": 5,
            "elements": [
                "abyssalcraft:monolithpillar@0"
            ]
        },
        {
            "x": 0,
            "y": 0,
            "z": 8,
            "elements": [
                "abyssalcraft:darkstone_brick@2"
            ]
        },
        {
            "x": 2,
            "y": 5,
            "z": 5,
            "elements": [
                "abyssalcraft:darkstone_brick@2"
            ]
        },
        {
            "x": -2,
            "y": 20,
            "z": 6,
            "elements": [
                "abyssalcraft:ethaxiumbrick@0"
            ]
        },
        {
            "x": -1,
            "y": 34,
            "z": 6,
            "elements": [
                "minecraft:magma@0"
            ]
        },
        {
            "x": -1,
            "y": 10,
            "z": 5,
            "elements": [
                "abyssalcraft:darkstone_brick@2"
            ]
        },
        {
            "x": -2,
            "y": 36,
            "z": 5,
            "elements": [
                "minecraft:stained_glass@14"
            ]
        },
        {
            "x": 2,
            "y": 8,
            "z": 5,
            "elements": [
                "abyssalcraft:darkstone_brick@2"
            ]
        },
        {
            "x": 3,
            "y": -2,
            "z": 3,
            "elements": [
                "abyssalcraft:cstonebrick@0"
            ]
        },
        {
            "x": 1,
            "y": 34,
            "z": 5,
            "elements": [
                "minecraft:stained_glass@14"
            ]
        },
        {
            "x": -1,
            "y": 33,
            "z": 6,
            "elements": [
                "minecraft:stained_glass@14"
            ]
        },
        {
            "x": -1,
            "y": 24,
            "z": -5,
            "elements": [
                "abyssalcraft:coraliumcobblestoneslab1@8"
            ]
        },
        {
            "x": -1,
            "y": 24,
            "z": 14,
            "elements": [
                "abyssalcraft:coraliumcobblestoneslab1@8"
            ]
        },
        {
            "x": -1,
            "y": 8,
            "z": 4,
            "elements": [
                "abyssalcraft:darkethaxiumbrick@1"
            ]
        },
        {
            "x": -1,
            "y": 21,
            "z": 6,
            "elements": [
                "abyssalcraft:ethaxiumbrick@0"
            ]
        },
        {
            "x": 0,
            "y": -1,
            "z": 10,
            "elements": [
                "abyssalcraft:cstonebrick@0"
            ]
        },
        {
            "x": -1,
            "y": -1,
            "z": 3,
            "elements": [
                "abyssalcraft:darkstone_brick@2"
            ]
        },
        {
            "x": 0,
            "y": 23,
            "z": 7,
            "elements": [
                "abyssalcraft:ethaxiumbrick@0"
            ]
        },
        {
            "x": -1,
            "y": 38,
            "z": 8,
            "elements": [
                "abyssalcraft:coraliumcobblestonestairs@3"
            ]
        },
        {
            "x": 7,
            "y": 31,
            "z": 5,
            "elements": [
                "abyssalcraft:monolithpillar@0"
            ]
        },
        {
            "x": -4,
            "y": 23,
            "z": 5,
            "elements": [
                "abyssalcraft:ethaxiumbrick@0"
            ]
        },
        {
            "x": 0,
            "y": 25,
            "z": 10,
            "elements": [
                "abyssalcraft:darkethaxiumbrick@0"
            ]
        },
        {
            "x": -1,
            "y": 22,
            "z": 6,
            "elements": [
                "abyssalcraft:ethaxiumbrick@0"
            ]
        },
        {
            "x": -1,
            "y": 7,
            "z": 4,
            "elements": [
                "abyssalcraft:darkethaxiumbrick@1"
            ]
        },
        {
            "x": 1,
            "y": 42,
            "z": 5,
            "elements": [
                "abyssalcraft:abyssalnitecobblestoneslab1@0"
            ]
        },
        {
            "x": 0,
            "y": -2,
            "z": 10,
            "elements": [
                "abyssalcraft:cstonebrick@0"
            ]
        },
        {
            "x": -1,
            "y": 20,
            "z": 6,
            "elements": [
                "abyssalcraft:ethaxiumbrick@0"
            ]
        },
        {
            "x": 0,
            "y": 22,
            "z": 7,
            "elements": [
                "abyssalcraft:ethaxiumbrick@0"
            ]
        },
        {
            "x": 2,
            "y": -2,
            "z": 3,
            "elements": [
                "abyssalcraft:cstonebrick@0"
            ]
        },
        {
            "x": 0,
            "y": 24,
            "z": -1,
            "elements": [
                "abyssalcraft:darkethaxiumbrick@0"
            ]
        },
        {
            "x": -3,
            "y": -2,
            "z": 4,
            "elements": [
                "abyssalcraft:cstonebrick@0"
            ]
        },
        {
            "x": 1,
            "y": 23,
            "z": 6,
            "elements": [
                "abyssalcraft:ethaxiumbrick@0"
            ]
        },
        {
            "x": 2,
            "y": 3,
            "z": 4,
            "elements": [
                "abyssalcraft:darkstone_brick@2"
            ]
        },
        {
            "x": -1,
            "y": 19,
            "z": 6,
            "elements": [
                "abyssalcraft:ethaxiumbrick@0"
            ]
        },
        {
            "x": -1,
            "y": 10,
            "z": 4,
            "elements": [
                "abyssalcraft:darkstone_brick@2"
            ]
        },
        {
            "x": -1,
            "y": 23,
            "z": 7,
            "elements": [
                "abyssalcraft:ethaxiumbrick@0"
            ]
        },
        {
            "x": -1,
            "y": 25,
            "z": 14,
            "elements": [
                "abyssalcraft:dreadstonecobblestoneslab1@0"
            ]
        },
        {
            "x": -3,
            "y": 34,
            "z": 6,
            "elements": [
                "minecraft:stained_glass@14"
            ]
        },
        {
            "x": -1,
            "y": 22,
            "z": 7,
            "elements": [
                "abyssalcraft:ethaxiumbrick@0"
            ]
        },
        {
            "x": -3,
            "y": -2,
            "z": 3,
            "elements": [
                "abyssalcraft:cstonebrick@0"
            ]
        },
        {
            "x": -7,
            "y": -2,
            "z": 5,
            "elements": [
                "abyssalcraft:cstonebrick@0"
            ]
        },
        {
            "x": -1,
            "y": 9,
            "z": 4,
            "elements": [
                "abyssalcraft:darkstone_brick@2"
            ]
        },
        {
            "x": 0,
            "y": 6,
            "z": 8,
            "elements": [
                "abyssalcraft:darkstone_brick@2"
            ]
        },
        {
            "x": 0,
            "y": 19,
            "z": 7,
            "elements": [
                "abyssalcraft:darkstone_brick@2"
            ]
        },
        {
            "x": 0,
            "y": 23,
            "z": 6,
            "elements": [
                "abyssalcraft:ethaxiumbrick@0"
            ]
        },
        {
            "x": -1,
            "y": 1,
            "z": 3,
            "elements": [
                "abyssalcraft:darkstone_brick@2"
            ]
        },
        {
            "x": -1,
            "y": 23,
            "z": 12,
            "elements": [
                "abyssalcraft:dreadstonecobblestoneslab1@8"
            ]
        },
        {
            "x": -2,
            "y": 23,
            "z": 1,
            "elements": [
                "abyssalcraft:coraliumcobblestoneslab1@8"
            ]
        },
        {
            "x": -1,
            "y": 23,
            "z": -1,
            "elements": [
                "abyssalcraft:darkethaxiumbrick@2"
            ]
        },
        {
            "x": 2,
            "y": 1,
            "z": 4,
            "elements": [
                "abyssalcraft:darkstone_brick@2"
            ]
        },
        {
            "x": -1,
            "y": 16,
            "z": 5,
            "elements": [
                "abyssalcraft:darkstone_brick@2"
            ]
        },
        {
            "x": 1,
            "y": -2,
            "z": 9,
            "elements": [
                "abyssalcraft:cstonebrick@0"
            ]
        },
        {
            "x": -1,
            "y": 21,
            "z": 5,
            "elements": [
                "abyssalcraft:darkethaxiumbrick@2"
            ]
        },
        {
            "x": 2,
            "y": 2,
            "z": 4,
            "elements": [
                "abyssalcraft:darkstone_brick@2"
            ]
        },
        {
            "x": 1,
            "y": 22,
            "z": 6,
            "elements": [
                "abyssalcraft:ethaxiumbrick@0"
            ]
        },
        {
            "x": -1,
            "y": 2,
            "z": 3,
            "elements": [
                "abyssalcraft:darkstone_brick@2"
            ]
        },
        {
            "x": 0,
            "y": 5,
            "z": 8,
            "elements": [
                "abyssalcraft:darkstone_brick@2"
            ]
        },
        {
            "x": -1,
            "y": 4,
            "z": 4,
            "elements": [
                "abyssalcraft:darkstone_brick@2"
            ]
        },
        {
            "x": 3,
            "y": -2,
            "z": 4,
            "elements": [
                "abyssalcraft:cstonebrick@0"
            ]
        },
        {
            "x": -1,
            "y": 35,
            "z": 8,
            "elements": [
                "abyssalcraft:monolithpillar@0"
            ]
        },
        {
            "x": -2,
            "y": 0,
            "z": 3,
            "elements": [
                "abyssalcraft:darkethaxiumbrick@2"
            ]
        },
        {
            "x": -3,
            "y": 24,
            "z": 7,
            "elements": [
                "abyssalcraft:monolithpillar@0"
            ]
        },
        {
            "x": -1,
            "y": 15,
            "z": 5,
            "elements": [
                "abyssalcraft:darkstone_brick@2"
            ]
        },
        {
            "x": -1,
            "y": 5,
            "z": 4,
            "elements": [
                "abyssalcraft:darkstone_brick@2"
            ]
        },
        {
            "x": 0,
            "y": 21,
            "z": 7,
            "elements": [
                "abyssalcraft:darkstone_brick@2"
            ]
        },
        {
            "x": -1,
            "y": 36,
            "z": 8,
            "elements": [
                "abyssalcraft:monolithpillar@0"
            ]
        },
        {
            "x": -1,
            "y": 18,
            "z": 5,
            "elements": [
                "abyssalcraft:darkethaxiumbrick@0"
            ]
        },
        {
            "x": 0,
            "y": 24,
            "z": 10,
            "elements": [
                "abyssalcraft:ethaxiumbrick@0"
            ]
        },
        {
            "x": -2,
            "y": 1,
            "z": 3,
            "elements": [
                "abyssalcraft:monolithpillar@0"
            ]
        },
        {
            "x": -1,
            "y": 6,
            "z": 4,
            "elements": [
                "abyssalcraft:darkstone_brick@2"
            ]
        },
        {
            "x": -2,
            "y": -1,
            "z": 3,
            "elements": [
                "abyssalcraft:cstonebrick@0"
            ]
        },
        {
            "x": -3,
            "y": 23,
            "z": 7,
            "elements": [
                "abyssalcraft:dreadstonecobblestoneslab1@8"
            ]
        },
        {
            "x": 0,
            "y": 8,
            "z": 8,
            "elements": [
                "abyssalcraft:darkstone_brick@2"
            ]
        },
        {
            "x": -2,
            "y": 2,
            "z": 3,
            "elements": [
                "abyssalcraft:monolithpillar@0"
            ]
        },
        {
            "x": -1,
            "y": 17,
            "z": 5,
            "elements": [
                "abyssalcraft:darkstone_brick@2"
            ]
        },
        {
            "x": -1,
            "y": 0,
            "z": 3,
            "elements": [
                "abyssalcraft:darkstone_brick@2"
            ]
        },
        {
            "x": 0,
            "y": 20,
            "z": 7,
            "elements": [
                "abyssalcraft:darkstone_brick@2"
            ]
        },
        {
            "x": -1,
            "y": -2,
            "z": 3,
            "elements": [
                "abyssalcraft:darkstone_brick@2"
            ]
        },
        {
            "x": 1,
            "y": 3,
            "z": 4,
            "elements": [
                "abyssalcraft:darkstone_brick@2"
            ]
        },
        {
            "x": -7,
            "y": 24,
            "z": 5,
            "elements": [
                "abyssalcraft:coraliumcobblestoneslab1@8"
            ]
        },
        {
            "x": 0,
            "y": 7,
            "z": 8,
            "elements": [
                "abyssalcraft:darkstone_brick@2"
            ]
        },
        {
            "x": -4,
            "y": 22,
            "z": 5,
            "elements": [
                "abyssalcraft:darkethaxiumbrick@0"
            ]
        },
        {
            "x": -1,
            "y": 37,
            "z": 8,
            "elements": [
                "abyssalcraft:darkethaxiumbrick@2"
            ]
        },
        {
            "x": -2,
            "y": 33,
            "z": 7,
            "elements": [
                "abyssalcraft:cstonebrick@0"
            ]
        },
        {
            "x": 1,
            "y": -1,
            "z": 7,
            "elements": [
                "abyssalcraft:darkstone_brick@2"
            ]
        },
        {
            "x": 2,
            "y": 2,
            "z": 6,
            "elements": [
                "abyssalcraft:darkstone_brick@2"
            ]
        },
        {
            "x": -1,
            "y": 24,
            "z": 10,
            "elements": [
                "abyssalcraft:dreadstonecobblestoneslab1@0"
            ]
        },
        {
            "x": 0,
            "y": 5,
            "z": 2,
            "elements": [
                "abyssalcraft:darkstone_brick@2"
            ]
        },
        {
            "x": 0,
            "y": 7,
            "z": 9,
            "elements": [
                "abyssalcraft:decorativestatue@1"
            ]
        },
        {
            "x": 0,
            "y": 6,
            "z": 2,
            "elements": [
                "abyssalcraft:darkstone_brick@2"
            ]
        },
        {
            "x": -1,
            "y": 2,
            "z": 7,
            "elements": [
                "abyssalcraft:darkstone_brick@2"
            ]
        },
        {
            "x": 2,
            "y": 19,
            "z": 5,
            "elements": [
                "abyssalcraft:darkethaxiumbrick@0"
            ]
        },
        {
            "x": -1,
            "y": 7,
            "z": 6,
            "elements": [
                "abyssalcraft:darkethaxiumbrick@1"
            ]
        },
        {
            "x": 1,
            "y": 21,
            "z": 5,
            "elements": [
                "abyssalcraft:darkethaxiumbrick@0"
            ]
        },
        {
            "x": 1,
            "y": 32,
            "z": 6,
            "elements": [
                "abyssalcraft:cstonebrick@0"
            ]
        },
        {
            "x": 0,
            "y": 5,
            "z": 9,
            "elements": [
                "abyssalcraft:monolithpillar@0"
            ]
        },
        {
            "x": 0,
            "y": 6,
            "z": 9,
            "elements": [
                "abyssalcraft:monolithpillar@0"
            ]
        },
        {
            "x": -1,
            "y": 23,
            "z": 10,
            "elements": [
                "abyssalcraft:darkethaxiumbrick@0"
            ]
        },
        {
            "x": -5,
            "y": 32,
            "z": 5,
            "elements": [
                "abyssalcraft:monolithpillar@0"
            ]
        },
        {
            "x": 1,
            "y": 22,
            "z": 5,
            "elements": [
                "abyssalcraft:darkethaxiumbrick@0"
            ]
        },
        {
            "x": 1,
            "y": 4,
            "z": 4,
            "elements": [
                "abyssalcraft:darkstone_brick@2"
            ]
        },
        {
            "x": 2,
            "y": 3,
            "z": 6,
            "elements": [
                "abyssalcraft:darkstone_brick@2"
            ]
        },
        {
            "x": -1,
            "y": 23,
            "z": 13,
            "elements": [
                "abyssalcraft:dreadstonecobblestoneslab1@8"
            ]
        },
        {
            "x": 0,
            "y": 4,
            "z": 2,
            "elements": [
                "abyssalcraft:darkstone_brick@2"
            ]
        },
        {
            "x": -1,
            "y": 6,
            "z": 6,
            "elements": [
                "abyssalcraft:darkstone_brick@2"
            ]
        },
        {
            "x": 1,
            "y": 27,
            "z": 7,
            "elements": [
                "abyssalcraft:dreadstonecobblestoneslab1@0"
            ]
        },
        {
            "x": -2,
            "y": -2,
            "z": 3,
            "elements": [
                "abyssalcraft:cstonebrick@0"
            ]
        },
        {
            "x": -1,
            "y": 3,
            "z": 7,
            "elements": [
                "abyssalcraft:darkstone_brick@2"
            ]
        },
        {
            "x": -1,
            "y": 9,
            "z": 6,
            "elements": [
                "abyssalcraft:darkstone_brick@2"
            ]
        },
        {
            "x": 0,
            "y": 7,
            "z": 2,
            "elements": [
                "abyssalcraft:darkstone_brick@2"
            ]
        },
        {
            "x": 2,
            "y": 20,
            "z": 5,
            "elements": [
                "abyssalcraft:darkethaxiumbrick@0"
            ]
        },
        {
            "x": 1,
            "y": 23,
            "z": 3,
            "elements": [
                "abyssalcraft:darkethaxiumbrick@0"
            ]
        },
        {
            "x": -2,
            "y": 35,
            "z": 6,
            "elements": [
                "minecraft:stained_glass@14"
            ]
        },
        {
            "x": 1,
            "y": 27,
            "z": 3,
            "elements": [
                "abyssalcraft:coraliumcobblestoneslab1@0"
            ]
        },
        {
            "x": 2,
            "y": 21,
            "z": 5,
            "elements": [
                "abyssalcraft:darkethaxiumbrick@0"
            ]
        },
        {
            "x": 1,
            "y": 19,
            "z": 5,
            "elements": [
                "abyssalcraft:darkethaxiumbrick@0"
            ]
        },
        {
            "x": 3,
            "y": -1,
            "z": 4,
            "elements": [
                "abyssalcraft:cstonebrick@0"
            ]
        },
        {
            "x": 1,
            "y": 6,
            "z": 4,
            "elements": [
                "abyssalcraft:darkstone_brick@2"
            ]
        },
        {
            "x": 1,
            "y": 34,
            "z": 6,
            "elements": [
                "minecraft:stained_glass@14"
            ]
        },
        {
            "x": 2,
            "y": 22,
            "z": 5,
            "elements": [
                "abyssalcraft:darkethaxiumbrick@0"
            ]
        },
        {
            "x": -1,
            "y": 8,
            "z": 6,
            "elements": [
                "abyssalcraft:darkethaxiumbrick@1"
            ]
        },
        {
            "x": 2,
            "y": 0,
            "z": 7,
            "elements": [
                "abyssalcraft:darkethaxiumbrick@2"
            ]
        },
        {
            "x": -2,
            "y": 23,
            "z": 10,
            "elements": [
                "abyssalcraft:abyssalnitecobblestoneslab1@8"
            ]
        },
        {
            "x": 4,
            "y": -2,
            "z": 4,
            "elements": [
                "abyssalcraft:cstonebrick@0"
            ]
        },
        {
            "x": 0,
            "y": 35,
            "z": 4,
            "elements": [
                "minecraft:stained_glass@14"
            ]
        },
        {
            "x": 1,
            "y": 5,
            "z": 4,
            "elements": [
                "abyssalcraft:darkstone_brick@2"
            ]
        },
        {
            "x": 0,
            "y": 25,
            "z": 0,
            "elements": [
                "abyssalcraft:darkethaxiumbrick@0"
            ]
        },
        {
            "x": 1,
            "y": 20,
            "z": 5,
            "elements": [
                "abyssalcraft:darkethaxiumbrick@0"
            ]
        },
        {
            "x": 0,
            "y": 25,
            "z": 11,
            "elements": [
                "abyssalcraft:ethaxiumbrick@0"
            ]
        },
        {
            "x": 2,
            "y": -2,
            "z": 2,
            "elements": [
                "abyssalcraft:cstonebrick@0"
            ]
        },
        {
            "x": -1,
            "y": 1,
            "z": 7,
            "elements": [
                "abyssalcraft:darkstone_brick@2"
            ]
        },
        {
            "x": -1,
            "y": 4,
            "z": 6,
            "elements": [
                "abyssalcraft:darkstone_brick@2"
            ]
        },
        {
            "x": 2,
            "y": 23,
            "z": 5,
            "elements": [
                "abyssalcraft:darkethaxiumbrick@0"
            ]
        },
        {
            "x": -2,
            "y": 23,
            "z": 7,
            "elements": [
                "abyssalcraft:ethaxiumbrick@0"
            ]
        },
        {
            "x": 1,
            "y": 8,
            "z": 4,
            "elements": [
                "abyssalcraft:darkethaxiumbrick@1"
            ]
        },
        {
            "x": 2,
            "y": 24,
            "z": 5,
            "elements": [
                "abyssalcraft:darkethaxiumbrick@0"
            ]
        },
        {
            "x": 4,
            "y": -1,
            "z": 4,
            "elements": [
                "abyssalcraft:cstonebrick@0"
            ]
        },
        {
            "x": 2,
            "y": 2,
            "z": 3,
            "elements": [
                "abyssalcraft:monolithpillar@0"
            ]
        },
        {
            "x": 0,
            "y": 1,
            "z": 2,
            "elements": [
                "abyssalcraft:darkstone_brick@2"
            ]
        },
        {
            "x": -1,
            "y": 0,
            "z": 7,
            "elements": [
                "abyssalcraft:darkstone_brick@2"
            ]
        },
        {
            "x": 1,
            "y": 7,
            "z": 4,
            "elements": [
                "abyssalcraft:darkethaxiumbrick@1"
            ]
        },
        {
            "x": 0,
            "y": 2,
            "z": 9,
            "elements": [
                "modularmachinery:blockcasing@0"
            ]
        },
        {
            "x": 2,
            "y": 0,
            "z": 3,
            "elements": [
                "abyssalcraft:darkethaxiumbrick@2"
            ]
        },
        {
            "x": 2,
            "y": 1,
            "z": 7,
            "elements": [
                "abyssalcraft:monolithpillar@0"
            ]
        },
        {
            "x": 0,
            "y": 1,
            "z": 9,
            "elements": [
                "modularmachinery:blockcasing@0"
            ]
        },
        {
            "x": -2,
            "y": 22,
            "z": 7,
            "elements": [
                "abyssalcraft:ethaxiumbrick@0"
            ]
        },
        {
            "x": -1,
            "y": 3,
            "z": 3,
            "elements": [
                "abyssalcraft:darkstone_brick@2"
            ]
        },
        {
            "x": -2,
            "y": 33,
            "z": 6,
            "elements": [
                "minecraft:stained_glass@14"
            ]
        },
        {
            "x": 0,
            "y": 0,
            "z": 2,
            "elements": [
                "abyssalcraft:darkstone_brick@2"
            ]
        },
        {
            "x": 0,
            "y": 3,
            "z": 9,
            "elements": [
                "abyssalcraft:cstonebrick@0"
            ]
        },
        {
            "x": 1,
            "y": 24,
            "z": 7,
            "elements": [
                "abyssalcraft:ethaxiumbrick@0"
            ]
        },
        {
            "x": 2,
            "y": 1,
            "z": 3,
            "elements": [
                "abyssalcraft:monolithpillar@0"
            ]
        },
        {
            "x": 0,
            "y": 3,
            "z": 2,
            "elements": [
                "abyssalcraft:darkstone_brick@2"
            ]
        },
        {
            "x": -2,
            "y": 22,
            "z": 3,
            "elements": [
                "abyssalcraft:darkethaxiumbrick@2"
            ]
        },
        {
            "x": -2,
            "y": 32,
            "z": 6,
            "elements": [
                "abyssalcraft:darkethaxiumbrick@2"
            ]
        },
        {
            "x": -1,
            "y": 5,
            "z": 6,
            "elements": [
                "abyssalcraft:darkstone_brick@2"
            ]
        },
        {
            "x": 1,
            "y": 10,
            "z": 4,
            "elements": [
                "abyssalcraft:darkstone_brick@2"
            ]
        },
        {
            "x": 1,
            "y": 23,
            "z": 7,
            "elements": [
                "abyssalcraft:ethaxiumbrick@0"
            ]
        },
        {
            "x": -1,
            "y": 25,
            "z": 13,
            "elements": [
                "abyssalcraft:dreadstonecobblestoneslab1@0"
            ]
        },
        {
            "x": -2,
            "y": -1,
            "z": 7,
            "elements": [
                "abyssalcraft:cstonebrick@0"
            ]
        },
        {
            "x": 0,
            "y": 22,
            "z": 5,
            "elements": [
                "abyssalcraft:darkethaxiumbrick@0"
            ]
        },
        {
            "x": -1,
            "y": 3,
            "z": 6,
            "elements": [
                "abyssalcraft:darkstone_brick@2"
            ]
        },
        {
            "x": -4,
            "y": 32,
            "z": 5,
            "elements": [
                "abyssalcraft:coraliumcobblestoneslab1@0"
            ]
        },
        {
            "x": -1,
            "y": 24,
            "z": 13,
            "elements": [
                "abyssalcraft:dreadstonecobblestoneslab1@8"
            ]
        },
        {
            "x": -2,
            "y": -2,
            "z": 7,
            "elements": [
                "abyssalcraft:cstonebrick@0"
            ]
        },
        {
            "x": 1,
            "y": 9,
            "z": 4,
            "elements": [
                "abyssalcraft:darkstone_brick@2"
            ]
        },
        {
            "x": -2,
            "y": 31,
            "z": 6,
            "elements": [
                "abyssalcraft:coraliumcobblestoneslab1@8"
            ]
        },
        {
            "x": 0,
            "y": 2,
            "z": 2,
            "elements": [
                "abyssalcraft:darkstone_brick@2"
            ]
        },
        {
            "x": -2,
            "y": 23,
            "z": 3,
            "elements": [
                "abyssalcraft:darkethaxiumbrick@0"
            ]
        },
        {
            "x": 0,
            "y": 4,
            "z": 9,
            "elements": [
                "abyssalcraft:darkethaxiumbrick@1"
            ]
        },
        {
            "x": 2,
            "y": 1,
            "z": 6,
            "elements": [
                "abyssalcraft:darkstone_brick@2"
            ]
        },
        {
            "x": -2,
            "y": 33,
            "z": 5,
            "elements": [
                "minecraft:stained_glass@14"
            ]
        },
        {
            "x": -1,
            "y": -2,
            "z": 9,
            "elements": [
                "abyssalcraft:cstonebrick@0"
            ]
        },
        {
            "x": 1,
            "y": 16,
            "z": 5,
            "elements": [
                "abyssalcraft:darkethaxiumbrick@0"
            ]
        },
        {
            "x": -1,
            "y": 31,
            "z": 5,
            "elements": [
                "abyssalcraft:darkethaxiumbrick@2"
            ]
        },
        {
            "x": -3,
            "y": 21,
            "z": 5,
            "elements": [
                "abyssalcraft:darkethaxiumbrick@0"
            ]
        },
        {
            "x": 1,
            "y": 35,
            "z": 7,
            "elements": [
                "abyssalcraft:cstonebrick@0"
            ]
        },
        {
            "x": -2,
            "y": 37,
            "z": 3,
            "elements": [
                "abyssalcraft:coraliumcobblestoneslab1@0"
            ]
        },
        {
            "x": -2,
            "y": -2,
            "z": 8,
            "elements": [
                "abyssalcraft:cstonebrick@0"
            ]
        },
        {
            "x": -1,
            "y": 32,
            "z": 5,
            "elements": [
                "minecraft:stained_glass@14"
            ]
        },
        {
            "x": 1,
            "y": 34,
            "z": 7,
            "elements": [
                "abyssalcraft:cstonebrick@0"
            ]
        },
        {
            "x": -2,
            "y": 34,
            "z": 5,
            "elements": [
                "minecraft:magma@0"
            ]
        },
        {
            "x": -3,
            "y": 22,
            "z": 5,
            "elements": [
                "abyssalcraft:darkethaxiumbrick@0"
            ]
        },
        {
            "x": 1,
            "y": 15,
            "z": 5,
            "elements": [
                "abyssalcraft:darkethaxiumbrick@0"
            ]
        },
        {
            "x": 1,
            "y": 33,
            "z": 3,
            "elements": [
                "abyssalcraft:darkethaxiumbrick@2"
            ]
        },
        {
            "x": -2,
            "y": 18,
            "z": 4,
            "elements": [
                "abyssalcraft:darkethaxiumbrick@0"
            ]
        },
        {
            "x": 0,
            "y": 36,
            "z": 7,
            "elements": [
                "abyssalcraft:cstonebrick@0"
            ]
        },
        {
            "x": -2,
            "y": 31,
            "z": 5,
            "elements": [
                "abyssalcraft:cstonebrick@0"
            ]
        },
        {
            "x": 1,
            "y": 11,
            "z": 4,
            "elements": [
                "abyssalcraft:darkstone_brick@2"
            ]
        },
        {
            "x": 1,
            "y": 18,
            "z": 5,
            "elements": [
                "abyssalcraft:darkethaxiumbrick@0"
            ]
        },
        {
            "x": -1,
            "y": -2,
            "z": 2,
            "elements": [
                "abyssalcraft:cstonebrick@0"
            ]
        },
        {
            "x": 0,
            "y": 35,
            "z": 7,
            "elements": [
                "abyssalcraft:cstonebrick@0"
            ]
        },
        {
            "x": 0,
            "y": 0,
            "z": 9,
            "elements": [
                "modularmachinery:blockcasing@0"
            ]
        },
        {
            "x": 2,
            "y": 2,
            "z": 7,
            "elements": [
                "abyssalcraft:monolithpillar@0"
            ]
        },
        {
            "x": -5,
            "y": 23,
            "z": 5,
            "elements": [
                "abyssalcraft:darkethaxiumbrick@0"
            ]
        },
        {
            "x": 4,
            "y": 26,
            "z": 5,
            "elements": [
                "abyssalcraft:darkethaxiumbrick@0"
            ]
        },
        {
            "x": 1,
            "y": 34,
            "z": 3,
            "elements": [
                "abyssalcraft:cstonebrick@0"
            ]
        },
        {
            "x": -5,
            "y": 24,
            "z": 5,
            "elements": [
                "abyssalcraft:monolithpillar@0"
            ]
        },
        {
            "x": 1,
            "y": 12,
            "z": 4,
            "elements": [
                "abyssalcraft:darkstone_brick@2"
            ]
        },
        {
            "x": -1,
            "y": -1,
            "z": 2,
            "elements": [
                "abyssalcraft:cstonebrick@0"
            ]
        },
        {
            "x": 1,
            "y": 17,
            "z": 5,
            "elements": [
                "abyssalcraft:darkethaxiumbrick@0"
            ]
        },
        {
            "x": 0,
            "y": 24,
            "z": 11,
            "elements": [
                "abyssalcraft:ethaxiumbrick@0"
            ]
        },
        {
            "x": -2,
            "y": 32,
            "z": 5,
            "elements": [
                "minecraft:stained_glass@14"
            ]
        },
        {
            "x": 2,
            "y": 3,
            "z": 3,
            "elements": [
                "abyssalcraft:decorativestatue@5"
            ]
        },
        {
            "x": 0,
            "y": 34,
            "z": 7,
            "elements": [
                "minecraft:stained_glass@14"
            ]
        },
        {
            "x": -3,
            "y": 20,
            "z": 5,
            "elements": [
                "abyssalcraft:darkethaxiumbrick@0"
            ]
        },
        {
            "x": -2,
            "y": 22,
            "z": 5,
            "elements": [
                "abyssalcraft:ethaxiumbrick@0"
            ]
        },
        {
            "x": 4,
            "y": 25,
            "z": 5,
            "elements": [
                "abyssalcraft:darkethaxiumbrick@0"
            ]
        },
        {
            "x": 2,
            "y": 3,
            "z": 7,
            "elements": [
                "gct_mac:pe_collector@0"
            ]
        },
        {
            "x": 0,
            "y": 24,
            "z": 0,
            "elements": [
                "abyssalcraft:darkethaxiumbrick@0"
            ]
        },
        {
            "x": -2,
            "y": -2,
            "z": 2,
            "elements": [
                "abyssalcraft:cstonebrick@0"
            ]
        },
        {
            "x": -2,
            "y": 20,
            "z": 4,
            "elements": [
                "abyssalcraft:darkethaxiumbrick@0"
            ]
        },
        {
            "x": -1,
            "y": 10,
            "z": 6,
            "elements": [
                "abyssalcraft:darkstone_brick@2"
            ]
        },
        {
            "x": -2,
            "y": 19,
            "z": 4,
            "elements": [
                "abyssalcraft:darkethaxiumbrick@0"
            ]
        },
        {
            "x": -1,
            "y": 36,
            "z": 5,
            "elements": [
                "minecraft:stained_glass@14"
            ]
        },
        {
            "x": -1,
            "y": 11,
            "z": 6,
            "elements": [
                "abyssalcraft:darkstone_brick@2"
            ]
        },
        {
            "x": 1,
            "y": -2,
            "z": 2,
            "elements": [
                "abyssalcraft:cstonebrick@0"
            ]
        },
        {
            "x": -1,
            "y": 24,
            "z": 15,
            "elements": [
                "abyssalcraft:dreadstonecobblestoneslab1@8"
            ]
        },
        {
            "x": -4,
            "y": 24,
            "z": 9,
            "elements": [
                "abyssalcraft:dreadstonecobblestoneslab1@0"
            ]
        },
        {
            "x": 0,
            "y": 33,
            "z": 4,
            "elements": [
                "minecraft:stained_glass@14"
            ]
        },
        {
            "x": 1,
            "y": 23,
            "z": 5,
            "elements": [
                "abyssalcraft:darkethaxiumbrick@0"
            ]
        },
        {
            "x": 4,
            "y": -2,
            "z": 6,
            "elements": [
                "abyssalcraft:cstonebrick@0"
            ]
        },
        {
            "x": 1,
            "y": -1,
            "z": 2,
            "elements": [
                "abyssalcraft:cstonebrick@0"
            ]
        },
        {
            "x": 1,
            "y": 33,
            "z": 7,
            "elements": [
                "abyssalcraft:cstonebrick@0"
            ]
        },
        {
            "x": -2,
            "y": 22,
            "z": 4,
            "elements": [
                "abyssalcraft:darkethaxiumbrick@0"
            ]
        },
        {
            "x": 0,
            "y": 32,
            "z": 4,
            "elements": [
                "abyssalcraft:cstonebrick@0"
            ]
        },
        {
            "x": -2,
            "y": 21,
            "z": 4,
            "elements": [
                "abyssalcraft:darkethaxiumbrick@0"
            ]
        },
        {
            "x": -1,
            "y": 23,
            "z": 11,
            "elements": [
                "abyssalcraft:ethaxiumbrick@0"
            ]
        },
        {
            "x": -2,
            "y": 34,
            "z": 7,
            "elements": [
                "minecraft:stained_glass@14"
            ]
        },
        {
            "x": 4,
            "y": -1,
            "z": 6,
            "elements": [
                "abyssalcraft:cstonebrick@0"
            ]
        },
        {
            "x": -1,
            "y": 24,
            "z": 9,
            "elements": [
                "abyssalcraft:dreadstonecobblestoneslab1@0"
            ]
        },
        {
            "x": 1,
            "y": 23,
            "z": 4,
            "elements": [
                "abyssalcraft:darkethaxiumbrick@0"
            ]
        },
        {
            "x": 0,
            "y": 3,
            "z": 1,
            "elements": [
                "abyssalcraft:darkethaxiumbrick@1"
            ]
        },
        {
            "x": 0,
            "y": 31,
            "z": 4,
            "elements": [
                "abyssalcraft:cstonebrick@0"
            ]
        },
        {
            "x": 1,
            "y": 1,
            "z": 7,
            "elements": [
                "abyssalcraft:darkstone_brick@2"
            ]
        },
        {
            "x": -2,
            "y": 14,
            "z": 5,
            "elements": [
                "abyssalcraft:ethaxiumbrick@0"
            ]
        },
        {
            "x": 0,
            "y": 2,
            "z": 1,
            "elements": [
                "modularmachinery:blockcasing@0"
            ]
        },
        {
            "x": 3,
            "y": 0,
            "z": 6,
            "elements": [
                "abyssalcraft:darkstone_brick@2"
            ]
        },
        {
            "x": 3,
            "y": 1,
            "z": 6,
            "elements": [
                "abyssalcraft:darkstone_brick@2"
            ]
        },
        {
            "x": -1,
            "y": 23,
            "z": 9,
            "elements": [
                "abyssalcraft:ethaxiumbrick@0"
            ]
        },
        {
            "x": 1,
            "y": 0,
            "z": 7,
            "elements": [
                "abyssalcraft:darkstone_brick@2"
            ]
        },
        {
            "x": 1,
            "y": 8,
            "z": 5,
            "elements": [
                "abyssalcraft:darkstone_brick@2"
            ]
        },
        {
            "x": -3,
            "y": 18,
            "z": 5,
            "elements": [
                "abyssalcraft:darkethaxiumbrick@0"
            ]
        },
        {
            "x": -1,
            "y": 22,
            "z": 9,
            "elements": [
                "abyssalcraft:darkethaxiumbrick@0"
            ]
        },
        {
            "x": 0,
            "y": 36,
            "z": 5,
            "elements": [
                "minecraft:stained_glass@14"
            ]
        },
        {
            "x": 1,
            "y": 9,
            "z": 5,
            "elements": [
                "abyssalcraft:darkstone_brick@2"
            ]
        },
        {
            "x": 0,
            "y": 35,
            "z": 5,
            "elements": [
                "minecraft:stained_glass@14"
            ]
        },
        {
            "x": 0,
            "y": 0,
            "z": 1,
            "elements": [
                "abyssalcraft:cstonebrick@0"
            ]
        },
        {
            "x": -3,
            "y": 34,
            "z": 4,
            "elements": [
                "minecraft:stained_glass@14"
            ]
        },
        {
            "x": -2,
            "y": 23,
            "z": 9,
            "elements": [
                "abyssalcraft:dreadstonecobblestoneslab1@8"
            ]
        },
        {
            "x": -3,
            "y": 24,
            "z": 2,
            "elements": [
                "abyssalcraft:coraliumcobblestoneslab1@0"
            ]
        },
        {
            "x": 1,
            "y": 10,
            "z": 5,
            "elements": [
                "abyssalcraft:darkstone_brick@2"
            ]
        },
        {
            "x": 3,
            "y": 34,
            "z": 5,
            "elements": [
                "abyssalcraft:coraliumcobblestonestairs@5"
            ]
        },
        {
            "x": -2,
            "y": 3,
            "z": 7,
            "elements": [
                "abyssalcraft:decorativestatue@0"
            ]
        },
        {
            "x": 0,
            "y": 1,
            "z": 1,
            "elements": [
                "modularmachinery:blockcasing@0"
            ]
        },
        {
            "x": 3,
            "y": 36,
            "z": 5,
            "elements": [
                "abyssalcraft:darkethaxiumbrick@2"
            ]
        },
        {
            "x": -1,
            "y": -2,
            "z": 1,
            "elements": [
                "abyssalcraft:cstonebrick@0"
            ]
        },
        {
            "x": -1,
            "y": 22,
            "z": 3,
            "elements": [
                "abyssalcraft:darkethaxiumbrick@0"
            ]
        },
        {
            "x": -2,
            "y": 18,
            "z": 5,
            "elements": [
                "abyssalcraft:darkethaxiumbrick@0"
            ]
        },
        {
            "x": 1,
            "y": 11,
            "z": 5,
            "elements": [
                "abyssalcraft:darkstone_brick@2"
            ]
        },
        {
            "x": -2,
            "y": 31,
            "z": 4,
            "elements": [
                "abyssalcraft:coraliumcobblestoneslab1@8"
            ]
        },
        {
            "x": -5,
            "y": 21,
            "z": 5,
            "elements": [
                "abyssalcraft:monolithpillar@0"
            ]
        },
        {
            "x": 1,
            "y": 2,
            "z": 7,
            "elements": [
                "abyssalcraft:darkstone_brick@2"
            ]
        },
        {
            "x": 0,
            "y": 34,
            "z": 3,
            "elements": [
                "minecraft:stained_glass@14"
            ]
        },
        {
            "x": -6,
            "y": 23,
            "z": 5,
            "elements": [
                "abyssalcraft:abyssalnitecobblestoneslab1@8"
            ]
        },
        {
            "x": -2,
            "y": 17,
            "z": 5,
            "elements": [
                "abyssalcraft:ethaxiumbrick@0"
            ]
        },
        {
            "x": 3,
            "y": -2,
            "z": 7,
            "elements": [
                "abyssalcraft:cstonebrick@0"
            ]
        },
        {
            "x": -6,
            "y": 24,
            "z": 5,
            "elements": [
                "abyssalcraft:coraliumcobblestoneslab1@0"
            ]
        },
        {
            "x": 1,
            "y": 12,
            "z": 5,
            "elements": [
                "abyssalcraft:darkstone_brick@2"
            ]
        },
        {
            "x": -3,
            "y": 19,
            "z": 5,
            "elements": [
                "abyssalcraft:darkethaxiumbrick@0"
            ]
        },
        {
            "x": -2,
            "y": 2,
            "z": 7,
            "elements": [
                "abyssalcraft:monolithpillar@0"
            ]
        },
        {
            "x": 3,
            "y": 35,
            "z": 5,
            "elements": [
                "abyssalcraft:darkethaxiumbrick@2"
            ]
        },
        {
            "x": 1,
            "y": 3,
            "z": 7,
            "elements": [
                "abyssalcraft:darkstone_brick@2"
            ]
        },
        {
            "x": -3,
            "y": 23,
            "z": 2,
            "elements": [
                "abyssalcraft:coraliumcobblestoneslab1@8"
            ]
        },
        {
            "x": -1,
            "y": 23,
            "z": 3,
            "elements": [
                "abyssalcraft:darkethaxiumbrick@2"
            ]
        },
        {
            "x": 0,
            "y": -2,
            "z": -1,
            "elements": [
                "abyssalcraft:cstonebrick@0"
            ]
        },
        {
            "x": -5,
            "y": 22,
            "z": 5,
            "elements": [
                "abyssalcraft:monolithpillar@0"
            ]
        },
        {
            "x": 0,
            "y": 32,
            "z": 3,
            "elements": [
                "abyssalcraft:cstonebrick@0"
            ]
        },
        {
            "x": 0,
            "y": 23,
            "z": 4,
            "elements": [
                "abyssalcraft:darkethaxiumbrick@0"
            ]
        },
        {
            "x": 0,
            "y": 23,
            "z": 2,
            "elements": [
                "abyssalcraft:ethaxiumbrick@0"
            ]
        },
        {
            "x": 1,
            "y": 14,
            "z": 5,
            "elements": [
                "abyssalcraft:darkstone_brick@2"
            ]
        },
        {
            "x": 0,
            "y": -1,
            "z": 1,
            "elements": [
                "abyssalcraft:cstonebrick@0"
            ]
        },
        {
            "x": 3,
            "y": 38,
            "z": 5,
            "elements": [
                "abyssalcraft:abyssalnitecobblestonestairs@5"
            ]
        },
        {
            "x": 3,
            "y": 37,
            "z": 5,
            "elements": [
                "abyssalcraft:coraliumcobblestonestairs@1"
            ]
        },
        {
            "x": -3,
            "y": 24,
            "z": 3,
            "elements": [
                "abyssalcraft:monolithpillar@0"
            ]
        },
        {
            "x": -2,
            "y": 16,
            "z": 5,
            "elements": [
                "abyssalcraft:darkethaxiumbrick@0"
            ]
        },
        {
            "x": 0,
            "y": 33,
            "z": 3,
            "elements": [
                "abyssalcraft:cstonebrick@0"
            ]
        },
        {
            "x": 1,
            "y": 22,
            "z": 4,
            "elements": [
                "abyssalcraft:ethaxiumbrick@0"
            ]
        },
        {
            "x": -1,
            "y": 21,
            "z": 3,
            "elements": [
                "abyssalcraft:darkethaxiumbrick@0"
            ]
        },
        {
            "x": -2,
            "y": 15,
            "z": 5,
            "elements": [
                "abyssalcraft:darkethaxiumbrick@2"
            ]
        },
        {
            "x": 1,
            "y": 13,
            "z": 5,
            "elements": [
                "abyssalcraft:darkstone_brick@2"
            ]
        },
        {
            "x": 0,
            "y": 24,
            "z": 9,
            "elements": [
                "abyssalcraft:ethaxiumbrick@0"
            ]
        },
        {
            "x": -3,
            "y": 23,
            "z": 4,
            "elements": [
                "abyssalcraft:darkethaxiumbrick@0"
            ]
        },
        {
            "x": -2,
            "y": 8,
            "z": 5,
            "elements": [
                "abyssalcraft:darkstone_brick@2"
            ]
        },
        {
            "x": 0,
            "y": 20,
            "z": 3,
            "elements": [
                "abyssalcraft:darkstone_brick@2"
            ]
        },
        {
            "x": 1,
            "y": -2,
            "z": 1,
            "elements": [
                "abyssalcraft:cstonebrick@0"
            ]
        },
        {
            "x": -3,
            "y": 35,
            "z": 5,
            "elements": [
                "minecraft:stained_glass@14"
            ]
        },
        {
            "x": 0,
            "y": 20,
            "z": 4,
            "elements": [
                "abyssalcraft:darkstone_brick@2"
            ]
        },
        {
            "x": 0,
            "y": 22,
            "z": 4,
            "elements": [
                "abyssalcraft:ethaxiumbrick@0"
            ]
        },
        {
            "x": 2,
            "y": 26,
            "z": 3,
            "elements": [
                "abyssalcraft:darkethaxiumbrick@0"
            ]
        },
        {
            "x": -2,
            "y": 7,
            "z": 5,
            "elements": [
                "abyssalcraft:darkstone_brick@2"
            ]
        },
        {
            "x": 1,
            "y": 32,
            "z": 4,
            "elements": [
                "abyssalcraft:cstonebrick@0"
            ]
        },
        {
            "x": -2,
            "y": 34,
            "z": 3,
            "elements": [
                "minecraft:stained_glass@14"
            ]
        },
        {
            "x": 1,
            "y": 34,
            "z": 4,
            "elements": [
                "minecraft:stained_glass@14"
            ]
        },
        {
            "x": -2,
            "y": 3,
            "z": 6,
            "elements": [
                "abyssalcraft:darkstone_brick@2"
            ]
        },
        {
            "x": -2,
            "y": 2,
            "z": 6,
            "elements": [
                "abyssalcraft:darkstone_brick@2"
            ]
        },
        {
            "x": 1,
            "y": -2,
