{
    "registryname": "mana_ele",
    "localizedname": "魔力聚能机",
    "requires-blueprint": false,
    "failure-action": "still",
    "color": "4D697D",
    "parts": [
        {
            "x": -5,
            "y": -9,
            "z": -1,
            "elements": [
                "botania:shimmerrock0stairs@0"
            ]
        },
        {
            "x": 4,
            "y": -9,
            "z": 0,
            "elements": [
                "botania:storage@4"
            ]
        },
        {
            "x": 0,
            "y": -2,
            "z": 0,
            "elements": [
                "modularmachinery:blockoutputbus@3"
            ]
        },
        {
            "x": 2,
            "y": -9,
            "z": 5,
            "elements": [
                "botania:shimmerrock0stairs@1"
            ]
        },
        {
            "x": -1,
            "y": -6,
            "z": -2,
            "elements": [
                "gct_ores:rainboquartz_stair@3"
            ]
        },
        {
            "x": 1,
            "y": -9,
            "z": 2,
            "elements": [
                "additions:elfsteel_block@0"
            ]
        },
        {
            "x": -2,
            "y": -3,
            "z": 3,
            "elements": [
                "botania:storage@4"
            ]
        },
        {
            "x": 2,
            "y": -9,
            "z": -2,
            "elements": [
                "additions:elfsteel_block"
            ]
        },
        {
            "x": 2,
            "y": -6,
            "z": 0,
            "elements": [
                "botania:bifrostperm@0"
            ]
        },
        {
            "x": 0,
            "y": -1,
            "z": 0,
            "elements": [
                "avaritiatweaks:gaia_block@0"
            ]
        },
        {
            "x": -2,
            "y": -9,
            "z": 1,
            "elements": [
                "additions:elfsteel_block@0"
            ]
        },
        {
            "x": -4,
            "y": -9,
            "z": -3,
            "elements": [
                "botania:shimmerrock0slab@0"
            ]
        },
        {
            "x": 1,
            "y": 0,
            "z": 0,
            "elements": [
                "botania:shimmerrock0slab@0"
            ]
        },
        {
            "x": 5,
            "y": -9,
            "z": 0,
            "elements": [
                "botania:shimmerrock0stairs@1"
            ]
        },
        {
            "x": 1,
            "y": -9,
            "z": 5,
            "elements": [
                "botania:shimmerrock0stairs@3"
            ]
        },
        {
            "x": 1,
            "y": -2,
            "z": 0,
            "elements": [
                "botania:storage@0"
            ]
        },
        {
            "x": -2,
            "y": -4,
            "z": 3,
            "elements": [
                "minecraft:end_rod@0"
            ]
        },
        {
            "x": 1,
            "y": -3,
            "z": 3,
            "elements": [
                "botania:storage@0"
            ]
        },
        {
            "x": -1,
            "y": -9,
            "z": -4,
            "elements": [
                "additions:elfsteel_block"
            ]
        },
        {
            "x": 3,
            "y": -6,
            "z": 0,
            "selector-tag": "input6",
            "elements": [
                "modularmachinery:blockinputbus"
            ]
        },
        {
            "x": 1,
            "y": -9,
            "z": -2,
            "elements": [
                "additions:elfsteel_block@0"
            ]
        },
        {
            "x": -3,
            "y": -6,
            "z": -1,
            "elements": [
                "botania:storage@0"
            ]
        },
        {
            "x": -2,
            "y": -6,
            "z": 2,
            "selector-tag": "input1",
            "elements": [
                "modularmachinery:blockinputbus"
            ]
        },
        {
            "x": 1,
            "y": -1,
            "z": 0,
            "elements": [
                "additions:elfsteel_block@0"
            ]
        },
        {
            "x": -2,
            "y": -5,
            "z": 3,
            "elements": [
                "minecraft:end_rod@1"
            ]
        },
        {
            "x": -5,
            "y": -9,
            "z": 1,
            "elements": [
                "botania:shimmerrock0stairs@0"
            ]
        },
        {
            "x": 4,
            "y": -9,
            "z": 3,
            "elements": [
                "botania:shimmerrock0slab@0"
            ]
        },
        {
            "x": 1,
            "y": -2,
            "z": 3,
            "elements": [
                "botania:shimmerrock0slab@0"
            ]
        },
        {
            "x": -2,
            "y": -6,
            "z": -4,
            "elements": [
                "botania:shimmerrock0stairs@2"
            ]
        },
        {
            "x": -3,
            "y": -6,
            "z": 1,
            "elements": [
                "botania:storage@0"
            ]
        },
        {
            "x": -1,
            "y": -9,
            "z": -3,
            "elements": [
                "avaritiatweaks:gaia_block@0"
            ]
        },
        {
            "x": 0,
            "y": -9,
            "z": 5,
            "elements": [
                "botania:shimmerrock0stairs@3"
            ]
        },
        {
            "x": -3,
            "y": -9,
            "z": -1,
            "elements": [
                "avaritiatweaks:gaia_block@0"
            ]
        },
        {
            "x": 2,
            "y": -2,
            "z": 2,
            "elements": [
                "botania:shimmerrock0slab@0"
            ]
        },
        {
            "x": 2,
            "y": -9,
            "z": -3,
            "elements": [
                "botania:storage@4"
            ]
        },
        {
            "x": 2,
            "y": -8,
            "z": 0,
            "elements": [
                "botania:terraplate"
            ]
        },
        {
            "x": 2,
            "y": -9,
            "z": 0,
            "elements": [
                "botania:quartztypered@0",
                "botania:shimmerwoodplanks"
            ]
        },
        {
            "x": -2,
            "y": -9,
            "z": 3,
            "elements": [
                "botania:storage@4"
            ]
        },
        {
            "x": -2,
            "y": -2,
            "z": 0,
            "elements": [
                "avaritiatweaks:gaia_block@0"
            ]
        },
        {
            "x": 4,
            "y": -6,
            "z": 0,
            "elements": [
                "botania:storage@4"
            ]
        },
        {
            "x": -2,
            "y": -6,
            "z": 3,
            "elements": [
                "botania:storage@4"
            ]
        },
        {
            "x": -2,
            "y": -9,
            "z": -4,
            "elements": [
                "botania:shimmerrock0stairs@2"
            ]
        },
        {
            "x": -5,
            "y": -9,
            "z": 2,
            "elements": [
                "botania:shimmerrock0stairs@3"
            ]
        },
        {
            "x": -1,
            "y": -2,
            "z": -2,
            "elements": [
                "gct_ores:rainboquartz_stair@7"
            ]
        },
        {
            "x": 3,
            "y": -3,
            "z": 0,
            "elements": [
                "botania:pylon@2"
            ]
        },
        {
            "x": -2,
            "y": -1,
            "z": 0,
            "elements": [
                "botania:shimmerrock0stairs@0"
            ]
        },
        {
            "x": 2,
            "y": -8,
            "z": -3,
            "elements": [
                "minecraft:end_rod@1"
            ]
        },
        {
            "x": -4,
            "y": -9,
            "z": 1,
            "elements": [
                "additions:elfsteel_block"
            ]
        },
        {
            "x": 4,
            "y": -5,
            "z": 0,
            "elements": [
                "minecraft:end_rod@1"
            ]
        },
        {
            "x": -1,
            "y": -6,
            "z": -3,
            "elements": [
                "botania:storage@0"
            ]
        },
        {
            "x": 2,
            "y": -3,
            "z": -2,
            "elements": [
                "botania:pylon@2"
            ]
        },
        {
            "x": -2,
            "y": -7,
            "z": 3,
            "elements": [
                "minecraft:end_rod@0"
            ]
        },
        {
            "x": -1,
            "y": 0,
            "z": 0,
            "elements": [
                "botania:shimmerrock0slab@0"
            ]
        },
        {
            "x": 3,
            "y": -2,
            "z": 0,
            "elements": [
                "botania:shimmerrock0slab@0"
            ]
        },
        {
            "x": -2,
            "y": -9,
            "z": -1,
            "elements": [
                "additions:elfsteel_block@0"
            ]
        },
        {
            "x": -5,
            "y": -9,
            "z": -2,
            "elements": [
                "botania:shimmerrock0stairs@2"
            ]
        },
        {
            "x": -2,
            "y": -9,
            "z": 2,
            "elements": [
                "additions:elfsteel_block"
            ]
        },
        {
            "x": -3,
            "y": -9,
            "z": -4,
            "elements": [
                "botania:shimmerrock0slab@0"
            ]
        },
        {
            "x": -2,
            "y": -8,
            "z": 3,
            "elements": [
                "minecraft:end_rod@1"
            ]
        },
        {
            "x": -3,
            "y": -6,
            "z": 3,
            "elements": [
                "botania:shimmerrock0slab@0"
            ]
        },
        {
            "x": 2,
            "y": -2,
            "z": -2,
            "elements": [
                "botania:shimmerrock0slab@0"
            ]
        },
        {
            "x": 1,
            "y": -6,
            "z": 0,
            "elements": [
                "botania:bifrostperm@0"
            ]
        },
        {
            "x": 4,
            "y": -8,
            "z": 0,
            "elements": [
                "minecraft:end_rod@1"
            ]
        },
        {
            "x": -3,
            "y": -9,
            "z": 1,
            "elements": [
                "avaritiatweaks:gaia_block@0"
            ]
        },
        {
            "x": 2,
            "y": -3,
            "z": 2,
            "elements": [
                "botania:pylon@2"
            ]
        },
        {
            "x": 0,
            "y": -6,
            "z": -3,
            "selector-tag": "input4",
            "elements": [
                "modularmachinery:blockinputbus"
            ]
        },
        {
            "x": 4,
            "y": -7,
            "z": 0,
            "elements": [
                "minecraft:end_rod@0"
            ]
        },
        {
            "x": -2,
            "y": -9,
            "z": 5,
            "elements": [
                "botania:shimmerrock0stairs@0"
            ]
        },
        {
            "x": 0,
            "y": -2,
            "z": 2,
            "elements": [
                "avaritiatweaks:gaia_block@0"
            ]
        },
        {
            "x": 0,
            "y": -9,
            "z": -3,
            "elements": [
                "additions:elfsteel_block"
            ]
        },
        {
            "x": 3,
            "y": -6,
            "z": -2,
            "elements": [
                "botania:storage@4"
            ]
        },
        {
            "x": 5,
            "y": -9,
            "z": 2,
            "elements": [
                "botania:shimmerrock0stairs@3"
            ]
        },
        {
            "x": 4,
            "y": -6,
            "z": -1,
            "elements": [
                "botania:shimmerrock0stairs@1"
            ]
        },
        {
            "x": 2,
            "y": -9,
            "z": 1,
            "elements": [
                "additions:elfsteel_block@0"
            ]
        },
        {
            "x": 0,
            "y": -9,
            "z": 0,
            "elements": [
                "avaritiatweaks:gaia_block"
            ]
        },
        {
            "x": 2,
            "y": -6,
            "z": 2,
            "selector-tag": "input7",
            "elements": [
                "modularmachinery:blockinputbus"
            ]
        },
        {
            "x": 1,
            "y": -2,
            "z": -2,
            "elements": [
                "gct_ores:rainboquartz_stair@7"
            ]
        },
        {
            "x": 3,
            "y": -5,
            "z": -2,
            "elements": [
                "minecraft:end_rod@1"
            ]
        },
        {
            "x": 0,
            "y": -1,
            "z": 2,
            "elements": [
                "botania:shimmerrock0stairs@3"
            ]
        },
        {
            "x": -3,
            "y": -6,
            "z": -3,
            "elements": [
                "botania:shimmerrock0slab@0"
            ]
        },
        {
            "x": 3,
            "y": -8,
            "z": -2,
            "elements": [
                "minecraft:end_rod@1"
            ]
        },
        {
            "x": -3,
            "y": -3,
            "z": 0,
            "elements": [
                "botania:pylon@2"
            ]
        },
        {
            "x": -2,
            "y": -2,
            "z": -1,
            "elements": [
                "gct_ores:rainboquartz_stair@5"
            ]
        },
        {
            "x": -1,
            "y": -3,
            "z": -4,
            "elements": [
                "botania:shimmerrock0slab@0"
            ]
        },
        {
            "x": -4,
            "y": -6,
            "z": 1,
            "elements": [
                "botania:shimmerrock0stairs@0"
            ]
        },
        {
            "x": 2,
            "y": -9,
            "z": -5,
            "elements": [
                "botania:shimmerrock0stairs@1"
            ]
        },
        {
            "x": 2,
            "y": -6,
            "z": -4,
            "elements": [
                "botania:shimmerrock0stairs@2"
            ]
        },
        {
            "x": 1,
            "y": -6,
            "z": -1,
            "elements": [
                "botania:bifrostperm@0"
            ]
        },
        {
            "x": 4,
            "y": -9,
            "z": 2,
            "elements": [
                "botania:shimmerrock0stairs@1"
            ]
        },
        {
            "x": -3,
            "y": -2,
            "z": 0,
            "elements": [
                "botania:shimmerrock0slab@0"
            ]
        },
        {
            "x": 4,
            "y": -4,
            "z": 0,
            "elements": [
                "minecraft:end_rod@0"
            ]
        },
        {
            "x": 2,
            "y": -6,
            "z": -2,
            "selector-tag": "input5",
            "elements": [
                "modularmachinery:blockinputbus"
            ]
        },
        {
            "x": -1,
            "y": -2,
            "z": 2,
            "elements": [
                "gct_ores:rainboquartz_stair@6"
            ]
        },
        {
            "x": -3,
            "y": -9,
            "z": 3,
            "elements": [
                "botania:shimmerrock0slab@0"
            ]
        },
        {
            "x": 5,
            "y": -9,
            "z": -2,
            "elements": [
                "botania:shimmerrock0stairs@2"
            ]
        },
        {
            "x": 0,
            "y": -2,
            "z": -2,
            "elements": [
                "avaritiatweaks:gaia_block@0"
            ]
        },
        {
            "x": 1,
            "y": -6,
            "z": 2,
            "elements": [
                "gct_ores:rainboquartz_stair@2"
            ]
        },
        {
            "x": 3,
            "y": -8,
            "z": 2,
            "elements": [
                "minecraft:end_rod@1"
            ]
        },
        {
            "x": 4,
            "y": -3,
            "z": 0,
            "elements": [
                "botania:shimmerrock0stairs@1"
            ]
        },
        {
            "x": 3,
            "y": -7,
            "z": -2,
            "elements": [
                "minecraft:end_rod@0"
            ]
        },
        {
            "x": -1,
            "y": -9,
            "z": 1,
            "elements": [
                "avaritiatweaks:gaia_block"
            ]
        },
        {
            "x": 0,
            "y": -1,
            "z": -2,
            "elements": [
                "botania:shimmerrock0stairs@2"
            ]
        },
        {
            "x": 3,
            "y": -2,
            "z": 1,
            "elements": [
                "botania:shimmerrock0slab@0"
            ]
        },
        {
            "x": -2,
            "y": -6,
            "z": -1,
            "elements": [
                "gct_ores:rainboquartz_stair@1"
            ]
        },
        {
            "x": 1,
            "y": -6,
            "z": -2,
            "elements": [
                "gct_ores:rainboquartz_stair@3"
            ]
        },
        {
            "x": -2,
            "y": -2,
            "z": 2,
            "elements": [
                "botania:shimmerrock0slab@0"
            ]
        },
        {
            "x": 2,
            "y": -9,
            "z": -4,
            "elements": [
                "botania:shimmerrock0stairs@2"
            ]
        },
        {
            "x": -3,
            "y": -3,
            "z": 1,
            "elements": [
                "botania:storage@0"
            ]
        },
        {
            "x": -2,
            "y": -6,
            "z": 4,
            "elements": [
                "botania:shimmerrock0stairs@3"
            ]
        },
        {
            "x": 4,
            "y": -9,
            "z": -2,
            "elements": [
                "botania:shimmerrock0stairs@1"
            ]
        },
        {
            "x": 4,
            "y": -6,
            "z": 2,
            "elements": [
                "botania:shimmerrock0stairs@1"
            ]
        },
        {
            "x": -2,
            "y": -8,
            "z": -3,
            "elements": [
                "minecraft:end_rod@1"
            ]
        },
        {
            "x": 0,
            "y": -6,
            "z": 0,
            "elements": [
                "modularmachinery:blockenergyoutputhatch",
                "gugu-utils:energyoutputport"
            ]
        },
        {
            "x": -2,
            "y": -3,
            "z": -2,
            "elements": [
                "botania:pylon@2"
            ]
        },
        {
            "x": 0,
            "y": -9,
            "z": -1,
            "elements": [
                "additions:elfsteel_block"
            ]
        },
        {
            "x": -1,
            "y": -6,
            "z": -4,
            "elements": [
                "botania:shimmerrock0stairs@2"
            ]
        },
        {
            "x": -2,
            "y": -9,
            "z": -3,
            "elements": [
                "botania:storage@4"
            ]
        },
        {
            "x": 1,
            "y": -2,
            "z": 2,
            "elements": [
                "gct_ores:rainboquartz_stair@6"
            ]
        },
        {
            "x": 2,
            "y": -9,
            "z": 2,
            "elements": [
                "additions:elfsteel_block"
            ]
        },
        {
            "x": 4,
            "y": -6,
            "z": -2,
            "elements": [
                "botania:shimmerrock0stairs@1"
            ]
        },
        {
            "x": 1,
            "y": -9,
            "z": -4,
            "elements": [
                "additions:elfsteel_block"
            ]
        },
        {
            "x": 3,
            "y": -9,
            "z": 0,
            "elements": [
                "additions:elfsteel_block"
            ]
        },
        {
            "x": -2,
            "y": -9,
            "z": 4,
            "elements": [
                "botania:shimmerrock0stairs@3"
            ]
        },
        {
            "x": -4,
            "y": -3,
            "z": 1,
            "elements": [
                "botania:shimmerrock0slab@0"
            ]
        },
        {
            "x": -2,
            "y": -2,
            "z": -2,
            "elements": [
                "botania:shimmerrock0slab@0"
            ]
        },
        {
            "x": 3,
            "y": -4,
            "z": -2,
            "elements": [
                "minecraft:end_rod@0"
            ]
        },
        {
            "x": 4,
            "y": -3,
            "z": -1,
            "elements": [
                "botania:shimmerrock0slab@0"
            ]
        },
        {
            "x": -1,
            "y": -6,
            "z": 2,
            "elements": [
                "gct_ores:rainboquartz_stair@2"
            ]
        },
        {
            "x": -3,
            "y": -6,
            "z": 0,
            "selector-tag": "input2",
            "elements": [
                "modularmachinery:blockinputbus"
            ]
        },
        {
            "x": 3,
            "y": -3,
            "z": 1,
            "elements": [
                "botania:storage@0"
            ]
        },
        {
            "x": -3,
            "y": -9,
            "z": -3,
            "elements": [
                "botania:shimmerrock0slab@0"
            ]
        },
        {
            "x": -2,
            "y": -3,
            "z": 2,
            "elements": [
                "botania:pylon@2"
            ]
        },
        {
            "x": 3,
            "y": -3,
            "z": -2,
            "elements": [
                "botania:storage@4"
            ]
        },
        {
            "x": 1,
            "y": -9,
            "z": -1,
            "elements": [
                "avaritiatweaks:gaia_block"
            ]
        },
        {
            "x": -1,
            "y": -6,
            "z": 1,
            "elements": [
                "botania:bifrostperm@0"
            ]
        },
        {
            "x": 0,
            "y": -6,
            "z": -1,
            "elements": [
                "botania:bifrostperm@0"
            ]
        },
        {
            "x": -1,
            "y": -9,
            "z": 4,
            "elements": [
                "additions:elfsteel_block"
            ]
        },
        {
            "x": 1,
            "y": -6,
            "z": -4,
            "elements": [
                "botania:shimmerrock0stairs@2"
            ]
        },
        {
            "x": -4,
            "y": -9,
            "z": 3,
            "elements": [
                "botania:shimmerrock0slab@0"
            ]
        },
        {
            "x": 4,
            "y": -9,
            "z": -3,
            "elements": [
                "botania:shimmerrock0slab@0"
            ]
        },
        {
            "x": 3,
            "y": -4,
            "z": 2,
            "elements": [
                "minecraft:end_rod@0"
            ]
        },
        {
            "x": -3,
            "y": -2,
            "z": 1,
            "elements": [
                "botania:shimmerrock0slab@0"
            ]
        },
        {
            "x": -2,
            "y": -5,
            "z": -3,
            "elements": [
                "minecraft:end_rod@1"
            ]
        },
        {
            "x": -4,
            "y": -9,
            "z": 0,
            "elements": [
                "botania:storage@4"
            ]
        },
        {
            "x": 0,
            "y": -6,
            "z": 1,
            "elements": [
                "botania:bifrostperm@0"
            ]
        },
        {
            "x": 3,
            "y": -3,
            "z": 2,
            "elements": [
                "botania:storage@4"
            ]
        },
        {
            "x": -1,
            "y": -9,
            "z": 3,
            "elements": [
                "avaritiatweaks:gaia_block@0"
            ]
        },
        {
            "x": 1,
            "y": -6,
            "z": -3,
            "elements": [
                "botania:storage@0"
            ]
        },
        {
            "x": -2,
            "y": -9,
            "z": -5,
            "elements": [
                "botania:shimmerrock0stairs@0"
            ]
        },
        {
            "x": 2,
            "y": -2,
            "z": -1,
            "elements": [
                "gct_ores:rainboquartz_stair@4"
            ]
        },
        {
            "x": -2,
            "y": -4,
            "z": -3,
            "elements": [
                "minecraft:end_rod@0"
            ]
        },
        {
            "x": 2,
            "y": -2,
            "z": 1,
            "elements": [
                "gct_ores:rainboquartz_stair@4"
            ]
        },
        {
            "x": -1,
            "y": -6,
            "z": 3,
            "elements": [
                "botania:storage@0"
            ]
        },
        {
            "x": -2,
            "y": -7,
            "z": -3,
            "elements": [
                "minecraft:end_rod@0"
            ]
        },
        {
            "x": -3,
            "y": -4,
            "z": -2,
            "elements": [
                "minecraft:end_rod@0"
            ]
        },
        {
            "x": 0,
            "y": -8,
            "z": 2,
            "elements": [
                "botania:terraplate"
            ]
        },
        {
            "x": 0,
            "y": -9,
            "z": 2,
            "elements": [
                "botania:quartztypeblaze@0",
                "additions:elfsteel_block"
            ]
        },
        {
            "x": -1,
            "y": -6,
            "z": 4,
            "elements": [
                "botania:shimmerrock0stairs@3"
            ]
        },
        {
            "x": -3,
            "y": -9,
            "z": 0,
            "elements": [
                "additions:elfsteel_block"
            ]
        },
        {
            "x": 3,
            "y": -9,
            "z": 1,
            "elements": [
                "avaritiatweaks:gaia_block@0"
            ]
        },
        {
            "x": 0,
            "y": 0,
            "z": 1,
            "elements": [
                "botania:shimmerrock0slab@0"
            ]
        },
        {
            "x": -1,
            "y": -1,
            "z": -1,
            "elements": [
                "botania:shimmerrock0slab@0"
            ]
        },
        {
            "x": 1,
            "y": -3,
            "z": 4,
            "elements": [
                "botania:shimmerrock0slab@0"
            ]
        },
        {
            "x": -3,
            "y": -3,
            "z": -2,
            "elements": [
                "botania:storage@4"
            ]
        },
        {
            "x": -2,
            "y": -6,
            "z": -3,
            "elements": [
                "botania:storage@4"
            ]
        },
        {
            "x": 3,
            "y": -9,
            "z": -1,
            "elements": [
                "avaritiatweaks:gaia_block@0"
            ]
        },
        {
            "x": 0,
            "y": -3,
            "z": -4,
            "elements": [
                "botania:shimmerrock0stairs@2"
            ]
        },
        {
            "x": -1,
            "y": -2,
            "z": -1,
            "elements": [
                "gct_mobs:mana_block@0"
            ]
        },
        {
            "x": -4,
            "y": -5,
            "z": 0,
            "elements": [
                "minecraft:end_rod@1"
            ]
        },
        {
            "x": -1,
            "y": -9,
            "z": -5,
            "elements": [
                "botania:shimmerrock0stairs@2"
            ]
        },
        {
            "x": -3,
            "y": -5,
            "z": 2,
            "elements": [
                "minecraft:end_rod@1"
            ]
        },
        {
            "x": 0,
            "y": -1,
            "z": -1,
            "elements": [
                "additions:elfsteel_block@0"
            ]
        },
        {
            "x": 1,
            "y": -9,
            "z": 4,
            "elements": [
                "additions:elfsteel_block"
            ]
        },
        {
            "x": 3,
            "y": -9,
            "z": 2,
            "elements": [
                "botania:storage@4"
            ]
        },
        {
            "x": -1,
            "y": -2,
            "z": 1,
            "elements": [
                "gct_mobs:mana_block@0"
            ]
        },
        {
            "x": 2,
            "y": -6,
            "z": -1,
            "elements": [
                "gct_ores:rainboquartz_stair@0"
            ]
        },
        {
            "x": 2,
            "y": -6,
            "z": 4,
            "elements": [
                "botania:shimmerrock0stairs@3"
            ]
        },
        {
            "x": -4,
            "y": -6,
            "z": 0,
            "elements": [
                "botania:storage@4"
            ]
        },
        {
            "x": 4,
            "y": -9,
            "z": 1,
            "elements": [
                "additions:elfsteel_block"
            ]
        },
        {
            "x": -3,
            "y": -7,
            "z": -2,
            "elements": [
                "minecraft:end_rod@0"
            ]
        },
        {
            "x": -3,
            "y": -4,
            "z": 2,
            "elements": [
                "minecraft:end_rod@0"
            ]
        },
        {
            "x": 0,
            "y": -6,
            "z": 2,
            "elements": [
                "botania:bifrostperm@0"
            ]
        },
        {
            "x": 0,
            "y": -8,
            "z": -2,
            "elements": [
                "botania:terraplate"
            ]
        },
        {
            "x": 0,
            "y": -9,
            "z": -2,
            "elements": [
                "botania:quartztypeelf@0",
                "botania:storage@1"
            ]
        },
        {
            "x": 0,
            "y": -3,
            "z": 4,
            "elements": [
                "botania:shimmerrock0stairs@3"
            ]
        },
        {
            "x": 0,
            "y": 0,
            "z": -1,
            "elements": [
                "botania:shimmerrock0slab@0"
            ]
        },
        {
            "x": -3,
            "y": -6,
            "z": 2,
            "elements": [
                "botania:storage@4"
            ]
        },
        {
            "x": 2,
            "y": -6,
            "z": 1,
            "elements": [
                "gct_ores:rainboquartz_stair@0"
            ]
        },
        {
            "x": -1,
            "y": -1,
            "z": 1,
            "elements": [
                "botania:shimmerrock0slab@0"
            ]
        },
        {
            "x": -3,
            "y": -5,
            "z": -2,
            "elements": [
                "minecraft:end_rod@1"
            ]
        },
        {
            "x": 4,
            "y": -9,
            "z": -1,
            "elements": [
                "additions:elfsteel_block"
            ]
        },
        {
            "x": 1,
            "y": -3,
            "z": -4,
            "elements": [
                "botania:shimmerrock0slab@0"
            ]
        },
        {
            "x": -3,
            "y": -3,
            "z": 2,
            "elements": [
                "botania:storage@4"
            ]
        },
        {
            "x": 0,
            "y": -9,
            "z": -5,
            "elements": [
                "botania:shimmerrock0stairs@2"
            ]
        },
        {
            "x": 0,
            "y": -2,
            "z": -1,
            "elements": [
                "botania:storage@0"
            ]
        },
        {
            "x": -3,
            "y": -8,
            "z": -2,
            "elements": [
                "minecraft:end_rod@1"
            ]
        },
        {
            "x": 3,
            "y": -7,
            "z": 2,
            "elements": [
                "minecraft:end_rod@0"
            ]
        },
        {
            "x": 1,
            "y": -9,
            "z": -3,
            "elements": [
                "avaritiatweaks:gaia_block@0"
            ]
        },
        {
            "x": 1,
            "y": -1,
            "z": -1,
            "elements": [
                "botania:shimmerrock0slab@0"
            ]
        },
        {
            "x": -4,
            "y": -7,
            "z": 0,
            "elements": [
                "minecraft:end_rod@0"
            ]
        },
        {
            "x": 0,
            "y": -2,
            "z": 1,
            "elements": [
                "botania:storage@0"
            ]
        },
        {
            "x": 2,
            "y": -9,
            "z": 4,
            "elements": [
                "botania:shimmerrock0stairs@3"
            ]
        },
        {
            "x": -3,
            "y": -7,
            "z": 2,
            "elements": [
                "minecraft:end_rod@0"
            ]
        },
        {
            "x": 3,
            "y": -6,
            "z": -1,
            "elements": [
                "botania:storage@0"
            ]
        },
        {
            "x": 0,
            "y": -6,
            "z": -2,
            "elements": [
                "botania:bifrostperm@0"
            ]
        },
        {
            "x": 3,
            "y": -9,
            "z": -2,
            "elements": [
                "botania:storage@4"
            ]
        },
        {
            "x": 3,
            "y": -6,
            "z": 2,
            "elements": [
                "botania:storage@4"
            ]
        },
        {
            "x": 1,
            "y": -6,
            "z": 4,
            "elements": [
                "botania:shimmerrock0stairs@3"
            ]
        },
        {
            "x": -1,
            "y": -9,
            "z": 0,
            "elements": [
                "additions:elfsteel_block"
            ]
        },
        {
            "x": -2,
            "y": -3,
            "z": -3,
            "elements": [
                "botania:storage@4"
            ]
        },
        {
            "x": 5,
            "y": -9,
            "z": 1,
            "elements": [
                "botania:shimmerrock0stairs@1"
            ]
        },
        {
            "x": 0,
            "y": -4,
            "z": 4,
            "elements": [
                "minecraft:end_rod@0"
            ]
        },
        {
            "x": 0,
            "y": -1,
            "z": 1,
            "elements": [
                "additions:elfsteel_block@0"
            ]
        },
        {
            "x": -1,
            "y": -3,
            "z": 4,
            "elements": [
                "botania:shimmerrock0slab@0"
            ]
        },
        {
            "x": 3,
            "y": -6,
            "z": 1,
            "elements": [
                "botania:storage@0"
            ]
        },
        {
            "x": -3,
            "y": -8,
            "z": 2,
            "elements": [
                "minecraft:end_rod@1"
            ]
        },
        {
            "x": -3,
            "y": -6,
            "z": -2,
            "elements": [
                "botania:storage@4"
            ]
        },
        {
            "x": 3,
            "y": -5,
            "z": 2,
            "elements": [
                "minecraft:end_rod@1"
            ]
        },
        {
            "x": -4,
            "y": -8,
            "z": 0,
            "elements": [
                "minecraft:end_rod@1"
            ]
        },
        {
            "x": 5,
            "y": -9,
            "z": -1,
            "elements": [
                "botania:shimmerrock0stairs@1"
            ]
        },
        {
            "x": 1,
            "y": -2,
            "z": -1,
            "elements": [
                "gct_mobs:mana_block@0"
            ]
        },
        {
            "x": 0,
            "y": -5,
            "z": 4,
            "elements": [
                "minecraft:end_rod@1"
            ]
        },
        {
            "x": 1,
            "y": -9,
            "z": -5,
            "elements": [
                "botania:shimmerrock0stairs@2"
            ]
        },
        {
            "x": 0,
            "y": -7,
            "z": 4,
            "elements": [
                "minecraft:end_rod@0"
            ]
        },
        {
            "x": -2,
            "y": -9,
            "z": -2,
            "elements": [
                "additions:elfsteel_block"
            ]
        },
        {
            "x": 0,
            "y": -6,
            "z": 3,
            "selector-tag": "input0",
            "elements": [
                "modularmachinery:blockinputbus"
            ]
        },
        {
            "x": 3,
            "y": -9,
            "z": 4,
            "elements": [
                "botania:shimmerrock0slab@0"
            ]
        },
        {
            "x": 1,
            "y": -2,
            "z": 1,
            "elements": [
                "gct_mobs:mana_block@0"
            ]
        },
        {
            "x": 0,
            "y": -9,
            "z": -4,
            "elements": [
                "botania:storage@4"
            ]
        },
        {
            "x": 2,
            "y": -5,
            "z": -3,
            "elements": [
                "minecraft:end_rod@1"
            ]
        },
        {
            "x": -3,
            "y": -9,
            "z": 2,
            "elements": [
                "botania:storage@4"
            ]
        },
        {
            "x": 0,
            "y": -6,
            "z": 4,
            "elements": [
                "botania:storage@4"
            ]
        },
        {
            "x": -4,
            "y": -6,
            "z": -1,
            "elements": [
                "botania:shimmerrock0stairs@0"
            ]
        },
        {
            "x": -2,
            "y": -6,
            "z": 0,
            "elements": [
                "botania:bifrostperm@0"
            ]
        },
        {
            "x": 3,
            "y": -3,
            "z": -1,
            "elements": [
                "botania:storage@0"
            ]
        },
        {
            "x": 2,
            "y": -3,
            "z": 3,
            "elements": [
                "botania:storage@4"
            ]
        },
        {
            "x": 2,
            "y": -3,
            "z": -3,
            "elements": [
                "botania:storage@4"
            ]
        },
        {
            "x": 1,
            "y": -1,
            "z": 1,
            "elements": [
                "botania:shimmerrock0slab@0"
            ]
        },
        {
            "x": 4,
            "y": -6,
            "z": 1,
            "elements": [
                "botania:shimmerrock0stairs@1"
            ]
        },
        {
            "x": 0,
            "y": -8,
            "z": -4,
            "elements": [
                "minecraft:end_rod@1"
            ]
        },
        {
            "x": 3,
            "y": -9,
            "z": 3,
            "elements": [
                "botania:shimmerrock0slab@0"
            ]
        },
        {
            "x": -4,
            "y": -6,
            "z": -2,
            "elements": [
                "botania:shimmerrock0stairs@0"
            ]
        },
        {
            "x": 2,
            "y": -9,
            "z": -1,
            "elements": [
                "additions:elfsteel_block@0"
            ]
        },
        {
            "x": -1,
            "y": -2,
            "z": -3,
            "elements": [
                "botania:shimmerrock0slab@0"
            ]
        },
        {
            "x": -4,
            "y": -9,
            "z": -1,
            "elements": [
                "additions:elfsteel_block"
            ]
        },
        {
            "x": -3,
            "y": -9,
            "z": -2,
            "elements": [
                "botania:storage@4"
            ]
        },
        {
            "x": 3,
            "y": -9,
            "z": -3,
            "elements": [
                "botania:shimmerrock0slab@0"
            ]
        },
        {
            "x": 1,
            "y": -9,
            "z": 0,
            "elements": [
                "additions:elfsteel_block"
            ]
        },
        {
            "x": 3,
            "y": -6,
            "z": 3,
            "elements": [
                "botania:shimmerrock0slab@0"
            ]
        },
        {
            "x": 3,
            "y": -9,
            "z": -4,
            "elements": [
                "botania:shimmerrock0slab@0"
            ]
        },
        {
            "x": -2,
            "y": -2,
            "z": 1,
            "elements": [
                "gct_ores:rainboquartz_stair@5"
            ]
        },
        {
            "x": 0,
            "y": -9,
            "z": 4,
            "elements": [
                "botania:storage@4"
            ]
        },
        {
            "x": 2,
            "y": -7,
            "z": -3,
            "elements": [
                "minecraft:end_rod@0"
            ]
        },
        {
            "x": -4,
            "y": -9,
            "z": 2,
            "elements": [
                "botania:shimmerrock0stairs@0"
            ]
        },
        {
            "x": -4,
            "y": -4,
            "z": 0,
            "elements": [
                "minecraft:end_rod@0"
            ]
        },
        {
            "x": 3,
            "y": -2,
            "z": -1,
            "elements": [
                "botania:shimmerrock0slab@0"
            ]
        },
        {
            "x": -1,
            "y": -6,
            "z": 0,
            "elements": [
                "botania:bifrostperm@0"
            ]
        },
        {
            "x": 1,
            "y": -6,
            "z": 1,
            "elements": [
                "botania:bifrostperm@0"
            ]
        },
        {
            "x": 0,
            "y": -8,
            "z": 4,
            "elements": [
                "minecraft:end_rod@1"
            ]
        },
        {
            "x": -1,
            "y": -3,
            "z": -3,
            "elements": [
                "botania:storage@0"
            ]
        },
        {
            "x": 2,
            "y": -5,
            "z": 3,
            "elements": [
                "minecraft:end_rod@1"
            ]
        },
        {
            "x": 0,
            "y": -9,
            "z": 3,
            "elements": [
                "additions:elfsteel_block"
            ]
        },
        {
            "x": 2,
            "y": -6,
            "z": -3,
            "elements": [
                "botania:storage@4"
            ]
        },
        {
            "x": 2,
            "y": -4,
            "z": 3,
            "elements": [
                "minecraft:end_rod@0"
            ]
        },
        {
            "x": -4,
            "y": -3,
            "z": 0,
            "elements": [
                "botania:shimmerrock0stairs@0"
            ]
        },
        {
            "x": -1,
            "y": -9,
            "z": -1,
            "elements": [
                "avaritiatweaks:gaia_block"
            ]
        },
        {
            "x": 2,
            "y": -2,
            "z": 0,
            "elements": [
                "avaritiatweaks:gaia_block@0"
            ]
        },
        {
            "x": 2,
            "y": -6,
            "z": 3,
            "elements": [
                "botania:storage@4"
            ]
        },
        {
            "x": -4,
            "y": -9,
            "z": -2,
            "elements": [
                "botania:shimmerrock0stairs@0"
            ]
        },
        {
            "x": 0,
            "y": -3,
            "z": 3,
            "elements": [
                "botania:pylon@2"
            ]
        },
        {
            "x": 0,
            "y": -4,
            "z": -4,
            "elements": [
                "minecraft:end_rod@0"
            ]
        },
        {
            "x": 0,
            "y": -2,
            "z": -3,
            "elements": [
                "botania:shimmerrock0slab@0"
            ]
        },
        {
            "x": -3,
            "y": -9,
            "z": 4,
            "elements": [
                "botania:shimmerrock0slab@0"
            ]
        },
        {
            "x": -2,
            "y": -8,
            "z": 0,
            "elements": [
                "botania:terraplate"
            ]
        },
        {
            "x": -2,
            "y": -9,
            "z": 0,
            "elements": [
                "botania:quartztypelavender@0",
                "botania:storage@3"
            ]
        },
        {
            "x": -1,
            "y": -9,
            "z": 2,
            "elements": [
                "additions:elfsteel_block@0"
            ]
        },
        {
            "x": 2,
            "y": -7,
            "z": 3,
            "elements": [
                "minecraft:end_rod@0"
            ]
        },
        {
            "x": 0,
            "y": -5,
            "z": -4,
            "elements": [
                "minecraft:end_rod@1"
            ]
        },
        {
            "x": 0,
            "y": -3,
            "z": -3,
            "elements": [
                "botania:pylon@2"
            ]
        },
        {
            "x": 4,
            "y": -3,
            "z": 1,
            "elements": [
                "botania:shimmerrock0slab@0"
            ]
        },
        {
            "x": -3,
            "y": -3,
            "z": -1,
            "elements": [
                "botania:storage@0"
            ]
        },
        {
            "x": 0,
            "y": -9,
            "z": 1,
            "elements": [
                "additions:elfsteel_block"
            ]
        },
        {
            "x": -2,
            "y": -6,
            "z": -2,
            "selector-tag": "input3",
            "elements": [
                "modularmachinery:blockinputbus"
            ]
        },
        {
            "x": 1,
            "y": -9,
            "z": 3,
            "elements": [
                "avaritiatweaks:gaia_block@0"
            ]
        },
        {
            "x": 3,
            "y": -6,
            "z": -3,
            "elements": [
                "botania:shimmerrock0slab@0"
            ]
        },
        {
            "x": -1,
            "y": -9,
            "z": 5,
            "elements": [
                "botania:shimmerrock0stairs@3"
            ]
        },
        {
            "x": -2,
            "y": -6,
            "z": 1,
            "elements": [
                "gct_ores:rainboquartz_stair@1"
            ]
        },
        {
            "x": 0,
            "y": -2,
            "z": 3,
            "elements": [
                "botania:shimmerrock0slab@0"
            ]
        },
        {
            "x": 1,
            "y": -6,
            "z": 3,
            "elements": [
                "botania:storage@0"
            ]
        },
        {
            "x": -1,
            "y": -6,
            "z": -1,
            "elements": [
                "botania:bifrostperm@0"
            ]
        },
        {
            "x": 0,
            "y": -6,
            "z": -4,
            "elements": [
                "botania:storage@4"
            ]
        },
        {
            "x": 2,
            "y": -4,
            "z": -3,
            "elements": [
                "minecraft:end_rod@0"
            ]
        },
        {
            "x": -1,
            "y": -2,
            "z": 0,
            "elements": [
                "botania:storage@0"
            ]
        },
        {
            "x": 1,
            "y": -2,
            "z": -3,
            "elements": [
                "botania:shimmerrock0slab@0"
            ]
        },
        {
            "x": 1,
            "y": -9,
            "z": 1,
            "elements": [
                "avaritiatweaks:gaia_block"
            ]
        },
        {
            "x": -1,
            "y": -3,
            "z": 3,
            "elements": [
                "botania:storage@0"
            ]
        },
        {
            "x": -1,
            "y": -9,
            "z": -2,
            "elements": [
                "additions:elfsteel_block@0"
            ]
        },
        {
            "x": 2,
            "y": -8,
            "z": 3,
            "elements": [
                "minecraft:end_rod@1"
            ]
        },
        {
            "x": -5,
            "y": -9,
            "z": 0,
            "elements": [
                "botania:shimmerrock0stairs@0"
            ]
        },
        {
            "x": 2,
            "y": -1,
            "z": 0,
            "elements": [
                "botania:shimmerrock0stairs@1"
            ]
        },
        {
            "x": 0,
            "y": -7,
            "z": -4,
            "elements": [
                "minecraft:end_rod@0"
            ]
        },
        {
            "x": -4,
            "y": -6,
            "z": 2,
            "elements": [
                "botania:shimmerrock0stairs@0"
            ]
        },
        {
            "x": 1,
            "y": -3,
            "z": -3,
            "elements": [
                "botania:storage@0"
            ]
        },
        {
            "x": -1,
            "y": -1,
            "z": 0,
            "elements": [
                "additions:elfsteel_block@0"
            ]
        },
        {
            "x": -4,
            "y": -3,
            "z": -1,
            "elements": [
                "botania:shimmerrock0slab@0"
            ]
        },
        {
            "x": -1,
            "y": -2,
            "z": 3,
            "elements": [
                "botania:shimmerrock0slab@0"
            ]
        },
        {
            "x": -3,
            "y": -2,
            "z": -1,
            "elements": [
                "botania:shimmerrock0slab@0"
            ]
        },
        {
            "x": 2,
            "y": -9,
            "z": 3,
            "elements": [
                "botania:storage@4"
            ]
        }
    ]}