{
    "registryname": "miner_molten",
    "localizedname": "熔融矿机",
    "requires-blueprint": true,
    "failure-action": "still",
    "color": "d7bbb4",
    "modifiers": [
        {
            "elements": "modularmachinery:blockcasing@1",
            "x": 0,
            "y": -1,
            "z": 0,
            "description": "将控制器下方的紧挨着的方块换成此方块以提高25%产品产出率！",
            "modifier": {
                "io": "output",
                "target": "item",
                "operation": 1,
                "multiplier": 1.25,
                "affectChance": true
            }
        },
        {
            "elements": "modularmachinery:blockcasing@2",
            "x": 0,
            "y": -1,
            "z": 0,
            "description": "将控制器下方的紧挨着的方块换成此方块以提高50%产品产出率！",
            "modifier": {
                "io": "output",
                "target": "item",
                "operation": 1,
                "multiplier": 1.5,
                "affectChance": true
            }
        },
        {
            "elements": "modularmachinery:blockcasing@3",
            "x": 0,
            "y": -1,
            "z": 0,
            "description": "将控制器下方的紧挨着的方块换成此方块以提高100%产品产出率！",
            "modifier": {
                "io": "output",
                "target": "item",
                "operation": 1,
                "multiplier": 2.0,
                "affectChance": true
            }
        },
        {
            "elements": "modularmachinery:blockcasing@5",
            "x": 0,
            "y": 1,
            "z": 0,
            "description": "将控制器下方的紧挨着的方块换成此方块以提高150%产品产出率！",
            "modifier": {
                "io": "output",
                "target": "item",
                "operation": 1,
                "multiplier": 2.5,
                "affectChance": true
            }
        }
    ],
    "parts": [
        {
            "x": 2,
            "y": 3,
            "z": 0,
            "elements": [
                "minecraft:iron_bars@0"
            ]
        },
        {
            "x": -3,
            "y": 0,
            "z": 4,
            "elements": [
                "jaopca:block.oneo@0"
            ]
        },
        {
            "x": 2,
            "y": 3,
            "z": 1,
            "elements": [
                "thermalfoundation:glass@8"
            ]
        },
        {
            "x": -4,
            "y": 2,
            "z": 1,
            "elements": [
                "betternether:cincinnasite_stairs@0"
            ]
        },
        {
            "x": 4,
            "y": 2,
            "z": 1,
            "elements": [
                "betternether:cincinnasite_stairs@1"
            ]
        },
        {
            "x": 2,
            "y": 3,
            "z": 2,
            "elements": [
                "minecraft:iron_bars@0"
            ]
        },
        {
            "x": -4,
            "y": -1,
            "z": -2,
            "elements": [
                "jaopca:block.mangisite@0"
            ]
        },
        {
            "x": -1,
            "y": -1,
            "z": 1,
            "elements": [
                "modularmachinery:blockcasing@4"
            ]
        },
        {
            "x": -1,
            "y": -1,
            "z": 2,
            "elements": [
                "taiga:osram_block@0"
            ]
        },
        {
            "x": 0,
            "y": 4,
            "z": 1,
            "elements": [
                "betternether:cincinnasite_slab_half@1"
            ]
        },
        {
            "x": -4,
            "y": -1,
            "z": 1,
            "elements": [
                "betternether:cincinnasite_tile_large@0"
            ]
        },
        {
            "x": -3,
            "y": 0,
            "z": -2,
            "elements": [
                "jaopca:block.mangisite@0"
            ]
        },
        {
            "x": -1,
            "y": -1,
            "z": 0,
            "elements": [
                "taiga:osram_block@0"
            ]
        },
        {
            "x": 0,
            "y": 0,
            "z": 5,
            "elements": [
                "betternether:cincinnasite_tile_large@0"
            ]
        },
        {
            "x": 0,
            "y": 0,
            "z": 2,
            "elements": [
                "casings_all"
            ]
        },
        {
            "x": 1,
            "y": 2,
            "z": 3,
            "elements": [
                "betternether:cincinnasite_slab_half@0"
            ]
        },
        {
            "x": 1,
            "y": 2,
            "z": 2,
            "elements": [
                "betternether:cincinnasite_tile_large@0"
            ]
        },
        {
            "x": -1,
            "y": 3,
            "z": 3,
            "elements": [
                "minecraft:iron_bars@0"
            ]
        },
        {
            "x": 1,
            "y": 2,
            "z": 1,
            "elements": [
                "betternether:cincinnasite_tile_large@0"
            ]
        },
        {
            "x": -1,
            "y": 3,
            "z": 2,
            "elements": [
                "minecraft:iron_bars@0"
            ]
        },
        {
            "x": 0,
            "y": 0,
            "z": -3,
            "elements": [
                "betternether:cincinnasite_tile_large@0"
            ]
        },
        {
            "x": 1,
            "y": 2,
            "z": 0,
            "elements": [
                "betternether:cincinnasite_tile_large@0"
            ]
        },
        {
            "x": -1,
            "y": 3,
            "z": 1,
            "elements": [
                "thermalfoundation:glass@8"
            ]
        },
        {
            "x": 1,
            "y": 2,
            "z": -1,
            "elements": [
                "betternether:cincinnasite_slab_half@0"
            ]
        },
        {
            "x": -1,
            "y": 3,
            "z": 0,
            "elements": [
                "minecraft:iron_bars@0"
            ]
        },
        {
            "x": -1,
            "y": 3,
            "z": -1,
            "elements": [
                "minecraft:iron_bars@0"
            ]
        },
        {
            "x": 1,
            "y": -1,
            "z": 2,
            "elements": [
                "taiga:osram_block@0"
            ]
        },
        {
            "x": 1,
            "y": -1,
            "z": 1,
            "elements": [
                "modularmachinery:blockcasing@4"
            ]
        },
        {
            "x": 1,
            "y": -1,
            "z": 0,
            "elements": [
                "taiga:osram_block@0"
            ]
        },
        {
            "x": 0,
            "y": 3,
            "z": -1,
            "elements": [
                "thermalfoundation:glass@8"
            ]
        },
        {
            "x": 0,
            "y": 3,
            "z": 1,
            "elements": [
                "gct_ores:fire_alloy_block@0"
            ]
        },
        {
            "x": 0,
            "y": 3,
            "z": 0,
            "elements": [
                "thermalfoundation:glass@8"
            ]
        },
        {
            "x": 0,
            "y": 3,
            "z": 3,
            "elements": [
                "thermalfoundation:glass@8"
            ]
        },
        {
            "x": 0,
            "y": 3,
            "z": 2,
            "elements": [
                "thermalfoundation:glass@8"
            ]
        },
        {
            "x": 1,
            "y": 1,
            "z": 0,
            "elements": [
                "taiga:osram_block@0"
            ]
        },
        {
            "x": 1,
            "y": 1,
            "z": 2,
            "elements": [
                "taiga:osram_block@0"
            ]
        },
        {
            "x": 1,
            "y": 1,
            "z": 1,
            "elements": [
                "casings_all"
            ]
        },
        {
            "x": 3,
            "y": 2,
            "z": 1,
            "elements": [
                "betternether:cincinnasite_tile_large@0"
            ]
        },
        {
            "x": 4,
            "y": 0,
            "z": 1,
            "elements": [
                "betternether:cincinnasite_tile_large@0"
            ]
        },
        {
            "x": -4,
            "y": -1,
            "z": 4,
            "elements": [
                "jaopca:block.oneo@0"
            ]
        },
        {
            "x": -2,
            "y": -1,
            "z": 4,
            "elements": [
                "jaopca:block.oneo@0"
            ]
        },
        {
            "x": -2,
            "y": -1,
            "z": -2,
            "elements": [
                "jaopca:block.mangisite@0"
            ]
        },
        {
            "x": -2,
            "y": 2,
            "z": 0,
            "elements": [
                "betternether:cincinnasite_slab_half@0"
            ]
        },
        {
            "x": -2,
            "y": 2,
            "z": 2,
            "elements": [
                "betternether:cincinnasite_slab_half@0"
            ]
        },
        {
            "x": -2,
            "y": 2,
            "z": 1,
            "elements": [
                "betternether:cincinnasite_tile_large@0"
            ]
        },
        {
            "x": 1,
            "y": 0,
            "z": 2,
            "elements": [
                "taiga:osram_block@0"
            ]
        },
        {
            "x": 1,
            "y": 0,
            "z": 1,
            "elements": [
                "casings_all"
            ]
        },
        {
            "x": 1,
            "y": 0,
            "z": 0,
            "elements": [
                "taiga:osram_block@0"
            ]
        },
        {
            "x": 0,
            "y": 2,
            "z": 5,
            "elements": [
                "betternether:cincinnasite_stairs@3"
            ]
        },
        {
            "x": 0,
            "y": -1,
            "z": -3,
            "elements": [
                "betternether:cincinnasite_tile_large@0"
            ]
        },
        {
            "x": 3,
            "y": -1,
            "z": 5,
            "elements": [
                "jaopca:block.rapesesium@0"
            ]
        },
        {
            "x": 3,
            "y": -1,
            "z": 3,
            "elements": [
                "jaopca:block.rapesesium@0"
            ]
        },
        {
            "x": 3,
            "y": -1,
            "z": 4,
            "elements": [
                "jaopca:block.rapesesium@0"
            ]
        },
        {
            "x": 3,
            "y": -1,
            "z": -1,
            "elements": [
                "jaopca:block.xenidium@0"
            ]
        },
        {
            "x": -1,
            "y": 1,
            "z": 2,
            "elements": [
                "taiga:osram_block@0"
            ]
        },
        {
            "x": -1,
            "y": 1,
            "z": 1,
            "elements": [
                "casings_all"
            ]
        },
        {
            "x": 3,
            "y": -1,
            "z": -3,
            "elements": [
                "jaopca:block.xenidium@0"
            ]
        },
        {
            "x": -1,
            "y": 1,
            "z": 0,
            "elements": [
                "taiga:osram_block@0"
            ]
        },
        {
            "x": 3,
            "y": -1,
            "z": -2,
            "elements": [
                "jaopca:block.xenidium@0"
            ]
        },
        {
            "x": 0,
            "y": 2,
            "z": 2,
            "elements": [
                "betternether:cincinnasite_tile_large@0"
            ]
        },
        {
            "x": 0,
            "y": 2,
            "z": 1,
            "elements": [
                "betternether:cincinnasite_tile_large@0"
            ]
        },
        {
            "x": -2,
            "y": 3,
            "z": 2,
            "elements": [
                "minecraft:iron_bars@0"
            ]
        },
        {
            "x": 1,
            "y": 3,
            "z": 3,
            "elements": [
                "minecraft:iron_bars@0"
            ]
        },
        {
            "x": 0,
            "y": 2,
            "z": 4,
            "elements": [
                "betternether:cincinnasite_tile_large@0"
            ]
        },
        {
            "x": 0,
            "y": 2,
            "z": 3,
            "elements": [
                "betternether:cincinnasite_tile_large@0"
            ]
        },
        {
            "x": 0,
            "y": 2,
            "z": -2,
            "elements": [
                "betternether:cincinnasite_tile_large@0"
            ]
        },
        {
            "x": 0,
            "y": 2,
            "z": -3,
            "elements": [
                "betternether:cincinnasite_stairs@2"
            ]
        },
        {
            "x": 0,
            "y": 2,
            "z": 0,
            "elements": [
                "betternether:cincinnasite_tile_large@0"
            ]
        },
        {
            "x": -2,
            "y": 3,
            "z": 1,
            "elements": [
                "thermalfoundation:glass@8"
            ]
        },
        {
            "x": 0,
            "y": 2,
            "z": -1,
            "elements": [
                "betternether:cincinnasite_tile_large@0"
            ]
        },
        {
            "x": -2,
            "y": 3,
            "z": 0,
            "elements": [
                "minecraft:iron_bars@0"
            ]
        },
        {
            "x": 1,
            "y": 3,
            "z": 1,
            "elements": [
                "thermalfoundation:glass@8"
            ]
        },
        {
            "x": 1,
            "y": 3,
            "z": 2,
            "elements": [
                "minecraft:iron_bars@0"
            ]
        },
        {
            "x": 1,
            "y": 3,
            "z": -1,
            "elements": [
                "minecraft:iron_bars@0"
            ]
        },
        {
            "x": 1,
            "y": 3,
            "z": 0,
            "elements": [
                "minecraft:iron_bars@0"
            ]
        },
        {
            "x": 4,
            "y": 1,
            "z": 1,
            "elements": [
                "betternether:cincinnasite_tile_large@0"
            ]
        },
        {
            "x": -4,
            "y": 1,
            "z": 1,
            "elements": [
                "betternether:cincinnasite_tile_large@0"
            ]
        },
        {
            "x": 0,
            "y": -1,
            "z": 0,
            "elements": [
                "modularmachinery:blockcasing@4"
            ]
        },
        {
            "x": 0,
            "y": -1,
            "z": 2,
            "elements": [
                "modularmachinery:blockcasing@4"
            ]
        },
        {
            "x": 0,
            "y": -1,
            "z": 5,
            "elements": [
                "betternether:cincinnasite_tile_large@0"
            ]
        },
        {
            "x": 2,
            "y": 2,
            "z": 0,
            "elements": [
                "betternether:cincinnasite_slab_half@0"
            ]
        },
        {
            "x": 2,
            "y": 2,
            "z": 1,
            "elements": [
                "betternether:cincinnasite_tile_large@0"
            ]
        },
        {
            "x": 2,
            "y": 2,
            "z": 2,
            "elements": [
                "betternether:cincinnasite_slab_half@0"
            ]
        },
        {
            "x": -1,
            "y": 0,
            "z": 2,
            "elements": [
                "taiga:osram_block@0"
            ]
        },
        {
            "x": -1,
            "y": 0,
            "z": 1,
            "elements": [
                "casings_all"
            ]
        },
        {
            "x": 3,
            "y": 0,
            "z": 4,
            "elements": [
                "jaopca:block.rapesesium@0"
            ]
        },
        {
            "x": -1,
            "y": 0,
            "z": 0,
            "elements": [
                "taiga:osram_block@0"
            ]
        },
        {
            "x": 3,
            "y": 0,
            "z": -2,
            "elements": [
                "jaopca:block.xenidium@0"
            ]
        },
        {
            "x": 2,
            "y": -1,
            "z": 4,
            "elements": [
                "jaopca:block.rapesesium@0"
            ]
        },
        {
            "x": 2,
            "y": -1,
            "z": -2,
            "elements": [
                "jaopca:block.xenidium@0"
            ]
        },
        {
            "x": -4,
            "y": 0,
            "z": 1,
            "elements": [
                "betternether:cincinnasite_tile_large@0"
            ]
        },
        {
            "x": 0,
            "y": 1,
            "z": -3,
            "elements": [
                "betternether:cincinnasite_tile_large@0"
            ]
        },
        {
            "x": -1,
            "y": 2,
            "z": 1,
            "elements": [
                "betternether:cincinnasite_tile_large@0"
            ]
        },
        {
            "x": -1,
            "y": 2,
            "z": 0,
            "elements": [
                "betternether:cincinnasite_tile_large@0"
            ]
        },
        {
            "x": -3,
            "y": 2,
            "z": 1,
            "elements": [
                "betternether:cincinnasite_tile_large@0"
            ]
        },
        {
            "x": -1,
            "y": 2,
            "z": -1,
            "elements": [
                "betternether:cincinnasite_slab_half@0"
            ]
        },
        {
            "x": -1,
            "y": 2,
            "z": 3,
            "elements": [
                "betternether:cincinnasite_slab_half@0"
            ]
        },
        {
            "x": -1,
            "y": 2,
            "z": 2,
            "elements": [
                "betternether:cincinnasite_tile_large@0"
            ]
        },
        {
            "x": -3,
            "y": -1,
            "z": -1,
            "elements": [
                "jaopca:block.mangisite@0"
            ]
        },
        {
            "x": 4,
            "y": -1,
            "z": 4,
            "elements": [
                "jaopca:block.rapesesium@0"
            ]
        },
        {
            "x": -3,
            "y": -1,
            "z": -3,
            "elements": [
                "jaopca:block.mangisite@0"
            ]
        },
        {
            "x": -3,
            "y": -1,
            "z": -2,
            "elements": [
                "jaopca:block.mangisite@0"
            ]
        },
        {
            "x": 4,
            "y": -1,
            "z": -2,
            "elements": [
                "jaopca:block.xenidium@0"
            ]
        },
        {
            "x": 0,
            "y": 1,
            "z": 0,
            "elements": [
                "casings_all",
                "casings_parallel"
            ]
        },
        {
            "x": -3,
            "y": -1,
            "z": 3,
            "elements": [
                "jaopca:block.oneo@0"
            ]
        },
        {
            "x": 4,
            "y": -1,
            "z": 1,
            "elements": [
                "betternether:cincinnasite_tile_large@0"
            ]
        },
        {
            "x": 0,
            "y": 1,
            "z": 2,
            "elements": [
                "casings_all"
            ]
        },
        {
            "x": -3,
            "y": -1,
            "z": 4,
            "elements": [
                "jaopca:block.oneo@0"
            ]
        },
        {
            "x": -3,
            "y": -1,
            "z": 5,
            "elements": [
                "jaopca:block.oneo@0"
            ]
        },
        {
            "x": 0,
            "y": 1,
            "z": 5,
            "elements": [
                "betternether:cincinnasite_tile_large@0"
            ]
        }
    ]}