{
    "registryname": "elysia_pyrolyzer",
    "localizedname": "§cELYSIA单元 - 大型热解单元",
    "requires-blueprint": false,
    "failure-action": "still",
    "color": "251e0f",
    "modifiers": [
        {
            "elements": "modularmachinery:blockcasing@1",
            "x": 0,
            "y": 1,
            "z": 0,
            "description": "将控制器上方紧挨着的方块换成此方块以降低配方制作时间至75%！",
            "modifier": {
                "io": "input",
                "target": "modularmachinery:duration",
                "operation": 1,
                "multiplier": 0.75
            }
        },
        {
            "elements": "modularmachinery:blockcasing@2",
            "x": 0,
            "y": 1,
            "z": 0,
            "description": "将控制器上方紧挨着的方块换成此方块以降低配方制作时间至66%！",
            "modifier": {
                "io": "input",
                "target": "modularmachinery:duration",
                "operation": 1,
                "multiplier": 0.66
            }
        },
        {
            "elements": "modularmachinery:blockcasing@3",
            "x": 0,
            "y": 1,
            "z": 0,
            "description": "将控制器上方紧挨着的方块换成此方块以降低配方制作时间至50%！",
            "modifier": {
                "io": "input",
                "target": "modularmachinery:duration",
                "operation": 1,
                "multiplier": 0.5
            }
        },
        {
            "elements": "modularmachinery:blockcasing@5",
            "x": 0,
            "y": 1,
            "z": 0,
            "description": "将控制器上方紧挨着的方块换成此方块以降低配方制作时间至33%！",
            "modifier": {
                "io": "input",
                "target": "modularmachinery:duration",
                "operation": 1,
                "multiplier": 0.33
            }
        }
    ],
    "parts": [
        {
            "x": 0,
            "y": 0,
            "z": 0,
            "elements": [
                "modularmachinery:blockcontroller@2"
            ]
        },
        {
            "x": 3,
            "y": 11,
            "z": 7,
            "elements": [
                "tconstruct:metal@0"
            ]
        },
        {
            "x": -2,
            "y": -1,
            "z": 12,
            "elements": [
                "tcomplement:scorched_block@2"
            ]
        },
        {
            "x": -1,
            "y": 2,
            "z": 0,
            "elements": [
                "thermalfoundation:glass@5"
            ]
        },
        {
            "x": 0,
            "y": 16,
            "z": -1,
            "elements": [
                "minecraft:iron_block@0"
            ]
        },
        {
            "x": -2,
            "y": 4,
            "z": 0,
            "elements": [
                "thermalfoundation:glass@5"
            ]
        },
        {
            "x": -3,
            "y": 12,
            "z": 3,
            "elements": [
                "tconstruct:metal@0"
            ]
        },
        {
            "x": 2,
            "y": 13,
            "z": -3,
            "elements": [
                "minecraft:iron_block@0"
            ]
        },
        {
            "x": -1,
            "y": 15,
            "z": -3,
            "elements": [
                "minecraft:iron_block@0"
            ]
        },
        {
            "x": -2,
            "y": 11,
            "z": 9,
            "elements": [
                "minecraft:iron_block@0"
            ]
        },
        {
            "x": -1,
            "y": 17,
            "z": 4,
            "elements": [
                "tconstruct:metal@0"
            ]
        },
        {
            "x": -2,
            "y": 5,
            "z": 11,
            "elements": [
                "jaopca:block.hellite@0"
            ]
        },
        {
            "x": 1,
            "y": 16,
            "z": 2,
            "elements": [
                "tconstruct:metal@0"
            ]
        },
        {
            "x": -3,
            "y": 11,
            "z": 4,
            "elements": [
                "tconstruct:metal@0"
            ]
        },
        {
            "x": 3,
            "y": 12,
            "z": -1,
            "elements": [
                "minecraft:iron_block@0"
            ]
        },
        {
            "x": 0,
            "y": 9,
            "z": 4,
            "elements": [
                "tconstruct:metal@0"
            ]
        },
        {
            "x": 1,
            "y": 0,
            "z": 0,
            "elements": [
                "tcomplement:scorched_block@6"
            ]
        },
        {
            "x": -2,
            "y": 2,
            "z": 0,
            "elements": [
                "tcomplement:scorched_block@11"
            ]
        },
        {
            "x": -1,
            "y": 4,
            "z": 0,
            "elements": [
                "taiga:molten_nitronite_fluid@0"
            ]
        },
        {
            "x": 2,
            "y": 15,
            "z": -3,
            "elements": [
                "minecraft:iron_block@0"
            ]
        },
        {
            "x": 1,
            "y": 5,
            "z": 9,
            "elements": [
                "taiga:molten_nitronite_fluid@0"
            ]
        },
        {
            "x": -3,
            "y": 14,
            "z": 3,
            "elements": [
                "tconstruct:metal@0"
            ]
        },
        {
            "x": 0,
            "y": 7,
            "z": 4,
            "elements": [
                "tcomplement:scorched_block@11"
            ]
        },
        {
            "x": -1,
            "y": 14,
            "z": -4,
            "elements": [
                "minecraft:iron_block@0"
            ]
        },
        {
            "x": -2,
            "y": 2,
            "z": 5,
            "elements": [
                "tcomplement:scorched_block@11"
            ]
        },
        {
            "x": 0,
            "y": 12,
            "z": -4,
            "elements": [
                "minecraft:iron_block@0"
            ]
        },
        {
            "x": 0,
            "y": 17,
            "z": 7,
            "elements": [
                "tconstruct:metal@0"
            ]
        },
        {
            "x": 0,
            "y": 6,
            "z": 3,
            "elements": [
                "thermalfoundation:glass@5"
            ]
        },
        {
            "x": 1,
            "y": 2,
            "z": 0,
            "elements": [
                "thermalfoundation:glass@5"
            ]
        },
        {
            "x": 3,
            "y": 3,
            "z": 4,
            "elements": [
                "tcomplement:scorched_block@11"
            ]
        },
        {
            "x": -2,
            "y": 15,
            "z": 9,
            "elements": [
                "minecraft:iron_block@0"
            ]
        },
        {
            "x": -3,
            "y": 11,
            "z": 7,
            "elements": [
                "tconstruct:metal@0"
            ]
        },
        {
            "x": 3,
            "y": 12,
            "z": 7,
            "elements": [
                "tconstruct:metal@0"
            ]
        },
        {
            "x": 3,
            "y": 10,
            "z": 6,
            "elements": [
                "tconstruct:metal@0"
            ]
        },
        {
            "x": 3,
            "y": 12,
            "z": 3,
            "elements": [
                "tconstruct:metal@0"
            ]
        },
        {
            "x": 1,
            "y": 13,
            "z": 2,
            "elements": [
                "minecraft:iron_block@0"
            ]
        },
        {
            "x": -1,
            "y": 11,
            "z": -3,
            "elements": [
                "minecraft:iron_block@0"
            ]
        },
        {
            "x": 3,
            "y": 14,
            "z": 3,
            "elements": [
                "tconstruct:metal@0"
            ]
        },
        {
            "x": 3,
            "y": 11,
            "z": 6,
            "elements": [
                "tconstruct:metal@0"
            ]
        },
        {
            "x": 1,
            "y": 12,
            "z": 2,
            "elements": [
                "minecraft:iron_block@0"
            ]
        },
        {
            "x": 0,
            "y": 16,
            "z": 8,
            "elements": [
                "tconstruct:metal@0"
            ]
        },
        {
            "x": 0,
            "y": 14,
            "z": -4,
            "elements": [
                "minecraft:iron_block@0"
            ]
        },
        {
            "x": -3,
            "y": 3,
            "z": 11,
            "elements": [
                "tcomplement:scorched_block@8"
            ]
        },
        {
            "x": -1,
            "y": 0,
            "z": 0,
            "elements": [
                "tcomplement:scorched_block@6"
            ]
        },
        {
            "x": 0,
            "y": 14,
            "z": 8,
            "elements": [
                "minecraft:iron_block@0"
            ]
        },
        {
            "x": 1,
            "y": 15,
            "z": 2,
            "elements": [
                "tconstruct:metal@0"
            ]
        },
        {
            "x": 0,
            "y": 4,
            "z": 3,
            "elements": [
                "taiga:molten_nitronite_fluid@0"
            ]
        },
        {
            "x": -2,
            "y": 6,
            "z": 0,
            "elements": [
                "tcomplement:scorched_block@11"
            ]
        },
        {
            "x": 0,
            "y": 0,
            "z": 5,
            "elements": [
                "thermalfoundation:fluid_pyrotheum@0"
            ]
        },
        {
            "x": -3,
            "y": 15,
            "z": 4,
            "elements": [
                "tconstruct:metal@0"
            ]
        },
        {
            "x": 0,
            "y": 2,
            "z": 5,
            "elements": [
                "thermalfoundation:glass@5"
            ]
        },
        {
            "x": 1,
            "y": 4,
            "z": 0,
            "elements": [
                "taiga:molten_nitronite_fluid@0"
            ]
        },
        {
            "x": 0,
            "y": 17,
            "z": 6,
            "elements": [
                "tconstruct:metal@0"
            ]
        },
        {
            "x": -3,
            "y": 14,
            "z": 7,
            "elements": [
                "tconstruct:metal@0"
            ]
        },
        {
            "x": -3,
            "y": 4,
            "z": 5,
            "elements": [
                "tcomplement:scorched_block@11"
            ]
        },
        {
            "x": 1,
            "y": 14,
            "z": 2,
            "elements": [
                "minecraft:iron_block@0"
            ]
        },
        {
            "x": -2,
            "y": 13,
            "z": 9,
            "elements": [
                "minecraft:iron_block@0"
            ]
        },
        {
            "x": -3,
            "y": 12,
            "z": 7,
            "elements": [
                "tconstruct:metal@0"
            ]
        },
        {
            "x": -2,
            "y": 3,
            "z": 11,
            "elements": [
                "jaopca:block.hellite@0"
            ]
        },
        {
            "x": 3,
            "y": 5,
            "z": 4,
            "elements": [
                "tcomplement:scorched_block@11"
            ]
        },
        {
            "x": -3,
            "y": 12,
            "z": 0,
            "elements": [
                "minecraft:iron_block@0"
            ]
        },
        {
            "x": -3,
            "y": 15,
            "z": 7,
            "elements": [
                "tconstruct:metal@0"
            ]
        },
        {
            "x": -3,
            "y": 1,
            "z": 11,
            "elements": [
                "tcomplement:scorched_block@2"
            ]
        },
        {
            "x": -1,
            "y": 6,
            "z": 12,
            "elements": [
                "tconstruct:seared@10"
            ]
        },
        {
            "x": -3,
            "y": 11,
            "z": 6,
            "elements": [
                "tconstruct:metal@0"
            ]
        },
        {
            "x": -3,
            "y": -1,
            "z": 11,
            "elements": [
                "tcomplement:scorched_block@2"
            ]
        },
        {
            "x": -1,
            "y": 6,
            "z": 5,
            "elements": [
                "thermalfoundation:glass@5"
            ]
        },
        {
            "x": 2,
            "y": 1,
            "z": 12,
            "elements": [
                "tcomplement:scorched_block@2"
            ]
        },
        {
            "x": 0,
            "y": 4,
            "z": 5,
            "elements": [
                "taiga:molten_nitronite_fluid@0"
            ]
        },
        {
            "x": 0,
            "y": 9,
            "z": 7,
            "elements": [
                "tconstruct:metal@0"
            ]
        },
        {
            "x": -3,
            "y": 3,
            "z": 4,
            "elements": [
                "tcomplement:scorched_block@11"
            ]
        },
        {
            "x": 2,
            "y": 4,
            "z": 0,
            "elements": [
                "thermalfoundation:glass@5"
            ]
        },
        {
            "x": 0,
            "y": 1,
            "z": 4,
            "elements": [
                "tcomplement:scorched_block@11"
            ]
        },
        {
            "x": -3,
            "y": 10,
            "z": 6,
            "elements": [
                "tconstruct:metal@0"
            ]
        },
        {
            "x": 0,
            "y": 10,
            "z": -1,
            "elements": [
                "minecraft:iron_block@0"
            ]
        },
        {
            "x": 2,
            "y": 0,
            "z": 12,
            "elements": [
                "tcomplement:scorched_block@2"
            ]
        },
        {
            "x": -1,
            "y": -1,
            "z": 4,
            "elements": [
                "tcomplement:scorched_block@11"
            ]
        },
        {
            "x": -1,
            "y": 10,
            "z": 0,
            "elements": [
                "minecraft:iron_block@0"
            ]
        },
        {
            "x": 0,
            "y": -1,
            "z": 9,
            "elements": [
                "tcomplement:scorched_block@11"
            ]
        },
        {
            "x": -1,
            "y": 7,
            "z": 12,
            "elements": [
                "tconstruct:seared@10"
            ]
        },
        {
            "x": 3,
            "y": 3,
            "z": 7,
            "elements": [
                "tcomplement:scorched_block@11"
            ]
        },
        {
            "x": 3,
            "y": 4,
            "z": 7,
            "elements": [
                "tcomplement:scorched_block@11"
            ]
        },
        {
            "x": 0,
            "y": 6,
            "z": 7,
            "elements": [
                "thermalfoundation:glass@5"
            ]
        },
        {
            "x": -1,
            "y": 4,
            "z": 12,
            "elements": [
                "jaopca:block.hellite@0"
            ]
        },
        {
            "x": -2,
            "y": 3,
            "z": 9,
            "elements": [
                "thermalfoundation:glass@5"
            ]
        },
        {
            "x": 2,
            "y": 2,
            "z": 0,
            "elements": [
                "tcomplement:scorched_block@11"
            ]
        },
        {
            "x": 0,
            "y": 6,
            "z": 5,
            "elements": [
                "thermalfoundation:glass@5"
            ]
        },
        {
            "x": -3,
            "y": 5,
            "z": 4,
            "elements": [
                "tcomplement:scorched_block@11"
            ]
        },
        {
            "x": -1,
            "y": 4,
            "z": 5,
            "elements": [
                "taiga:molten_nitronite_fluid@0"
            ]
        },
        {
            "x": 2,
            "y": 2,
            "z": 5,
            "elements": [
                "tcomplement:scorched_block@11"
            ]
        },
        {
            "x": -1,
            "y": 5,
            "z": 12,
            "elements": [
                "jaopca:block.hellite@0"
            ]
        },
        {
            "x": 0,
            "y": 7,
            "z": 7,
            "elements": [
                "tcomplement:scorched_block@11"
            ]
        },
        {
            "x": 3,
            "y": 5,
            "z": 7,
            "elements": [
                "tcomplement:scorched_block@11"
            ]
        },
        {
            "x": 2,
            "y": 3,
            "z": 12,
            "elements": [
                "tcomplement:scorched_block@8"
            ]
        },
        {
            "x": 1,
            "y": 11,
            "z": 9,
            "elements": [
                "minecraft:iron_block@0"
            ]
        },
        {
            "x": 3,
            "y": 13,
            "z": 8,
            "elements": [
                "tconstruct:metal@0"
            ]
        },
        {
            "x": -3,
            "y": 10,
            "z": 5,
            "elements": [
                "tconstruct:metal@0"
            ]
        },
        {
            "x": 3,
            "y": 12,
            "z": 8,
            "elements": [
                "tconstruct:metal@0"
            ]
        },
        {
            "x": 2,
            "y": 2,
            "z": 12,
            "elements": [
                "tcomplement:scorched_block@2"
            ]
        },
        {
            "x": 3,
            "y": 14,
            "z": -1,
            "elements": [
                "minecraft:iron_block@0"
            ]
        },
        {
            "x": 1,
            "y": 3,
            "z": 9,
            "elements": [
                "taiga:molten_nitronite_fluid@0"
            ]
        },
        {
            "x": 3,
            "y": 14,
            "z": 8,
            "elements": [
                "tconstruct:metal@0"
            ]
        },
        {
            "x": -3,
            "y": 4,
            "z": 10,
            "elements": [
                "tcomplement:scorched_block@11"
            ]
        },
        {
            "x": 0,
            "y": 9,
            "z": 6,
            "elements": [
                "tconstruct:metal@0"
            ]
        },
        {
            "x": -1,
            "y": 0,
            "z": 5,
            "elements": [
                "casings_all"
            ]
        },
        {
            "x": -3,
            "y": 13,
            "z": -1,
            "elements": [
                "minecraft:iron_block@0"
            ]
        },
        {
            "x": 3,
            "y": 4,
            "z": 3,
            "elements": [
                "tcomplement:scorched_block@11"
            ]
        },
        {
            "x": -1,
            "y": 3,
            "z": 12,
            "elements": [
                "jaopca:block.hellite@0"
            ]
        },
        {
            "x": -2,
            "y": 5,
            "z": 9,
            "elements": [
                "thermalfoundation:glass@5"
            ]
        },
        {
            "x": 0,
            "y": 6,
            "z": -1,
            "elements": [
                "taiga:molten_nitronite_fluid@0"
            ]
        },
        {
            "x": 0,
            "y": 4,
            "z": 7,
            "elements": [
                "taiga:molten_nitronite_fluid@0"
            ]
        },
        {
            "x": -1,
            "y": 6,
            "z": 0,
            "elements": [
                "thermalfoundation:glass@5"
            ]
        },
        {
            "x": 0,
            "y": 0,
            "z": 10,
            "elements": [
                "casings_all"
            ]
        },
        {
            "x": -1,
            "y": 2,
            "z": 5,
            "elements": [
                "thermalfoundation:glass@5"
            ]
        },
        {
            "x": 0,
            "y": 4,
            "z": 10,
            "elements": [
                "taiga:molten_nitronite_fluid@0"
            ]
        },
        {
            "x": -3,
            "y": 15,
            "z": 6,
            "elements": [
                "tconstruct:metal@0"
            ]
        },
        {
            "x": 0,
            "y": 5,
            "z": 7,
            "elements": [
                "taiga:molten_nitronite_fluid@0"
            ]
        },
        {
            "x": 3,
            "y": 1,
            "z": -1,
            "elements": [
                "tcomplement:scorched_block@2"
            ]
        },
        {
            "x": 0,
            "y": 7,
            "z": -1,
            "elements": [
                "taiga:molten_nitronite_fluid@0"
            ]
        },
        {
            "x": 0,
            "y": 5,
            "z": 4,
            "elements": [
                "taiga:molten_nitronite_fluid@0"
            ]
        },
        {
            "x": -3,
            "y": 12,
            "z": -1,
            "elements": [
                "minecraft:iron_block@0"
            ]
        },
        {
            "x": 0,
            "y": 3,
            "z": 4,
            "elements": [
                "taiga:molten_nitronite_fluid@0"
            ]
        },
        {
            "x": 0,
            "y": 4,
            "z": -1,
            "elements": [
                "thermalfoundation:glass@5"
            ]
        },
        {
            "x": -3,
            "y": 16,
            "z": 6,
            "elements": [
                "tconstruct:metal@0"
            ]
        },
        {
            "x": 1,
            "y": 1,
            "z": 9,
            "elements": [
                "tcomplement:scorched_block@11"
            ]
        },
        {
            "x": 0,
            "y": 2,
            "z": 7,
            "elements": [
                "thermalfoundation:glass@5"
            ]
        },
        {
            "x": 3,
            "y": 2,
            "z": -1,
            "elements": [
                "tcomplement:scorched_block@2"
            ]
        },
        {
            "x": 0,
            "y": 7,
            "z": 6,
            "elements": [
                "tcomplement:scorched_block@11"
            ]
        },
        {
            "x": 3,
            "y": 5,
            "z": 6,
            "elements": [
                "tcomplement:scorched_block@11"
            ]
        },
        {
            "x": 0,
            "y": 6,
            "z": 6,
            "elements": [
                "thermalfoundation:glass@5"
            ]
        },
        {
            "x": 3,
            "y": 13,
            "z": -1,
            "elements": [
                "minecraft:iron_block@0"
            ]
        },
        {
            "x": 2,
            "y": 6,
            "z": 0,
            "elements": [
                "tcomplement:scorched_block@11"
            ]
        },
        {
            "x": 1,
            "y": 7,
            "z": 9,
            "elements": [
                "tcomplement:scorched_block@11"
            ]
        },
        {
            "x": 3,
            "y": 0,
            "z": -1,
            "elements": [
                "tcomplement:scorched_block@2"
            ]
        },
        {
            "x": -1,
            "y": 8,
            "z": 0,
            "elements": [
                "tconstruct:seared@10"
            ]
        },
        {
            "x": 3,
            "y": 3,
            "z": 6,
            "elements": [
                "tcomplement:scorched_block@11"
            ]
        },
        {
            "x": -3,
            "y": 14,
            "z": -1,
            "elements": [
                "minecraft:iron_block@0"
            ]
        },
        {
            "x": 0,
            "y": 2,
            "z": 10,
            "elements": [
                "thermalfoundation:glass@5"
            ]
        },
        {
            "x": 2,
            "y": 11,
            "z": -3,
            "elements": [
                "minecraft:iron_block@0"
            ]
        },
        {
            "x": 3,
            "y": 4,
            "z": 6,
            "elements": [
                "tcomplement:scorched_block@11"
            ]
        },
        {
            "x": 3,
            "y": 3,
            "z": -1,
            "elements": [
                "tcomplement:scorched_block@8"
            ]
        },
        {
            "x": 0,
            "y": 3,
            "z": 7,
            "elements": [
                "taiga:molten_nitronite_fluid@0"
            ]
        },
        {
            "x": 0,
            "y": 5,
            "z": -1,
            "elements": [
                "taiga:molten_nitronite_fluid@0"
            ]
        },
        {
            "x": 0,
            "y": 15,
            "z": 13,
            "elements": [
                "minecraft:iron_block@0"
            ]
        },
        {
            "x": 0,
            "y": 1,
            "z": 8,
            "elements": [
                "tcomplement:scorched_block@11"
            ]
        },
        {
            "x": -2,
            "y": 5,
            "z": 4,
            "elements": [
                "thermalfoundation:glass@5"
            ]
        },
        {
            "x": -2,
            "y": 6,
            "z": 3,
            "elements": [
                "tcomplement:scorched_block@11"
            ]
        },
        {
            "x": 1,
            "y": 4,
            "z": 3,
            "elements": [
                "taiga:molten_nitronite_fluid@0"
            ]
        },
        {
            "x": -3,
            "y": 3,
            "z": 8,
            "elements": [
                "tcomplement:scorched_block@11"
            ]
        },
        {
            "x": 0,
            "y": 8,
            "z": 10,
            "elements": [
                "tconstruct:seared@10"
            ]
        },
        {
            "x": -3,
            "y": 4,
            "z": 8,
            "elements": [
                "tcomplement:scorched_block@11"
            ]
        },
        {
            "x": 0,
            "y": 2,
            "z": 8,
            "elements": [
                "thermalfoundation:glass@5"
            ]
        },
        {
            "x": -2,
            "y": 3,
            "z": 4,
            "elements": [
                "thermalfoundation:glass@5"
            ]
        },
        {
            "x": 3,
            "y": 4,
            "z": 5,
            "elements": [
                "tcomplement:scorched_block@11"
            ]
        },
        {
            "x": 1,
            "y": 6,
            "z": 3,
            "elements": [
                "thermalfoundation:glass@5"
            ]
        },
        {
            "x": -3,
            "y": 13,
            "z": 11,
            "elements": [
                "minecraft:iron_block@0"
            ]
        },
        {
            "x": -1,
            "y": 1,
            "z": 4,
            "elements": [
                "tcomplement:scorched_block@11"
            ]
        },
        {
            "x": 0,
            "y": 11,
            "z": 13,
            "elements": [
                "minecraft:iron_block@0"
            ]
        },
        {
            "x": -3,
            "y": 14,
            "z": -2,
            "elements": [
                "minecraft:iron_block@0"
            ]
        },
        {
            "x": 0,
            "y": 3,
            "z": 8,
            "elements": [
                "taiga:molten_nitronite_fluid@0"
            ]
        },
        {
            "x": -3,
            "y": 12,
            "z": 10,
            "elements": [
                "minecraft:iron_block@0"
            ]
        },
        {
            "x": -2,
            "y": 4,
            "z": 3,
            "elements": [
                "thermalfoundation:glass@5"
            ]
        },
        {
            "x": 1,
            "y": 0,
            "z": 3,
            "elements": [
                "casings_upgrade"
            ]
        },
        {
            "x": 0,
            "y": 4,
            "z": 8,
            "elements": [
                "taiga:molten_nitronite_fluid@0"
            ]
        },
        {
            "x": 1,
            "y": 4,
            "z": 10,
            "elements": [
                "taiga:molten_nitronite_fluid@0"
            ]
        },
        {
            "x": 0,
            "y": 6,
            "z": 10,
            "elements": [
                "thermalfoundation:glass@5"
            ]
        },
        {
            "x": 0,
            "y": 11,
            "z": -3,
            "elements": [
                "minecraft:iron_block@0"
            ]
        },
        {
            "x": -3,
            "y": 13,
            "z": -2,
            "elements": [
                "minecraft:iron_block@0"
            ]
        },
        {
            "x": 2,
            "y": 11,
            "z": 12,
            "elements": [
                "minecraft:iron_block@0"
            ]
        },
        {
            "x": -3,
            "y": 14,
            "z": 10,
            "elements": [
                "minecraft:iron_block@0"
            ]
        },
        {
            "x": 0,
            "y": 12,
            "z": 14,
            "elements": [
                "minecraft:iron_block@0"
            ]
        },
        {
            "x": -3,
            "y": 3,
            "z": 9,
            "elements": [
                "tcomplement:scorched_block@11"
            ]
        },
        {
            "x": 2,
            "y": 4,
            "z": 5,
            "elements": [
                "thermalfoundation:glass@5"
            ]
        },
        {
            "x": -4,
            "y": 14,
            "z": 5,
            "elements": [
                "tconstruct:metal@0"
            ]
        },
        {
            "x": -2,
            "y": 10,
            "z": 3,
            "elements": [
                "tconstruct:metal@0"
            ]
        },
        {
            "x": 1,
            "y": 6,
            "z": 10,
            "elements": [
                "thermalfoundation:glass@5"
            ]
        },
        {
            "x": 1,
            "y": 2,
            "z": 10,
            "elements": [
                "thermalfoundation:glass@5"
            ]
        },
        {
            "x": 3,
            "y": 14,
            "z": -2,
            "elements": [
                "minecraft:iron_block@0"
            ]
        },
        {
            "x": 2,
            "y": 6,
            "z": 5,
            "elements": [
                "tcomplement:scorched_block@11"
            ]
        },
        {
            "x": -1,
            "y": -1,
            "z": 8,
            "elements": [
                "tcomplement:scorched_block@11"
            ]
        },
        {
            "x": 0,
            "y": 14,
            "z": 14,
            "elements": [
                "minecraft:iron_block@0"
            ]
        },
        {
            "x": 0,
            "y": 10,
            "z": 10,
            "elements": [
                "minecraft:iron_block@0"
            ]
        },
        {
            "x": -1,
            "y": 8,
            "z": 12,
            "elements": [
                "tconstruct:seared@10"
            ]
        },
        {
            "x": -3,
            "y": 5,
            "z": 8,
            "elements": [
                "tcomplement:scorched_block@11"
            ]
        },
        {
            "x": 1,
            "y": 2,
            "z": 3,
            "elements": [
                "thermalfoundation:glass@5"
            ]
        },
        {
            "x": 0,
            "y": 13,
            "z": 14,
            "elements": [
                "minecraft:iron_block@0"
            ]
        },
        {
            "x": 1,
            "y": 0,
            "z": 10,
            "elements": [
                "tcomplement:scorched_block@6"
            ]
        },
        {
            "x": 3,
            "y": 13,
            "z": -2,
            "elements": [
                "minecraft:iron_block@0"
            ]
        },
        {
            "x": 0,
            "y": 0,
            "z": 8,
            "elements": [
                "thermalfoundation:fluid_pyrotheum@0"
            ]
        },
        {
            "x": -1,
            "y": 10,
            "z": 12,
            "elements": [
                "minecraft:iron_block@0"
            ]
        },
        {
            "x": -4,
            "y": 12,
            "z": 5,
            "elements": [
                "tconstruct:metal@0"
            ]
        },
        {
            "x": 1,
            "y": 8,
            "z": 10,
            "elements": [
                "tconstruct:seared@10"
            ]
        },
        {
            "x": -1,
            "y": 9,
            "z": 12,
            "elements": [
                "tconstruct:seared@10"
            ]
        },
        {
            "x": -2,
            "y": 6,
            "z": 10,
            "elements": [
                "tcomplement:scorched_block@11"
            ]
        },
        {
            "x": -1,
            "y": 3,
            "z": 9,
            "elements": [
                "taiga:molten_nitronite_fluid@0"
            ]
        },
        {
            "x": -3,
            "y": 14,
            "z": 8,
            "elements": [
                "tconstruct:metal@0"
            ]
        },
        {
            "x": 3,
            "y": 13,
            "z": 12,
            "elements": [
                "minecraft:iron_block@0"
            ]
        },
        {
            "x": 3,
            "y": 12,
            "z": -2,
            "elements": [
                "minecraft:iron_block@0"
            ]
        },
        {
            "x": -3,
            "y": 4,
            "z": 3,
            "elements": [
                "tcomplement:scorched_block@11"
            ]
        },
        {
            "x": 0,
            "y": 12,
            "z": 8,
            "elements": [
                "minecraft:iron_block@0"
            ]
        },
        {
            "x": 1,
            "y": 6,
            "z": 0,
            "elements": [
                "thermalfoundation:glass@5"
            ]
        },
        {
            "x": -1,
            "y": 7,
            "z": 4,
            "elements": [
                "tcomplement:scorched_block@11"
            ]
        },
        {
            "x": 0,
            "y": 13,
            "z": 8,
            "elements": [
                "minecraft:iron_block@0"
            ]
        },
        {
            "x": 0,
            "y": 0,
            "z": 3,
            "elements": [
                "thermalfoundation:fluid_pyrotheum@0"
            ]
        },
        {
            "x": 3,
            "y": 3,
            "z": 11,
            "elements": [
                "tcomplement:scorched_block@8"
            ]
        },
        {
            "x": 2,
            "y": 15,
            "z": 12,
            "elements": [
                "minecraft:iron_block@0"
            ]
        },
        {
            "x": 2,
            "y": 5,
            "z": 4,
            "elements": [
                "thermalfoundation:glass@5"
            ]
        },
        {
            "x": 3,
            "y": 12,
            "z": 12,
            "elements": [
                "minecraft:iron_block@0"
            ]
        },
        {
            "x": 0,
            "y": 16,
            "z": -2,
            "elements": [
                "minecraft:iron_block@0"
            ]
        },
        {
            "x": -2,
            "y": 4,
            "z": 10,
            "elements": [
                "thermalfoundation:glass@5"
            ]
        },
        {
            "x": -3,
            "y": 5,
            "z": 9,
            "elements": [
                "tcomplement:scorched_block@11"
            ]
        },
        {
            "x": -4,
            "y": 13,
            "z": 4,
            "elements": [
                "tconstruct:metal@0"
            ]
        },
        {
            "x": 0,
            "y": 16,
            "z": 12,
            "elements": [
                "minecraft:iron_block@0"
            ]
        },
        {
            "x": 2,
            "y": 3,
            "z": 4,
            "elements": [
                "thermalfoundation:glass@5"
            ]
        },
        {
            "x": 3,
            "y": 14,
            "z": 12,
            "elements": [
                "minecraft:iron_block@0"
            ]
        },
        {
            "x": 3,
            "y": 14,
            "z": 7,
            "elements": [
                "tconstruct:metal@0"
            ]
        },
        {
            "x": 0,
            "y": 2,
            "z": 3,
            "elements": [
                "thermalfoundation:glass@5"
            ]
        },
        {
            "x": 0,
            "y": 10,
            "z": 8,
            "elements": [
                "tconstruct:metal@0"
            ]
        },
        {
            "x": 3,
            "y": 5,
            "z": 8,
            "elements": [
                "tcomplement:scorched_block@11"
            ]
        },
        {
            "x": 3,
            "y": 15,
            "z": 7,
            "elements": [
                "tconstruct:metal@0"
            ]
        },
        {
            "x": 1,
            "y": 8,
            "z": 0,
            "elements": [
                "tconstruct:seared@10"
            ]
        },
        {
            "x": -1,
            "y": 1,
            "z": 9,
            "elements": [
                "tcomplement:scorched_block@11"
            ]
        },
        {
            "x": 0,
            "y": 3,
            "z": 11,
            "elements": [
                "thermalfoundation:glass@5"
            ]
        },
        {
            "x": 3,
            "y": -1,
            "z": 11,
            "elements": [
                "tcomplement:scorched_block@2"
            ]
        },
        {
            "x": -2,
            "y": 2,
            "z": 10,
            "elements": [
                "tcomplement:scorched_block@11"
            ]
        },
        {
            "x": -1,
            "y": 9,
            "z": 4,
            "elements": [
                "tconstruct:metal@0"
            ]
        },
        {
            "x": 3,
            "y": 1,
            "z": 11,
            "elements": [
                "tcomplement:scorched_block@2"
            ]
        },
        {
            "x": -1,
            "y": 3,
            "z": 4,
            "elements": [
                "taiga:molten_nitronite_fluid@0"
            ]
        },
        {
            "x": -1,
            "y": 16,
            "z": 12,
            "elements": [
                "minecraft:iron_block@0"
            ]
        },
        {
            "x": 2,
            "y": 15,
            "z": 13,
            "elements": [
                "minecraft:iron_block@0"
            ]
        },
        {
            "x": 0,
            "y": 6,
            "z": 8,
            "elements": [
                "thermalfoundation:glass@5"
            ]
        },
        {
            "x": 3,
            "y": 4,
            "z": 8,
            "elements": [
                "tcomplement:scorched_block@11"
            ]
        },
        {
            "x": 0,
            "y": 9,
            "z": -2,
            "elements": [
                "tconstruct:seared@10"
            ]
        },
        {
            "x": 0,
            "y": -1,
            "z": 4,
            "elements": [
                "tcomplement:scorched_block@11"
            ]
        },
        {
            "x": 3,
            "y": 3,
            "z": 8,
            "elements": [
                "tcomplement:scorched_block@11"
            ]
        },
        {
            "x": 0,
            "y": 8,
            "z": -2,
            "elements": [
                "tconstruct:seared@10"
            ]
        },
        {
            "x": 1,
            "y": 16,
            "z": 0,
            "elements": [
                "minecraft:iron_block@0"
            ]
        },
        {
            "x": -1,
            "y": 2,
            "z": 3,
            "elements": [
                "thermalfoundation:glass@5"
            ]
        },
        {
            "x": -1,
            "y": 12,
            "z": -4,
            "elements": [
                "minecraft:iron_block@0"
            ]
        },
        {
            "x": 2,
            "y": 14,
            "z": 13,
            "elements": [
                "minecraft:iron_block@0"
            ]
        },
        {
            "x": 0,
            "y": 10,
            "z": -2,
            "elements": [
                "minecraft:iron_block@0"
            ]
        },
        {
            "x": 2,
            "y": 13,
            "z": 13,
            "elements": [
                "minecraft:iron_block@0"
            ]
        },
        {
            "x": 0,
            "y": 5,
            "z": 8,
            "elements": [
                "taiga:molten_nitronite_fluid@0"
            ]
        },
        {
            "x": 0,
            "y": 5,
            "z": 11,
            "elements": [
                "taiga:molten_nitronite_fluid@0"
            ]
        },
        {
            "x": 1,
            "y": 3,
            "z": 11,
            "elements": [
                "thermalfoundation:glass@5"
            ]
        },
        {
            "x": 3,
            "y": 16,
            "z": 6,
            "elements": [
                "tconstruct:metal@0"
            ]
        },
        {
            "x": 1,
            "y": 10,
            "z": 0,
            "elements": [
                "minecraft:iron_block@0"
            ]
        },
        {
            "x": 2,
            "y": 12,
            "z": 13,
            "elements": [
                "minecraft:iron_block@0"
            ]
        },
        {
            "x": -1,
            "y": 5,
            "z": 4,
            "elements": [
                "taiga:molten_nitronite_fluid@0"
            ]
        },
        {
            "x": 1,
            "y": -1,
            "z": 4,
            "elements": [
                "tcomplement:scorched_block@11"
            ]
        },
        {
            "x": 2,
            "y": 11,
            "z": 13,
            "elements": [
                "minecraft:iron_block@0"
            ]
        },
        {
            "x": 3,
            "y": 15,
            "z": 6,
            "elements": [
                "tconstruct:metal@0"
            ]
        },
        {
            "x": 1,
            "y": 1,
            "z": 4,
            "elements": [
                "tcomplement:scorched_block@11"
            ]
        },
        {
            "x": 0,
            "y": 7,
            "z": 11,
            "elements": [
                "taiga:molten_nitronite_fluid@0"
            ]
        },
        {
            "x": -2,
            "y": 2,
            "z": 3,
            "elements": [
                "tcomplement:scorched_block@11"
            ]
        },
        {
            "x": -1,
            "y": 0,
            "z": 3,
            "elements": [
                "casings_parallel"
            ]
        },
        {
            "x": -3,
            "y": 12,
            "z": 8,
            "elements": [
                "tconstruct:metal@0"
            ]
        },
        {
            "x": 1,
            "y": 3,
            "z": 4,
            "elements": [
                "taiga:molten_nitronite_fluid@0"
            ]
        },
        {
            "x": -3,
            "y": 13,
            "z": 8,
            "elements": [
                "tconstruct:metal@0"
            ]
        },
        {
            "x": 0,
            "y": 7,
            "z": 8,
            "elements": [
                "tcomplement:scorched_block@11"
            ]
        },
        {
            "x": 1,
            "y": -1,
            "z": 9,
            "elements": [
                "tcomplement:scorched_block@11"
            ]
        },
        {
            "x": 2,
            "y": 2,
            "z": 6,
            "elements": [
                "tcomplement:scorched_block@11"
            ]
        },
        {
            "x": 1,
            "y": 6,
            "z": 11,
            "elements": [
                "jaopca:block.hellite@0"
            ]
        },
        {
            "x": 1,
            "y": 6,
            "z": -2,
            "elements": [
                "tconstruct:seared@10"
            ]
        },
        {
            "x": 3,
            "y": 3,
            "z": 2,
            "elements": [
                "tcomplement:scorched_block@11"
            ]
        },
        {
            "x": 1,
            "y": -1,
            "z": 7,
            "elements": [
                "tcomplement:scorched_block@11"
            ]
        },
        {
            "x": 1,
            "y": 9,
            "z": -1,
            "elements": [
                "tconstruct:seared@10"
            ]
        },
        {
            "x": 0,
            "y": 5,
            "z": 2,
            "elements": [
                "taiga:molten_nitronite_fluid@0"
            ]
        },
        {
            "x": 3,
            "y": 14,
            "z": 10,
            "elements": [
                "minecraft:iron_block@0"
            ]
        },
        {
            "x": -3,
            "y": 3,
            "z": 12,
            "elements": [
                "tcomplement:scorched_block@6"
            ]
        },
        {
            "x": -2,
            "y": 12,
            "z": 1,
            "elements": [
                "minecraft:iron_block@0"
            ]
        },
        {
            "x": -4,
            "y": 12,
            "z": 6,
            "elements": [
                "tconstruct:metal@0"
            ]
        },
        {
            "x": 1,
            "y": 7,
            "z": 11,
            "elements": [
                "tconstruct:seared@10"
            ]
        },
        {
            "x": 3,
            "y": 3,
            "z": 9,
            "elements": [
                "tcomplement:scorched_block@11"
            ]
        },
        {
            "x": 0,
            "y": 5,
            "z": 9,
            "elements": [
                "taiga:molten_nitronite_fluid@0"
            ]
        },
        {
            "x": 1,
            "y": 14,
            "z": 1,
            "elements": [
                "tconstruct:metal@0"
            ]
        },
        {
            "x": 0,
            "y": 7,
            "z": 9,
            "elements": [
                "tcomplement:scorched_block@11"
            ]
        },
        {
            "x": 1,
            "y": 4,
            "z": 4,
            "elements": [
                "taiga:molten_nitronite_fluid@0"
            ]
        },
        {
            "x": 3,
            "y": 13,
            "z": 10,
            "elements": [
                "minecraft:iron_block@0"
            ]
        },
        {
            "x": 3,
            "y": 0,
            "z": -2,
            "elements": [
                "tcomplement:scorched_block@2"
            ]
        },
        {
            "x": -2,
            "y": 11,
            "z": 2,
            "elements": [
                "tconstruct:metal@0"
            ]
        },
        {
            "x": 0,
            "y": 6,
            "z": 9,
            "elements": [
                "thermalfoundation:glass@5"
            ]
        },
        {
            "x": -1,
            "y": 6,
            "z": 6,
            "elements": [
                "thermalfoundation:glass@5"
            ]
        },
        {
            "x": -1,
            "y": 3,
            "z": 7,
            "elements": [
                "taiga:molten_nitronite_fluid@0"
            ]
        },
        {
            "x": 1,
            "y": 4,
            "z": -2,
            "elements": [
                "jaopca:block.hellite@0"
            ]
        },
        {
            "x": 3,
            "y": 4,
            "z": 9,
            "elements": [
                "tcomplement:scorched_block@11"
            ]
        },
        {
            "x": 0,
            "y": 7,
            "z": 2,
            "elements": [
                "tcomplement:scorched_block@11"
            ]
        },
        {
            "x": 0,
            "y": 6,
            "z": -2,
            "elements": [
                "tconstruct:seared@10"
            ]
        },
        {
            "x": -1,
            "y": 6,
            "z": 8,
            "elements": [
                "thermalfoundation:glass@5"
            ]
        },
        {
            "x": -3,
            "y": 1,
            "z": 12,
            "elements": [
                "tcomplement:scorched_block@2"
            ]
        },
        {
            "x": 1,
            "y": 4,
            "z": 11,
            "elements": [
                "thermalfoundation:glass@5"
            ]
        },
        {
            "x": 1,
            "y": 12,
            "z": 1,
            "elements": [
                "tconstruct:metal@0"
            ]
        },
        {
            "x": 1,
            "y": 6,
            "z": 4,
            "elements": [
                "thermalfoundation:glass@5"
            ]
        },
        {
            "x": -2,
            "y": 14,
            "z": 1,
            "elements": [
                "minecraft:iron_block@0"
            ]
        },
        {
            "x": 4,
            "y": 15,
            "z": 5,
            "elements": [
                "tconstruct:metal@0"
            ]
        },
        {
            "x": 1,
            "y": 5,
            "z": 11,
            "elements": [
                "thermalfoundation:glass@5"
            ]
        },
        {
            "x": -1,
            "y": 5,
            "z": 7,
            "elements": [
                "taiga:molten_nitronite_fluid@0"
            ]
        },
        {
            "x": -2,
            "y": 15,
            "z": -1,
            "elements": [
                "minecraft:iron_block@0"
            ]
        },
        {
            "x": 1,
            "y": 5,
            "z": 4,
            "elements": [
                "taiga:molten_nitronite_fluid@0"
            ]
        },
        {
            "x": 3,
            "y": 2,
            "z": -2,
            "elements": [
                "tcomplement:scorched_block@2"
            ]
        },
        {
            "x": 2,
            "y": 5,
            "z": -1,
            "elements": [
                "jaopca:block.hellite@0"
            ]
        },
        {
            "x": 2,
            "y": 6,
            "z": 6,
            "elements": [
                "tcomplement:scorched_block@11"
            ]
        },
        {
            "x": -2,
            "y": 15,
            "z": 2,
            "elements": [
                "tconstruct:metal@0"
            ]
        },
        {
            "x": -1,
            "y": 1,
            "z": 7,
            "elements": [
                "tcomplement:scorched_block@11"
            ]
        },
        {
            "x": -1,
            "y": 4,
            "z": 6,
            "elements": [
                "taiga:molten_nitronite_fluid@0"
            ]
        },
        {
            "x": 0,
            "y": 12,
            "z": 1,
            "elements": [
                "tconstruct:metal@0"
            ]
        },
        {
            "x": -3,
            "y": 3,
            "z": 2,
            "elements": [
                "tcomplement:scorched_block@11"
            ]
        },
        {
            "x": 4,
            "y": 14,
            "z": 5,
            "elements": [
                "tconstruct:metal@0"
            ]
        },
        {
            "x": 0,
            "y": 1,
            "z": 2,
            "elements": [
                "tcomplement:scorched_block@11"
            ]
        },
        {
            "x": -3,
            "y": 0,
            "z": -2,
            "elements": [
                "tcomplement:scorched_block@2"
            ]
        },
        {
            "x": 2,
            "y": 11,
            "z": -1,
            "elements": [
                "minecraft:iron_block@0"
            ]
        },
        {
            "x": -2,
            "y": 2,
            "z": 8,
            "elements": [
                "tcomplement:scorched_block@11"
            ]
        },
        {
            "x": 3,
            "y": 3,
            "z": 12,
            "elements": [
                "tcomplement:scorched_block@6"
            ]
        },
        {
            "x": 1,
            "y": 7,
            "z": 4,
            "elements": [
                "tcomplement:scorched_block@11"
            ]
        },
        {
            "x": 1,
            "y": 10,
            "z": 11,
            "elements": [
                "minecraft:iron_block@0"
            ]
        },
        {
            "x": 1,
            "y": 0,
            "z": 8,
            "elements": [
                "tcomplement:scorched_block@8"
            ]
        },
        {
            "x": 0,
            "y": 2,
            "z": 9,
            "elements": [
                "thermalfoundation:glass@5"
            ]
        },
        {
            "x": -1,
            "y": 4,
            "z": 8,
            "elements": [
                "taiga:molten_nitronite_fluid@0"
            ]
        },
        {
            "x": 0,
            "y": 1,
            "z": 9,
            "elements": [
                "tcomplement:scorched_block@11"
            ]
        },
        {
            "x": 4,
            "y": 13,
            "z": 5,
            "elements": [
                "tconstruct:metal@0"
            ]
        },
        {
            "x": -2,
            "y": 15,
            "z": 11,
            "elements": [
                "minecraft:iron_block@0"
            ]
        },
        {
            "x": 0,
            "y": 3,
            "z": 9,
            "elements": [
                "taiga:molten_nitronite_fluid@0"
            ]
        },
        {
            "x": 3,
            "y": 12,
            "z": 10,
            "elements": [
                "minecraft:iron_block@0"
            ]
        },
        {
            "x": 4,
            "y": 11,
            "z": 5,
            "elements": [
                "tconstruct:metal@0"
            ]
        },
        {
            "x": 0,
            "y": 3,
            "z": 2,
            "elements": [
                "taiga:molten_nitronite_fluid@0"
            ]
        },
        {
            "x": 1,
            "y": 9,
            "z": 11,
            "elements": [
                "tconstruct:seared@10"
            ]
        },
        {
            "x": 0,
            "y": 3,
            "z": 12,
            "elements": [
                "jaopca:block.hellite@0"
            ]
        },
        {
            "x": 1,
            "y": 8,
            "z": -2,
            "elements": [
                "tconstruct:seared@10"
            ]
        },
        {
            "x": 2,
            "y": 10,
            "z": 6,
            "elements": [
                "tconstruct:metal@0"
            ]
        },
        {
            "x": 4,
            "y": 12,
            "z": 5,
            "elements": [
                "tconstruct:metal@0"
            ]
        },
        {
            "x": -1,
            "y": 2,
            "z": 6,
            "elements": [
                "thermalfoundation:glass@5"
            ]
        },
        {
            "x": 3,
            "y": 1,
            "z": 12,
            "elements": [
                "tcomplement:scorched_block@2"
            ]
        },
        {
            "x": 0,
            "y": 14,
            "z": 1,
            "elements": [
                "tconstruct:metal@0"
            ]
        },
        {
            "x": 1,
            "y": 10,
            "z": -2,
            "elements": [
                "minecraft:iron_block@0"
            ]
        },
        {
            "x": -3,
            "y": 2,
            "z": -2,
            "elements": [
                "tcomplement:scorched_block@2"
            ]
        },
        {
            "x": 1,
            "y": 16,
            "z": 3,
            "elements": [
                "tconstruct:metal@0"
            ]
        },
        {
            "x": 1,
            "y": 9,
            "z": 4,
            "elements": [
                "tconstruct:metal@0"
            ]
        },
        {
            "x": 1,
            "y": 8,
            "z": 11,
            "elements": [
                "tconstruct:seared@10"
            ]
        },
        {
            "x": -2,
            "y": 4,
            "z": 8,
            "elements": [
                "thermalfoundation:glass@5"
            ]
        },
        {
            "x": 0,
            "y": 16,
            "z": 10,
            "elements": [
                "minecraft:iron_block@0"
            ]
        },
        {
            "x": 0,
            "y": 4,
            "z": 9,
            "elements": [
                "taiga:molten_nitronite_fluid@0"
            ]
        },
        {
            "x": -1,
            "y": 2,
            "z": 8,
            "elements": [
                "thermalfoundation:glass@5"
            ]
        },
        {
            "x": 1,
            "y": 9,
            "z": 10,
            "elements": [
                "tconstruct:seared@10"
            ]
        },
        {
            "x": -1,
            "y": 3,
            "z": 2,
            "elements": [
                "taiga:molten_nitronite_fluid@0"
            ]
        },
        {
            "x": 2,
            "y": -1,
            "z": 12,
            "elements": [
                "tcomplement:scorched_block@2"
            ]
        },
        {
            "x": 1,
            "y": 10,
            "z": 10,
            "elements": [
                "minecraft:iron_block@0"
            ]
        },
        {
            "x": 3,
            "y": 5,
            "z": 10,
            "elements": [
                "tcomplement:scorched_block@11"
            ]
        },
        {
            "x": 1,
            "y": 7,
            "z": 7,
            "elements": [
                "tcomplement:scorched_block@11"
            ]
        },
        {
            "x": 1,
            "y": 0,
            "z": 1,
            "elements": [
                "tcomplement:scorched_block@8"
            ]
        },
        {
            "x": 0,
            "y": 5,
            "z": 12,
            "elements": [
                "jaopca:block.hellite@0"
            ]
        },
        {
            "x": -2,
            "y": 6,
            "z": 1,
            "elements": [
                "tcomplement:scorched_block@11"
            ]
        },
        {
            "x": 0,
            "y": -1,
            "z": 2,
            "elements": [
                "tcomplement:scorched_block@11"
            ]
        },
        {
            "x": -1,
            "y": 0,
            "z": 8,
            "elements": [
                "tcomplement:scorched_block@8"
            ]
        },
        {
            "x": -2,
            "y": 16,
            "z": 3,
            "elements": [
                "tconstruct:metal@0"
            ]
        },
        {
            "x": 2,
            "y": 5,
            "z": 7,
            "elements": [
                "thermalfoundation:glass@5"
            ]
        },
        {
            "x": -1,
            "y": 13,
            "z": 14,
            "elements": [
                "minecraft:iron_block@0"
            ]
        },
        {
            "x": -2,
            "y": 16,
            "z": 4,
            "elements": [
                "tconstruct:metal@0"
            ]
        },
        {
            "x": 4,
            "y": 12,
            "z": 4,
            "elements": [
                "tconstruct:metal@0"
            ]
        },
        {
            "x": -3,
            "y": 5,
            "z": 2,
            "elements": [
                "tcomplement:scorched_block@11"
            ]
        },
        {
            "x": 0,
            "y": 0,
            "z": 9,
            "elements": [
                "thermalfoundation:fluid_pyrotheum@0"
            ]
        },
        {
            "x": -2,
            "y": 3,
            "z": 2,
            "elements": [
                "thermalfoundation:glass@5"
            ]
        },
        {
            "x": 1,
            "y": 2,
            "z": 1,
            "elements": [
                "thermalfoundation:glass@5"
            ]
        },
        {
            "x": 4,
            "y": 13,
            "z": 4,
            "elements": [
                "tconstruct:metal@0"
            ]
        },
        {
            "x": -1,
            "y": 1,
            "z": 2,
            "elements": [
                "tcomplement:scorched_block@11"
            ]
        },
        {
            "x": -1,
            "y": -1,
            "z": 2,
            "elements": [
                "tcomplement:scorched_block@11"
            ]
        },
        {
            "x": 1,
            "y": 17,
            "z": 5,
            "elements": [
                "tconstruct:metal@0"
            ]
        },
        {
            "x": -2,
            "y": 4,
            "z": 1,
            "elements": [
                "thermalfoundation:glass@5"
            ]
        },
        {
            "x": 4,
            "y": 14,
            "z": 4,
            "elements": [
                "tconstruct:metal@0"
            ]
        },
        {
            "x": 0,
            "y": 7,
            "z": 12,
            "elements": [
                "tconstruct:seared@10"
            ]
        },
        {
            "x": -1,
            "y": -1,
            "z": 9,
            "elements": [
                "tcomplement:scorched_block@11"
            ]
        },
        {
            "x": 2,
            "y": 3,
            "z": 7,
            "elements": [
                "thermalfoundation:glass@5"
            ]
        },
        {
            "x": -4,
            "y": 13,
            "z": 7,
            "elements": [
                "tconstruct:metal@0"
            ]
        },
        {
            "x": 1,
            "y": 16,
            "z": 11,
            "elements": [
                "minecraft:iron_block@0"
            ]
        },
        {
            "x": 1,
            "y": 3,
            "z": 2,
            "elements": [
                "taiga:molten_nitronite_fluid@0"
            ]
        },
        {
            "x": -2,
            "y": 5,
            "z": 2,
            "elements": [
                "thermalfoundation:glass@5"
            ]
        },
        {
            "x": -2,
            "y": 10,
            "z": 4,
            "elements": [
                "tconstruct:metal@0"
            ]
        },
        {
            "x": -3,
            "y": 12,
            "z": -2,
            "elements": [
                "minecraft:iron_block@0"
            ]
        },
        {
            "x": 1,
            "y": 7,
            "z": 3,
            "elements": [
                "tcomplement:scorched_block@11"
            ]
        },
        {
            "x": -3,
            "y": 13,
            "z": 12,
            "elements": [
                "minecraft:iron_block@0"
            ]
        },
        {
            "x": -1,
            "y": 7,
            "z": 7,
            "elements": [
                "tcomplement:scorched_block@11"
            ]
        },
        {
            "x": 1,
            "y": 4,
            "z": 1,
            "elements": [
                "taiga:molten_nitronite_fluid@0"
            ]
        },
        {
            "x": -2,
            "y": 15,
            "z": 10,
            "elements": [
                "minecraft:iron_block@0"
            ]
        },
        {
            "x": -2,
            "y": 2,
            "z": -2,
            "elements": [
                "tcomplement:scorched_block@2"
            ]
        },
        {
            "x": 1,
            "y": 17,
            "z": 4,
            "elements": [
                "tconstruct:metal@0"
            ]
        },
        {
            "x": 0,
            "y": 9,
            "z": 12,
            "elements": [
                "tconstruct:seared@10"
            ]
        },
        {
            "x": 2,
            "y": 4,
            "z": 6,
            "elements": [
                "thermalfoundation:glass@5"
            ]
        },
        {
            "x": 2,
            "y": 3,
            "z": -1,
            "elements": [
                "jaopca:block.hellite@0"
            ]
        },
        {
            "x": 1,
            "y": 16,
            "z": 10,
            "elements": [
                "minecraft:iron_block@0"
            ]
        },
        {
            "x": 1,
            "y": 1,
            "z": 2,
            "elements": [
                "tcomplement:scorched_block@11"
            ]
        },
        {
            "x": 0,
            "y": 15,
            "z": -3,
            "elements": [
                "minecraft:iron_block@0"
            ]
        },
        {
            "x": -4,
            "y": 14,
            "z": 6,
            "elements": [
                "tconstruct:metal@0"
            ]
        },
        {
            "x": 1,
            "y": -1,
            "z": 2,
            "elements": [
                "tcomplement:scorched_block@11"
            ]
        },
        {
            "x": -2,
            "y": 0,
            "z": -2,
            "elements": [
                "tcomplement:scorched_block@2"
            ]
        },
        {
            "x": 3,
            "y": 3,
            "z": 10,
            "elements": [
                "tcomplement:scorched_block@11"
            ]
        },
        {
            "x": 1,
            "y": 10,
            "z": 3,
            "elements": [
                "tconstruct:metal@0"
            ]
        },
        {
            "x": 3,
            "y": 4,
            "z": 10,
            "elements": [
                "tcomplement:scorched_block@11"
            ]
        },
        {
            "x": 0,
            "y": 4,
            "z": -2,
            "elements": [
                "jaopca:block.hellite@0"
            ]
        },
        {
            "x": 1,
            "y": 6,
            "z": 1,
            "elements": [
                "thermalfoundation:glass@5"
            ]
        },
        {
            "x": 3,
            "y": 13,
            "z": 2,
            "elements": [
                "tconstruct:metal@0"
            ]
        },
        {
            "x": -3,
            "y": 4,
            "z": 6,
            "elements": [
                "tcomplement:scorched_block@11"
            ]
        },
        {
            "x": -2,
            "y": 1,
            "z": 12,
            "elements": [
                "tcomplement:scorched_block@2"
            ]
        },
        {
            "x": 1,
            "y": 1,
            "z": 7,
            "elements": [
                "tcomplement:scorched_block@11"
            ]
        },
        {
            "x": -3,
            "y": 3,
            "z": -1,
            "elements": [
                "tcomplement:scorched_block@8"
            ]
        },
        {
            "x": 1,
            "y": 14,
            "z": 8,
            "elements": [
                "minecraft:iron_block@0"
            ]
        },
        {
            "x": -1,
            "y": 16,
            "z": 0,
            "elements": [
                "minecraft:iron_block@0"
            ]
        },
        {
            "x": 0,
            "y": 2,
            "z": 1,
            "elements": [
                "thermalfoundation:glass@5"
            ]
        },
        {
            "x": -1,
            "y": 5,
            "z": -1,
            "elements": [
                "thermalfoundation:glass@5"
            ]
        },
        {
            "x": -1,
            "y": 4,
            "z": 1,
            "elements": [
                "taiga:molten_nitronite_fluid@0"
            ]
        },
        {
            "x": -2,
            "y": 5,
            "z": 7,
            "elements": [
                "thermalfoundation:glass@5"
            ]
        },
        {
            "x": 0,
            "y": 3,
            "z": -1,
            "elements": [
                "thermalfoundation:glass@5"
            ]
        },
        {
            "x": 0,
            "y": -1,
            "z": 7,
            "elements": [
                "tcomplement:scorched_block@11"
            ]
        },
        {
            "x": -2,
            "y": 14,
            "z": 8,
            "elements": [
                "tconstruct:metal@0"
            ]
        },
        {
            "x": -3,
            "y": 1,
            "z": -1,
            "elements": [
                "tcomplement:scorched_block@2"
            ]
        },
        {
            "x": -1,
            "y": 8,
            "z": -2,
            "elements": [
                "tconstruct:seared@10"
            ]
        },
        {
            "x": 1,
            "y": 9,
            "z": 5,
            "elements": [
                "tconstruct:metal@0"
            ]
        },
        {
            "x": 0,
            "y": 0,
            "z": 6,
            "elements": [
                "thermalfoundation:fluid_pyrotheum@0"
            ]
        },
        {
            "x": 0,
            "y": 0,
            "z": 1,
            "elements": [
                "thermalfoundation:fluid_pyrotheum@0"
            ]
        },
        {
            "x": -2,
            "y": 3,
            "z": 12,
            "elements": [
                "tcomplement:scorched_block@8"
            ]
        },
        {
            "x": -1,
            "y": 10,
            "z": -2,
            "elements": [
                "minecraft:iron_block@0"
            ]
        },
        {
            "x": 2,
            "y": 11,
            "z": 0,
            "elements": [
                "minecraft:iron_block@0"
            ]
        },
        {
            "x": 1,
            "y": 7,
            "z": 5,
            "elements": [
                "tcomplement:scorched_block@11"
            ]
        },
        {
            "x": 1,
            "y": 16,
            "z": 8,
            "elements": [
                "tconstruct:metal@0"
            ]
        },
        {
            "x": -1,
            "y": 7,
            "z": -1,
            "elements": [
                "tconstruct:seared@10"
            ]
        },
        {
            "x": -2,
            "y": 3,
            "z": 7,
            "elements": [
                "thermalfoundation:glass@5"
            ]
        },
        {
            "x": -1,
            "y": 6,
            "z": 1,
            "elements": [
                "thermalfoundation:glass@5"
            ]
        },
        {
            "x": 0,
            "y": 2,
            "z": 6,
            "elements": [
                "thermalfoundation:glass@5"
            ]
        },
        {
            "x": -1,
            "y": 0,
            "z": 1,
            "elements": [
                "tcomplement:scorched_block@8"
            ]
        },
        {
            "x": -1,
            "y": 6,
            "z": -2,
            "elements": [
                "tconstruct:seared@10"
            ]
        },
        {
            "x": 1,
            "y": 13,
            "z": 9,
            "elements": [
                "tconstruct:metal@0"
            ]
        },
        {
            "x": -2,
            "y": 2,
            "z": 1,
            "elements": [
                "tcomplement:scorched_block@11"
            ]
        },
        {
            "x": -2,
            "y": 17,
            "z": 5,
            "elements": [
                "tconstruct:metal@0"
            ]
        },
        {
            "x": 1,
            "y": 10,
            "z": 8,
            "elements": [
                "tconstruct:metal@0"
            ]
        },
        {
            "x": -3,
            "y": 4,
            "z": 1,
            "elements": [
                "tcomplement:scorched_block@11"
            ]
        },
        {
            "x": -2,
            "y": 3,
            "z": -1,
            "elements": [
                "jaopca:block.hellite@0"
            ]
        },
        {
            "x": 2,
            "y": 2,
            "z": -2,
            "elements": [
                "tcomplement:scorched_block@2"
            ]
        },
        {
            "x": 1,
            "y": 3,
            "z": 7,
            "elements": [
                "taiga:molten_nitronite_fluid@0"
            ]
        },
        {
            "x": 1,
            "y": 14,
            "z": 9,
            "elements": [
                "tconstruct:metal@0"
            ]
        },
        {
            "x": -1,
            "y": 4,
            "z": -2,
            "elements": [
                "jaopca:block.hellite@0"
            ]
        },
        {
            "x": -3,
            "y": -1,
            "z": 12,
            "elements": [
                "tcomplement:scorched_block@2"
            ]
        },
        {
            "x": 1,
            "y": 15,
            "z": 9,
            "elements": [
                "minecraft:iron_block@0"
            ]
        },
        {
            "x": 0,
            "y": 4,
            "z": 6,
            "elements": [
                "taiga:molten_nitronite_fluid@0"
            ]
        },
        {
            "x": -1,
            "y": 2,
            "z": 1,
            "elements": [
                "thermalfoundation:glass@5"
            ]
        },
        {
            "x": 1,
            "y": 12,
            "z": 8,
            "elements": [
                "minecraft:iron_block@0"
            ]
        },
        {
            "x": 2,
            "y": 0,
            "z": -2,
            "elements": [
                "tcomplement:scorched_block@2"
            ]
        },
        {
            "x": 1,
            "y": 5,
            "z": 7,
            "elements": [
                "taiga:molten_nitronite_fluid@0"
            ]
        },
        {
            "x": 2,
            "y": 15,
            "z": 0,
            "elements": [
                "minecraft:iron_block@0"
            ]
        },
        {
            "x": -1,
            "y": 3,
            "z": -1,
            "elements": [
                "thermalfoundation:glass@5"
            ]
        },
        {
            "x": 4,
            "y": 13,
            "z": 3,
            "elements": [
                "tconstruct:metal@0"
            ]
        },
        {
            "x": -2,
            "y": 6,
            "z": 8,
            "elements": [
                "tcomplement:scorched_block@11"
            ]
        },
        {
            "x": 1,
            "y": 4,
            "z": 8,
            "elements": [
                "taiga:molten_nitronite_fluid@0"
            ]
        },
        {
            "x": 1,
            "y": 0,
            "z": 5,
            "elements": [
                "casings_all"
            ]
        },
        {
            "x": -1,
            "y": 0,
            "z": 6,
            "elements": [
                "casings_all"
            ]
        },
        {
            "x": 1,
            "y": 2,
            "z": 5,
            "elements": [
                "thermalfoundation:glass@5"
            ]
        },
        {
            "x": 0,
            "y": 15,
            "z": 9,
            "elements": [
                "minecraft:iron_block@0"
            ]
        },
        {
            "x": -2,
            "y": 2,
            "z": 6,
            "elements": [
                "tcomplement:scorched_block@11"
            ]
        },
        {
            "x": 3,
            "y": 4,
            "z": 1,
            "elements": [
                "tcomplement:scorched_block@11"
            ]
        },
        {
            "x": 3,
            "y": 5,
            "z": 2,
            "elements": [
                "tcomplement:scorched_block@11"
            ]
        },
        {
            "x": 1,
            "y": 1,
            "z": 5,
            "elements": [
                "tcomplement:scorched_block@11"
            ]
        },
        {
            "x": 3,
            "y": -1,
            "z": -1,
            "elements": [
                "tcomplement:scorched_block@2"
            ]
        },
        {
            "x": -2,
            "y": 4,
            "z": 6,
            "elements": [
                "thermalfoundation:glass@5"
            ]
        },
        {
            "x": 1,
            "y": 11,
            "z": 2,
            "elements": [
                "tconstruct:metal@0"
            ]
        },
        {
            "x": 0,
            "y": 13,
            "z": 9,
            "elements": [
                "tconstruct:metal@0"
            ]
        },
        {
            "x": 0,
            "y": 13,
            "z": 2,
            "elements": [
                "minecraft:iron_block@0"
            ]
        },
        {
            "x": -2,
            "y": 5,
            "z": -1,
            "elements": [
                "jaopca:block.hellite@0"
            ]
        },
        {
            "x": 1,
            "y": 3,
            "z": -1,
            "elements": [
                "thermalfoundation:glass@5"
            ]
        },
        {
            "x": 0,
            "y": -1,
            "z": 5,
            "elements": [
                "tcomplement:scorched_block@11"
            ]
        },
        {
            "x": 1,
            "y": 2,
            "z": 8,
            "elements": [
                "thermalfoundation:glass@5"
            ]
        },
        {
            "x": 0,
            "y": 14,
            "z": 9,
            "elements": [
                "tconstruct:metal@0"
            ]
        },
        {
            "x": 1,
            "y": 6,
            "z": 5,
            "elements": [
                "thermalfoundation:glass@5"
            ]
        },
        {
            "x": -1,
            "y": -1,
            "z": 7,
            "elements": [
                "tcomplement:scorched_block@11"
            ]
        },
        {
            "x": -1,
            "y": 16,
            "z": -2,
            "elements": [
                "minecraft:iron_block@0"
            ]
        },
        {
            "x": -2,
            "y": 11,
            "z": -1,
            "elements": [
                "minecraft:iron_block@0"
            ]
        },
        {
            "x": 0,
            "y": 12,
            "z": 9,
            "elements": [
                "tconstruct:metal@0"
            ]
        },
        {
            "x": -1,
            "y": 9,
            "z": -1,
            "elements": [
                "tconstruct:seared@10"
            ]
        },
        {
            "x": -2,
            "y": 4,
            "z": 5,
            "elements": [
                "thermalfoundation:glass@5"
            ]
        },
        {
            "x": -3,
            "y": 13,
            "z": 2,
            "elements": [
                "tconstruct:metal@0"
            ]
        },
        {
            "x": -2,
            "y": 9,
            "z": 5,
            "elements": [
                "tconstruct:metal@0"
            ]
        },
        {
            "x": -2,
            "y": 12,
            "z": 8,
            "elements": [
                "tconstruct:metal@0"
            ]
        },
        {
            "x": 0,
            "y": 11,
            "z": 9,
            "elements": [
                "minecraft:iron_block@0"
            ]
        },
        {
            "x": 2,
            "y": 2,
            "z": 1,
            "elements": [
                "tcomplement:scorched_block@11"
            ]
        },
        {
            "x": 1,
            "y": 5,
            "z": 5,
            "elements": [
                "taiga:molten_nitronite_fluid@0"
            ]
        },
        {
            "x": -3,
            "y": 3,
            "z": 7,
            "elements": [
                "tcomplement:scorched_block@11"
            ]
        },
        {
            "x": 1,
            "y": 5,
            "z": 2,
            "elements": [
                "taiga:molten_nitronite_fluid@0"
            ]
        },
        {
            "x": 2,
            "y": 2,
            "z": 8,
            "elements": [
                "tcomplement:scorched_block@11"
            ]
        },
        {
            "x": -2,
            "y": 3,
            "z": 5,
            "elements": [
                "thermalfoundation:glass@5"
            ]
        },
        {
            "x": 0,
            "y": 6,
            "z": 1,
            "elements": [
                "thermalfoundation:glass@5"
            ]
        },
        {
            "x": 1,
            "y": 5,
            "z": -1,
            "elements": [
                "thermalfoundation:glass@5"
            ]
        },
        {
            "x": 1,
            "y": 6,
            "z": 8,
            "elements": [
                "thermalfoundation:glass@5"
            ]
        },
        {
            "x": -2,
            "y": 11,
            "z": 11,
            "elements": [
                "minecraft:iron_block@0"
            ]
        },
        {
            "x": -2,
            "y": 6,
            "z": 5,
            "elements": [
                "tcomplement:scorched_block@11"
            ]
        },
        {
            "x": 0,
            "y": 1,
            "z": 7,
            "elements": [
                "tcomplement:scorched_block@11"
            ]
        },
        {
            "x": 2,
            "y": 4,
            "z": 8,
            "elements": [
                "thermalfoundation:glass@5"
            ]
        },
        {
            "x": 3,
            "y": 5,
            "z": 9,
            "elements": [
                "tcomplement:scorched_block@11"
            ]
        },
        {
            "x": 1,
            "y": 4,
            "z": 5,
            "elements": [
                "taiga:molten_nitronite_fluid@0"
            ]
        },
        {
            "x": -3,
            "y": -1,
            "z": -1,
            "elements": [
                "tcomplement:scorched_block@2"
            ]
        },
        {
            "x": 0,
            "y": 4,
            "z": 1,
            "elements": [
                "taiga:molten_nitronite_fluid@0"
            ]
        },
        {
            "x": 1,
            "y": 7,
            "z": -1,
            "elements": [
                "tconstruct:seared@10"
            ]
        },
        {
            "x": -3,
            "y": 5,
            "z": 7,
            "elements": [
                "tcomplement:scorched_block@11"
            ]
        },
        {
            "x": 1,
            "y": 3,
            "z": 5,
            "elements": [
                "taiga:molten_nitronite_fluid@0"
            ]
        },
        {
            "x": -2,
            "y": 5,
            "z": 5,
            "elements": [
                "thermalfoundation:glass@5"
            ]
        },
        {
            "x": 1,
            "y": 7,
            "z": 2,
            "elements": [
                "tcomplement:scorched_block@11"
            ]
        },
        {
            "x": -3,
            "y": 15,
            "z": 3,
            "elements": [
                "tconstruct:metal@0"
            ]
        },
        {
            "x": 2,
            "y": 6,
            "z": 8,
            "elements": [
                "tcomplement:scorched_block@11"
            ]
        },
        {
            "x": 1,
            "y": 9,
            "z": 12,
            "elements": [
                "tconstruct:seared@10"
            ]
        },
        {
            "x": -2,
            "y": 12,
            "z": 9,
            "elements": [
                "minecraft:iron_block@0"
            ]
        },
        {
            "x": -2,
            "y": 15,
            "z": 12,
            "elements": [
                "minecraft:iron_block@0"
            ]
        },
        {
            "x": -2,
            "y": 4,
            "z": 11,
            "elements": [
                "jaopca:block.hellite@0"
            ]
        },
        {
            "x": 0,
            "y": 9,
            "z": 3,
            "elements": [
                "tconstruct:metal@0"
            ]
        },
        {
            "x": -1,
            "y": 1,
            "z": 0,
            "elements": [
                "tcomplement:scorched_block@11"
            ]
        },
        {
            "x": 0,
            "y": -1,
            "z": 0,
            "elements": [
                "tcomplement:scorched_block@11"
            ]
        },
        {
            "x": 2,
            "y": 5,
            "z": 8,
            "elements": [
                "thermalfoundation:glass@5"
            ]
        },
        {
            "x": -1,
            "y": 11,
            "z": 1,
            "elements": [
                "minecraft:iron_block@0"
            ]
        },
        {
            "x": 3,
            "y": 10,
            "z": 4,
            "elements": [
                "tconstruct:metal@0"
            ]
        },
        {
            "x": -2,
            "y": 3,
            "z": 0,
            "elements": [
                "thermalfoundation:glass@5"
            ]
        },
        {
            "x": -3,
            "y": 5,
            "z": 0,
            "elements": [
                "tcomplement:scorched_block@11"
            ]
        },
        {
            "x": 2,
            "y": 14,
            "z": -3,
            "elements": [
                "minecraft:iron_block@0"
            ]
        },
        {
            "x": 2,
            "y": 6,
            "z": 1,
            "elements": [
                "tcomplement:scorched_block@11"
            ]
        },
        {
            "x": -1,
            "y": 13,
            "z": -4,
            "elements": [
                "minecraft:iron_block@0"
            ]
        },
        {
            "x": -1,
            "y": 11,
            "z": 8,
            "elements": [
                "tconstruct:metal@0"
            ]
        },
        {
            "x": 1,
            "y": 8,
            "z": 12,
            "elements": [
                "tconstruct:seared@10"
            ]
        },
        {
            "x": 2,
            "y": 5,
            "z": 1,
            "elements": [
                "thermalfoundation:glass@5"
            ]
        },
        {
            "x": 1,
            "y": -1,
            "z": 0,
            "elements": [
                "tcomplement:scorched_block@11"
            ]
        },
        {
            "x": 2,
            "y": 4,
            "z": 1,
            "elements": [
                "thermalfoundation:glass@5"
            ]
        },
        {
            "x": -1,
            "y": 12,
            "z": 8,
            "elements": [
                "minecraft:iron_block@0"
            ]
        },
        {
            "x": -1,
            "y": 13,
            "z": 8,
            "elements": [
                "minecraft:iron_block@0"
            ]
        },
        {
            "x": 0,
            "y": 7,
            "z": 3,
            "elements": [
                "tcomplement:scorched_block@11"
            ]
        },
        {
            "x": -1,
            "y": 3,
            "z": 0,
            "elements": [
                "taiga:molten_nitronite_fluid@0"
            ]
        },
        {
            "x": 1,
            "y": 10,
            "z": 12,
            "elements": [
                "minecraft:iron_block@0"
            ]
        },
        {
            "x": 1,
            "y": 6,
            "z": 9,
            "elements": [
                "thermalfoundation:glass@5"
            ]
        },
        {
            "x": 3,
            "y": 11,
            "z": 3,
            "elements": [
                "tconstruct:metal@0"
            ]
        },
        {
            "x": -1,
            "y": 14,
            "z": 8,
            "elements": [
                "minecraft:iron_block@0"
            ]
        },
        {
            "x": 2,
            "y": 11,
            "z": 8,
            "elements": [
                "tconstruct:metal@0"
            ]
        },
        {
            "x": 0,
            "y": 13,
            "z": -4,
            "elements": [
                "minecraft:iron_block@0"
            ]
        },
        {
            "x": -1,
            "y": 15,
            "z": 1,
            "elements": [
                "minecraft:iron_block@0"
            ]
        },
        {
            "x": 3,
            "y": 15,
            "z": 3,
            "elements": [
                "tconstruct:metal@0"
            ]
        },
        {
            "x": -2,
            "y": 15,
            "z": 13,
            "elements": [
                "minecraft:iron_block@0"
            ]
        },
        {
            "x": 3,
            "y": 4,
            "z": 4,
            "elements": [
                "tcomplement:scorched_block@11"
            ]
        },
        {
            "x": 0,
            "y": 17,
            "z": 3,
            "elements": [
                "tconstruct:metal@0"
            ]
        },
        {
            "x": 1,
            "y": 0,
            "z": 6,
            "elements": [
                "casings_all"
            ]
        },
        {
            "x": -3,
            "y": 2,
            "z": 11,
            "elements": [
                "tcomplement:scorched_block@2"
            ]
        },
        {
            "x": -1,
            "y": 14,
            "z": 1,
            "elements": [
                "tconstruct:metal@0"
            ]
        },
        {
            "x": 1,
            "y": 1,
            "z": 0,
            "elements": [
                "tcomplement:scorched_block@11"
            ]
        },
        {
            "x": -1,
            "y": -1,
            "z": 5,
            "elements": [
                "tcomplement:scorched_block@11"
            ]
        },
        {
            "x": -1,
            "y": 15,
            "z": 8,
            "elements": [
                "tconstruct:metal@0"
            ]
        },
        {
            "x": -2,
            "y": 13,
            "z": 13,
            "elements": [
                "minecraft:iron_block@0"
            ]
        },
        {
            "x": 0,
            "y": 5,
            "z": 3,
            "elements": [
                "taiga:molten_nitronite_fluid@0"
            ]
        },
        {
            "x": -3,
            "y": 5,
            "z": 5,
            "elements": [
                "tcomplement:scorched_block@11"
            ]
        },
        {
            "x": 2,
            "y": 12,
            "z": 8,
            "elements": [
                "tconstruct:metal@0"
            ]
        },
        {
            "x": -2,
            "y": 14,
            "z": 13,
            "elements": [
                "minecraft:iron_block@0"
            ]
        },
        {
            "x": 1,
            "y": 1,
            "z": 6,
            "elements": [
                "tcomplement:scorched_block@11"
            ]
        },
        {
            "x": -2,
            "y": 11,
            "z": 13,
            "elements": [
                "minecraft:iron_block@0"
            ]
        },
        {
            "x": -1,
            "y": 12,
            "z": 1,
            "elements": [
                "tconstruct:metal@0"
            ]
        },
        {
            "x": 0,
            "y": 3,
            "z": 3,
            "elements": [
                "taiga:molten_nitronite_fluid@0"
            ]
        },
        {
            "x": -1,
            "y": 16,
            "z": 8,
            "elements": [
                "tconstruct:metal@0"
            ]
        },
        {
            "x": 1,
            "y": 3,
            "z": 0,
            "elements": [
                "taiga:molten_nitronite_fluid@0"
            ]
        },
        {
            "x": -3,
            "y": 11,
            "z": 3,
            "elements": [
                "tconstruct:metal@0"
            ]
        },
        {
            "x": -2,
            "y": 5,
            "z": 0,
            "elements": [
                "thermalfoundation:glass@5"
            ]
        },
        {
            "x": -2,
            "y": 14,
            "z": 9,
            "elements": [
                "minecraft:iron_block@0"
            ]
        },
        {
            "x": -2,
            "y": 12,
            "z": 13,
            "elements": [
                "minecraft:iron_block@0"
            ]
        },
        {
            "x": 0,
            "y": -1,
            "z": 6,
            "elements": [
                "tcomplement:scorched_block@11"
            ]
        },
        {
            "x": -3,
            "y": 16,
            "z": 4,
            "elements": [
                "tconstruct:metal@0"
            ]
        },
        {
            "x": 2,
            "y": 11,
            "z": 1,
            "elements": [
                "minecraft:iron_block@0"
            ]
        },
        {
            "x": 0,
            "y": 1,
            "z": 5,
            "elements": [
                "tcomplement:scorched_block@11"
            ]
        },
        {
            "x": -3,
            "y": 3,
            "z": 5,
            "elements": [
                "tcomplement:scorched_block@11"
            ]
        },
        {
            "x": -1,
            "y": 13,
            "z": 1,
            "elements": [
                "tconstruct:metal@0"
            ]
        },
        {
            "x": 1,
            "y": 16,
            "z": -2,
            "elements": [
                "minecraft:iron_block@0"
