{
    "registryname": "factory_atomic_decayer",
    "localizedname": "§eELYSIA工厂 - 原子衰变工厂",
    "requires-blueprint": false,
    "failure-action": "still",
    "color": "b680e9",
    "modifiers": [
        {
            "elements": "modularmachinery:blockcasing@1",
            "x": 0,
            "y": 1,
            "z": 1,
            "description": "将机器顶端的方块换成此方块以降低配方制作时间至75%！",
            "modifier": {
                "io": "input",
                "target": "modularmachinery:duration",
                "operation": 1,
                "multiplier": 0.75
            }
        },
        {
            "elements": "modularmachinery:blockcasing@2",
            "x": 0,
            "y": 1,
            "z": 1,
            "description": "将机器顶端的方块换成此方块以降低配方制作时间至50%！",
            "modifier": {
                "io": "input",
                "target": "modularmachinery:duration",
                "operation": 1,
                "multiplier": 0.5
            }
        },
        {
            "elements": "modularmachinery:blockcasing@3",
            "x": 0,
            "y": 1,
            "z": 1,
            "description": "将机器顶端的方块换成此方块以降低配方制作时间至33%！",
            "modifier": {
                "io": "input",
                "target": "modularmachinery:duration",
                "operation": 1,
                "multiplier": 0.333
            }
        },
        {
            "elements": "modularmachinery:blockcasing@5",
            "x": 0,
            "y": 1,
            "z": 1,
            "description": "将机器顶端的方块换成此方块以降低配方制作时间至22%！",
            "modifier": {
                "io": "input",
                "target": "modularmachinery:duration",
                "operation": 1,
                "multiplier": 0.222
            }
        },
        {
            "elements": "mmce_complement:blockcasing@0",
            "x": 0,
            "y": 1,
            "z": 1,
            "description": "将机器顶端的方块换成此方块以降低配方制作时间至15%！",
            "modifier": {
                "io": "input",
                "target": "modularmachinery:duration",
                "operation": 1,
                "multiplier": 0.148
            }
        },
        {
            "elements": "mmce_complement:blockcasing@1",
            "x": 0,
            "y": 1,
            "z": 1,
            "description": "将机器顶端的方块换成此方块以降低配方制作时间至10%！",
            "modifier": {
                "io": "input",
                "target": "modularmachinery:duration",
                "operation": 1,
                "multiplier": 0.099
            }
        },
        {
            "elements": "mmce_complement:blockcasing@2",
            "x": 0,
            "y": 1,
            "z": 1,
            "description": "将机器顶端的方块换成此方块以降低配方制作时间至7%！",
            "modifier": {
                "io": "input",
                "target": "modularmachinery:duration",
                "operation": 1,
                "multiplier": 0.066
            }
        },
        {
            "elements": "mmce_complement:blockcasing@3",
            "x": 0,
            "y": 1,
            "z": 1,
            "description": "将机器顶端的方块换成此方块以降低配方制作时间至4%！",
            "modifier": {
                "io": "input",
                "target": "modularmachinery:duration",
                "operation": 1,
                "multiplier": 0.044
            }
        },
        {
            "elements": "mmce_complement:blockcasing@4",
            "x": 0,
            "y": 1,
            "z": 1,
            "description": "将机器顶端的方块换成此方块以降低配方制作时间至3%！",
            "modifier": {
                "io": "input",
                "target": "modularmachinery:duration",
                "operation": 1,
                "multiplier": 0.029
            }
        },
        {
            "elements": "mmce_complement:blockcasing@5",
            "x": 0,
            "y": 1,
            "z": 1,
            "description": "将机器顶端的方块换成此方块以降低配方制作时间至2%！",
            "modifier": {
                "io": "input",
                "target": "modularmachinery:duration",
                "operation": 1,
                "multiplier": 0.019
            }
        }
    ],
    "parts": [
        {
            "x": -1,
            "y": 0,
            "z": 1,
            "elements": [
                "casings_all"
            ]
        },
        {
            "x": 0,
            "y": -1,
            "z": 2,
            "elements": [
                "jaopca:block.porpezite@0"
            ]
        },
        {
            "x": -1,
            "y": 1,
            "z": 0,
            "elements": [
                "extendedcrafting:trimmed@4"
            ]
        },
        {
            "x": 0,
            "y": 1,
            "z": 2,
            "elements": [
                "jaopca:block.porpezite@0"
            ]
        },
        {
            "x": 1,
            "y": 0,
            "z": 1,
            "elements": [
                "casings_all"
            ]
        },
        {
            "x": 1,
            "y": -1,
            "z": 1,
            "elements": [
                "jaopca:block.porpezite@0"
            ]
        },
        {
            "x": 0,
            "y": -1,
            "z": 0,
            "elements": [
                "jaopca:block.porpezite@0",
                "casings_upgrade"
            ]
        },
        {
            "x": -1,
            "y": -1,
            "z": 1,
            "elements": [
                "jaopca:block.porpezite@0"
            ]
        },
        {
            "x": 1,
            "y": 1,
            "z": 0,
            "elements": [
                "extendedcrafting:trimmed@4"
            ]
        },
        {
            "x": 1,
            "y": 1,
            "z": 1,
            "elements": [
                "jaopca:block.porpezite@0"
            ]
        },
        {
            "x": -1,
            "y": 1,
            "z": 1,
            "elements": [
                "jaopca:block.porpezite@0"
            ]
        },
        {
            "x": 0,
            "y": 0,
            "z": 2,
            "elements": [
                "casings_all"
            ]
        },
        {
            "x": -1,
            "y": 0,
            "z": 0,
            "elements": [
                "additions:electronium_block@0"
            ]
        },
        {
            "x": 1,
            "y": 0,
            "z": 0,
            "elements": [
                "additions:electronium_block@0"
            ]
        },
        {
            "x": 1,
            "y": 1,
            "z": 2,
            "elements": [
                "extendedcrafting:trimmed@4"
            ]
        },
        {
            "x": 1,
            "y": -1,
            "z": 2,
            "elements": [
                "extendedcrafting:trimmed@4"
            ]
        },
        {
            "x": -1,
            "y": -1,
            "z": 0,
            "elements": [
                "extendedcrafting:trimmed@4"
            ]
        },
        {
            "x": -1,
            "y": 1,
            "z": 2,
            "elements": [
                "extendedcrafting:trimmed@4"
            ]
        },
        {
            "x": 0,
            "y": -1,
            "z": 1,
            "elements": [
                "casings_all"
            ]
        },
        {
            "x": 1,
            "y": -1,
            "z": 0,
            "elements": [
                "extendedcrafting:trimmed@4"
            ]
        },
        {
            "x": -1,
            "y": -1,
            "z": 2,
            "elements": [
                "extendedcrafting:trimmed@4"
            ]
        },
        {
            "x": 0,
            "y": 1,
            "z": 0,
            "elements": [
                "jaopca:block.porpezite@0",
                "casings_parallel"
            ]
        },
        {
            "x": -1,
            "y": 0,
            "z": 2,
            "elements": [
                "additions:electronium_block@0"
            ]
        },
        {
            "x": 0,
            "y": 1,
            "z": 1,
            "elements": [
                "casings_all"
            ]
        },
        {
            "x": 1,
            "y": 0,
            "z": 2,
            "elements": [
                "additions:electronium_block@0"
            ]
        }
    ]}

