{
    "registryname": "elysia_liquefier",
    "localizedname": "§cELYSIA单元 - 大型液化单元",
    "requires-blueprint": false,
    "failure-action": "still",
    "color": "2ab5bf",
    "modifiers": [
        {
            "elements": "modularmachinery:blockcasing@1",
            "x": 0,
            "y": -1,
            "z": 0,
            "description": "将控制器下方紧挨着的方块换成此方块以降低配方制作时间至75%！",
            "modifier": {
                "io": "input",
                "target": "modularmachinery:duration",
                "operation": 1,
                "multiplier": 0.75
            }
        },
        {
            "elements": "modularmachinery:blockcasing@2",
            "x": 0,
            "y": -1,
            "z": 0,
            "description": "将控制器下方紧挨着的方块换成此方块以降低配方制作时间至66%！",
            "modifier": {
                "io": "input",
                "target": "modularmachinery:duration",
                "operation": 1,
                "multiplier": 0.66
            }
        },
        {
            "elements": "modularmachinery:blockcasing@3",
            "x": 0,
            "y": -1,
            "z": 0,
            "description": "将控制器下方紧挨着的方块换成此方块以降低配方制作时间至50%！",
            "modifier": {
                "io": "input",
                "target": "modularmachinery:duration",
                "operation": 1,
                "multiplier": 0.5
            }
        },
        {
            "elements": "modularmachinery:blockcasing@5",
            "x": 0,
            "y": -1,
            "z": 0,
            "description": "将控制器下方紧挨着的方块换成此方块以降低配方制作时间至33%！",
            "modifier": {
                "io": "input",
                "target": "modularmachinery:duration",
                "operation": 1,
                "multiplier": 0.33
            }
        }
    ],
    "parts": [
        {
            "x": 0,
            "y": 0,
            "z": 0,
            "elements": [
                "modularmachinery:blockcontroller@2"
            ]
        },
        {
            "x": -3,
            "y": -2,
            "z": 5,
            "elements": [
                "jaopca:block.chillinium@0"
            ]
        },
        {
            "x": -3,
            "y": 0,
            "z": 5,
            "elements": [
                "casings_all"
            ]
        },
        {
            "x": 0,
            "y": -2,
            "z": 0,
            "elements": [
                "jaopca:block.chillinium@0"
            ]
        },
        {
            "x": -2,
            "y": -6,
            "z": 10,
            "elements": [
                "chisel:blockinvar@5"
            ]
        },
        {
            "x": -4,
            "y": -7,
            "z": 4,
            "elements": [
                "nuclearcraft:ingot_block@11"
            ]
        },
        {
            "x": -7,
            "y": -5,
            "z": 4,
            "elements": [
                "thermaldynamics:duct_64@0"
            ]
        },
        {
            "x": 3,
            "y": -5,
            "z": -5,
            "elements": [
                "thermaldynamics:duct_64@0"
            ]
        },
        {
            "x": 3,
            "y": -8,
            "z": 0,
            "elements": [
                "thermaldynamics:duct_64@0"
            ]
        },
        {
            "x": 1,
            "y": -8,
            "z": 5,
            "elements": [
                "thermaldynamics:duct_64@0"
            ]
        },
        {
            "x": -4,
            "y": -8,
            "z": -4,
            "elements": [
                "jaopca:block.chillinium@0"
            ]
        },
        {
            "x": -2,
            "y": -8,
            "z": 10,
            "elements": [
                "jaopca:block.chillinium@0"
            ]
        },
        {
            "x": -1,
            "y": -5,
            "z": 11,
            "elements": [
                "thermalfoundation:glass_alloy@7"
            ]
        },
        {
            "x": -7,
            "y": -7,
            "z": -3,
            "elements": [
                "thermaldynamics:duct_64@0"
            ]
        },
        {
            "x": 1,
            "y": 0,
            "z": 0,
            "elements": [
                "casings_all"
            ]
        },
        {
            "x": -4,
            "y": -2,
            "z": 5,
            "elements": [
                "thermalfoundation:glass_alloy@7"
            ]
        },
        {
            "x": 8,
            "y": -7,
            "z": 1,
            "elements": [
                "thermalfoundation:fluid_cryotheum@0"
            ]
        },
        {
            "x": -7,
            "y": -5,
            "z": -3,
            "elements": [
                "thermaldynamics:duct_64@0"
            ]
        },
        {
            "x": 8,
            "y": -6,
            "z": 1,
            "elements": [
                "thermalfoundation:fluid_cryotheum@0"
            ]
        },
        {
            "x": -9,
            "y": -6,
            "z": 3,
            "elements": [
                "chisel:blockinvar@5"
            ]
        },
        {
            "x": -2,
            "y": 0,
            "z": 5,
            "elements": [
                "casings_all"
            ]
        },
        {
            "x": 0,
            "y": -4,
            "z": 0,
            "elements": [
                "chisel:blockinvar@5"
            ]
        },
        {
            "x": 4,
            "y": -5,
            "z": -5,
            "elements": [
                "thermaldynamics:duct_64@0"
            ]
        },
        {
            "x": 2,
            "y": -8,
            "z": 0,
            "elements": [
                "thermaldynamics:duct_64@0"
            ]
        },
        {
            "x": 1,
            "y": -3,
            "z": -5,
            "elements": [
                "nuclearcraft:ingot_block@11"
            ]
        },
        {
            "x": 8,
            "y": -8,
            "z": 1,
            "elements": [
                "jaopca:block.iciricium@0"
            ]
        },
        {
            "x": -1,
            "y": -8,
            "z": -4,
            "elements": [
                "thermaldynamics:duct_64@0"
            ]
        },
        {
            "x": 2,
            "y": -8,
            "z": 5,
            "elements": [
                "thermaldynamics:duct_64@0"
            ]
        },
        {
            "x": -1,
            "y": -8,
            "z": 10,
            "elements": [
                "jaopca:block.iciricium@0"
            ]
        },
        {
            "x": 8,
            "y": -5,
            "z": 1,
            "elements": [
                "thermalfoundation:fluid_cryotheum@0"
            ]
        },
        {
            "x": -1,
            "y": -7,
            "z": 11,
            "elements": [
                "nuclearcraft:ingot_block@11"
            ]
        },
        {
            "x": 2,
            "y": 0,
            "z": 0,
            "elements": [
                "thermaldynamics:duct_64@0"
            ]
        },
        {
            "x": -4,
            "y": -4,
            "z": -4,
            "elements": [
                "chisel:blockinvar@5"
            ]
        },
        {
            "x": 8,
            "y": -4,
            "z": 1,
            "elements": [
                "thermalfoundation:fluid_cryotheum@0"
            ]
        },
        {
            "x": 0,
            "y": -3,
            "z": 11,
            "elements": [
                "thermalfoundation:fluid_cryotheum@0"
            ]
        },
        {
            "x": -2,
            "y": -2,
            "z": 0,
            "elements": [
                "thermaldynamics:duct_64@0"
            ]
        },
        {
            "x": -3,
            "y": -8,
            "z": 3,
            "elements": [
                "thermaldynamics:duct_64@0"
            ]
        },
        {
            "x": -2,
            "y": -2,
            "z": 10,
            "elements": [
                "jaopca:block.chillinium@0"
            ]
        },
        {
            "x": 4,
            "y": -6,
            "z": 0,
            "elements": [
                "chisel:blockinvar@5"
            ]
        },
        {
            "x": 5,
            "y": -5,
            "z": -5,
            "elements": [
                "thermaldynamics:duct_64@0"
            ]
        },
        {
            "x": -7,
            "y": -3,
            "z": 1,
            "elements": [
                "nuclearcraft:ingot_block@11"
            ]
        },
        {
            "x": -7,
            "y": -4,
            "z": 1,
            "elements": [
                "chisel:blockinvar@5"
            ]
        },
        {
            "x": 3,
            "y": -8,
            "z": 5,
            "elements": [
                "jaopca:block.chillinium@0"
            ]
        },
        {
            "x": 1,
            "y": -8,
            "z": 0,
            "elements": [
                "thermaldynamics:duct_64@0"
            ]
        },
        {
            "x": -1,
            "y": 0,
            "z": 0,
            "elements": [
                "casings_all"
            ]
        },
        {
            "x": -3,
            "y": -4,
            "z": 5,
            "elements": [
                "chisel:blockinvar@5"
            ]
        },
        {
            "x": 8,
            "y": -3,
            "z": 1,
            "elements": [
                "thermalfoundation:fluid_cryotheum@0"
            ]
        },
        {
            "x": -1,
            "y": -6,
            "z": 10,
            "elements": [
                "thermalfoundation:fluid_cryotheum@0"
            ]
        },
        {
            "x": -1,
            "y": -3,
            "z": 11,
            "elements": [
                "nuclearcraft:ingot_block@11"
            ]
        },
        {
            "x": 5,
            "y": -7,
            "z": -5,
            "elements": [
                "thermaldynamics:duct_64@0"
            ]
        },
        {
            "x": 8,
            "y": -5,
            "z": 4,
            "elements": [
                "minecraft:sticky_piston@2"
            ]
        },
        {
            "x": -1,
            "y": -3,
            "z": -5,
            "elements": [
                "nuclearcraft:ingot_block@11"
            ]
        },
        {
            "x": 8,
            "y": -2,
            "z": 1,
            "elements": [
                "thermalfoundation:glass_alloy@7"
            ]
        },
        {
            "x": -2,
            "y": -4,
            "z": 0,
            "elements": [
                "thermaldynamics:duct_64@0"
            ]
        },
        {
            "x": 2,
            "y": -5,
            "z": -5,
            "elements": [
                "thermaldynamics:duct_64@0"
            ]
        },
        {
            "x": -2,
            "y": -4,
            "z": 10,
            "elements": [
                "chisel:blockinvar@5"
            ]
        },
        {
            "x": 3,
            "y": 0,
            "z": 3,
            "elements": [
                "casings_all"
            ]
        },
        {
            "x": -9,
            "y": -8,
            "z": 3,
            "elements": [
                "jaopca:block.chillinium@0"
            ]
        },
        {
            "x": 3,
            "y": -5,
            "z": 9,
            "elements": [
                "thermaldynamics:duct_64@0"
            ]
        },
        {
            "x": 4,
            "y": -8,
            "z": 0,
            "elements": [
                "jaopca:block.chillinium@0"
            ]
        },
        {
            "x": 0,
            "y": -8,
            "z": 5,
            "elements": [
                "thermaldynamics:duct_64@0"
            ]
        },
        {
            "x": -3,
            "y": -8,
            "z": -4,
            "elements": [
                "thermaldynamics:duct_64@0"
            ]
        },
        {
            "x": -3,
            "y": -6,
            "z": 5,
            "elements": [
                "chisel:blockinvar@5"
            ]
        },
        {
            "x": -7,
            "y": -2,
            "z": 1,
            "elements": [
                "jaopca:block.chillinium@0"
            ]
        },
        {
            "x": -4,
            "y": -6,
            "z": -4,
            "elements": [
                "chisel:blockinvar@5"
            ]
        },
        {
            "x": 2,
            "y": -6,
            "z": 10,
            "elements": [
                "chisel:blockinvar@5"
            ]
        },
        {
            "x": 4,
            "y": -2,
            "z": 0,
            "elements": [
                "jaopca:block.chillinium@0"
            ]
        },
        {
            "x": -7,
            "y": -8,
            "z": 1,
            "elements": [
                "jaopca:block.chillinium@0"
            ]
        },
        {
            "x": 1,
            "y": -8,
            "z": 10,
            "elements": [
                "jaopca:block.iciricium@0"
            ]
        },
        {
            "x": 0,
            "y": -7,
            "z": -5,
            "elements": [
                "thermalfoundation:fluid_cryotheum@0"
            ]
        },
        {
            "x": -1,
            "y": -5,
            "z": -5,
            "elements": [
                "thermaldynamics:duct_64@0"
            ]
        },
        {
            "x": 2,
            "y": -1,
            "z": 4,
            "elements": [
                "thermaldynamics:duct_64@0"
            ]
        },
        {
            "x": 5,
            "y": -5,
            "z": 4,
            "elements": [
                "thermaldynamics:duct_64@0"
            ]
        },
        {
            "x": -1,
            "y": -4,
            "z": 10,
            "elements": [
                "thermalfoundation:fluid_cryotheum@0"
            ]
        },
        {
            "x": -3,
            "y": -8,
            "z": 5,
            "elements": [
                "jaopca:block.chillinium@0"
            ]
        },
        {
            "x": 5,
            "y": -2,
            "z": 7,
            "elements": [
                "jaopca:block.chillinium@0"
            ]
        },
        {
            "x": 2,
            "y": -3,
            "z": 4,
            "elements": [
                "thermaldynamics:duct_64@0"
            ]
        },
        {
            "x": -7,
            "y": -7,
            "z": 1,
            "elements": [
                "nuclearcraft:ingot_block@11"
            ]
        },
        {
            "x": 0,
            "y": -7,
            "z": 11,
            "elements": [
                "thermalfoundation:fluid_cryotheum@0"
            ]
        },
        {
            "x": -5,
            "y": -4,
            "z": 5,
            "elements": [
                "chisel:blockinvar@5"
            ]
        },
        {
            "x": 8,
            "y": -7,
            "z": 4,
            "elements": [
                "nuclearcraft:ingot_block@11"
            ]
        },
        {
            "x": 8,
            "y": -6,
            "z": 3,
            "elements": [
                "thermalfoundation:fluid_cryotheum@0"
            ]
        },
        {
            "x": 4,
            "y": -6,
            "z": 5,
            "elements": [
                "thermalfoundation:fluid_cryotheum@0"
            ]
        },
        {
            "x": 0,
            "y": -5,
            "z": -5,
            "elements": [
                "thermalfoundation:fluid_cryotheum@0"
            ]
        },
        {
            "x": 0,
            "y": -5,
            "z": 11,
            "elements": [
                "thermalfoundation:fluid_cryotheum@0"
            ]
        },
        {
            "x": 1,
            "y": -6,
            "z": 10,
            "elements": [
                "thermalfoundation:fluid_cryotheum@0"
            ]
        },
        {
            "x": 8,
            "y": -8,
            "z": 3,
            "elements": [
                "jaopca:block.iciricium@0"
            ]
        },
        {
            "x": -1,
            "y": -7,
            "z": -7,
            "elements": [
                "nuclearcraft:ingot_block@11"
            ]
        },
        {
            "x": -4,
            "y": -8,
            "z": 1,
            "elements": [
                "thermaldynamics:duct_64@0"
            ]
        },
        {
            "x": 2,
            "y": -8,
            "z": 10,
            "elements": [
                "jaopca:block.chillinium@0"
            ]
        },
        {
            "x": -1,
            "y": -7,
            "z": -5,
            "elements": [
                "nuclearcraft:ingot_block@11"
            ]
        },
        {
            "x": 4,
            "y": -4,
            "z": 0,
            "elements": [
                "chisel:blockinvar@5"
            ]
        },
        {
            "x": 2,
            "y": 0,
            "z": 5,
            "elements": [
                "casings_all"
            ]
        },
        {
            "x": 8,
            "y": -3,
            "z": 4,
            "elements": [
                "nuclearcraft:ingot_block@11"
            ]
        },
        {
            "x": -4,
            "y": -2,
            "z": -4,
            "elements": [
                "jaopca:block.chillinium@0"
            ]
        },
        {
            "x": -1,
            "y": -2,
            "z": 10,
            "elements": [
                "thermalfoundation:glass_alloy@7"
            ]
        },
        {
            "x": -7,
            "y": -5,
            "z": 1,
            "elements": [
                "thermaldynamics:duct_64@0"
            ]
        },
        {
            "x": 6,
            "y": -8,
            "z": 0,
            "elements": [
                "thermaldynamics:duct_64@0"
            ]
        },
        {
            "x": -4,
            "y": -3,
            "z": -3,
            "elements": [
                "thermalfoundation:fluid_cryotheum@0"
            ]
        },
        {
            "x": -1,
            "y": -8,
            "z": -7,
            "elements": [
                "jaopca:block.chillinium@0"
            ]
        },
        {
            "x": 0,
            "y": -3,
            "z": 9,
            "elements": [
                "thermalfoundation:fluid_cryotheum@0"
            ]
        },
        {
            "x": -4,
            "y": -1,
            "z": 4,
            "elements": [
                "betterendforge:ancient_emerald_ice@0"
            ]
        },
        {
            "x": -5,
            "y": -6,
            "z": 5,
            "elements": [
                "chisel:blockinvar@5"
            ]
        },
        {
            "x": -7,
            "y": -6,
            "z": 1,
            "elements": [
                "chisel:blockinvar@5"
            ]
        },
        {
            "x": -2,
            "y": 0,
            "z": 0,
            "elements": [
                "thermaldynamics:duct_64@0"
            ]
        },
        {
            "x": 2,
            "y": -5,
            "z": 4,
            "elements": [
                "thermaldynamics:duct_64@0"
            ]
        },
        {
            "x": -5,
            "y": -2,
            "z": 5,
            "elements": [
                "jaopca:block.chillinium@0"
            ]
        },
        {
            "x": 9,
            "y": -8,
            "z": 3,
            "elements": [
                "jaopca:block.chillinium@0"
            ]
        },
        {
            "x": -1,
            "y": 0,
            "z": 5,
            "elements": [
                "casings_upgrade"
            ]
        },
        {
            "x": 4,
            "y": -4,
            "z": 5,
            "elements": [
                "thermalfoundation:fluid_cryotheum@0"
            ]
        },
        {
            "x": 5,
            "y": -5,
            "z": 7,
            "elements": [
                "thermalfoundation:glass_alloy@7"
            ]
        },
        {
            "x": -1,
            "y": -7,
            "z": 1,
            "elements": [
                "nuclearcraft:ingot_block@11"
            ]
        },
        {
            "x": 5,
            "y": -2,
            "z": 6,
            "elements": [
                "thermalfoundation:glass_alloy@7"
            ]
        },
        {
            "x": -4,
            "y": -5,
            "z": -3,
            "elements": [
                "thermalfoundation:fluid_cryotheum@0"
            ]
        },
        {
            "x": 5,
            "y": -3,
            "z": -1,
            "elements": [
                "nuclearcraft:ingot_block@11"
            ]
        },
        {
            "x": -9,
            "y": -4,
            "z": 3,
            "elements": [
                "chisel:blockinvar@5"
            ]
        },
        {
            "x": -1,
            "y": -5,
            "z": -7,
            "elements": [
                "thermalfoundation:glass_alloy@7"
            ]
        },
        {
            "x": 2,
            "y": -8,
            "z": -4,
            "elements": [
                "thermaldynamics:duct_64@0"
            ]
        },
        {
            "x": 0,
            "y": -6,
            "z": 0,
            "elements": [
                "chisel:blockinvar@5"
            ]
        },
        {
            "x": 0,
            "y": -3,
            "z": -5,
            "elements": [
                "thermalfoundation:fluid_cryotheum@0"
            ]
        },
        {
            "x": -6,
            "y": -8,
            "z": 3,
            "elements": [
                "thermaldynamics:duct_64@0"
            ]
        },
        {
            "x": -1,
            "y": -6,
            "z": -7,
            "elements": [
                "chisel:blockinvar@5"
            ]
        },
        {
            "x": 2,
            "y": -2,
            "z": 10,
            "elements": [
                "jaopca:block.chillinium@0"
            ]
        },
        {
            "x": 8,
            "y": -2,
            "z": 3,
            "elements": [
                "thermalfoundation:glass_alloy@7"
            ]
        },
        {
            "x": -1,
            "y": -8,
            "z": 1,
            "elements": [
                "jaopca:block.chillinium@0"
            ]
        },
        {
            "x": 7,
            "y": -8,
            "z": 5,
            "elements": [
                "thermaldynamics:duct_64@0"
            ]
        },
        {
            "x": 5,
            "y": -6,
            "z": 7,
            "elements": [
                "chisel:blockinvar@5"
            ]
        },
        {
            "x": -4,
            "y": -3,
            "z": 4,
            "elements": [
                "nuclearcraft:ingot_block@11"
            ]
        },
        {
            "x": 5,
            "y": -4,
            "z": -1,
            "elements": [
                "chisel:blockinvar@5"
            ]
        },
        {
            "x": 5,
            "y": -3,
            "z": 7,
            "elements": [
                "nuclearcraft:ingot_block@11"
            ]
        },
        {
            "x": -1,
            "y": -5,
            "z": 1,
            "elements": [
                "thermaldynamics:duct_64@0"
            ]
        },
        {
            "x": -4,
            "y": -7,
            "z": -3,
            "elements": [
                "thermalfoundation:fluid_cryotheum@0"
            ]
        },
        {
            "x": -9,
            "y": -2,
            "z": 3,
            "elements": [
                "jaopca:block.chillinium@0"
            ]
        },
        {
            "x": -1,
            "y": -3,
            "z": -7,
            "elements": [
                "nuclearcraft:ingot_block@11"
            ]
        },
        {
            "x": 2,
            "y": -4,
            "z": 10,
            "elements": [
                "chisel:blockinvar@5"
            ]
        },
        {
            "x": -1,
            "y": -8,
            "z": -6,
            "elements": [
                "jaopca:block.iciricium@0"
            ]
        },
        {
            "x": 5,
            "y": -2,
            "z": -1,
            "elements": [
                "jaopca:block.chillinium@0"
            ]
        },
        {
            "x": -4,
            "y": -1,
            "z": 1,
            "elements": [
                "betterendforge:ancient_emerald_ice@0"
            ]
        },
        {
            "x": 3,
            "y": 0,
            "z": -1,
            "elements": [
                "casings_all"
            ]
        },
        {
            "x": 4,
            "y": -8,
            "z": 5,
            "elements": [
                "jaopca:block.iciricium@0"
            ]
        },
        {
            "x": 0,
            "y": -8,
            "z": 0,
            "elements": [
                "jaopca:block.chillinium@0"
            ]
        },
        {
            "x": 9,
            "y": -6,
            "z": 3,
            "elements": [
                "chisel:blockinvar@5"
            ]
        },
        {
            "x": -4,
            "y": -5,
            "z": 4,
            "elements": [
                "minecraft:sticky_piston@3"
            ]
        },
        {
            "x": -1,
            "y": -4,
            "z": -7,
            "elements": [
                "chisel:blockinvar@5"
            ]
        },
        {
            "x": 5,
            "y": -4,
            "z": 7,
            "elements": [
                "chisel:blockinvar@5"
            ]
        },
        {
            "x": 8,
            "y": -4,
            "z": 3,
            "elements": [
                "thermalfoundation:fluid_cryotheum@0"
            ]
        },
        {
            "x": -1,
            "y": -7,
            "z": -6,
            "elements": [
                "thermalfoundation:fluid_cryotheum@0"
            ]
        },
        {
            "x": -1,
            "y": -6,
            "z": 1,
            "elements": [
                "chisel:blockinvar@5"
            ]
        },
        {
            "x": -7,
            "y": -4,
            "z": 3,
            "elements": [
                "chisel:blockinvar@5"
            ]
        },
        {
            "x": 5,
            "y": -2,
            "z": 5,
            "elements": [
                "jaopca:block.chillinium@0"
            ]
        },
        {
            "x": -10,
            "y": -7,
            "z": 2,
            "elements": [
                "nuclearcraft:ingot_block@11"
            ]
        },
        {
            "x": -1,
            "y": -8,
            "z": 3,
            "elements": [
                "jaopca:block.chillinium@0"
            ]
        },
        {
            "x": -8,
            "y": -2,
            "z": 0,
            "elements": [
                "jaopca:block.chillinium@0"
            ]
        },
        {
            "x": -5,
            "y": -3,
            "z": -3,
            "elements": [
                "nuclearcraft:ingot_block@11"
            ]
        },
        {
            "x": -1,
            "y": -5,
            "z": 9,
            "elements": [
                "thermaldynamics:duct_64@0"
            ]
        },
        {
            "x": -7,
            "y": -8,
            "z": 5,
            "elements": [
                "thermaldynamics:duct_64@0"
            ]
        },
        {
            "x": -2,
            "y": -3,
            "z": 4,
            "elements": [
                "thermaldynamics:duct_64@0"
            ]
        },
        {
            "x": 4,
            "y": -8,
            "z": -4,
            "elements": [
                "jaopca:block.chillinium@0"
            ]
        },
        {
            "x": -4,
            "y": -8,
            "z": 3,
            "elements": [
                "thermaldynamics:duct_64@0"
            ]
        },
        {
            "x": -5,
            "y": -8,
            "z": 0,
            "elements": [
                "thermaldynamics:duct_64@0"
            ]
        },
        {
            "x": 5,
            "y": -5,
            "z": 8,
            "elements": [
                "thermaldynamics:duct_64@0"
            ]
        },
        {
            "x": 4,
            "y": -7,
            "z": 4,
            "elements": [
                "nuclearcraft:ingot_block@11"
            ]
        },
        {
            "x": -10,
            "y": -8,
            "z": 2,
            "elements": [
                "jaopca:block.chillinium@0"
            ]
        },
        {
            "x": -1,
            "y": -6,
            "z": 3,
            "elements": [
                "chisel:blockinvar@5"
            ]
        },
        {
            "x": -7,
            "y": -2,
            "z": 3,
            "elements": [
                "jaopca:block.chillinium@0"
            ]
        },
        {
            "x": -4,
            "y": -5,
            "z": -5,
            "elements": [
                "thermaldynamics:duct_64@0"
            ]
        },
        {
            "x": -10,
            "y": -5,
            "z": 2,
            "elements": [
                "minecraft:sticky_piston@5"
            ]
        },
        {
            "x": -1,
            "y": -7,
            "z": 9,
            "elements": [
                "nuclearcraft:ingot_block@11"
            ]
        },
        {
            "x": 4,
            "y": -2,
            "z": 5,
            "elements": [
                "thermalfoundation:glass_alloy@7"
            ]
        },
        {
            "x": -2,
            "y": -5,
            "z": 9,
            "elements": [
                "thermaldynamics:duct_64@0"
            ]
        },
        {
            "x": 0,
            "y": -2,
            "z": -4,
            "elements": [
                "jaopca:block.chillinium@0"
            ]
        },
        {
            "x": -8,
            "y": -4,
            "z": 0,
            "elements": [
                "chisel:blockinvar@5"
            ]
        },
        {
            "x": 1,
            "y": 0,
            "z": 3,
            "elements": [
                "betterendforge:ancient_emerald_ice@0"
            ]
        },
        {
            "x": -10,
            "y": -6,
            "z": 2,
            "elements": [
                "chisel:blockinvar@5"
            ]
        },
        {
            "x": -2,
            "y": -5,
            "z": 4,
            "elements": [
                "thermaldynamics:duct_64@0"
            ]
        },
        {
            "x": 5,
            "y": -8,
            "z": 8,
            "elements": [
                "thermaldynamics:duct_64@0"
            ]
        },
        {
            "x": 5,
            "y": -8,
            "z": 3,
            "elements": [
                "thermaldynamics:duct_64@0"
            ]
        },
        {
            "x": -2,
            "y": 1,
            "z": 4,
            "elements": [
                "casings_all"
            ]
        },
        {
            "x": 4,
            "y": -4,
            "z": -4,
            "elements": [
                "chisel:blockinvar@5"
            ]
        },
        {
            "x": 0,
            "y": -7,
            "z": 9,
            "elements": [
                "thermalfoundation:fluid_cryotheum@0"
            ]
        },
        {
            "x": -3,
            "y": -5,
            "z": 9,
            "elements": [
                "thermaldynamics:duct_64@0"
            ]
        },
        {
            "x": -3,
            "y": -5,
            "z": -5,
            "elements": [
                "thermaldynamics:duct_64@0"
            ]
        },
        {
            "x": 6,
            "y": -8,
            "z": -4,
            "elements": [
                "thermaldynamics:duct_64@0"
            ]
        },
        {
            "x": 7,
            "y": -7,
            "z": -3,
            "elements": [
                "thermaldynamics:duct_64@0"
            ]
        },
        {
            "x": 3,
            "y": 0,
            "z": 5,
            "elements": [
                "casings_all"
            ]
        },
        {
            "x": 7,
            "y": -5,
            "z": -3,
            "elements": [
                "thermaldynamics:duct_64@0"
            ]
        },
        {
            "x": 0,
            "y": -3,
            "z": 4,
            "elements": [
                "nuclearcraft:ingot_block@11"
            ]
        },
        {
            "x": 4,
            "y": -3,
            "z": -3,
            "elements": [
                "thermalfoundation:fluid_cryotheum@0"
            ]
        },
        {
            "x": -1,
            "y": -5,
            "z": 4,
            "elements": [
                "thermaldynamics:duct_64@0"
            ]
        },
        {
            "x": 5,
            "y": -4,
            "z": 5,
            "elements": [
                "chisel:blockinvar@5"
            ]
        },
        {
            "x": 4,
            "y": -6,
            "z": -4,
            "elements": [
                "chisel:blockinvar@5"
            ]
        },
        {
            "x": 0,
            "y": -5,
            "z": 9,
            "elements": [
                "thermalfoundation:fluid_cryotheum@0"
            ]
        },
        {
            "x": 5,
            "y": -8,
            "z": -4,
            "elements": [
                "thermaldynamics:duct_64@0"
            ]
        },
        {
            "x": 5,
            "y": -3,
            "z": -3,
            "elements": [
                "nuclearcraft:ingot_block@11"
            ]
        },
        {
            "x": -2,
            "y": -1,
            "z": 4,
            "elements": [
                "thermaldynamics:duct_64@0"
            ]
        },
        {
            "x": 2,
            "y": -5,
            "z": 8,
            "elements": [
                "thermaldynamics:duct_64@0"
            ]
        },
        {
            "x": 0,
            "y": -5,
            "z": 4,
            "elements": [
                "minecraft:sticky_piston@2"
            ]
        },
        {
            "x": 5,
            "y": -6,
            "z": 5,
            "elements": [
                "chisel:blockinvar@5"
            ]
        },
        {
            "x": 0,
            "y": -7,
            "z": 4,
            "elements": [
                "nuclearcraft:ingot_block@11"
            ]
        },
        {
            "x": 0,
            "y": -6,
            "z": 3,
            "elements": [
                "thermalfoundation:fluid_cryotheum@0"
            ]
        },
        {
            "x": -5,
            "y": -5,
            "z": 9,
            "elements": [
                "thermaldynamics:duct_64@0"
            ]
        },
        {
            "x": 5,
            "y": -7,
            "z": -3,
            "elements": [
                "nuclearcraft:ingot_block@11"
            ]
        },
        {
            "x": 2,
            "y": -5,
            "z": -3,
            "elements": [
                "thermaldynamics:duct_64@0"
            ]
        },
        {
            "x": 3,
            "y": -8,
            "z": 3,
            "elements": [
                "thermaldynamics:duct_64@0"
            ]
        },
        {
            "x": 0,
            "y": 0,
            "z": 3,
            "elements": [
                "betterendforge:dense_emerald_ice@0"
            ]
        },
        {
            "x": 5,
            "y": -5,
            "z": -3,
            "elements": [
                "thermalfoundation:glass_alloy@7"
            ]
        },
        {
            "x": 0,
            "y": -2,
            "z": 10,
            "elements": [
                "additions:cryonium_block@0"
            ]
        },
        {
            "x": -4,
            "y": -6,
            "z": 5,
            "elements": [
                "thermalfoundation:fluid_cryotheum@0"
            ]
        },
        {
            "x": 0,
            "y": -8,
            "z": -4,
            "elements": [
                "jaopca:block.chillinium@0"
            ]
        },
        {
            "x": 5,
            "y": -8,
            "z": 5,
            "elements": [
                "jaopca:block.chillinium@0"
            ]
        },
        {
            "x": -5,
            "y": -7,
            "z": 9,
            "elements": [
                "thermaldynamics:duct_64@0"
            ]
        },
        {
            "x": -6,
            "y": -5,
            "z": 4,
            "elements": [
                "thermaldynamics:duct_64@0"
            ]
        },
        {
            "x": 0,
            "y": -8,
            "z": 3,
            "elements": [
                "jaopca:block.iciricium@0"
            ]
        },
        {
            "x": 4,
            "y": -2,
            "z": -4,
            "elements": [
                "jaopca:block.chillinium@0"
            ]
        },
        {
            "x": 0,
            "y": -4,
            "z": 10,
            "elements": [
                "thermalfoundation:fluid_cryotheum@0"
            ]
        },
        {
            "x": 1,
            "y": -5,
            "z": 9,
            "elements": [
                "thermaldynamics:duct_64@0"
            ]
        },
        {
            "x": -7,
            "y": -4,
            "z": 2,
            "elements": [
                "thermalfoundation:fluid_cryotheum@0"
            ]
        },
        {
            "x": -2,
            "y": -8,
            "z": 0,
            "elements": [
                "thermaldynamics:duct_64@0"
            ]
        },
        {
            "x": -7,
            "y": -8,
            "z": -1,
            "elements": [
                "thermaldynamics:duct_64@0"
            ]
        },
        {
            "x": -3,
            "y": 0,
            "z": 3,
            "elements": [
                "casings_all"
            ]
        },
        {
            "x": -7,
            "y": -5,
            "z": -1,
            "elements": [
                "thermaldynamics:duct_64@0"
            ]
        },
        {
            "x": -4,
            "y": -4,
            "z": 5,
            "elements": [
                "thermalfoundation:fluid_cryotheum@0"
            ]
        },
        {
            "x": -1,
            "y": -4,
            "z": 3,
            "elements": [
                "chisel:blockinvar@5"
            ]
        },
        {
            "x": -7,
            "y": -5,
            "z": 2,
            "elements": [
                "thermalfoundation:fluid_cryotheum@0"
            ]
        },
        {
            "x": 0,
            "y": -6,
            "z": 10,
            "elements": [
                "thermalfoundation:fluid_cryotheum@0"
            ]
        },
        {
            "x": -10,
            "y": -3,
            "z": 2,
            "elements": [
                "nuclearcraft:ingot_block@11"
            ]
        },
        {
            "x": -4,
            "y": -7,
            "z": 2,
            "elements": [
                "betterendforge:ancient_emerald_ice@0"
            ]
        },
        {
            "x": 0,
            "y": -4,
            "z": -4,
            "elements": [
                "chisel:blockinvar@5"
            ]
        },
        {
            "x": 3,
            "y": -7,
            "z": -3,
            "elements": [
                "nuclearcraft:ingot_block@11"
            ]
        },
        {
            "x": 1,
            "y": -8,
            "z": 3,
            "elements": [
                "jaopca:block.chillinium@0"
            ]
        },
        {
            "x": 4,
            "y": -5,
            "z": -3,
            "elements": [
                "thermalfoundation:fluid_cryotheum@0"
            ]
        },
        {
            "x": 2,
            "y": 1,
            "z": 4,
            "elements": [
                "casings_all"
            ]
        },
        {
            "x": -10,
            "y": -2,
            "z": 2,
            "elements": [
                "jaopca:block.chillinium@0"
            ]
        },
        {
            "x": -1,
            "y": -8,
            "z": 5,
            "elements": [
                "thermaldynamics:duct_64@0"
            ]
        },
        {
            "x": 1,
            "y": -3,
            "z": 9,
            "elements": [
                "nuclearcraft:ingot_block@11"
            ]
        },
        {
            "x": 4,
            "y": -5,
            "z": 9,
            "elements": [
                "thermaldynamics:duct_64@0"
            ]
        },
        {
            "x": -10,
            "y": -4,
            "z": 2,
            "elements": [
                "chisel:blockinvar@5"
            ]
        },
        {
            "x": -8,
            "y": -6,
            "z": 0,
            "elements": [
                "chisel:blockinvar@5"
            ]
        },
        {
            "x": -7,
            "y": -6,
            "z": 2,
            "elements": [
                "thermalfoundation:fluid_cryotheum@0"
            ]
        },
        {
            "x": 4,
            "y": -3,
            "z": 4,
            "elements": [
                "nuclearcraft:ingot_block@11"
            ]
        },
        {
            "x": 0,
            "y": -8,
            "z": 10,
            "elements": [
                "jaopca:block.iciricium@0"
            ]
        },
        {
            "x": -4,
            "y": -8,
            "z": 2,
            "elements": [
                "betterendforge:ancient_emerald_ice@0"
            ]
        },
        {
            "x": -2,
            "y": 0,
            "z": 3,
            "elements": [
                "casings_all"
            ]
        },
        {
            "x": -7,
            "y": -3,
            "z": 2,
            "elements": [
                "thermalfoundation:fluid_cryotheum@0"
            ]
        },
        {
            "x": 1,
            "y": -6,
            "z": 3,
            "elements": [
                "chisel:blockinvar@5"
            ]
        },
        {
            "x": 3,
            "y": -5,
            "z": 4,
            "elements": [
                "thermaldynamics:duct_64@0"
            ]
        },
        {
            "x": 0,
            "y": -2,
            "z": 3,
            "elements": [
                "thermalfoundation:glass_alloy@7"
            ]
        },
        {
            "x": -4,
            "y": -5,
            "z": 2,
            "elements": [
                "betterendforge:ancient_emerald_ice@0"
            ]
        },
        {
            "x": 0,
            "y": -6,
            "z": -4,
            "elements": [
                "chisel:blockinvar@5"
            ]
        },
        {
            "x": 0,
            "y": -4,
            "z": 3,
            "elements": [
                "thermalfoundation:fluid_cryotheum@0"
            ]
        },
        {
            "x": -7,
            "y": -7,
            "z": 2,
            "elements": [
                "thermalfoundation:fluid_cryotheum@0"
            ]
        },
        {
            "x": 1,
            "y": -7,
            "z": 9,
            "elements": [
                "nuclearcraft:ingot_block@11"
            ]
        },
        {
            "x": -7,
            "y": -2,
            "z": 2,
            "elements": [
                "thermalfoundation:glass_alloy@7"
            ]
        },
        {
            "x": 4,
            "y": -7,
            "z": -3,
            "elements": [
                "thermalfoundation:fluid_cryotheum@0"
            ]
        },
        {
            "x": 2,
            "y": -8,
            "z": 3,
            "elements": [
                "thermaldynamics:duct_64@0"
            ]
        },
        {
            "x": 3,
            "y": -5,
            "z": -3,
            "elements": [
                "thermaldynamics:duct_64@0"
            ]
        },
        {
            "x": 4,
            "y": -5,
            "z": 4,
            "elements": [
                "minecraft:sticky_piston@3"
            ]
        },
        {
            "x": -4,
            "y": -8,
            "z": 5,
            "elements": [
                "jaopca:block.iciricium@0"
            ]
        },
        {
            "x": -4,
            "y": -6,
            "z": 2,
            "elements": [
                "betterendforge:ancient_emerald_ice@0"
            ]
        },
        {
            "x": -1,
            "y": 0,
            "z": 3,
            "elements": [
                "betterendforge:ancient_emerald_ice@0"
            ]
        },
        {
            "x": -1,
            "y": -2,
            "z": 3,
            "elements": [
                "jaopca:block.chillinium@0"
            ]
        },
        {
            "x": -7,
            "y": -8,
            "z": 2,
            "elements": [
                "jaopca:block.iciricium@0"
            ]
        },
        {
            "x": -8,
            "y": -8,
            "z": 0,
            "elements": [
                "jaopca:block.chillinium@0"
            ]
        },
        {
            "x": -2,
            "y": -7,
            "z": 2,
            "elements": [
                "nuclearcraft:ingot_block@11"
            ]
        },
        {
            "x": 5,
            "y": -6,
            "z": 9,
            "elements": [
                "thermaldynamics:duct_64@0"
            ]
        },
        {
            "x": -4,
            "y": -4,
            "z": -2,
            "elements": [
                "thermalfoundation:fluid_cryotheum@0"
            ]
        },
        {
            "x": 3,
            "y": -8,
            "z": 8,
            "elements": [
                "thermaldynamics:duct_64@0"
            ]
        },
        {
            "x": 0,
            "y": -6,
            "z": 8,
            "elements": [
                "chisel:blockinvar@5"
            ]
        },
        {
            "x": -3,
            "y": -8,
            "z": 1,
            "elements": [
                "thermaldynamics:duct_64@0"
            ]
        },
        {
            "x": 5,
            "y": -2,
            "z": -2,
            "elements": [
                "thermalfoundation:glass_alloy@7"
            ]
        },
        {
            "x": -2,
            "y": -5,
            "z": -4,
            "elements": [
                "thermaldynamics:duct_64@0"
            ]
        },
        {
            "x": -9,
            "y": -4,
            "z": 1,
            "elements": [
                "chisel:blockinvar@5"
            ]
        },
        {
            "x": -5,
            "y": -5,
            "z": 7,
            "elements": [
                "thermalfoundation:glass_alloy@7"
            ]
        },
        {
            "x": 4,
            "y": -7,
            "z": 7,
            "elements": [
                "thermalfoundation:fluid_cryotheum@0"
            ]
        },
        {
            "x": -4,
            "y": -1,
            "z": 2,
            "elements": [
                "betterendforge:dense_emerald_ice@0"
            ]
        },
        {
            "x": -8,
            "y": -6,
            "z": 1,
            "elements": [
                "thermalfoundation:fluid_cryotheum@0"
            ]
        },
        {
            "x": 0,
            "y": -7,
            "z": -6,
            "elements": [
                "thermalfoundation:fluid_cryotheum@0"
            ]
        },
        {
            "x": 0,
            "y": -4,
            "z": -7,
            "elements": [
                "thermalfoundation:fluid_cryotheum@0"
            ]
        },
        {
            "x": -1,
            "y": -8,
            "z": -2,
            "elements": [
                "thermaldynamics:duct_64@0"
            ]
        },
        {
            "x": -2,
            "y": -5,
            "z": 2,
            "elements": [
                "minecraft:sticky_piston@5"
            ]
        },
        {
            "x": -8,
            "y": -8,
            "z": 1,
            "elements": [
                "jaopca:block.iciricium@0"
            ]
        },
        {
            "x": -1,
            "y": -7,
            "z": 2,
            "elements": [
                "thermalfoundation:fluid_cryotheum@0"
            ]
        },
        {
            "x": 6,
            "y": -8,
            "z": 8,
            "elements": [
                "thermaldynamics:duct_64@0"
            ]
        },
        {
            "x": -4,
            "y": -2,
            "z": -2,
            "elements": [
                "additions:cryonium_block@0"
            ]
        },
        {
            "x": 0,
            "y": -4,
            "z": 8,
            "elements": [
                "chisel:blockinvar@5"
            ]
        },
        {
            "x": 0,
            "y": -7,
            "z": -8,
            "elements": [
                "nuclearcraft:ingot_block@11"
            ]
        },
        {
            "x": 5,
            "y": -4,
            "z": -2,
            "elements": [
                "thermalfoundation:fluid_cryotheum@0"
            ]
        },
        {
            "x": 6,
            "y": -5,
            "z": 4,
            "elements": [
                "thermaldynamics:duct_64@0"
            ]
        },
        {
            "x": -5,
            "y": -3,
            "z": 7,
            "elements": [
                "nuclearcraft:ingot_block@11"
            ]
        },
        {
            "x": 5,
            "y": -5,
            "z": 9,
            "elements": [
                "thermaldynamics:duct_64@0"
            ]
        },
        {
            "x": 0,
            "y": -6,
            "z": -7,
            "elements": [
                "thermalfoundation:fluid_cryotheum@0"
            ]
        },
        {
            "x": -4,
            "y": -3,
            "z": 2,
            "elements": [
                "betterendforge:ancient_emerald_ice@0"
            ]
        },
        {
            "x": -9,
            "y": -2,
            "z": 1,
            "elements": [
                "jaopca:block.chillinium@0"
            ]
        },
        {
            "x": 5,
            "y": -6,
            "z": -2,
            "elements": [
                "thermalfoundation:fluid_cryotheum@0"
            ]
        },
        {
            "x": 0,
            "y": -2,
            "z": -7,
            "elements": [
                "thermalfoundation:glass_alloy@7"
            ]
        },
        {
            "x": 4,
            "y": -3,
            "z": 7,
            "elements": [
                "thermalfoundation:fluid_cryotheum@0"
            ]
        },
        {
            "x": 0,
            "y": -5,
            "z": -6,
            "elements": [
                "thermalfoundation:fluid_cryotheum@0"
            ]
        },
        {
            "x": -5,
            "y": -8,
            "z": 1,
            "elements": [
                "thermaldynamics:duct_64@0"
            ]
        },
        {
            "x": 2,
            "y": -4,
            "z": -2,
            "elements": [
                "chisel:blockinvar@5"
            ]
        },
        {
            "x": 9,
            "y": -6,
            "z": 1,
            "elements": [
                "chisel:blockinvar@5"
            ]
        },
        {
            "x": 0,
            "y": -2,
            "z": 8,
            "elements": [
                "jaopca:block.chillinium@0"
            ]
        },
        {
            "x": 8,
            "y": -5,
            "z": 2,
            "elements": [
                "thermalfoundation:fluid_cryotheum@0"
            ]
        },
        {
            "x": -2,
            "y": -8,
            "z": -4,
            "elements": [
                "thermaldynamics:duct_64@0"
            ]
        },
        {
            "x": 0,
            "y": -5,
            "z": -8,
            "elements": [
                "minecraft:sticky_piston@3"
            ]
        },
        {
            "x": -5,
            "y": -7,
            "z": -1,
            "elements": [
                "nuclearcraft:ingot_block@11"
            ]
        },
        {
            "x": -8,
            "y": -2,
            "z": 1,
            "elements": [
                "thermalfoundation:glass_alloy@7"
            ]
        },
        {
            "x": 5,
            "y": -8,
            "z": -2,
            "elements": [
                "jaopca:block.iciricium@0"
            ]
        },
        {
            "x": 4,
            "y": -5,
            "z": 7,
            "elements": [
                "thermalfoundation:fluid_cryotheum@0"
            ]
        },
        {
            "x": 2,
            "y": -2,
            "z": -2,
            "elements": [
                "jaopca:block.chillinium@0"
            ]
        },
        {
            "x": -5,
            "y": -5,
            "z": -4,
            "elements": [
                "thermaldynamics:duct_64@0"
            ]
        },
        {
            "x": 0,
            "y": -3,
            "z": -6,
            "elements": [
                "thermalfoundation:fluid_cryotheum@1"
            ]
        },
        {
            "x": 5,
            "y": -7,
            "z": 9,
            "elements": [
                "thermaldynamics:duct_64@0"
            ]
        },
        {
            "x": 0,
            "y": -3,
            "z": -8,
            "elements": [
                "nuclearcraft:ingot_block@11"
            ]
        },
        {
            "x": -8,
            "y": -4,
            "z": 1,
            "elements": [
                "thermalfoundation:fluid_cryotheum@0"
            ]
        },
        {
            "x": -5,
            "y": -5,
            "z": -1,
            "elements": [
                "thermaldynamics:duct_64@0"
            ]
        },
        {
            "x": 7,
            "y": -7,
            "z": 7,
            "elements": [
                "thermaldynamics:duct_64@0"
            ]
        },
        {
            "x": 8,
            "y": -7,
            "z": 2,
            "elements": [
                "thermalfoundation:fluid_cryotheum@0"
            ]
        },
        {
            "x": 2,
            "y": -3,
            "z": 2,
            "elements": [
                "nuclearcraft:ingot_block@11"
            ]
        },
        {
            "x": -4,
            "y": -8,
            "z": 8,
            "elements": [
                "jaopca:block.chillinium@0"
            ]
        },
        {
            "x": 2,
            "y": -8,
            "z": -2,
            "elements": [
                "jaopca:block.chillinium@0"
            ]
        },
        {
            "x": -1,
            "y": -2,
            "z": 9,
            "elements": [
                "jaopca:block.chillinium@0"
            ]
        },
        {
            "x": -4,
            "y": -6,
            "z": 8,
            "elements": [
                "chisel:blockinvar@5"
            ]
        },
        {
            "x": 3,
            "y": -6,
            "z": -2,
            "elements": [
                "thermalfoundation:fluid_cryotheum@0"
            ]
        },
        {
            "x": 0,
            "y": -4,
            "z": -2,
            "elements": [
                "betterendforge:ancient_emerald_ice@0"
            ]
        },
        {
            "x": 4,
            "y": -5,
            "z": -1,
            "elements": [
                "thermalfoundation:fluid_cryotheum@0"
            ]
        },
        {
            "x": 9,
            "y": -2,
            "z": 1,
            "elements": [
                "jaopca:block.chillinium@0"
            ]
        },
        {
            "x": 1,
            "y": 0,
            "z": 1,
            "elements": [
                "betterendforge:ancient_emerald_ice@0"
            ]
        },
        {
            "x": 7,
            "y": -5,
            "z": 7,
            "elements": [
                "thermaldynamics:duct_64@0"
            ]
        },
        {
            "x": 9,
            "y": -8,
            "z": 1,
            "elements": [
                "jaopca:block.chillinium@0"
            ]
        },
        {
            "x": 2,
            "y": -5,
            "z": 9,
            "elements": [
                "thermaldynamics:duct_64@0"
            ]
        },
        {
            "x": -1,
            "y": -3,
            "z": 9,
            "elements": [
                "nuclearcraft:ingot_block@11"
            ]
        },
        {
            "x": 0,
            "y": -1,
            "z": 2,
            "elements": [
                "betterendforge:dense_emerald_ice@0"
            ]
        },
        {
            "x": -1,
            "y": -3,
            "z": 2,
            "elements": [
                "thermalfoundation:fluid_cryotheum@0"
            ]
        },
        {
            "x": -5,
            "y": -3,
            "z": -1,
            "elements": [
                "nuclearcraft:ingot_block@11"
            ]
        },
        {
            "x": 3,
            "y": -8,
            "z": -2,
            "elements": [
                "jaopca:block.iciricium@0"
            ]
        },
        {
            "x": 2,
            "y": -5,
            "z": 2,
            "elements": [
                "minecraft:sticky_piston@4"
            ]
        },
        {
            "x": 5,
            "y": -8,
            "z": 9,
            "elements": [
                "thermaldynamics:duct_64@0"
            ]
        },
        {
            "x": 4,
            "y": -4,
            "z": 6,
            "elements": [
                "thermalfoundation:fluid_cryotheum@0"
            ]
        },
        {
            "x": 9,
            "y": -4,
            "z": 1,
            "elements": [
                "chisel:blockinvar@5"
            ]
        },
        {
            "x": 2,
            "y": -8,
            "z": 8,
            "elements": [
                "thermaldynamics:duct_64@0"
            ]
        },
        {
            "x": -4,
            "y": -4,
            "z": 8,
            "elements": [
                "chisel:blockinvar@5"
            ]
        },
        {
            "x": 2,
            "y": -6,
            "z": -2,
            "elements": [
                "chisel:blockinvar@5"
            ]
        },
        {
            "x": 0,
            "y": -2,
            "z": -2,
            "elements": [
                "betterendforge:ancient_emerald_ice@0"
            ]
        },
        {
            "x": -4,
            "y": -8,
            "z": 6,
            "elements": [
                "jaopca:block.iciricium@0"
            ]
        },
        {
            "x": -5,
            "y": -8,
            "z": -3,
            "elements": [
                "jaopca:block.chillinium@0"
            ]
        },
        {
            "x": -4,
            "y": -8,
            "z": 9,
            "elements": [
                "thermaldynamics:duct_64@0"
            ]
        },
        {
            "x": 4,
            "y": -6,
            "z": 6,
            "elements": [
                "thermalfoundation:fluid_cryotheum@0"
            ]
        },
        {
            "x": 4,
            "y": -7,
            "z": -1,
            "elements": [
                "thermalfoundation:fluid_cryotheum@0"
            ]
        },
        {
            "x": 7,
            "y": -8,
            "z": 6,
            "elements": [
                "thermaldynamics:duct_64@0"
            ]
        },
        {
            "x": 0,
            "y": -3,
            "z": 2,
            "elements": [
                "thermalfoundation:fluid_cryotheum@0"
            ]
        },
        {
            "x": 4,
            "y": -8,
            "z": -2,
            "elements": [
                "jaopca:block.iciricium@0"
            ]
        },
        {
            "x": 1,
            "y": -5,
            "z": 2,
            "elements": [
                "thermalfoundation:fluid_cryotheum@0"
            ]
        },
        {
            "x": -7,
            "y": -7,
            "z": 7,
            "elements": [
                "thermaldynamics:duct_64@0"
            ]
        },
        {
            "x": -5,
            "y": -8,
            "z": -4,
            "elements": [
                "thermaldynamics:duct_64@0"
            ]
        },
        {
            "x": 2,
            "y": -7,
            "z": 2,
            "elements": [
                "nuclearcraft:ingot_block@11"
            ]
        },
        {
            "x": -7,
            "y": -8,
            "z": 6,
            "elements": [
                "thermaldynamics:duct_64@0"
            ]
        },
        {
            "x": -5,
            "y": -7,
            "z": -3,
            "elements": [
                "nuclearcraft:ingot_block@11"
            ]
        },
        {
            "x": -2,
            "y": -4,
            "z": -2,
            "elements": [
                "chisel:blockinvar@5"
            ]
        },
        {
            "x": 4,
            "y": -1,
            "z": -1,
            "elements": [
                "betterendforge:ancient_emerald_ice@0"
            ]
        },
        {
            "x": -4,
            "y": -2,
            "z": 8,
            "elements": [
                "jaopca:block.chillinium@0"
            ]
        },
        {
            "x": 3,
            "y": -2,
            "z": -2,
            "elements": [
                "thermalfoundation:glass_alloy@7"
            ]
        },
        {
            "x": 0,
            "y": -8,
            "z": -7,
            "elements": [
                "jaopca:block.iciricium@0"
            ]
        },
        {
            "x": -5,
            "y": -6,
            "z": -3,
            "elements": [
                "chisel:blockinvar@5"
            ]
        },
        {
            "x": 1,
            "y": -3,
            "z": 2,
            "elements": [
                "thermalfoundation:fluid_cryotheum@0"
            ]
        },
        {
            "x": -1,
            "y": -8,
            "z": 9,
            "elements": [
                "jaopca:block.chillinium@0"
            ]
        },
        {
            "x": 4,
            "y": -5,
            "z": 2,
            "elements": [
                "betterendforge:ancient_emerald_ice@0"
            ]
        },
        {
            "x": 1,
            "y": -8,
            "z": -2,
            "elements": [
                "thermaldynamics:duct_64@0"
            ]
        },
        {
            "x": 1,
            "y": -8,
            "z": 8,
            "elements": [
                "thermaldynamics:duct_64@0"
            ]
        },
        {
            "x": 1,
            "y": -7,
            "z": 2,
            "elements": [
                "thermalfoundation:fluid_cryotheum@0"
            ]
        },
        {
            "x": 4,
            "y": -6,
            "z": -2,
            "elements": [
                "thermalfoundation:fluid_cryotheum@0"
            ]
        },
        {
            "x": -5,
            "y": -5,
            "z": -3,
            "elements": [
                "thermalfoundation:glass_alloy@7"
            ]
        },
        {
            "x": -4,
            "y": -5,
            "z": 9,
            "elements": [
                "thermaldynamics:duct_64@0"
            ]
        },
        {
            "x": -1,
            "y": -4,
            "z": 9,
            "elements": [
                "chisel:blockinvar@5"
            ]
        },
        {
            "x": -7,
            "y": -6,
            "z": 3,
            "elements": [
                "chisel:blockinvar@5"
            ]
        },
        {
            "x": 7,
            "y": -5,
            "z": -1,
            "elements": [
                "thermaldynamics:duct_64@0"
            ]
        },
        {
            "x": 4,
            "y": -2,
            "z": 6,
            "elements": [
                "additions:cryonium_block@0"
            ]
        },
        {
            "x": -2,
            "y": -2,
            "z": -2,
            "elements": [
                "jaopca:block.chillinium@0"
            ]
        },
        {
            "x": 3,
            "y": -4,
            "z": -2,
            "elements": [
                "thermalfoundation:fluid_cryotheum@0"
            ]
        },
        {
            "x": 4,
            "y": -3,
            "z": -1,
            "elements": [
                "thermalfoundation:fluid_cryotheum@0"
            ]
        },
        {
            "x": 6,
            "y": -8,
            "z": 1,
            "elements": [
                "thermaldynamics:duct_64@0"
            ]
        },
        {
            "x": -2,
            "y": -3,
            "z": 2,
            "elements": [
                "nuclearcraft:ingot_block@11"
            ]
        },
        {
            "x": -5,
            "y": -7,
            "z": 7,
            "elements": [
                "nuclearcraft:ingot_block@11"
            ]
        },
        {
            "x": -5,
            "y": -4,
            "z": -3,
            "elements": [
                "chisel:blockinvar@5"
            ]
        },
        {
            "x": 4,
            "y": -7,
            "z": 2,
            "elements": [
                "betterendforge:ancient_emerald_ice@0"
            ]
        },
        {
            "x": 0,
            "y": -8,
            "z": 8,
            "elements": [
                "jaopca:block.chillinium@0"
            ]
        },
        {
            "x": -1,
            "y": -5,
            "z": 2,
            "elements": [
                "thermalfoundation:fluid_cryotheum@0"
            ]
        },
        {
            "x": -7,
            "y": -7,
            "z": 3,
            "elements": [
                "nuclearcraft:ingot_block@11"
            ]
        },
        {
            "x": -6,
            "y": -5,
            "z": 0,
            "elements": [
                "thermaldynamics:duct_64@0"
            ]
        },
        {
            "x": 2,
            "y": -5,
            "z": -6,
            "elements": [
                "minecraft:sticky_piston@4"
            ]
        },
        {
            "x": -3,
            "y": 0,
            "z": 1,
            "elements": [
                "casings_all"
            ]
        },
        {
            "x": -9,
            "y": -5,
            "z": 2,
            "elements": [
                "thermalfoundation:fluid_cryotheum@0"
            ]
        },
        {
            "x": -5,
            "y": -5,
            "z": -5,
            "elements": [
                "thermaldynamics:duct_64@0"
            ]
        },
        {
            "x": 4,
            "y": -4,
            "z": -2,
            "elements": [
                "thermalfoundation:fluid_cryotheum@0"
            ]
        },
        {
            "x": 3,
            "y": -5,
            "z": 7,
            "elements": [
                "thermaldynamics:duct_64@0"
            ]
        },
        {
            "x": -5,
            "y": -8,
            "z": 6,
            "elements": [
                "jaopca:block.iciricium@0"
            ]
        },
        {
            "x": 9,
            "y": -5,
            "z": 3,
            "elements": [
                "thermalfoundation:glass_alloy@7"
            ]
        },
        {
            "x": 0,
            "y": -6,
            "z": 1,
            "elements": [
                "thermalfoundation:fluid_cryotheum@0"
            ]
        },
        {
            "x": 9,
            "y": -4,
            "z": 3,
            "elements": [
                "chisel:blockinvar@5"
            ]
        },
        {
            "x": 6,
            "y": -5,
            "z": 2,
            "elements": [
                "minecraft:sticky_piston@5"
            ]
        },
        {
            "x": 5,
            "y": -7,
            "z": -1,
            "elements": [
                "nuclearcraft:ingot_block@11"
            ]
        },
        {
            "x": 1,
            "y": -6,
            "z": -7,
            "elements": [
                "chisel:blockinvar@5"
            ]
        },
        {
            "x": -1,
            "y": -4,
            "z": 1,
            "elements": [
                "chisel:blockinvar@5"
            ]
        },
        {
            "x": -5,
            "y": -8,
            "z": 8,
            "elements": [
                "thermaldynamics:duct_64@0"
            ]
        },
        {
            "x": 0,
            "y": -3,
            "z": 12,
            "elements": [
                "nuclearcraft:ingot_block@11"
            ]
        },
        {
            "x": 5,
            "y": -8,
            "z": 1,
            "elements": [
                "thermaldynamics:duct_64@0"
            ]
        },
        {
            "x": -4,
            "y": -7,
            "z": 7,
            "elements": [
                "thermalfoundation:fluid_cryotheum@0"
            ]
        },
        {
            "x": 5,
            "y": -6,
            "z": 6,
            "elements": [
                "thermalfoundation:fluid_cryotheum@0"
            ]
        },
        {
            "x": 9,
            "y": -3,
            "z": 3,
            "elements": [
                "nuclearcraft:ingot_block@11"
            ]
        },
        {
            "x": -5,
            "y": -7,
            "z": -5,
            "elements": [
                "thermaldynamics:duct_64@0"
            ]
        },
        {
            "x": 7,
            "y": -8,
            "z": -2,
            "elements": [
                "thermaldynamics:duct_64@0"
            ]
        },
        {
            "x": 2,
            "y": -2,
            "z": 6,
            "elements": [
                "jaopca:block.chillinium@0"
            ]
        },
        {
            "x": 5,
            "y": -5,
            "z": -1,
            "elements": [
                "thermaldynamics:duct_64@0"
            ]
        },
        {
            "x": -9,
            "y": -7,
            "z": 2,
            "elements": [
                "thermalfoundation:fluid_cryotheum@0"
            ]
        },
        {
            "x": 3,
            "y": -3,
            "z": 7,
            "elements": [
                "nuclearcraft:ingot_block@11"
            ]
        },
        {
            "x": 0,
            "y": 0,
            "z": 1,
            "elements": [
                "betterendforge:dense_emerald_ice@0"
            ]
        },
        {
            "x": -6,
            "y": -8,
            "z": 5,
            "elements": [
                "thermaldynamics:duct_64@0"
            ]
        },
        {
            "x": 2,
            "y": -3,
            "z": -6,
            "elements": [
                "nuclearcraft:ingot_block@11"
            ]
        },
        {
            "x": 4,
            "y": -2,
            "z": -2,
            "elements": [
                "additions:cryonium_block@0"
            ]
        },
        {
            "x": -5,
            "y": -6,
            "z": -5,
            "elements": [
                "thermaldynamics:duct_64@0"
            ]
        },
        {
            "x": -7,
            "y": -8,
            "z": 3,
            "elements": [
                "jaopca:block.chillinium@0"
            ]
        },
        {
            "x": 6,
            "y": -7,
            "z": 2,
            "elements": [
                "nuclearcraft:ingot_block@11"
            ]
        },
        {
            "x": 9,
            "y": -2,
            "z": 3,
            "elements": [
                "jaopca:block.chillinium@0"
            ]
        },
        {
            "x": 5,
            "y": -7,
            "z": 7,
            "elements": [
                "nuclearcraft:ingot_block@11"
            ]
        },
        {
            "x": -6,
            "y": -8,
            "z": 0,
            "elements": [
                "thermaldynamics:duct_64@0"
            ]
        },
        {
            "x": 5,
            "y": -4,
            "z": 6,
            "elements": [
                "thermalfoundation:fluid_cryotheum@0"
            ]
        },
        {
            "x": 1,
            "y": -4,
            "z": -7,
            "elements": [
                "chisel:blockinvar@5"
            ]
        },
        {
            "x": 0,
            "y": -8,
            "z": 1,
            "elements": [
                "jaopca:block.iciricium@0"
            ]
        },
        {
            "x": -2,
            "y": -8,
            "z": 8,
            "elements": [
                "thermaldynamics:duct_64@0"
            ]
        },
        {
            "x": 0,
            "y": -7,
            "z": 2,
            "elements": [
                "thermalfoundation:fluid_cryotheum@0"
            ]
        },
        {
            "x": -1,
            "y": 0,
            "z": 1,
            "elements": [
                "betterendforge:ancient_emerald_ice@0"
            ]
        },
        {
            "x": -1,
            "y": -3,
            "z": -6,
            "elements": [
                "thermalfoundation:fluid_cryotheum@0"
            ]
        },
        {
            "x": -1,
            "y": -2,
            "z": 1,
            "elements": [
                "jaopca:block.chillinium@0"
            ]
        },
        {
            "x": -6,
            "y": -5,
            "z": 5,
            "elements": [
                "thermaldynamics:duct_64@0"
            ]
        },
        {
            "x": -4,
            "y": -6,
            "z": 6,
            "elements": [
                "thermalfoundation:fluid_cryotheum@0"
            ]
        },
        {
            "x": -4,
            "y": -3,
            "z": 7,
            "elements": [
                "thermalfoundation:fluid_cryotheum@0"
            ]
        },
        {
            "x": 3,
            "y": -7,
            "z": -1,
            "elements": [
                "nuclearcraft:ingot_block@11"
            ]
        },
        {
            "x": 2,
            "y": -5,
            "z": -1,
            "elements": [
                "thermaldynamics:duct_64@0"
            ]
        },
        {
            "x": 1,
            "y": -4,
            "z": 1,
            "elements": [
                "chisel:blockinvar@5"
            ]
        },
        {
            "x": 4,
            "y": -8,
            "z": 6,
            "elements": [
                "jaopca:block.iciricium@0"
            ]
        },
        {
            "x": 2,
            "y": -7,
            "z": -6,
            "elements": [
                "nuclearcraft:ingot_block@11"
            ]
        },
        {
            "x": 2,
            "y": -4,
            "z": 6,
            "elements": [
                "chisel:blockinvar@5"
            ]
        },
        {
            "x": 0,
            "y": -5,
            "z": 2,
            "elements": [
                "thermalfoundation:fluid_cryotheum@0"
            ]
        },
        {
            "x": 3,
            "y": -8,
            "z": 1,
            "elements": [
                "thermaldynamics:duct_64@0"
            ]
        },
        {
            "x": -7,
            "y": -5,
            "z": 7,
            "elements": [
                "thermaldynamics:duct_64@0"
            ]
        },
        {
            "x": 4,
            "y": -8,
            "z": 8,
            "elements": [
                "jaopca:block.chillinium@0"
            ]
        },
        {
            "x": -2,
            "y": 0,
            "z": 1,
            "elements": [
                "casings_all"
            ]
        },
        {
            "x": 0,
            "y": -2,
            "z": 1,
            "elements": [
                "thermalfoundation:glass_alloy@7"
            ]
        },
        {
            "x": -1,
            "y": -5,
            "z": -6,
            "elements": [
                "thermalfoundation:fluid_cryotheum@0"
            ]
        },
        {
            "x": -5,
            "y": -6,
            "z": 6,
            "elements": [
                "thermalfoundation:fluid_cryotheum@0"
            ]
        },
        {
            "x": 3,
            "y": -5,
            "z": -1,
            "elements": [
                "thermaldynamics:duct_64@0"
            ]
        },
        {
            "x": -2,
            "y": -8,
            "z": 6,
            "elements": [
                "jaopca:block.chillinium@0"
            ]
        },
        {
            "x": 0,
            "y": -7,
            "z": 12,
            "elements": [
                "nuclearcraft:ingot_block@11"
            ]
        },
        {
            "x": -4,
            "y": -5,
            "z": 7,
            "elements": [
                "thermalfoundation:fluid_cryotheum@0"
            ]
        },
        {
            "x": 2,
            "y": -6,
            "z": 6,
            "elements": [
                "chisel:blockinvar@5"
            ]
        },
        {
            "x": 1,
            "y": -8,
            "z": -7,
            "elements": [
                "jaopca:block.chillinium@0"
            ]
        },
        {
            "x": -5,
            "y": -4,
            "z": 6,
            "elements": [
                "thermalfoundation:fluid_cryotheum@0"
            ]
        },
        {
            "x": 5,
            "y": -8,
            "z": 6,
            "elements": [
                "jaopca:block.iciricium@0"
            ]
        },
        {
            "x": 0,
            "y": -5,
            "z": 12,
            "elements": [
                "minecraft:sticky_piston@2"
            ]
        },
        {
            "x": 0,
            "y": -4,
            "z": 1,
            "elements": [
                "thermalfoundation:fluid_cryotheum@0"
            ]
        },
        {
            "x": -6,
            "y": -3,
            "z": 2,
            "elements": [
                "nuclearcraft:ingot_block@11"
            ]
        },
        {
            "x": 1,
            "y": -2,
            "z": 1,
            "elements": [
                "jaopca:block.chillinium@0"
            ]
        },
        {
            "x": -6,
            "y": -7,
            "z": 2,
            "elements": [
                "nuclearcraft:ingot_block@11"
            ]
        },
        {
            "x": 4,
            "y": -6,
            "z": 8,
            "elements": [
                "chisel:blockinvar@5"
            ]
        },
        {
            "x": 1,
            "y": 0,
            "z": 5,
            "elements": [
                "casings_upgrade"
            ]
        },
        {
            "x": -1,
            "y": -8,
            "z": 6,
            "elements": [
                "thermaldynamics:duct_64@0"
            ]
        },

        {
            "x": 1,
            "y": -3,
            "z": -6,
            "elements": [
                "thermalfoundation:fluid_cryotheum@0"
            ]
        },
        {
            "x": 3,
            "y": -5,
            "z": 5,
            "elements": [
                "thermaldynamics:duct_64@0"
            ]
        },
        {
            "x": 3,
            "y": -3,
            "z": -1,
            "elements": [
                "nuclearcraft:ingot_block@11"
            ]
        },
        {
            "x": 1,
            "y": -8,
            "z": -5,
            "elements": [
                "jaopca:block.chillinium@0"
            ]
        },
        {
            "x": -5,
            "y": -8,
            "z": -2,
            "elements": [
                "jaopca:block.iciricium@0"
            ]
        },
        {
            "x": -5,
            "y": -2,
            "z": 6,
            "elements": [
                "thermalfoundation:glass_alloy@7"
            ]
        },
        {
            "x": -4,
            "y": -5,
            "z": -1,
            "elements": [
                "thermalfoundation:fluid_cryotheum@0"
            ]
        },
        {
            "x": -4,
            "y": -4,
            "z": 6,
            "elements": [
                "thermalfoundation:fluid_cryotheum@0"
            ]
        },
        {
            "x": 9,
            "y": -7,
            "z": 2,
            "elements": [
                "thermalfoundation:fluid_cryotheum@0"
            ]
        },
        {
            "x": 1,
            "y": -8,
            "z": 1,
            "elements": [
                "jaopca:block.chillinium@0"
            ]
        },
        {
            "x": -4,
            "y": -6,
            "z": -2,
            "elements": [
                "thermalfoundation:fluid_cryotheum@0"
            ]
        },
        {
            "x": -9,
            "y": -3,
            "z": 2,
            "elements": [
                "thermalfoundation:fluid_cryotheum@0"
            ]
        },
        {
            "x": 3,
            "y": -4,
            "z": 5,
            "elements": [
                "chisel:blockinvar@5"
            ]
        },
        {
            "x": -6,
            "y": -5,
            "z": 2,
            "elements": [
                "minecraft:sticky_piston@4"
            ]
        },
        {
            "x": 1,
            "y": -5,
            "z": -6,
            "elements": [
                "thermalfoundation:fluid_cryotheum@0"
            ]
        },
        {
            "x": 1,
            "y": -2,
            "z": -7,
            "elements": [
                "jaopca:block.chillinium@0"
            ]
        },
        {
            "x": 4,
            "y": -4,
            "z": 8,
            "elements": [
                "chisel:blockinvar@5"
            ]
        },
        {
            "x": 8,
            "y": -3,
            "z": 2,
            "elements": [
                "thermalfoundation:fluid_cryotheum@0"
            ]
        },
        {
            "x": -5,
            "y": -8,
            "z": -5,
            "elements": [
                "thermaldynamics:duct_64@0"
            ]
        },
        {
            "x": 1,
            "y": -6,
            "z": 1,
            "elements": [
                "chisel:blockinvar@5"
            ]
        },
        {
            "x": 9,
            "y": -5,
            "z": 2,
            "elements": [
                "thermalfoundation:fluid_cryotheum@0"
            ]
        },
        {
            "x": -2,
            "y": -2,
            "z": 6,
            "elements": [
                "jaopca:block.chillinium@0"
            ]
        },
        {
            "x": 3,
            "y": -3,
            "z": 5,
            "elements": [
                "nuclearcraft:ingot_block@11"
            ]
        },
        {
            "x": -2,
            "y": -5,
            "z": 7,
            "elements": [
                "thermaldynamics:duct_64@0"
            ]
        },
        {
            "x": -4,
            "y": -7,
            "z": -1,
            "elements": [
                "thermalfoundation:fluid_cryotheum@0"
            ]
        },
        {
            "x": -5,
            "y": -6,
            "z": -2,
            "elements": [
                "thermalfoundation:fluid_cryotheum@0"
            ]
        },
        {
            "x": 3,
            "y": -6,
            "z": 5,
            "elements": [
                "chisel:blockinvar@5"
            ]
        },
        {
            "x": -4,
            "y": -8,
            "z": -2,
            "elements": [
                "jaopca:block.iciricium@0"
            ]
        },
        {
            "x": 4,
            "y": -8,
            "z": 1,
            "elements": [
                "thermaldynamics:duct_64@0"
            ]
        },
        {
            "x": 6,
            "y": -5,
            "z": -1,
            "elements": [
                "thermaldynamics:duct_64@0"
            ]
        },
        {
            "x": 1,
            "y": -8,
            "z": 6,
            "elements": [
                "thermaldynamics:duct_64@0"
            ]
        },
        {
            "x": 1,
            "y": -5,
            "z": -5,
            "elements": [
                "thermaldynamics:duct_64@0"
            ]
        },
        {
            "x": -5,
            "y": -2,
            "z": -2,
            "elements": [
                "thermalfoundation:glass_alloy@7"
            ]
        },
        {
            "x": 3,
            "y": -2,
            "z": 5,
            "elements": [
                "jaopca:block.chillinium@0"
            ]
        },
        {
            "x": -4,
            "y": -1,
            "z": -1,
            "elements": [
                "betterendforge:ancient_emerald_ice@0"
            ]
        },
        {
            "x": 3,
            "y": 0,
            "z": 1,
            "elements": [
                "casings_all"
            ]
        },
        {
            "x": 9,
            "y": -3,
            "z": 2,
            "elements": [
                "thermalfoundation:fluid_cryotheum@0"
            ]
        },
        {
            "x": 7,
            "y": -8,
            "z": 1,
            "elements": [
                "jaopca:block.chillinium@0"
            ]
        },
        {
            "x": -3,
            "y": -5,
            "z": 7,
            "elements": [
                "thermaldynamics:duct_64@0"
            ]
        },
        {
            "x": -2,
            "y": -4,
            "z": 6,
            "elements": [
                "chisel:blockinvar@5"
            ]
        },
        {
            "x": -7,
            "y": -8,
            "z": -2,
            "elements": [
                "thermaldynamics:duct_64@0"
            ]
        },
        {
            "x": -3,
            "y": -2,
            "z": 6,
            "elements": [
                "thermalfoundation:glass_alloy@7"
            ]
        },
        {
            "x": -3,
            "y": -3,
            "z": -1,
            "elements": [
                "nuclearcraft:ingot_block@11"
            ]
        },
        {
            "x": -2,
            "y": -6,
            "z": -2,
            "elements": [
                "chisel:blockinvar@5"
            ]
        },
        {
            "x": 1,
            "y": -4,
            "z": -5,
            "elements": [
                "chisel:blockinvar@5"
            ]
        },
        {
            "x": -5,
            "y": -4,
            "z": -2,
            "elements": [
                "thermalfoundation:fluid_cryotheum@0"
            ]
        },
        {
            "x": 1,
            "y": -7,
            "z": -5,
            "elements": [
                "nuclearcraft:ingot_block@11"
            ]
        },
        {
            "x": -1,
            "y": -2,
            "z": -7,
            "elements": [
                "jaopca:block.chillinium@0"
            ]
        },
        {
            "x": 2,
            "y": -8,
            "z": 6,
            "elements": [
                "jaopca:block.chillinium@0"
            ]
        },
        {
            "x": -2,
            "y": -5,
            "z": -5,
            "elements": [
                "thermaldynamics:duct_64@0"
            ]
        },
        {
            "x": -3,
            "y": -3,
            "z": 7,
            "elements": [
                "nuclearcraft:ingot_block@11"
            ]
        },
        {
            "x": 2,
            "y": 0,
            "z": 1,
            "elements": [
                "casings_all"
            ]
        },
        {
            "x": 6,
            "y": -3,
            "z": 2,
            "elements": [
                "nuclearcraft:ingot_block@11"
            ]
        },
        {
            "x": 3,
            "y": -7,
            "z": 7,
            "elements": [
                "nuclearcraft:ingot_block@11"
            ]
        },
        {
            "x": -4,
            "y": -2,
            "z": 6,
            "elements": [
                "additions:cryonium_block@0"
            ]
        },
        {
            "x": 4,
            "y": -2,
            "z": 8,
            "elements": [
                "jaopca:block.chillinium@0"
            ]
        },
        {
            "x": 4,
            "y": -8,
            "z": -5,
            "elements": [
                "thermaldynamics:duct_64@0"
            ]
        },
        {
            "x": -4,
            "y": -3,
            "z": -1,
            "elements": [
                "thermalfoundation:fluid_cryotheum@0"
            ]
        },
        {
            "x": -2,
            "y": -6,
            "z": 6,
            "elements": [
                "chisel:blockinvar@5"
            ]
        },
        {
            "x": 7,
            "y": -6,
            "z": 1,
            "elements": [
                "chisel:blockinvar@5"
            ]
        },
        {
            "x": -2,
            "y": -8,
            "z": 1,
            "elements": [
                "thermaldynamics:duct_64@0"
            ]
        },
        {
            "x": 1,
            "y": -6,
            "z": -5,
            "elements": [
                "chisel:blockinvar@5"
            ]
        },
        {
            "x": -2,
            "y": -8,
            "z": -2,
            "elements": [
                "jaopca:block.chillinium@0"
            ]
        },
        {
            "x": 6,
            "y": -7,
            "z": 6,
            "elements": [
                "nuclearcraft:ingot_block@11"
            ]
        },
        {
            "x": -3,
            "y": -5,
            "z": 6,
            "elements": [
                "thermalfoundation:fluid_cryotheum@0"
            ]
        },
        {
            "x": -6,
            "y": -6,
            "z": 6,
            "elements": [
                "chisel:blockinvar@5"
            ]
        },
        {
            "x": -3,
            "y": -8,
            "z": -1,
            "elements": [
                "jaopca:block.chillinium@0"
            ]
        },
        {
            "x": 0,
            "y": -3,
            "z": 6,
            "elements": [
                "betterendforge:ancient_emerald_ice@0"
            ]
        },
        {
            "x": -1,
            "y": -6,
            "z": 11,
            "elements": [
                "chisel:blockinvar@5"
            ]
        },
        {
            "x": -4,
            "y": -8,
            "z": -3,
            "elements": [
                "jaopca:block.iciricium@0"
            ]
        },
        {
            "x": -2,
            "y": -5,
            "z": 10,
            "elements": [
                "minecraft:sticky_piston@5"
            ]
        },
        {
            "x": -7,
            "y": -6,
            "z": -3,
            "elements": [
                "thermaldynamics:duct_64@0"
            ]
        },
        {
            "x": 5,
            "y": -8,
            "z": -5,
            "elements": [
                "thermaldynamics:duct_64@0"
            ]
        },
        {
            "x": 6,
            "y": -8,
            "z": 6,
            "elements": [
                "jaopca:block.chillinium@0"
            ]
        },
        {
            "x": -3,
            "y": -6,
            "z": 6,
            "elements": [
                "thermalfoundation:fluid_cryotheum@0"
            ]
        },
        {
            "x": -4,
            "y": -6,
            "z": 4,
            "elements": [
                "chisel:blockinvar@5"
            ]
        },
        {
            "x": 2,
            "y": -5,
            "z": 0,
            "elements": [
                "thermaldynamics:duct_64@0"
            ]
        },
        {
            "x": -3,
            "y": -7,
            "z": -1,
            "elements": [
                "nuclearcraft:ingot_block@11"
            ]
        },
        {
            "x": 0,
            "y": -4,
            "z": 6,
            "elements": [
                "betterendforge:ancient_emerald_ice@0"
            ]
        },
        {
            "x": 0,
            "y": -5,
            "z": 6,
            "elements": [
                "betterendforge:ancient_emerald_ice@0"
            ]
        },
        {
            "x": 3,
            "y": -7,
            "z": 6,
            "elements": [
                "thermalfoundation:fluid_cryotheum@0"
            ]
        },
        {
            "x": -1,
            "y": -8,
            "z": 11,
            "elements": [
                "jaopca:block.chillinium@0"
            ]
        },
        {
            "x": -1,
            "y": -8,
            "z": -3,
            "elements": [
                "thermaldynamics:duct_64@0"
            ]
        },
        {
            "x": -3,
            "y": -3,
            "z": 6,
            "elements": [
                "thermalfoundation:fluid_cryotheum@0"
            ]
        },
        {
            "x": -6,
            "y": -2,
            "z": 6,
            "elements": [
                "jaopca:block.chillinium@0"
            ]
        },
        {
            "x": 0,
            "y": -8,
            "z": 6,
            "elements": [
                "betterendforge:ancient_emerald_ice@0"
            ]
        },
        {
            "x": -2,
            "y": 1,
            "z": 0,
            "elements": [
                "casings_all"
            ]
        },
        {
            "x": -3,
            "y": -6,
            "z": -1,
            "elements": [
                "chisel:blockinvar@5"
            ]
        },
        {
            "x": -3,
            "y": -4,
            "z": 6,
            "elements": [
                "thermalfoundation:fluid_cryotheum@0"
            ]
        },
        {
            "x": -4,
            "y": -1,
            "z": 5,
            "elements": [
                "betterendforge:ancient_emerald_ice@0"
            ]
        },
        {
            "x": -4,
            "y": -8,
            "z": 4,
            "elements": [
                "jaopca:block.chillinium@0"
            ]
        },
        {
            "x": -3,
            "y": -5,
            "z": -1,
