{
    "registryname": "elysia_crusher",
    "localizedname": "§cELYSIA单元 - 大型粉碎单元",
    "requires-blueprint": false,
    "failure-action": "still",
    "color": "7b7b7b",
    "modifiers": [
        {
            "elements": "modularmachinery:blockcasing@1",
            "x": -1,
            "y": 0,
            "z": 0,
            "description": "将控制器右方紧挨着的方块换成此方块以降低配方制作时间至75%！",
            "modifier": {
                "io": "input",
                "target": "modularmachinery:duration",
                "operation": 1,
                "multiplier": 0.75
            }
        },
        {
            "elements": "modularmachinery:blockcasing@2",
            "x": -1,
            "y": 0,
            "z": 0,
            "description": "将控制器右方紧挨着的方块换成此方块以降低配方制作时间至66%！",
            "modifier": {
                "io": "input",
                "target": "modularmachinery:duration",
                "operation": 1,
                "multiplier": 0.66
            }
        },
        {
            "elements": "modularmachinery:blockcasing@3",
            "x": -1,
            "y": 0,
            "z": 0,
            "description": "将控制器右方紧挨着的方块换成此方块以降低配方制作时间至50%！",
            "modifier": {
                "io": "input",
                "target": "modularmachinery:duration",
                "operation": 1,
                "multiplier": 0.5
            }
        },
        {
            "elements": "modularmachinery:blockcasing@5",
            "x": -1,
            "y": 0,
            "z": 0,
            "description": "将控制器右方紧挨着的方块换成此方块以降低配方制作时间至33%！",
            "modifier": {
                "io": "input",
                "target": "modularmachinery:duration",
                "operation": 1,
                "multiplier": 0.33
            }
        }
    ],
    "parts": [
        {
            "x": 0,
            "y": 0,
            "z": 0,
            "elements": [
                "modularmachinery:blockcontroller@2"
            ]
        },
        {
            "x": -3,
            "y": -2,
            "z": 5,
            "elements": [
                "actuallyadditions:block_misc@9"
            ]
        },
        {
            "x": -5,
            "y": 4,
            "z": 10,
            "elements": [
                "chisel:blockaluminum@1"
            ]
        },
        {
            "x": -2,
            "y": -1,
            "z": 12,
            "elements": [
                "chisel:blockaluminum@1"
            ]
        },
        {
            "x": 0,
            "y": -2,
            "z": 0,
            "elements": [
                "additions:stainless_steel_block@0"
            ]
        },
        {
            "x": -3,
            "y": -2,
            "z": 24,
            "elements": [
                "actuallyadditions:block_misc@9"
            ]
        },
        {
            "x": -4,
            "y": -2,
            "z": 10,
            "elements": [
                "actuallyadditions:block_misc@9"
            ]
        },
        {
            "x": -2,
            "y": 4,
            "z": 0,
            "elements": [
                "minecraft:quartz_stairs@0"
            ]
        },
        {
            "x": -5,
            "y": -1,
            "z": 21,
            "elements": [
                "chisel:blocksilver@3"
            ]
        },
        {
            "x": -4,
            "y": 4,
            "z": 5,
            "elements": [
                "jaopca:block.lead_platinum@0"
            ]
        },
        {
            "x": -1,
            "y": 2,
            "z": 28,
            "elements": [
                "extrautils2:spike_stone@3"
            ]
        },
        {
            "x": -4,
            "y": 5,
            "z": 19,
            "elements": [
                "minecraft:quartz_stairs@1"
            ]
        },
        {
            "x": -5,
            "y": 2,
            "z": 10,
            "elements": [
                "chisel:blockaluminum@1"
            ]
        },
        {
            "x": 3,
            "y": -2,
            "z": 23,
            "elements": [
                "additions:stainless_steel_block@0"
            ]
        },
        {
            "x": -5,
            "y": 0,
            "z": 15,
            "elements": [
                "chisel:blockaluminum@1"
            ]
        },
        {
            "x": 4,
            "y": -1,
            "z": 28,
            "elements": [
                "chisel:blocksilver@3"
            ]
        },
        {
            "x": 1,
            "y": 0,
            "z": 0,
            "elements": [
                "chisel:blockaluminum@1"
            ]
        },
        {
            "x": -4,
            "y": -2,
            "z": 5,
            "elements": [
                "actuallyadditions:block_misc@9"
            ]
        },
        {
            "x": -2,
            "y": 2,
            "z": 0,
            "elements": [
                "chisel:blockaluminum@1"
            ]
        },
        {
            "x": 1,
            "y": -2,
            "z": 0,
            "elements": [
                "additions:stainless_steel_block@0"
            ]
        },
        {
            "x": 2,
            "y": 0,
            "z": 22,
            "elements": [
                "chisel:blocksilver@3"
            ]
        },
        {
            "x": 1,
            "y": -2,
            "z": 28,
            "elements": [
                "actuallyadditions:block_misc@9"
            ]
        },
        {
            "x": -1,
            "y": 4,
            "z": 0,
            "elements": [
                "minecraft:quartz_stairs@2"
            ]
        },
        {
            "x": -5,
            "y": 4,
            "z": 5,
            "elements": [
                "chisel:blockaluminum@1"
            ]
        },
        {
            "x": 2,
            "y": 3,
            "z": 17,
            "elements": [
                "additions:stainless_steel_block@0"
            ]
        },
        {
            "x": -5,
            "y": -2,
            "z": 10,
            "elements": [
                "additions:stainless_steel_block@0"
            ]
        },
        {
            "x": -2,
            "y": 2,
            "z": 5,
            "elements": [
                "additions:manganese_steel_block@0"
            ]
        },
        {
            "x": -5,
            "y": 0,
            "z": 10,
            "elements": [
                "chisel:blockaluminum@1"
            ]
        },
        {
            "x": -1,
            "y": 4,
            "z": 28,
            "elements": [
                "chisel:blocktin@0"
            ]
        },
        {
            "x": 2,
            "y": 2,
            "z": 17,
            "elements": [
                "chisel:blocksilver@3"
            ]
        },
        {
            "x": -1,
            "y": -2,
            "z": 5,
            "elements": [
                "actuallyadditions:block_misc@9"
            ]
        },
        {
            "x": 3,
            "y": 3,
            "z": 4,
            "elements": [
                "extrautils2:spike_stone@0"
            ]
        },
        {
            "x": 4,
            "y": 1,
            "z": 23,
            "elements": [
                "chisel:blocksilver@3"
            ]
        },
        {
            "x": 2,
            "y": 1,
            "z": 17,
            "elements": [
                "chisel:blocksilver@3"
            ]
        },
        {
            "x": -2,
            "y": -2,
            "z": 0,
            "elements": [
                "additions:stainless_steel_block@0"
            ]
        },
        {
            "x": -1,
            "y": -1,
            "z": 11,
            "elements": [
                "cyclicmagic:plate_push_fast@1"
            ]
        },
        {
            "x": 1,
            "y": 2,
            "z": 0,
            "elements": [
                "chisel:blockaluminum@1"
            ]
        },
        {
            "x": -5,
            "y": 0,
            "z": 5,
            "elements": [
                "chisel:blockaluminum@1"
            ]
        },
        {
            "x": -2,
            "y": -2,
            "z": 10,
            "elements": [
                "actuallyadditions:block_misc@9"
            ]
        },
        {
            "x": 4,
            "y": -1,
            "z": 23,
            "elements": [
                "chisel:blocksilver@3"
            ]
        },
        {
            "x": -5,
            "y": -1,
            "z": 16,
            "elements": [
                "chisel:blocksilver@3"
            ]
        },
        {
            "x": 2,
            "y": 0,
            "z": 17,
            "elements": [
                "chisel:blocksilver@3"
            ]
        },
        {
            "x": 4,
            "y": 2,
            "z": 23,
            "elements": [
                "chisel:blocksilver@3"
            ]
        },
        {
            "x": -4,
            "y": 0,
            "z": 10,
            "elements": [
                "extrautils2:spike_stone@1"
            ]
        },
        {
            "x": -5,
            "y": 2,
            "z": 5,
            "elements": [
                "chisel:blockaluminum@1"
            ]
        },
        {
            "x": 2,
            "y": 4,
            "z": 28,
            "elements": [
                "chisel:blocktin@0"
            ]
        },
        {
            "x": -4,
            "y": 3,
            "z": 21,
            "elements": [
                "additions:stainless_steel_block@0"
            ]
        },
        {
            "x": -1,
            "y": 0,
            "z": 0,
            "elements": [
                "casings_all"
            ]
        },
        {
            "x": 0,
            "y": -1,
            "z": 11,
            "elements": [
                "cyclicmagic:plate_push_fast@1"
            ]
        },
        {
            "x": 1,
            "y": -1,
            "z": 17,
            "elements": [
                "chisel:blockaluminum@1"
            ]
        },
        {
            "x": -4,
            "y": 4,
            "z": 10,
            "elements": [
                "jaopca:block.lead_platinum@0"
            ]
        },
        {
            "x": 0,
            "y": 0,
            "z": 5,
            "elements": [
                "extrautils2:spike_stone@1"
            ]
        },
        {
            "x": 2,
            "y": 4,
            "z": 23,
            "elements": [
                "chisel:blocktin@0"
            ]
        },
        {
            "x": 0,
            "y": 4,
            "z": 3,
            "elements": [
                "chisel:blocktin@0"
            ]
        },
        {
            "x": 1,
            "y": -2,
            "z": 17,
            "elements": [
                "additions:stainless_steel_block@0"
            ]
        },
        {
            "x": -3,
            "y": 4,
            "z": 5,
            "elements": [
                "thermalfoundation:glass@3"
            ]
        },
        {
            "x": 0,
            "y": 2,
            "z": 5,
            "elements": [
                "extrautils2:spike_stone@0"
            ]
        },
        {
            "x": 1,
            "y": 4,
            "z": 0,
            "elements": [
                "minecraft:quartz_stairs@2"
            ]
        },
        {
            "x": -4,
            "y": 2,
            "z": 10,
            "elements": [
                "extrautils2:spike_stone@0"
            ]
        },
        {
            "x": -4,
            "y": 1,
            "z": 21,
            "elements": [
                "extrautils2:spike_stone@2"
            ]
        },
        {
            "x": -4,
            "y": 1,
            "z": 16,
            "elements": [
                "extrautils2:spike_stone@2"
            ]
        },
        {
            "x": 3,
            "y": 5,
            "z": 4,
            "elements": [
                "minecraft:quartz_stairs@0"
            ]
        },
        {
            "x": 4,
            "y": 0,
            "z": 23,
            "elements": [
                "chisel:blocksilver@3"
            ]
        },
        {
            "x": -3,
            "y": 0,
            "z": 22,
            "elements": [
                "chisel:blocksilver@3"
            ]
        },
        {
            "x": -5,
            "y": -1,
            "z": 26,
            "elements": [
                "chisel:blocksilver@3"
            ]
        },
        {
            "x": 2,
            "y": 2,
            "z": 19,
            "elements": [
                "extrautils2:spike_stone@3"
            ]
        },
        {
            "x": 1,
            "y": -2,
            "z": 5,
            "elements": [
                "actuallyadditions:block_misc@9"
            ]
        },
        {
            "x": -5,
            "y": -1,
            "z": 19,
            "elements": [
                "chisel:blockaluminum@1"
            ]
        },
        {
            "x": 1,
            "y": 4,
            "z": 23,
            "elements": [
                "chisel:blocktin@0"
            ]
        },
        {
            "x": 2,
            "y": 1,
            "z": 12,
            "elements": [
                "chisel:blocksilver@3"
            ]
        },
        {
            "x": 4,
            "y": 5,
            "z": 9,
            "elements": [
                "additions:stainless_steel_block@0"
            ]
        },
        {
            "x": -3,
            "y": -2,
            "z": 20,
            "elements": [
                "actuallyadditions:block_misc@9"
            ]
        },
        {
            "x": 3,
            "y": 2,
            "z": 7,
            "elements": [
                "chisel:blocksilver@3"
            ]
        },
        {
            "x": -1,
            "y": -2,
            "z": 22,
            "elements": [
                "actuallyadditions:block_misc@9"
            ]
        },
        {
            "x": -5,
            "y": 0,
            "z": 20,
            "elements": [
                "chisel:blockaluminum@1"
            ]
        },
        {
            "x": 0,
            "y": 1,
            "z": 4,
            "elements": [
                "extrautils2:spike_stone@3"
            ]
        },
        {
            "x": -4,
            "y": 3,
            "z": 16,
            "elements": [
                "additions:stainless_steel_block@0"
            ]
        },
        {
            "x": -1,
            "y": -1,
            "z": 4,
            "elements": [
                "cyclicmagic:plate_push_fast@1"
            ]
        },
        {
            "x": 2,
            "y": 0,
            "z": 12,
            "elements": [
                "chisel:blocksilver@3"
            ]
        },
        {
            "x": 0,
            "y": -1,
            "z": 9,
            "elements": [
                "cyclicmagic:plate_push_fast@1"
            ]
        },
        {
            "x": 3,
            "y": 3,
            "z": 7,
            "elements": [
                "additions:stainless_steel_block@0"
            ]
        },
        {
            "x": -5,
            "y": 2,
            "z": 20,
            "elements": [
                "chisel:blockaluminum@1"
            ]
        },
        {
            "x": 2,
            "y": 4,
            "z": 19,
            "elements": [
                "thermalfoundation:glass@3"
            ]
        },
        {
            "x": -3,
            "y": 2,
            "z": 22,
            "elements": [
                "chisel:blocksilver@3"
            ]
        },
        {
            "x": -1,
            "y": 4,
            "z": 5,
            "elements": [
                "thermalfoundation:glass@3"
            ]
        },
        {
            "x": -4,
            "y": 1,
            "z": 26,
            "elements": [
                "extrautils2:spike_stone@2"
            ]
        },
        {
            "x": -2,
            "y": -2,
            "z": 22,
            "elements": [
                "additions:stainless_steel_block@0"
            ]
        },
        {
            "x": -1,
            "y": -2,
            "z": 10,
            "elements": [
                "actuallyadditions:block_misc@9"
            ]
        },
        {
            "x": 3,
            "y": 1,
            "z": 4,
            "elements": [
                "extrautils2:spike_stone@1"
            ]
        },
        {
            "x": 2,
            "y": 2,
            "z": 5,
            "elements": [
                "additions:manganese_steel_block@0"
            ]
        },
        {
            "x": 3,
            "y": 2,
            "z": 3,
            "elements": [
                "extrautils2:spike_stone@3"
            ]
        },
        {
            "x": -5,
            "y": -2,
            "z": 19,
            "elements": [
                "additions:stainless_steel_block@0"
            ]
        },
        {
            "x": 2,
            "y": 3,
            "z": 12,
            "elements": [
                "additions:stainless_steel_block@0"
            ]
        },
        {
            "x": -3,
            "y": 1,
            "z": 29,
            "elements": [
                "additions:manganese_steel_block@0"
            ]
        },
        {
            "x": -1,
            "y": -1,
            "z": 29,
            "elements": [
                "cyclicmagic:plate_push_fast@1"
            ]
        },
        {
            "x": 2,
            "y": 2,
            "z": 12,
            "elements": [
                "chisel:blocksilver@3"
            ]
        },
        {
            "x": -2,
            "y": 0,
            "z": 0,
            "elements": [
                "chisel:blockaluminum@1"
            ]
        },
        {
            "x": -5,
            "y": -2,
            "z": 5,
            "elements": [
                "additions:stainless_steel_block@0"
            ]
        },
        {
            "x": -4,
            "y": 2,
            "z": 22,
            "elements": [
                "chisel:blocksilver@3"
            ]
        },
        {
            "x": 4,
            "y": 1,
            "z": 9,
            "elements": [
                "chisel:blockaluminum@1"
            ]
        },
        {
            "x": -5,
            "y": 1,
            "z": 11,
            "elements": [
                "chisel:blocksilver@3"
            ]
        },
        {
            "x": -3,
            "y": 4,
            "z": 10,
            "elements": [
                "thermalfoundation:glass@3"
            ]
        },
        {
            "x": -4,
            "y": -2,
            "z": 15,
            "elements": [
                "actuallyadditions:block_misc@9"
            ]
        },
        {
            "x": 0,
            "y": -1,
            "z": 23,
            "elements": [
                "cyclicmagic:plate_push_fast@1"
            ]
        },
        {
            "x": -5,
            "y": -1,
            "z": 11,
            "elements": [
                "chisel:blocksilver@3"
            ]
        },
        {
            "x": 1,
            "y": -2,
            "z": 22,
            "elements": [
                "additions:stainless_steel_block@0"
            ]
        },
        {
            "x": -1,
            "y": 3,
            "z": 12,
            "elements": [
                "chisel:diamond@2"
            ]
        },
        {
            "x": -2,
            "y": -2,
            "z": 19,
            "elements": [
                "actuallyadditions:block_misc@9"
            ]
        },
        {
            "x": 0,
            "y": 0,
            "z": 10,
            "elements": [
                "extrautils2:spike_stone@1"
            ]
        },
        {
            "x": -1,
            "y": 2,
            "z": 5,
            "elements": [
                "extrautils2:spike_stone@2"
            ]
        },
        {
            "x": -1,
            "y": 3,
            "z": 19,
            "elements": [
                "extrautils2:spike_stone@0"
            ]
        },
        {
            "x": 3,
            "y": 0,
            "z": 7,
            "elements": [
                "chisel:blocksilver@3"
            ]
        },
        {
            "x": 2,
            "y": -2,
            "z": 10,
            "elements": [
                "actuallyadditions:block_misc@9"
            ]
        },
        {
            "x": 4,
            "y": -1,
            "z": 19,
            "elements": [
                "chisel:blockaluminum@1"
            ]
        },
        {
            "x": -4,
            "y": 1,
            "z": 19,
            "elements": [
                "extrautils2:spike_stone@3"
            ]
        },
        {
            "x": -3,
            "y": -2,
            "z": 15,
            "elements": [
                "actuallyadditions:block_misc@9"
            ]
        },
        {
            "x": -5,
            "y": 4,
            "z": 15,
            "elements": [
                "chisel:blockaluminum@1"
            ]
        },
        {
            "x": -2,
            "y": -2,
            "z": 5,
            "elements": [
                "actuallyadditions:block_misc@9"
            ]
        },
        {
            "x": -4,
            "y": 0,
            "z": 5,
            "elements": [
                "extrautils2:spike_stone@1"
            ]
        },
        {
            "x": -5,
            "y": 5,
            "z": 9,
            "elements": [
                "additions:stainless_steel_block@0"
            ]
        },
        {
            "x": 2,
            "y": -1,
            "z": 7,
            "elements": [
                "chisel:blocksilver@3"
            ]
        },
        {
            "x": -4,
            "y": 4,
            "z": 19,
            "elements": [
                "jaopca:block.lead_platinum@0"
            ]
        },
        {
            "x": 1,
            "y": -1,
            "z": 12,
            "elements": [
                "chisel:blockaluminum@1"
            ]
        },
        {
            "x": 1,
            "y": 1,
            "z": 9,
            "elements": [
                "additions:manganese_steel_block@0"
            ]
        },
        {
            "x": 4,
            "y": -2,
            "z": 19,
            "elements": [
                "additions:stainless_steel_block@0"
            ]
        },
        {
            "x": -1,
            "y": 2,
            "z": 19,
            "elements": [
                "additions:manganese_steel_block@0"
            ]
        },
        {
            "x": 4,
            "y": 3,
            "z": 9,
            "elements": [
                "chisel:blockaluminum@1"
            ]
        },
        {
            "x": -2,
            "y": -2,
            "z": 26,
            "elements": [
                "actuallyadditions:block_misc@9"
            ]
        },
        {
            "x": 1,
            "y": 1,
            "z": 23,
            "elements": [
                "extrautils2:spike_stone@3"
            ]
        },
        {
            "x": -4,
            "y": 0,
            "z": 22,
            "elements": [
                "chisel:blocksilver@3"
            ]
        },
        {
            "x": 2,
            "y": 2,
            "z": 27,
            "elements": [
                "chisel:blocksilver@3"
            ]
        },
        {
            "x": -4,
            "y": 2,
            "z": 5,
            "elements": [
                "extrautils2:spike_stone@0"
            ]
        },
        {
            "x": 1,
            "y": -2,
            "z": 12,
            "elements": [
                "additions:stainless_steel_block@0"
            ]
        },
        {
            "x": 0,
            "y": -1,
            "z": 16,
            "elements": [
                "cyclicmagic:plate_push_fast@1"
            ]
        },
        {
            "x": -2,
            "y": 4,
            "z": 23,
            "elements": [
                "chisel:blocktin@0"
            ]
        },
        {
            "x": 1,
            "y": -2,
            "z": 19,
            "elements": [
                "actuallyadditions:block_misc@9"
            ]
        },
        {
            "x": 3,
            "y": 3,
            "z": 6,
            "elements": [
                "additions:stainless_steel_block@0"
            ]
        },
        {
            "x": -4,
            "y": 3,
            "z": 26,
            "elements": [
                "additions:stainless_steel_block@0"
            ]
        },
        {
            "x": 3,
            "y": 1,
            "z": 7,
            "elements": [
                "chisel:blocksilver@3"
            ]
        },
        {
            "x": -5,
            "y": 2,
            "z": 15,
            "elements": [
                "chisel:blockaluminum@1"
            ]
        },
        {
            "x": -1,
            "y": 3,
            "z": 27,
            "elements": [
                "chisel:diamond@2"
            ]
        },
        {
            "x": 0,
            "y": 3,
            "z": 7,
            "elements": [
                "chisel:diamond@2"
            ]
        },
        {
            "x": 2,
            "y": 3,
            "z": 27,
            "elements": [
                "additions:stainless_steel_block@0"
            ]
        },
        {
            "x": 0,
            "y": 2,
            "z": 10,
            "elements": [
                "extrautils2:spike_stone@0"
            ]
        },
        {
            "x": -1,
            "y": 1,
            "z": 19,
            "elements": [
                "extrautils2:spike_stone@1"
            ]
        },
        {
            "x": -4,
            "y": 3,
            "z": 28,
            "elements": [
                "additions:stainless_steel_block@0"
            ]
        },
        {
            "x": -4,
            "y": 3,
            "z": 18,
            "elements": [
                "additions:stainless_steel_block@0"
            ]
        },
        {
            "x": 0,
            "y": -2,
            "z": 23,
            "elements": [
                "actuallyadditions:block_misc@9"
            ]
        },
        {
            "x": -4,
            "y": 3,
            "z": 31,
            "elements": [
                "additions:stainless_steel_block@0"
            ]
        },
        {
            "x": 4,
            "y": 1,
            "z": 24,
            "elements": [
                "chisel:blockaluminum@1"
            ]
        },
        {
            "x": -5,
            "y": 3,
            "z": 9,
            "elements": [
                "chisel:blockaluminum@1"
            ]
        },
        {
            "x": 2,
            "y": 1,
            "z": 27,
            "elements": [
                "chisel:blocksilver@3"
            ]
        },
        {
            "x": -4,
            "y": 1,
            "z": 4,
            "elements": [
                "extrautils2:spike_stone@3"
            ]
        },
        {
            "x": 1,
            "y": 4,
            "z": 3,
            "elements": [
                "chisel:blocktin@0"
            ]
        },
        {
            "x": -1,
            "y": 4,
            "z": 18,
            "elements": [
                "chisel:blocktin@0"
            ]
        },
        {
            "x": 0,
            "y": -2,
            "z": 32,
            "elements": [
                "additions:stainless_steel_block@0"
            ]
        },
        {
            "x": -2,
            "y": 0,
            "z": 32,
            "elements": [
                "chisel:blockaluminum@1"
            ]
        },
        {
            "x": 4,
            "y": 2,
            "z": 3,
            "elements": [
                "chisel:blocksilver@3"
            ]
        },
        {
            "x": 4,
            "y": 0,
            "z": 3,
            "elements": [
                "chisel:blocksilver@3"
            ]
        },
        {
            "x": 4,
            "y": 2,
            "z": 24,
            "elements": [
                "chisel:blockaluminum@1"
            ]
        },
        {
            "x": 2,
            "y": 0,
            "z": 27,
            "elements": [
                "chisel:blocksilver@3"
            ]
        },
        {
            "x": -5,
            "y": -1,
            "z": 4,
            "elements": [
                "chisel:blockaluminum@1"
            ]
        },
        {
            "x": 1,
            "y": -2,
            "z": 27,
            "elements": [
                "additions:stainless_steel_block@0"
            ]
        },
        {
            "x": 3,
            "y": 2,
            "z": 10,
            "elements": [
                "extrautils2:spike_stone@2"
            ]
        },
        {
            "x": -5,
            "y": 1,
            "z": 16,
            "elements": [
                "chisel:blocksilver@3"
            ]
        },
        {
            "x": -3,
            "y": 4,
            "z": 8,
            "elements": [
                "chisel:blocktin@0"
            ]
        },
        {
            "x": -3,
            "y": -1,
            "z": 32,
            "elements": [
                "chisel:blocksilver@3"
            ]
        },
        {
            "x": -2,
            "y": -2,
            "z": 18,
            "elements": [
                "actuallyadditions:block_misc@9"
            ]
        },
        {
            "x": -2,
            "y": 1,
            "z": 32,
            "elements": [
                "chisel:blockaluminum@1"
            ]
        },
        {
            "x": 4,
            "y": -1,
            "z": 24,
            "elements": [
                "chisel:blockaluminum@1"
            ]
        },
        {
            "x": -3,
            "y": 1,
            "z": 8,
            "elements": [
                "extrautils2:spike_stone@3"
            ]
        },
        {
            "x": 4,
            "y": -2,
            "z": 5,
            "elements": [
                "additions:stainless_steel_block@0"
            ]
        },
        {
            "x": -2,
            "y": 2,
            "z": 32,
            "elements": [
                "chisel:blockaluminum@1"
            ]
        },
        {
            "x": -4,
            "y": -2,
            "z": 20,
            "elements": [
                "actuallyadditions:block_misc@9"
            ]
        },
        {
            "x": -5,
            "y": 0,
            "z": 23,
            "elements": [
                "chisel:blocksilver@3"
            ]
        },
        {
            "x": -5,
            "y": 0,
            "z": 25,
            "elements": [
                "chisel:blockaluminum@1"
            ]
        },
        {
            "x": 3,
            "y": 4,
            "z": 5,
            "elements": [
                "jaopca:block.lead_platinum@0"
            ]
        },
        {
            "x": -4,
            "y": 3,
            "z": 27,
            "elements": [
                "additions:stainless_steel_block@0"
            ]
        },
        {
            "x": -3,
            "y": -2,
            "z": 23,
            "elements": [
                "additions:stainless_steel_block@0"
            ]
        },
        {
            "x": -1,
            "y": 1,
            "z": 4,
            "elements": [
                "extrautils2:spike_stone@1"
            ]
        },
        {
            "x": 1,
            "y": -1,
            "z": 27,
            "elements": [
                "chisel:blockaluminum@1"
            ]
        },
        {
            "x": -5,
            "y": 1,
            "z": 23,
            "elements": [
                "chisel:blocksilver@3"
            ]
        },
        {
            "x": -1,
            "y": -2,
            "z": 8,
            "elements": [
                "actuallyadditions:block_misc@9"
            ]
        },
        {
            "x": 2,
            "y": 4,
            "z": 31,
            "elements": [
                "chisel:blocktin@0"
            ]
        },
        {
            "x": -4,
            "y": 1,
            "z": 31,
            "elements": [
                "extrautils2:spike_stone@2"
            ]
        },
        {
            "x": -2,
            "y": 4,
            "z": 3,
            "elements": [
                "chisel:blocktin@0"
            ]
        },
        {
            "x": 4,
            "y": 0,
            "z": 24,
            "elements": [
                "chisel:blockaluminum@1"
            ]
        },
        {
            "x": 2,
            "y": -2,
            "z": 8,
            "elements": [
                "additions:stainless_steel_block@0"
            ]
        },
        {
            "x": -5,
            "y": -1,
            "z": 9,
            "elements": [
                "chisel:blockaluminum@1"
            ]
        },
        {
            "x": -5,
            "y": 1,
            "z": 9,
            "elements": [
                "chisel:blockaluminum@1"
            ]
        },
        {
            "x": -4,
            "y": 2,
            "z": 27,
            "elements": [
                "chisel:blocksilver@3"
            ]
        },
        {
            "x": 1,
            "y": -2,
            "z": 18,
            "elements": [
                "actuallyadditions:block_misc@9"
            ]
        },
        {
            "x": 3,
            "y": -2,
            "z": 10,
            "elements": [
                "actuallyadditions:block_misc@9"
            ]
        },
        {
            "x": -2,
            "y": 3,
            "z": 32,
            "elements": [
                "chisel:blockaluminum@1"
            ]
        },
        {
            "x": 0,
            "y": 4,
            "z": 8,
            "elements": [
                "chisel:blocktin@0"
            ]
        },
        {
            "x": -3,
            "y": -2,
            "z": 25,
            "elements": [
                "actuallyadditions:block_misc@9"
            ]
        },
        {
            "x": 1,
            "y": 4,
            "z": 10,
            "elements": [
                "thermalfoundation:glass@3"
            ]
        },
        {
            "x": -2,
            "y": -2,
            "z": 27,
            "elements": [
                "additions:stainless_steel_block@0"
            ]
        },
        {
            "x": -5,
            "y": 2,
            "z": 23,
            "elements": [
                "chisel:blocksilver@3"
            ]
        },
        {
            "x": 2,
            "y": 4,
            "z": 24,
            "elements": [
                "thermalfoundation:glass@3"
            ]
        },
        {
            "x": -5,
            "y": 2,
            "z": 25,
            "elements": [
                "chisel:blockaluminum@1"
            ]
        },
        {
            "x": 3,
            "y": -1,
            "z": 32,
            "elements": [
                "chisel:blocksilver@3"
            ]
        },
        {
            "x": -4,
            "y": 5,
            "z": 4,
            "elements": [
                "minecraft:quartz_stairs@1"
            ]
        },
        {
            "x": -4,
            "y": 0,
            "z": 25,
            "elements": [
                "extrautils2:spike_stone@1"
            ]
        },
        {
            "x": 4,
            "y": 5,
            "z": 24,
            "elements": [
                "additions:stainless_steel_block@0"
            ]
        },
        {
            "x": -2,
            "y": -1,
            "z": 27,
            "elements": [
                "chisel:blockaluminum@1"
            ]
        },
        {
            "x": -1,
            "y": -2,
            "z": 20,
            "elements": [
                "actuallyadditions:block_misc@9"
            ]
        },
        {
            "x": 3,
            "y": 2,
            "z": 5,
            "elements": [
                "extrautils2:spike_stone@2"
            ]
        },
        {
            "x": -5,
            "y": 3,
            "z": 4,
            "elements": [
                "chisel:blockaluminum@1"
            ]
        },
        {
            "x": -1,
            "y": 4,
            "z": 15,
            "elements": [
                "thermalfoundation:glass@3"
            ]
        },
        {
            "x": -1,
            "y": 2,
            "z": 18,
            "elements": [
                "extrautils2:spike_stone@3"
            ]
        },
        {
            "x": 2,
            "y": 2,
            "z": 24,
            "elements": [
                "extrautils2:spike_stone@3"
            ]
        },
        {
            "x": -5,
            "y": 2,
            "z": 3,
            "elements": [
                "chisel:blocksilver@3"
            ]
        },
        {
            "x": 2,
            "y": 2,
            "z": 31,
            "elements": [
                "extrautils2:spike_stone@2"
            ]
        },
        {
            "x": -5,
            "y": -1,
            "z": 28,
            "elements": [
                "chisel:blocksilver@3"
            ]
        },
        {
            "x": -4,
            "y": -2,
            "z": 3,
            "elements": [
                "additions:stainless_steel_block@0"
            ]
        },
        {
            "x": 4,
            "y": 0,
            "z": 10,
            "elements": [
                "chisel:blockaluminum@1"
            ]
        },
        {
            "x": 4,
            "y": 4,
            "z": 10,
            "elements": [
                "chisel:blockaluminum@1"
            ]
        },
        {
            "x": -1,
            "y": -1,
            "z": 8,
            "elements": [
                "cyclicmagic:plate_push_fast@1"
            ]
        },
        {
            "x": -5,
            "y": 5,
            "z": 4,
            "elements": [
                "additions:stainless_steel_block@0"
            ]
        },
        {
            "x": 2,
            "y": -2,
            "z": 5,
            "elements": [
                "actuallyadditions:block_misc@9"
            ]
        },
        {
            "x": 1,
            "y": -2,
            "z": 15,
            "elements": [
                "actuallyadditions:block_misc@9"
            ]
        },
        {
            "x": -3,
            "y": 1,
            "z": 4,
            "elements": [
                "additions:manganese_steel_block@0"
            ]
        },
        {
            "x": 4,
            "y": -2,
            "z": 24,
            "elements": [
                "additions:stainless_steel_block@0"
            ]
        },
        {
            "x": -5,
            "y": 4,
            "z": 25,
            "elements": [
                "chisel:blockaluminum@1"
            ]
        },
        {
            "x": 4,
            "y": 3,
            "z": 24,
            "elements": [
                "chisel:blockaluminum@1"
            ]
        },
        {
            "x": 4,
            "y": -1,
            "z": 13,
            "elements": [
                "chisel:blocksilver@3"
            ]
        },
        {
            "x": -4,
            "y": 0,
            "z": 15,
            "elements": [
                "extrautils2:spike_stone@1"
            ]
        },
        {
            "x": 4,
            "y": 2,
            "z": 10,
            "elements": [
                "chisel:blockaluminum@1"
            ]
        },
        {
            "x": -5,
            "y": 0,
            "z": 3,
            "elements": [
                "chisel:blocksilver@3"
            ]
        },
        {
            "x": -1,
            "y": 2,
            "z": 15,
            "elements": [
                "extrautils2:spike_stone@2"
            ]
        },
        {
            "x": -3,
            "y": 1,
            "z": 9,
            "elements": [
                "additions:manganese_steel_block@0"
            ]
        },
        {
            "x": 3,
            "y": -2,
            "z": 3,
            "elements": [
                "additions:stainless_steel_block@0"
            ]
        },
        {
            "x": -5,
            "y": -2,
            "z": 25,
            "elements": [
                "additions:stainless_steel_block@0"
            ]
        },
        {
            "x": 4,
            "y": 4,
            "z": 24,
            "elements": [
                "chisel:blockaluminum@1"
            ]
        },
        {
            "x": 3,
            "y": 3,
            "z": 13,
            "elements": [
                "additions:stainless_steel_block@0"
            ]
        },
        {
            "x": -2,
            "y": -2,
            "z": 15,
            "elements": [
                "actuallyadditions:block_misc@9"
            ]
        },
        {
            "x": 2,
            "y": 4,
            "z": 26,
            "elements": [
                "chisel:blocktin@0"
            ]
        },
        {
            "x": -1,
            "y": 3,
            "z": 9,
            "elements": [
                "extrautils2:spike_stone@0"
            ]
        },
        {
            "x": -4,
            "y": 5,
            "z": 9,
            "elements": [
                "minecraft:quartz_stairs@1"
            ]
        },
        {
            "x": -1,
            "y": 3,
            "z": 24,
            "elements": [
                "extrautils2:spike_stone@0"
            ]
        },
        {
            "x": 4,
            "y": 3,
            "z": 25,
            "elements": [
                "chisel:blockaluminum@1"
            ]
        },
        {
            "x": -4,
            "y": -2,
            "z": 30,
            "elements": [
                "actuallyadditions:block_misc@9"
            ]
        },
        {
            "x": -3,
            "y": 4,
            "z": 3,
            "elements": [
                "chisel:blocktin@0"
            ]
        },
        {
            "x": 3,
            "y": 5,
            "z": 14,
            "elements": [
                "minecraft:quartz_stairs@0"
            ]
        },
        {
            "x": -1,
            "y": 2,
            "z": 32,
            "elements": [
                "casings_upgrade"
            ]
        },
        {
            "x": -4,
            "y": 0,
            "z": 30,
            "elements": [
                "extrautils2:spike_stone@1"
            ]
        },
        {
            "x": -1,
            "y": 3,
            "z": 17,
            "elements": [
                "chisel:diamond@2"
            ]
        },
        {
            "x": 1,
            "y": 0,
            "z": 24,
            "elements": [
                "extrautils2:spike_stone@1"
            ]
        },
        {
            "x": -1,
            "y": -1,
            "z": 21,
            "elements": [
                "cyclicmagic:plate_push_fast@1"
            ]
        },
        {
            "x": 2,
            "y": 0,
            "z": 32,
            "elements": [
                "chisel:blocksilver@3"
            ]
        },
        {
            "x": 0,
            "y": -2,
            "z": 10,
            "elements": [
                "actuallyadditions:block_misc@9"
            ]
        },
        {
            "x": 3,
            "y": 3,
            "z": 11,
            "elements": [
                "additions:stainless_steel_block@0"
            ]
        },
        {
            "x": -1,
            "y": 3,
            "z": 32,
            "elements": [
                "chisel:blockaluminum@1"
            ]
        },
        {
            "x": -4,
            "y": 2,
            "z": 15,
            "elements": [
                "extrautils2:spike_stone@0"
            ]
        },
        {
            "x": -3,
            "y": 4,
            "z": 20,
            "elements": [
                "thermalfoundation:glass@3"
            ]
        },
        {
            "x": 2,
            "y": 1,
            "z": 32,
            "elements": [
                "chisel:blocksilver@3"
            ]
        },
        {
            "x": 0,
            "y": -1,
            "z": 24,
            "elements": [
                "cyclicmagic:plate_push_fast@1"
            ]
        },
        {
            "x": 0,
            "y": 2,
            "z": 20,
            "elements": [
                "extrautils2:spike_stone@0"
            ]
        },
        {
            "x": 0,
            "y": 1,
            "z": 11,
            "elements": [
                "extrautils2:spike_stone@2"
            ]
        },
        {
            "x": 2,
            "y": -2,
            "z": 3,
            "elements": [
                "additions:stainless_steel_block@0"
            ]
        },

        {
            "x": 1,
            "y": -1,
            "z": 32,
            "elements": [
                "chisel:blockaluminum@1"
            ]
        },
        {
            "x": 2,
            "y": 2,
            "z": 26,
            "elements": [
                "extrautils2:spike_stone@2"
            ]
        },
        {
            "x": 4,
            "y": 5,
            "z": 25,
            "elements": [
                "additions:stainless_steel_block@0"
            ]
        },
        {
            "x": 0,
            "y": 0,
            "z": 20,
            "elements": [
                "extrautils2:spike_stone@1"
            ]
        },
        {
            "x": 3,
            "y": 3,
            "z": 14,
            "elements": [
                "extrautils2:spike_stone@0"
            ]
        },
        {
            "x": 1,
            "y": 1,
            "z": 24,
            "elements": [
                "additions:manganese_steel_block@0"
            ]
        },
        {
            "x": 2,
            "y": 2,
            "z": 32,
            "elements": [
                "chisel:blocksilver@3"
            ]
        },
        {
            "x": 4,
            "y": -1,
            "z": 26,
            "elements": [
                "chisel:blocksilver@3"
            ]
        },
        {
            "x": -5,
            "y": 1,
            "z": 4,
            "elements": [
                "chisel:blockaluminum@1"
            ]
        },
        {
            "x": -5,
            "y": -2,
            "z": 15,
            "elements": [
                "additions:stainless_steel_block@0"
            ]
        },
        {
            "x": -1,
            "y": 0,
            "z": 32,
            "elements": [
                "chisel:blockaluminum@1"
            ]
        },
        {
            "x": -2,
            "y": 4,
            "z": 24,
            "elements": [
                "thermalfoundation:glass@3"
            ]
        },
        {
            "x": 2,
            "y": 3,
            "z": 32,
            "elements": [
                "additions:stainless_steel_block@0"
            ]
        },
        {
            "x": 1,
            "y": 2,
            "z": 24,
            "elements": [
                "extrautils2:spike_stone@0"
            ]
        },
        {
            "x": 3,
            "y": 4,
            "z": 14,
            "elements": [
                "jaopca:block.lead_platinum@0"
            ]
        },
        {
            "x": -1,
            "y": 1,
            "z": 9,
            "elements": [
                "extrautils2:spike_stone@1"
            ]
        },
        {
            "x": 3,
            "y": 2,
            "z": 20,
            "elements": [
                "extrautils2:spike_stone@2"
            ]
        },
        {
            "x": -1,
            "y": 1,
            "z": 32,
            "elements": [
                "chisel:blockaluminum@1"
            ]
        },
        {
            "x": -3,
            "y": -2,
            "z": 3,
            "elements": [
                "additions:stainless_steel_block@0"
            ]
        },
        {
            "x": -4,
            "y": 4,
            "z": 15,
            "elements": [
                "jaopca:block.lead_platinum@0"
            ]
        },
        {
            "x": -2,
            "y": -1,
            "z": 32,
            "elements": [
                "chisel:blockaluminum@1"
            ]
        },
        {
            "x": -2,
            "y": 2,
            "z": 10,
            "elements": [
                "additions:manganese_steel_block@0"
            ]
        },

        {
            "x": 0,
            "y": -1,
            "z": 4,
            "elements": [
                "cyclicmagic:plate_push_fast@1"
            ]
        },
        {
            "x": 1,
            "y": 2,
            "z": 32,
            "elements": [
                "chisel:blockaluminum@1"
            ]
        },
        {
            "x": -1,
            "y": 3,
            "z": 4,
            "elements": [
                "extrautils2:spike_stone@0"
            ]
        },

        {
            "x": 4,
            "y": -2,
            "z": 15,
            "elements": [
                "additions:stainless_steel_block@0"
            ]
        },
        {
            "x": -2,
            "y": -2,
            "z": 28,
            "elements": [
                "actuallyadditions:block_misc@9"
            ]
        },
        {
            "x": 3,
            "y": 3,
            "z": 8,
            "elements": [
                "additions:stainless_steel_block@0"
            ]
        },
        {
            "x": 0,
            "y": -2,
            "z": 25,
            "elements": [
                "actuallyadditions:block_misc@9"
            ]
        },
        {
            "x": -4,
            "y": 1,
            "z": 27,
            "elements": [
                "chisel:blocksilver@3"
            ]
        },
        {
            "x": -5,
            "y": -1,
            "z": 31,
            "elements": [
                "chisel:blocksilver@3"
            ]
        },
        {
            "x": 3,
            "y": -2,
            "z": 24,
            "elements": [
                "actuallyadditions:block_misc@9"
            ]
        },
        {
            "x": 0,
            "y": 4,
            "z": 14,
            "elements": [
                "thermalfoundation:glass@3"
            ]
        },

        {
            "x": -1,
            "y": 2,
            "z": 3,
            "elements": [
                "extrautils2:spike_stone@3"
            ]
        },
        {
            "x": 1,
            "y": 3,
            "z": 32,
            "elements": [
                "chisel:blockaluminum@1"
            ]
        },
        {
            "x": -2,
            "y": 2,
            "z": 24,
            "elements": [
                "extrautils2:spike_stone@3"
            ]
        },
        {
            "x": 1,
            "y": -2,
            "z": 26,
            "elements": [
                "actuallyadditions:block_misc@9"
            ]
        },
        {
            "x": -4,
            "y": 0,
            "z": 27,
            "elements": [
                "chisel:blocksilver@3"
            ]
        },
        {
            "x": -4,
            "y": 1,
            "z": 9,
            "elements": [
                "extrautils2:spike_stone@3"
            ]
        },
        {
            "x": 2,
            "y": 2,
            "z": 15,
            "elements": [
                "additions:manganese_steel_block@0"
            ]
        },
        {
            "x": 0,
            "y": -2,
            "z": 3,
            "elements": [
                "actuallyadditions:block_misc@9"
            ]
        },
        {
            "x": -1,
            "y": 4,
            "z": 26,
            "elements": [
                "chisel:blocktin@0"
            ]
        },

        {
            "x": 0,
            "y": -2,
            "z": 24,
            "elements": [
                "actuallyadditions:block_misc@9"
            ]
        },
        {
            "x": -5,
            "y": -2,
            "z": 30,
            "elements": [
                "additions:stainless_steel_block@0"
            ]
        },
        {
            "x": 4,
            "y": -1,
            "z": 18,
            "elements": [
                "chisel:blocksilver@3"
            ]
        },
        {
            "x": -3,
            "y": -2,
            "z": 10,
            "elements": [
                "actuallyadditions:block_misc@9"
            ]
        },
        {
            "x": 1,
            "y": 1,
            "z": 4,
            "elements": [
                "additions:manganese_steel_block@0"
            ]
        },
        {
            "x": 1,
            "y": -2,
            "z": 32,
            "elements": [
                "additions:stainless_steel_block@0"
            ]
        },
        {
            "x": 2,
            "y": 4,
            "z": 18,
            "elements": [
                "chisel:blocktin@0"
            ]
        },
        {
            "x": -2,
            "y": 2,
            "z": 25,
            "elements": [
                "additions:manganese_steel_block@0"
            ]
        },
        {
            "x": 3,
            "y": 2,
            "z": 14,
            "elements": [
                "additions:manganese_steel_block@0"
            ]
        },
        {
            "x": 2,
            "y": -2,
            "z": 20,
            "elements": [
                "actuallyadditions:block_misc@9"
            ]
        },

        {
            "x": 1,
            "y": 0,
            "z": 32,
            "elements": [
                "chisel:blockaluminum@1"
            ]
        },
        {
            "x": -1,
            "y": -2,
            "z": 3,
            "elements": [
                "actuallyadditions:block_misc@9"
            ]
        },
        {
            "x": 0,
            "y": 1,
            "z": 21,
            "elements": [
                "extrautils2:spike_stone@2"
            ]
        },
        {
            "x": 2,
            "y": 2,
            "z": 6,
            "elements": [
                "extrautils2:spike_stone@2"
            ]
        },

        {
            "x": 3,
            "y": 2,
            "z": 8,
            "elements": [
                "extrautils2:spike_stone@3"
            ]
        },
        {
            "x": 1,
            "y": 1,
            "z": 32,
            "elements": [
                "chisel:blockaluminum@1"
            ]
        },
        {
            "x": 3,
            "y": 1,
            "z": 14,
            "elements": [
                "extrautils2:spike_stone@1"
            ]
        },
        {
            "x": 3,
            "y": 3,
            "z": 2,
            "elements": [
                "additions:stainless_steel_block@0"
            ]
        },
        {
            "x": 0,
            "y": -1,
            "z": 32,
            "elements": [
                "chisel:blockaluminum@1"
            ]
        },
        {
            "x": -5,
            "y": 0,
            "z": 29,
            "elements": [
                "chisel:blockaluminum@1"
            ]
        },
        {
            "x": -1,
            "y": 4,
            "z": 21,
            "elements": [
                "chisel:blocktin@0"
            ]
        },
        {
            "x": 4,
            "y": 1,
            "z": 4,
            "elements": [
                "chisel:blockaluminum@1"
            ]
        },
        {
            "x": 1,
            "y": -1,
            "z": 7,
            "elements": [
                "chisel:blockaluminum@1"
            ]
        },
        {
            "x": -1,
            "y": -1,
            "z": 19,
            "elements": [
                "cyclicmagic:plate_push_fast@1"
            ]
        },
        {
            "x": -5,
            "y": 3,
            "z": 24,
            "elements": [
                "chisel:blockaluminum@1"
            ]
        },
        {
            "x": 4,
            "y": 2,
            "z": 31,
            "elements": [
                "chisel:blocksilver@3"
            ]
        },
        {
            "x": 2,
            "y": 2,
            "z": 21,
            "elements": [
                "extrautils2:spike_stone@2"
            ]
        },
        {
            "x": -3,
            "y": 3,
            "z": 12,
            "elements": [
                "additions:stainless_steel_block@0"
            ]
        },
        {
            "x": 3,
            "y": 3,
            "z": 9,
            "elements": [
                "extrautils2:spike_stone@0"
            ]
        },

        {
            "x": 4,
            "y": 0,
            "z": 11,
            "elements": [
                "chisel:blocksilver@3"
            ]
        },
        {
            "x": 4,
            "y": 2,
            "z": 4,
            "elements": [
                "chisel:blockaluminum@1"
            ]
        },

        {
            "x": -4,
            "y": -2,
            "z": 13,
            "elements": [
                "additions:stainless_steel_block@0"
            ]
        },
        {
            "x": -4,
            "y": 1,
            "z": 17,
            "elements": [
                "chisel:blocksilver@3"
            ]
        },
        {
            "x": -4,
            "y": -1,
            "z": 2,
            "elements": [
                "chisel:blocksilver@3"
            ]
        },
        {
            "x": 4,
            "y": 1,
            "z": 11,
            "elements": [
                "chisel:blocksilver@3"
            ]
        },
        {
            "x": -5,
            "y": 5,
            "z": 24,
            "elements": [
                "additions:stainless_steel_block@0"
            ]
        },
        {
            "x": -1,
            "y": 3,
            "z": 7,
            "elements": [
                "chisel:diamond@2"
            ]
        },

        {
            "x": -4,
            "y": 1,
            "z": 24,
            "elements": [
                "extrautils2:spike_stone@3"
            ]
        },
        {
            "x": 3,
            "y": 4,
            "z": 9,
            "elements": [
                "jaopca:block.lead_platinum@0"
            ]
        },
        {
            "x": -3,
            "y": 4,
            "z": 16,
            "elements": [
                "chisel:blocktin@0"
            ]
        },
        {
            "x": -1,
            "y": 3,
            "z": 14,
            "elements": [
                "extrautils2:spike_stone@0"
            ]
        },
        {
            "x": 4,
            "y": -2,
            "z": 20,
            "elements": [
                "additions:stainless_steel_block@0"
            ]
        },
        {
            "x": 0,
            "y": 4,
            "z": 21,
            "elements": [
                "chisel:blocktin@0"
            ]
        },
        {
            "x": -1,
            "y": -1,
            "z": 12,
            "elements": [
                "cyclicmagic:plate_push_fast@1"
            ]
        },
        {
            "x": 3,
            "y": 1,
            "z": 9,
            "elements": [
                "extrautils2:spike_stone@1"
            ]
        },
        {
            "x": -3,
            "y": 1,
            "z": 12,
            "elements": [
                "chisel:blocksilver@3"
            ]
        },
        {
            "x": 2,
            "y": -2,
            "z": 16,
            "elements": [
                "additions:stainless_steel_block@0"
            ]
        },
        {
            "x": 4,
            "y": 1,
            "z": 31,
            "elements": [
                "chisel:blocksilver@3"
            ]
        },
        {
            "x": 1,
            "y": 4,
            "z": 11,
            "elements": [
                "chisel:blocktin@0"
            ]
        },

        {
            "x": 4,
            "y": 2,
            "z": 11,
            "elements": [
                "chisel:blocksilver@3"
            ]
        },
        {
            "x": 3,
            "y": 1,
            "z": 2,
            "elements": [
                "chisel:blocksilver@3"
            ]
        },

        {
            "x": -5,
            "y": 0,
            "z": 8,
            "elements": [
                "chisel:blocksilver@3"
            ]
        },
        {
            "x": 0,
            "y": -1,
            "z": 26,
            "elements": [
                "cyclicmagic:plate_push_fast@1"
            ]
        },
        {
            "x": 3,
            "y": 2,
            "z": 9,
            "elements": [
                "additions:manganese_steel_block@0"
            ]
        },
        {
            "x": 4,
            "y": -1,
            "z": 20,
            "elements": [
                "chisel:blockaluminum@1"
            ]
        },
        {
            "x": -5,
            "y": -1,
            "z": 24,
            "elements": [
                "chisel:blockaluminum@1"
            ]
        },
        {
            "x": 4,
            "y": 0,
            "z": 31,
            "elements": [
                "chisel:blocksilver@3"
            ]
        },
        {
            "x": -5,
            "y": 5,
            "z": 19,
            "elements": [
                "additions:stainless_steel_block@0"
            ]
        },
        {
            "x": -4,
            "y": 5,
            "z": 14,
            "elements": [
                "minecraft:quartz_stairs@1"
            ]
        },
        {
            "x": -1,
            "y": 4,
            "z": 8,
            "elements": [
                "chisel:blocktin@0"
            ]
        },
        {
            "x": 0,
            "y": 4,
            "z": 16,
            "elements": [
                "chisel:blocktin@0"
            ]
        },
        {
            "x": -3,
            "y": 1,
            "z": 19,
            "elements": [
                "additions:manganese_steel_block@0"
            ]
        },
        {
            "x": 4,
            "y": 0,
            "z": 4,
            "elements": [
                "chisel:blockaluminum@1"
            ]
        },

        {
            "x": -4,
            "y": 5,
            "z": 24,
            "elements": [
                "minecraft:quartz_stairs@1"
            ]
        },
        {
            "x": 3,
            "y": 5,
            "z": 20,
            "elements": [
                "minecraft:quartz_stairs@0"
            ]
        },
        {
            "x": -4,
            "y": -2,
            "z": 16,
            "elements": [
                "additions:stainless_steel_block@0"
            ]
        },
        {
            "x": 4,
            "y": -2,
            "z": 25,
            "elements": [
                "additions:stainless_steel_block@0"
            ]
        },
        {
            "x": 0,
            "y": 1,
            "z": 9,
            "elements": [
                "extrautils2:spike_stone@3"
            ]
        },
        {
            "x": 1,
            "y": 4,
            "z": 31,
            "elements": [
                "chisel:blocktin@0"
            ]
        },
        {
            "x": -2,
            "y": -2,
            "z": 32,
            "elements": [
                "additions:stainless_steel_block@0"
            ]
        },
        {
            "x": -1,
            "y": 4,
            "z": 6,
            "elements": [
                "chisel:blocktin@0"
            ]
        },
        {
            "x": -5,
            "y": 4,
            "z": 29,
            "elements": [
                "chisel:blockaluminum@1"
            ]
        },
        {
            "x": 4,
            "y": 0,
            "z": 25,
            "elements": [
                "chisel:blockaluminum@1"
            ]
        },
        {
            "x": -3,
            "y": 3,
            "z": 2,
            "elements": [
                "additions:stainless_steel_block@0"
            ]
        },
        {
            "x": -5,
            "y": 1,
            "z": 26,
            "elements": [
                "chisel:blocksilver@3"
            ]
        },
        {
            "x": -4,
            "y": 0,
            "z": 32,
            "elements": [
                "chisel:blocksilver@3"
            ]
        },
        {
            "x": 2,
            "y": -1,
            "z": 2,
            "elements": [
                "chisel:blocksilver@3"
            ]
        },
        {
            "x": 3,
            "y": 3,
            "z": 12,
            "elements": [
                "additions:stainless_steel_block@0"
            ]
        },
        {
            "x": 0,
            "y": -2,
            "z": 8,
            "elements": [
                "actuallyadditions:block_misc@9"
            ]
        },

        {
            "x": 4,
            "y": -1,
            "z": 25,
            "elements": [
                "chisel:blockaluminum@1"
            ]
        },
        {
            "x": 3,
            "y": 4,
            "z": 20,
            "elements": [
                "jaopca:block.lead_platinum@0"
            ]
        },
        {
            "x": 1,
            "y": 4,
            "z": 25,
            "elements": [
                "thermalfoundation:glass@3"
            ]
        },

        {
            "x": 2,
            "y": 1,
            "z": 7,
            "elements": [
                "chisel:blocksilver@3"
            ]
        },
        {
            "x": 0,
            "y": 1,
            "z": 19,
            "elements": [
                "extrautils2:spike_stone@3"
            ]
        },
        {
            "x": 1,
            "y": -2,
            "z": 6,
            "elements": [
                "actuallyadditions:block_misc@9"
            ]
        },
        {
            "x": -5,
            "y": 3,
            "z": 19,
            "elements": [
                "chisel:blockaluminum@1"
            ]
        },
        {
            "x": 0,
            "y": -1,
            "z": 19,
            "elements": [
                "cyclicmagic:plate_push_fast@1"
            ]
        },
        {
            "x": 1,
            "y": -2,
            "z": 21,
            "elements": [
                "actuallyadditions:block_misc@9"
            ]
        },
        {
            "x": -2,
            "y": -1,
            "z": 17,
            "elements": [
                "chisel:blockaluminum@1"
            ]
        },
        {
            "x": -3,
            "y": -2,
            "z": 29,
            "elements": [
                "actuallyadditions:block_misc@9"
            ]
        },
        {
            "x": 4,
            "y": 1,
            "z": 25,
            "elements": [
                "chisel:blockaluminum@1"
            ]
        },
        {
            "x": 4,
            "y": 5,
            "z": 4,
            "elements": [
                "additions:stainless_steel_block@0"
            ]
        },
        {
            "x": -5,
            "y": 3,
            "z": 29,
            "elements": [
                "chisel:blockaluminum@1"
            ]
        },
        {
            "x": -4,
            "y": 3,
            "z": 17,
            "elements": [
                "additions:stainless_steel_block@0"
            ]
        },
        {
            "x": -5,
            "y": 2,
            "z": 29,
            "elements": [
                "chisel:blockaluminum@1"
            ]
        },
        {
            "x": -4,
            "y": 1,
            "z": 7,
            "elements": [
                "chisel:blocksilver@3"
            ]
        },
        {
            "x": 3,
            "y": -2,
            "z": 25,
            "elements": [
                "actuallyadditions:block_misc@9"
            ]
        },
        {
            "x": 0,
            "y": 3,
            "z": 2,
            "elements": [
                "chisel:diamond@2"
            ]
        },
        {
            "x": 4,
            "y": 3,
            "z": 4,
            "elements": [
                "chisel:blockaluminum@1"
            ]
        },
        {
            "x": 2,
            "y": -2,
            "z": 9,
            "elements": [
                "actuallyadditions:block_misc@9"
            ]
        },
        {
            "x": 0,
            "y": 3,
            "z": 12,
            "elements": [
                "chisel:diamond@2"
            ]
        },
        {
            "x": 2,
            "y": 2,
            "z": 25,
            "elements": [
                "additions:manganese_steel_block@0"
            ]
        },
        {
            "x": 3,
            "y": 3,
            "z": 16,
            "elements": [
                "additions:stainless_steel_block@0"
            ]
        },
        {
            "x": 4,
            "y": 4,
            "z": 4,
            "elements": [
                "chisel:blockaluminum@1"
            ]
        },
        {
            "x": -3,
            "y": 1,
            "z": 2,
            "elements": [
                "chisel:blocksilver@3"
            ]
        },
        {
            "x": -4,
            "y": 2,
            "z": 32,
            "elements": [
                "chisel:blocksilver@3"
            ]
        },
        {
            "x": -2,
            "y": -1,
            "z": 7,
            "elements": [
                "chisel:blockaluminum@1"
            ]
        },
        {
            "x": 3,
            "y": 1,
            "z": 12,
            "elements": [
                "chisel:blocksilver@3"
            ]
        },
        {
            "x": 2,
            "y": 3,
            "z": 25,
            "elements": [
                "extrautils2:spike_stone@0"
            ]
        },
        {
            "x": 0,
            "y": 4,
            "z": 9,
            "elements": [
                "thermalfoundation:glass@3"
            ]
        },
        {
            "x": -1,
            "y": 1,
            "z": 24,
            "elements": [
                "extrautils2:spike_stone@1"
            ]
        },
        {
            "x": 4,
            "y": -1,
            "z": 21,
            "elements": [
                "chisel:blocksilver@3"
            ]
        },
        {
            "x": -5,
            "y": 1,
            "z": 29,
            "elements": [
                "chisel:blockaluminum@1"
            ]
        },
        {
            "x": -1,
            "y": 1,
            "z": 14,
            "elements": [
                "extrautils2:spike_stone@1"
            ]
        },
        {
            "x": -4,
            "y": 3,
            "z": 7,
            "elements": [
                "additions:stainless_steel_block@0"
            ]
        },
        {
            "x": -1,
            "y": -2,
            "z": 13,
            "elements": [
                "actuallyadditions:block_misc@9"
            ]
        },
        {
            "x": -2,
            "y": 4,
            "z": 8,
            "elements": [
                "chisel:blocktin@0"
            ]
        },
        {
            "x": -2,
            "y": 1,
            "z": 2,
            "elements": [
                "chisel:blockaluminum@1"
            ]
        },
        {
            "x": -2,
            "y": 2,
            "z": 29,
            "elements": [
                "extrautils2:spike_stone@3"
            ]
        },
        {
            "x": -4,
            "y": -2,
            "z": 23,
            "elements": [
                "additions:stainless_steel_block@0"
            ]
        },
        {
            "x": -1,
            "y": 2,
            "z": 8,
            "elements": [
                "extrautils2:spike_stone@3"
            ]
        },
        {
            "x": -1,
            "y": -2,
            "z": 9,
            "elements": [
                "actuallyadditions:block_misc@9"
            ]
        },
        {
            "x": 3,
            "y": 2,
            "z": 13,
            "elements": [
                "extrautils2:spike_stone@3"
            ]
        },

        {
            "x": -5,
            "y": 5,
            "z": 29,
            "elements": [
                "additions:stainless_steel_block@0"
            ]
        },
        {
            "x": 2,
            "y": -1,
            "z": 12,
            "elements": [
                "chisel:blocksilver@3"
            ]
        },
        {
            "x": -1,
            "y": 3,
            "z": 2,
            "elements": [
                "chisel:diamond@2"
            ]
        },
        {
            "x": 4,
            "y": 3,
            "z": 29,
            "elements": [
                "chisel:blockaluminum@1"
            ]
        },
        {
            "x": 3,
            "y": 5,
            "z": 10,
            "elements": [
                "minecraft:quartz_stairs@0"
            ]
        },
        {
            "x": 2,
            "y": 4,
            "z": 13,
            "elements": [
                "chisel:blocktin@0"
            ]
        },
        {
            "x": -4,
            "y": 4,
            "z": 25,
            "elements": [
                "jaopca:block.lead_platinum@0"
            ]
        },

        {
            "x": -1,
            "y": 4,
            "z": 31,
            "elements": [
                "chisel:blocktin@0"
            ]
        },

        {
            "x": -2,
            "y": -2,
            "z": 8,
            "elements": [
                "actuallyadditions:block_misc@9"
            ]
        },

        {
            "x": 1,
            "y": 0,
            "z": 1,
            "elements": [
                "casings_all"
            ]
        },

        {
            "x": 4,
            "y": 4,
            "z": 29,
            "elements": [
                "chisel:blockaluminum@1"
            ]
        },
        {
            "x": 0,
            "y": -1,
            "z": 2,
            "elements": [
                "cyclicmagic:plate_push_fast@1"
            ]
        },
        {
            "x": -2,
            "y": -2,
            "z": 25,
            "elements": [
                "actuallyadditions:block_misc@9"
            ]
        },
        {
            "x": 4,
            "y": -1,
            "z": 14,
            "elements": [
                "chisel:blockaluminum@1"
            ]
        },
        {
            "x": -4,
            "y": 5,
            "z": 25,
            "elements": [
                "minecraft:quartz_stairs@1"
            ]
        },
        {
            "x": 2,
            "y": 4,
            "z": 21,
            "elements": [
                "chisel:blocktin@0"
            ]
        },
        {
            "x": 1,
            "y": 4,
            "z": 30,
            "elements": [
                "thermalfoundation:glass@3"
            ]
        },
        {
            "x": 2,
            "y": 1,
            "z": 25,
            "elements": [
                "extrautils2:spike_stone@1"
            ]
        },
        {
            "x": -3,
            "y": 4,
            "z": 13,
            "elements": [
                "chisel:blocktin@0"
            ]
        },
        {
            "x": -4,
            "y": 2,
            "z": 25,
            "elements": [
                "extrautils2:spike_stone@0"
            ]
        },
        {
            "x": 1,
            "y": -2,
            "z": 25,
            "elements": [
                "actuallyadditions:block_misc@9"
            ]
        },
        {
            "x": -2,
            "y": 4,
            "z": 31,
            "elements": [
                "chisel:blocktin@0"
            ]
        },
        {
            "x": -2,
            "y": 3,
            "z": 2,
            "elements": [
                "chisel:blockaluminum@1"
            ]
        },
        {
            "x": 1,
            "y": 2,
            "z": 1,
            "elements": [
                "casings_all"
            ]
        },
        {
            "x": 4,
            "y": 5,
            "z": 10,
            "elements": [
                "additions:stainless_steel_block@0"
            ]
        },

        {
            "x": -1,
            "y": -1,
            "z": 2,
            "elements": [
                "cyclicmagic:plate_push_fast@1"
            ]
        },
        {
            "x": -2,
            "y": 4,
            "z": 1,
            "elements": [
                "minecraft:quartz_stairs@0"
            ]
        },
        {
            "x": 4,
            "y": 2,
            "z": 29,
            "elements": [
                "chisel:blockaluminum@1"
            ]
        },

        {
            "x": 2,
            "y": 3,
            "z": 7,
            "elements": [
                "additions:stainless_steel_block@0"
            ]
        },
        {
            "x": -1,
            "y": -1,
            "z": 9,
            "elements": [
                "cyclicmagic:plate_push_fast@1"
            ]
        },
        {
            "x": -1,
            "y": -2,
            "z": 16,
            "elements": [
                "actuallyadditions:block_misc@9"
            ]
        },
        {
            "x": 1,
            "y": 1,
            "z": 30,
            "elements": [
                "extrautils2:spike_stone@2"
            ]
        },
        {
            "x": 1,
            "y": 3,
            "z": 2,
            "elements": [
                "chisel:blockaluminum@1"
            ]
        },
        {
            "x": -2,
            "y": -1,
            "z": 2,
            "elements": [
                "chisel:blockaluminum@1"
            ]
        },

        {
            "x": -4,
            "y": -2,
            "z": 8,
            "elements": [
                "additions:stainless_steel_block@0"
            ]
        },
        {
            "x": -1,
            "y": 2,
            "z": 25,
            "elements": [
                "extrautils2:spike_stone@2"
            ]
        },

        {
            "x": 2,
            "y": 3,
            "z": 20,
            "elements": [
                "extrautils2:spike_stone@0"
            ]
        },
        {
            "x": 0,
            "y": 4,
            "z": 13,
            "elements": [
                "chisel:blocktin@0"
            ]
        },
        {
            "x": -2,
            "y": 2,
            "z": 31,
            "elements": [
                "extrautils2:spike_stone@2"
            ]
        },
        {
            "x": 1,
            "y": 4,
            "z": 1,
            "elements": [
                "minecraft:quartz_stairs@1"
            ]
        },
        {
            "x": -4,
            "y": 1,
            "z": 2,
            "elements": [
                "chisel:blocksilver@3"
            ]
        },
        {
            "x": -1,
            "y": -1,
            "z": 16,
            "elements": [
                "cyclicmagic:plate_push_fast@1"
            ]
        },
        {
            "x": 2,
            "y": 2,
            "z": 20,
            "elements": [
                "additions:manganese_steel_block@0"
            ]
        },
        {
            "x": 2,
            "y": 4,
            "z": 6,
            "elements": [
                "chisel:blocktin@0"
            ]
        },
        {
            "x": -4,
            "y": -2,
            "z": 18,
            "elements": [
                "additions:stainless_steel_block@0"
            ]
        },
        {
            "x": 3,
            "y": -2,
            "z": 31,
            "elements": [
                "additions:stainless_steel_block@0"
            ]
        },
        {
            "x": -1,
            "y": 4,
            "z": 20,
            "elements": [
                "thermalfoundation:glass@3"
            ]
        },
        {
            "x": 4,
            "y": 1,
            "z": 29,
            "elements": [
                "chisel:blockaluminum@1"
            ]
        },
        {
            "x": 2,
            "y": -2,
            "z": 13,
            "elements": [
                "additions:stainless_steel_block@0"
            ]
        },
        {
            "x": 1,
            "y": -1,
            "z": 2,
            "elements": [
                "chisel:blockaluminum@1"
            ]
        },
        {
            "x": 1,
            "y": 1,
            "z": 2,
            "elements": [
                "chisel:blockaluminum@1"
            ]
        },
        {
            "x": -4,
            "y": 3,
            "z": 2,
            "elements": [
                "additions:stainless_steel_block@0"
            ]
        },
        {
            "x": -1,
            "y": 4,
            "z": 13,
            "elements": [
                "chisel:blocktin@0"
            ]
        },
        {
            "x": -1,
            "y": 4,
            "z": 25,
            "elements": [
                "thermalfoundation:glass@3"
            ]
        },
        {
            "x": 3,
            "y": -2,
            "z": 30,
            "elements": [
                "actuallyadditions:block_misc@9"
            ]
        },
        {
            "x": -3,
            "y": -2,
            "z": 8,
            "elements": [
                "additions:stainless_steel_block@0"
            ]
        },
        {
            "x": 4,
            "y": 5,
            "z": 29,
            "elements": [
                "additions:stainless_steel_block@0"
            ]
        },
        {
            "x": 0,
            "y": -1,
            "z": 31,
            "elements": [
                "cyclicmagic:plate_push_fast@1"
            ]
        },
        {
            "x": -5,
            "y": 2,
            "z": 8,
            "elements": [
                "chisel:blocksilver@3"
            ]
        },
        {
            "x": 2,
            "y": 1,
            "z": 20,
            "elements": [
                "extrautils2:spike_stone@1"
            ]
        },
        {
            "x": 3,
            "y": 3,
            "z": 21,
            "elements": [
                "additions:stainless_steel_block@0"
            ]
        },
        {
            "x": 0,
            "y": 1,
            "z": 16,
            "elements": [
                "extrautils2:spike_stone@2"
            ]
        },
        {
            "x": 0,
            "y": -2,
            "z": 31,
            "elements": [
                "actuallyadditions:block_misc@9"
            ]
        },
        {
            "x": 3,
            "y": 4,
            "z": 10,
            "elements": [
                "jaopca:block.lead_platinum@0"
            ]
        },
        {
            "x": -4,
            "y": 2,
            "z": 20,
            "elements": [
                "extrautils2:spike_stone@0"
            ]
        },
        {
            "x": 1,
            "y": 1,
            "z": 7,
            "elements": [
                "chisel:blockaluminum@1"
            ]
        },
        {
            "x": -1,
            "y": 2,
            "z": 13,
            "elements": [
                "extrautils2:spike_stone@3"
            ]
        },
        {
            "x": -3,
            "y": 4,
            "z": 6,
            "elements": [
                "chisel:blocktin@0"
            ]
        },
        {
            "x": 0,
            "y": 0,
            "z": 15,
            "elements": [
                "extrautils2:spike_stone@1"
            ]
        },
        {
            "x": 4,
            "y": 4,
            "z": 5,
            "elements": [
                "chisel:blockaluminum@1"
            ]
        },
        {
            "x": -2,
            "y": 1,
            "z": 12,
            "elements": [
                "chisel:blockaluminum@1"
            ]
        },
        {
            "x": 3,
            "y": -2,
            "z": 29,
            "elements": [
                "actuallyadditions:block_misc@9"
            ]
        },
        {
            "x": 2,
            "y": -2,
            "z": 15,
            "elements": [
                "actuallyadditions:block_misc@9"
            ]
        },
        {
            "x": -2,
            "y": 3,
            "z": 30,
            "elements": [
                "extrautils2:spike_stone@0"
            ]
        },
        {
            "x": 0,
            "y": -2,
            "z": 30,
            "elements": [
                "actuallyadditions:block_misc@9"
            ]
        },
        {
            "x": 1,
            "y": -2,
            "z": 20,
            "elements": [
                "actuallyadditions:block_misc@9"
            ]
        },
        {
            "x": -3,
            "y": 4,
            "z": 15,
            "elements": [
                "thermalfoundation:glass@3"
            ]
        },
        {
            "x": -2,
            "y": 2,
            "z": 30,
            "elements": [
                "additions:manganese_steel_block@0"
            ]
        },
        {
            "x": -1,
            "y": -2,
            "z": 6,
            "elements": [
                "actuallyadditions:block_misc@9"
            ]
        },
        {
            "x": -1,
            "y": 4,
            "z": 1,
            "elements": [
                "chisel:blocktin@0"
            ]
        },
        {
            "x": 4,
            "y": 3,
            "z": 5,
            "elements": [
                "chisel:blockaluminum@1"
            ]
        },
        {
            "x": -3,
            "y": -2,
            "z": 31,
            "elements": [
                "additions:stainless_steel_block@0"
            ]
        },
        {
            "x": 0,
            "y": 2,
            "z": 15,
            "elements": [
                "extrautils2:spike_stone@0"
            ]
        },
        {
            "x": 0,
            "y": -1,
            "z": 30,
            "elements": [
                "cyclicmagic:plate_push_fast@1"
            ]
        },
        {
            "x": 0,
            "y": -1,
            "z": 7,
            "elements": [
                "cyclicmagic:plate_push_fast@1"
            ]
        },
        {
            "x": -1,
            "y": -2,
            "z": 15,
            "elements": [
                "actuallyadditions:block_misc@9"
            ]
        },
        {
            "x": -2,
            "y": 1,
            "z": 30,
            "elements": [
                "extrautils2:spike_stone@1"
            ]
        },
        {
            "x": -5,
            "y": 3,
            "z": 30,
            "elements": [
                "chisel:blockaluminum@1"
            ]
        },
        {
            "x": 1,
            "y": 2,
            "z": 29,
            "elements": [
                "extrautils2:spike_stone@0"
            ]
        },
        {
            "x": -1,
            "y": 2,
            "z": 20,
            "elements": [
                "extrautils2:spike_stone@2"
            ]
        },
        {
            "x": 3,
            "y": -1,
            "z": 17,
            "elements": [
                "chisel:blocksilver@3"
            ]
        },
        {
            "x": 2,
            "y": -2,
            "z": 6,
            "elements": [
                "additions:stainless_steel_block@0"
            ]
        },

        {
            "x": -3,
            "y": -2,
            "z": 30,
            "elements": [
                "actuallyadditions:block_misc@9"
            ]
        },
        {
            "x": 4,
            "y": 0,
            "z": 29,
            "elements": [
                "chisel:blockaluminum@1"
            ]
        },
        {
            "x": -5,
            "y": 0,
            "z": 30,
            "elements": [
                "chisel:blockaluminum@1"
            ]
        },
        {
            "x": 3,
            "y": -1,
            "z": 2,
            "elements": [
                "chisel:blocksilver@3"
            ]
        },
        {
            "x": 0,
            "y": 3,
            "z": 22,
            "elements": [
                "chisel:diamond@2"
            ]
        },
        {
            "x": -4,
            "y": 0,
            "z": 20,
            "elements": [
                "extrautils2:spike_stone@1"
            ]
        },
        {
            "x": -2,
            "y": 3,
            "z": 12,
            "elements": [
                "chisel:blockaluminum@1"
            ]
        },
        {
            "x": 4,
            "y": 5,
            "z": 5,
            "elements": [
                "additions:stainless_steel_block@0"
            ]
        },
        {
            "x": -5,
            "y": 2,
            "z": 30,
            "elements": [
                "chisel:blockaluminum@1"
            ]
        },
        {
            "x": -4,
            "y": 1,
            "z": 20,
            "elements": [
                "additions:manganese_steel_block@0"
            ]
        },
        {
            "x": 2,
            "y": -1,
            "z": 22,
            "elements": [
                "chisel:blocksilver@3"
            ]
        },
        {
            "x": -1,
            "y": -1,
            "z": 15,
            "elements": [
                "cyclicmagic:plate_push_fast@1"
            ]
        },
        {
            "x": 1,
            "y": -2,
            "z": 13,
            "elements": [
                "actuallyadditions:block_misc@9"
            ]
        },
        {
            "x": 1,
            "y": 1,
            "z": 29,
            "elements": [
                "additions:manganese_steel_block@0"
            ]
        },
        {
            "x": -2,
            "y": 3,
            "z": 7,
            "elements": [
                "chisel:blockaluminum@1"
            ]
        },
        {
            "x": -5,
            "y": 1,
            "z": 30,
            "elements": [
                "chisel:blockaluminum@1"
            ]
        },
        {
            "x": 3,
            "y": 0,
            "z": 22,
            "elements": [
                "chisel:blocksilver@3"
            ]
        },
        {
            "x": 3,
            "y": -1,
            "z": 7,
            "elements": [
                "chisel:blocksilver@3"
            ]
        },
        {
            "x": 0,
            "y": -1,
            "z": 12,
            "elements": [
                "cyclicmagic:plate_push_fast@1"
            ]
        },
        {
            "x": -1,
            "y": -2,
            "z": 1,
            "elements": [
                "chisel:blockaluminum@1"
            ]
        },
        {
            "x": -2,
            "y": -2,
            "z": 23,
            "elements": [
                "actuallyadditions:block_misc@9"
            ]
        },
        {
            "x": -2,
            "y": 2,
            "z": 1,
            "elements": [
                "casings_all"
            ]
        },
        {
            "x": 1,
            "y": 0,
            "z": 29,
            "elements": [
                "extrautils2:spike_stone@1"
            ]
        },
        {
            "x": -5,
            "y": 5,
            "z": 30,
            "elements": [
                "additions:stainless_steel_block@0"
            ]
        },
        {
            "x": 4,
            "y": 3,
            "z": 30,
            "elements": [
                "chisel:blockaluminum@1"
            ]
        },
        {
            "x": 3,
            "y": 3,
            "z": 22,
            "elements": [
                "additions:stainless_steel_block@0"
            ]
        },
        {
            "x": 1,
            "y": 3,
            "z": 17,
            "elements": [
                "chisel:blockaluminum@1"
            ]
        },
        {
            "x": -4,
            "y": 1,
            "z": 14,
            "elements": [
                "extrautils2:spike_stone@3"
            ]
        },
        {
            "x": -5,
            "y": 4,
            "z": 30,
            "elements": [
                "chisel:blockaluminum@1"
            ]
        },
        {
            "x": -2,
            "y": 4,
            "z": 29,
            "elements": [
                "thermalfoundation:glass@3"
            ]
        },
        {
            "x": 0,
            "y": -2,
            "z": 18,
            "elements": [
                "actuallyadditions:block_misc@9"
            ]
        },
        {
            "x": 0,
            "y": -1,
            "z": 29,
            "elements": [
                "cyclicmagic:plate_push_fast@1"
            ]
        },
        {
            "x": 4,
            "y": 2,
            "z": 30,
            "elements": [
                "chisel:blockaluminum@1"
            ]
        },
        {
            "x": 1,
            "y": 3,
            "z": 7,
            "elements": [
                "chisel:blockaluminum@1"
            ]
        },
        {
            "x": -2,
            "y": -2,
            "z": 13,
            "elements": [
                "actuallyadditions:block_misc@9"
            ]
        },

        {
            "x": 3,
            "y": 2,
            "z": 22,
            "elements": [
                "chisel:blocksilver@3"
            ]
        },
        {
            "x": -3,
            "y": -1,
            "z": 12,
            "elements": [
                "chisel:blocksilver@3"
            ]
        },
        {
            "x": -2,
            "y": 0,
            "z": 1,
            "elements": [
                "casings_all"
            ]
        },
        {
            "x": 0,
            "y": -2,
            "z": 29,
            "elements": [
                "actuallyadditions:block_misc@9"
            ]
        },
        {
            "x": 0,
            "y": -2,
            "z": 1,
            "elements": [
                "chisel:blockaluminum@1"
            ]
        },
        {
            "x": 0,
            "y": 4,
            "z": 6,
            "elements": [
                "chisel:blocktin@0"
            ]
        },
        {
            "x": 3,
            "y": 1,
            "z": 22,
            "elements": [
                "chisel:blocksilver@3"
            ]
        },
        {
            "x": 4,
            "y": 1,
            "z": 30,
            "elements": [
                "chisel:blockaluminum@1"
            ]
        },
        {
            "x": -2,
            "y": 4,
            "z": 18,
