{
    "registryname": "elysia_polymer",
    "localizedname": "§cELYSIA单元 - 大型聚合单元",
    "requires-blueprint": false,
    "failure-action": "still",
    "color": "070707",
    "modifiers": [
        {
            "elements": "modularmachinery:blockcasing@1",
            "x": 0,
            "y": -1,
            "z": 0,
            "description": "将控制器下方紧挨着的方块换成此方块以降低配方制作时间至75%！",
            "modifier": {
                "io": "input",
                "target": "modularmachinery:duration",
                "operation": 1,
                "multiplier": 0.75
            }
        },
        {
            "elements": "modularmachinery:blockcasing@2",
            "x": 0,
            "y": -1,
            "z": 0,
            "description": "将控制器下方紧挨着的方块换成此方块以降低配方制作时间至66%！",
            "modifier": {
                "io": "input",
                "target": "modularmachinery:duration",
                "operation": 1,
                "multiplier": 0.66
            }
        },
        {
            "elements": "modularmachinery:blockcasing@3",
            "x": 0,
            "y": -1,
            "z": 0,
            "description": "将控制器下方紧挨着的方块换成此方块以降低配方制作时间至50%！",
            "modifier": {
                "io": "input",
                "target": "modularmachinery:duration",
                "operation": 1,
                "multiplier": 0.5
            }
        },
        {
            "elements": "modularmachinery:blockcasing@5",
            "x": 0,
            "y": -1,
            "z": 0,
            "description": "将控制器下方紧挨着的方块换成此方块以降低配方制作时间至33%！",
            "modifier": {
                "io": "input",
                "target": "modularmachinery:duration",
                "operation": 1,
                "multiplier": 0.33
            }
        }
    ],
    "parts": [
        {
            "x": 0,
            "y": 0,
            "z": 0,
            "elements": [
                "modularmachinery:blockcontroller@2"
            ]
        },
        {
            "x": 0,
            "y": -2,
            "z": 0,
            "elements": [
                "minecraft:iron_bars@0"
            ]
        },
        {
            "x": -3,
            "y": 0,
            "z": 5,
            "elements": [
                "casings_all"
            ]
        },
        {
            "x": -3,
            "y": -8,
            "z": -1,
            "elements": [
                "jaopca:block.niobium_titanium@0"
            ]
        },
        {
            "x": -6,
            "y": -1,
            "z": -1,
            "elements": [
                "avaritia:block_resource@0"
            ]
        },
        {
            "x": 5,
            "y": 0,
            "z": 1,
            "elements": [
                "jaopca:block.ruthenium@0"
            ]
        },
        {
            "x": -1,
            "y": -10,
            "z": -3,
            "elements": [
                "jaopca:block.niobium_titanium@0"
            ]
        },
        {
            "x": -6,
            "y": 1,
            "z": -1,
            "elements": [
                "avaritia:block_resource@0"
            ]
        },
        {
            "x": 2,
            "y": -6,
            "z": 0,
            "elements": [
                "nuclearcraft:machine_frame@0"
            ]
        },
        {
            "x": 3,
            "y": -8,
            "z": 0,
            "elements": [
                "jaopca:block.niobium_titanium@0"
            ]
        },
        {
            "x": 0,
            "y": -1,
            "z": 0,
            "elements": [
                "minecraft:iron_bars@0"
            ]
        },
        {
            "x": 0,
            "y": -12,
            "z": -1,
            "elements": [
                "jaopca:block.zirconium_molybdenum@0"
            ]
        },
        {
            "x": 1,
            "y": -3,
            "z": 0,
            "elements": [
                "moretcon:blockgravitonium@0"
            ]
        },
        {
            "x": -1,
            "y": -12,
            "z": -3,
            "elements": [
                "jaopca:block.niobium_titanium@0"
            ]
        },
        {
            "x": 2,
            "y": -5,
            "z": 0,
            "elements": [
                "nuclearcraft:machine_frame@0"
            ]
        },
        {
            "x": -1,
            "y": -11,
            "z": -3,
            "elements": [
                "jaopca:block.niobium_titanium@0"
            ]
        },
        {
            "x": -6,
            "y": 0,
            "z": -1,
            "elements": [
                "avaritia:block_resource@0"
            ]
        },
        {
            "x": 3,
            "y": -7,
            "z": 0,
            "elements": [
                "jaopca:block.niobium_titanium@0"
            ]
        },
        {
            "x": -3,
            "y": -7,
            "z": -1,
            "elements": [
                "jaopca:block.niobium_titanium@0"
            ]
        },
        {
            "x": 2,
            "y": -7,
            "z": 0,
            "elements": [
                "nuclearcraft:machine_frame@0"
            ]
        },
        {
            "x": 1,
            "y": -2,
            "z": 0,
            "elements": [
                "tiths:block_steamium@0"
            ]
        },
        {
            "x": 0,
            "y": -4,
            "z": 0,
            "elements": [
                "minecraft:iron_bars@0"
            ]
        },
        {
            "x": 3,
            "y": -6,
            "z": 0,
            "elements": [
                "jaopca:block.niobium_titanium@0"
            ]
        },
        {
            "x": -3,
            "y": -6,
            "z": -1,
            "elements": [
                "jaopca:block.niobium_titanium@0"
            ]
        },
        {
            "x": -3,
            "y": -5,
            "z": -1,
            "elements": [
                "jaopca:block.niobium_titanium@0"
            ]
        },
        {
            "x": 2,
            "y": -8,
            "z": 0,
            "elements": [
                "nuclearcraft:machine_frame@0"
            ]
        },
        {
            "x": -1,
            "y": -8,
            "z": -3,
            "elements": [
                "jaopca:block.niobium_titanium@0"
            ]
        },
        {
            "x": 3,
            "y": 0,
            "z": -5,
            "elements": [
                "casings_all"
            ]
        },
        {
            "x": 0,
            "y": -3,
            "z": 0,
            "elements": [
                "minecraft:iron_bars@0"
            ]
        },
        {
            "x": 3,
            "y": -5,
            "z": 0,
            "elements": [
                "jaopca:block.niobium_titanium@0"
            ]
        },
        {
            "x": -1,
            "y": -9,
            "z": -3,
            "elements": [
                "jaopca:block.niobium_titanium@0"
            ]
        },
        {
            "x": 0,
            "y": -4,
            "z": 5,
            "elements": [
                "jaopca:block.niobium_titanium@0"
            ]
        },
        {
            "x": 0,
            "y": 1,
            "z": -5,
            "elements": [
                "thermalfoundation:storage@7"
            ]
        },
        {
            "x": -3,
            "y": -9,
            "z": -1,
            "elements": [
                "jaopca:block.niobium_titanium@0"
            ]
        },
        {
            "x": 2,
            "y": -9,
            "z": -3,
            "elements": [
                "additions:manganese_steel_block@0"
            ]
        },
        {
            "x": 2,
            "y": -9,
            "z": 0,
            "elements": [
                "nuclearcraft:machine_frame@0"
            ]
        },
        {
            "x": -1,
            "y": -7,
            "z": -3,
            "elements": [
                "jaopca:block.niobium_titanium@0"
            ]
        },
        {
            "x": 3,
            "y": -4,
            "z": 0,
            "elements": [
                "jaopca:block.niobium_titanium@0"
            ]
        },
        {
            "x": 1,
            "y": 0,
            "z": 6,
            "elements": [
                "avaritia:block_resource@0"
            ]
        },
        {
            "x": 0,
            "y": -3,
            "z": 5,
            "elements": [
                "jaopca:block.niobium_titanium@0"
            ]
        },
        {
            "x": 0,
            "y": -12,
            "z": 3,
            "elements": [
                "jaopca:block.niobium_titanium@0"
            ]
        },
        {
            "x": 0,
            "y": 0,
            "z": -5,
            "elements": [
                "thermalfoundation:storage@7"
            ]
        },
        {
            "x": 2,
            "y": -8,
            "z": -3,
            "elements": [
                "additions:manganese_steel_block@0"
            ]
        },
        {
            "x": -3,
            "y": -10,
            "z": -1,
            "elements": [
                "jaopca:block.niobium_titanium@0"
            ]
        },
        {
            "x": -1,
            "y": -6,
            "z": -3,
            "elements": [
                "jaopca:block.niobium_titanium@0"
            ]
        },
        {
            "x": 4,
            "y": -5,
            "z": 0,
            "elements": [
                "jaopca:block.niobium_titanium@0"
            ]
        },
        {
            "x": 2,
            "y": -10,
            "z": 0,
            "elements": [
                "nuclearcraft:machine_frame@0"
            ]
        },
        {
            "x": 1,
            "y": 1,
            "z": 6,
            "elements": [
                "avaritia:block_resource@0"
            ]
        },
        {
            "x": 0,
            "y": 0,
            "z": 5,
            "elements": [
                "mekanism:basicblock@0"
            ]
        },
        {
            "x": 0,
            "y": -11,
            "z": 3,
            "elements": [
                "jaopca:block.niobium_titanium@0"
            ]
        },
        {
            "x": -3,
            "y": -11,
            "z": -1,
            "elements": [
                "jaopca:block.niobium_titanium@0"
            ]
        },
        {
            "x": 6,
            "y": 0,
            "z": -1,
            "elements": [
                "avaritia:block_resource@0"
            ]
        },
        {
            "x": -1,
            "y": -5,
            "z": -3,
            "elements": [
                "jaopca:block.niobium_titanium@0"
            ]
        },
        {
            "x": 6,
            "y": 1,
            "z": 1,
            "elements": [
                "avaritia:block_resource@0"
            ]
        },
        {
            "x": 6,
            "y": 0,
            "z": 1,
            "elements": [
                "avaritia:block_resource@0"
            ]
        },
        {
            "x": -2,
            "y": -4,
            "z": 0,
            "elements": [
                "nuclearcraft:machine_frame@0"
            ]
        },
        {
            "x": 2,
            "y": -10,
            "z": -3,
            "elements": [
                "additions:manganese_steel_block@0"
            ]
        },
        {
            "x": 2,
            "y": -11,
            "z": 0,
            "elements": [
                "nuclearcraft:machine_frame@0"
            ]
        },
        {
            "x": 0,
            "y": -1,
            "z": 6,
            "elements": [
                "avaritia:block_resource@0"
            ]
        },
        {
            "x": -1,
            "y": 1,
            "z": -6,
            "elements": [
                "avaritia:block_resource@0"
            ]
        },
        {
            "x": 0,
            "y": -10,
            "z": 3,
            "elements": [
                "jaopca:block.niobium_titanium@0"
            ]
        },
        {
            "x": 6,
            "y": 1,
            "z": -1,
            "elements": [
                "avaritia:block_resource@0"
            ]
        },
        {
            "x": -3,
            "y": -12,
            "z": -1,
            "elements": [
                "jaopca:block.niobium_titanium@0"
            ]
        },
        {
            "x": -2,
            "y": -3,
            "z": 0,
            "elements": [
                "jaopca:block.niobium_titanium@0"
            ]
        },
        {
            "x": -1,
            "y": 0,
            "z": -6,
            "elements": [
                "avaritia:block_resource@0"
            ]
        },
        {
            "x": 2,
            "y": -12,
            "z": 0,
            "elements": [
                "nuclearcraft:machine_frame@0"
            ]
        },
        {
            "x": -1,
            "y": -4,
            "z": -3,
            "elements": [
                "jaopca:block.niobium_titanium@0"
            ]
        },
        {
            "x": 0,
            "y": 1,
            "z": 5,
            "elements": [
                "mekanism:basicblock@0"
            ]
        },
        {
            "x": 4,
            "y": 0,
            "z": 0,
            "elements": [
                "jaopca:block.ruthenium@0"
            ]
        },
        {
            "x": 2,
            "y": -10,
            "z": 1,
            "elements": [
                "extendedcrafting:storage@0"
            ]
        },
        {
            "x": 2,
            "y": -9,
            "z": 1,
            "elements": [
                "extendedcrafting:storage@0"
            ]
        },
        {
            "x": 0,
            "y": -9,
            "z": 0,
            "elements": [
                "minecraft:iron_bars@0"
            ]
        },
        {
            "x": -3,
            "y": -4,
            "z": 0,
            "elements": [
                "jaopca:block.niobium_titanium@0"
            ]
        },
        {
            "x": -1,
            "y": -12,
            "z": 1,
            "elements": [
                "jaopca:block.zirconium_molybdenum@0"
            ]
        },
        {
            "x": -4,
            "y": 1,
            "z": 0,
            "elements": [
                "jaopca:block.ruthenium@0"
            ]
        },
        {
            "x": 0,
            "y": 1,
            "z": 4,
            "elements": [
                "mekanism:basicblock@0"
            ]
        },
        {
            "x": 0,
            "y": 0,
            "z": -4,
            "elements": [
                "thermalfoundation:storage@7"
            ]
        },
        {
            "x": 0,
            "y": -10,
            "z": 0,
            "elements": [
                "minecraft:iron_bars@0"
            ]
        },
        {
            "x": 2,
            "y": -12,
            "z": 1,
            "elements": [
                "nuclearcraft:machine_frame@0"
            ]
        },
        {
            "x": 5,
            "y": 0,
            "z": 0,
            "elements": [
                "jaopca:block.ruthenium@0"
            ]
        },
        {
            "x": 0,
            "y": -11,
            "z": 0,
            "elements": [
                "minecraft:iron_bars@0"
            ]
        },
        {
            "x": 4,
            "y": -1,
            "z": 0,
            "elements": [
                "jaopca:block.ruthenium@0"
            ]
        },
        {
            "x": -5,
            "y": 1,
            "z": 0,
            "elements": [
                "jaopca:block.ruthenium@0"
            ]
        },
        {
            "x": 2,
            "y": -11,
            "z": 1,
            "elements": [
                "extendedcrafting:storage@0"
            ]
        },
        {
            "x": 0,
            "y": 0,
            "z": 4,
            "elements": [
                "mekanism:basicblock@0"
            ]
        },
        {
            "x": 0,
            "y": -4,
            "z": -5,
            "elements": [
                "jaopca:block.niobium_titanium@0"
            ]
        },
        {
            "x": 0,
            "y": -12,
            "z": 0,
            "elements": [
                "jaopca:block.zirconium_molybdenum@0"
            ]
        },
        {
            "x": -3,
            "y": -7,
            "z": 0,
            "elements": [
                "jaopca:block.niobium_titanium@0"
            ]
        },
        {
            "x": 3,
            "y": -11,
            "z": 0,
            "elements": [
                "jaopca:block.niobium_titanium@0"
            ]
        },
        {
            "x": 0,
            "y": -1,
            "z": -5,
            "elements": [
                "thermalfoundation:storage@7"
            ]
        },
        {
            "x": -1,
            "y": 0,
            "z": 5,
            "elements": [
                "mekanism:basicblock@0"
            ]
        },
        {
            "x": 4,
            "y": 0,
            "z": -5,
            "elements": [
                "casings_all"
            ]
        },
        {
            "x": 0,
            "y": -6,
            "z": 0,
            "elements": [
                "jaopca:block.blue_alloy@0"
            ]
        },
        {
            "x": 0,
            "y": -3,
            "z": -5,
            "elements": [
                "jaopca:block.niobium_titanium@0"
            ]
        },
        {
            "x": -6,
            "y": -1,
            "z": 0,
            "elements": [
                "avaritia:block_resource@0"
            ]
        },
        {
            "x": 5,
            "y": 1,
            "z": 0,
            "elements": [
                "jaopca:block.ruthenium@0"
            ]
        },
        {
            "x": -3,
            "y": -8,
            "z": 0,
            "elements": [
                "jaopca:block.niobium_titanium@0"
            ]
        },
        {
            "x": -5,
            "y": 0,
            "z": 0,
            "elements": [
                "jaopca:block.ruthenium@0"
            ]
        },
        {
            "x": 0,
            "y": -5,
            "z": 0,
            "elements": [
                "minecraft:iron_bars@0"
            ]
        },
        {
            "x": 3,
            "y": -12,
            "z": 0,
            "elements": [
                "jaopca:block.niobium_titanium@0"
            ]
        },
        {
            "x": 0,
            "y": -2,
            "z": -5,
            "elements": [
                "jaopca:block.niobium_titanium@0"
            ]
        },
        {
            "x": 0,
            "y": -7,
            "z": 0,
            "elements": [
                "minecraft:iron_bars@0"
            ]
        },
        {
            "x": -3,
            "y": -5,
            "z": 0,
            "elements": [
                "jaopca:block.niobium_titanium@0"
            ]
        },
        {
            "x": -4,
            "y": 0,
            "z": 5,
            "elements": [
                "casings_all"
            ]
        },
        {
            "x": -6,
            "y": 0,
            "z": 1,
            "elements": [
                "avaritia:block_resource@0"
            ]
        },
        {
            "x": 3,
            "y": -9,
            "z": 0,
            "elements": [
                "jaopca:block.niobium_titanium@0"
            ]
        },
        {
            "x": -3,
            "y": -6,
            "z": 0,
            "elements": [
                "jaopca:block.niobium_titanium@0"
            ]
        },
        {
            "x": -6,
            "y": 1,
            "z": 1,
            "elements": [
                "avaritia:block_resource@0"
            ]
        },
        {
            "x": 1,
            "y": 0,
            "z": -5,
            "elements": [
                "thermalfoundation:storage@7"
            ]
        },
        {
            "x": 0,
            "y": -8,
            "z": 0,
            "elements": [
                "minecraft:iron_bars@0"
            ]
        },
        {
            "x": 3,
            "y": -10,
            "z": 0,
            "elements": [
                "jaopca:block.niobium_titanium@0"
            ]
        },
        {
            "x": -2,
            "y": -12,
            "z": 0,
            "elements": [
                "nuclearcraft:machine_frame@0"
            ]
        },
        {
            "x": -1,
            "y": -11,
            "z": 3,
            "elements": [
                "jaopca:block.niobium_titanium@0"
            ]
        },
        {
            "x": 1,
            "y": -7,
            "z": -3,
            "elements": [
                "jaopca:block.niobium_titanium@0"
            ]
        },
        {
            "x": 2,
            "y": -10,
            "z": 3,
            "elements": [
                "additions:manganese_steel_block@0"
            ]
        },
        {
            "x": -1,
            "y": -8,
            "z": 3,
            "elements": [
                "jaopca:block.niobium_titanium@0"
            ]
        },
        {
            "x": -2,
            "y": -11,
            "z": 0,
            "elements": [
                "nuclearcraft:machine_frame@0"
            ]
        },
        {
            "x": -1,
            "y": -10,
            "z": 3,
            "elements": [
                "jaopca:block.niobium_titanium@0"
            ]
        },
        {
            "x": -1,
            "y": 0,
            "z": 4,
            "elements": [
                "mekanism:basicblock@0"
            ]
        },
        {
            "x": -1,
            "y": -9,
            "z": 3,
            "elements": [
                "jaopca:block.niobium_titanium@0"
            ]
        },
        {
            "x": 1,
            "y": -6,
            "z": -3,
            "elements": [
                "jaopca:block.niobium_titanium@0"
            ]
        },
        {
            "x": 0,
            "y": -1,
            "z": -4,
            "elements": [
                "thermalfoundation:storage@7"
            ]
        },
        {
            "x": -1,
            "y": -6,
            "z": 3,
            "elements": [
                "jaopca:block.niobium_titanium@0"
            ]
        },
        {
            "x": -2,
            "y": -7,
            "z": -3,
            "elements": [
                "additions:manganese_steel_block@0"
            ]
        },
        {
            "x": 0,
            "y": -7,
            "z": -2,
            "elements": [
                "nuclearcraft:machine_frame@0"
            ]
        },
        {
            "x": 1,
            "y": -5,
            "z": -3,
            "elements": [
                "jaopca:block.niobium_titanium@0"
            ]
        },
        {
            "x": -2,
            "y": -6,
            "z": -3,
            "elements": [
                "additions:manganese_steel_block@0"
            ]
        },
        {
            "x": 0,
            "y": -8,
            "z": -2,
            "elements": [
                "nuclearcraft:machine_frame@0"
            ]
        },
        {
            "x": 1,
            "y": -4,
            "z": -3,
            "elements": [
                "jaopca:block.niobium_titanium@0"
            ]
        },
        {
            "x": -1,
            "y": -7,
            "z": 3,
            "elements": [
                "jaopca:block.niobium_titanium@0"
            ]
        },
        {
            "x": -1,
            "y": -12,
            "z": 3,
            "elements": [
                "jaopca:block.niobium_titanium@0"
            ]
        },
        {
            "x": 3,
            "y": 0,
            "z": 5,
            "elements": [
                "casings_all"
            ]
        },
        {
            "x": 0,
            "y": -9,
            "z": -2,
            "elements": [
                "nuclearcraft:machine_frame@0"
            ]
        },
        {
            "x": -3,
            "y": -7,
            "z": -2,
            "elements": [
                "additions:manganese_steel_block@0"
            ]
        },
        {
            "x": -5,
            "y": -4,
            "z": 0,
            "elements": [
                "jaopca:block.niobium_titanium@0"
            ]
        },
        {
            "x": 1,
            "y": -10,
            "z": -3,
            "elements": [
                "jaopca:block.niobium_titanium@0"
            ]
        },
        {
            "x": 0,
            "y": -10,
            "z": -2,
            "elements": [
                "nuclearcraft:machine_frame@0"
            ]
        },
        {
            "x": 1,
            "y": -12,
            "z": -3,
            "elements": [
                "jaopca:block.niobium_titanium@0"
            ]
        },
        {
            "x": -5,
            "y": -3,
            "z": 0,
            "elements": [
                "jaopca:block.niobium_titanium@0"
            ]
        },
        {
            "x": 1,
            "y": -11,
            "z": -3,
            "elements": [
                "jaopca:block.niobium_titanium@0"
            ]
        },
        {
            "x": -3,
            "y": -8,
            "z": -2,
            "elements": [
                "additions:manganese_steel_block@0"
            ]
        },
        {
            "x": 1,
            "y": -9,
            "z": -3,
            "elements": [
                "jaopca:block.niobium_titanium@0"
            ]
        },
        {
            "x": 0,
            "y": 1,
            "z": -4,
            "elements": [
                "thermalfoundation:storage@7"
            ]
        },
        {
            "x": 0,
            "y": -6,
            "z": -2,
            "elements": [
                "nuclearcraft:machine_frame@0"
            ]
        },
        {
            "x": 0,
            "y": -11,
            "z": -2,
            "elements": [
                "nuclearcraft:machine_frame@0"
            ]
        },
        {
            "x": -5,
            "y": -2,
            "z": 0,
            "elements": [
                "jaopca:block.niobium_titanium@0"
            ]
        },
        {
            "x": 3,
            "y": -9,
            "z": -2,
            "elements": [
                "additions:manganese_steel_block@0"
            ]
        },
        {
            "x": 6,
            "y": -1,
            "z": 0,
            "elements": [
                "avaritia:block_resource@0"
            ]
        },
        {
            "x": 5,
            "y": 0,
            "z": -3,
            "elements": [
                "casings_all"
            ]
        },
        {
            "x": 1,
            "y": 0,
            "z": -4,
            "elements": [
                "thermalfoundation:storage@7"
            ]
        },
        {
            "x": 0,
            "y": -5,
            "z": -2,
            "elements": [
                "nuclearcraft:machine_frame@0"
            ]
        },
        {
            "x": 1,
            "y": -8,
            "z": -3,
            "elements": [
                "jaopca:block.niobium_titanium@0"
            ]
        },
        {
            "x": 0,
            "y": -12,
            "z": -2,
            "elements": [
                "nuclearcraft:machine_frame@0"
            ]
        },
        {
            "x": -5,
            "y": -1,
            "z": 0,
            "elements": [
                "jaopca:block.ruthenium@0"
            ]
        },
        {
            "x": 4,
            "y": 1,
            "z": 0,
            "elements": [
                "jaopca:block.ruthenium@0"
            ]
        },
        {
            "x": -5,
            "y": 0,
            "z": 3,
            "elements": [
                "casings_all"
            ]
        },
        {
            "x": -3,
            "y": -6,
            "z": -2,
            "elements": [
                "additions:manganese_steel_block@0"
            ]
        },
        {
            "x": -3,
            "y": 0,
            "z": -5,
            "elements": [
                "casings_all"
            ]
        },
        {
            "x": -4,
            "y": 0,
            "z": 0,
            "elements": [
                "jaopca:block.ruthenium@0"
            ]
        },
        {
            "x": 0,
            "y": -5,
            "z": 4,
            "elements": [
                "jaopca:block.niobium_titanium@0"
            ]
        },
        {
            "x": 3,
            "y": -10,
            "z": -2,
            "elements": [
                "additions:manganese_steel_block@0"
            ]
        },
        {
            "x": 0,
            "y": -6,
            "z": 3,
            "elements": [
                "jaopca:block.niobium_titanium@0"
            ]
        },
        {
            "x": 0,
            "y": 0,
            "z": -3,
            "elements": [
                "thermalfoundation:storage@7"
            ]
        },
        {
            "x": -2,
            "y": -6,
            "z": 0,
            "elements": [
                "nuclearcraft:machine_frame@0"
            ]
        },
        {
            "x": 0,
            "y": 0,
            "z": 3,
            "elements": [
                "mekanism:basicblock@0"
            ]
        },
        {
            "x": 0,
            "y": -7,
            "z": 3,
            "elements": [
                "jaopca:block.niobium_titanium@0"
            ]
        },
        {
            "x": -2,
            "y": -5,
            "z": 0,
            "elements": [
                "nuclearcraft:machine_frame@0"
            ]
        },
        {
            "x": -3,
            "y": -9,
            "z": -2,
            "elements": [
                "additions:manganese_steel_block@0"
            ]
        },
        {
            "x": 1,
            "y": -12,
            "z": 0,
            "elements": [
                "jaopca:block.zirconium_molybdenum@0"
            ]
        },
        {
            "x": -2,
            "y": -7,
            "z": 0,
            "elements": [
                "nuclearcraft:machine_frame@0"
            ]
        },
        {
            "x": 2,
            "y": -7,
            "z": -3,
            "elements": [
                "additions:manganese_steel_block@0"
            ]
        },
        {
            "x": 0,
            "y": -8,
            "z": 3,
            "elements": [
                "jaopca:block.niobium_titanium@0"
            ]
        },
        {
            "x": -3,
            "y": -10,
            "z": -2,
            "elements": [
                "additions:manganese_steel_block@0"
            ]
        },
        {
            "x": -2,
            "y": -8,
            "z": 0,
            "elements": [
                "nuclearcraft:machine_frame@0"
            ]
        },
        {
            "x": 0,
            "y": -9,
            "z": 3,
            "elements": [
                "jaopca:block.niobium_titanium@0"
            ]
        },
        {
            "x": 2,
            "y": -6,
            "z": -3,
            "elements": [
                "additions:manganese_steel_block@0"
            ]
        },
        {
            "x": 2,
            "y": -6,
            "z": 3,
            "elements": [
                "additions:manganese_steel_block@0"
            ]
        },
        {
            "x": -1,
            "y": -4,
            "z": 3,
            "elements": [
                "jaopca:block.niobium_titanium@0"
            ]
        },
        {
            "x": -1,
            "y": -10,
            "z": 2,
            "elements": [
                "extendedcrafting:storage@0"
            ]
        },
        {
            "x": 0,
            "y": -1,
            "z": 4,
            "elements": [
                "mekanism:basicblock@0"
            ]
        },
        {
            "x": -2,
            "y": -9,
            "z": 0,
            "elements": [
                "nuclearcraft:machine_frame@0"
            ]
        },
        {
            "x": -1,
            "y": -9,
            "z": 2,
            "elements": [
                "extendedcrafting:storage@0"
            ]
        },
        {
            "x": 1,
            "y": -8,
            "z": 3,
            "elements": [
                "jaopca:block.niobium_titanium@0"
            ]
        },
        {
            "x": -1,
            "y": -5,
            "z": 3,
            "elements": [
                "jaopca:block.niobium_titanium@0"
            ]
        },
        {
            "x": -1,
            "y": 0,
            "z": -4,
            "elements": [
                "thermalfoundation:storage@7"
            ]
        },
        {
            "x": -1,
            "y": -11,
            "z": 2,
            "elements": [
                "extendedcrafting:storage@0"
            ]
        },
        {
            "x": 0,
            "y": -5,
            "z": -4,
            "elements": [
                "jaopca:block.niobium_titanium@0"
            ]
        },
        {
            "x": 2,
            "y": -7,
            "z": 3,
            "elements": [
                "additions:manganese_steel_block@0"
            ]
        },
        {
            "x": 1,
            "y": 0,
            "z": 4,
            "elements": [
                "mekanism:basicblock@0"
            ]
        },
        {
            "x": 1,
            "y": -9,
            "z": 3,
            "elements": [
                "jaopca:block.niobium_titanium@0"
            ]
        },
        {
            "x": -2,
            "y": -10,
            "z": 0,
            "elements": [
                "nuclearcraft:machine_frame@0"
            ]
        },
        {
            "x": 1,
            "y": -6,
            "z": 3,
            "elements": [
                "jaopca:block.niobium_titanium@0"
            ]
        },
        {
            "x": 0,
            "y": -4,
            "z": 3,
            "elements": [
                "jaopca:block.niobium_titanium@0"
            ]
        },
        {
            "x": -5,
            "y": 0,
            "z": 4,
            "elements": [
                "casings_all"
            ]
        },
        {
            "x": 2,
            "y": -8,
            "z": 3,
            "elements": [
                "additions:manganese_steel_block@0"
            ]
        },
        {
            "x": 5,
            "y": 0,
            "z": -4,
            "elements": [
                "casings_all"
            ]
        },
        {
            "x": 0,
            "y": -5,
            "z": 3,
            "elements": [
                "jaopca:block.niobium_titanium@0"
            ]
        },
        {
            "x": 6,
            "y": 0,
            "z": -2,
            "elements": [
                "avaritia:block_resource@0"
            ]
        },
        {
            "x": 2,
            "y": -9,
            "z": 3,
            "elements": [
                "additions:manganese_steel_block@0"
            ]
        },
        {
            "x": 1,
            "y": -7,
            "z": 3,
            "elements": [
                "jaopca:block.niobium_titanium@0"
            ]
        },
        {
            "x": -1,
            "y": -12,
            "z": 2,
            "elements": [
                "nuclearcraft:machine_frame@0"
            ]
        },
        {
            "x": 1,
            "y": -11,
            "z": -2,
            "elements": [
                "extendedcrafting:storage@0"
            ]
        },
        {
            "x": -2,
            "y": -7,
            "z": 2,
            "elements": [
                "jaopca:block.zirconium_molybdenum@0"
            ]
        },
        {
            "x": -2,
            "y": -10,
            "z": 1,
            "elements": [
                "extendedcrafting:storage@0"
            ]
        },
        {
            "x": -6,
            "y": 0,
            "z": 2,
            "elements": [
                "avaritia:block_resource@0"
            ]
        },
        {
            "x": 1,
            "y": -9,
            "z": 2,
            "elements": [
                "extendedcrafting:storage@0"
            ]
        },
        {
            "x": -1,
            "y": -6,
            "z": -2,
            "elements": [
                "extendedcrafting:storage@0"
            ]
        },
        {
            "x": -3,
            "y": -8,
            "z": 1,
            "elements": [
                "jaopca:block.niobium_titanium@0"
            ]
        },
        {
            "x": 1,
            "y": -10,
            "z": 2,
            "elements": [
                "extendedcrafting:storage@0"
            ]
        },
        {
            "x": -3,
            "y": -7,
            "z": 1,
            "elements": [
                "jaopca:block.niobium_titanium@0"
            ]
        },
        {
            "x": -1,
            "y": -7,
            "z": -2,
            "elements": [
                "extendedcrafting:storage@0"
            ]
        },
        {
            "x": 2,
            "y": -9,
            "z": -2,
            "elements": [
                "jaopca:block.zirconium_molybdenum@0"
            ]
        },
        {
            "x": 1,
            "y": -11,
            "z": 2,
            "elements": [
                "extendedcrafting:storage@0"
            ]
        },
        {
            "x": 1,
            "y": -5,
            "z": 3,
            "elements": [
                "jaopca:block.niobium_titanium@0"
            ]
        },
        {
            "x": -1,
            "y": -5,
            "z": -2,
            "elements": [
                "extendedcrafting:storage@0"
            ]
        },
        {
            "x": 1,
            "y": -12,
            "z": -2,
            "elements": [
                "nuclearcraft:machine_frame@0"
            ]
        },
        {
            "x": -2,
            "y": -8,
            "z": 2,
            "elements": [
                "jaopca:block.zirconium_molybdenum@0"
            ]
        },
        {
            "x": -2,
            "y": -9,
            "z": 1,
            "elements": [
                "extendedcrafting:storage@0"
            ]
        },
        {
            "x": 1,
            "y": -4,
            "z": 3,
            "elements": [
                "jaopca:block.niobium_titanium@0"
            ]
        },
        {
            "x": -1,
            "y": -8,
            "z": -2,
            "elements": [
                "extendedcrafting:storage@0"
            ]
        },
        {
            "x": -2,
            "y": -5,
            "z": 2,
            "elements": [
                "jaopca:block.zirconium_molybdenum@0"
            ]
        },
        {
            "x": 2,
            "y": -11,
            "z": -2,
            "elements": [
                "jaopca:block.zirconium_molybdenum@0"
            ]
        },
        {
            "x": 2,
            "y": -10,
            "z": -2,
            "elements": [
                "jaopca:block.zirconium_molybdenum@0"
            ]
        },
        {
            "x": -3,
            "y": -5,
            "z": 1,
            "elements": [
                "jaopca:block.niobium_titanium@0"
            ]
        },
        {
            "x": 1,
            "y": -12,
            "z": 2,
            "elements": [
                "nuclearcraft:machine_frame@0"
            ]
        },
        {
            "x": -1,
            "y": -7,
            "z": 2,
            "elements": [
                "extendedcrafting:storage@0"
            ]
        },
        {
            "x": 1,
            "y": -9,
            "z": -2,
            "elements": [
                "extendedcrafting:storage@0"
            ]
        },
        {
            "x": 1,
            "y": -10,
            "z": -2,
            "elements": [
                "extendedcrafting:storage@0"
            ]
        },
        {
            "x": -2,
            "y": -12,
            "z": 1,
            "elements": [
                "nuclearcraft:machine_frame@0"
            ]
        },
        {
            "x": -2,
            "y": -6,
            "z": 2,
            "elements": [
                "jaopca:block.zirconium_molybdenum@0"
            ]
        },
        {
            "x": -2,
            "y": -11,
            "z": 1,
            "elements": [
                "extendedcrafting:storage@0"
            ]
        },
        {
            "x": -2,
            "y": -5,
            "z": -2,
            "elements": [
                "jaopca:block.zirconium_molybdenum@0"
            ]
        },
        {
            "x": -1,
            "y": -8,
            "z": 2,
            "elements": [
                "extendedcrafting:storage@0"
            ]
        },
        {
            "x": 2,
            "y": -12,
            "z": -2,
            "elements": [
                "jaopca:block.zirconium_molybdenum@0"
            ]
        },
        {
            "x": -6,
            "y": -1,
            "z": 1,
            "elements": [
                "avaritia:block_resource@0"
            ]
        },
        {
            "x": 5,
            "y": 0,
            "z": -1,
            "elements": [
                "jaopca:block.ruthenium@0"
            ]
        },
        {
            "x": -3,
            "y": -6,
            "z": 1,
            "elements": [
                "jaopca:block.niobium_titanium@0"
            ]
        },
        {
            "x": 1,
            "y": -11,
            "z": 3,
            "elements": [
                "jaopca:block.niobium_titanium@0"
            ]
        },
        {
            "x": -2,
            "y": -9,
            "z": 3,
            "elements": [
                "additions:manganese_steel_block@0"
            ]
        },
        {
            "x": -2,
            "y": -11,
            "z": -1,
            "elements": [
                "extendedcrafting:storage@0"
            ]
        },
        {
            "x": 2,
            "y": -4,
            "z": -2,
            "elements": [
                "jaopca:block.zirconium_molybdenum@0"
            ]
        },
        {
            "x": -5,
            "y": 0,
            "z": -4,
            "elements": [
                "casings_all"
            ]
        },
        {
            "x": -2,
            "y": -6,
            "z": 3,
            "elements": [
                "additions:manganese_steel_block@0"
            ]
        },
        {
            "x": -3,
            "y": -12,
            "z": 1,
            "elements": [
                "jaopca:block.niobium_titanium@0"
            ]
        },
        {
            "x": 0,
            "y": -5,
            "z": -3,
            "elements": [
                "jaopca:block.niobium_titanium@0"
            ]
        },
        {
            "x": 1,
            "y": -10,
            "z": 3,
            "elements": [
                "jaopca:block.niobium_titanium@0"
            ]
        },
        {
            "x": 1,
            "y": -1,
            "z": 6,
            "elements": [
                "avaritia:block_resource@0"
            ]
        },
        {
            "x": -2,
            "y": 0,
            "z": -6,
            "elements": [
                "avaritia:block_resource@0"
            ]
        },
        {
            "x": 5,
            "y": 0,
            "z": 4,
            "elements": [
                "casings_all"
            ]
        },
        {
            "x": -2,
            "y": -12,
            "z": -1,
            "elements": [
                "nuclearcraft:machine_frame@0"
            ]
        },
        {
            "x": 0,
            "y": -4,
            "z": -3,
            "elements": [
                "jaopca:block.niobium_titanium@0"
            ]
        },
        {
            "x": -3,
            "y": -11,
            "z": 1,
            "elements": [
                "jaopca:block.niobium_titanium@0"
            ]
        },
        {
            "x": -2,
            "y": -7,
            "z": 3,
            "elements": [
                "additions:manganese_steel_block@0"
            ]
        },
        {
            "x": -2,
            "y": -12,
            "z": 2,
            "elements": [
                "jaopca:block.zirconium_molybdenum@0"
            ]
        },
        {
            "x": -2,
            "y": -9,
            "z": -1,
            "elements": [
                "extendedcrafting:storage@0"
            ]
        },
        {
            "x": -2,
            "y": -10,
            "z": 2,
            "elements": [
                "jaopca:block.zirconium_molybdenum@0"
            ]
        },
        {
            "x": -3,
            "y": -10,
            "z": 1,
            "elements": [
                "jaopca:block.niobium_titanium@0"
            ]
        },
        {
            "x": -2,
            "y": -8,
            "z": 3,
            "elements": [
                "additions:manganese_steel_block@0"
            ]
        },
        {
            "x": -1,
            "y": -4,
            "z": -2,
            "elements": [
                "extendedcrafting:storage@0"
            ]
        },
        {
            "x": 0,
            "y": -7,
            "z": -3,
            "elements": [
                "jaopca:block.niobium_titanium@0"
            ]
        },
        {
            "x": 2,
            "y": -4,
            "z": 2,
            "elements": [
                "jaopca:block.zirconium_molybdenum@0"
            ]
        },
        {
            "x": -2,
            "y": -9,
            "z": 2,
            "elements": [
                "jaopca:block.zirconium_molybdenum@0"
            ]
        },
        {
            "x": -6,
            "y": 0,
            "z": -2,
            "elements": [
                "avaritia:block_resource@0"
            ]
        },
        {
            "x": 2,
            "y": 0,
            "z": 6,
            "elements": [
                "avaritia:block_resource@0"
            ]
        },
        {
            "x": 1,
            "y": -12,
            "z": 3,
            "elements": [
                "jaopca:block.niobium_titanium@0"
            ]
        },
        {
            "x": -2,
            "y": -10,
            "z": -1,
            "elements": [
                "extendedcrafting:storage@0"
            ]
        },
        {
            "x": -2,
            "y": -11,
            "z": 2,
            "elements": [
                "jaopca:block.zirconium_molybdenum@0"
            ]
        },
        {
            "x": -3,
            "y": -9,
            "z": 1,
            "elements": [
                "jaopca:block.niobium_titanium@0"
            ]
        },
        {
            "x": -1,
            "y": -3,
            "z": -2,
            "elements": [
                "jaopca:block.niobium_titanium@0"
            ]
        },
        {
            "x": 2,
            "y": -8,
            "z": -2,
            "elements": [
                "jaopca:block.zirconium_molybdenum@0"
            ]
        },
        {
            "x": 0,
            "y": -6,
            "z": -3,
            "elements": [
                "jaopca:block.niobium_titanium@0"
            ]
        },
        {
            "x": 0,
            "y": -9,
            "z": -3,
            "elements": [
                "jaopca:block.niobium_titanium@0"
            ]
        },
        {
            "x": 3,
            "y": -6,
            "z": -2,
            "elements": [
                "additions:manganese_steel_block@0"
            ]
        },
        {
            "x": 0,
            "y": -4,
            "z": -2,
            "elements": [
                "nuclearcraft:machine_frame@0"
            ]
        },
        {
            "x": -1,
            "y": -4,
            "z": 2,
            "elements": [
                "extendedcrafting:storage@0"
            ]
        },
        {
            "x": 2,
            "y": -6,
            "z": 2,
            "elements": [
                "jaopca:block.zirconium_molybdenum@0"
            ]
        },
        {
            "x": 0,
            "y": -8,
            "z": -3,
            "elements": [
                "jaopca:block.niobium_titanium@0"
            ]
        },
        {
            "x": 2,
            "y": -8,
            "z": 2,
            "elements": [
                "jaopca:block.zirconium_molybdenum@0"
            ]
        },
        {
            "x": -1,
            "y": -3,
            "z": 2,
            "elements": [
                "jaopca:block.niobium_titanium@0"
            ]
        },
        {
            "x": 2,
            "y": -7,
            "z": -2,
            "elements": [
                "jaopca:block.zirconium_molybdenum@0"
            ]
        },
        {
            "x": 3,
            "y": -8,
            "z": -2,
            "elements": [
                "additions:manganese_steel_block@0"
            ]
        },
        {
            "x": 2,
            "y": -5,
            "z": 2,
            "elements": [
                "jaopca:block.zirconium_molybdenum@0"
            ]
        },
        {
            "x": 0,
            "y": -3,
            "z": -2,
            "elements": [
                "jaopca:block.niobium_titanium@0"
            ]
        },
        {
            "x": -2,
            "y": -4,
            "z": -1,
            "elements": [
                "extendedcrafting:storage@0"
            ]
        },
        {
            "x": 2,
            "y": -6,
            "z": -2,
            "elements": [
                "jaopca:block.zirconium_molybdenum@0"
            ]
        },
        {
            "x": -5,
            "y": 0,
            "z": -3,
            "elements": [
                "casings_all"
            ]
        },
        {
            "x": 1,
            "y": -4,
            "z": -2,
            "elements": [
                "extendedcrafting:storage@0"
            ]
        },
        {
            "x": 0,
            "y": -4,
            "z": 2,
            "elements": [
                "nuclearcraft:machine_frame@0"
            ]
        },
        {
            "x": 4,
            "y": 0,
            "z": 1,
            "elements": [
                "jaopca:block.ruthenium@0"
            ]
        },
        {
            "x": -2,
            "y": -3,
            "z": -1,
            "elements": [
                "jaopca:block.niobium_titanium@0"
            ]
        },
        {
            "x": 0,
            "y": -10,
            "z": -3,
            "elements": [
                "jaopca:block.niobium_titanium@0"
            ]
        },
        {
            "x": 1,
            "y": -6,
            "z": 2,
            "elements": [
                "extendedcrafting:storage@0"
            ]
        },
        {
            "x": 2,
            "y": -5,
            "z": -2,
            "elements": [
                "jaopca:block.zirconium_molybdenum@0"
            ]
        },
        {
            "x": 3,
            "y": -8,
            "z": 2,
            "elements": [
                "additions:manganese_steel_block@0"
            ]
        },
        {
            "x": 5,
            "y": 0,
            "z": 3,
            "elements": [
                "casings_all"
            ]
        },
        {
            "x": -2,
            "y": -10,
            "z": 3,
            "elements": [
                "additions:manganese_steel_block@0"
            ]
        },
        {
            "x": 0,
            "y": -3,
            "z": 2,
            "elements": [
                "jaopca:block.niobium_titanium@0"
            ]
        },
        {
            "x": 0,
            "y": -12,
            "z": -3,
            "elements": [
                "jaopca:block.niobium_titanium@0"
            ]
        },
        {
            "x": 3,
            "y": -7,
            "z": -2,
            "elements": [
                "additions:manganese_steel_block@0"
            ]
        },
        {
            "x": 1,
            "y": -3,
            "z": -2,
            "elements": [
                "jaopca:block.niobium_titanium@0"
            ]
        },
        {
            "x": 0,
            "y": -11,
            "z": -3,
            "elements": [
                "jaopca:block.niobium_titanium@0"
            ]
        },
        {
            "x": 6,
            "y": -1,
            "z": 1,
            "elements": [
                "avaritia:block_resource@0"
            ]
        },
        {
            "x": 1,
            "y": -5,
            "z": 2,
            "elements": [
                "extendedcrafting:storage@0"
            ]
        },
        {
            "x": 2,
            "y": -7,
            "z": 2,
            "elements": [
                "jaopca:block.zirconium_molybdenum@0"
            ]
        },
        {
            "x": 2,
            "y": -12,
            "z": 2,
            "elements": [
                "jaopca:block.zirconium_molybdenum@0"
            ]
        },
        {
            "x": -2,
            "y": -6,
            "z": -1,
            "elements": [
                "extendedcrafting:storage@0"
            ]
        },
        {
            "x": -2,
            "y": -4,
            "z": -2,
            "elements": [
                "jaopca:block.zirconium_molybdenum@0"
            ]
        },
        {
            "x": 1,
            "y": -6,
            "z": -2,
            "elements": [
                "extendedcrafting:storage@0"
            ]
        },
        {
            "x": -5,
            "y": 0,
            "z": 1,
            "elements": [
                "jaopca:block.ruthenium@0"
            ]
        },
        {
            "x": 1,
            "y": -4,
            "z": 2,
            "elements": [
                "extendedcrafting:storage@0"
            ]
        },
        {
            "x": 1,
            "y": -7,
            "z": -2,
            "elements": [
                "extendedcrafting:storage@0"
            ]
        },
        {
            "x": -2,
            "y": -5,
            "z": -1,
            "elements": [
                "extendedcrafting:storage@0"
            ]
        },
        {
            "x": -2,
            "y": -8,
            "z": -3,
            "elements": [
                "additions:manganese_steel_block@0"
            ]
        },
        {
            "x": 1,
            "y": -5,
            "z": -2,
            "elements": [
                "extendedcrafting:storage@0"
            ]
        },
        {
            "x": 1,
            "y": -3,
            "z": 2,
            "elements": [
                "jaopca:block.niobium_titanium@0"
            ]
        },
        {
            "x": 1,
            "y": -8,
            "z": -2,
            "elements": [
                "extendedcrafting:storage@0"
            ]
        },
        {
            "x": -3,
            "y": -4,
            "z": 1,
            "elements": [
                "jaopca:block.niobium_titanium@0"
            ]
        },
        {
            "x": -4,
            "y": 0,
            "z": -1,
            "elements": [
                "jaopca:block.ruthenium@0"
            ]
        },
        {
            "x": -2,
            "y": -9,
            "z": -3,
            "elements": [
                "additions:manganese_steel_block@0"
            ]
        },
        {
            "x": 1,
            "y": -7,
            "z": 2,
            "elements": [
                "extendedcrafting:storage@0"
            ]
        },
        {
            "x": 2,
            "y": -9,
            "z": 2,
            "elements": [
                "jaopca:block.zirconium_molybdenum@0"
            ]
        },
        {
            "x": 3,
            "y": -4,
            "z": 1,
            "elements": [
                "jaopca:block.niobium_titanium@0"
            ]
        },
        {
            "x": 2,
            "y": -10,
            "z": 2,
            "elements": [
                "jaopca:block.zirconium_molybdenum@0"
            ]
        },
        {
            "x": -2,
            "y": -8,
            "z": -1,
            "elements": [
                "extendedcrafting:storage@0"
            ]
        },
        {
            "x": -2,
            "y": -10,
            "z": -3,
            "elements": [
                "additions:manganese_steel_block@0"
            ]
        },
        {
            "x": -2,
            "y": -4,
            "z": 2,
            "elements": [
                "jaopca:block.zirconium_molybdenum@0"
            ]
        },
        {
            "x": -1,
            "y": -6,
            "z": 2,
            "elements": [
                "extendedcrafting:storage@0"
            ]
        },
        {
            "x": 1,
            "y": -8,
            "z": 2,
            "elements": [
                "extendedcrafting:storage@0"
            ]
        },
        {
            "x": 2,
            "y": -11,
            "z": 2,
            "elements": [
                "jaopca:block.zirconium_molybdenum@0"
            ]
        },
        {
            "x": 1,
            "y": -12,
            "z": -1,
            "elements": [
                "jaopca:block.zirconium_molybdenum@0"
            ]
        },
        {
            "x": -1,
            "y": -5,
            "z": 2,
            "elements": [
                "extendedcrafting:storage@0"
            ]
        },
        {
            "x": -2,
            "y": -7,
            "z": -1,
            "elements": [
                "extendedcrafting:storage@0"
            ]
        },
        {
            "x": 3,
            "y": -12,
            "z": 1,
            "elements": [
                "jaopca:block.niobium_titanium@0"
            ]
        },
        {
            "x": 2,
            "y": -4,
            "z": 1,
            "elements": [
                "extendedcrafting:storage@0"
            ]
        },
        {
            "x": -1,
            "y": -3,
            "z": -1,
            "elements": [
                "moretcon:blockgravitonium@0"
            ]
        },
        {
            "x": 2,
            "y": -3,
            "z": 1,
            "elements": [
                "jaopca:block.niobium_titanium@0"
            ]
        },
        {
            "x": 0,
            "y": 1,
            "z": -6,
            "elements": [
                "avaritia:block_resource@0"
            ]
        },
        {
            "x": 3,
            "y": -11,
            "z": 1,
            "elements": [
                "jaopca:block.niobium_titanium@0"
            ]
        },
        {
            "x": -1,
            "y": -1,
            "z": 6,
            "elements": [
                "avaritia:block_resource@0"
            ]
        },
        {
            "x": 0,
            "y": 0,
            "z": -6,
            "elements": [
                "casings_upgrade"
            ]
        },
        {
            "x": 0,
            "y": -12,
            "z": 2,
            "elements": [
                "nuclearcraft:machine_frame@0"
            ]
        },
        {
            "x": -3,
            "y": -12,
            "z": 0,
            "elements": [
                "jaopca:block.niobium_titanium@0"
            ]
        },
        {
            "x": 3,
            "y": -11,
            "z": -1,
            "elements": [
                "jaopca:block.niobium_titanium@0"
            ]
        },
        {
            "x": 0,
            "y": -10,
            "z": 2,
            "elements": [
                "nuclearcraft:machine_frame@0"
            ]
        },
        {
            "x": 0,
            "y": -9,
            "z": 2,
            "elements": [
                "nuclearcraft:machine_frame@0"
            ]
        },
        {
            "x": -1,
            "y": -1,
            "z": -6,
            "elements": [
                "avaritia:block_resource@0"
            ]
        },
        {
            "x": -3,
            "y": -9,
            "z": 0,
            "elements": [
                "jaopca:block.niobium_titanium@0"
            ]
        },
        {
            "x": 0,
            "y": 0,
            "z": 6,
            "elements": [
                "casings_upgrade"
            ]
        },
        {
            "x": 3,
            "y": -9,
            "z": 1,
            "elements": [
                "jaopca:block.niobium_titanium@0"
            ]
        },
        {
            "x": 3,
            "y": -10,
            "z": -1,
            "elements": [
                "jaopca:block.niobium_titanium@0"
            ]
        },
        {
            "x": 2,
            "y": -3,
            "z": -1,
            "elements": [
                "jaopca:block.niobium_titanium@0"
            ]
        },
        {
            "x": 3,
            "y": -12,
            "z": -1,
            "elements": [
                "jaopca:block.niobium_titanium@0"
            ]
        },
        {
            "x": -3,
            "y": -11,
            "z": 0,
            "elements": [
                "jaopca:block.niobium_titanium@0"
            ]
        },
        {
            "x": 0,
            "y": -11,
            "z": 2,
            "elements": [
                "nuclearcraft:machine_frame@0"
            ]
        },
        {
            "x": 2,
            "y": -4,
            "z": -1,
            "elements": [
                "extendedcrafting:storage@0"
            ]
        },
        {
            "x": 3,
            "y": -9,
            "z": -1,
            "elements": [
                "jaopca:block.niobium_titanium@0"
            ]
        },
        {
            "x": 6,
            "y": 1,
            "z": 0,
            "elements": [
                "avaritia:block_resource@0"
            ]
        },
        {
            "x": 3,
            "y": -10,
            "z": 1,
            "elements": [
                "jaopca:block.niobium_titanium@0"
            ]
        },
        {
            "x": -6,
            "y": 0,
            "z": 0,
            "elements": [
                "casings_parallel"
            ]
        },
        {
            "x": 0,
            "y": 1,
            "z": 6,
            "elements": [
                "avaritia:block_resource@0"
            ]
        },
        {
            "x": -1,
            "y": -2,
            "z": -1,
            "elements": [
                "tiths:block_steamium@0"
            ]
        },
        {
            "x": -3,
            "y": -10,
            "z": 0,
            "elements": [
                "jaopca:block.niobium_titanium@0"
            ]
        },
        {
            "x": -4,
            "y": -5,
            "z": 0,
            "elements": [
                "jaopca:block.niobium_titanium@0"
            ]
        },
        {
            "x": 3,
            "y": -7,
            "z": 1,
            "elements": [
                "jaopca:block.niobium_titanium@0"
            ]
        },
        {
            "x": 0,
            "y": -7,
            "z": 2,
            "elements": [
                "nuclearcraft:machine_frame@0"
            ]
        },
        {
            "x": 2,
            "y": -5,
            "z": 1,
            "elements": [
                "extendedcrafting:storage@0"
            ]
        },
        {
            "x": -1,
            "y": -2,
            "z": 1,
            "elements": [
                "tiths:block_steamium@0"
            ]
        },
        {
            "x": 3,
            "y": -9,
            "z": 2,
            "elements": [
                "additions:manganese_steel_block@0"
            ]
        },
        {
            "x": 2,
            "y": -6,
            "z": -1,
            "elements": [
                "extendedcrafting:storage@0"
            ]
        },
        {
            "x": 1,
            "y": -3,
            "z": -1,
            "elements": [
                "moretcon:blockgravitonium@0"
            ]
        },
        {
            "x": 3,
            "y": -10,
            "z": 2,
            "elements": [
                "additions:manganese_steel_block@0"
            ]
        },
        {
            "x": 3,
            "y": -8,
            "z": -1,
            "elements": [
                "jaopca:block.niobium_titanium@0"
            ]
        },
        {
            "x": 0,
            "y": -6,
            "z": 2,
            "elements": [
                "nuclearcraft:machine_frame@0"
            ]
        },
        {
            "x": 3,
            "y": -7,
            "z": -1,
            "elements": [
                "jaopca:block.niobium_titanium@0"
            ]
        },
        {
            "x": -3,
            "y": -6,
            "z": 2,
            "elements": [
                "additions:manganese_steel_block@0"
            ]
        },
        {
            "x": 2,
            "y": -6,
            "z": 1,
            "elements": [
                "extendedcrafting:storage@0"
            ]
        },
        {
            "x": 2,
            "y": -5,
            "z": -1,
            "elements": [
                "extendedcrafting:storage@0"
            ]
        },
        {
            "x": 0,
            "y": -8,
            "z": 2,
            "elements": [
                "nuclearcraft:machine_frame@0"
            ]
        },
        {
            "x": 0,
            "y": -3,
            "z": 1,
            "elements": [
                "moretcon:blockgravitonium@0"
            ]
        },
        {
            "x": 3,
            "y": -8,
            "z": 1,
            "elements": [
                "jaopca:block.niobium_titanium@0"
            ]
        },
        {
            "x": 0,
            "y": -5,
            "z": 2,
            "elements": [
                "nuclearcraft:machine_frame@0"
            ]
        },
        {
            "x": 0,
            "y": -2,
            "z": -1,
            "elements": [
                "tiths:block_steamium@0"
            ]
        },
        {
            "x": 3,
            "y": -7,
            "z": 2,
            "elements": [
                "additions:manganese_steel_block@0"
            ]
        },
        {
            "x": -1,
            "y": -12,
            "z": 0,
            "elements": [
                "jaopca:block.zirconium_molybdenum@0"
            ]
        },
        {
            "x": 0,
            "y": -2,
            "z": 1,
            "elements": [
                "tiths:block_steamium@0"
            ]
        },
        {
            "x": -3,
            "y": -7,
            "z": 2,
            "elements": [
                "additions:manganese_steel_block@0"
            ]
        },
        {
            "x": 3,
            "y": -5,
            "z": 1,
            "elements": [
                "jaopca:block.niobium_titanium@0"
            ]
        },
        {
            "x": 3,
            "y": -6,
            "z": -1,
            "elements": [
                "jaopca:block.niobium_titanium@0"
            ]
        },
        {
            "x": 0,
            "y": -3,
            "z": -1,
            "elements": [
                "moretcon:blockgravitonium@0"
            ]
        },
        {
            "x": 2,
            "y": -8,
            "z": -1,
            "elements": [
                "extendedcrafting:storage@0"
            ]
        },
        {
            "x": 3,
            "y": -5,
            "z": -1,
            "elements": [
                "jaopca:block.niobium_titanium@0"
            ]
        },
        {
            "x": 3,
            "y": -6,
            "z": 2,
            "elements": [
                "additions:manganese_steel_block@0"
            ]
        },
        {
            "x": 2,
            "y": -7,
            "z": 1,
            "elements": [
                "extendedcrafting:storage@0"
            ]
        },
        {
            "x": 2,
            "y": -7,
            "z": -1,
            "elements": [
                "extendedcrafting:storage@0"
            ]
        },
        {
            "x": 3,
            "y": -6,
            "z": 1,
            "elements": [
                "jaopca:block.niobium_titanium@0"
            ]
        },
        {
            "x": -3,
            "y": -8,
            "z": 2,
            "elements": [
                "additions:manganese_steel_block@0"
            ]
        },
        {
            "x": -1,
            "y": -3,
            "z": 1,
            "elements": [
                "moretcon:blockgravitonium@0"
            ]
        },
        {
            "x": 2,
            "y": -8,
            "z": 1,
            "elements": [
                "extendedcrafting:storage@0"
            ]
        },
        {
            "x": 1,
            "y": -2,
            "z": -1,
            "elements": [
                "tiths:block_steamium@0"
            ]
        },
        {
            "x": -2,
            "y": -9,
            "z": -2,
            "elements": [
                "jaopca:block.zirconium_molybdenum@0"
            ]
        },
        {
            "x": 1,
            "y": -2,
            "z": 1,
            "elements": [
                "tiths:block_steamium@0"
            ]
        },
        {
            "x": -3,
            "y": -10,
            "z": 2,
            "elements": [
                "additions:manganese_steel_block@0"
            ]
        },
        {
            "x": 5,
            "y": -4,
            "z": 0,
            "elements": [
                "jaopca:block.niobium_titanium@0"
            ]
        },
        {
            "x": 6,
            "y": -1,
            "z": -1,
            "elements": [
                "avaritia:block_resource@0"
            ]
        },
        {
            "x": 1,
            "y": 0,
            "z": 5,
            "elements": [
                "mekanism:basicblock@0"
            ]
        },
        {
            "x": 0,
            "y": -1,
            "z": -6,
            "elements": [
                "avaritia:block_resource@0"
            ]
        },
        {
            "x": -1,
            "y": 0,
            "z": 6,
            "elements": [
                "avaritia:block_resource@0"
            ]
        },
        {
            "x": -3,
            "y": -9,
            "z": 2,
            "elements": [
                "additions:manganese_steel_block@0"
            ]
        },
        {
            "x": 2,
            "y": -10,
            "z": -1,
            "elements": [
                "extendedcrafting:storage@0"
            ]
        },
        {
            "x": 5,
            "y": -3,
            "z": 0,
            "elements": [
                "jaopca:block.niobium_titanium@0"
            ]
        },
        {
            "x": -2,
            "y": -10,
            "z": -2,
            "elements": [
                "jaopca:block.zirconium_molybdenum@0"
            ]
        },
        {
            "x": -4,
            "y": -1,
            "z": 0,
            "elements": [
                "jaopca:block.ruthenium@0"
            ]
        },
        {
            "x": 3,
            "y": -4,
            "z": -1,
            "elements": [
                "jaopca:block.niobium_titanium@0"
            ]
        },
        {
            "x": 6,
            "y": 0,
            "z": 2,
            "elements": [
                "avaritia:block_resource@0"
            ]
        },
        {
            "x": -1,
            "y": 1,
            "z": 6,
            "elements": [
                "avaritia:block_resource@0"
            ]
        },
        {
            "x": -3,
            "y": 0,
            "z": 0,
            "elements": [
                "jaopca:block.ruthenium@0"
            ]
        },
        {
            "x": 2,
            "y": -9,
            "z": -1,
            "elements": [
                "extendedcrafting:storage@0"
            ]
        },
        {
            "x": -4,
            "y": 0,
            "z": 1,
            "elements": [
                "jaopca:block.ruthenium@0"
            ]
        },
        {
            "x": 1,
            "y": 0,
            "z": -6,
            "elements": [
                "avaritia:block_resource@0"
            ]
        },
        {
            "x": -2,
            "y": -11,
            "z": -2,
            "elements": [
                "jaopca:block.zirconium_molybdenum@0"
            ]
        },
        {
            "x": 0,
            "y": -2,
            "z": 5,
            "elements": [
                "jaopca:block.niobium_titanium@0"
            ]
        },
        {
            "x": -2,
            "y": -3,
            "z": 1,
            "elements": [
                "jaopca:block.niobium_titanium@0"
            ]
        },
        {
            "x": -2,
            "y": -12,
            "z": -2,
            "elements": [
                "jaopca:block.zirconium_molybdenum@0"
            ]
        },
        {
            "x": -1,
            "y": -12,
            "z": -1,
            "elements": [
                "jaopca:block.zirconium_molybdenum@0"
            ]
        },
        {
            "x": 1,
            "y": -3,
            "z": 1,
            "elements": [
                "moretcon:blockgravitonium@0"
            ]
        },
        {
            "x": 1,
            "y": 1,
            "z": -6,
            "elements": [
                "avaritia:block_resource@0"
            ]
        },
        {
            "x": 0,
            "y": -1,
            "z": 5,
            "elements": [
                "mekanism:basicblock@0"
            ]
        },
        {
            "x": -1,
            "y": 0,
            "z": -5,
            "elements": [
                "thermalfoundation:storage@7"
            ]
        },
        {
            "x": -2,
            "y": -4,
            "z": 1,
            "elements": [
                "extendedcrafting:storage@0"
            ]
        },
        {
            "x": -3,
            "y": -4,
            "z": -1,
            "elements": [
                "jaopca:block.niobium_titanium@0"
            ]
        },
        {
            "x": -2,
            "y": -5,
            "z": 1,
            "elements": [
                "extendedcrafting:storage@0"
            ]
        },
        {
            "x": 1,
            "y": -12,
            "z": 1,
            "elements": [
                "jaopca:block.zirconium_molybdenum@0"
            ]
        },
        {
            "x": 2,
            "y": -11,
            "z": -1,
            "elements": [
                "extendedcrafting:storage@0"
            ]
        },
        {
            "x": 2,
            "y": 0,
            "z": -6,
            "elements": [
                "avaritia:block_resource@0"
            ]
        },
        {
            "x": 6,
            "y": 0,
            "z": 0,
            "elements": [
                "casings_parallel"
            ]
        },
        {
            "x": -1,
            "y": -11,
            "z": -2,
            "elements": [
                "extendedcrafting:storage@0"
            ]
        },
        {
            "x": 5,
            "y": -1,
            "z": 0,
            "elements": [
                "jaopca:block.ruthenium@0"
            ]
        },
        {
            "x": -1,
            "y": -12,
            "z": -2,
            "elements": [
                "nuclearcraft:machine_frame@0"
            ]
        },
        {
            "x": -6,
            "y": 1,
            "z": 0,
            "elements": [
                "avaritia:block_resource@0"
            ]
        },
        {
            "x": -4,
            "y": 0,
            "z": -5,
            "elements": [
                "casings_all"
            ]
        },
        {
            "x": 4,
            "y": 0,
            "z": -1,
            "elements": [
                "jaopca:block.ruthenium@0"
            ]
        },
        {
            "x": 2,
            "y": -12,
            "z": -1,
            "elements": [
                "nuclearcraft:machine_frame@0"
            ]
        },
        {
            "x": -1,
            "y": -3,
            "z": 0,
            "elements": [
                "moretcon:blockgravitonium@0"
            ]
        },
        {
            "x": -2,
            "y": -6,
            "z": -2,
            "elements": [
                "jaopca:block.zirconium_molybdenum@0"
            ]
        },
        {
            "x": -2,
            "y": -6,
            "z": 1,
            "elements": [
                "extendedcrafting:storage@0"
            ]
        },
        {
            "x": 5,
            "y": -2,
            "z": 0,
            "elements": [
                "jaopca:block.niobium_titanium@0"
            ]
        },
        {
            "x": 3,
            "y": 0,
            "z": 0,
            "elements": [
                "jaopca:block.ruthenium@0"
            ]
        },
        {
            "x": -1,
            "y": -2,
            "z": 0,
            "elements": [
                "tiths:block_steamium@0"
            ]
        },
        {
            "x": -2,
            "y": 0,
            "z": 6,
            "elements": [
                "avaritia:block_resource@0"
            ]
        },
        {
            "x": -2,
            "y": -7,
            "z": -2,
            "elements": [
                "jaopca:block.zirconium_molybdenum@0"
            ]
        },
        {
            "x": 2,
            "y": -4,
            "z": 0,
            "elements": [
                "nuclearcraft:machine_frame@0"
            ]
        },
        {
            "x": 1,
            "y": -1,
            "z": -6,
            "elements": [
                "avaritia:block_resource@0"
            ]
        },
        {
            "x": -2,
            "y": -7,
            "z": 1,
            "elements": [
                "extendedcrafting:storage@0"
            ]
        },
        {
            "x": 4,
            "y": 0,
            "z": 5,
            "elements": [
                "casings_all"
            ]
        },
        {
            "x": 0,
            "y": -12,
            "z": 1,
            "elements": [
                "jaopca:block.zirconium_molybdenum@0"
            ]
        },
        {
            "x": -1,
            "y": -9,
            "z": -2,
            "elements": [
                "extendedcrafting:storage@0"
            ]
        },
        {
            "x": -1,
            "y": -10,
            "z": -2,
            "elements": [
                "extendedcrafting:storage@0"
            ]
        },
        {
            "x": 2,
            "y": -3,
            "z": 0,
            "elements": [
                "jaopca:block.niobium_titanium@0"
            ]
        },
        {
            "x": -2,
            "y": -8,
            "z": 1,
            "elements": [
                "extendedcrafting:storage@0"
            ]
        },
        {
            "x": -5,
            "y": 0,
            "z": -1,
            "elements": [
                "jaopca:block.ruthenium@0"
            ]
        },
        {
            "x": -2,
            "y": -8,
            "z": -2,
            "elements": [
                "jaopca:block.zirconium_molybdenum@0"
            ]
        }
    ]}