{
    "registryname": "elysia_solidifier",
    "localizedname": "§cELYSIA单元 - 大型凝结单元",
    "requires-blueprint": false,
    "failure-action": "still",
    "color": "a1c3dd",
    "modifiers": [
        {
            "elements": "modularmachinery:blockcasing@1",
            "x": 0,
            "y": 1,
            "z": 0,
            "description": "将控制器上方紧挨着的方块换成此方块以降低配方制作时间至75%！",
            "modifier": {
                "io": "input",
                "target": "modularmachinery:duration",
                "operation": 1,
                "multiplier": 0.75
            }
        },
        {
            "elements": "modularmachinery:blockcasing@2",
            "x": 0,
            "y": 1,
            "z": 0,
            "description": "将控制器上方紧挨着的方块换成此方块以降低配方制作时间至66%！",
            "modifier": {
                "io": "input",
                "target": "modularmachinery:duration",
                "operation": 1,
                "multiplier": 0.66
            }
        },
        {
            "elements": "modularmachinery:blockcasing@3",
            "x": 0,
            "y": 1,
            "z": 0,
            "description": "将控制器上方紧挨着的方块换成此方块以降低配方制作时间至50%！",
            "modifier": {
                "io": "input",
                "target": "modularmachinery:duration",
                "operation": 1,
                "multiplier": 0.5
            }
        },
        {
            "elements": "modularmachinery:blockcasing@5",
            "x": 0,
            "y": 1,
            "z": 0,
            "description": "将控制器上方紧挨着的方块换成此方块以降低配方制作时间至33%！",
            "modifier": {
                "io": "input",
                "target": "modularmachinery:duration",
                "operation": 1,
                "multiplier": 0.33
            }
        }
    ],
    "parts": [
        {
            "x": 0,
            "y": 0,
            "z": 0,
            "elements": [
                "modularmachinery:blockcontroller@2"
            ]
        },
        {
            "x": -3,
            "y": -2,
            "z": 5,
            "elements": [
                "quark:biome_brick@1"
            ]
        },
        {
            "x": -4,
            "y": 3,
            "z": 5,
            "elements": [
                "theaurorian:auroriansteelblock@0"
            ]
        },
        {
            "x": -3,
            "y": -5,
            "z": 6,
            "elements": [
                "theaurorian:auroriansteelblock@0"
            ]
        },
        {
            "x": 0,
            "y": -2,
            "z": 0,
            "elements": [
                "quark:biome_brick@1"
            ]
        },
        {
            "x": -4,
            "y": -7,
            "z": 4,
            "elements": [
                "chisel:technical1@1"
            ]
        },
        {
            "x": -7,
            "y": -5,
            "z": 4,
            "elements": [
                "thermalfoundation:glass@8"
            ]
        },
        {
            "x": 1,
            "y": -7,
            "z": 5,
            "elements": [
                "theaurorian:auroriansteelblock@0"
            ]
        },
        {
            "x": -7,
            "y": -4,
            "z": 4,
            "elements": [
                "casings_all"
            ]
        },
        {
            "x": -6,
            "y": -6,
            "z": 6,
            "elements": [
                "chisel:technical1@1"
            ]
        },
        {
            "x": 0,
            "y": -5,
            "z": 5,
            "elements": [
                "theaurorian:auroriansteelblock@0"
            ]
        },
        {
            "x": -4,
            "y": 4,
            "z": 5,
            "elements": [
                "thermalfoundation:glass@8"
            ]
        },
        {
            "x": -3,
            "y": 2,
            "z": 5,
            "elements": [
                "quark:biome_brick@1"
            ]
        },
        {
            "x": 0,
            "y": -1,
            "z": 0,
            "elements": [
                "quark:biome_brick@1"
            ]
        },
        {
            "x": -1,
            "y": 1,
            "z": 0,
            "elements": [
                "casings_upgrade"
            ]
        },
        {
            "x": -2,
            "y": -3,
            "z": 5,
            "elements": [
                "quark:biome_brick@1"
            ]
        },
        {
            "x": -3,
            "y": -6,
            "z": 6,
            "elements": [
                "theaurorian:auroriansteelblock@0"
            ]
        },
        {
            "x": -4,
            "y": -6,
            "z": 4,
            "elements": [
                "nuclearcraft:fluid_nak@0"
            ]
        },
        {
            "x": 0,
            "y": -6,
            "z": 5,
            "elements": [
                "thermalfoundation:glass@8"
            ]
        },
        {
            "x": -1,
            "y": -4,
            "z": 5,
            "elements": [
                "quark:biome_brick@1"
            ]
        },
        {
            "x": 0,
            "y": -4,
            "z": 6,
            "elements": [
                "quark:biome_brick@1"
            ]
        },
        {
            "x": -5,
            "y": 5,
            "z": 5,
            "elements": [
                "jaopca:block.skythern@0"
            ]
        },
        {
            "x": 1,
            "y": 0,
            "z": 0,
            "elements": [
                "quark:biome_brick@1"
            ]
        },
        {
            "x": -5,
            "y": 3,
            "z": 5,
            "elements": [
                "thermalfoundation:glass@8"
            ]
        },
        {
            "x": 6,
            "y": 4,
            "z": 3,
            "elements": [
                "jaopca:block.skythern@0"
            ]
        },
        {
            "x": 2,
            "y": -7,
            "z": 5,
            "elements": [
                "jaopca:block.skythern@0"
            ]
        },
        {
            "x": 6,
            "y": 4,
            "z": 4,
            "elements": [
                "randomthings:superlubricentice@0"
            ]
        },
        {
            "x": -4,
            "y": 6,
            "z": 5,
            "elements": [
                "jaopca:block.skythern@0"
            ]
        },
        {
            "x": -5,
            "y": 4,
            "z": 5,
            "elements": [
                "thermalfoundation:glass@8"
            ]
        },
        {
            "x": -1,
            "y": -5,
            "z": 5,
            "elements": [
                "theaurorian:auroriansteelblock@0"
            ]
        },
        {
            "x": -3,
            "y": -3,
            "z": 6,
            "elements": [
                "theaurorian:auroriansteelblock@0"
            ]
        },
        {
            "x": -7,
            "y": -2,
            "z": 4,
            "elements": [
                "randomthings:superlubricentice@0"
            ]
        },
        {
            "x": 1,
            "y": -1,
            "z": 0,
            "elements": [
                "casings_parallel"
            ]
        },
        {
            "x": 0,
            "y": 7,
            "z": 4,
            "elements": [
                "randomthings:superlubricentice@0"
            ]
        },
        {
            "x": -3,
            "y": -4,
            "z": 6,
            "elements": [
                "theaurorian:auroriansteelblock@0"
            ]
        },
        {
            "x": 0,
            "y": 7,
            "z": 3,
            "elements": [
                "theaurorian:auroriansteelblock@0"
            ]
        },
        {
            "x": -4,
            "y": -1,
            "z": 5,
            "elements": [
                "quark:biome_brick@1"
            ]
        },
        {
            "x": -4,
            "y": 5,
            "z": 5,
            "elements": [
                "thermalfoundation:glass@8"
            ]
        },
        {
            "x": -1,
            "y": -6,
            "z": 5,
            "elements": [
                "thermalfoundation:glass@8"
            ]
        },
        {
            "x": -7,
            "y": -3,
            "z": 4,
            "elements": [
                "theaurorian:auroriansteelblock@0"
            ]
        },
        {
            "x": 6,
            "y": 3,
            "z": 3,
            "elements": [
                "jaopca:block.skythern@0"
            ]
        },
        {
            "x": 6,
            "y": 3,
            "z": 4,
            "elements": [
                "randomthings:superlubricentice@0"
            ]
        },
        {
            "x": -6,
            "y": -3,
            "z": 6,
            "elements": [
                "theaurorian:auroriansteelblock@0"
            ]
        },
        {
            "x": -6,
            "y": 3,
            "z": 5,
            "elements": [
                "jaopca:block.skythern@0"
            ]
        },
        {
            "x": 2,
            "y": 0,
            "z": 0,
            "elements": [
                "quark:biome_brick@1"
            ]
        },
        {
            "x": 6,
            "y": 1,
            "z": 4,
            "elements": [
                "nuclearcraft:fluid_nak@0"
            ]
        },
        {
            "x": -3,
            "y": 6,
            "z": 5,
            "elements": [
                "jaopca:block.skythern@0"
            ]
        },
        {
            "x": 0,
            "y": -4,
            "z": 5,
            "elements": [
                "quark:biome_brick@1"
            ]
        },
        {
            "x": 0,
            "y": 6,
            "z": 3,
            "elements": [
                "thermalfoundation:glass@8"
            ]
        },
        {
            "x": -5,
            "y": 0,
            "z": 5,
            "elements": [
                "theaurorian:auroriansteelblock@0"
            ]
        },
        {
            "x": 3,
            "y": 3,
            "z": 4,
            "elements": [
                "quark:biome_brick@1"
            ]
        },
        {
            "x": -6,
            "y": -7,
            "z": 4,
            "elements": [
                "chisel:technical1@1"
            ]
        },
        {
            "x": 3,
            "y": 4,
            "z": 4,
            "elements": [
                "randomthings:superlubricentice@0"
            ]
        },
        {
            "x": -6,
            "y": 4,
            "z": 5,
            "elements": [
                "jaopca:block.skythern@0"
            ]
        },
        {
            "x": 2,
            "y": -5,
            "z": 5,
            "elements": [
                "thermalfoundation:glass@8"
            ]
        },
        {
            "x": -6,
            "y": -4,
            "z": 6,
            "elements": [
                "chisel:technical1@1"
            ]
        },
        {
            "x": 1,
            "y": 1,
            "z": 0,
            "elements": [
                "casings_upgrade"
            ]
        },
        {
            "x": -5,
            "y": 2,
            "z": 5,
            "elements": [
                "thermalfoundation:glass@8"
            ]
        },
        {
            "x": -6,
            "y": -6,
            "z": 4,
            "elements": [
                "nuclearcraft:fluid_nak@0"
            ]
        },
        {
            "x": 6,
            "y": 2,
            "z": 4,
            "elements": [
                "nuclearcraft:fluid_nak@0"
            ]
        },
        {
            "x": -3,
            "y": 5,
            "z": 5,
            "elements": [
                "thermalfoundation:glass@8"
            ]
        },
        {
            "x": 0,
            "y": 5,
            "z": 3,
            "elements": [
                "theaurorian:auroriansteelblock@0"
            ]
        },
        {
            "x": -5,
            "y": 1,
            "z": 5,
            "elements": [
                "theaurorian:auroriansteelblock@0"
            ]
        },
        {
            "x": -3,
            "y": -7,
            "z": 6,
            "elements": [
                "theaurorian:auroriansteelblock@0"
            ]
        },
        {
            "x": 2,
            "y": -6,
            "z": 5,
            "elements": [
                "thermalfoundation:glass@8"
            ]
        },
        {
            "x": -3,
            "y": -4,
            "z": 5,
            "elements": [
                "randomthings:superlubricentice@0"
            ]
        },
        {
            "x": -1,
            "y": 0,
            "z": 0,
            "elements": [
                "quark:biome_brick@1"
            ]
        },
        {
            "x": -6,
            "y": -2,
            "z": 5,
            "elements": [
                "thermalfoundation:glass@8"
            ]
        },
        {
            "x": -6,
            "y": -5,
            "z": 6,
            "elements": [
                "chisel:technical1@1"
            ]
        },
        {
            "x": -7,
            "y": -7,
            "z": 4,
            "elements": [
                "theaurorian:auroriansteelblock@0"
            ]
        },
        {
            "x": 0,
            "y": -7,
            "z": 5,
            "elements": [
                "theaurorian:auroriansteelblock@0"
            ]
        },
        {
            "x": 0,
            "y": 4,
            "z": 3,
            "elements": [
                "quark:biome_brick@1"
            ]
        },
        {
            "x": -3,
            "y": -5,
            "z": 5,
            "elements": [
                "nuclearcraft:fluid_nak@0"
            ]
        },
        {
            "x": -3,
            "y": -6,
            "z": 3,
            "elements": [
                "nuclearcraft:fluid_nak@0"
            ]
        },
        {
            "x": 3,
            "y": 6,
            "z": 4,
            "elements": [
                "randomthings:superlubricentice@0"
            ]
        },
        {
            "x": 5,
            "y": -1,
            "z": 4,
            "elements": [
                "randomthings:superlubricentice@0"
            ]
        },
        {
            "x": -3,
            "y": 4,
            "z": 5,
            "elements": [
                "theaurorian:auroriansteelblock@0"
            ]
        },
        {
            "x": -6,
            "y": -1,
            "z": 5,
            "elements": [
                "thermalfoundation:glass@8"
            ]
        },
        {
            "x": -7,
            "y": -6,
            "z": 4,
            "elements": [
                "casings_all"
            ]
        },
        {
            "x": 2,
            "y": 7,
            "z": 4,
            "elements": [
                "randomthings:superlubricentice@0"
            ]
        },
        {
            "x": -3,
            "y": -3,
            "z": 5,
            "elements": [
                "quark:biome_brick@1"
            ]
        },
        {
            "x": -3,
            "y": -6,
            "z": 5,
            "elements": [
                "nuclearcraft:fluid_nak@0"
            ]
        },
        {
            "x": -3,
            "y": -7,
            "z": 3,
            "elements": [
                "theaurorian:auroriansteelblock@0"
            ]
        },
        {
            "x": 3,
            "y": 5,
            "z": 4,
            "elements": [
                "nuclearcraft:fluid_nak@0"
            ]
        },
        {
            "x": -3,
            "y": 3,
            "z": 5,
            "elements": [
                "quark:biome_brick@1"
            ]
        },
        {
            "x": 6,
            "y": 0,
            "z": 4,
            "elements": [
                "nuclearcraft:fluid_nak@0"
            ]
        },
        {
            "x": -7,
            "y": 0,
            "z": 5,
            "elements": [
                "theaurorian:auroriansteelblock@0"
            ]
        },
        {
            "x": -6,
            "y": -2,
            "z": 3,
            "elements": [
                "thermalfoundation:glass@8"
            ]
        },
        {
            "x": -3,
            "y": -7,
            "z": 5,
            "elements": [
                "theaurorian:auroriansteelblock@0"
            ]
        },
        {
            "x": 5,
            "y": -4,
            "z": 4,
            "elements": [
                "nuclearcraft:fluid_nak@0"
            ]
        },
        {
            "x": -1,
            "y": 6,
            "z": 5,
            "elements": [
                "thermalfoundation:glass@8"
            ]
        },
        {
            "x": 0,
            "y": 4,
            "z": 5,
            "elements": [
                "quark:biome_brick@1"
            ]
        },
        {
            "x": 3,
            "y": -2,
            "z": 6,
            "elements": [
                "quark:biome_brick@1"
            ]
        },
        {
            "x": 5,
            "y": -5,
            "z": 3,
            "elements": [
                "jaopca:block.skythern@0"
            ]
        },
        {
            "x": -3,
            "y": 3,
            "z": 4,
            "elements": [
                "quark:biome_brick@1"
            ]
        },
        {
            "x": -5,
            "y": -3,
            "z": 5,
            "elements": [
                "nuclearcraft:fluid_nak@0"
            ]
        },
        {
            "x": 5,
            "y": -5,
            "z": 4,
            "elements": [
                "randomthings:superlubricentice@0"
            ]
        },
        {
            "x": -3,
            "y": 4,
            "z": 4,
            "elements": [
                "randomthings:superlubricentice@0"
            ]
        },
        {
            "x": -7,
            "y": 2,
            "z": 5,
            "elements": [
                "jaopca:block.skythern@0"
            ]
        },
        {
            "x": -7,
            "y": 1,
            "z": 5,
            "elements": [
                "theaurorian:auroriansteelblock@0"
            ]
        },
        {
            "x": -6,
            "y": -3,
            "z": 3,
            "elements": [
                "nuclearcraft:fluid_nak@0"
            ]
        },
        {
            "x": -5,
            "y": -4,
            "z": 5,
            "elements": [
                "nuclearcraft:fluid_nak@0"
            ]
        },
        {
            "x": 5,
            "y": -2,
            "z": 4,
            "elements": [
                "nuclearcraft:fluid_nak@0"
            ]
        },
        {
            "x": -1,
            "y": 5,
            "z": 5,
            "elements": [
                "theaurorian:auroriansteelblock@0"
            ]
        },
        {
            "x": 3,
            "y": -1,
            "z": 6,
            "elements": [
                "quark:biome_brick@1"
            ]
        },
        {
            "x": 4,
            "y": -6,
            "z": 5,
            "elements": [
                "jaopca:block.skythern@0"
            ]
        },
        {
            "x": 5,
            "y": -4,
            "z": 3,
            "elements": [
                "thermalfoundation:glass@8"
            ]
        },
        {
            "x": 2,
            "y": -4,
            "z": 4,
            "elements": [
                "quark:biome_brick@1"
            ]
        },
        {
            "x": -6,
            "y": -4,
            "z": 3,
            "elements": [
                "nuclearcraft:fluid_nak@0"
            ]
        },
        {
            "x": -2,
            "y": -7,
            "z": 5,
            "elements": [
                "theaurorian:auroriansteelblock@0"
            ]
        },
        {
            "x": 0,
            "y": 6,
            "z": 5,
            "elements": [
                "thermalfoundation:glass@8"
            ]
        },
        {
            "x": -3,
            "y": 5,
            "z": 4,
            "elements": [
                "nuclearcraft:fluid_nak@0"
            ]
        },
        {
            "x": -5,
            "y": -5,
            "z": 5,
            "elements": [
                "minecraft:piston@3"
            ]
        },
        {
            "x": -1,
            "y": 4,
            "z": 5,
            "elements": [
                "quark:biome_brick@1"
            ]
        },
        {
            "x": -3,
            "y": 6,
            "z": 4,
            "elements": [
                "randomthings:superlubricentice@0"
            ]
        },
        {
            "x": 4,
            "y": 0,
            "z": 6,
            "elements": [
                "quark:biome_brick@1"
            ]
        },
        {
            "x": 5,
            "y": -3,
            "z": 3,
            "elements": [
                "thermalfoundation:glass@8"
            ]
        },
        {
            "x": 3,
            "y": 2,
            "z": 3,
            "elements": [
                "quark:biome_brick@1"
            ]
        },
        {
            "x": -6,
            "y": 3,
            "z": 4,
            "elements": [
                "randomthings:superlubricentice@0"
            ]
        },
        {
            "x": 1,
            "y": 3,
            "z": 6,
            "elements": [
                "quark:biome_brick@1"
            ]
        },
        {
            "x": 5,
            "y": -2,
            "z": 3,
            "elements": [
                "thermalfoundation:glass@8"
            ]
        },
        {
            "x": 0,
            "y": 5,
            "z": 5,
            "elements": [
                "theaurorian:auroriansteelblock@0"
            ]
        },
        {
            "x": -4,
            "y": -1,
            "z": 4,
            "elements": [
                "quark:biome_brick@1"
            ]
        },
        {
            "x": -5,
            "y": -6,
            "z": 5,
            "elements": [
                "nuclearcraft:fluid_nak@0"
            ]
        },
        {
            "x": 5,
            "y": -3,
            "z": 4,
            "elements": [
                "nuclearcraft:fluid_nak@0"
            ]
        },
        {
            "x": -6,
            "y": -5,
            "z": 3,
            "elements": [
                "nuclearcraft:fluid_nak@0"
            ]
        },
        {
            "x": -6,
            "y": 4,
            "z": 4,
            "elements": [
                "randomthings:superlubricentice@0"
            ]
        },
        {
            "x": -2,
            "y": 0,
            "z": 0,
            "elements": [
                "quark:biome_brick@1"
            ]
        },
        {
            "x": 2,
            "y": -5,
            "z": 4,
            "elements": [
                "nuclearcraft:fluid_nak@0"
            ]
        },
        {
            "x": 5,
            "y": -1,
            "z": 3,
            "elements": [
                "theaurorian:auroriansteelblock@0"
            ]
        },
        {
            "x": -4,
            "y": -2,
            "z": 4,
            "elements": [
                "quark:biome_brick@1"
            ]
        },
        {
            "x": -5,
            "y": -2,
            "z": 5,
            "elements": [
                "theaurorian:auroriansteelblock@0"
            ]
        },
        {
            "x": -6,
            "y": 0,
            "z": 4,
            "elements": [
                "nuclearcraft:fluid_nak@0"
            ]
        },
        {
            "x": 4,
            "y": -4,
            "z": 5,
            "elements": [
                "thermalfoundation:glass@8"
            ]
        },
        {
            "x": -6,
            "y": -6,
            "z": 3,
            "elements": [
                "nuclearcraft:fluid_nak@0"
            ]
        },
        {
            "x": 6,
            "y": 2,
            "z": 3,
            "elements": [
                "thermalfoundation:glass@8"
            ]
        },
        {
            "x": 0,
            "y": 6,
            "z": 4,
            "elements": [
                "nuclearcraft:fluid_nak@0"
            ]
        },
        {
            "x": 3,
            "y": 4,
            "z": 3,
            "elements": [
                "theaurorian:auroriansteelblock@0"
            ]
        },
        {
            "x": -2,
            "y": -5,
            "z": 5,
            "elements": [
                "theaurorian:auroriansteelblock@0"
            ]
        },
        {
            "x": -5,
            "y": -1,
            "z": 5,
            "elements": [
                "theaurorian:auroriansteelblock@0"
            ]
        },
        {
            "x": -7,
            "y": -1,
            "z": 4,
            "elements": [
                "randomthings:superlubricentice@0"
            ]
        },
        {
            "x": 0,
            "y": 7,
            "z": 5,
            "elements": [
                "theaurorian:auroriansteelblock@0"
            ]
        },
        {
            "x": 6,
            "y": 0,
            "z": 3,
            "elements": [
                "thermalfoundation:glass@8"
            ]
        },
        {
            "x": 4,
            "y": -3,
            "z": 5,
            "elements": [
                "theaurorian:auroriansteelblock@0"
            ]
        },
        {
            "x": 3,
            "y": 0,
            "z": 7,
            "elements": [
                "quark:biome_brick@1"
            ]
        },
        {
            "x": -2,
            "y": -6,
            "z": 5,
            "elements": [
                "thermalfoundation:glass@8"
            ]
        },
        {
            "x": -6,
            "y": -7,
            "z": 3,
            "elements": [
                "chisel:technical1@1"
            ]
        },
        {
            "x": 3,
            "y": 3,
            "z": 3,
            "elements": [
                "quark:biome_brick@1"
            ]
        },
        {
            "x": -6,
            "y": 2,
            "z": 4,
            "elements": [
                "nuclearcraft:fluid_nak@0"
            ]
        },
        {
            "x": 0,
            "y": 5,
            "z": 4,
            "elements": [
                "additions:freezite_block@0"
            ]
        },
        {
            "x": 6,
            "y": 1,
            "z": 3,
            "elements": [
                "thermalfoundation:glass@8"
            ]
        },
        {
            "x": -4,
            "y": -3,
            "z": 4,
            "elements": [
                "randomthings:superlubricentice@0"
            ]
        },
        {
            "x": 2,
            "y": -1,
            "z": 7,
            "elements": [
                "quark:biome_brick@1"
            ]
        },
        {
            "x": 3,
            "y": 2,
            "z": 6,
            "elements": [
                "quark:biome_brick@1"
            ]
        },
        {
            "x": 1,
            "y": -4,
            "z": 5,
            "elements": [
                "quark:biome_brick@1"
            ]
        },
        {
            "x": 3,
            "y": 6,
            "z": 3,
            "elements": [
                "jaopca:block.skythern@0"
            ]
        },
        {
            "x": -4,
            "y": 0,
            "z": 5,
            "elements": [
                "quark:biome_brick@1"
            ]
        },
        {
            "x": -4,
            "y": -4,
            "z": 4,
            "elements": [
                "nuclearcraft:fluid_nak@0"
            ]
        },
        {
            "x": 1,
            "y": -5,
            "z": 5,
            "elements": [
                "theaurorian:auroriansteelblock@0"
            ]
        },
        {
            "x": -4,
            "y": 2,
            "z": 5,
            "elements": [
                "theaurorian:auroriansteelblock@0"
            ]
        },
        {
            "x": 4,
            "y": -5,
            "z": 5,
            "elements": [
                "thermalfoundation:glass@8"
            ]
        },
        {
            "x": 2,
            "y": -2,
            "z": 7,
            "elements": [
                "quark:biome_brick@1"
            ]
        },
        {
            "x": 3,
            "y": 5,
            "z": 3,
            "elements": [
                "thermalfoundation:glass@8"
            ]
        },
        {
            "x": -6,
            "y": 1,
            "z": 4,
            "elements": [
                "nuclearcraft:fluid_nak@0"
            ]
        },
        {
            "x": 0,
            "y": 1,
            "z": 8,
            "elements": [
                "quark:biome_brick@1"
            ]
        },
        {
            "x": 0,
            "y": 4,
            "z": 4,
            "elements": [
                "quark:biome_brick@1"
            ]
        },
        {
            "x": 3,
            "y": 1,
            "z": 7,
            "elements": [
                "quark:biome_brick@1"
            ]
        },
        {
            "x": -4,
            "y": -5,
            "z": 4,
            "elements": [
                "minecraft:piston@5"
            ]
        },
        {
            "x": -4,
            "y": 1,
            "z": 5,
            "elements": [
                "quark:biome_brick@1"
            ]
        },
        {
            "x": 1,
            "y": -6,
            "z": 5,
            "elements": [
                "thermalfoundation:glass@8"
            ]
        },
        {
            "x": -6,
            "y": -7,
            "z": 6,
            "elements": [
                "theaurorian:auroriansteelblock@0"
            ]
        },
        {
            "x": 0,
            "y": 3,
            "z": 7,
            "elements": [
                "quark:biome_brick@1"
            ]
        },
        {
            "x": 3,
            "y": 6,
            "z": 5,
            "elements": [
                "jaopca:block.skythern@0"
            ]
        },
        {
            "x": 5,
            "y": 1,
            "z": 5,
            "elements": [
                "theaurorian:auroriansteelblock@0"
            ]
        },
        {
            "x": -7,
            "y": -7,
            "z": 5,
            "elements": [
                "theaurorian:auroriansteelblock@0"
            ]
        },
        {
            "x": 1,
            "y": -4,
            "z": 4,
            "elements": [
                "quark:biome_brick@1"
            ]
        },
        {
            "x": 5,
            "y": 2,
            "z": 5,
            "elements": [
                "thermalfoundation:glass@8"
            ]
        },
        {
            "x": -7,
            "y": -4,
            "z": 3,
            "elements": [
                "casings_all"
            ]
        },
        {
            "x": -2,
            "y": 5,
            "z": 4,
            "elements": [
                "nuclearcraft:fluid_nak@0"
            ]
        },
        {
            "x": -2,
            "y": 6,
            "z": 3,
            "elements": [
                "thermalfoundation:glass@8"
            ]
        },
        {
            "x": -4,
            "y": 0,
            "z": 4,
            "elements": [
                "quark:biome_brick@1"
            ]
        },
        {
            "x": 5,
            "y": -2,
            "z": 5,
            "elements": [
                "thermalfoundation:glass@8"
            ]
        },
        {
            "x": 1,
            "y": 4,
            "z": 3,
            "elements": [
                "quark:biome_brick@1"
            ]
        },
        {
            "x": 6,
            "y": -3,
            "z": 3,
            "elements": [
                "jaopca:block.skythern@0"
            ]
        },
        {
            "x": -4,
            "y": 1,
            "z": 4,
            "elements": [
                "quark:biome_brick@1"
            ]
        },
        {
            "x": -2,
            "y": 6,
            "z": 4,
            "elements": [
                "nuclearcraft:fluid_nak@0"
            ]
        },
        {
            "x": 4,
            "y": -6,
            "z": 4,
            "elements": [
                "randomthings:superlubricentice@0"
            ]
        },
        {
            "x": 5,
            "y": 0,
            "z": 5,
            "elements": [
                "theaurorian:auroriansteelblock@0"
            ]
        },
        {
            "x": 4,
            "y": 2,
            "z": 3,
            "elements": [
                "theaurorian:auroriansteelblock@0"
            ]
        },
        {
            "x": -4,
            "y": -6,
            "z": 3,
            "elements": [
                "nuclearcraft:fluid_nak@0"
            ]
        },
        {
            "x": 4,
            "y": 0,
            "z": 3,
            "elements": [
                "quark:biome_brick@1"
            ]
        },
        {
            "x": 6,
            "y": -2,
            "z": 3,
            "elements": [
                "thermalfoundation:glass@8"
            ]
        },
        {
            "x": -5,
            "y": -1,
            "z": 4,
            "elements": [
                "randomthings:superlubricentice@0"
            ]
        },
        {
            "x": 3,
            "y": 5,
            "z": 5,
            "elements": [
                "thermalfoundation:glass@8"
            ]
        },
        {
            "x": -4,
            "y": -7,
            "z": 3,
            "elements": [
                "chisel:technical1@1"
            ]
        },
        {
            "x": -4,
            "y": 2,
            "z": 4,
            "elements": [
                "quark:biome_brick@1"
            ]
        },
        {
            "x": 0,
            "y": 2,
            "z": 8,
            "elements": [
                "quark:biome_brick@1"
            ]
        },
        {
            "x": 4,
            "y": 1,
            "z": 3,
            "elements": [
                "quark:biome_brick@1"
            ]
        },
        {
            "x": -2,
            "y": 5,
            "z": 3,
            "elements": [
                "thermalfoundation:glass@8"
            ]
        },
        {
            "x": 1,
            "y": -5,
            "z": 4,
            "elements": [
                "randomthings:superlubricentice@0"
            ]
        },
        {
            "x": 5,
            "y": -1,
            "z": 5,
            "elements": [
                "theaurorian:auroriansteelblock@0"
            ]
        },
        {
            "x": -5,
            "y": 3,
            "z": 3,
            "elements": [
                "thermalfoundation:glass@8"
            ]
        },
        {
            "x": -7,
            "y": -5,
            "z": 3,
            "elements": [
                "casings_all"
            ]
        },
        {
            "x": -1,
            "y": -7,
            "z": 4,
            "elements": [
                "randomthings:superlubricentice@0"
            ]
        },
        {
            "x": 6,
            "y": 1,
            "z": 5,
            "elements": [
                "thermalfoundation:glass@8"
            ]
        },
        {
            "x": -1,
            "y": -6,
            "z": 3,
            "elements": [
                "thermalfoundation:glass@8"
            ]
        },
        {
            "x": 3,
            "y": 4,
            "z": 5,
            "elements": [
                "theaurorian:auroriansteelblock@0"
            ]
        },
        {
            "x": -7,
            "y": -2,
            "z": 3,
            "elements": [
                "theaurorian:auroriansteelblock@0"
            ]
        },
        {
            "x": 1,
            "y": 6,
            "z": 3,
            "elements": [
                "thermalfoundation:glass@8"
            ]
        },
        {
            "x": 2,
            "y": 3,
            "z": 2,
            "elements": [
                "quark:biome_brick@1"
            ]
        },
        {
            "x": -1,
            "y": -6,
            "z": 4,
            "elements": [
                "nuclearcraft:fluid_nak@0"
            ]
        },
        {
            "x": 4,
            "y": -2,
            "z": 5,
            "elements": [
                "theaurorian:auroriansteelblock@0"
            ]
        },
        {
            "x": 6,
            "y": 2,
            "z": 5,
            "elements": [
                "thermalfoundation:glass@8"
            ]
        },
        {
            "x": -2,
            "y": -4,
            "z": 4,
            "elements": [
                "quark:biome_brick@1"
            ]
        },
        {
            "x": -2,
            "y": 4,
            "z": 3,
            "elements": [
                "theaurorian:auroriansteelblock@0"
            ]
        },
        {
            "x": -7,
            "y": -3,
            "z": 3,
            "elements": [
                "theaurorian:auroriansteelblock@0"
            ]
        },
        {
            "x": -2,
            "y": 4,
            "z": 4,
            "elements": [
                "quark:biome_brick@1"
            ]
        },
        {
            "x": 6,
            "y": 0,
            "z": 5,
            "elements": [
                "thermalfoundation:glass@8"
            ]
        },
        {
            "x": 1,
            "y": 5,
            "z": 3,
            "elements": [
                "theaurorian:auroriansteelblock@0"
            ]
        },
        {
            "x": 3,
            "y": 3,
            "z": 5,
            "elements": [
                "quark:biome_brick@1"
            ]
        },
        {
            "x": -2,
            "y": -5,
            "z": 4,
            "elements": [
                "randomthings:superlubricentice@0"
            ]
        },
        {
            "x": 4,
            "y": -1,
            "z": 5,
            "elements": [
                "quark:biome_brick@1"
            ]
        },
        {
            "x": -2,
            "y": 3,
            "z": 3,
            "elements": [
                "quark:biome_brick@1"
            ]
        },
        {
            "x": 6,
            "y": -4,
            "z": 3,
            "elements": [
                "jaopca:block.skythern@0"
            ]
        },
        {
            "x": -1,
            "y": -7,
            "z": 3,
            "elements": [
                "theaurorian:auroriansteelblock@0"
            ]
        },
        {
            "x": -4,
            "y": 5,
            "z": 4,
            "elements": [
                "nuclearcraft:fluid_nak@0"
            ]
        },
        {
            "x": 2,
            "y": 4,
            "z": 5,
            "elements": [
                "theaurorian:auroriansteelblock@0"
            ]
        },
        {
            "x": 3,
            "y": 2,
            "z": 5,
            "elements": [
                "quark:biome_brick@1"
            ]
        },
        {
            "x": 7,
            "y": -2,
            "z": 5,
            "elements": [
                "jaopca:block.skythern@0"
            ]
        },
        {
            "x": -5,
            "y": 1,
            "z": 3,
            "elements": [
                "theaurorian:auroriansteelblock@0"
            ]
        },
        {
            "x": -7,
            "y": -1,
            "z": 3,
            "elements": [
                "theaurorian:auroriansteelblock@0"
            ]
        },
        {
            "x": 2,
            "y": -6,
            "z": 4,
            "elements": [
                "nuclearcraft:fluid_nak@0"
            ]
        },
        {
            "x": -5,
            "y": 3,
            "z": 4,
            "elements": [
                "nuclearcraft:fluid_nak@0"
            ]
        },
        {
            "x": -1,
            "y": -4,
            "z": 4,
            "elements": [
                "quark:biome_brick@1"
            ]
        },
        {
            "x": 5,
            "y": 5,
            "z": 5,
            "elements": [
                "jaopca:block.skythern@0"
            ]
        },
        {
            "x": 5,
            "y": -5,
            "z": 5,
            "elements": [
                "jaopca:block.skythern@0"
            ]
        },
        {
            "x": -5,
            "y": 4,
            "z": 4,
            "elements": [
                "nuclearcraft:fluid_nak@0"
            ]
        },
        {
            "x": -4,
            "y": -3,
            "z": 3,
            "elements": [
                "randomthings:superlubricentice@0"
            ]
        },
        {
            "x": 3,
            "y": -5,
            "z": 3,
            "elements": [
                "thermalfoundation:glass@8"
            ]
        },
        {
            "x": -4,
            "y": 6,
            "z": 4,
            "elements": [
                "randomthings:superlubricentice@0"
            ]
        },
        {
            "x": -5,
            "y": 2,
            "z": 3,
            "elements": [
                "thermalfoundation:glass@8"
            ]
        },
        {
            "x": 2,
            "y": 3,
            "z": 5,
            "elements": [
                "quark:biome_brick@1"
            ]
        },
        {
            "x": 3,
            "y": -4,
            "z": 3,
            "elements": [
                "theaurorian:auroriansteelblock@0"
            ]
        },
        {
            "x": -1,
            "y": -5,
            "z": 4,
            "elements": [
                "randomthings:superlubricentice@0"
            ]
        },
        {
            "x": -1,
            "y": -1,
            "z": 8,
            "elements": [
                "quark:biome_brick@1"
            ]
        },
        {
            "x": 2,
            "y": 6,
            "z": 5,
            "elements": [
                "thermalfoundation:glass@8"
            ]
        },
        {
            "x": 7,
            "y": -1,
            "z": 5,
            "elements": [
                "theaurorian:auroriansteelblock@0"
            ]
        },
        {
            "x": -6,
            "y": 0,
            "z": 3,
            "elements": [
                "thermalfoundation:glass@8"
            ]
        },
        {
            "x": 2,
            "y": -7,
            "z": 4,
            "elements": [
                "randomthings:superlubricentice@0"
            ]
        },
        {
            "x": -4,
            "y": -4,
            "z": 3,
            "elements": [
                "nuclearcraft:fluid_nak@0"
            ]
        },
        {
            "x": -5,
            "y": 5,
            "z": 4,
            "elements": [
                "theaurorian:auroriansteelblock@0"
            ]
        },
        {
            "x": 0,
            "y": 0,
            "z": 8,
            "elements": [
                "quark:biome_brick@1"
            ]
        },
        {
            "x": 5,
            "y": -4,
            "z": 5,
            "elements": [
                "thermalfoundation:glass@8"
            ]
        },
        {
            "x": 5,
            "y": 4,
            "z": 5,
            "elements": [
                "thermalfoundation:glass@8"
            ]
        },
        {
            "x": 2,
            "y": 7,
            "z": 5,
            "elements": [
                "jaopca:block.skythern@0"
            ]
        },
        {
            "x": -6,
            "y": 1,
            "z": 3,
            "elements": [
                "thermalfoundation:glass@8"
            ]
        },
        {
            "x": 1,
            "y": -6,
            "z": 4,
            "elements": [
                "nuclearcraft:fluid_nak@0"
            ]
        },
        {
            "x": -1,
            "y": 7,
            "z": 5,
            "elements": [
                "theaurorian:auroriansteelblock@0"
            ]
        },
        {
            "x": -6,
            "y": -1,
            "z": 3,
            "elements": [
                "thermalfoundation:glass@8"
            ]
        },
        {
            "x": -4,
            "y": 3,
            "z": 4,
            "elements": [
                "randomthings:superlubricentice@0"
            ]
        },
        {
            "x": 0,
            "y": -4,
            "z": 4,
            "elements": [
                "quark:biome_brick@1"
            ]
        },
        {
            "x": 3,
            "y": -3,
            "z": 3,
            "elements": [
                "quark:biome_brick@1"
            ]
        },
        {
            "x": 5,
            "y": 3,
            "z": 5,
            "elements": [
                "thermalfoundation:glass@8"
            ]
        },
        {
            "x": 5,
            "y": -3,
            "z": 5,
            "elements": [
                "thermalfoundation:glass@8"
            ]
        },
        {
            "x": -4,
            "y": -5,
            "z": 3,
            "elements": [
                "nuclearcraft:fluid_nak@0"
            ]
        },
        {
            "x": -4,
            "y": 4,
            "z": 4,
            "elements": [
                "nuclearcraft:fluid_nak@0"
            ]
        },
        {
            "x": -6,
            "y": 2,
            "z": 3,
            "elements": [
                "thermalfoundation:glass@8"
            ]
        },
        {
            "x": -2,
            "y": 7,
            "z": 3,
            "elements": [
                "jaopca:block.skythern@0"
            ]
        },
        {
            "x": 2,
            "y": 5,
            "z": 5,
            "elements": [
                "thermalfoundation:glass@8"
            ]
        },
        {
            "x": -5,
            "y": 0,
            "z": 3,
            "elements": [
                "theaurorian:auroriansteelblock@0"
            ]
        },
        {
            "x": 2,
            "y": -4,
            "z": 5,
            "elements": [
                "theaurorian:auroriansteelblock@0"
            ]
        },
        {
            "x": 3,
            "y": -2,
            "z": 3,
            "elements": [
                "quark:biome_brick@1"
            ]
        },
        {
            "x": 0,
            "y": -5,
            "z": 4,
            "elements": [
                "additions:freezite_block@0"
            ]
        },
        {
            "x": 1,
            "y": -7,
            "z": 4,
            "elements": [
                "randomthings:superlubricentice@0"
            ]
        },
        {
            "x": -6,
            "y": 3,
            "z": 3,
            "elements": [
                "jaopca:block.skythern@0"
            ]
        },
        {
            "x": -5,
            "y": -5,
            "z": 2,
            "elements": [
                "thermalfoundation:glass@8"
            ]
        },
        {
            "x": 0,
            "y": -7,
            "z": 4,
            "elements": [
                "randomthings:superlubricentice@0"
            ]
        },
        {
            "x": 0,
            "y": -6,
            "z": 3,
            "elements": [
                "thermalfoundation:glass@8"
            ]
        },
        {
            "x": -7,
            "y": -1,
            "z": 5,
            "elements": [
                "theaurorian:auroriansteelblock@0"
            ]
        },
        {
            "x": -3,
            "y": -4,
            "z": 3,
            "elements": [
                "randomthings:superlubricentice@0"
            ]
        },
        {
            "x": -4,
            "y": -5,
            "z": 5,
            "elements": [
                "nuclearcraft:fluid_nak@0"
            ]
        },
        {
            "x": -3,
            "y": -5,
            "z": 3,
            "elements": [
                "nuclearcraft:fluid_nak@0"
            ]
        },
        {
            "x": 2,
            "y": -3,
            "z": 3,
            "elements": [
                "quark:biome_brick@1"
            ]
        },
        {
            "x": 0,
            "y": -6,
            "z": 4,
            "elements": [
                "nuclearcraft:fluid_nak@0"
            ]
        },
        {
            "x": -3,
            "y": 4,
            "z": 3,
            "elements": [
                "theaurorian:auroriansteelblock@0"
            ]
        },
        {
            "x": -3,
            "y": -4,
            "z": 4,
            "elements": [
                "randomthings:superlubricentice@0"
            ]
        },
        {
            "x": -6,
            "y": -2,
            "z": 4,
            "elements": [
                "nuclearcraft:fluid_nak@0"
            ]
        },
        {
            "x": 2,
            "y": 6,
            "z": 4,
            "elements": [
                "nuclearcraft:fluid_nak@0"
            ]
        },
        {
            "x": -3,
            "y": 2,
            "z": 3,
            "elements": [
                "quark:biome_brick@1"
            ]
        },
        {
            "x": -1,
            "y": 7,
            "z": 4,
            "elements": [
                "randomthings:superlubricentice@0"
            ]
        },
        {
            "x": -6,
            "y": 4,
            "z": 3,
            "elements": [
                "jaopca:block.skythern@0"
            ]
        },
        {
            "x": -5,
            "y": -6,
            "z": 2,
            "elements": [
                "chisel:technical1@1"
            ]
        },
        {
            "x": 2,
            "y": -3,
            "z": 5,
            "elements": [
                "quark:biome_brick@1"
            ]
        },
        {
            "x": -4,
            "y": -6,
            "z": 5,
            "elements": [
                "nuclearcraft:fluid_nak@0"
            ]
        },
        {
            "x": -3,
            "y": -5,
            "z": 4,
            "elements": [
                "nuclearcraft:fluid_nak@0"
            ]
        },
        {
            "x": 2,
            "y": 5,
            "z": 4,
            "elements": [
                "nuclearcraft:fluid_nak@0"
            ]
        },
        {
            "x": 0,
            "y": -7,
            "z": 3,
            "elements": [
                "theaurorian:auroriansteelblock@0"
            ]
        },
        {
            "x": -6,
            "y": -3,
            "z": 4,
            "elements": [
                "nuclearcraft:fluid_nak@0"
            ]
        },
        {
            "x": -6,
            "y": 0,
            "z": 5,
            "elements": [
                "thermalfoundation:glass@8"
            ]
        },
        {
            "x": 3,
            "y": -6,
            "z": 3,
            "elements": [
                "jaopca:block.skythern@0"
            ]
        },
        {
            "x": -6,
            "y": -5,
            "z": 4,
            "elements": [
                "minecraft:piston@4"
            ]
        },
        {
            "x": -5,
            "y": -7,
            "z": 2,
            "elements": [
                "theaurorian:auroriansteelblock@0"
            ]
        },
        {
            "x": -6,
            "y": -4,
            "z": 4,
            "elements": [
                "nuclearcraft:fluid_nak@0"
            ]
        },
        {
            "x": -3,
            "y": 6,
            "z": 3,
            "elements": [
                "jaopca:block.skythern@0"
            ]
        },
        {
            "x": -5,
            "y": 1,
            "z": 4,
            "elements": [
                "randomthings:superlubricentice@0"
            ]
        },
        {
            "x": -4,
            "y": -3,
            "z": 5,
            "elements": [
                "randomthings:superlubricentice@0"
            ]
        },
        {
            "x": 3,
            "y": -6,
            "z": 4,
            "elements": [
                "randomthings:superlubricentice@0"
            ]
        },
        {
            "x": -4,
            "y": -1,
            "z": 3,
            "elements": [
                "quark:biome_brick@1"
            ]
        },
        {
            "x": -7,
            "y": -4,
            "z": 2,
            "elements": [
                "theaurorian:auroriansteelblock@0"
            ]
        },
        {
            "x": -6,
            "y": 1,
            "z": 5,
            "elements": [
                "thermalfoundation:glass@8"
            ]
        },
        {
            "x": -3,
            "y": -3,
            "z": 3,
            "elements": [
                "quark:biome_brick@1"
            ]
        },
        {
            "x": 2,
            "y": -5,
            "z": 3,
            "elements": [
                "thermalfoundation:glass@8"
            ]
        },
        {
            "x": 2,
            "y": 4,
            "z": 4,
            "elements": [
                "quark:biome_brick@1"
            ]
        },
        {
            "x": -6,
            "y": 2,
            "z": 5,
            "elements": [
                "thermalfoundation:glass@8"
            ]
        },
        {
            "x": -3,
            "y": -2,
            "z": 3,
            "elements": [
                "quark:biome_brick@1"
            ]
        },
        {
            "x": 2,
            "y": -4,
            "z": 3,
            "elements": [
                "theaurorian:auroriansteelblock@0"
            ]
        },
        {
            "x": -5,
            "y": 2,
            "z": 4,
            "elements": [
                "nuclearcraft:fluid_nak@0"
            ]
        },
        {
            "x": -3,
            "y": 5,
            "z": 3,
            "elements": [
                "thermalfoundation:glass@8"
            ]
        },
        {
            "x": -7,
            "y": -2,
            "z": 5,
            "elements": [
                "theaurorian:auroriansteelblock@0"
            ]
        },
        {
            "x": -4,
            "y": -4,
            "z": 5,
            "elements": [
                "nuclearcraft:fluid_nak@0"
            ]
        },
        {
            "x": -3,
            "y": -3,
            "z": 4,
            "elements": [
                "quark:biome_brick@1"
            ]
        },
        {
            "x": -4,
            "y": 3,
            "z": 3,
            "elements": [
                "theaurorian:auroriansteelblock@0"
            ]
        },
        {
            "x": 2,
            "y": -6,
            "z": 3,
            "elements": [
                "thermalfoundation:glass@8"
            ]
        },
        {
            "x": -7,
            "y": -5,
            "z": 2,
            "elements": [
                "theaurorian:auroriansteelblock@0"
            ]
        },
        {
            "x": 3,
            "y": -4,
            "z": 4,
            "elements": [
                "randomthings:superlubricentice@0"
            ]
        },
        {
            "x": -4,
            "y": -7,
            "z": 2,
            "elements": [
                "theaurorian:auroriansteelblock@0"
            ]
        },
        {
            "x": -1,
            "y": -4,
            "z": 3,
            "elements": [
                "quark:biome_brick@1"
            ]
        },
        {
            "x": -1,
            "y": -7,
            "z": 5,
            "elements": [
                "theaurorian:auroriansteelblock@0"
            ]
        },
        {
            "x": -4,
            "y": 6,
            "z": 3,
            "elements": [
                "jaopca:block.skythern@0"
            ]
        },
        {
            "x": -5,
            "y": 4,
            "z": 3,
            "elements": [
                "thermalfoundation:glass@8"
            ]
        },
        {
            "x": -7,
            "y": -3,
            "z": 5,
            "elements": [
                "theaurorian:auroriansteelblock@0"
            ]
        },
        {
            "x": -1,
            "y": -5,
            "z": 3,
            "elements": [
                "theaurorian:auroriansteelblock@0"
            ]
        },
        {
            "x": 2,
            "y": -7,
            "z": 3,
            "elements": [
                "jaopca:block.skythern@0"
            ]
        },
        {
            "x": 4,
            "y": -3,
            "z": 4,
            "elements": [
                "randomthings:superlubricentice@0"
            ]
        },
        {
            "x": -7,
            "y": -6,
            "z": 2,
            "elements": [
                "theaurorian:auroriansteelblock@0"
            ]
        },
        {
            "x": -1,
            "y": 4,
            "z": 4,
            "elements": [
                "quark:biome_brick@1"
            ]
        },
        {
            "x": -7,
            "y": -4,
            "z": 5,
            "elements": [
                "casings_all"
            ]
        },
        {
            "x": 0,
            "y": -4,
            "z": 3,
            "elements": [
                "quark:biome_brick@1"
            ]
        },
        {
            "x": -3,
            "y": 3,
            "z": 3,
            "elements": [
                "quark:biome_brick@1"
            ]
        },
        {
            "x": -7,
            "y": -3,
            "z": 2,
            "elements": [
                "theaurorian:auroriansteelblock@0"
            ]
        },
        {
            "x": -4,
            "y": 5,
            "z": 3,
            "elements": [
                "thermalfoundation:glass@8"
            ]
        },
        {
            "x": 3,
            "y": -5,
            "z": 4,
            "elements": [
                "nuclearcraft:fluid_nak@0"
            ]
        },
        {
            "x": 1,
            "y": -6,
            "z": 3,
            "elements": [
                "thermalfoundation:glass@8"
            ]
        },
        {
            "x": -4,
            "y": -5,
            "z": 2,
            "elements": [
                "chisel:technical1@1"
            ]
        },
        {
            "x": -3,
            "y": -7,
            "z": 4,
            "elements": [
                "theaurorian:auroriansteelblock@0"
            ]
        },
        {
            "x": 4,
            "y": -4,
            "z": 4,
            "elements": [
                "nuclearcraft:fluid_nak@0"
            ]
        },
        {
            "x": -4,
            "y": -7,
            "z": 5,
            "elements": [
                "chisel:technical1@1"
            ]
        },
        {
            "x": -5,
            "y": 0,
            "z": 4,
            "elements": [
                "additions:freezite_block@0"
            ]
        },
        {
            "x": -1,
            "y": 5,
            "z": 4,
            "elements": [
                "randomthings:superlubricentice@0"
            ]
        },
        {
            "x": -7,
            "y": -5,
            "z": 5,
            "elements": [
                "casings_all"
            ]
        },
        {
            "x": -1,
            "y": 6,
            "z": 4,
            "elements": [
                "nuclearcraft:fluid_nak@0"
            ]
        },
        {
            "x": -7,
            "y": -7,
            "z": 2,
            "elements": [
                "theaurorian:auroriansteelblock@0"
            ]
        },
        {
            "x": -4,
            "y": 4,
            "z": 3,
            "elements": [
                "thermalfoundation:glass@8"
            ]
        },
        {
            "x": -4,
            "y": -6,
            "z": 2,
            "elements": [
                "chisel:technical1@1"
            ]
        },
        {
            "x": 4,
            "y": -5,
            "z": 4,
            "elements": [
                "nuclearcraft:fluid_nak@0"
            ]
        },
        {
            "x": -6,
            "y": -1,
            "z": 4,
            "elements": [
                "nuclearcraft:fluid_nak@0"
            ]
        },
        {
            "x": -7,
            "y": -6,
            "z": 5,
            "elements": [
                "casings_all"
            ]
        },
        {
            "x": 0,
            "y": -5,
            "z": 3,
            "elements": [
                "theaurorian:auroriansteelblock@0"
            ]
        },
        {
            "x": 3,
            "y": -3,
            "z": 4,
            "elements": [
                "quark:biome_brick@1"
            ]
        },
        {
            "x": -3,
            "y": -6,
            "z": 4,
            "elements": [
                "nuclearcraft:fluid_nak@0"
            ]
        },
        {
            "x": -5,
            "y": 5,
            "z": 3,
            "elements": [
                "jaopca:block.skythern@0"
            ]
        },
        {
            "x": 1,
            "y": -7,
            "z": 3,
            "elements": [
                "theaurorian:auroriansteelblock@0"
            ]
        },
        {
            "x": 4,
            "y": 1,
            "z": 4,
            "elements": [
                "quark:biome_brick@1"
            ]
        },
        {
            "x": 4,
            "y": -6,
            "z": 3,
            "elements": [
                "jaopca:block.skythern@0"
            ]
        },
        {
            "x": -1,
            "y": 2,
            "z": 7,
            "elements": [
                "quark:biome_brick@1"
            ]
        },
        {
            "x": -7,
            "y": 1,
            "z": 3,
            "elements": [
                "theaurorian:auroriansteelblock@0"
            ]
        },
        {
            "x": -2,
            "y": -3,
            "z": 3,
            "elements": [
                "quark:biome_brick@1"
            ]
        },
        {
            "x": -5,
            "y": -1,
            "z": 3,
            "elements": [
                "theaurorian:auroriansteelblock@0"
            ]
        },
        {
            "x": -5,
            "y": -4,
            "z": 2,
            "elements": [
                "chisel:technical1@1"
            ]
        },
        {
            "x": 6,
            "y": -1,
            "z": 4,
            "elements": [
                "nuclearcraft:fluid_nak@0"
            ]
        },
        {
            "x": 7,
            "y": 0,
            "z": 4,
            "elements": [
                "randomthings:superlubricentice@0"
            ]
        },
        {
            "x": 4,
            "y": 2,
            "z": 4,
            "elements": [
                "quark:biome_brick@1"
            ]
        },
        {
            "x": 2,
            "y": 3,
            "z": 6,
            "elements": [
                "quark:biome_brick@1"
            ]
        },
        {
            "x": -7,
            "y": 2,
            "z": 3,
            "elements": [
                "jaopca:block.skythern@0"
            ]
        },
        {
            "x": 3,
            "y": 2,
            "z": 2,
            "elements": [
                "quark:biome_brick@1"
            ]
        },
        {
            "x": 1,
            "y": 4,
            "z": 4,
            "elements": [
                "quark:biome_brick@1"
            ]
        },
        {
            "x": -7,
            "y": 1,
            "z": 4,
            "elements": [
                "randomthings:superlubricentice@0"
            ]
        },
        {
            "x": 0,
            "y": 4,
            "z": 2,
            "elements": [
                "quark:biome_brick@1"
            ]
        },
        {
            "x": 1,
            "y": -5,
            "z": 3,
            "elements": [
                "theaurorian:auroriansteelblock@0"
            ]
        },
        {
            "x": -5,
            "y": -3,
            "z": 2,
            "elements": [
                "theaurorian:auroriansteelblock@0"
            ]
        },
        {
            "x": -4,
            "y": 0,
            "z": 3,
            "elements": [
                "quark:biome_brick@1"
            ]
        },
        {
            "x": -1,
            "y": 3,
            "z": 7,
            "elements": [
                "quark:biome_brick@1"
            ]
        },
        {
            "x": 1,
            "y": -4,
            "z": 3,
            "elements": [
                "quark:biome_brick@1"
            ]
        },
        {
            "x": 1,
            "y": -2,
            "z": 7,
            "elements": [
                "quark:biome_brick@1"
            ]
        },
        {
            "x": 7,
            "y": 1,
            "z": 4,
            "elements": [
                "randomthings:superlubricentice@0"
            ]
        },
        {
            "x": -4,
            "y": 1,
            "z": 3,
            "elements": [
                "quark:biome_brick@1"
            ]
        },
        {
            "x": -7,
            "y": 0,
            "z": 4,
            "elements": [
                "randomthings:superlubricentice@0"
            ]
        },
        {
            "x": 6,
            "y": -4,
            "z": 4,
            "elements": [
                "randomthings:superlubricentice@0"
            ]
        },
        {
            "x": 3,
            "y": 1,
            "z": 2,
            "elements": [
                "quark:biome_brick@1"
            ]
        },
        {
            "x": -4,
            "y": -4,
            "z": 2,
            "elements": [
                "chisel:technical1@1"
            ]
        },
        {
            "x": 1,
            "y": 6,
            "z": 4,
            "elements": [
                "nuclearcraft:fluid_nak@0"
            ]
        },
        {
            "x": -2,
            "y": -5,
            "z": 3,
            "elements": [
                "theaurorian:auroriansteelblock@0"
            ]
        },
        {
            "x": -2,
            "y": 0,
            "z": 8,
            "elements": [
                "quark:biome_brick@1"
            ]
        },
        {
            "x": 7,
            "y": 2,
            "z": 4,
            "elements": [
                "randomthings:superlubricentice@0"
            ]
        },
        {
            "x": -4,
            "y": 2,
            "z": 3,
            "elements": [
                "theaurorian:auroriansteelblock@0"
            ]
        },
        {
            "x": -4,
            "y": -3,
            "z": 2,
            "elements": [
                "theaurorian:auroriansteelblock@0"
            ]
        },
        {
            "x": 4,
            "y": -2,
            "z": 4,
            "elements": [
                "quark:biome_brick@1"
            ]
        },
        {
            "x": 1,
            "y": 5,
            "z": 4,
            "elements": [
                "randomthings:superlubricentice@0"
            ]
        },
        {
            "x": -7,
            "y": 0,
            "z": 3,
            "elements": [
                "theaurorian:auroriansteelblock@0"
            ]
        },
        {
            "x": 4,
            "y": 0,
            "z": 4,
            "elements": [
                "quark:biome_brick@1"
            ]
        },
        {
            "x": -5,
            "y": -4,
            "z": 3,
            "elements": [
                "nuclearcraft:fluid_nak@0"
            ]
        },
        {
            "x": 0,
            "y": -1,
            "z": 8,
            "elements": [
                "quark:biome_brick@1"
            ]
        },
        {
            "x": 4,
            "y": -3,
            "z": 3,
            "elements": [
                "theaurorian:auroriansteelblock@0"
            ]
        },
        {
            "x": -2,
            "y": -6,
            "z": 3,
            "elements": [
                "thermalfoundation:glass@8"
            ]
        },
        {
            "x": 4,
            "y": -1,
            "z": 4,
            "elements": [
                "quark:biome_brick@1"
            ]
        },
        {
            "x": 4,
            "y": 6,
            "z": 4,
            "elements": [
                "randomthings:superlubricentice@0"
            ]
        },
        {
            "x": -1,
            "y": 4,
            "z": 3,
            "elements": [
                "quark:biome_brick@1"
            ]
        },
        {
            "x": 0,
            "y": -2,
            "z": 8,
            "elements": [
                "quark:biome_brick@1"
            ]
        },
        {
            "x": 4,
            "y": -2,
            "z": 3,
            "elements": [
                "theaurorian:auroriansteelblock@0"
            ]
        },
        {
            "x": 1,
            "y": 7,
            "z": 4,
            "elements": [
                "randomthings:superlubricentice@0"
            ]
        },
        {
            "x": 1,
            "y": 0,
            "z": 8,
            "elements": [
                "quark:biome_brick@1"
            ]
        },
        {
            "x": 2,
            "y": 1,
            "z": 7,
            "elements": [
                "quark:biome_brick@1"
            ]
        },
        {
            "x": -3,
            "y": 2,
            "z": 2,
            "elements": [
                "quark:biome_brick@1"
            ]
        },
        {
            "x": -5,
            "y": -5,
            "z": 3,
            "elements": [
                "minecraft:piston@2"
            ]
        },
        {
            "x": -2,
            "y": -7,
            "z": 3,
            "elements": [
                "theaurorian:auroriansteelblock@0"
            ]
        },
        {
            "x": 7,
            "y": -2,
            "z": 4,
            "elements": [
                "randomthings:superlubricentice@0"
            ]
        },
        {
            "x": 5,
            "y": 0,
            "z": 4,
            "elements": [
                "additions:freezite_block@0"
            ]
        },
        {
            "x": 4,
            "y": 5,
            "z": 4,
            "elements": [
                "nuclearcraft:fluid_nak@0"
            ]
        },
        {
            "x": -1,
            "y": 1,
            "z": 8,
            "elements": [
                "quark:biome_brick@1"
            ]
        },
        {
            "x": 5,
            "y": 1,
            "z": 4,
            "elements": [
                "randomthings:superlubricentice@0"
            ]
        },
        {
            "x": -5,
            "y": -2,
            "z": 3,
            "elements": [
                "theaurorian:auroriansteelblock@0"
            ]
        },
        {
            "x": 4,
            "y": 3,
            "z": 4,
            "elements": [
                "randomthings:superlubricentice@0"
            ]
        },
        {
            "x": -1,
            "y": 6,
            "z": 3,
            "elements": [
                "thermalfoundation:glass@8"
            ]
        },
        {
            "x": 6,
            "y": -3,
            "z": 4,
            "elements": [
                "randomthings:superlubricentice@0"
            ]
        },
        {
            "x": 4,
            "y": -5,
            "z": 3,
            "elements": [
                "thermalfoundation:glass@8"
            ]
        },
        {
            "x": 4,
            "y": 4,
            "z": 4,
            "elements": [
                "nuclearcraft:fluid_nak@0"
            ]
        },
        {
            "x": -3,
            "y": 1,
            "z": 2,
            "elements": [
                "quark:biome_brick@1"
            ]
        },
        {
            "x": 1,
            "y": -3,
            "z": 7,
            "elements": [
                "quark:biome_brick@1"
            ]
        },
        {
            "x": -2,
            "y": -1,
            "z": 7,
            "elements": [
                "quark:biome_brick@1"
            ]
        },
        {
            "x": -1,
            "y": 3,
            "z": 6,
            "elements": [
                "quark:biome_brick@1"
            ]
        },
        {
            "x": 4,
            "y": -4,
            "z": 3,
            "elements": [
                "thermalfoundation:glass@8"
            ]
        },
        {
            "x": 2,
            "y": -3,
            "z": 2,
            "elements": [
                "quark:biome_brick@1"
            ]
        },
        {
            "x": -5,
            "y": -3,
            "z": 3,
            "elements": [
                "nuclearcraft:fluid_nak@0"
            ]
        },
        {
            "x": 5,
            "y": 2,
            "z": 4,
            "elements": [
                "nuclearcraft:fluid_nak@0"
            ]
        },
        {
            "x": -1,
            "y": 5,
            "z": 3,
            "elements": [
                "theaurorian:auroriansteelblock@0"
            ]
        },
        {
            "x": 6,
            "y": -2,
            "z": 4,
            "elements": [
                "nuclearcraft:fluid_nak@0"
            ]
        },
        {
            "x": -2,
            "y": -2,
            "z": 7,
            "elements": [
                "quark:biome_brick@1"
            ]
        },
        {
            "x": 7,
            "y": -1,
            "z": 3,
            "elements": [
                "theaurorian:auroriansteelblock@0"
            ]
        },
        {
            "x": 2,
            "y": 6,
            "z": 3,
            "elements": [
                "thermalfoundation:glass@8"
            ]
        },
        {
            "x": 5,
            "y": 4,
            "z": 3,
            "elements": [
                "thermalfoundation:glass@8"
            ]
        },
        {
            "x": -1,
            "y": 3,
            "z": 2,
            "elements": [
                "quark:biome_brick@1"
            ]
        },
        {
            "x": -1,
            "y": 7,
            "z": 3,
            "elements": [
                "theaurorian:auroriansteelblock@0"
            ]
        },
        {
            "x": -1,
            "y": 0,
            "z": 8,
            "elements": [
                "quark:biome_brick@1"
            ]
        },
        {
            "x": -1,
            "y": -3,
            "z": 2,
            "elements": [
                "quark:biome_brick@1"
            ]
        },
        {
            "x": 2,
            "y": 5,
            "z": 3,
            "elements": [
                "thermalfoundation:glass@8"
            ]
        },
        {
            "x": 5,
            "y": 3,
            "z": 3,
            "elements": [
                "thermalfoundation:glass@8"
            ]
        },
        {
            "x": 2,
            "y": 2,
            "z": 7,
            "elements": [
                "quark:biome_brick@1"
            ]
        },
        {
            "x": -7,
            "y": -3,
            "z": 6,
            "elements": [
                "theaurorian:auroriansteelblock@0"
            ]
        },
        {
            "x": -5,
            "y": -7,
            "z": 4,
            "elements": [
                "chisel:technical1@1"
            ]
        },
        {
            "x": -7,
            "y": -6,
            "z": 6,
            "elements": [
                "theaurorian:auroriansteelblock@0"
            ]
        },
        {
            "x": 4,
            "y": -1,
            "z": 3,
            "elements": [
                "quark:biome_brick@1"
            ]
        },
        {
            "x": 1,
            "y": 3,
            "z": 1,
            "elements": [
                "quark:biome_brick@1"
            ]
        },
        {
            "x": 1,
            "y": 2,
            "z": 1,
            "elements": [
                "quark:biome_brick@1"
            ]
        },
        {
            "x": 0,
            "y": -4,
            "z": 2,
            "elements": [
                "quark:biome_brick@1"
            ]
        },
        {
            "x": -2,
            "y": 3,
            "z": 2,
            "elements": [
                "quark:biome_brick@1"
            ]
        },
        {
            "x": 2,
            "y": 4,
            "z": 3,
            "elements": [
                "theaurorian:auroriansteelblock@0"
            ]
        },
        {
            "x": -5,
            "y": -6,
            "z": 3,
            "elements": [
                "nuclearcraft:fluid_nak@0"
            ]
        },
        {
            "x": 5,
            "y": 0,
            "z": 3,
            "elements": [
                "theaurorian:auroriansteelblock@0"
            ]
        },
        {
            "x": 5,
            "y": 5,
            "z": 3,
            "elements": [
                "jaopca:block.skythern@0"
            ]
        },
        {
            "x": -5,
            "y": -6,
            "z": 4,
            "elements": [
                "minecraft:piston@0"
            ]
        },
        {
            "x": -7,
            "y": -4,
            "z": 6,
            "elements": [
                "theaurorian:auroriansteelblock@0"
            ]
        },
        {
            "x": -7,
            "y": -5,
            "z": 6,
            "elements": [
                "theaurorian:auroriansteelblock@0"
            ]
        },
        {
            "x": 2,
            "y": 3,
            "z": 3,
            "elements": [
                "quark:biome_brick@1"
            ]
        },
        {
            "x": -4,
            "y": -7,
            "z": 6,
            "elements": [
                "theaurorian:auroriansteelblock@0"
            ]
        },
        {
            "x": -5,
            "y": -7,
            "z": 3,
            "elements": [
                "chisel:technical1@1"
            ]
        },
        {
            "x": 4,
            "y": 6,
            "z": 3,
            "elements": [
                "jaopca:block.skythern@0"
            ]
        },
        {
            "x": -4,
            "y": 0,
            "z": 2,
            "elements": [
                "quark:biome_brick@1"
            ]
        },
        {
            "x": -2,
            "y": -7,
            "z": 4,
            "elements": [
                "randomthings:superlubricentice@0"
            ]
        },
        {
            "x": 6,
            "y": 4,
            "z": 5,
            "elements": [
                "jaopca:block.skythern@0"
            ]
        },
        {
            "x": -5,
            "y": -5,
            "z": 4,
            "elements": [
                "avaritia:block_resource@0"
            ]
        },
        {
            "x": 1,
            "y": 3,
            "z": 2,
            "elements": [
                "quark:biome_brick@1"
            ]
        },
        {
            "x": -2,
            "y": -6,
            "z": 4,
            "elements": [
                "nuclearcraft:fluid_nak@0"
            ]
        },
        {
            "x": -5,
            "y": -4,
            "z": 4,
            "elements": [
                "minecraft:piston@1"
            ]
        },
        {
            "x": 1,
            "y": 7,
            "z": 3,
            "elements": [
                "theaurorian:auroriansteelblock@0"
            ]
        },
        {
            "x": 6,
            "y": 3,
            "z": 5,
            "elements": [
                "jaopca:block.skythern@0"
            ]
        },
        {
            "x": 4,
            "y": 5,
            "z": 3,
            "elements": [
                "thermalfoundation:glass@8"
            ]
        },
        {
            "x": 1,
            "y": -3,
            "z": 2,
            "elements": [
                "quark:biome_brick@1"
            ]
        },
        {
            "x": -7,
            "y": -7,
            "z": 6,
            "elements": [
                "theaurorian:auroriansteelblock@0"
            ]
        },
        {
            "x": 3,
            "y": -1,
            "z": 1,
            "elements": [
                "quark:biome_brick@1"
            ]
        },
        {
            "x": -5,
            "y": -2,
            "z": 4,
            "elements": [
                "randomthings:superlubricentice@0"
            ]
        },
        {
            "x": 6,
            "y": -1,
            "z": 3,
            "elements": [
                "thermalfoundation:glass@8"
            ]
        },
        {
            "x": 4,
            "y": 4,
            "z": 3,
            "elements": [
                "thermalfoundation:glass@8"
            ]
        },
        {
            "x": -7,
            "y": -6,
            "z": 3,
            "elements": [
                "casings_all"
            ]
        },
        {
            "x": 5,
            "y": 2,
            "z": 3,
            "elements": [
                "thermalfoundation:glass@8"
            ]
        },
        {
            "x": 7,
            "y": -2,
            "z": 3,
            "elements": [
                "jaopca:block.skythern@0"
            ]
        },
        {
            "x": 2,
            "y": 7,
            "z": 3,
            "elements": [
                "jaopca:block.skythern@0"
            ]
        },
        {
            "x": -2,
            "y": 7,
            "z": 4,
            "elements": [
                "randomthings:superlubricentice@0"
            ]
        },
        {
            "x": 4,
            "y": 3,
            "z": 3,
            "elements": [
                "theaurorian:auroriansteelblock@0"
            ]
        },
        {
            "x": -2,
            "y": -3,
            "z": 2,
            "elements": [
                "quark:biome_brick@1"
            ]
        },
        {
            "x": -7,
            "y": 2,
            "z": 4,
            "elements": [
                "randomthings:superlubricentice@0"
            ]
        },
        {
            "x": 5,
            "y": 1,
            "z": 3,
            "elements": [
                "theaurorian:auroriansteelblock@0"
            ]
        },
        {
            "x": -5,
            "y": -3,
            "z": 4,
            "elements": [
                "nuclearcraft:fluid_nak@0"
            ]
        },
        {
            "x": 4,
            "y": 4,
            "z": 5,
            "elements": [
                "thermalfoundation:glass@8"
            ]
        },
        {
            "x": 6,
            "y": -4,
            "z": 5,
            "elements": [
                "jaopca:block.skythern@0"
            ]
        },
        {
            "x": -3,
            "y": 0,
            "z": 1,
            "elements": [
                "quark:biome_brick@1"
            ]
        },
        {
            "x": 0,
            "y": 3,
            "z": 1,
            "elements": [
                "quark:biome_brick@1"
            ]
        },
        {
            "x": -7,
            "y": -7,
            "z": 3,
            "elements": [
                "theaurorian:auroriansteelblock@0"
            ]
        },
        {
            "x": 7,
            "y": 0,
            "z": 3,
            "elements": [
                "theaurorian:auroriansteelblock@0"
            ]
        },
        {
            "x": 3,
            "y": 1,
            "z": 6,
            "elements": [
                "quark:biome_brick@1"
            ]
        },
        {
            "x": -3,
            "y": -1,
            "z": 1,
            "elements": [
                "quark:biome_brick@1"
            ]
        },
        {
            "x": 4,
            "y": 3,
            "z": 5,
            "elements": [
                "theaurorian:auroriansteelblock@0"
            ]
        },
        {
            "x": 6,
            "y": -3,
            "z": 5,
            "elements": [
                "jaopca:block.skythern@0"
            ]
        },
        {
            "x": -5,
            "y": -7,
            "z": 6,
            "elements": [
                "theaurorian:auroriansteelblock@0"
            ]
        },
        {
            "x": -3,
            "y": 1,
            "z": 1,
            "elements": [
                "quark:biome_brick@1"
            ]
        },
        {
            "x": 4,
            "y": 6,
            "z": 5,
            "elements": [
                "jaopca:block.skythern@0"
            ]
        },
        {
            "x": -6,
            "y": -7,
            "z": 5,
            "elements": [
                "chisel:technical1@1"
            ]
        },
        {
            "x": 2,
            "y": -2,
            "z": 1,
            "elements": [
                "quark:biome_brick@1"
            ]
        },
        {
            "x": 3,
            "y": -2,
            "z": 2,
            "elements": [
                "quark:biome_brick@1"
            ]
        },
        {
            "x": 2,
            "y": -2,
            "z": 6,
            "elements": [
                "quark:biome_brick@1"
            ]
        },
        {
            "x": 7,
            "y": 2,
            "z": 3,
            "elements": [
                "jaopca:block.skythern@0"
            ]
        },
        {
            "x": -3,
            "y": 2,
            "z": 6,
            "elements": [
                "quark:biome_brick@1"
            ]
        },
        {
            "x": 3,
            "y": -1,
            "z": 2,
            "elements": [
                "quark:biome_brick@1"
            ]
        },
        {
            "x": 4,
            "y": 5,
            "z": 5,
            "elements": [
                "thermalfoundation:glass@8"
            ]
        },
        {
            "x": 1,
            "y": 7,
            "z": 5,
            "elements": [
                "theaurorian:auroriansteelblock@0"
            ]
        },
        {
            "x": 7,
            "y": 1,
            "z": 3,
            "elements": [
                "theaurorian:auroriansteelblock@0"
            ]
        },
        {
            "x": 2,
            "y": -1,
            "z": 1,
            "elements": [
                "quark:biome_brick@1"
            ]
        },
        {
            "x": -3,
            "y": -5,
            "z": 2,
            "elements": [
                "theaurorian:auroriansteelblock@0"
            ]
        },
        {
            "x": -5,
            "y": -7,
            "z": 5,
            "elements": [
                "chisel:technical1@1"
            ]
        },
        {
            "x": 3,
            "y": -1,
            "z": 7,
            "elements": [
                "quark:biome_brick@1"
            ]
        },
        {
            "x": -1,
            "y": -2,
            "z": 1,
            "elements": [
                "quark:biome_brick@1"
            ]
        },
        {
            "x": -5,
            "y": -5,
            "z": 6,
            "elements": [
                "thermalfoundation:glass@8"
            ]
        },
        {
            "x": -6,
            "y": -5,
            "z": 5,
            "elements": [
                "nuclearcraft:fluid_nak@0"
            ]
        },
        {
            "x": -4,
            "y": -6,
            "z": 6,
            "elements": [
                "chisel:technical1@1"
            ]
        },
        {
            "x": -2,
            "y": 2,
            "z": 1,
            "elements": [
                "quark:biome_brick@1"
            ]
        },
        {
            "x": 2,
            "y": -3,
            "z": 6,
            "elements": [
                "quark:biome_brick@1"
            ]
        },
        {
            "x": 1,
            "y": 2,
            "z": 7,
            "elements": [
                "quark:biome_brick@1"
            ]
        },
        {
            "x": -3,
            "y": -4,
            "z": 2,
            "elements": [
                "theaurorian:auroriansteelblock@0"
            ]
        },
        {
            "x": -3,
            "y": -6,
            "z": 2,
            "elements": [
                "theaurorian:auroriansteelblock@0"
            ]
        },
        {
            "x": -6,
            "y": -6,
            "z": 5,
            "elements": [
                "nuclearcraft:fluid_nak@0"
            ]
        },
        {
            "x": -2,
            "y": 2,
            "z": 7,
            "elements": [
                "quark:biome_brick@1"
            ]
        },
        {
            "x": 0,
            "y": -3,
            "z": 1,
            "elements": [
                "quark:biome_brick@1"
            ]
        },
        {
            "x": -3,
            "y": -3,
            "z": 2,
            "elements": [
                "theaurorian:auroriansteelblock@0"
            ]
        },
        {
            "x": 1,
            "y": 3,
            "z": 7,
            "elements": [
                "quark:biome_brick@1"
            ]
        },
        {
            "x": -5,
            "y": -3,
            "z": 6,
            "elements": [
                "theaurorian:auroriansteelblock@0"
            ]
        },
        {
            "x": 0,
            "y": 4,
            "z": 6,
            "elements": [
                "quark:biome_brick@1"
            ]
        },
        {
            "x": -3,
            "y": -7,
            "z": 2,
            "elements": [
                "theaurorian:auroriansteelblock@0"
            ]
        },
        {
            "x": -1,
            "y": 3,
            "z": 1,
            "elements": [
                "quark:biome_brick@1"
            ]
        },
        {
            "x": -3,
            "y": -2,
            "z": 2,
            "elements": [
                "quark:biome_brick@1"
            ]
        },
        {
            "x": -1,
            "y": 2,
            "z": 1,
            "elements": [
                "quark:biome_brick@1"
            ]
        },
        {
            "x": -5,
            "y": -6,
            "z": 6,
            "elements": [
                "chisel:technical1@1"
            ]
        },
        {
            "x": -6,
            "y": -3,
            "z": 5,
            "elements": [
                "nuclearcraft:fluid_nak@0"
            ]
        },
        {
            "x": -6,
            "y": -4,
            "z": 2,
            "elements": [
                "chisel:technical1@1"
            ]
        },
        {
            "x": -3,
            "y": -1,
            "z": 2,
            "elements": [
                "quark:biome_brick@1"
            ]
        },
        {
            "x": -5,
            "y": -4,
            "z": 6,
            "elements": [
                "chisel:technical1@1"
            ]
        },
        {
            "x": -1,
            "y": -3,
            "z": 1,
            "elements": [
                "quark:biome_brick@1"
            ]
        },
        {
            "x": -6,
            "y": -4,
            "z": 5,
            "elements": [
                "nuclearcraft:fluid_nak@0"
            ]
        },
        {
            "x": -2,
            "y": 1,
            "z": 1,
            "elements": [
                "quark:biome_brick@1"
            ]
        },
        {
            "x": -6,
            "y": -3,
            "z": 2,
            "elements": [
                "theaurorian:auroriansteelblock@0"
            ]
        },
        {
            "x": -4,
            "y": -3,
            "z": 6,
            "elements": [
                "theaurorian:auroriansteelblock@0"
            ]
        },
        {
            "x": -3,
            "y": 1,
            "z": 7,
            "elements": [
                "quark:biome_brick@1"
            ]
        },
        {
            "x": 1,
            "y": -2,
            "z": 1,
            "elements": [
                "quark:biome_brick@1"
            ]
        },
        {
            "x": 5,
            "y": 3,
            "z": 4,
            "elements": [
                "nuclearcraft:fluid_nak@0"
            ]
        },
        {
            "x": -6,
            "y": -7,
            "z": 2,
            "elements": [
                "theaurorian:auroriansteelblock@0"
            ]
        },
        {
            "x": 5,
            "y": 4,
            "z": 4,
            "elements": [
                "nuclearcraft:fluid_nak@0"
            ]
        },
        {
            "x": -3,
            "y": 0,
            "z": 7,
            "elements": [
                "quark:biome_brick@1"
            ]
        },
        {
            "x": -3,
            "y": -1,
            "z": 7,
            "elements": [
                "quark:biome_brick@1"
            ]
        },
        {
            "x": -2,
            "y": 3,
            "z": 6,
            "elements": [
                "quark:biome_brick@1"
            ]
        },
        {
            "x": -2,
            "y": 7,
            "z": 5,
            "elements": [
                "jaopca:block.skythern@0"
            ]
        },
        {
            "x": 3,
            "y": -5,
            "z": 5,
            "elements": [
                "thermalfoundation:glass@8"
            ]
        },
        {
            "x": -4,
            "y": -4,
            "z": 6,
            "elements": [
                "chisel:technical1@1"
            ]
        },
        {
            "x": 3,
            "y": -4,
            "z": 5,
            "elements": [
                "theaurorian:auroriansteelblock@0"
            ]
        },
        {
            "x": -6,
            "y": -5,
            "z": 2,
            "elements": [
                "chisel:technical1@1"
            ]
        },
        {
            "x": 1,
            "y": -1,
            "z": 8,
            "elements": [
                "quark:biome_brick@1"
            ]
        },
        {
            "x": -2,
            "y": 1,
            "z": 7,
            "elements": [
                "quark:biome_brick@1"
            ]
        },
        {
            "x": -4,
            "y": -5,
            "z": 6,
            "elements": [
                "chisel:technical1@1"
