{
    "registryname": "basic_miner",
    "localizedname": "§aLV1 - 基础采掘机",
    "requires-blueprint": false,
    "failure-action": "still",
    "color": "454545",
    "modifiers": [
        {
            "elements": "modularmachinery:blockcasing@1",
            "x": 0,
            "y": -1,
            "z": 0,
            "description": "将控制器下方的紧挨着的方块换成此方块以提高25%产品产出率！",
            "modifier": {
                "io": "output",
                "target": "modularmachinery:item",
                "operation": 1,
                "multiplier": 1.25,
                "affectChance": true
            }
        },
        {
            "elements": "modularmachinery:blockcasing@2",
            "x": 0,
            "y": -1,
            "z": 0,
            "description": "将控制器下方的紧挨着的方块换成此方块以提高50%产品产出率！",
            "modifier": {
                "io": "output",
                "target": "modularmachinery:item",
                "operation": 1,
                "multiplier": 1.5,
                "affectChance": true
            }
        },
        {
            "elements": "modularmachinery:blockcasing@3",
            "x": 0,
            "y": -1,
            "z": 0,
            "description": "将控制器下方的紧挨着的方块换成此方块以提高100%产品产出率！",
            "modifier": {
                "io": "output",
                "target": "modularmachinery:item",
                "operation": 1,
                "multiplier": 2.0,
                "affectChance": true
            }
        },
        {
            "elements": "modularmachinery:blockcasing@5",
            "x": 0,
            "y": -1,
            "z": 0,
            "description": "将控制器下方的紧挨着的方块换成此方块以提高150%产品产出率！",
            "modifier": {
                "io": "output",
                "target": "modularmachinery:item",
                "operation": 1,
                "multiplier": 2.5,
                "affectChance": true
            }
        }
    ],
    "parts": [
        {
            "x": 0,
            "y": 0,
            "z": 0,
            "elements": [
                "modularmachinery:basic_miner_factory_controller@2"
            ]
        },
        {
            "x": 0,
            "y": 11,
            "z": 4,
            "elements": [
                "appliedenergistics2:sky_stone_small_brick@0"
            ]
        },
        {
            "x": -3,
            "y": 0,
            "z": 5,
            "elements": [
                "twilightforest:magic_log@2"
            ]
        },
        {
            "x": -2,
            "y": 4,
            "z": 0,
            "elements": [
                "chisel:technical@13"
            ]
        },
        {
            "x": -3,
            "y": 9,
            "z": 14,
            "elements": [
                "appliedenergistics2:sky_stone_small_brick_slab@8"
            ]
        },
        {
            "x": -3,
            "y": 2,
            "z": 5,
            "elements": [
                "appliedenergistics2:sky_stone_small_brick@0"
            ]
        },
        {
            "x": -3,
            "y": 11,
            "z": 4,
            "elements": [
                "appliedenergistics2:sky_stone_small_brick@0"
            ]
        },
        {
            "x": 1,
            "y": 0,
            "z": 0,
            "elements": [
                "casings_parallel"
            ]
        },
        {
            "x": -2,
            "y": 2,
            "z": 0,
            "elements": [
                "appliedenergistics2:sky_stone_small_brick@0"
            ]
        },
        {
            "x": -2,
            "y": 0,
            "z": 5,
            "elements": [
                "appliedenergistics2:sky_stone_small_brick@0"
            ]
        },
        {
            "x": -2,
            "y": 2,
            "z": 5,
            "elements": [
                "tconstruct:seared_slab@3"
            ]
        },
        {
            "x": 3,
            "y": -1,
            "z": 9,
            "elements": [
                "chisel:technicalnew@2"
            ]
        },
        {
            "x": 0,
            "y": 8,
            "z": 3,
            "elements": [
                "actuallyadditions:block_misc@2"
            ]
        },
        {
            "x": -2,
            "y": 9,
            "z": 9,
            "elements": [
                "appliedenergistics2:sky_stone_small_brick_slab@8"
            ]
        },
        {
            "x": 2,
            "y": 0,
            "z": 0,
            "elements": [
                "twilightforest:magic_log@2"
            ]
        },
        {
            "x": 0,
            "y": 6,
            "z": 3,
            "elements": [
                "actuallyadditions:block_misc@2"
            ]
        },
        {
            "x": -3,
            "y": 6,
            "z": 5,
            "elements": [
                "chisel:technical@4"
            ]
        },
        {
            "x": -2,
            "y": 13,
            "z": 16,
            "elements": [
                "chisel:blockgold@0"
            ]
        },
        {
            "x": -3,
            "y": 13,
            "z": 14,
            "elements": [
                "thermalfoundation:glass@0"
            ]
        },
        {
            "x": -2,
            "y": 8,
            "z": 0,
            "elements": [
                "chisel:technical@13"
            ]
        },
        {
            "x": 4,
            "y": 10,
            "z": 2,
            "elements": [
                "appliedenergistics2:sky_stone_small_brick@0"
            ]
        },
        {
            "x": -1,
            "y": 0,
            "z": 0,
            "elements": [
                "casings_all"
            ]
        },
        {
            "x": 4,
            "y": 8,
            "z": 2,
            "elements": [
                "appliedenergistics2:sky_stone_small_brick@0"
            ]
        },
        {
            "x": -1,
            "y": 11,
            "z": 4,
            "elements": [
                "appliedenergistics2:sky_stone_small_brick@0"
            ]
        },
        {
            "x": 0,
            "y": 4,
            "z": 3,
            "elements": [
                "actuallyadditions:block_misc@2"
            ]
        },
        {
            "x": -2,
            "y": 6,
            "z": 0,
            "elements": [
                "chisel:technical@13"
            ]
        },
        {
            "x": -3,
            "y": 4,
            "z": 5,
            "elements": [
                "chisel:technical@4"
            ]
        },
        {
            "x": 3,
            "y": 0,
            "z": 3,
            "elements": [
                "casings_upgrade"
            ]
        },
        {
            "x": 2,
            "y": 7,
            "z": 4,
            "elements": [
                "tconstruct:seared_slab@3"
            ]
        },
        {
            "x": 4,
            "y": 9,
            "z": 2,
            "elements": [
                "appliedenergistics2:sky_stone_brick@0"
            ]
        },
        {
            "x": -2,
            "y": 13,
            "z": 9,
            "elements": [
                "thermalfoundation:glass@0"
            ]
        },
        {
            "x": -2,
            "y": 11,
            "z": 16,
            "elements": [
                "mca:rose_gold_block@0"
            ]
        },
        {
            "x": 0,
            "y": 13,
            "z": 7,
            "elements": [
                "appliedenergistics2:sky_stone_small_brick@0"
            ]
        },
        {
            "x": -4,
            "y": 11,
            "z": 12,
            "elements": [
                "mca:rose_gold_block@0"
            ]
        },
        {
            "x": -1,
            "y": 6,
            "z": 12,
            "elements": [
                "enderio:block_alloy@9"
            ]
        },
        {
            "x": 3,
            "y": 9,
            "z": 8,
            "elements": [
                "enderio:block_dark_iron_bars@0"
            ]
        },
        {
            "x": -1,
            "y": 6,
            "z": 5,
            "elements": [
                "tconstruct:seared_slab@3"
            ]
        },
        {
            "x": 2,
            "y": -1,
            "z": 4,
            "elements": [
                "chisel:planks-oak@12"
            ]
        },
        {
            "x": 0,
            "y": 12,
            "z": 6,
            "elements": [
                "appliedenergistics2:sky_stone_small_brick@0"
            ]
        },
        {
            "x": 0,
            "y": 9,
            "z": 7,
            "elements": [
                "appliedenergistics2:sky_stone_small_brick_stairs@6"
            ]
        },
        {
            "x": 2,
            "y": 4,
            "z": 0,
            "elements": [
                "chisel:technical@13"
            ]
        },
        {
            "x": 0,
            "y": 10,
            "z": -1,
            "elements": [
                "appliedenergistics2:sky_stone_small_brick@0"
            ]
        },
        {
            "x": 0,
            "y": 13,
            "z": 6,
            "elements": [
                "appliedenergistics2:sky_stone_small_brick_slab@0"
            ]
        },
        {
            "x": -1,
            "y": -1,
            "z": 4,
            "elements": [
                "chisel:planks-oak@12"
            ]
        },
        {
            "x": 3,
            "y": 10,
            "z": 8,
            "elements": [
                "enderio:block_dark_iron_bars@0"
            ]
        },
        {
            "x": -1,
            "y": 7,
            "z": 12,
            "elements": [
                "enderio:block_alloy@9"
            ]
        },
        {
            "x": -2,
            "y": 1,
            "z": 9,
            "elements": [
                "chisel:technicalnew@2"
            ]
        },
        {
            "x": 1,
            "y": 9,
            "z": 9,
            "elements": [
                "appliedenergistics2:sky_stone_small_brick_slab@8"
            ]
        },
        {
            "x": 0,
            "y": 8,
            "z": 7,
            "elements": [
                "enderio:block_dark_iron_bars@0"
            ]
        },
        {
            "x": 0,
            "y": 6,
            "z": 7,
            "elements": [
                "enderio:block_dark_iron_bars@0"
            ]
        },
        {
            "x": -1,
            "y": 4,
            "z": 12,
            "elements": [
                "thermalfoundation:storage_alloy@0"
            ]
        },
        {
            "x": 3,
            "y": 11,
            "z": 8,
            "elements": [
                "enderio:block_dark_iron_bars@0"
            ]
        },
        {
            "x": -3,
            "y": 8,
            "z": 5,
            "elements": [
                "chisel:technical@4"
            ]
        },
        {
            "x": -2,
            "y": 9,
            "z": 16,
            "elements": [
                "appliedenergistics2:sky_stone_small_brick_stairs@6"
            ]
        },
        {
            "x": 0,
            "y": 9,
            "z": -1,
            "elements": [
                "enderio:block_dark_iron_bars@0"
            ]
        },
        {
            "x": 2,
            "y": 2,
            "z": 0,
            "elements": [
                "appliedenergistics2:sky_stone_small_brick@0"
            ]
        },
        {
            "x": 3,
            "y": 1,
            "z": 4,
            "elements": [
                "appliedenergistics2:sky_stone_small_brick@0"
            ]
        },
        {
            "x": 2,
            "y": 0,
            "z": 5,
            "elements": [
                "appliedenergistics2:sky_stone_small_brick@0"
            ]
        },
        {
            "x": -1,
            "y": 5,
            "z": 12,
            "elements": [
                "thermalfoundation:storage_alloy@0"
            ]
        },
        {
            "x": 0,
            "y": 7,
            "z": 7,
            "elements": [
                "enderio:block_dark_iron_bars@0"
            ]
        },
        {
            "x": 0,
            "y": 8,
            "z": -1,
            "elements": [
                "enderio:block_dark_iron_bars@0"
            ]
        },
        {
            "x": -3,
            "y": 10,
            "z": 5,
            "elements": [
                "chisel:technical@4"
            ]
        },
        {
            "x": 3,
            "y": 12,
            "z": 8,
            "elements": [
                "enderio:block_dark_iron_bars@0"
            ]
        },
        {
            "x": -2,
            "y": 0,
            "z": 0,
            "elements": [
                "twilightforest:magic_log@2"
            ]
        },
        {
            "x": -2,
            "y": 0,
            "z": 15,
            "elements": [
                "chisel:technicalnew@2"
            ]
        },
        {
            "x": 4,
            "y": 1,
            "z": 9,
            "elements": [
                "chisel:technicalnew@2"
            ]
        },
        {
            "x": 0,
            "y": 9,
            "z": 6,
            "elements": [
                "appliedenergistics2:sky_stone_small_brick_stairs@2"
            ]
        },
        {
            "x": 0,
            "y": 4,
            "z": 7,
            "elements": [
                "enderio:block_dark_iron_bars@0"
            ]
        },
        {
            "x": 0,
            "y": 6,
            "z": -1,
            "elements": [
                "enderio:block_dark_iron_bars@0"
            ]
        },
        {
            "x": -1,
            "y": 3,
            "z": 12,
            "elements": [
                "thermalfoundation:storage_alloy@0"
            ]
        },
        {
            "x": -1,
            "y": 2,
            "z": 5,
            "elements": [
                "tconstruct:seared_slab@3"
            ]
        },
        {
            "x": 0,
            "y": 5,
            "z": 7,
            "elements": [
                "enderio:block_dark_iron_bars@0"
            ]
        },
        {
            "x": 0,
            "y": 7,
            "z": -1,
            "elements": [
                "enderio:block_dark_iron_bars@0"
            ]
        },
        {
            "x": 2,
            "y": 8,
            "z": 0,
            "elements": [
                "chisel:technical@13"
            ]
        },
        {
            "x": 0,
            "y": 4,
            "z": -1,
            "elements": [
                "enderio:block_dark_iron_bars@0"
            ]
        },
        {
            "x": -3,
            "y": 0,
            "z": 15,
            "elements": [
                "chisel:technicalnew@2"
            ]
        },
        {
            "x": 0,
            "y": 2,
            "z": 7,
            "elements": [
                "appliedenergistics2:sky_stone_small_brick@0"
            ]
        },
        {
            "x": 0,
            "y": 12,
            "z": 3,
            "elements": [
                "appliedenergistics2:sky_stone_small_brick_slab@0"
            ]
        },
        {
            "x": 2,
            "y": 6,
            "z": 0,
            "elements": [
                "chisel:technical@13"
            ]
        },
        {
            "x": -3,
            "y": 0,
            "z": 10,
            "elements": [
                "chisel:technicalnew@2"
            ]
        },
        {
            "x": 0,
            "y": 3,
            "z": 7,
            "elements": [
                "enderio:block_dark_iron_bars@0"
            ]
        },
        {
            "x": 0,
            "y": 5,
            "z": -1,
            "elements": [
                "enderio:block_dark_iron_bars@0"
            ]
        },
        {
            "x": 3,
            "y": 6,
            "z": 5,
            "elements": [
                "chisel:technical@4"
            ]
        },
        {
            "x": 0,
            "y": 9,
            "z": 11,
            "elements": [
                "enderio:block_dark_iron_bars@0"
            ]
        },
        {
            "x": -1,
            "y": 13,
            "z": 12,
            "elements": [
                "thermalfoundation:glass@0"
            ]
        },
        {
            "x": 4,
            "y": 2,
            "z": 3,
            "elements": [
                "appliedenergistics2:sky_stone_small_brick@0"
            ]
        },
        {
            "x": -4,
            "y": -1,
            "z": 9,
            "elements": [
                "chisel:factory@6"
            ]
        },
        {
            "x": 3,
            "y": 13,
            "z": 14,
            "elements": [
                "thermalfoundation:glass@0"
            ]
        },
        {
            "x": -3,
            "y": -1,
            "z": 16,
            "elements": [
                "chisel:factory@6"
            ]
        },
        {
            "x": 0,
            "y": 13,
            "z": 13,
            "elements": [
                "thermalfoundation:glass@0"
            ]
        },
        {
            "x": -1,
            "y": 12,
            "z": 5,
            "elements": [
                "appliedenergistics2:sky_stone_small_brick_slab@0"
            ]
        },
        {
            "x": 3,
            "y": 0,
            "z": 8,
            "elements": [
                "chisel:technicalnew@2"
            ]
        },
        {
            "x": -4,
            "y": 12,
            "z": 15,
            "elements": [
                "enderio:block_dark_iron_bars@0"
            ]
        },
        {
            "x": 3,
            "y": 4,
            "z": 5,
            "elements": [
                "chisel:technical@4"
            ]
        },
        {
            "x": -3,
            "y": 1,
            "z": 8,
            "elements": [
                "chisel:technicalnew@2"
            ]
        },
        {
            "x": 0,
            "y": 11,
            "z": 11,
            "elements": [
                "additions:ignite_block@0"
            ]
        },
        {
            "x": 3,
            "y": 9,
            "z": 11,
            "elements": [
                "appliedenergistics2:sky_stone_small_brick_slab@8"
            ]
        },
        {
            "x": -3,
            "y": 13,
            "z": 11,
            "elements": [
                "thermalfoundation:glass@0"
            ]
        },
        {
            "x": 0,
            "y": 11,
            "z": 13,
            "elements": [
                "additions:aqualite_block@0"
            ]
        },
        {
            "x": 3,
            "y": 9,
            "z": 13,
            "elements": [
                "appliedenergistics2:sky_stone_small_brick_slab@8"
            ]
        },
        {
            "x": -3,
            "y": 13,
            "z": 13,
            "elements": [
                "thermalfoundation:glass@0"
            ]
        },
        {
            "x": 0,
            "y": 13,
            "z": 11,
            "elements": [
                "thermalfoundation:glass@0"
            ]
        },
        {
            "x": 3,
            "y": 0,
            "z": 10,
            "elements": [
                "chisel:technicalnew@2"
            ]
        },
        {
            "x": 2,
            "y": 11,
            "z": 12,
            "elements": [
                "thermalfoundation:storage_alloy@5"
            ]
        },
        {
            "x": 0,
            "y": 12,
            "z": 14,
            "elements": [
                "thermalfoundation:storage_alloy@5"
            ]
        },
        {
            "x": -4,
            "y": 5,
            "z": 4,
            "elements": [
                "appliedenergistics2:sky_stone_brick@0"
            ]
        },
        {
            "x": -3,
            "y": 3,
            "z": 9,
            "elements": [
                "chisel:technicalnew@2"
            ]
        },
        {
            "x": 3,
            "y": 9,
            "z": 14,
            "elements": [
                "appliedenergistics2:sky_stone_small_brick_slab@8"
            ]
        },
        {
            "x": 0,
            "y": 12,
            "z": 10,
            "elements": [
                "thermalfoundation:storage_alloy@5"
            ]
        },
        {
            "x": 3,
            "y": 2,
            "z": 5,
            "elements": [
                "appliedenergistics2:sky_stone_small_brick@0"
            ]
        },
        {
            "x": 3,
            "y": 0,
            "z": 5,
            "elements": [
                "twilightforest:magic_log@2"
            ]
        },
        {
            "x": 0,
            "y": 9,
            "z": 13,
            "elements": [
                "enderio:block_dark_iron_bars@0"
            ]
        },
        {
            "x": 2,
            "y": 10,
            "z": 12,
            "elements": [
                "thermalfoundation:storage_alloy@5"
            ]
        },
        {
            "x": -3,
            "y": -1,
            "z": 4,
            "elements": [
                "appliedenergistics2:sky_stone_small_brick@0"
            ]
        },
        {
            "x": 0,
            "y": 11,
            "z": 14,
            "elements": [
                "thermalfoundation:storage_alloy@5"
            ]
        },
        {
            "x": -4,
            "y": 13,
            "z": 12,
            "elements": [
                "chisel:blockgold@0"
            ]
        },
        {
            "x": -1,
            "y": 11,
            "z": 12,
            "elements": [
                "additions:asgardium_block@0"
            ]
        },
        {
            "x": 2,
            "y": 9,
            "z": 12,
            "elements": [
                "enderio:block_alloy@6"
            ]
        },
        {
            "x": 0,
            "y": 7,
            "z": 13,
            "elements": [
                "enderio:block_alloy@9"
            ]
        },
        {
            "x": 0,
            "y": 10,
            "z": 10,
            "elements": [
                "thermalfoundation:storage_alloy@5"
            ]
        },
        {
            "x": -1,
            "y": 8,
            "z": 12,
            "elements": [
                "enderio:block_dark_iron_bars@0"
            ]
        },
        {
            "x": -3,
            "y": 1,
            "z": 4,
            "elements": [
                "appliedenergistics2:sky_stone_small_brick@0"
            ]
        },
        {
            "x": -4,
            "y": 3,
            "z": 4,
            "elements": [
                "appliedenergistics2:sky_stone_brick@0"
            ]
        },
        {
            "x": 0,
            "y": 13,
            "z": 14,
            "elements": [
                "thermalfoundation:glass@0"
            ]
        },
        {
            "x": -4,
            "y": 12,
            "z": 12,
            "elements": [
                "appliedenergistics2:sky_stone_small_brick@0"
            ]
        },
        {
            "x": -3,
            "y": -1,
            "z": 9,
            "elements": [
                "chisel:technicalnew@2"
            ]
        },
        {
            "x": 0,
            "y": 8,
            "z": 13,
            "elements": [
                "enderio:block_dark_iron_bars@0"
            ]
        },
        {
            "x": -2,
            "y": -1,
            "z": 4,
            "elements": [
                "chisel:planks-oak@12"
            ]
        },
        {
            "x": -3,
            "y": 1,
            "z": 9,
            "elements": [
                "chisel:technicalnew@2"
            ]
        },
        {
            "x": -1,
            "y": 9,
            "z": 12,
            "elements": [
                "enderio:block_dark_iron_bars@0"
            ]
        },
        {
            "x": -4,
            "y": 10,
            "z": 15,
            "elements": [
                "enderio:block_dark_iron_bars@0"
            ]
        },
        {
            "x": -4,
            "y": 0,
            "z": 15,
            "elements": [
                "chisel:technicalnew@2"
            ]
        },
        {
            "x": 3,
            "y": 10,
            "z": 1,
            "elements": [
                "chisel:technical@13"
            ]
        },
        {
            "x": -3,
            "y": 7,
            "z": 9,
            "elements": [
                "chisel:technicalnew@2"
            ]
        },
        {
            "x": 3,
            "y": 13,
            "z": 12,
            "elements": [
                "thermalfoundation:glass@0"
            ]
        },
        {
            "x": 2,
            "y": 9,
            "z": 13,
            "elements": [
                "additions:manganese_steel_block@0"
            ]
        },
        {
            "x": 0,
            "y": 13,
            "z": 8,
            "elements": [
                "chisel:blockgold@0"
            ]
        },
        {
            "x": -4,
            "y": 9,
            "z": 4,
            "elements": [
                "appliedenergistics2:sky_stone_brick@0"
            ]
        },
        {
            "x": 0,
            "y": 0,
            "z": 3,
            "elements": [
                "actuallyadditions:block_misc@2"
            ]
        },
        {
            "x": 0,
            "y": 9,
            "z": 8,
            "elements": [
                "appliedenergistics2:sky_stone_small_brick_stairs@7"
            ]
        },
        {
            "x": 3,
            "y": 11,
            "z": 1,
            "elements": [
                "appliedenergistics2:sky_stone_small_brick_slab@0"
            ]
        },
        {
            "x": 2,
            "y": 10,
            "z": 13,
            "elements": [
                "tconstruct:clear_glass@0"
            ]
        },
        {
            "x": -4,
            "y": 10,
            "z": 3,
            "elements": [
                "appliedenergistics2:sky_stone_small_brick@0"
            ]
        },
        {
            "x": 3,
            "y": 8,
            "z": 1,
            "elements": [
                "chisel:technical@13"
            ]
        },
        {
            "x": -3,
            "y": 5,
            "z": 9,
            "elements": [
                "chisel:technicalnew@2"
            ]
        },
        {
            "x": -4,
            "y": 8,
            "z": 3,
            "elements": [
                "enderio:block_dark_iron_bars@0"
            ]
        },
        {
            "x": 2,
            "y": 3,
            "z": 4,
            "elements": [
                "tconstruct:seared_slab@3"
            ]
        },
        {
            "x": -3,
            "y": 10,
            "z": 8,
            "elements": [
                "enderio:block_dark_iron_bars@0"
            ]
        },
        {
            "x": 2,
            "y": 13,
            "z": 12,
            "elements": [
                "thermalfoundation:glass@0"
            ]
        },
        {
            "x": 0,
            "y": 10,
            "z": 14,
            "elements": [
                "thermalfoundation:storage_alloy@5"
            ]
        },
        {
            "x": 2,
            "y": 12,
            "z": 5,
            "elements": [
                "appliedenergistics2:sky_stone_small_brick_slab@0"
            ]
        },
        {
            "x": 0,
            "y": 2,
            "z": 3,
            "elements": [
                "actuallyadditions:block_misc@2"
            ]
        },
        {
            "x": 0,
            "y": 9,
            "z": 14,
            "elements": [
                "enderio:block_alloy@6"
            ]
        },
        {
            "x": -4,
            "y": 7,
            "z": 4,
            "elements": [
                "appliedenergistics2:sky_stone_brick@0"
            ]
        },
        {
            "x": 3,
            "y": 9,
            "z": 1,
            "elements": [
                "chisel:technical@13"
            ]
        },
        {
            "x": 2,
            "y": 0,
            "z": 15,
            "elements": [
                "chisel:technicalnew@2"
            ]
        },
        {
            "x": -2,
            "y": 10,
            "z": 0,
            "elements": [
                "chisel:technical@13"
            ]
        },
        {
            "x": -3,
            "y": 0,
            "z": 3,
            "elements": [
                "casings_upgrade"
            ]
        },
        {
            "x": 0,
            "y": 3,
            "z": 11,
            "elements": [
                "thermalfoundation:storage_alloy@0"
            ]
        },
        {
            "x": 2,
            "y": 12,
            "z": 12,
            "elements": [
                "thermalfoundation:storage_alloy@5"
            ]
        },
        {
            "x": -3,
            "y": 9,
            "z": 8,
            "elements": [
                "enderio:block_dark_iron_bars@0"
            ]
        },
        {
            "x": -4,
            "y": 6,
            "z": 3,
            "elements": [
                "enderio:block_dark_iron_bars@0"
            ]
        },
        {
            "x": 3,
            "y": 9,
            "z": 12,
            "elements": [
                "appliedenergistics2:sky_stone_small_brick_slab@8"
            ]
        },
        {
            "x": 0,
            "y": -1,
            "z": 4,
            "elements": [
                "chisel:planks-oak@12"
            ]
        },
        {
            "x": 3,
            "y": 0,
            "z": 14,
            "elements": [
                "chisel:technicalnew@2"
            ]
        },
        {
            "x": 2,
            "y": 13,
            "z": 13,
            "elements": [
                "thermalfoundation:glass@0"
            ]
        },
        {
            "x": 0,
            "y": 5,
            "z": 11,
            "elements": [
                "thermalfoundation:storage_alloy@0"
            ]
        },
        {
            "x": -4,
            "y": 1,
            "z": 9,
            "elements": [
                "chisel:technicalnew@2"
            ]
        },
        {
            "x": -2,
            "y": -1,
            "z": 9,
            "elements": [
                "chisel:factory@6"
            ]
        },
        {
            "x": 2,
            "y": 12,
            "z": 13,
            "elements": [
                "tconstruct:clear_glass@0"
            ]
        },
        {
            "x": -3,
            "y": 11,
            "z": 8,
            "elements": [
                "enderio:block_dark_iron_bars@0"
            ]
        },
        {
            "x": 1,
            "y": -1,
            "z": 4,
            "elements": [
                "chisel:planks-oak@12"
            ]
        },
        {
            "x": 2,
            "y": 11,
            "z": 13,
            "elements": [
                "tconstruct:clear_glass@0"
            ]
        },
        {
            "x": -4,
            "y": 4,
            "z": 3,
            "elements": [
                "enderio:block_dark_iron_bars@0"
            ]
        },
        {
            "x": -3,
            "y": 9,
            "z": 11,
            "elements": [
                "appliedenergistics2:sky_stone_small_brick_slab@8"
            ]
        },
        {
            "x": 0,
            "y": 13,
            "z": 12,
            "elements": [
                "thermalfoundation:glass@0"
            ]
        },
        {
            "x": 3,
            "y": 1,
            "z": 8,
            "elements": [
                "chisel:technicalnew@2"
            ]
        },
        {
            "x": 0,
            "y": 7,
            "z": 11,
            "elements": [
                "enderio:block_alloy@9"
            ]
        },
        {
            "x": 3,
            "y": 13,
            "z": 13,
            "elements": [
                "thermalfoundation:glass@0"
            ]
        },
        {
            "x": -3,
            "y": 12,
            "z": 8,
            "elements": [
                "enderio:block_dark_iron_bars@0"
            ]
        },
        {
            "x": 3,
            "y": 1,
            "z": 14,
            "elements": [
                "chisel:technicalnew@2"
            ]
        },
        {
            "x": 0,
            "y": 12,
            "z": 12,
            "elements": [
                "additions:stainless_steel_block@0"
            ]
        },
        {
            "x": 1,
            "y": 6,
            "z": 11,
            "elements": [
                "enderio:block_alloy@9"
            ]
        },
        {
            "x": 0,
            "y": 11,
            "z": 12,
            "elements": [
                "additions:balancite_block@0"
            ]
        },
        {
            "x": 2,
            "y": 2,
            "z": 6,
            "elements": [
                "appliedenergistics2:sky_stone_small_brick@0"
            ]
        },
        {
            "x": 1,
            "y": 9,
            "z": -1,
            "elements": [
                "appliedenergistics2:sky_stone_brick@0"
            ]
        },
        {
            "x": 3,
            "y": 3,
            "z": 9,
            "elements": [
                "chisel:technicalnew@2"
            ]
        },
        {
            "x": 3,
            "y": 0,
            "z": 16,
            "elements": [
                "chisel:technicalnew@2"
            ]
        },
        {
            "x": 1,
            "y": 7,
            "z": 11,
            "elements": [
                "enderio:block_alloy@9"
            ]
        },
        {
            "x": -3,
            "y": 10,
            "z": 9,
            "elements": [
                "appliedenergistics2:sky_stone_small_brick@0"
            ]
        },
        {
            "x": 4,
            "y": 2,
            "z": 4,
            "elements": [
                "appliedenergistics2:sky_stone_small_brick@0"
            ]
        },
        {
            "x": 2,
            "y": 8,
            "z": 6,
            "elements": [
                "chisel:technical@4"
            ]
        },
        {
            "x": 3,
            "y": 1,
            "z": 16,
            "elements": [
                "chisel:technicalnew@2"
            ]
        },
        {
            "x": 3,
            "y": 13,
            "z": 10,
            "elements": [
                "thermalfoundation:glass@0"
            ]
        },
        {
            "x": -2,
            "y": 11,
            "z": 2,
            "elements": [
                "appliedenergistics2:sky_stone_small_brick@0"
            ]
        },
        {
            "x": -3,
            "y": 9,
            "z": 9,
            "elements": [
                "chisel:technicalnew@2"
            ]
        },
        {
            "x": -1,
            "y": 3,
            "z": 7,
            "elements": [
                "appliedenergistics2:sky_stone_brick@0"
            ]
        },
        {
            "x": 3,
            "y": 4,
            "z": 9,
            "elements": [
                "chisel:technicalnew@2"
            ]
        },
        {
            "x": -3,
            "y": 12,
            "z": 9,
            "elements": [
                "appliedenergistics2:sky_stone_small_brick@0"
            ]
        },
        {
            "x": 3,
            "y": 1,
            "z": 9,
            "elements": [
                "chisel:technicalnew@2"
            ]
        },
        {
            "x": 3,
            "y": -1,
            "z": 4,
            "elements": [
                "appliedenergistics2:sky_stone_small_brick@0"
            ]
        },
        {
            "x": 3,
            "y": 1,
            "z": 2,
            "elements": [
                "appliedenergistics2:sky_stone_small_brick@0"
            ]
        },
        {
            "x": -4,
            "y": 9,
            "z": 14,
            "elements": [
                "appliedenergistics2:sky_stone_small_brick_stairs@5"
            ]
        },
        {
            "x": 3,
            "y": 2,
            "z": 9,
            "elements": [
                "chisel:technicalnew@2"
            ]
        },
        {
            "x": -3,
            "y": 11,
            "z": 9,
            "elements": [
                "thermalfoundation:storage_alloy@6"
            ]
        },
        {
            "x": -2,
            "y": 9,
            "z": 2,
            "elements": [
                "tconstruct:seared_slab@3"
            ]
        },
        {
            "x": -3,
            "y": 11,
            "z": 2,
            "elements": [
                "appliedenergistics2:sky_stone_small_brick_slab@0"
            ]
        },
        {
            "x": -1,
            "y": 5,
            "z": 7,
            "elements": [
                "appliedenergistics2:sky_stone_brick@0"
            ]
        },
        {
            "x": 4,
            "y": 13,
            "z": 10,
            "elements": [
                "chisel:blockgold@0"
            ]
        },
        {
            "x": 2,
            "y": 6,
            "z": 6,
            "elements": [
                "chisel:technical@4"
            ]
        },
        {
            "x": -3,
            "y": 0,
            "z": 16,
            "elements": [
                "chisel:technicalnew@2"
            ]
        },
        {
            "x": -3,
            "y": 10,
            "z": 16,
            "elements": [
                "enderio:block_dark_iron_bars@0"
            ]
        },
        {
            "x": 3,
            "y": 0,
            "z": 9,
            "elements": [
                "chisel:technicalnew@2"
            ]
        },
        {
            "x": 0,
            "y": 1,
            "z": 12,
            "elements": [
                "chisel:diamond@5"
            ]
        },
        {
            "x": 2,
            "y": 12,
            "z": 6,
            "elements": [
                "appliedenergistics2:sky_stone_small_brick_slab@0"
            ]
        },
        {
            "x": 2,
            "y": -1,
            "z": 2,
            "elements": [
                "chisel:planks-oak@12"
            ]
        },
        {
            "x": 4,
            "y": 6,
            "z": 4,
            "elements": [
                "appliedenergistics2:sky_stone_small_brick@0"
            ]
        },
        {
            "x": -3,
            "y": 1,
            "z": 16,
            "elements": [
                "chisel:technicalnew@2"
            ]
        },
        {
            "x": -3,
            "y": 11,
            "z": 16,
            "elements": [
                "enderio:block_dark_iron_bars@0"
            ]
        },
        {
            "x": 2,
            "y": -1,
            "z": 9,
            "elements": [
                "chisel:factory@6"
            ]
        },
        {
            "x": 3,
            "y": 9,
            "z": 10,
            "elements": [
                "appliedenergistics2:sky_stone_small_brick_slab@8"
            ]
        },
        {
            "x": 0,
            "y": 9,
            "z": 16,
            "elements": [
                "appliedenergistics2:sky_stone_small_brick_stairs@6"
            ]
        },
        {
            "x": 4,
            "y": 5,
            "z": 4,
            "elements": [
                "appliedenergistics2:sky_stone_brick@0"
            ]
        },
        {
            "x": 1,
            "y": 8,
            "z": 1,
            "elements": [
                "tconstruct:seared_slab@3"
            ]
        },
        {
            "x": 4,
            "y": 3,
            "z": 4,
            "elements": [
                "appliedenergistics2:sky_stone_brick@0"
            ]
        },
        {
            "x": 1,
            "y": 9,
            "z": 11,
            "elements": [
                "additions:manganese_steel_block@0"
            ]
        },
        {
            "x": 2,
            "y": 0,
            "z": 6,
            "elements": [
                "twilightforest:magic_log@2"
            ]
        },
        {
            "x": -3,
            "y": 12,
            "z": 16,
            "elements": [
                "enderio:block_dark_iron_bars@0"
            ]
        },
        {
            "x": -3,
            "y": 8,
            "z": 9,
            "elements": [
                "chisel:technicalnew@2"
            ]
        },
        {
            "x": 4,
            "y": 4,
            "z": 4,
            "elements": [
                "appliedenergistics2:sky_stone_small_brick@0"
            ]
        },
        {
            "x": -3,
            "y": 1,
            "z": 2,
            "elements": [
                "appliedenergistics2:sky_stone_small_brick@0"
            ]
        },
        {
            "x": 2,
            "y": 10,
            "z": 6,
            "elements": [
                "chisel:technical@4"
            ]
        },
        {
            "x": -2,
            "y": 13,
            "z": 11,
            "elements": [
                "thermalfoundation:glass@0"
            ]
        },
        {
            "x": 1,
            "y": 8,
            "z": 11,
            "elements": [
                "enderio:block_alloy@9"
            ]
        },
        {
            "x": -4,
            "y": 5,
            "z": 2,
            "elements": [
                "appliedenergistics2:sky_stone_brick@0"
            ]
        },
        {
            "x": 1,
            "y": 9,
            "z": 10,
            "elements": [
                "additions:manganese_steel_block@0"
            ]
        },
        {
            "x": 4,
            "y": 9,
            "z": 11,
            "elements": [
                "appliedenergistics2:sky_stone_small_brick_stairs@4"
            ]
        },
        {
            "x": 4,
            "y": 9,
            "z": 3,
            "elements": [
                "enderio:block_dark_iron_bars@0"
            ]
        },
        {
            "x": 1,
            "y": 10,
            "z": 10,
            "elements": [
                "tconstruct:clear_glass@0"
            ]
        },
        {
            "x": 1,
            "y": 12,
            "z": 3,
            "elements": [
                "appliedenergistics2:sky_stone_small_brick_slab@0"
            ]
        },
        {
            "x": -2,
            "y": 1,
            "z": 2,
            "elements": [
                "tconstruct:seared_slab@3"
            ]
        },
        {
            "x": 1,
            "y": 7,
            "z": 7,
            "elements": [
                "appliedenergistics2:sky_stone_brick@0"
            ]
        },
        {
            "x": 1,
            "y": 0,
            "z": 1,
            "elements": [
                "tconstruct:seared_slab@3"
            ]
        },
        {
            "x": 0,
            "y": -1,
            "z": 2,
            "elements": [
                "chisel:planks-oak@12"
            ]
        },
        {
            "x": -1,
            "y": 8,
            "z": 13,
            "elements": [
                "enderio:block_alloy@9"
            ]
        },
        {
            "x": -1,
            "y": 13,
            "z": 14,
            "elements": [
                "thermalfoundation:glass@0"
            ]
        },
        {
            "x": 4,
            "y": 10,
            "z": 3,
            "elements": [
                "appliedenergistics2:sky_stone_small_brick@0"
            ]
        },
        {
            "x": -4,
            "y": 7,
            "z": 2,
            "elements": [
                "appliedenergistics2:sky_stone_brick@0"
            ]
        },
        {
            "x": 4,
            "y": 9,
            "z": 4,
            "elements": [
                "appliedenergistics2:sky_stone_brick@0"
            ]
        },
        {
            "x": 1,
            "y": 13,
            "z": 11,
            "elements": [
                "thermalfoundation:glass@0"
            ]
        },
        {
            "x": 1,
            "y": 12,
            "z": 10,
            "elements": [
                "tconstruct:clear_glass@0"
            ]
        },
        {
            "x": -1,
            "y": 13,
            "z": 7,
            "elements": [
                "appliedenergistics2:sky_stone_small_brick_slab@0"
            ]
        },
        {
            "x": -2,
            "y": 11,
            "z": 7,
            "elements": [
                "appliedenergistics2:sky_stone_small_brick@0"
            ]
        },
        {
            "x": 1,
            "y": 11,
            "z": 4,
            "elements": [
                "appliedenergistics2:sky_stone_small_brick@0"
            ]
        },
        {
            "x": 4,
            "y": 8,
            "z": 4,
            "elements": [
                "appliedenergistics2:sky_stone_small_brick@0"
            ]
        },
        {
            "x": 1,
            "y": 9,
            "z": 7,
            "elements": [
                "appliedenergistics2:sky_stone_brick@0"
            ]
        },
        {
            "x": 4,
            "y": 12,
            "z": 11,
            "elements": [
                "appliedenergistics2:sky_stone_small_brick@0"
            ]
        },
        {
            "x": 4,
            "y": 7,
            "z": 3,
            "elements": [
                "enderio:block_dark_iron_bars@0"
            ]
        },
        {
            "x": 1,
            "y": 12,
            "z": 4,
            "elements": [
                "appliedenergistics2:sky_stone_small_brick_slab@0"
            ]
        },
        {
            "x": 4,
            "y": 10,
            "z": 11,
            "elements": [
                "appliedenergistics2:sky_stone_small_brick@0"
            ]
        },
        {
            "x": -1,
            "y": -1,
            "z": 2,
            "elements": [
                "chisel:planks-oak@12"
            ]
        },
        {
            "x": -4,
            "y": 12,
            "z": 13,
            "elements": [
                "appliedenergistics2:sky_stone_small_brick@0"
            ]
        },
        {
            "x": -1,
            "y": 11,
            "z": 14,
            "elements": [
                "tconstruct:clear_glass@0"
            ]
        },
        {
            "x": -3,
            "y": 9,
            "z": 12,
            "elements": [
                "appliedenergistics2:sky_stone_small_brick_slab@8"
            ]
        },
        {
            "x": 4,
            "y": 8,
            "z": 3,
            "elements": [
                "enderio:block_dark_iron_bars@0"
            ]
        },
        {
            "x": -2,
            "y": 11,
            "z": 4,
            "elements": [
                "appliedenergistics2:sky_stone_small_brick@0"
            ]
        },
        {
            "x": 4,
            "y": 7,
            "z": 4,
            "elements": [
                "appliedenergistics2:sky_stone_brick@0"
            ]
        },
        {
            "x": 1,
            "y": 11,
            "z": 10,
            "elements": [
                "tconstruct:clear_glass@0"
            ]
        },
        {
            "x": 4,
            "y": 13,
            "z": 11,
            "elements": [
                "chisel:blockgold@0"
            ]
        },
        {
            "x": 4,
            "y": 6,
            "z": 3,
            "elements": [
                "enderio:block_dark_iron_bars@0"
            ]
        },
        {
            "x": -3,
            "y": 9,
            "z": 16,
            "elements": [
                "enderio:block_dark_iron_bars@0"
            ]
        },
        {
            "x": 4,
            "y": 12,
            "z": 10,
            "elements": [
                "appliedenergistics2:sky_stone_small_brick@0"
            ]
        },
        {
            "x": 1,
            "y": 4,
            "z": 1,
            "elements": [
                "tconstruct:seared_slab@3"
            ]
        },
        {
            "x": -2,
            "y": 5,
            "z": 2,
            "elements": [
                "tconstruct:seared_slab@3"
            ]
        },
        {
            "x": -1,
            "y": 7,
            "z": 7,
            "elements": [
                "appliedenergistics2:sky_stone_brick@0"
            ]
        },
        {
            "x": -4,
            "y": 10,
            "z": 13,
            "elements": [
                "appliedenergistics2:sky_stone_small_brick@0"
            ]
        },
        {
            "x": -1,
            "y": 6,
            "z": 13,
            "elements": [
                "enderio:block_alloy@9"
            ]
        },
        {
            "x": -3,
            "y": 13,
            "z": 12,
            "elements": [
                "thermalfoundation:glass@0"
            ]
        },
        {
            "x": -1,
            "y": 9,
            "z": 14,
            "elements": [
                "additions:manganese_steel_block@0"
            ]
        },
        {
            "x": 0,
            "y": 4,
            "z": 13,
            "elements": [
                "thermalfoundation:storage_alloy@0"
            ]
        },
        {
            "x": 4,
            "y": 11,
            "z": 10,
            "elements": [
                "mca:rose_gold_block@0"
            ]
        },
        {
            "x": -3,
            "y": 0,
            "z": 8,
            "elements": [
                "chisel:technicalnew@2"
            ]
        },
        {
            "x": 1,
            "y": 7,
            "z": 3,
            "elements": [
                "tconstruct:seared_slab@3"
            ]
        },
        {
            "x": -2,
            "y": -1,
            "z": 2,
            "elements": [
                "chisel:planks-oak@12"
            ]
        },
        {
            "x": 1,
            "y": 13,
            "z": 10,
            "elements": [
                "thermalfoundation:glass@0"
            ]
        },
        {
            "x": 4,
            "y": 5,
            "z": 3,
            "elements": [
                "enderio:block_dark_iron_bars@0"
            ]
        },
        {
            "x": 4,
            "y": 11,
            "z": 11,
            "elements": [
                "thermalfoundation:storage@5"
            ]
        },
        {
            "x": 2,
            "y": 4,
            "z": 6,
            "elements": [
                "chisel:technical@4"
            ]
        },
        {
            "x": -4,
            "y": 11,
            "z": 14,
            "elements": [
                "mca:rose_gold_block@0"
            ]
        },
        {
            "x": 4,
            "y": 4,
            "z": 3,
            "elements": [
                "enderio:block_dark_iron_bars@0"
            ]
        },
        {
            "x": -1,
            "y": 12,
            "z": 6,
            "elements": [
                "appliedenergistics2:sky_stone_small_brick@0"
            ]
        },
        {
            "x": -4,
            "y": 3,
            "z": 2,
            "elements": [
                "appliedenergistics2:sky_stone_brick@0"
            ]
        },
        {
            "x": -1,
            "y": 9,
            "z": 7,
            "elements": [
                "appliedenergistics2:sky_stone_brick@0"
            ]
        },
        {
            "x": 0,
            "y": 6,
            "z": 13,
            "elements": [
                "enderio:block_alloy@9"
            ]
        },
        {
            "x": 1,
            "y": -1,
            "z": 2,
            "elements": [
                "chisel:planks-oak@12"
            ]
        },
        {
            "x": 4,
            "y": 10,
            "z": 10,
            "elements": [
                "appliedenergistics2:sky_stone_small_brick@0"
            ]
        },
        {
            "x": 2,
            "y": 9,
            "z": 14,
            "elements": [
                "appliedenergistics2:sky_stone_small_brick_slab@8"
            ]
        },
        {
            "x": -2,
            "y": 13,
            "z": 10,
            "elements": [
                "thermalfoundation:glass@0"
            ]
        },
        {
            "x": -4,
            "y": 13,
            "z": 14,
            "elements": [
                "chisel:blockgold@0"
            ]
        },
        {
            "x": 4,
            "y": 10,
            "z": 4,
            "elements": [
                "appliedenergistics2:sky_stone_small_brick@0"
            ]
        },
        {
            "x": 4,
            "y": 9,
            "z": 10,
            "elements": [
                "appliedenergistics2:sky_stone_small_brick_stairs@4"
            ]
        },
        {
            "x": 1,
            "y": 11,
            "z": 3,
            "elements": [
                "appliedenergistics2:sky_stone_small_brick@0"
            ]
        },
        {
            "x": 4,
            "y": 3,
            "z": 3,
            "elements": [
                "enderio:block_dark_iron_bars@0"
            ]
        },
        {
            "x": -3,
            "y": 0,
            "z": 1,
            "elements": [
                "twilightforest:magic_log@2"
            ]
        },
        {
            "x": -3,
            "y": 6,
            "z": 15,
            "elements": [
                "chisel:technicalnew@2"
            ]
        },
        {
            "x": 3,
            "y": 1,
            "z": 15,
            "elements": [
                "chisel:technicalnew@2"
            ]
        },
        {
            "x": 3,
            "y": 13,
            "z": 9,
            "elements": [
                "chisel:blockgold@0"
            ]
        },
        {
            "x": -3,
            "y": 4,
            "z": 15,
            "elements": [
                "chisel:technicalnew@2"
            ]
        },
        {
            "x": -1,
            "y": 5,
            "z": -1,
            "elements": [
                "appliedenergistics2:sky_stone_brick@0"
            ]
        },
        {
            "x": 2,
            "y": -1,
            "z": 15,
            "elements": [
                "chisel:factory@6"
            ]
        },
        {
            "x": 3,
            "y": 0,
            "z": 15,
            "elements": [
                "chisel:technicalnew@2"
            ]
        },
        {
            "x": 0,
            "y": 3,
            "z": -1,
            "elements": [
                "enderio:block_dark_iron_bars@0"
            ]
        },
        {
            "x": -3,
            "y": 5,
            "z": 15,
            "elements": [
                "chisel:technicalnew@2"
            ]
        },
        {
            "x": 2,
            "y": 9,
            "z": 0,
            "elements": [
                "chisel:technical@13"
            ]
        },
        {
            "x": -2,
            "y": 11,
            "z": 5,
            "elements": [
                "appliedenergistics2:sky_stone_small_brick@0"
            ]
        },
        {
            "x": 0,
            "y": 0,
            "z": 6,
            "elements": [
                "casings_all"
            ]
        },
        {
            "x": -3,
            "y": 3,
            "z": 15,
            "elements": [
                "chisel:technicalnew@2"
            ]
        },
        {
            "x": -3,
            "y": 2,
            "z": 1,
            "elements": [
                "appliedenergistics2:sky_stone_small_brick@0"
            ]
        },
        {
            "x": 3,
            "y": -1,
            "z": 2,
            "elements": [
                "appliedenergistics2:sky_stone_small_brick@0"
            ]
        },
        {
            "x": 2,
            "y": 11,
            "z": 0,
            "elements": [
                "appliedenergistics2:sky_stone_small_brick_slab@0"
            ]
        },
        {
            "x": -2,
            "y": 12,
            "z": 5,
            "elements": [
                "appliedenergistics2:sky_stone_small_brick_slab@0"
            ]
        },
        {
            "x": -1,
            "y": 7,
            "z": -1,
            "elements": [
                "appliedenergistics2:sky_stone_brick@0"
            ]
        },
        {
            "x": -3,
            "y": 2,
            "z": 15,
            "elements": [
                "chisel:technicalnew@2"
            ]
        },
        {
            "x": 2,
            "y": 10,
            "z": 0,
            "elements": [
                "chisel:technical@13"
            ]
        },
        {
            "x": -3,
            "y": 9,
            "z": 15,
            "elements": [
                "chisel:technicalnew@2"
            ]
        },
        {
            "x": 1,
            "y": 11,
            "z": 5,
            "elements": [
                "appliedenergistics2:sky_stone_small_brick@0"
            ]
        },
        {
            "x": 1,
            "y": 13,
            "z": 9,
            "elements": [
                "thermalfoundation:glass@0"
            ]
        },
        {
            "x": 1,
            "y": 12,
            "z": 5,
            "elements": [
                "appliedenergistics2:sky_stone_small_brick_slab@0"
            ]
        },
        {
            "x": 4,
            "y": 11,
            "z": 9,
            "elements": [
                "enderio:block_dark_iron_bars@0"
            ]
        },
        {
            "x": -3,
            "y": 4,
            "z": 1,
            "elements": [
                "chisel:technical@13"
            ]
        },
        {
            "x": 4,
            "y": 12,
            "z": 9,
            "elements": [
                "enderio:block_dark_iron_bars@0"
            ]
        },
        {
            "x": 1,
            "y": 3,
            "z": 7,
            "elements": [
                "appliedenergistics2:sky_stone_brick@0"
            ]
        },
        {
            "x": -4,
            "y": 9,
            "z": 12,
            "elements": [
                "appliedenergistics2:sky_stone_small_brick_stairs@5"
            ]
        },
        {
            "x": -3,
            "y": 10,
            "z": 15,
            "elements": [
                "appliedenergistics2:sky_stone_small_brick@0"
            ]
        },
        {
            "x": -2,
            "y": 0,
            "z": 1,
            "elements": [
                "appliedenergistics2:sky_stone_small_brick@0"
            ]
        },
        {
            "x": -3,
            "y": 7,
            "z": 15,
            "elements": [
                "chisel:technicalnew@2"
            ]
        },
        {
            "x": 4,
            "y": 10,
            "z": 9,
            "elements": [
                "enderio:block_dark_iron_bars@0"
            ]
        },
        {
            "x": -3,
            "y": -1,
            "z": 2,
            "elements": [
                "appliedenergistics2:sky_stone_small_brick@0"
            ]
        },
        {
            "x": 4,
            "y": 9,
            "z": 9,
            "elements": [
                "enderio:block_dark_iron_bars@0"
            ]
        },
        {
            "x": -3,
            "y": 6,
            "z": 1,
            "elements": [
                "chisel:technical@13"
            ]
        },
        {
            "x": -3,
            "y": 8,
            "z": 15,
            "elements": [
                "chisel:technicalnew@2"
            ]
        },
        {
            "x": 1,
            "y": 5,
            "z": 7,
            "elements": [
                "appliedenergistics2:sky_stone_brick@0"
            ]
        },
        {
            "x": -1,
            "y": 3,
            "z": -1,
            "elements": [
                "appliedenergistics2:sky_stone_brick@0"
            ]
        },
        {
            "x": 3,
            "y": 12,
            "z": 15,
            "elements": [
                "appliedenergistics2:sky_stone_small_brick@0"
            ]
        },
        {
            "x": 3,
            "y": 6,
            "z": 9,
            "elements": [
                "chisel:technicalnew@2"
            ]
        },
        {
            "x": 0,
            "y": 12,
            "z": 16,
            "elements": [
                "appliedenergistics2:sky_stone_small_brick@0"
            ]
        },
        {
            "x": 3,
            "y": 9,
            "z": 15,
            "elements": [
                "chisel:technicalnew@2"
            ]
        },
        {
            "x": -1,
            "y": 0,
            "z": 6,
            "elements": [
                "casings_all"
            ]
        },
        {
            "x": 3,
            "y": 10,
            "z": 16,
            "elements": [
                "enderio:block_dark_iron_bars@0"
            ]
        },
        {
            "x": -2,
            "y": 2,
            "z": 6,
            "elements": [
                "appliedenergistics2:sky_stone_small_brick@0"
            ]
        },
        {
            "x": 0,
            "y": 13,
            "z": 15,
            "elements": [
                "thermalfoundation:glass@0"
            ]
        },
        {
            "x": 3,
            "y": 11,
            "z": 15,
            "elements": [
                "thermalfoundation:storage_alloy@6"
            ]
        },
        {
            "x": 4,
            "y": 7,
            "z": 2,
            "elements": [
                "appliedenergistics2:sky_stone_brick@0"
            ]
        },
        {
            "x": 3,
            "y": 4,
            "z": 1,
            "elements": [
                "chisel:technical@13"
            ]
        },
        {
            "x": 0,
            "y": 13,
            "z": 16,
            "elements": [
                "chisel:blockgold@0"
            ]
        },
        {
            "x": -2,
            "y": 12,
            "z": 11,
            "elements": [
                "tconstruct:clear_glass@0"
            ]
        },
        {
            "x": 3,
            "y": 11,
            "z": 16,
            "elements": [
                "enderio:block_dark_iron_bars@0"
            ]
        },
        {
            "x": 3,
            "y": 10,
            "z": 15,
            "elements": [
                "appliedenergistics2:sky_stone_small_brick@0"
            ]
        },
        {
            "x": -3,
            "y": 8,
            "z": 1,
            "elements": [
                "chisel:technical@13"
            ]
        },
        {
            "x": 3,
            "y": 7,
            "z": 15,
            "elements": [
                "chisel:technicalnew@2"
            ]
        },
        {
            "x": 3,
            "y": 12,
            "z": 16,
            "elements": [
                "enderio:block_dark_iron_bars@0"
            ]
        },
        {
            "x": -2,
            "y": 4,
            "z": 6,
            "elements": [
                "chisel:technical@4"
            ]
        },
        {
            "x": -3,
            "y": 11,
            "z": 15,
            "elements": [
                "thermalfoundation:storage_alloy@6"
            ]
        },
        {
            "x": 0,
            "y": 10,
            "z": 16,
            "elements": [
                "appliedenergistics2:sky_stone_small_brick@0"
            ]
        },
        {
            "x": 1,
            "y": 11,
            "z": 2,
            "elements": [
                "appliedenergistics2:sky_stone_small_brick@0"
            ]
        },
        {
            "x": 0,
            "y": 13,
            "z": 9,
            "elements": [
                "thermalfoundation:glass@0"
            ]
        },
        {
            "x": 3,
            "y": 8,
            "z": 9,
            "elements": [
                "chisel:technicalnew@2"
            ]
        },
        {
            "x": 3,
            "y": 13,
            "z": 15,
            "elements": [
                "chisel:blockgold@0"
            ]
        },
        {
            "x": -3,
            "y": 12,
            "z": 15,
            "elements": [
                "appliedenergistics2:sky_stone_small_brick@0"
            ]
        },
        {
            "x": 4,
            "y": 5,
            "z": 2,
            "elements": [
                "appliedenergistics2:sky_stone_brick@0"
            ]
        },
        {
            "x": -3,
            "y": 1,
            "z": 14,
            "elements": [
                "chisel:technicalnew@2"
            ]
        },
        {
            "x": 3,
            "y": 7,
            "z": 9,
            "elements": [
                "chisel:technicalnew@2"
            ]
        },
        {
            "x": 3,
            "y": 6,
            "z": 1,
            "elements": [
                "chisel:technical@13"
            ]
        },
        {
            "x": 0,
            "y": -1,
            "z": 5,
            "elements": [
                "chisel:planks-oak@12"
            ]
        },
        {
            "x": 1,
            "y": 3,
            "z": -1,
            "elements": [
                "appliedenergistics2:sky_stone_brick@0"
            ]
        },
        {
            "x": 0,
            "y": 11,
            "z": 16,
            "elements": [
                "mca:rose_gold_block@0"
            ]
        },
        {
            "x": 3,
            "y": 8,
            "z": 15,
            "elements": [
                "chisel:technicalnew@2"
            ]
        },
        {
            "x": -3,
            "y": 10,
            "z": 1,
            "elements": [
                "chisel:technical@13"
            ]
        },
        {
            "x": -1,
            "y": 9,
            "z": -1,
            "elements": [
                "appliedenergistics2:sky_stone_brick@0"
            ]
        },
        {
            "x": 3,
            "y": 5,
            "z": 15,
            "elements": [
                "chisel:technicalnew@2"
            ]
        },
        {
            "x": 3,
            "y": 10,
            "z": 9,
            "elements": [
                "appliedenergistics2:sky_stone_small_brick@0"
            ]
        },
        {
            "x": 0,
            "y": 11,
            "z": 2,
            "elements": [
                "appliedenergistics2:sky_stone_small_brick@0"
            ]
        },
        {
            "x": -2,
            "y": 10,
            "z": 8,
            "elements": [
                "appliedenergistics2:sky_stone_small_brick@0"
            ]
        },
        {
            "x": -2,
            "y": 9,
            "z": 11,
            "elements": [
                "additions:manganese_steel_block@0"
            ]
        },
        {
            "x": 3,
            "y": 0,
            "z": 1,
            "elements": [
                "twilightforest:magic_log@2"
            ]
        },
        {
            "x": -2,
            "y": 12,
            "z": 8,
            "elements": [
                "appliedenergistics2:sky_stone_small_brick@0"
            ]
        },
        {
            "x": 3,
            "y": 9,
            "z": 9,
            "elements": [
                "chisel:technicalnew@2"
            ]
        },
        {
            "x": -3,
            "y": 13,
            "z": 9,
            "elements": [
                "chisel:blockgold@0"
            ]
        },
        {
            "x": 3,
            "y": 6,
            "z": 15,
            "elements": [
                "chisel:technicalnew@2"
            ]
        },
        {
            "x": 3,
            "y": 4,
            "z": 15,
            "elements": [
                "chisel:technicalnew@2"
            ]
        },
        {
            "x": 3,
            "y": -1,
            "z": 5,
            "elements": [
                "twilightforest:magic_log@2"
            ]
        },
        {
            "x": 1,
            "y": 5,
            "z": -1,
            "elements": [
                "appliedenergistics2:sky_stone_brick@0"
            ]
        },
        {
            "x": 4,
            "y": 3,
            "z": 2,
            "elements": [
                "appliedenergistics2:sky_stone_brick@0"
            ]
        },
        {
            "x": 3,
            "y": 3,
            "z": 15,
            "elements": [
                "chisel:technicalnew@2"
            ]
        },
        {
            "x": -2,
            "y": 11,
            "z": 11,
            "elements": [
                "tconstruct:clear_glass@0"
            ]
        },
        {
            "x": -2,
            "y": 6,
            "z": 5,
            "elements": [
                "tconstruct:seared_slab@3"
            ]
        },
        {
            "x": -2,
            "y": 0,
            "z": 6,
            "elements": [
                "twilightforest:magic_log@2"
            ]
        },
        {
            "x": 3,
            "y": 5,
            "z": 9,
            "elements": [
                "chisel:technicalnew@2"
            ]
        },
        {
            "x": 3,
            "y": 11,
            "z": 2,
            "elements": [
                "appliedenergistics2:sky_stone_small_brick_slab@0"
            ]
        },
        {
            "x": 2,
            "y": 0,
            "z": 1,
            "elements": [
                "appliedenergistics2:sky_stone_small_brick@0"
            ]
        },
        {
            "x": 0,
            "y": 9,
            "z": 15,
            "elements": [
                "appliedenergistics2:sky_stone_small_brick_slab@8"
            ]
        },
        {
            "x": 3,
            "y": 2,
            "z": 15,
            "elements": [
                "chisel:technicalnew@2"
            ]
        },
        {
            "x": 3,
            "y": 2,
            "z": 1,
            "elements": [
                "appliedenergistics2:sky_stone_small_brick@0"
            ]
        },
        {
            "x": 3,
            "y": 11,
            "z": 9,
            "elements": [
                "thermalfoundation:storage_alloy@6"
            ]
        },
        {
            "x": -3,
            "y": 13,
            "z": 15,
            "elements": [
                "chisel:blockgold@0"
            ]
        },
        {
            "x": -2,
            "y": 10,
            "z": 11,
            "elements": [
                "tconstruct:clear_glass@0"
            ]
        },
        {
            "x": 1,
            "y": 7,
            "z": -1,
            "elements": [
                "appliedenergistics2:sky_stone_brick@0"
            ]
        },
        {
            "x": 3,
            "y": 9,
            "z": 16,
            "elements": [
                "enderio:block_dark_iron_bars@0"
            ]
        },
        {
            "x": 3,
            "y": 12,
            "z": 9,
            "elements": [
                "appliedenergistics2:sky_stone_small_brick@0"
            ]
        },
        {
            "x": 0,
            "y": 9,
            "z": 9,
            "elements": [
                "appliedenergistics2:sky_stone_small_brick_slab@8"
            ]
        },
        {
            "x": -2,
            "y": 9,
            "z": 13,
            "elements": [
                "additions:manganese_steel_block@0"
            ]
        },
        {
            "x": 1,
            "y": 9,
            "z": 12,
            "elements": [
                "enderio:block_dark_iron_bars@0"
            ]
        },
        {
            "x": 0,
            "y": 9,
            "z": 3,
            "elements": [
                "actuallyadditions:block_misc@2"
            ]
        },
        {
            "x": 0,
            "y": -1,
            "z": 0,
            "elements": [
                "appliedenergistics2:sky_stone_small_brick@0"
            ]
        },
        {
            "x": 0,
            "y": 12,
            "z": 4,
            "elements": [
                "appliedenergistics2:sky_stone_small_brick@0"
            ]
        },
        {
            "x": -1,
            "y": 1,
            "z": 0,
            "elements": [
                "appliedenergistics2:sky_stone_small_brick@0"
            ]
        },
        {
            "x": -1,
            "y": 11,
            "z": 1,
            "elements": [
                "appliedenergistics2:sky_stone_small_brick@0"
            ]
        },
        {
            "x": 0,
            "y": 11,
            "z": 3,
            "elements": [
                "appliedenergistics2:sky_stone_small_brick@0"
            ]
        },
        {
            "x": -2,
            "y": 3,
            "z": 0,
            "elements": [
                "chisel:technical@13"
            ]
        },
        {
            "x": -3,
            "y": -1,
            "z": 5,
            "elements": [
                "twilightforest:magic_log@2"
            ]
        },
        {
            "x": -3,
            "y": 1,
            "z": 5,
            "elements": [
                "twilightforest:magic_log@2"
            ]
        },
        {
            "x": -2,
            "y": 10,
            "z": 13,
            "elements": [
                "tconstruct:clear_glass@0"
            ]
        },
        {
            "x": 1,
            "y": 11,
            "z": 12,
            "elements": [
                "additions:aeroite_block@0"
            ]
        },
        {
            "x": 1,
            "y": 8,
            "z": 12,
            "elements": [
                "enderio:block_dark_iron_bars@0"
            ]
        },
        {
            "x": 2,
            "y": 4,
            "z": 1,
            "elements": [
                "tconstruct:seared_slab@3"
            ]
        },
        {
            "x": -2,
            "y": 13,
            "z": 12,
            "elements": [
                "thermalfoundation:glass@0"
            ]
        },
        {
            "x": -2,
            "y": 1,
            "z": 0,
            "elements": [
                "twilightforest:magic_log@2"
            ]
        },
        {
            "x": 1,
            "y": -1,
            "z": 0,
            "elements": [
                "appliedenergistics2:sky_stone_small_brick@0"
            ]
        },
        {
            "x": 0,
            "y": 7,
            "z": 3,
            "elements": [
                "actuallyadditions:block_misc@2"
            ]
        },
        {
            "x": -2,
            "y": 12,
            "z": 12,
            "elements": [
                "thermalfoundation:storage_alloy@5"
            ]
        },
        {
            "x": -1,
            "y": 13,
            "z": 8,
            "elements": [
                "chisel:blockgold@0"
            ]
        },
        {
            "x": 1,
            "y": 6,
            "z": 13,
            "elements": [
                "enderio:block_alloy@9"
            ]
        },
        {
            "x": 4,
            "y": 0,
            "z": 9,
            "elements": [
                "chisel:technicalnew@2"
            ]
        },
        {
            "x": -2,
            "y": 1,
            "z": 5,
            "elements": [
                "appliedenergistics2:sky_stone_small_brick@0"
            ]
        },
        {
            "x": 3,
            "y": 11,
            "z": 3,
            "elements": [
                "appliedenergistics2:sky_stone_small_brick@0"
            ]
        },
        {
            "x": 2,
            "y": 8,
            "z": 1,
            "elements": [
                "tconstruct:seared_slab@3"
            ]
        },
        {
            "x": 2,
            "y": 11,
            "z": 8,
            "elements": [
                "mca:rose_gold_block@0"
            ]
        },
        {
            "x": 3,
            "y": 1,
            "z": 3,
            "elements": [
                "appliedenergistics2:sky_stone_small_brick@0"
            ]
        },
        {
            "x": -2,
            "y": 7,
            "z": 0,
            "elements": [
                "chisel:technical@13"
            ]
        },
        {
            "x": -2,
            "y": 12,
            "z": 16,
            "elements": [
                "appliedenergistics2:sky_stone_small_brick@0"
            ]
        },
        {
            "x": 1,
            "y": 7,
            "z": 13,
            "elements": [
                "enderio:block_alloy@9"
            ]
        },
        {
            "x": 1,
            "y": 13,
            "z": 12,
            "elements": [
                "thermalfoundation:glass@0"
            ]
        },
        {
            "x": 1,
            "y": 0,
            "z": 6,
            "elements": [
                "casings_all"
            ]
        },
        {
            "x": 2,
            "y": 13,
            "z": 8,
            "elements": [
                "chisel:blockgold@0"
            ]
        },
        {
            "x": 1,
            "y": 8,
            "z": 13,
            "elements": [
                "enderio:block_alloy@9"
            ]
        },
        {
            "x": -2,
            "y": -1,
            "z": 0,
            "elements": [
                "twilightforest:magic_log@2"
            ]
        },
        {
            "x": 1,
            "y": 1,
            "z": 0,
            "elements": [
                "appliedenergistics2:sky_stone_small_brick@0"
            ]
        },
        {
            "x": -1,
            "y": -1,
            "z": 5,
            "elements": [
                "chisel:planks-oak@12"
            ]
        },
        {
            "x": -2,
            "y": 13,
            "z": 13,
            "elements": [
                "thermalfoundation:glass@0"
            ]
        },
        {
            "x": 0,
            "y": 5,
            "z": 3,
            "elements": [
                "actuallyadditions:block_misc@2"
            ]
        },
        {
            "x": -3,
            "y": 5,
            "z": 5,
            "elements": [
                "chisel:technical@4"
            ]
        },
        {
            "x": 2,
            "y": 9,
            "z": 8,
            "elements": [
                "appliedenergistics2:sky_stone_small_brick_stairs@7"
            ]
        },
        {
            "x": 2,
            "y": 12,
            "z": 8,
            "elements": [
                "appliedenergistics2:sky_stone_small_brick@0"
            ]
        },
        {
            "x": 1,
            "y": 1,
            "z": 6,
            "elements": [
                "appliedenergistics2:sky_stone_small_brick@0"
            ]
        },
        {
            "x": 2,
            "y": -1,
            "z": 3,
            "elements": [
                "chisel:planks-oak@12"
            ]
        },
        {
            "x": 4,
            "y": 13,
            "z": 12,
            "elements": [
                "chisel:blockgold@0"
            ]
        },
        {
            "x": -2,
            "y": 11,
            "z": 13,
            "elements": [
                "tconstruct:clear_glass@0"
            ]
        },
        {
            "x": 1,
            "y": 9,
            "z": 13,
            "elements": [
                "additions:manganese_steel_block@0"
            ]
        },
        {
            "x": -2,
            "y": 9,
            "z": 14,
            "elements": [
                "appliedenergistics2:sky_stone_small_brick_slab@8"
            ]
        },
        {
            "x": -2,
            "y": 10,
            "z": 16,
            "elements": [
                "appliedenergistics2:sky_stone_small_brick@0"
            ]
        },
        {
            "x": -1,
            "y": 12,
            "z": 4,
            "elements": [
                "appliedenergistics2:sky_stone_small_brick_slab@0"
            ]
        },
        {
            "x": -2,
            "y": 12,
            "z": 13,
            "elements": [
                "tconstruct:clear_glass@0"
            ]
        },
        {
            "x": -3,
            "y": 11,
            "z": 3,
            "elements": [
                "appliedenergistics2:sky_stone_small_brick@0"
            ]
        },
        {
            "x": 2,
            "y": 10,
            "z": 8,
            "elements": [
                "appliedenergistics2:sky_stone_small_brick@0"
            ]
        },
        {
            "x": 4,
            "y": 12,
            "z": 12,
            "elements": [
                "appliedenergistics2:sky_stone_small_brick@0"
            ]
        },
        {
            "x": 3,
            "y": -1,
            "z": 14,
            "elements": [
                "chisel:factory@6"
            ]
        },
        {
            "x": 0,
            "y": -1,
            "z": 6,
            "elements": [
                "appliedenergistics2:sky_stone_small_brick@0"
            ]
        },
        {
            "x": 2,
            "y": 11,
            "z": 1,
            "elements": [
                "appliedenergistics2:sky_stone_small_brick_slab@0"
            ]
        },
        {
            "x": -3,
            "y": 3,
            "z": 5,
            "elements": [
                "chisel:technical@4"
            ]
        },
        {
            "x": -2,
            "y": 5,
            "z": 0,
            "elements": [
                "chisel:technical@13"
            ]
        },
        {
            "x": 0,
            "y": 3,
            "z": 3,
            "elements": [
                "actuallyadditions:block_misc@2"
            ]
        },
        {
            "x": -2,
            "y": 9,
            "z": 6,
            "elements": [
                "chisel:technical@4"
            ]
        },
        {
            "x": 1,
            "y": 3,
            "z": 12,
            "elements": [
                "thermalfoundation:storage_alloy@0"
            ]
        },
        {
            "x": -2,
            "y": 9,
            "z": 12,
            "elements": [
                "enderio:block_alloy@6"
            ]
        },
        {
            "x": -2,
            "y": 8,
            "z": 6,
            "elements": [
                "chisel:technical@4"
            ]
        },
        {
            "x": 2,
            "y": 3,
            "z": 0,
            "elements": [
                "chisel:technical@13"
            ]
        },
        {
            "x": 1,
            "y": -1,
            "z": 5,
            "elements": [
                "chisel:planks-oak@12"
            ]
        },
        {
            "x": 0,
            "y": 2,
            "z": 4,
            "elements": [
                "tconstruct:seared_slab@3"
            ]
        },
        {
            "x": 3,
            "y": 0,
            "z": 4,
            "elements": [
                "casings_all"
            ]
        },
        {
            "x": -3,
            "y": 0,
            "z": 4,
            "elements": [
                "casings_all"
            ]
        },
        {
            "x": -3,
            "y": 9,
            "z": 5,
            "elements": [
                "chisel:technical@4"
            ]
        },
        {
            "x": -1,
            "y": 11,
            "z": 0,
            "elements": [
                "appliedenergistics2:sky_stone_small_brick_slab@0"
            ]
        },
        {
            "x": -2,
            "y": 7,
            "z": 6,
            "elements": [
                "chisel:technical@4"
            ]
        },
        {
            "x": -3,
            "y": -1,
            "z": 14,
            "elements": [
                "chisel:factory@6"
            ]
        },
        {
            "x": 2,
            "y": 1,
            "z": 0,
            "elements": [
                "twilightforest:magic_log@2"
            ]
        },
        {
            "x": -3,
            "y": 7,
            "z": 5,
            "elements": [
                "chisel:technical@4"
            ]
        },
        {
            "x": -2,
            "y": 6,
            "z": 6,
            "elements": [
                "chisel:technical@4"
            ]
        },
        {
            "x": 2,
            "y": 1,
            "z": 5,
            "elements": [
                "appliedenergistics2:sky_stone_small_brick@0"
            ]
        },
        {
            "x": 2,
            "y": 7,
            "z": 0,
            "elements": [
                "chisel:technical@13"
            ]
        },
        {
            "x": -2,
            "y": 11,
            "z": 12,
            "elements": [
                "thermalfoundation:storage_alloy@5"
            ]
        },
        {
            "x": -3,
            "y": 11,
            "z": 5,
            "elements": [
                "appliedenergistics2:sky_stone_small_brick@0"
            ]
        },
        {
            "x": 0,
            "y": 6,
            "z": 4,
            "elements": [
                "tconstruct:seared_slab@3"
            ]
        },
        {
            "x": 1,
            "y": 6,
            "z": 12,
            "elements": [
                "enderio:block_alloy@9"
            ]
        },
        {
            "x": -2,
            "y": 12,
            "z": 6,
            "elements": [
                "appliedenergistics2:sky_stone_small_brick_slab@0"
            ]
        },
        {
            "x": -4,
            "y": -1,
            "z": 15,
            "elements": [
                "chisel:factory@6"
            ]
        },
        {
            "x": -2,
            "y": 10,
            "z": 12,
            "elements": [
                "thermalfoundation:storage_alloy@5"
            ]
        },
        {
            "x": 1,
            "y": 7,
            "z": 12,
            "elements": [
                "enderio:block_alloy@9"
            ]
        },
        {
            "x": -3,
            "y": 1,
            "z": 10,
            "elements": [
                "chisel:technicalnew@2"
            ]
        },
        {
            "x": 1,
            "y": 4,
            "z": 12,
            "elements": [
                "thermalfoundation:storage_alloy@0"
            ]
        },
        {
            "x": 2,
            "y": 5,
            "z": 0,
            "elements": [
                "chisel:technical@13"
            ]
        },
        {
            "x": 1,
            "y": 9,
            "z": 6,
            "elements": [
                "appliedenergistics2:sky_stone_small_brick_stairs@2"
            ]
        },
        {
            "x": -2,
            "y": 10,
            "z": 6,
            "elements": [
                "chisel:technical@4"
            ]
        },
        {
            "x": -3,
            "y": -1,
            "z": 15,
            "elements": [
                "chisel:technicalnew@2"
            ]
        },
        {
            "x": -2,
            "y": -1,
            "z": 5,
            "elements": [
                "appliedenergistics2:sky_stone_small_brick@0"
            ]
        },
        {
            "x": -3,
            "y": 1,
            "z": 15,
            "elements": [
                "chisel:technicalnew@2"
            ]
        },
        {
            "x": 1,
            "y": 5,
            "z": 12,
            "elements": [
                "thermalfoundation:storage_alloy@0"
            ]
        },
        {
            "x": -2,
            "y": 11,
            "z": 6,
            "elements": [
                "appliedenergistics2:sky_stone_small_brick@0"
            ]
        },
        {
            "x": -3,
            "y": 9,
            "z": 10,
            "elements": [
                "appliedenergistics2:sky_stone_small_brick_slab@8"
            ]
        },
        {
            "x": -1,
            "y": 11,
            "z": 5,
            "elements": [
                "appliedenergistics2:sky_stone_small_brick@0"
            ]
        },
        {
            "x": 3,
            "y": -1,
            "z": 3,
            "elements": [
                "appliedenergistics2:sky_stone_small_brick@0"
            ]
        },
        {
            "x": -3,
            "y": 0,
            "z": 9,
            "elements": [
                "chisel:technicalnew@2"
            ]
        },
        {
            "x": -1,
            "y": 9,
            "z": 15,
            "elements": [
                "appliedenergistics2:sky_stone_small_brick_slab@8"
            ]
        },
        {
            "x": -4,
            "y": 11,
            "z": 15,
            "elements": [
                "enderio:block_dark_iron_bars@0"
            ]
        },
        {
            "x": 2,
            "y": 12,
            "z": 7,
            "elements": [
                "appliedenergistics2:sky_stone_small_brick@0"
            ]
        },
        {
            "x": 1,
            "y": 11,
            "z": 0,
            "elements": [
                "appliedenergistics2:sky_stone_small_brick_slab@0"
            ]
        },
        {
            "x": 3,
            "y": 5,
            "z": 5,
            "elements": [
                "chisel:technical@4"
            ]
        },
        {
            "x": -4,
            "y": 2,
            "z": 4,
            "elements": [
                "appliedenergistics2:sky_stone_small_brick@0"
            ]
        },
        {
            "x": 0,
            "y": 8,
            "z": 11,
            "elements": [
                "enderio:block_dark_iron_bars@0"
            ]
        },
        {
            "x": 1,
            "y": 13,
            "z": 7,
            "elements": [
                "appliedenergistics2:sky_stone_small_brick_slab@0"
            ]
        },
        {
            "x": 1,
            "y": 3,
            "z": 3,
            "elements": [
                "tconstruct:seared_slab@3"
            ]
        },
        {
            "x": 2,
            "y": 11,
            "z": 7,
            "elements": [
                "appliedenergistics2:sky_stone_small_brick@0"
            ]
        },
        {
            "x": 3,
            "y": -1,
            "z": 10,
            "elements": [
                "chisel:factory@6"
            ]
        },
        {
            "x": -2,
            "y": 9,
            "z": 10,
            "elements": [
                "appliedenergistics2:sky_stone_small_brick_slab@8"
            ]
        },
        {
            "x": 4,
            "y": 10,
            "z": 14,
            "elements": [
                "appliedenergistics2:sky_stone_small_brick@0"
            ]
        },
        {
            "x": 1,
            "y": 12,
            "z": 6,
            "elements": [
                "appliedenergistics2:sky_stone_small_brick@0"
            ]
        },
        {
            "x": 0,
            "y": -1,
            "z": 3,
            "elements": [
                "chisel:planks-oak@12"
            ]
        },
        {
            "x": -4,
            "y": 0,
            "z": 9,
            "elements": [
                "chisel:technicalnew@2"
            ]
        },
        {
            "x": 3,
            "y": 1,
            "z": 10,
            "elements": [
                "chisel:technicalnew@2"
            ]
        },
        {
            "x": 2,
            "y": 13,
            "z": 14,
            "elements": [
                "thermalfoundation:glass@0"
            ]
        },
        {
            "x": 2,
            "y": 10,
            "z": 7,
            "elements": [
                "appliedenergistics2:sky_stone_small_brick@0"
            ]
        },
        {
            "x": 4,
            "y": 9,
            "z": 14,
            "elements": [
                "appliedenergistics2:sky_stone_small_brick_stairs@4"
            ]
        },
        {
            "x": 3,
            "y": 3,
            "z": 5,
            "elements": [
                "chisel:technical@4"
            ]
        },
        {
            "x": -4,
            "y": 10,
            "z": 2,
            "elements": [
                "appliedenergistics2:sky_stone_small_brick@0"
            ]
        },
        {
            "x": 3,
            "y": 1,
            "z": 5,
            "elements": [
                "twilightforest:magic_log@2"
            ]
        },
        {
            "x": -3,
            "y": 4,
            "z": 9,
            "elements": [
                "chisel:technicalnew@2"
            ]
        },
        {
            "x": -4,
            "y": 6,
            "z": 4,
            "elements": [
                "appliedenergistics2:sky_stone_small_brick@0"
            ]
        },
        {
            "x": -2,
            "y": 11,
            "z": 3,
            "elements": [
                "appliedenergistics2:sky_stone_small_brick@0"
            ]
        },
        {
            "x": 2,
            "y": 3,
            "z": 5,
            "elements": [
                "tconstruct:seared_slab@3"
            ]
        },
        {
            "x": 0,
            "y": 11,
            "z": 10,
            "elements": [
                "thermalfoundation:storage_alloy@5"
            ]
        },
        {
            "x": -3,
            "y": 13,
            "z": 10,
            "elements": [
                "thermalfoundation:glass@0"
            ]
        },
        {
            "x": -4,
            "y": 9,
            "z": 15,
            "elements": [
                "enderio:block_dark_iron_bars@0"
            ]
        },
        {
            "x": 0,
            "y": 9,
            "z": 10,
            "elements": [
                "enderio:block_alloy@6"
            ]
        },
        {
            "x": -4,
            "y": 8,
            "z": 2,
            "elements": [
                "appliedenergistics2:sky_stone_small_brick@0"
            ]
        },
        {
            "x": -3,
            "y": 2,
            "z": 9,
            "elements": [
                "chisel:technicalnew@2"
            ]
        },
        {
            "x": -2,
            "y": 0,
            "z": 9,
            "elements": [
                "chisel:technicalnew@2"
            ]
        },
        {
            "x": 2,
            "y": 7,
            "z": 5,
            "elements": [
                "tconstruct:seared_slab@3"
            ]
        },
