{
    "registryname": "end_forge",
    "localizedname": "§3LV2 - 末影冶炼炉",
    "requires-blueprint": false,
    "failure-action": "still",
    "color": "000000",
    "parts": [
        {
            "x": 0,
            "y": 0,
            "z": 0,
            "elements": [
                "modularmachinery:blockcontroller@2"
            ]
        },
        {
            "x": 1,
            "y": 1,
            "z": 3,
            "elements": [
                "thermalfoundation:fluid_ender@0"
            ]
        },
        {
            "x": -1,
            "y": 2,
            "z": 0,
            "elements": [
                "endreborn:block_endorium@0"
            ]
        },
        {
            "x": -2,
            "y": -2,
            "z": 4,
            "elements": [
                "endreborn:block_endorium@0"
            ]
        },
        {
            "x": 0,
            "y": -2,
            "z": 0,
            "elements": [
                "endreborn:block_endorium@0"
            ]
        },
        {
            "x": 2,
            "y": 1,
            "z": 2,
            "elements": [
                "quark:biotite_block@0"
            ]
        },
        {
            "x": -1,
            "y": 1,
            "z": 0,
            "elements": [
                "quark:biotite_block@0"
            ]
        },
        {
            "x": 0,
            "y": -1,
            "z": 0,
            "elements": [
                "casings_all"
            ]
        },
        {
            "x": -1,
            "y": 0,
            "z": 4,
            "elements": [
                "taiga:aurorium_block@0"
            ]
        },
        {
            "x": -2,
            "y": -2,
            "z": 3,
            "elements": [
                "endreborn:block_endorium@0"
            ]
        },
        {
            "x": 2,
            "y": 0,
            "z": 2,
            "elements": [
                "quark:biotite_block@0"
            ]
        },
        {
            "x": 1,
            "y": 0,
            "z": 0,
            "elements": [
                "taiga:aurorium_block@0"
            ]
        },
        {
            "x": 1,
            "y": -2,
            "z": 0,
            "elements": [
                "endreborn:block_endorium@0"
            ]
        },
        {
            "x": 2,
            "y": -2,
            "z": 1,
            "elements": [
                "endreborn:block_endorium@0"
            ]
        },
        {
            "x": -2,
            "y": 2,
            "z": 0,
            "elements": [
                "endreborn:block_endorium@0"
            ]
        },
        {
            "x": 1,
            "y": -2,
            "z": 4,
            "elements": [
                "endreborn:block_endorium@0"
            ]
        },
        {
            "x": -1,
            "y": 1,
            "z": 4,
            "elements": [
                "quark:biotite_block@0"
            ]
        },
        {
            "x": 0,
            "y": -1,
            "z": 3,
            "elements": [
                "thermalfoundation:fluid_ender@0"
            ]
        },
        {
            "x": 0,
            "y": 0,
            "z": 1,
            "elements": [
                "thermalfoundation:fluid_ender@0"
            ]
        },
        {
            "x": 1,
            "y": -1,
            "z": 0,
            "elements": [
                "casings_all"
            ]
        },
        {
            "x": -2,
            "y": 1,
            "z": 0,
            "elements": [
                "endreborn:block_endorium@0"
            ]
        },
        {
            "x": 2,
            "y": 2,
            "z": 2,
            "elements": [
                "endreborn:block_endorium@0"
            ]
        },
        {
            "x": 1,
            "y": 0,
            "z": 3,
            "elements": [
                "thermalfoundation:fluid_ender@0"
            ]
        },
        {
            "x": -1,
            "y": 2,
            "z": 4,
            "elements": [
                "endreborn:block_endorium@0"
            ]
        },
        {
            "x": 1,
            "y": -2,
            "z": 3,
            "elements": [
                "quark:biotite_block@0"
            ]
        },
        {
            "x": 0,
            "y": 1,
            "z": 1,
            "elements": [
                "thermalfoundation:fluid_ender@0"
            ]
        },
        {
            "x": 2,
            "y": -1,
            "z": 1,
            "elements": [
                "casings_all"
            ]
        },
        {
            "x": 1,
            "y": 2,
            "z": 0,
            "elements": [
                "endreborn:block_endorium@0"
            ]
        },
        {
            "x": 2,
            "y": 0,
            "z": 0,
            "elements": [
                "taiga:aurorium_block@0"
            ]
        },
        {
            "x": -1,
            "y": 0,
            "z": 1,
            "elements": [
                "thermalfoundation:fluid_ender@0"
            ]
        },
        {
            "x": 2,
            "y": -2,
            "z": 2,
            "elements": [
                "endreborn:block_endorium@0"
            ]
        },
        {
            "x": -1,
            "y": -2,
            "z": 1,
            "elements": [
                "quark:biotite_block@0"
            ]
        },
        {
            "x": 1,
            "y": -1,
            "z": 3,
            "elements": [
                "thermalfoundation:fluid_ender@0"
            ]
        },
        {
            "x": 0,
            "y": -2,
            "z": 4,
            "elements": [
                "endreborn:block_endorium@0"
            ]
        },
        {
            "x": -2,
            "y": -2,
            "z": 0,
            "elements": [
                "endreborn:block_endorium@0"
            ]
        },
        {
            "x": -2,
            "y": 1,
            "z": 4,
            "elements": [
                "endreborn:block_endorium@0"
            ]
        },
        {
            "x": -2,
            "y": 2,
            "z": 1,
            "elements": [
                "endreborn:block_endorium@0"
            ]
        },
        {
            "x": 2,
            "y": 2,
            "z": 3,
            "elements": [
                "endreborn:block_endorium@0"
            ]
        },
        {
            "x": 2,
            "y": -1,
            "z": 2,
            "elements": [
                "casings_parallel"
            ]
        },
        {
            "x": 0,
            "y": 1,
            "z": 2,
            "elements": [
                "thermalfoundation:fluid_ender@0"
            ]
        },
        {
            "x": -1,
            "y": -1,
            "z": 1,
            "elements": [
                "thermalfoundation:fluid_ender@0"
            ]
        },
        {
            "x": 1,
            "y": 1,
            "z": 0,
            "elements": [
                "quark:biotite_block@0"
            ]
        },
        {
            "x": -2,
            "y": -1,
            "z": 0,
            "elements": [
                "endreborn:block_endorium@0"
            ]
        },
        {
            "x": 2,
            "y": 0,
            "z": 3,
            "elements": [
                "taiga:aurorium_block@0"
            ]
        },
        {
            "x": -1,
            "y": 1,
            "z": 1,
            "elements": [
                "thermalfoundation:fluid_ender@0"
            ]
        },
        {
            "x": 0,
            "y": 0,
            "z": 2,
            "elements": [
                "thermalfoundation:fluid_ender@0"
            ]
        },
        {
            "x": -2,
            "y": 2,
            "z": 4,
            "elements": [
                "endreborn:block_endorium@0"
            ]
        },
        {
            "x": -1,
            "y": 0,
            "z": 0,
            "elements": [
                "taiga:aurorium_block@0"
            ]
        },
        {
            "x": -2,
            "y": 0,
            "z": 1,
            "elements": [
                "taiga:aurorium_block@0"
            ]
        },
        {
            "x": 2,
            "y": 1,
            "z": 3,
            "elements": [
                "quark:biotite_block@0"
            ]
        },
        {
            "x": 0,
            "y": -2,
            "z": 1,
            "elements": [
                "quark:biotite_block@0"
            ]
        },
        {
            "x": -1,
            "y": -2,
            "z": 4,
            "elements": [
                "endreborn:block_endorium@0"
            ]
        },
        {
            "x": 2,
            "y": -1,
            "z": 3,
            "elements": [
                "casings_all"
            ]
        },
        {
            "x": 0,
            "y": -1,
            "z": 1,
            "elements": [
                "thermalfoundation:fluid_ender@0"
            ]
        },
        {
            "x": -2,
            "y": -1,
            "z": 4,
            "elements": [
                "endreborn:block_endorium@0"
            ]
        },
        {
            "x": -2,
            "y": 0,
            "z": 4,
            "elements": [
                "taiga:aurorium_block@0"
            ]
        },
        {
            "x": -2,
            "y": 1,
            "z": 1,
            "elements": [
                "quark:biotite_block@0"
            ]
        },
        {
            "x": 0,
            "y": -2,
            "z": 2,
            "elements": [
                "quark:biotite_block@0"
            ]
        },
        {
            "x": -2,
            "y": 0,
            "z": 2,
            "elements": [
                "quark:biotite_block@0"
            ]
        },
        {
            "x": 1,
            "y": -2,
            "z": 1,
            "elements": [
                "quark:biotite_block@0"
            ]
        },
        {
            "x": 2,
            "y": -2,
            "z": 4,
            "elements": [
                "endreborn:block_endorium@0"
            ]
        },
        {
            "x": -1,
            "y": -1,
            "z": 3,
            "elements": [
                "thermalfoundation:fluid_ender@0"
            ]
        },
        {
            "x": 2,
            "y": -1,
            "z": 4,
            "elements": [
                "endreborn:block_endorium@0"
            ]
        },
        {
            "x": -2,
            "y": 1,
            "z": 2,
            "elements": [
                "quark:biotite_block@0"
            ]
        },
        {
            "x": 1,
            "y": 0,
            "z": 1,
            "elements": [
                "thermalfoundation:fluid_ender@0"
            ]
        },
        {
            "x": 0,
            "y": 1,
            "z": 4,
            "elements": [
                "quark:biotite_block@0"
            ]
        },
        {
            "x": 1,
            "y": -1,
            "z": 1,
            "elements": [
                "thermalfoundation:fluid_ender@0"
            ]
        },
        {
            "x": 0,
            "y": -1,
            "z": 2,
            "elements": [
                "thermalfoundation:fluid_ender@0"
            ]
        },
        {
            "x": 0,
            "y": 0,
            "z": 3,
            "elements": [
                "thermalfoundation:fluid_ender@0"
            ]
        },
        {
            "x": -1,
            "y": -1,
            "z": 4,
            "elements": [
                "casings_all"
            ]
        },
        {
            "x": 1,
            "y": 1,
            "z": 1,
            "elements": [
                "thermalfoundation:fluid_ender@0"
            ]
        },
        {
            "x": 0,
            "y": 2,
            "z": 4,
            "elements": [
                "endreborn:block_endorium@0"
            ]
        },
        {
            "x": 2,
            "y": -2,
            "z": 3,
            "elements": [
                "endreborn:block_endorium@0"
            ]
        },
        {
            "x": 0,
            "y": 1,
            "z": 3,
            "elements": [
                "thermalfoundation:fluid_ender@0"
            ]
        },
        {
            "x": 2,
            "y": 2,
            "z": 0,
            "elements": [
                "endreborn:block_endorium@0"
            ]
        },
        {
            "x": -2,
            "y": -2,
            "z": 1,
            "elements": [
                "endreborn:block_endorium@0"
            ]
        },
        {
            "x": -1,
            "y": -2,
            "z": 2,
            "elements": [
                "quark:biotite_block@0"
            ]
        },
        {
            "x": -1,
            "y": 1,
            "z": 2,
            "elements": [
                "thermalfoundation:fluid_ender@0"
            ]
        },
        {
            "x": -2,
            "y": -1,
            "z": 1,
            "elements": [
                "casings_all"
            ]
        },
        {
            "x": -1,
            "y": -1,
            "z": 2,
            "elements": [
                "thermalfoundation:fluid_ender@0"
            ]
        },
        {
            "x": 2,
            "y": 1,
            "z": 0,
            "elements": [
                "endreborn:block_endorium@0"
            ]
        },
        {
            "x": -2,
            "y": 2,
            "z": 2,
            "elements": [
                "endreborn:block_endorium@0"
            ]
        },
        {
            "x": 0,
            "y": 0,
            "z": 4,
            "elements": [
                "quark:biotite_block@0"
            ]
        },
        {
            "x": -1,
            "y": 0,
            "z": 2,
            "elements": [
                "thermalfoundation:fluid_ender@0"
            ]
        },
        {
            "x": -2,
            "y": 0,
            "z": 0,
            "elements": [
                "taiga:aurorium_block@0"
            ]
        },
        {
            "x": 2,
            "y": -2,
            "z": 0,
            "elements": [
                "endreborn:block_endorium@0"
            ]
        },
        {
            "x": -2,
            "y": -2,
            "z": 2,
            "elements": [
                "endreborn:block_endorium@0"
            ]
        },
        {
            "x": -1,
            "y": 1,
            "z": 3,
            "elements": [
                "thermalfoundation:fluid_ender@0"
            ]
        },
        {
            "x": 0,
            "y": -1,
            "z": 4,
            "elements": [
                "casings_upgrade"
            ]
        },
        {
            "x": 2,
            "y": 1,
            "z": 4,
            "elements": [
                "endreborn:block_endorium@0"
            ]
        },
        {
            "x": -2,
            "y": -1,
            "z": 2,
            "elements": [
                "casings_parallel"
            ]
        },
        {
            "x": 2,
            "y": 2,
            "z": 4,
            "elements": [
                "endreborn:block_endorium@0"
            ]
        },
        {
            "x": 2,
            "y": 2,
            "z": 1,
            "elements": [
                "endreborn:block_endorium@0"
            ]
        },
        {
            "x": -2,
            "y": 0,
            "z": 3,
            "elements": [
                "taiga:aurorium_block@0"
            ]
        },
        {
            "x": 1,
            "y": 0,
            "z": 4,
            "elements": [
                "taiga:aurorium_block@0"
            ]
        },
        {
            "x": 0,
            "y": -2,
            "z": 3,
            "elements": [
                "quark:biotite_block@0"
            ]
        },
        {
            "x": 1,
            "y": -2,
            "z": 2,
            "elements": [
                "quark:biotite_block@0"
            ]
        },
        {
            "x": 0,
            "y": 2,
            "z": 0,
            "elements": [
                "endreborn:block_endorium@0"
            ]
        },
        {
            "x": -1,
            "y": -2,
            "z": 0,
            "elements": [
                "endreborn:block_endorium@0"
            ]
        },
        {
            "x": -2,
            "y": 1,
            "z": 3,
            "elements": [
                "quark:biotite_block@0"
            ]
        },
        {
            "x": 1,
            "y": -1,
            "z": 4,
            "elements": [
                "casings_all"
            ]
        },
        {
            "x": -2,
            "y": -1,
            "z": 3,
            "elements": [
                "casings_all"
            ]
        },
        {
            "x": 1,
            "y": 1,
            "z": 2,
            "elements": [
                "thermalfoundation:fluid_ender@0"
            ]
        },
        {
            "x": 1,
            "y": -1,
            "z": 2,
            "elements": [
                "thermalfoundation:fluid_ender@0"
            ]
        },
        {
            "x": 2,
            "y": 0,
            "z": 1,
            "elements": [
                "taiga:aurorium_block@0"
            ]
        },
        {
            "x": 1,
            "y": 1,
            "z": 4,
            "elements": [
                "quark:biotite_block@0"
            ]
        },
        {
            "x": 2,
            "y": -1,
            "z": 0,
            "elements": [
                "endreborn:block_endorium@0"
            ]
        },
        {
            "x": -2,
            "y": 2,
            "z": 3,
            "elements": [
                "endreborn:block_endorium@0"
            ]
        },
        {
            "x": 0,
            "y": 1,
            "z": 0,
            "elements": [
                "quark:biotite_block@0"
            ]
        },
        {
            "x": -1,
            "y": -1,
            "z": 0,
            "elements": [
                "casings_all"
            ]
        },
        {
            "x": 1,
            "y": 2,
            "z": 4,
            "elements": [
                "endreborn:block_endorium@0"
            ]
        },
        {
            "x": -1,
            "y": 0,
            "z": 3,
            "elements": [
                "thermalfoundation:fluid_ender@0"
            ]
        },
        {
            "x": -1,
            "y": -2,
            "z": 3,
            "elements": [
                "quark:biotite_block@0"
            ]
        },
        {
            "x": 2,
            "y": 1,
            "z": 1,
            "elements": [
                "quark:biotite_block@0"
            ]
        },
        {
            "x": 2,
            "y": 0,
            "z": 4,
            "elements": [
                "taiga:aurorium_block@0"
            ]
        },
        {
            "x": 1,
            "y": 0,
            "z": 2,
            "elements": [
                "thermalfoundation:fluid_ender@0"
            ]
        }
    ]}