{
    "registryname": "aeonsteel_forge",
    "localizedname": "§3LV2 - 恒钢熔合机",
    "requires-blueprint": false,
    "color": "cccccc",
    "failure-action": "still",
    "modifiers": [
        {
            "elements": "modularmachinery:blockcasing@1",
            "x": 0,
            "y": 1,
            "z": 0,
            "description": "将控制器上方紧挨着的方块换成此方块以降低配方制作时间至80%！",
            "modifier": {
                "io": "input",
                "target": "modularmachinery:duration",
                "operation": 1,
                "multiplier": 0.80
            }
        },
        {
            "elements": "modularmachinery:blockcasing@2",
            "x": 0,
            "y": 1,
            "z": 0,
            "description": "将控制器上方紧挨着的方块换成此方块以降低配方制作时间至70%！",
            "modifier": {
                "io": "input",
                "target": "modularmachinery:duration",
                "operation": 1,
                "multiplier": 0.70
            }
        },
        {
            "elements": "modularmachinery:blockcasing@3",
            "x": 0,
            "y": 1,
            "z": 0,
            "description": "将控制器上方紧挨着的方块换成此方块以降低配方制作时间至60%！",
            "modifier": {
                "io": "input",
                "target": "modularmachinery:duration",
                "operation": 1,
                "multiplier": 0.60
            }
        },
        {
            "elements": "modularmachinery:blockcasing@5",
            "x": 0,
            "y": 1,
            "z": 0,
            "description": "将控制器上方紧挨着的方块换成此方块以降低配方制作时间至50%！",
            "modifier": {
                "io": "input",
                "target": "modularmachinery:duration",
                "operation": 1,
                "multiplier": 0.50
            }
        }
    ],
    "parts": [
        {
            "x": 0,
            "y": 0,
            "z": 0,
            "elements": [
                "modularmachinery:aeonsteel_forge_factory_controller@2"
            ]
        },
        {
            "x": 3,
            "y": 14,
            "z": 6,
            "elements": [
                "enderio:block_alloy@6"
            ]
        },
        {
            "x": 3,
            "y": 11,
            "z": 7,
            "elements": [
                "thermaldynamics:duct_16@2"
            ]
        },
        {
            "x": 4,
            "y": -1,
            "z": 17,
            "elements": [
                "astralsorcery:blockmarble@3"
            ]
        },
        {
            "x": -3,
            "y": 0,
            "z": 5,
            "elements": [
                "twilightforest:castle_stairs@3"
            ]
        },
        {
            "x": -6,
            "y": 0,
            "z": 10,
            "elements": [
                "minecraft:hopper@0"
            ]
        },
        {
            "x": 0,
            "y": 14,
            "z": 7,
            "elements": [
                "tconevo:metal_block@5"
            ]
        },
        {
            "x": -5,
            "y": 10,
            "z": 0,
            "elements": [
                "astralsorcery:blockmarbleslab@8"
            ]
        },
        {
            "x": 8,
            "y": -1,
            "z": 7,
            "elements": [
                "astralsorcery:blockmarble@3"
            ]
        },
        {
            "x": 6,
            "y": 5,
            "z": 4,
            "elements": [
                "minecraft:iron_trapdoor@10"
            ]
        },
        {
            "x": 10,
            "y": 3,
            "z": 2,
            "elements": [
                "actuallyadditions:block_quartz_wall@0"
            ]
        },
        {
            "x": 0,
            "y": 16,
            "z": 7,
            "elements": [
                "enderio:block_alloy@8"
            ]
        },
        {
            "x": 11,
            "y": -1,
            "z": 2,
            "elements": [
                "compactmachines3:wallbreakable@0"
            ]
        },
        {
            "x": -4,
            "y": 6,
            "z": 5,
            "elements": [
                "minecraft:quartz_stairs@3"
            ]
        },
        {
            "x": 1,
            "y": 5,
            "z": 9,
            "elements": [
                "twilightforest:aurora_block@0"
            ]
        },
        {
            "x": 0,
            "y": 17,
            "z": 7,
            "elements": [
                "enderio:block_dark_iron_bars@0"
            ]
        },
        {
            "x": 3,
            "y": -1,
            "z": 9,
            "elements": [
                "modularmachinery:blockcasing@4"
            ]
        },
        {
            "x": 9,
            "y": 6,
            "z": 3,
            "elements": [
                "actuallyadditions:block_quartz_wall@0"
            ]
        },
        {
            "x": -5,
            "y": 0,
            "z": 5,
            "elements": [
                "twilightforest:castle_stairs@3"
            ]
        },
        {
            "x": 3,
            "y": 7,
            "z": 7,
            "elements": [
                "tconstruct:seared_stairs_paver@6"
            ]
        },
        {
            "x": -5,
            "y": 6,
            "z": 0,
            "elements": [
                "twilightforest:castle_stairs_brick@6"
            ]
        },
        {
            "x": 0,
            "y": 17,
            "z": 8,
            "elements": [
                "quark:blaze_lantern@0"
            ]
        },
        {
            "x": -5,
            "y": -1,
            "z": 16,
            "elements": [
                "compactmachines3:wallbreakable@0"
            ]
        },
        {
            "x": 0,
            "y": 12,
            "z": 7,
            "elements": [
                "enderio:block_alloy@6"
            ]
        },
        {
            "x": -4,
            "y": 0,
            "z": 10,
            "elements": [
                "minecraft:quartz_stairs@1"
            ]
        },
        {
            "x": 10,
            "y": 7,
            "z": 2,
            "elements": [
                "astralsorcery:blockmarble@2"
            ]
        },
        {
            "x": -3,
            "y": 3,
            "z": 11,
            "elements": [
                "enderio:block_dark_iron_bars@0"
            ]
        },
        {
            "x": 9,
            "y": 2,
            "z": 3,
            "elements": [
                "minecraft:quartz_stairs@3"
            ]
        },
        {
            "x": 0,
            "y": -1,
            "z": 11,
            "elements": [
                "casings_all"
            ]
        },
        {
            "x": -7,
            "y": -1,
            "z": 1,
            "elements": [
                "nuclearcraft:ingot_block@8"
            ]
        },
        {
            "x": 0,
            "y": 17,
            "z": 6,
            "elements": [
                "enderio:block_dark_iron_bars@0"
            ]
        },
        {
            "x": 8,
            "y": -1,
            "z": -1,
            "elements": [
                "twilightforest:castle_stairs@11"
            ]
        },
        {
            "x": 6,
            "y": 8,
            "z": 3,
            "elements": [
                "minecraft:quartz_stairs@4"
            ]
        },
        {
            "x": 0,
            "y": 13,
            "z": 7,
            "elements": [
                "tconevo:metal_block@5"
            ]
        },
        {
            "x": -5,
            "y": 2,
            "z": 0,
            "elements": [
                "compactmachines3:wallbreakable@0"
            ]
        },
        {
            "x": -5,
            "y": 9,
            "z": 16,
            "elements": [
                "twilightforest:castle_stairs@10"
            ]
        },
        {
            "x": 10,
            "y": 11,
            "z": 2,
            "elements": [
                "astralsorcery:blockmarble@6"
            ]
        },
        {
            "x": -5,
            "y": -1,
            "z": 19,
            "elements": [
                "twilightforest:castle_stairs@10"
            ]
        },
        {
            "x": 9,
            "y": 9,
            "z": 2,
            "elements": [
                "twilightforest:castle_stairs@8"
            ]
        },
        {
            "x": 2,
            "y": -1,
            "z": 4,
            "elements": [
                "astralsorcery:blockmarble@3"
            ]
        },
        {
            "x": -7,
            "y": 6,
            "z": 0,
            "elements": [
                "twilightforest:castle_stairs_brick@6"
            ]
        },
        {
            "x": 4,
            "y": 7,
            "z": 9,
            "elements": [
                "twilightforest:castle_stairs@5"
            ]
        },
        {
            "x": 1,
            "y": -1,
            "z": 16,
            "elements": [
                "astralsorcery:blockmarble@3"
            ]
        },
        {
            "x": 1,
            "y": 9,
            "z": 9,
            "elements": [
                "astralsorcery:blockmarble@2"
            ]
        },
        {
            "x": 3,
            "y": 6,
            "z": 6,
            "elements": [
                "tconstruct:seared_stairs_paver@6"
            ]
        },
        {
            "x": 3,
            "y": 3,
            "z": 7,
            "elements": [
                "minecraft:quartz_block@0"
            ]
        },
        {
            "x": -3,
            "y": 8,
            "z": 5,
            "elements": [
                "thaumicaugmentation:fortified_glass_pane@0"
            ]
        },
        {
            "x": 0,
            "y": 6,
            "z": 7,
            "elements": [
                "thermalexpansion:cell@0"
            ]
        },
        {
            "x": -6,
            "y": -1,
            "z": 11,
            "elements": [
                "astralsorcery:blockmarble@3"
            ]
        },
        {
            "x": -4,
            "y": -1,
            "z": 4,
            "elements": [
                "compactmachines3:wallbreakable@0"
            ]
        },
        {
            "x": 8,
            "y": -1,
            "z": 4,
            "elements": [
                "compactmachines3:wallbreakable@0"
            ]
        },
        {
            "x": -4,
            "y": 7,
            "z": 16,
            "elements": [
                "actuallyadditions:block_quartz_wall@0"
            ]
        },
        {
            "x": 10,
            "y": -1,
            "z": 17,
            "elements": [
                "compactmachines3:wallbreakable@0"
            ]
        },
        {
            "x": -6,
            "y": 2,
            "z": 1,
            "elements": [
                "compactmachines3:wallbreakable@0"
            ]
        },
        {
            "x": 0,
            "y": 4,
            "z": 7,
            "elements": [
                "thermaldynamics:duct_0@3"
            ]
        },
        {
            "x": 1,
            "y": 1,
            "z": 16,
            "elements": [
                "quark:acacia_trapdoor@7"
            ]
        },
        {
            "x": 0,
            "y": 0,
            "z": 10,
            "elements": [
                "additions:star_metal_block@0"
            ]
        },
        {
            "x": 9,
            "y": 5,
            "z": 2,
            "elements": [
                "twilightforest:castle_stairs_brick@7"
            ]
        },
        {
            "x": -3,
            "y": 2,
            "z": 10,
            "elements": [
                "actuallyadditions:block_quartz_wall@0"
            ]
        },
        {
            "x": 6,
            "y": 0,
            "z": 3,
            "elements": [
                "minecraft:quartz_stairs@0"
            ]
        },
        {
            "x": -7,
            "y": 10,
            "z": 0,
            "elements": [
                "astralsorcery:blockmarbleslab@8"
            ]
        },
        {
            "x": 0,
            "y": 5,
            "z": 7,
            "elements": [
                "thermaldynamics:duct_0@3"
            ]
        },
        {
            "x": 0,
            "y": 4,
            "z": 10,
            "elements": [
                "minecraft:quartz_block@0"
            ]
        },
        {
            "x": 5,
            "y": -1,
            "z": 6,
            "elements": [
                "compactmachines3:wallbreakable@0"
            ]
        },
        {
            "x": -6,
            "y": 3,
            "z": 1,
            "elements": [
                "compactmachines3:wallbreakable@0"
            ]
        },
        {
            "x": -5,
            "y": 4,
            "z": 15,
            "elements": [
                "minecraft:quartz_stairs@6"
            ]
        },
        {
            "x": 1,
            "y": -1,
            "z": 12,
            "elements": [
                "casings_all"
            ]
        },
        {
            "x": 3,
            "y": 2,
            "z": 6,
            "elements": [
                "actuallyadditions:block_quartz_wall@0"
            ]
        },
        {
            "x": 2,
            "y": -1,
            "z": 7,
            "elements": [
                "modularmachinery:blockcasing@4"
            ]
        },
        {
            "x": -3,
            "y": 0,
            "z": 15,
            "elements": [
                "actuallyadditions:block_quartz_wall@0"
            ]
        },
        {
            "x": 9,
            "y": -1,
            "z": 9,
            "elements": [
                "astralsorcery:blockmarble@3"
            ]
        },
        {
            "x": 1,
            "y": 1,
            "z": 9,
            "elements": [
                "thermalfoundation:fluid_cryotheum@0"
            ]
        },
        {
            "x": 0,
            "y": 2,
            "z": 7,
            "elements": [
                "thermaldynamics:duct_0@3"
            ]
        },
        {
            "x": -4,
            "y": -1,
            "z": 11,
            "elements": [
                "astralsorcery:blockmarble@3"
            ]
        },
        {
            "x": 4,
            "y": 3,
            "z": 9,
            "elements": [
                "twilightforest:castle_stairs_brick@5"
            ]
        },
        {
            "x": 11,
            "y": -1,
            "z": 8,
            "elements": [
                "astralsorcery:blockmarble@3"
            ]
        },
        {
            "x": -6,
            "y": 1,
            "z": 1,
            "elements": [
                "casings_all"
            ]
        },
        {
            "x": -1,
            "y": 0,
            "z": 12,
            "elements": [
                "extrautils2:decorativeglass@1"
            ]
        },
        {
            "x": 1,
            "y": -1,
            "z": 19,
            "elements": [
                "astralsorcery:blockmarbleslab@0"
            ]
        },
        {
            "x": 11,
            "y": 0,
            "z": 17,
            "elements": [
                "casings_all"
            ]
        },
        {
            "x": 0,
            "y": 1,
            "z": 8,
            "elements": [
                "compactmachines3:wallbreakable@0"
            ]
        },
        {
            "x": -7,
            "y": 8,
            "z": 18,
            "elements": [
                "astralsorcery:blockmarbleslab@0"
            ]
        },
        {
            "x": -2,
            "y": 5,
            "z": 4,
            "elements": [
                "minecraft:iron_trapdoor@11"
            ]
        },
        {
            "x": 3,
            "y": 11,
            "z": 11,
            "elements": [
                "thermaldynamics:duct_16@2"
            ]
        },
        {
            "x": 0,
            "y": 8,
            "z": 10,
            "elements": [
                "thermaldynamics:duct_16@2"
            ]
        },
        {
            "x": 4,
            "y": 0,
            "z": 3,
            "elements": [
                "twilightforest:castle_pillar@6"
            ]
        },
        {
            "x": -3,
            "y": -1,
            "z": 16,
            "elements": [
                "compactmachines3:wallbreakable@0"
            ]
        },
        {
            "x": 3,
            "y": 0,
            "z": 8,
            "elements": [
                "thermaldynamics:duct_16@2"
            ]
        },
        {
            "x": 3,
            "y": 2,
            "z": 10,
            "elements": [
                "thermaldynamics:duct_16@2"
            ]
        },
        {
            "x": -5,
            "y": 1,
            "z": 16,
            "elements": [
                "actuallyadditions:block_quartz_wall@0"
            ]
        },
        {
            "x": 8,
            "y": -1,
            "z": 14,
            "elements": [
                "compactmachines3:wallbreakable@0"
            ]
        },
        {
            "x": -7,
            "y": 7,
            "z": 18,
            "elements": [
                "twilightforest:castle_stairs_brick@7"
            ]
        },
        {
            "x": 0,
            "y": 2,
            "z": 8,
            "elements": [
                "minecraft:quartz_block@0"
            ]
        },
        {
            "x": 10,
            "y": 6,
            "z": 1,
            "elements": [
                "twilightforest:castle_pillar@1"
            ]
        },
        {
            "x": 11,
            "y": 9,
            "z": 18,
            "elements": [
                "twilightforest:castle_stairs@11"
            ]
        },
        {
            "x": 5,
            "y": -1,
            "z": 8,
            "elements": [
                "casings_all"
            ]
        },
        {
            "x": 6,
            "y": 5,
            "z": 14,
            "elements": [
                "minecraft:iron_trapdoor@10"
            ]
        },
        {
            "x": 7,
            "y": -1,
            "z": 12,
            "elements": [
                "astralsorcery:blockmarbleslab@0"
            ]
        },
        {
            "x": 0,
            "y": 3,
            "z": 8,
            "elements": [
                "minecraft:quartz_block@0"
            ]
        },
        {
            "x": -5,
            "y": -1,
            "z": 9,
            "elements": [
                "astralsorcery:blockmarble@3"
            ]
        },
        {
            "x": 5,
            "y": 0,
            "z": 12,
            "elements": [
                "extrautils2:decorativeglass@1"
            ]
        },
        {
            "x": -7,
            "y": 5,
            "z": 18,
            "elements": [
                "twilightforest:castle_stairs_brick@7"
            ]
        },
        {
            "x": 0,
            "y": 13,
            "z": 11,
            "elements": [
                "tconevo:metal_block@5"
            ]
        },
        {
            "x": 11,
            "y": 11,
            "z": 18,
            "elements": [
                "quark:elder_sea_lantern@0"
            ]
        },
        {
            "x": 6,
            "y": 6,
            "z": 14,
            "elements": [
                "thaumicaugmentation:fortified_glass_pane@0"
            ]
        },
        {
            "x": 6,
            "y": 8,
            "z": 14,
            "elements": [
                "thaumicaugmentation:fortified_glass_pane@0"
            ]
        },
        {
            "x": 2,
            "y": 11,
            "z": 12,
            "elements": [
                "additions:stainless_steel_block@0"
            ]
        },
        {
            "x": 11,
            "y": 7,
            "z": 18,
            "elements": [
                "twilightforest:castle_stairs_brick@7"
            ]
        },
        {
            "x": -4,
            "y": 5,
            "z": 4,
            "elements": [
                "minecraft:quartz_stairs@7"
            ]
        },
        {
            "x": -7,
            "y": 9,
            "z": 16,
            "elements": [
                "twilightforest:castle_stairs@10"
            ]
        },
        {
            "x": 10,
            "y": 0,
            "z": 0,
            "elements": [
                "casings_all"
            ]
        },
        {
            "x": -7,
            "y": 11,
            "z": 18,
            "elements": [
                "quark:elder_sea_lantern@0"
            ]
        },
        {
            "x": 3,
            "y": 7,
            "z": 11,
            "elements": [
                "tconstruct:seared_stairs_paver@7"
            ]
        },
        {
            "x": 0,
            "y": 12,
            "z": 10,
            "elements": [
                "enderio:block_alloy@6"
            ]
        },
        {
            "x": -5,
            "y": 5,
            "z": 16,
            "elements": [
                "twilightforest:castle_stairs_brick@5"
            ]
        },
        {
            "x": 3,
            "y": 0,
            "z": 5,
            "elements": [
                "twilightforest:castle_stairs@2"
            ]
        },
        {
            "x": 11,
            "y": 8,
            "z": 18,
            "elements": [
                "astralsorcery:blockmarbleslab@0"
            ]
        },
        {
            "x": 5,
            "y": -1,
            "z": 13,
            "elements": [
                "astralsorcery:blockmarbleslab@0"
            ]
        },
        {
            "x": -5,
            "y": 2,
            "z": 3,
            "elements": [
                "minecraft:quartz_stairs@3"
            ]
        },
        {
            "x": 6,
            "y": 2,
            "z": 8,
            "elements": [
                "actuallyadditions:block_quartz_wall@0"
            ]
        },
        {
            "x": 4,
            "y": 0,
            "z": 10,
            "elements": [
                "additions:star_metal_block@0"
            ]
        },
        {
            "x": 4,
            "y": 4,
            "z": 10,
            "elements": [
                "minecraft:quartz_block@0"
            ]
        },
        {
            "x": -7,
            "y": -1,
            "z": 8,
            "elements": [
                "astralsorcery:blockmarble@3"
            ]
        },
        {
            "x": 1,
            "y": 6,
            "z": 10,
            "elements": [
                "thermaldynamics:duct_16@2"
            ]
        },
        {
            "x": 9,
            "y": 0,
            "z": 8,
            "elements": [
                "minecraft:hopper@0"
            ]
        },
        {
            "x": 1,
            "y": 2,
            "z": 10,
            "elements": [
                "thermaldynamics:duct_16@2"
            ]
        },
        {
            "x": -1,
            "y": -1,
            "z": 8,
            "elements": [
                "casings_all"
            ]
        },
        {
            "x": -2,
            "y": 8,
            "z": 3,
            "elements": [
                "minecraft:quartz_stairs@5"
            ]
        },
        {
            "x": 11,
            "y": 11,
            "z": 17,
            "elements": [
                "astralsorcery:blockmarble@6"
            ]
        },
        {
            "x": 11,
            "y": 5,
            "z": 18,
            "elements": [
                "twilightforest:castle_stairs_brick@7"
            ]
        },
        {
            "x": 9,
            "y": 8,
            "z": 1,
            "elements": [
                "astralsorcery:blockmarble@2"
            ]
        },
        {
            "x": 10,
            "y": 10,
            "z": 1,
            "elements": [
                "twilightforest:castle_pillar@1"
            ]
        },
        {
            "x": -3,
            "y": -1,
            "z": 9,
            "elements": [
                "astralsorcery:blockmarble@3"
            ]
        },
        {
            "x": 4,
            "y": -1,
            "z": 13,
            "elements": [
                "astralsorcery:blockmarbleslab@0"
            ]
        },
        {
            "x": 6,
            "y": 9,
            "z": 14,
            "elements": [
                "minecraft:iron_trapdoor@2"
            ]
        },
        {
            "x": -2,
            "y": -1,
            "z": 4,
            "elements": [
                "casings_all"
            ]
        },
        {
            "x": -7,
            "y": 9,
            "z": 18,
            "elements": [
                "twilightforest:castle_stairs@8"
            ]
        },
        {
            "x": 11,
            "y": 10,
            "z": 17,
            "elements": [
                "twilightforest:castle_stairs@9"
            ]
        },
        {
            "x": -7,
            "y": 2,
            "z": 0,
            "elements": [
                "compactmachines3:wallbreakable@0"
            ]
        },
        {
            "x": 8,
            "y": 0,
            "z": 13,
            "elements": [
                "minecraft:quartz_stairs@2"
            ]
        },
        {
            "x": 11,
            "y": 4,
            "z": 18,
            "elements": [
                "compactmachines3:wallbreakable@0"
            ]
        },
        {
            "x": 0,
            "y": 11,
            "z": 8,
            "elements": [
                "thermaldynamics:duct_16@2"
            ]
        },
        {
            "x": 3,
            "y": 8,
            "z": 8,
            "elements": [
                "thermaldynamics:duct_16@2"
            ]
        },
        {
            "x": 3,
            "y": 13,
            "z": 12,
            "elements": [
                "enderio:block_alloy@6"
            ]
        },
        {
            "x": 10,
            "y": 4,
            "z": 0,
            "elements": [
                "actuallyadditions:block_quartz_wall@0"
            ]
        },
        {
            "x": 11,
            "y": 3,
            "z": 18,
            "elements": [
                "compactmachines3:wallbreakable@0"
            ]
        },
        {
            "x": -7,
            "y": 5,
            "z": 16,
            "elements": [
                "twilightforest:castle_stairs_brick@4"
            ]
        },
        {
            "x": 11,
            "y": 8,
            "z": 17,
            "elements": [
                "astralsorcery:blockmarble@2"
            ]
        },
        {
            "x": -4,
            "y": 9,
            "z": 4,
            "elements": [
                "twilightforest:castle_stairs@8"
            ]
        },
        {
            "x": 2,
            "y": 15,
            "z": 12,
            "elements": [
                "casings_all"
            ]
        },
        {
            "x": 3,
            "y": 3,
            "z": 11,
            "elements": [
                "minecraft:quartz_block@0"
            ]
        },
        {
            "x": 0,
            "y": 0,
            "z": 3,
            "elements": [
                "twilightforest:castle_pillar@6"
            ]
        },
        {
            "x": 9,
            "y": 0,
            "z": 1,
            "elements": [
                "casings_all"
            ]
        },
        {
            "x": -2,
            "y": 0,
            "z": 10,
            "elements": [
                "twilightforest:castle_stairs@0"
            ]
        },
        {
            "x": 0,
            "y": 9,
            "z": 8,
            "elements": [
                "thermaldynamics:duct_16@2"
            ]
        },
        {
            "x": 0,
            "y": 1,
            "z": 11,
            "elements": [
                "thermaldynamics:duct_0@3"
            ]
        },
        {
            "x": 2,
            "y": -1,
            "z": 11,
            "elements": [
                "modularmachinery:blockcasing@4"
            ]
        },
        {
            "x": -4,
            "y": 8,
            "z": 3,
            "elements": [
                "twilightforest:castle_pillar@5"
            ]
        },
        {
            "x": -7,
            "y": 10,
            "z": 17,
            "elements": [
                "twilightforest:castle_stairs@8"
            ]
        },
        {
            "x": 11,
            "y": 6,
            "z": 17,
            "elements": [
                "astralsorcery:blockmarble@2"
            ]
        },
        {
            "x": -3,
            "y": 6,
            "z": 3,
            "elements": [
                "chisel:glasspane@0"
            ]
        },
        {
            "x": -4,
            "y": 6,
            "z": 15,
            "elements": [
                "twilightforest:castle_pillar@5"
            ]
        },
        {
            "x": 6,
            "y": 0,
            "z": 14,
            "elements": [
                "twilightforest:castle_stairs@0"
            ]
        },
        {
            "x": 10,
            "y": -1,
            "z": 13,
            "elements": [
                "compactmachines3:wallbreakable@0"
            ]
        },
        {
            "x": 0,
            "y": 10,
            "z": 8,
            "elements": [
                "thermaldynamics:duct_16@2"
            ]
        },
        {
            "x": -7,
            "y": 11,
            "z": 17,
            "elements": [
                "astralsorcery:blockmarble@6"
            ]
        },
        {
            "x": 11,
            "y": 1,
            "z": 18,
            "elements": [
                "actuallyadditions:block_quartz_wall@0"
            ]
        },
        {
            "x": 11,
            "y": 7,
            "z": 17,
            "elements": [
                "astralsorcery:blockmarble@2"
            ]
        },
        {
            "x": 11,
            "y": 4,
            "z": 17,
            "elements": [
                "actuallyadditions:block_quartz_wall@0"
            ]
        },
        {
            "x": 0,
            "y": 6,
            "z": 8,
            "elements": [
                "casings_all"
            ]
        },
        {
            "x": 3,
            "y": 4,
            "z": 8,
            "elements": [
                "thermaldynamics:duct_16@2"
            ]
        },
        {
            "x": 11,
            "y": 0,
            "z": 18,
            "elements": [
                "actuallyadditions:block_quartz_wall@0"
            ]
        },
        {
            "x": 11,
            "y": -1,
            "z": 1,
            "elements": [
                "nuclearcraft:ingot_block@8"
            ]
        },
        {
            "x": 0,
            "y": -1,
            "z": 4,
            "elements": [
                "astralsorcery:blockmarble@3"
            ]
        },
        {
            "x": 0,
            "y": 5,
            "z": 8,
            "elements": [
                "minecraft:quartz_block@0"
            ]
        },
        {
            "x": 0,
            "y": 5,
            "z": 11,
            "elements": [
                "thermaldynamics:duct_0@3"
            ]
        },
        {
            "x": 2,
            "y": -1,
            "z": 14,
            "elements": [
                "astralsorcery:blockmarble@3"
            ]
        },
        {
            "x": 1,
            "y": 3,
            "z": 11,
            "elements": [
                "minecraft:quartz_block@0"
            ]
        },
        {
            "x": 9,
            "y": 4,
            "z": 1,
            "elements": [
                "actuallyadditions:block_quartz_wall@0"
            ]
        },
        {
            "x": -2,
            "y": 0,
            "z": 3,
            "elements": [
                "minecraft:quartz_stairs@1"
            ]
        },
        {
            "x": -7,
            "y": 1,
            "z": 16,
            "elements": [
                "actuallyadditions:block_quartz_wall@0"
            ]
        },
        {
            "x": 10,
            "y": -1,
            "z": 18,
            "elements": [
                "nuclearcraft:ingot_block@8"
            ]
        },
        {
            "x": 10,
            "y": 8,
            "z": 0,
            "elements": [
                "astralsorcery:blockmarble@2"
            ]
        },
        {
            "x": 11,
            "y": 2,
            "z": 17,
            "elements": [
                "casings_all"
            ]
        },
        {
            "x": 4,
            "y": -1,
            "z": 18,
            "elements": [
                "astralsorcery:blockmarble@3"
            ]
        },
        {
            "x": -5,
            "y": 6,
            "z": 3,
            "elements": [
                "actuallyadditions:block_quartz_wall@0"
            ]
        },
        {
            "x": -4,
            "y": 4,
            "z": 3,
            "elements": [
                "minecraft:quartz_stairs@7"
            ]
        },
        {
            "x": -7,
            "y": -1,
            "z": 16,
            "elements": [
                "compactmachines3:wallbreakable@0"
            ]
        },
        {
            "x": 11,
            "y": 3,
            "z": 17,
            "elements": [
                "actuallyadditions:block_quartz_wall@0"
            ]
        },
        {
            "x": -6,
            "y": -1,
            "z": 4,
            "elements": [
                "twilightforest:castle_pillar@5"
            ]
        },
        {
            "x": -7,
            "y": -1,
            "z": 2,
            "elements": [
                "compactmachines3:wallbreakable@0"
            ]
        },
        {
            "x": 1,
            "y": -1,
            "z": 9,
            "elements": [
                "modularmachinery:blockcasing@4"
            ]
        },
        {
            "x": 0,
            "y": 7,
            "z": 8,
            "elements": [
                "tconstruct:seared_stairs_paver@4"
            ]
        },
        {
            "x": 1,
            "y": 6,
            "z": 11,
            "elements": [
                "casings_all"
            ]
        },
        {
            "x": 0,
            "y": 17,
            "z": 10,
            "elements": [
                "quark:blaze_lantern@0"
            ]
        },
        {
            "x": 7,
            "y": 2,
            "z": 11,
            "elements": [
                "actuallyadditions:block_quartz_wall@0"
            ]
        },
        {
            "x": 5,
            "y": -1,
            "z": 15,
            "elements": [
                "casings_all"
            ]
        },
        {
            "x": -7,
            "y": 7,
            "z": 17,
            "elements": [
                "astralsorcery:blockmarble@2"
            ]
        },
        {
            "x": 12,
            "y": -1,
            "z": 10,
            "elements": [
                "astralsorcery:blockmarbleslab@0"
            ]
        },
        {
            "x": -6,
            "y": 7,
            "z": 16,
            "elements": [
                "astralsorcery:blockmarble@2"
            ]
        },
        {
            "x": 1,
            "y": 7,
            "z": 11,
            "elements": [
                "tconstruct:seared_stairs_paver@7"
            ]
        },
        {
            "x": 6,
            "y": -1,
            "z": 4,
            "elements": [
                "casings_all"
            ]
        },
        {
            "x": 7,
            "y": 0,
            "z": 4,
            "elements": [
                "casings_all"
            ]
        },
        {
            "x": 7,
            "y": 3,
            "z": 11,
            "elements": [
                "enderio:block_dark_iron_bars@0"
            ]
        },
        {
            "x": 3,
            "y": 1,
            "z": 16,
            "elements": [
                "quark:acacia_trapdoor@6"
            ]
        },
        {
            "x": 0,
            "y": 7,
            "z": 9,
            "elements": [
                "twilightforest:castle_stairs@4"
            ]
        },
        {
            "x": 4,
            "y": 1,
            "z": 11,
            "elements": [
                "thermaldynamics:duct_0@3"
            ]
        },
        {
            "x": 0,
            "y": 6,
            "z": 9,
            "elements": [
                "casings_all"
            ]
        },
        {
            "x": 5,
            "y": -1,
            "z": 16,
            "elements": [
                "casings_all"
            ]
        },
        {
            "x": 10,
            "y": 0,
            "z": 10,
            "elements": [
                "minecraft:hopper@0"
            ]
        },
        {
            "x": -6,
            "y": 6,
            "z": 16,
            "elements": [
                "astralsorcery:blockmarble@2"
            ]
        },
        {
            "x": 8,
            "y": 1,
            "z": 7,
            "elements": [
                "casings_parallel_and_upgrade"
            ]
        },
        {
            "x": -1,
            "y": -1,
            "z": 12,
            "elements": [
                "compactmachines3:wallbreakable@0"
            ]
        },
        {
            "x": 3,
            "y": 1,
            "z": 9,
            "elements": [
                "thermalfoundation:fluid_cryotheum@0"
            ]
        },
        {
            "x": 1,
            "y": 17,
            "z": 10,
            "elements": [
                "astralsorcery:blockmarble@2"
            ]
        },
        {
            "x": 1,
            "y": 4,
            "z": 11,
            "elements": [
                "minecraft:quartz_block@0"
            ]
        },
        {
            "x": 7,
            "y": 0,
            "z": 11,
            "elements": [
                "twilightforest:castle_stairs@0"
            ]
        },
        {
            "x": 11,
            "y": -1,
            "z": 10,
            "elements": [
                "astralsorcery:blockmarble@3"
            ]
        },
        {
            "x": 3,
            "y": 1,
            "z": 2,
            "elements": [
                "quark:acacia_trapdoor@6"
            ]
        },
        {
            "x": -4,
            "y": 9,
            "z": 14,
            "elements": [
                "twilightforest:castle_stairs@8"
            ]
        },
        {
            "x": -6,
            "y": 3,
            "z": 2,
            "elements": [
                "actuallyadditions:block_quartz_wall@0"
            ]
        },
        {
            "x": 6,
            "y": 0,
            "z": 16,
            "elements": [
                "twilightforest:castle_stairs@0"
            ]
        },
        {
            "x": -5,
            "y": 0,
            "z": 8,
            "elements": [
                "minecraft:hopper@0"
            ]
        },
        {
            "x": -5,
            "y": -1,
            "z": 2,
            "elements": [
                "compactmachines3:wallbreakable@0"
            ]
        },
        {
            "x": -6,
            "y": 8,
            "z": 16,
            "elements": [
                "astralsorcery:blockmarble@2"
            ]
        },
        {
            "x": 3,
            "y": 5,
            "z": 12,
            "elements": [
                "nuclearcraft:ingot_block@8"
            ]
        },
        {
            "x": 1,
            "y": 18,
            "z": 10,
            "elements": [
                "astralsorcery:blockmarble@2"
            ]
        },
        {
            "x": -7,
            "y": 4,
            "z": 18,
            "elements": [
                "compactmachines3:wallbreakable@0"
            ]
        },
        {
            "x": 10,
            "y": -1,
            "z": -1,
            "elements": [
                "twilightforest:castle_stairs@11"
            ]
        },
        {
            "x": 11,
            "y": -1,
            "z": 16,
            "elements": [
                "compactmachines3:wallbreakable@0"
            ]
        },
        {
            "x": 1,
            "y": 11,
            "z": 11,
            "elements": [
                "thermaldynamics:duct_16@2"
            ]
        },
        {
            "x": -6,
            "y": 2,
            "z": 16,
            "elements": [
                "casings_all"
            ]
        },
        {
            "x": -7,
            "y": 3,
            "z": 17,
            "elements": [
                "actuallyadditions:block_quartz_wall@0"
            ]
        },
        {
            "x": -8,
            "y": -1,
            "z": -1,
            "elements": [
                "twilightforest:castle_stairs@11"
            ]
        },
        {
            "x": 7,
            "y": 7,
            "z": 5,
            "elements": [
                "thaumicaugmentation:fortified_glass_pane@0"
            ]
        },
        {
            "x": 2,
            "y": 12,
            "z": 6,
            "elements": [
                "enderio:block_alloy@6"
            ]
        },
        {
            "x": 3,
            "y": 10,
            "z": 10,
            "elements": [
                "netherex:quartz_wall@0"
            ]
        },
        {
            "x": -1,
            "y": 4,
            "z": 8,
            "elements": [
                "actuallyadditions:block_quartz_wall@0"
            ]
        },
        {
            "x": 7,
            "y": 8,
            "z": 5,
            "elements": [
                "thaumicaugmentation:fortified_glass_pane@0"
            ]
        },
        {
            "x": -2,
            "y": 2,
            "z": 8,
            "elements": [
                "actuallyadditions:block_quartz_wall@0"
            ]
        },
        {
            "x": 4,
            "y": 5,
            "z": 11,
            "elements": [
                "thermaldynamics:duct_0@3"
            ]
        },
        {
            "x": 1,
            "y": 10,
            "z": 11,
            "elements": [
                "thermaldynamics:duct_16@2"
            ]
        },
        {
            "x": -2,
            "y": -1,
            "z": 14,
            "elements": [
                "casings_all"
            ]
        },
        {
            "x": -6,
            "y": 3,
            "z": 16,
            "elements": [
                "actuallyadditions:block_quartz_wall@0"
            ]
        },
        {
            "x": 1,
            "y": 0,
            "z": 8,
            "elements": [
                "thermaldynamics:duct_16@2"
            ]
        },
        {
            "x": 0,
            "y": 2,
            "z": 9,
            "elements": [
                "chisel:glasspane@0"
            ]
        },
        {
            "x": -3,
            "y": 1,
            "z": 16,
            "elements": [
                "minecraft:quartz_stairs@1"
            ]
        },
        {
            "x": 2,
            "y": 1,
            "z": 7,
            "elements": [
                "chisel:glasspane@0"
            ]
        },
        {
            "x": 11,
            "y": 6,
            "z": 0,
            "elements": [
                "twilightforest:castle_stairs_brick@6"
            ]
        },
        {
            "x": -2,
            "y": -1,
            "z": 17,
            "elements": [
                "compactmachines3:wallbreakable@0"
            ]
        },
        {
            "x": 6,
            "y": -1,
            "z": 11,
            "elements": [
                "astralsorcery:blockmarbleslab@0"
            ]
        },
        {
            "x": 7,
            "y": 2,
            "z": 10,
            "elements": [
                "actuallyadditions:block_quartz_wall@0"
            ]
        },
        {
            "x": -6,
            "y": 7,
            "z": 2,
            "elements": [
                "astralsorcery:blockmarble@2"
            ]
        },
        {
            "x": -4,
            "y": 5,
            "z": 14,
            "elements": [
                "minecraft:quartz_stairs@6"
            ]
        },
        {
            "x": 0,
            "y": 3,
            "z": 9,
            "elements": [
                "twilightforest:castle_stairs_brick@4"
            ]
        },
        {
            "x": -4,
            "y": 1,
            "z": 7,
            "elements": [
                "casings_parallel_and_upgrade"
            ]
        },
        {
            "x": 7,
            "y": 9,
            "z": 5,
            "elements": [
                "minecraft:iron_trapdoor@1"
            ]
        },
        {
            "x": -6,
            "y": 4,
            "z": 16,
            "elements": [
                "actuallyadditions:block_quartz_wall@0"
            ]
        },
        {
            "x": 11,
            "y": 10,
            "z": 0,
            "elements": [
                "astralsorcery:blockmarbleslab@8"
            ]
        },
        {
            "x": 6,
            "y": 5,
            "z": 15,
            "elements": [
                "minecraft:iron_trapdoor@10"
            ]
        },
        {
            "x": 5,
            "y": -1,
            "z": 2,
            "elements": [
                "casings_all"
            ]
        },
        {
            "x": 5,
            "y": -1,
            "z": 12,
            "elements": [
                "compactmachines3:wallbreakable@0"
            ]
        },
        {
            "x": -3,
            "y": 1,
            "z": 2,
            "elements": [
                "minecraft:quartz_stairs@1"
            ]
        },
        {
            "x": 2,
            "y": 0,
            "z": 6,
            "elements": [
                "enderio:block_alloy@6"
            ]
        },
        {
            "x": 3,
            "y": 1,
            "z": 12,
            "elements": [
                "actuallyadditions:block_quartz_wall@0"
            ]
        },
        {
            "x": -2,
            "y": -1,
            "z": 7,
            "elements": [
                "astralsorcery:blockmarbleslab@0"
            ]
        },
        {
            "x": 6,
            "y": 6,
            "z": 15,
            "elements": [
                "minecraft:quartz_stairs@0"
            ]
        },
        {
            "x": 6,
            "y": 0,
            "z": 9,
            "elements": [
                "twilightforest:castle_stairs@1"
            ]
        },
        {
            "x": 5,
            "y": -1,
            "z": 9,
            "elements": [
                "compactmachines3:wallbreakable@0"
            ]
        },
        {
            "x": 1,
            "y": 8,
            "z": 11,
            "elements": [
                "thermaldynamics:duct_16@2"
            ]
        },
        {
            "x": 0,
            "y": 4,
            "z": 9,
            "elements": [
                "twilightforest:castle_stairs_brick@4"
            ]
        },
        {
            "x": -7,
            "y": 0,
            "z": 18,
            "elements": [
                "actuallyadditions:block_quartz_wall@0"
            ]
        },
        {
            "x": 3,
            "y": 2,
            "z": 13,
            "elements": [
                "actuallyadditions:block_quartz_wall@0"
            ]
        },
        {
            "x": 1,
            "y": 9,
            "z": 10,
            "elements": [
                "netherex:quartz_wall@0"
            ]
        },
        {
            "x": 1,
            "y": 12,
            "z": 11,
            "elements": [
                "enderio:block_alloy@6"
            ]
        },
        {
            "x": -3,
            "y": 6,
            "z": 13,
            "elements": [
                "thaumicaugmentation:fortified_glass_pane@0"
            ]
        },
        {
            "x": 1,
            "y": 10,
            "z": 10,
            "elements": [
                "netherex:quartz_wall@0"
            ]
        },
        {
            "x": -5,
            "y": 4,
            "z": 1,
            "elements": [
                "actuallyadditions:block_quartz_wall@0"
            ]
        },
        {
            "x": -8,
            "y": -1,
            "z": 17,
            "elements": [
                "twilightforest:castle_stairs@9"
            ]
        },
        {
            "x": -6,
            "y": 6,
            "z": 18,
            "elements": [
                "astralsorcery:blockmarble@2"
            ]
        },
        {
            "x": 1,
            "y": 7,
            "z": 7,
            "elements": [
                "tconstruct:seared_stairs_paver@6"
            ]
        },
        {
            "x": 1,
            "y": 0,
            "z": 1,
            "elements": [
                "minecraft:hopper@0"
            ]
        },
        {
            "x": 11,
            "y": 2,
            "z": 0,
            "elements": [
                "compactmachines3:wallbreakable@0"
            ]
        },
        {
            "x": -6,
            "y": 11,
            "z": 2,
            "elements": [
                "astralsorcery:blockmarble@6"
            ]
        },
        {
            "x": -1,
            "y": 0,
            "z": 8,
            "elements": [
                "compactmachines3:wallbreakable@0"
            ]
        },
        {
            "x": 3,
            "y": 6,
            "z": 10,
            "elements": [
                "thermaldynamics:duct_16@2"
            ]
        },
        {
            "x": 4,
            "y": 8,
            "z": 10,
            "elements": [
                "thermaldynamics:duct_16@2"
            ]
        },
        {
            "x": 2,
            "y": 5,
            "z": 7,
            "elements": [
                "twilightforest:castle_stairs_brick@6"
            ]
        },
        {
            "x": -7,
            "y": 9,
            "z": 2,
            "elements": [
                "twilightforest:castle_stairs@8"
            ]
        },
        {
            "x": 4,
            "y": -1,
            "z": 14,
            "elements": [
                "astralsorcery:blockmarble@3"
            ]
        },
        {
            "x": 10,
            "y": 11,
            "z": 18,
            "elements": [
                "astralsorcery:blockmarble@6"
            ]
        },
        {
            "x": -4,
            "y": 7,
            "z": 2,
            "elements": [
                "actuallyadditions:block_quartz_wall@0"
            ]
        },
        {
            "x": 6,
            "y": 0,
            "z": 10,
            "elements": [
                "twilightforest:castle_stairs@1"
            ]
        },
        {
            "x": 8,
            "y": -1,
            "z": 11,
            "elements": [
                "astralsorcery:blockmarble@3"
            ]
        },
        {
            "x": 4,
            "y": -1,
            "z": 7,
            "elements": [
                "casings_all"
            ]
        },
        {
            "x": 0,
            "y": 0,
            "z": 9,
            "elements": [
                "compactmachines3:wallbreakable@0"
            ]
        },
        {
            "x": -1,
            "y": -1,
            "z": 2,
            "elements": [
                "casings_all"
            ]
        },
        {
            "x": 9,
            "y": 9,
            "z": 16,
            "elements": [
                "twilightforest:castle_stairs@10"
            ]
        },
        {
            "x": 1,
            "y": 11,
            "z": 10,
            "elements": [
                "enderio:block_alloy@6"
            ]
        },
        {
            "x": 4,
            "y": 13,
            "z": 11,
            "elements": [
                "tconevo:metal_block@5"
            ]
        },
        {
            "x": -1,
            "y": -1,
            "z": 9,
            "elements": [
                "compactmachines3:wallbreakable@0"
            ]
        },
        {
            "x": 2,
            "y": 0,
            "z": 13,
            "elements": [
                "twilightforest:castle_stairs@3"
            ]
        },
        {
            "x": 4,
            "y": 12,
            "z": 10,
            "elements": [
                "enderio:block_alloy@6"
            ]
        },
        {
            "x": -5,
            "y": 0,
            "z": 1,
            "elements": [
                "casings_all"
            ]
        },
        {
            "x": 1,
            "y": 11,
            "z": 7,
            "elements": [
                "thermaldynamics:duct_16@2"
            ]
        },
        {
            "x": 10,
            "y": 2,
            "z": 1,
            "elements": [
                "compactmachines3:wallbreakable@0"
            ]
        },
        {
            "x": -3,
            "y": 0,
            "z": 8,
            "elements": [
                "minecraft:quartz_stairs@1"
            ]
        },
        {
            "x": -6,
            "y": 10,
            "z": 16,
            "elements": [
                "twilightforest:castle_stairs@10"
            ]
        },
        {
            "x": -1,
            "y": -1,
            "z": 16,
            "elements": [
                "casings_all"
            ]
        },
        {
            "x": -2,
            "y": 9,
            "z": 4,
            "elements": [
                "minecraft:iron_trapdoor@3"
            ]
        },
        {
            "x": -5,
            "y": 5,
            "z": 2,
            "elements": [
                "twilightforest:castle_stairs_brick@7"
            ]
        },
        {
            "x": -5,
            "y": 9,
            "z": 2,
            "elements": [
                "twilightforest:castle_stairs@11"
            ]
        },
        {
            "x": -6,
            "y": -1,
            "z": 17,
            "elements": [
                "compactmachines3:wallbreakable@0"
            ]
        },
        {
            "x": -6,
            "y": 0,
            "z": 9,
            "elements": [
                "astralsorcery:blockmarbleslab@0"
            ]
        },
        {
            "x": 6,
            "y": -1,
            "z": 3,
            "elements": [
                "compactmachines3:wallbreakable@0"
            ]
        },
        {
            "x": 0,
            "y": 0,
            "z": 16,
            "elements": [
                "twilightforest:castle_pillar@6"
            ]
        },
        {
            "x": 1,
            "y": 1,
            "z": 2,
            "elements": [
                "quark:acacia_trapdoor@7"
            ]
        },
        {
            "x": 5,
            "y": -1,
            "z": 10,
            "elements": [
                "casings_all"
            ]
        },
        {
            "x": 1,
            "y": -1,
            "z": 2,
            "elements": [
                "astralsorcery:blockmarble@3"
            ]
        },
        {
            "x": -7,
            "y": -1,
            "z": 9,
            "elements": [
                "astralsorcery:blockmarble@3"
            ]
        },
        {
            "x": -6,
            "y": 2,
            "z": 18,
            "elements": [
                "casings_all"
            ]
        },
        {
            "x": -4,
            "y": 8,
            "z": 13,
            "elements": [
                "minecraft:quartz_stairs@6"
            ]
        },
        {
            "x": -6,
            "y": 11,
            "z": 16,
            "elements": [
                "astralsorcery:blockmarble@6"
            ]
        },
        {
            "x": -5,
            "y": 3,
            "z": 17,
            "elements": [
                "actuallyadditions:block_quartz_wall@0"
            ]
        },
        {
            "x": 0,
            "y": 3,
            "z": 15,
            "elements": [
                "enderio:block_dark_iron_bars@0"
            ]
        },
        {
            "x": 2,
            "y": -1,
            "z": -1,
            "elements": [
                "astralsorcery:blockmarbleslab@0"
            ]
        },
        {
            "x": 1,
            "y": 17,
            "z": 9,
            "elements": [
                "thermaldynamics:duct_16@2"
            ]
        },
        {
            "x": 10,
            "y": 2,
            "z": 17,
            "elements": [
                "compactmachines3:wallbreakable@0"
            ]
        },
        {
            "x": 3,
            "y": 13,
            "z": 9,
            "elements": [
                "astralsorcery:blockmarble@2"
            ]
        },
        {
            "x": -6,
            "y": 6,
            "z": 1,
            "elements": [
                "twilightforest:castle_pillar@1"
            ]
        },
        {
            "x": -4,
            "y": 0,
            "z": 13,
            "elements": [
                "minecraft:quartz_stairs@2"
            ]
        },
        {
            "x": 3,
            "y": 0,
            "z": 15,
            "elements": [
                "minecraft:quartz_stairs@2"
            ]
        },
        {
            "x": -7,
            "y": 8,
            "z": 1,
            "elements": [
                "astralsorcery:blockmarble@2"
            ]
        },
        {
            "x": 0,
            "y": 2,
            "z": 15,
            "elements": [
                "actuallyadditions:block_quartz_wall@0"
            ]
        },
        {
            "x": 0,
            "y": -1,
            "z": 7,
            "elements": [
                "casings_all"
            ]
        },
        {
            "x": 11,
            "y": -1,
            "z": 9,
            "elements": [
                "astralsorcery:blockmarble@3"
            ]
        },
        {
            "x": 10,
            "y": 4,
            "z": 17,
            "elements": [
                "compactmachines3:wallbreakable@0"
            ]
        },
        {
            "x": 1,
            "y": 18,
            "z": 9,
            "elements": [
                "thermaldynamics:duct_16@2"
            ]
        },
        {
            "x": 0,
            "y": 0,
            "z": 6,
            "elements": [
                "extrautils2:decorativeglass@1"
            ]
        },
        {
            "x": 3,
            "y": -1,
            "z": 2,
            "elements": [
                "astralsorcery:blockmarble@3"
            ]
        },
        {
            "x": 4,
            "y": 10,
            "z": 8,
            "elements": [
                "thermaldynamics:duct_16@2"
            ]
        },
        {
            "x": -5,
            "y": 1,
            "z": 2,
            "elements": [
                "actuallyadditions:block_quartz_wall@0"
            ]
        },
        {
            "x": -1,
            "y": -1,
            "z": 15,
            "elements": [
                "casings_all"
            ]
        },
        {
            "x": -5,
            "y": 8,
            "z": 18,
            "elements": [
                "astralsorcery:blockmarbleslab@0"
            ]
        },
        {
            "x": 6,
            "y": -1,
            "z": 17,
            "elements": [
                "compactmachines3:wallbreakable@0"
            ]
        },
        {
            "x": 3,
            "y": 17,
            "z": 9,
            "elements": [
                "thermaldynamics:duct_16@2"
            ]
        },
        {
            "x": -6,
            "y": 10,
            "z": 18,
            "elements": [
                "twilightforest:castle_stairs@11"
            ]
        },
        {
            "x": 1,
            "y": 13,
            "z": 9,
            "elements": [
                "astralsorcery:blockmarble@2"
            ]
        },
        {
            "x": -5,
            "y": 7,
            "z": 17,
            "elements": [
                "astralsorcery:blockmarble@2"
            ]
        },
        {
            "x": 4,
            "y": 6,
            "z": 8,
            "elements": [
                "casings_all"
            ]
        },
        {
            "x": 4,
            "y": 11,
            "z": 9,
            "elements": [
                "enderio:block_alloy@6"
            ]
        },
        {
            "x": 1,
            "y": 3,
            "z": 7,
            "elements": [
                "minecraft:quartz_block@0"
            ]
        },
        {
            "x": -5,
            "y": 8,
            "z": 1,
            "elements": [
                "astralsorcery:blockmarble@2"
            ]
        },
        {
            "x": 10,
            "y": 0,
            "z": 17,
            "elements": [
                "casings_all"
            ]
        },
        {
            "x": 1,
            "y": 14,
            "z": 9,
            "elements": [
                "astralsorcery:blockmarble@2"
            ]
        },
        {
            "x": -6,
            "y": 10,
            "z": 1,
            "elements": [
                "twilightforest:castle_pillar@1"
            ]
        },
        {
            "x": -3,
            "y": -1,
            "z": 12,
            "elements": [
                "astralsorcery:blockmarbleslab@0"
            ]
        },
        {
            "x": 0,
            "y": 1,
            "z": 15,
            "elements": [
                "casings_parallel_and_upgrade"
            ]
        },
        {
            "x": 4,
            "y": 17,
            "z": 11,
            "elements": [
                "enderio:block_dark_iron_bars@0"
            ]
        },
        {
            "x": -7,
            "y": 0,
            "z": 8,
            "elements": [
                "twilightforest:castle_stairs@0"
            ]
        },
        {
            "x": -3,
            "y": -1,
            "z": 2,
            "elements": [
                "compactmachines3:wallbreakable@0"
            ]
        },
        {
            "x": 7,
            "y": 5,
            "z": 3,
            "elements": [
                "minecraft:quartz_stairs@4"
            ]
        },
        {
            "x": 1,
            "y": 16,
            "z": 9,
            "elements": [
                "astralsorcery:blockmarble@2"
            ]
        },
        {
            "x": -3,
            "y": 8,
            "z": 15,
            "elements": [
                "chisel:glasspane@0"
            ]
        },
        {
            "x": 1,
            "y": 0,
            "z": 18,
            "elements": [
                "twilightforest:castle_stairs@3"
            ]
        },
        {
            "x": 0,
            "y": 18,
            "z": 9,
            "elements": [
                "enderio:block_alloy@8"
            ]
        },
        {
            "x": -5,
            "y": 11,
            "z": 17,
            "elements": [
                "astralsorcery:blockmarble@6"
            ]
        },
        {
            "x": 7,
            "y": 6,
            "z": 3,
            "elements": [
                "chisel:glasspane@0"
            ]
        },
        {
            "x": 9,
            "y": 5,
            "z": 16,
            "elements": [
                "twilightforest:castle_stairs_brick@4"
            ]
        },
        {
            "x": 1,
            "y": 4,
            "z": 8,
            "elements": [
                "thermaldynamics:duct_16@2"
            ]
        },
        {
            "x": -7,
            "y": 0,
            "z": 1,
            "elements": [
                "casings_all"
            ]
        },
        {
            "x": 1,
            "y": 0,
            "z": 5,
            "elements": [
                "twilightforest:castle_stairs@2"
            ]
        },
        {
            "x": 7,
            "y": 7,
            "z": 3,
            "elements": [
                "chisel:glasspane@0"
            ]
        },
        {
            "x": 9,
            "y": 4,
            "z": 15,
            "elements": [
                "minecraft:quartz_stairs@6"
            ]
        },
        {
            "x": 6,
            "y": 7,
            "z": 15,
            "elements": [
                "minecraft:quartz_stairs@4"
            ]
        },
        {
            "x": -4,
            "y": -1,
            "z": 14,
            "elements": [
                "compactmachines3:wallbreakable@0"
            ]
        },
        {
            "x": 7,
            "y": 5,
            "z": 5,
            "elements": [
                "minecraft:iron_trapdoor@9"
            ]
        },
        {
            "x": 10,
            "y": 10,
            "z": 17,
            "elements": [
                "twilightforest:castle_pillar@1"
            ]
        },
        {
            "x": 0,
            "y": -1,
            "z": 17,
            "elements": [
                "astralsorcery:blockmarble@3"
            ]
        },
        {
            "x": 4,
            "y": 2,
            "z": 8,
            "elements": [
                "minecraft:quartz_block@0"
            ]
        },
        {
            "x": 7,
            "y": 0,
            "z": 8,
            "elements": [
                "minecraft:quartz_stairs@0"
            ]
        },
        {
            "x": -5,
            "y": -1,
            "z": 12,
            "elements": [
                "casings_all"
            ]
        },
        {
            "x": 7,
            "y": 9,
            "z": 3,
            "elements": [
                "twilightforest:castle_stairs@10"
            ]
        },
        {
            "x": 7,
            "y": 1,
            "z": 2,
            "elements": [
                "minecraft:quartz_stairs@0"
            ]
        },
        {
            "x": 6,
            "y": 9,
            "z": 15,
            "elements": [
                "astralsorcery:blockmarbleslab@0"
            ]
        },
        {
            "x": -4,
            "y": -1,
            "z": 7,
            "elements": [
                "astralsorcery:blockmarble@3"
            ]
        },
        {
            "x": -5,
            "y": 0,
            "z": 18,
            "elements": [
                "actuallyadditions:block_quartz_wall@0"
            ]
        },
        {
            "x": 0,
            "y": -1,
            "z": 5,
            "elements": [
                "astralsorcery:blockmarbleslab@0"
            ]
        },
        {
            "x": 11,
            "y": -1,
            "z": 15,
            "elements": [
                "twilightforest:castle_stairs@11"
            ]
        },
        {
            "x": -7,
            "y": -1,
            "z": 19,
            "elements": [
                "twilightforest:castle_stairs@10"
            ]
        },
        {
            "x": -7,
            "y": 4,
            "z": 1,
            "elements": [
                "actuallyadditions:block_quartz_wall@0"
            ]
        },
        {
            "x": 9,
            "y": 1,
            "z": 16,
            "elements": [
                "actuallyadditions:block_quartz_wall@0"
            ]
        },
        {
            "x": -4,
            "y": -1,
            "z": -1,
            "elements": [
                "twilightforest:castle_stairs@11"
            ]
        },
        {
            "x": 3,
            "y": 0,
            "z": 1,
            "elements": [
                "minecraft:hopper@0"
            ]
        },
        {
            "x": 1,
            "y": 8,
            "z": 8,
            "elements": [
                "thermaldynamics:duct_16@2"
            ]
        },
        {
            "x": 10,
            "y": 6,
            "z": 17,
            "elements": [
                "twilightforest:castle_pillar@1"
            ]
        },
        {
            "x": 0,
            "y": 11,
            "z": 9,
            "elements": [
                "enderio:block_alloy@6"
            ]
        },
        {
            "x": 3,
            "y": 9,
            "z": 9,
            "elements": [
                "astralsorcery:blockmarble@2"
            ]
        },
        {
            "x": 7,
            "y": 0,
            "z": 5,
            "elements": [
                "twilightforest:castle_stairs@3"
            ]
        },
        {
            "x": -3,
            "y": 3,
            "z": 7,
            "elements": [
                "enderio:block_dark_iron_bars@0"
            ]
        },
        {
            "x": 5,
            "y": 0,
            "z": 8,
            "elements": [
                "compactmachines3:wallbreakable@0"
            ]
        },
        {
            "x": 2,
            "y": 2,
            "z": 8,
            "elements": [
                "thermalfoundation:fluid_cryotheum@0"
            ]
        },
        {
            "x": 12,
            "y": -1,
            "z": 3,
            "elements": [
                "twilightforest:castle_stairs@8"
            ]
        },
        {
            "x": 9,
            "y": 1,
            "z": 2,
            "elements": [
                "actuallyadditions:block_quartz_wall@0"
            ]
        },
        {
            "x": 9,
            "y": -1,
            "z": 2,
            "elements": [
                "compactmachines3:wallbreakable@0"
            ]
        },
        {
            "x": 0,
            "y": 1,
            "z": 7,
            "elements": [
                "thermaldynamics:duct_0@3"
            ]
        },
        {
            "x": 3,
            "y": 5,
            "z": 9,
            "elements": [
                "twilightforest:aurora_block@0"
            ]
        },
        {
            "x": -6,
            "y": -1,
            "z": 7,
            "elements": [
                "astralsorcery:blockmarble@3"
            ]
        },
        {
            "x": 10,
            "y": 8,
            "z": 17,
            "elements": [
                "twilightforest:castle_pillar@1"
            ]
        },
        {
            "x": -5,
            "y": 4,
            "z": 18,
            "elements": [
                "compactmachines3:wallbreakable@0"
            ]
        },
        {
            "x": 6,
            "y": -1,
            "z": 5,
            "elements": [
                "astralsorcery:blockmarbleslab@0"
            ]
        },
        {
            "x": 2,
            "y": 6,
            "z": 8,
            "elements": [
                "twilightforest:aurora_block@0"
            ]
        },
        {
            "x": 6,
            "y": 6,
            "z": 4,
            "elements": [
                "thaumicaugmentation:fortified_glass_pane@0"
            ]
        },
        {
            "x": -6,
            "y": 1,
            "z": 10,
            "elements": [
                "quark:acacia_trapdoor@4"
            ]
        },
        {
            "x": 1,
            "y": 0,
            "z": 14,
            "elements": [
                "minecraft:quartz_stairs@2"
            ]
        },
        {
            "x": -6,
            "y": -1,
            "z": -1,
            "elements": [
                "twilightforest:castle_stairs@11"
            ]
        },
        {
            "x": 3,
            "y": -1,
            "z": 13,
            "elements": [
                "astralsorcery:blockmarble@3"
            ]
        },
        {
            "x": -6,
            "y": -1,
            "z": 15,
            "elements": [
                "twilightforest:castle_stairs@11"
            ]
        },
        {
            "x": 0,
            "y": -1,
            "z": 0,
            "elements": [
                "astralsorcery:blockmarble@3"
            ]
        },
        {
            "x": 9,
            "y": 5,
            "z": 17,
            "elements": [
                "twilightforest:castle_stairs_brick@4"
            ]
        },
        {
            "x": 0,
            "y": -1,
            "z": 14,
            "elements": [
                "astralsorcery:blockmarble@3"
            ]
        },
        {
            "x": -4,
            "y": -1,
            "z": 10,
            "elements": [
                "astralsorcery:blockmarble@3"
            ]
        },
        {
            "x": -6,
            "y": 9,
            "z": 0,
            "elements": [
                "twilightforest:castle_stairs@10"
            ]
        },
        {
            "x": 1,
            "y": 11,
            "z": 12,
            "elements": [
                "additions:stainless_steel_block@0"
            ]
        },
        {
            "x": 10,
            "y": -1,
            "z": 1,
            "elements": [
                "compactmachines3:wallbreakable@0"
            ]
        },
        {
            "x": 2,
            "y": 8,
            "z": 8,
            "elements": [
                "astralsorcery:blockmarble@2"
            ]
        },
        {
            "x": -5,
            "y": 11,
            "z": 0,
            "elements": [
                "quark:elder_sea_lantern@0"
            ]
        },
        {
            "x": 5,
            "y": 1,
            "z": 8,
            "elements": [
                "actuallyadditions:block_quartz_wall@0"
            ]
        },
        {
            "x": 9,
            "y": 5,
            "z": 3,
            "elements": [
                "minecraft:quartz_stairs@2"
            ]
        },
        {
            "x": -1,
            "y": 13,
            "z": 8,
            "elements": [
                "enderio:block_alloy@6"
            ]
        },
        {
            "x": -2,
            "y": 6,
            "z": 14,
            "elements": [
                "thaumicaugmentation:fortified_glass_pane@0"
            ]
        },
        {
            "x": -4,
            "y": -1,
            "z": 5,
            "elements": [
                "compactmachines3:wallbreakable@0"
            ]
        },
        {
            "x": 9,
            "y": 3,
            "z": 17,
            "elements": [
                "actuallyadditions:block_quartz_wall@0"
            ]
        },
        {
            "x": -4,
            "y": 5,
            "z": 5,
            "elements": [
                "minecraft:iron_trapdoor@10"
            ]
        },
        {
            "x": 9,
            "y": -1,
            "z": 18,
            "elements": [
                "compactmachines3:wallbreakable@0"
            ]
        },
        {
            "x": 11,
            "y": -1,
            "z": 3,
            "elements": [
                "twilightforest:castle_stairs@10"
            ]
        },
        {
            "x": 2,
            "y": 7,
            "z": 8,
            "elements": [
                "twilightforest:aurora_block@0"
            ]
        },
        {
            "x": 9,
            "y": 9,
            "z": 17,
            "elements": [
                "twilightforest:castle_stairs@8"
            ]
        },
        {
            "x": 2,
            "y": 11,
            "z": 8,
            "elements": [
                "astralsorcery:blockmarble@2"
            ]
        },
        {
            "x": -2,
            "y": -1,
            "z": 10,
            "elements": [
                "astralsorcery:blockmarble@3"
            ]
        },
        {
            "x": -3,
            "y": -1,
            "z": 13,
            "elements": [
                "casings_all"
            ]
        },
        {
            "x": 1,
            "y": 13,
            "z": 12,
            "elements": [
                "enderio:block_alloy@6"
            ]
        },
        {
            "x": 1,
            "y": 0,
            "z": 6,
            "elements": [
                "compactmachines3:wallbreakable@0"
            ]
        },
        {
            "x": -3,
            "y": 2,
            "z": 11,
            "elements": [
                "actuallyadditions:block_quartz_wall@0"
            ]
        },
        {
            "x": 9,
            "y": 2,
            "z": 17,
            "elements": [
                "casings_all"
            ]
        },
        {
            "x": 2,
            "y": 12,
            "z": 8,
            "elements": [
                "astralsorcery:blockmarble@2"
            ]
        },
        {
            "x": -8,
            "y": -1,
            "z": 15,
            "elements": [
                "twilightforest:castle_stairs@9"
            ]
        },
        {
            "x": 12,
            "y": -1,
            "z": 16,
            "elements": [
                "twilightforest:castle_stairs@8"
            ]
        },
        {
            "x": 7,
            "y": -1,
            "z": 8,
            "elements": [
                "astralsorcery:blockmarble@3"
            ]
        },
        {
            "x": 6,
            "y": 7,
            "z": 3,
            "elements": [
                "minecraft:quartz_stairs@4"
            ]
        },
        {
            "x": 9,
            "y": 6,
            "z": 17,
            "elements": [
                "astralsorcery:blockmarble@2"
            ]
        },
        {
            "x": -3,
            "y": 9,
            "z": 3,
            "elements": [
                "twilightforest:castle_stairs@10"
            ]
        },
        {
            "x": -6,
            "y": -1,
            "z": 5,
            "elements": [
                "compactmachines3:wallbreakable@0"
            ]
        },
        {
            "x": 5,
            "y": 5,
            "z": 8,
            "elements": [
                "nuclearcraft:ingot_block@8"
            ]
        },
        {
            "x": 1,
            "y": 15,
            "z": 12,
            "elements": [
                "enderio:block_alloy@6"
            ]
        },
        {
            "x": 2,
            "y": 10,
            "z": 8,
            "elements": [
                "astralsorcery:blockmarble@2"
            ]
        },
        {
            "x": 0,
            "y": -1,
            "z": 6,
            "elements": [
                "compactmachines3:wallbreakable@0"
            ]
        },
        {
            "x": 1,
            "y": 14,
            "z": 12,
            "elements": [
                "enderio:block_alloy@6"
            ]
        },
        {
            "x": 9,
            "y": 1,
            "z": 3,
            "elements": [
                "minecraft:quartz_stairs@6"
            ]
        },
        {
            "x": 9,
            "y": 7,
            "z": 17,
            "elements": [
                "astralsorcery:blockmarble@2"
            ]
        },
        {
            "x": -5,
            "y": 7,
            "z": 0,
            "elements": [
                "twilightforest:castle_stairs_brick@6"
            ]
        },
        {
            "x": 8,
            "y": 0,
            "z": 8,
            "elements": [
                "minecraft:quartz_stairs@0"
            ]
        },
        {
            "x": 8,
            "y": -1,
            "z": 17,
            "elements": [
                "twilightforest:castle_stairs@9"
            ]
        },
        {
            "x": 0,
            "y": 3,
            "z": 3,
            "elements": [
                "enderio:block_dark_iron_bars@0"
            ]
        },
        {
            "x": 11,
            "y": 11,
            "z": 1,
            "elements": [
                "astralsorcery:blockmarble@6"
            ]
        },
        {
            "x": 1,
            "y": 4,
            "z": 6,
            "elements": [
                "actuallyadditions:block_quartz_wall@0"
            ]
        },
        {
            "x": 1,
            "y": 3,
            "z": 12,
            "elements": [
                "actuallyadditions:block_quartz_wall@0"
            ]
        },
        {
            "x": 1,
            "y": 0,
            "z": 9,
            "elements": [
                "twilightforest:aurora_block@0"
            ]
        },
        {
            "x": 11,
            "y": 10,
            "z": 1,
            "elements": [
                "twilightforest:castle_stairs@9"
            ]
        },
        {
            "x": -4,
            "y": 9,
            "z": 5,
            "elements": [
                "astralsorcery:blockmarbleslab@0"
            ]
        },
        {
            "x": 11,
            "y": 4,
            "z": 1,
            "elements": [
                "actuallyadditions:block_quartz_wall@0"
            ]
        },
        {
            "x": 2,
            "y": 16,
            "z": 8,
            "elements": [
                "astralsorcery:blockmarble@2"
            ]
        },
        {
            "x": 4,
            "y": 1,
            "z": 7,
            "elements": [
                "thermaldynamics:duct_0@3"
            ]
        },
        {
            "x": 11,
            "y": 8,
            "z": 1,
            "elements": [
                "astralsorcery:blockmarble@2"
            ]
        },
        {
            "x": 0,
            "y": 2,
            "z": 4,
            "elements": [
                "actuallyadditions:block_quartz_wall@0"
            ]
        },
        {
            "x": 3,
            "y": 0,
            "z": 4,
            "elements": [
                "minecraft:quartz_stairs@3"
            ]
        },
        {
            "x": -8,
            "y": -1,
            "z": 10,
            "elements": [
                "astralsorcery:blockmarbleslab@0"
            ]
        },
        {
            "x": 1,
            "y": 2,
            "z": 12,
            "elements": [
                "actuallyadditions:block_quartz_wall@0"
            ]
        },
        {
            "x": 1,
            "y": 2,
            "z": 6,
            "elements": [
                "actuallyadditions:block_quartz_wall@0"
            ]
        },
        {
            "x": -4,
            "y": 4,
            "z": 16,
            "elements": [
                "minecraft:quartz_stairs@5"
            ]
        },
        {
            "x": 9,
            "y": 1,
            "z": 17,
            "elements": [
                "casings_all"
            ]
        },
        {
            "x": 2,
            "y": 14,
            "z": 8,
            "elements": [
                "astralsorcery:blockmarble@2"
            ]
        },
        {
            "x": 1,
            "y": 12,
            "z": 9,
            "elements": [
                "astralsorcery:blockmarble@2"
            ]
        },
        {
            "x": 4,
            "y": 6,
            "z": 9,
            "elements": [
                "casings_all"
            ]
        },
        {
            "x": 11,
            "y": 6,
            "z": 2,
            "elements": [
                "twilightforest:castle_stairs_brick@7"
            ]
        },
        {
            "x": -3,
            "y": 0,
            "z": 4,
            "elements": [
                "casings_all"
            ]
        },
        {
            "x": 2,
            "y": 15,
            "z": 8,
            "elements": [
                "astralsorcery:blockmarble@2"
            ]
        },
        {
            "x": 1,
            "y": 1,
            "z": 12,
            "elements": [
                "actuallyadditions:block_quartz_wall@0"
            ]
        },
        {
            "x": 2,
            "y": 0,
            "z": 16,
            "elements": [
                "astralsorcery:blockmarbleslab@0"
            ]
        },
        {
            "x": 9,
            "y": -1,
            "z": 8,
            "elements": [
                "astralsorcery:blockmarble@3"
            ]
        },
        {
            "x": 10,
            "y": 7,
            "z": 18,
            "elements": [
                "astralsorcery:blockmarble@2"
            ]
        },
        {
            "x": 4,
            "y": -1,
            "z": 0,
            "elements": [
                "astralsorcery:blockmarble@3"
            ]
        },
        {
            "x": 4,
            "y": 2,
            "z": 14,
            "elements": [
                "actuallyadditions:block_quartz_wall@0"
            ]
        },
        {
            "x": -5,
            "y": 3,
            "z": 0,
            "elements": [
                "compactmachines3:wallbreakable@0"
            ]
        },
        {
            "x": 1,
            "y": 3,
            "z": 6,
            "elements": [
                "actuallyadditions:block_quartz_wall@0"
            ]
        },
        {
            "x": -3,
            "y": 7,
            "z": 5,
            "elements": [
                "thaumicaugmentation:fortified_glass_pane@0"
            ]
        },
        {
            "x": -5,
            "y": 7,
            "z": 15,
            "elements": [
                "actuallyadditions:block_quartz_wall@0"
            ]
        },
        {
            "x": -5,
            "y": 6,
            "z": 16,
            "elements": [
                "twilightforest:castle_stairs_brick@6"
            ]
        },
        {
            "x": -7,
            "y": 7,
            "z": 0,
            "elements": [
                "twilightforest:castle_stairs_brick@6"
            ]
        },
        {
            "x": 6,
            "y": -1,
            "z": 6,
            "elements": [
                "astralsorcery:blockmarbleslab@0"
            ]
        },
        {
            "x": 5,
            "y": -1,
            "z": 3,
            "elements": [
                "casings_all"
            ]
        },
        {
            "x": 2,
            "y": -1,
            "z": 10,
            "elements": [
                "modularmachinery:blockcasing@4"
            ]
        },
        {
            "x": -5,
            "y": 0,
            "z": 14,
            "elements": [
                "minecraft:quartz_block@0"
            ]
        },
        {
            "x": 1,
            "y": 6,
            "z": 12,
            "elements": [
                "tconstruct:seared_stairs_paver@7"
            ]
        },
        {
            "x": 0,
            "y": 1,
            "z": 10,
            "elements": [
                "compactmachines3:wallbreakable@0"
            ]
        },
        {
            "x": -6,
            "y": -1,
            "z": 14,
            "elements": [
                "twilightforest:castle_pillar@5"
            ]
        },
        {
            "x": -4,
            "y": -1,
            "z": 15,
            "elements": [
                "twilightforest:castle_stairs@11"
            ]
        },
        {
            "x": 9,
            "y": 0,
            "z": 4,
            "elements": [
                "minecraft:quartz_block@0"
            ]
        },
        {
            "x": 4,
            "y": 2,
            "z": 9,
            "elements": [
                "chisel:glasspane@0"
            ]
        },
        {
            "x": 7,
            "y": 0,
            "z": 9,
            "elements": [
                "minecraft:quartz_stairs@0"
            ]
        },
        {
            "x": 11,
            "y": 0,
            "z": 1,
            "elements": [
                "casings_all"
            ]
        },
        {
            "x": -6,
            "y": -1,
            "z": 0,
            "elements": [
                "nuclearcraft:ingot_block@8"
            ]
        },
        {
            "x": 4,
            "y": 0,
            "z": 12,
            "elements": [
                "extrautils2:decorativeglass@1"
            ]
        },
        {
            "x": 1,
            "y": 4,
            "z": 9,
            "elements": [
                "twilightforest:aurora_block@0"
            ]
        },
        {
            "x": 1,
            "y": 6,
            "z": 6,
            "elements": [
                "tconstruct:seared_stairs_paver@6"
            ]
        },
        {
            "x": -7,
            "y": 11,
            "z": 0,
            "elements": [
                "quark:elder_sea_lantern@0"
            ]
        },
        {
            "x": 11,
            "y": 3,
            "z": 1,
            "elements": [
                "actuallyadditions:block_quartz_wall@0"
            ]
        },
        {
            "x": 1,
            "y": 8,
            "z": 9,
            "elements": [
                "astralsorcery:blockmarble@2"
            ]
        },
        {
            "x": 11,
            "y": 10,
            "z": 2,
            "elements": [
                "astralsorcery:blockmarbleslab@8"
            ]
        },
        {
            "x": 2,
            "y": 18,
            "z": 8,
            "elements": [
                "thermaldynamics:duct_16@2"
            ]
        },
        {
            "x": -2,
            "y": -1,
            "z": 5,
            "elements": [
                "astralsorcery:blockmarbleslab@0"
            ]
        },
        {
            "x": -5,
            "y": 10,
            "z": 16,
            "elements": [
                "astralsorcery:blockmarbleslab@8"
            ]
        },
        {
            "x": -5,
            "y": 1,
            "z": 14,
            "elements": [
                "minecraft:quartz_stairs@2"
            ]
        },
        {
            "x": 10,
            "y": 3,
            "z": 18,
            "elements": [
                "actuallyadditions:block_quartz_wall@0"
            ]
        },
        {
            "x": 5,
            "y": 13,
            "z": 8,
            "elements": [
                "enderio:block_alloy@6"
            ]
        },
        {
            "x": 1,
            "y": 5,
            "z": 12,
            "elements": [
                "nuclearcraft:ingot_block@8"
            ]
        },
        {
            "x": 9,
            "y": 1,
            "z": 18,
            "elements": [
                "actuallyadditions:block_quartz_wall@0"
            ]
        },
        {
            "x": -6,
            "y": 0,
            "z": 11,
            "elements": [
                "twilightforest:castle_pillar@4"
            ]
        },
        {
            "x": 11,
            "y": 2,
            "z": 1,
            "elements": [
                "casings_all"
            ]
        },
        {
            "x": 11,
            "y": -1,
            "z": 18,
            "elements": [
                "compactmachines3:wallbreakable@0"
            ]
        },
        {
            "x": 7,
            "y": 2,
            "z": 7,
            "elements": [
                "actuallyadditions:block_quartz_wall@0"
            ]
        },
        {
            "x": 3,
            "y": -1,
            "z": 3,
            "elements": [
                "astralsorcery:blockmarble@3"
            ]
        },
        {
            "x": 6,
            "y": -1,
            "z": 12,
            "elements": [
                "astralsorcery:blockmarbleslab@0"
            ]
        },
        {
            "x": -2,
            "y": 6,
            "z": 4,
            "elements": [
                "thaumicaugmentation:fortified_glass_pane@0"
            ]
        },
        {
            "x": 7,
            "y": 5,
            "z": 14,
            "elements": [
                "minecraft:iron_trapdoor@10"
            ]
        },
        {
            "x": -3,
            "y": 0,
            "z": 9,
            "elements": [
                "minecraft:quartz_stairs@1"
            ]
        },
        {
            "x": -7,
            "y": 6,
            "z": 2,
            "elements": [
                "twilightforest:castle_stairs_brick@7"
            ]
        },
        {
            "x": 3,
            "y": 10,
            "z": 11,
            "elements": [
                "thermaldynamics:duct_16@2"
            ]
        },
        {
            "x": -6,
            "y": 4,
            "z": 17,
            "elements": [
                "compactmachines3:wallbreakable@0"
            ]
        },
        {
            "x": 8,
            "y": 7,
            "z": 2,
            "elements": [
                "actuallyadditions:block_quartz_wall@0"
            ]
        },
        {
            "x": -1,
            "y": 17,
            "z": 7,
            "elements": [
                "enderio:block_dark_iron_bars@0"
            ]
        },
        {
            "x": -8,
            "y": -1,
            "z": 0,
            "elements": [
                "twilightforest:castle_stairs@9"
            ]
        },
        {
            "x": 1,
            "y": 11,
            "z": 6,
            "elements": [
                "additions:stainless_steel_block@0"
            ]
        },
        {
            "x": -4,
            "y": -1,
            "z": 17,
            "elements": [
                "twilightforest:castle_stairs@8"
            ]
        },
        {
            "x": 2,
            "y": 0,
            "z": 2,
            "elements": [
                "astralsorcery:blockmarbleslab@0"
            ]
        },
        {
            "x": 1,
            "y": 16,
            "z": 6,
            "elements": [
                "enderio:block_alloy_endergy@3"
            ]
        },
        {
            "x": -2,
            "y": 0,
            "z": 16,
            "elements": [
                "twilightforest:castle_stairs@1"
            ]
        },
        {
            "x": 0,
            "y": 5,
            "z": 10,
            "elements": [
                "minecraft:quartz_block@0"
            ]
        },
        {
            "x": 1,
            "y": 12,
            "z": 6,
            "elements": [
                "additions:stainless_steel_block@0"
            ]
        },
        {
            "x": 4,
            "y": 7,
            "z": 7,
            "elements": [
                "tconstruct:seared_stairs_paver@6"
            ]
        },
        {
            "x": 8,
            "y": 4,
            "z": 2,
            "elements": [
                "minecraft:quartz_stairs@4"
            ]
        },
        {
            "x": -7,
            "y": 10,
            "z": 16,
            "elements": [
                "astralsorcery:blockmarbleslab@8"
            ]
        },
        {
            "x": 8,
            "y": 5,
            "z": 2,
            "elements": [
                "minecraft:quartz_stairs@1"
            ]
        },
        {
            "x": 4,
            "y": -1,
            "z": 5,
            "elements": [
                "astralsorcery:blockmarbleslab@0"
            ]
