{
    "registryname": "unitcell_builder",
    "localizedname": "§dLV3 - 晶胞重塑器",
    "requires-blueprint": false,
    "color": "E6EBE5",
    "parts": [
        {
            "x": 0,
            "y": 0,
            "z": 0,
            "elements": [
                "modularmachinery:blockcontroller@2"
            ]
        },
        {
            "x": 3,
            "y": 14,
            "z": 6,
            "elements": [
                "chisel:blockelectrum@4"
            ]
        },
        {
            "x": -10,
            "y": 8,
            "z": 20,
            "elements": [
                "minecraft:quartz_block@2"
            ]
        },
        {
            "x": 0,
            "y": 21,
            "z": 8,
            "elements": [
                "chisel:blockplatinum@4"
            ]
        },
        {
            "x": 10,
            "y": -1,
            "z": 22,
            "elements": [
                "chisel:blockplatinum@4"
            ]
        },
        {
            "x": -10,
            "y": 18,
            "z": 0,
            "elements": [
                "minecraft:stained_glass@3"
            ]
        },
        {
            "x": -8,
            "y": 9,
            "z": 11,
            "elements": [
                "chisel:blockplatinum@4"
            ]
        },
        {
            "x": -12,
            "y": 0,
            "z": 20,
            "elements": [
                "minecraft:stained_glass@3"
            ]
        },
        {
            "x": -10,
            "y": 12,
            "z": 10,
            "elements": [
                "minecraft:stained_glass@3"
            ]
        },
        {
            "x": 0,
            "y": 20,
            "z": 8,
            "elements": [
                "minecraft:stained_glass@3"
            ]
        },
        {
            "x": -10,
            "y": -2,
            "z": 20,
            "elements": [
                "minecraft:stained_glass@3"
            ]
        },
        {
            "x": -11,
            "y": -1,
            "z": -2,
            "elements": [
                "chisel:blockplatinum@4"
            ]
        },
        {
            "x": 10,
            "y": 0,
            "z": 2,
            "elements": [
                "minecraft:stained_glass@3"
            ]
        },
        {
            "x": -10,
            "y": 6,
            "z": 20,
            "elements": [
                "minecraft:quartz_block@2"
            ]
        },
        {
            "x": 1,
            "y": 0,
            "z": 0,
            "elements": [
                "minecraft:quartz_block@3"
            ]
        },
        {
            "x": 10,
            "y": 17,
            "z": 20,
            "elements": [
                "minecraft:quartz_block@2"
            ]
        },
        {
            "x": 0,
            "y": 19,
            "z": 8,
            "elements": [
                "chisel:blockplatinum@4"
            ]
        },
        {
            "x": 11,
            "y": -1,
            "z": 2,
            "elements": [
                "chisel:blockplatinum@4"
            ]
        },
        {
            "x": -10,
            "y": 4,
            "z": 20,
            "elements": [
                "minecraft:quartz_block@2"
            ]
        },
        {
            "x": 6,
            "y": 17,
            "z": 6,
            "elements": [
                "chisel:blockelectrum@4"
            ]
        },
        {
            "x": -9,
            "y": 2,
            "z": 20,
            "elements": [
                "chisel:blockplatinum@4"
            ]
        },
        {
            "x": -10,
            "y": 0,
            "z": 12,
            "elements": [
                "minecraft:quartz_block@4"
            ]
        },
        {
            "x": -11,
            "y": 18,
            "z": 0,
            "elements": [
                "chisel:blockplatinum@4"
            ]
        },
        {
            "x": -8,
            "y": 11,
            "z": 11,
            "elements": [
                "chisel:blockplatinum@4"
            ]
        },
        {
            "x": 12,
            "y": 21,
            "z": 20,
            "elements": [
                "chisel:blockplatinum@4"
            ]
        },
        {
            "x": -11,
            "y": 12,
            "z": 10,
            "elements": [
                "chisel:blockplatinum@4"
            ]
        },
        {
            "x": -10,
            "y": 20,
            "z": 22,
            "elements": [
                "minecraft:stained_glass@3"
            ]
        },
        {
            "x": -9,
            "y": 8,
            "z": 10,
            "elements": [
                "chisel:blockplatinum@4"
            ]
        },
        {
            "x": -6,
            "y": 13,
            "z": 14,
            "elements": [
                "chisel:blockelectrum@4"
            ]
        },
        {
            "x": 2,
            "y": 0,
            "z": 0,
            "elements": [
                "minecraft:quartz_block@3"
            ]
        },
        {
            "x": -3,
            "y": 14,
            "z": 14,
            "elements": [
                "chisel:blockelectrum@4"
            ]
        },
        {
            "x": 9,
            "y": 9,
            "z": 8,
            "elements": [
                "chisel:blockplatinum@4"
            ]
        },
        {
            "x": -3,
            "y": 6,
            "z": 5,
            "elements": [
                "chisel:blockelectrum@4"
            ]
        },
        {
            "x": -1,
            "y": 10,
            "z": 22,
            "elements": [
                "chisel:blockplatinum@4"
            ]
        },
        {
            "x": -10,
            "y": 2,
            "z": 20,
            "elements": [
                "minecraft:stained_glass@3"
            ]
        },
        {
            "x": 12,
            "y": 19,
            "z": 20,
            "elements": [
                "chisel:blockplatinum@4"
            ]
        },
        {
            "x": 7,
            "y": 6,
            "z": 16,
            "elements": [
                "chisel:blockelectrum@4"
            ]
        },
        {
            "x": -6,
            "y": 17,
            "z": 14,
            "elements": [
                "chisel:blockelectrum@4"
            ]
        },
        {
            "x": -10,
            "y": 22,
            "z": 0,
            "elements": [
                "minecraft:stained_glass@3"
            ]
        },
        {
            "x": 10,
            "y": 18,
            "z": 21,
            "elements": [
                "chisel:blockplatinum@4"
            ]
        },
        {
            "x": -10,
            "y": 8,
            "z": 10,
            "elements": [
                "minecraft:stained_glass@3"
            ]
        },
        {
            "x": -1,
            "y": 0,
            "z": 0,
            "elements": [
                "minecraft:quartz_block@3"
            ]
        },
        {
            "x": 9,
            "y": 10,
            "z": 8,
            "elements": [
                "chisel:blockplatinum@4"
            ]
        },
        {
            "x": -9,
            "y": 2,
            "z": -1,
            "elements": [
                "chisel:blockplatinum@4"
            ]
        },
        {
            "x": 11,
            "y": 1,
            "z": 22,
            "elements": [
                "chisel:blockplatinum@4"
            ]
        },
        {
            "x": -9,
            "y": 2,
            "z": 1,
            "elements": [
                "chisel:blockplatinum@4"
            ]
        },
        {
            "x": -2,
            "y": 1,
            "z": 11,
            "elements": [
                "chisel:blockplatinum@4"
            ]
        },
        {
            "x": -10,
            "y": 18,
            "z": 19,
            "elements": [
                "chisel:blockplatinum@4"
            ]
        },
        {
            "x": -12,
            "y": -1,
            "z": 21,
            "elements": [
                "chisel:blockplatinum@4"
            ]
        },
        {
            "x": 9,
            "y": 11,
            "z": 8,
            "elements": [
                "chisel:blockplatinum@4"
            ]
        },
        {
            "x": -5,
            "y": 17,
            "z": 16,
            "elements": [
                "chisel:blockelectrum@4"
            ]
        },
        {
            "x": -12,
            "y": 20,
            "z": 0,
            "elements": [
                "minecraft:stained_glass@3"
            ]
        },
        {
            "x": -11,
            "y": 2,
            "z": 20,
            "elements": [
                "chisel:blockplatinum@4"
            ]
        },
        {
            "x": -3,
            "y": 4,
            "z": 5,
            "elements": [
                "chisel:blockelectrum@4"
            ]
        },
        {
            "x": 10,
            "y": 22,
            "z": 1,
            "elements": [
                "chisel:blockplatinum@4"
            ]
        },
        {
            "x": -9,
            "y": 18,
            "z": 0,
            "elements": [
                "chisel:blockplatinum@4"
            ]
        },
        {
            "x": -8,
            "y": 10,
            "z": 10,
            "elements": [
                "minecraft:stained_glass@3"
            ]
        },
        {
            "x": -9,
            "y": -2,
            "z": 20,
            "elements": [
                "chisel:blockplatinum@4"
            ]
        },
        {
            "x": 8,
            "y": -1,
            "z": -1,
            "elements": [
                "chisel:blockplatinum@4"
            ]
        },
        {
            "x": 8,
            "y": -1,
            "z": 1,
            "elements": [
                "chisel:blockplatinum@4"
            ]
        },
        {
            "x": 0,
            "y": 12,
            "z": -1,
            "elements": [
                "chisel:blockplatinum@4"
            ]
        },
        {
            "x": 11,
            "y": 2,
            "z": 19,
            "elements": [
                "chisel:blockplatinum@4"
            ]
        },
        {
            "x": 12,
            "y": 10,
            "z": 9,
            "elements": [
                "chisel:blockplatinum@4"
            ]
        },
        {
            "x": 10,
            "y": 22,
            "z": 21,
            "elements": [
                "chisel:blockplatinum@4"
            ]
        },
        {
            "x": 4,
            "y": 0,
            "z": 0,
            "elements": [
                "minecraft:quartz_block@3"
            ]
        },
        {
            "x": 5,
            "y": 4,
            "z": 17,
            "elements": [
                "chisel:blockelectrum@4"
            ]
        },
        {
            "x": -9,
            "y": 18,
            "z": -1,
            "elements": [
                "chisel:blockplatinum@4"
            ]
        },
        {
            "x": -5,
            "y": 0,
            "z": 20,
            "elements": [
                "minecraft:quartz_block@3"
            ]
        },
        {
            "x": -10,
            "y": 0,
            "z": 10,
            "elements": [
                "casings_all"
            ]
        },
        {
            "x": -12,
            "y": 9,
            "z": 11,
            "elements": [
                "chisel:blockplatinum@4"
            ]
        },
        {
            "x": 5,
            "y": 5,
            "z": 17,
            "elements": [
                "minecraft:stained_glass@4"
            ]
        },
        {
            "x": -7,
            "y": 20,
            "z": 0,
            "elements": [
                "minecraft:quartz_block@3"
            ]
        },
        {
            "x": -1,
            "y": 8,
            "z": 19,
            "elements": [
                "chisel:blockplatinum@4"
            ]
        },
        {
            "x": -2,
            "y": 1,
            "z": 9,
            "elements": [
                "chisel:blockplatinum@4"
            ]
        },
        {
            "x": -10,
            "y": 12,
            "z": 0,
            "elements": [
                "minecraft:quartz_block@2"
            ]
        },
        {
            "x": -10,
            "y": -2,
            "z": 1,
            "elements": [
                "chisel:blockplatinum@4"
            ]
        },
        {
            "x": 9,
            "y": 22,
            "z": 21,
            "elements": [
                "chisel:blockplatinum@4"
            ]
        },
        {
            "x": 9,
            "y": 2,
            "z": -1,
            "elements": [
                "chisel:blockplatinum@4"
            ]
        },
        {
            "x": 5,
            "y": 0,
            "z": 0,
            "elements": [
                "minecraft:quartz_block@3"
            ]
        },
        {
            "x": -3,
            "y": 5,
            "z": 4,
            "elements": [
                "chisel:blockelectrum@4"
            ]
        },
        {
            "x": 11,
            "y": 18,
            "z": 21,
            "elements": [
                "chisel:blockplatinum@4"
            ]
        },
        {
            "x": -12,
            "y": 11,
            "z": 11,
            "elements": [
                "chisel:blockplatinum@4"
            ]
        },
        {
            "x": -8,
            "y": 0,
            "z": 20,
            "elements": [
                "minecraft:stained_glass@3"
            ]
        },
        {
            "x": -1,
            "y": -2,
            "z": 10,
            "elements": [
                "chisel:blockplatinum@4"
            ]
        },
        {
            "x": 10,
            "y": -2,
            "z": 19,
            "elements": [
                "chisel:blockplatinum@4"
            ]
        },
        {
            "x": -3,
            "y": 15,
            "z": 14,
            "elements": [
                "chisel:blockelectrum@4"
            ]
        },
        {
            "x": 12,
            "y": 0,
            "z": -1,
            "elements": [
                "chisel:blockplatinum@4"
            ]
        },
        {
            "x": -6,
            "y": 3,
            "z": 4,
            "elements": [
                "chisel:blockelectrum@4"
            ]
        },
        {
            "x": -10,
            "y": 10,
            "z": 0,
            "elements": [
                "casings_parallel"
            ]
        },
        {
            "x": 12,
            "y": 1,
            "z": -1,
            "elements": [
                "chisel:blockplatinum@4"
            ]
        },
        {
            "x": -9,
            "y": 22,
            "z": 0,
            "elements": [
                "chisel:blockplatinum@4"
            ]
        },
        {
            "x": -5,
            "y": 13,
            "z": 16,
            "elements": [
                "chisel:blockelectrum@4"
            ]
        },
        {
            "x": -6,
            "y": 20,
            "z": 0,
            "elements": [
                "minecraft:quartz_block@3"
            ]
        },
        {
            "x": 0,
            "y": 8,
            "z": -1,
            "elements": [
                "chisel:blockplatinum@4"
            ]
        },
        {
            "x": -12,
            "y": 19,
            "z": -1,
            "elements": [
                "chisel:blockplatinum@4"
            ]
        },
        {
            "x": 2,
            "y": 2,
            "z": 12,
            "elements": [
                "minecraft:quartz_block@1"
            ]
        },
        {
            "x": -2,
            "y": 0,
            "z": 0,
            "elements": [
                "minecraft:quartz_block@3"
            ]
        },
        {
            "x": 1,
            "y": 19,
            "z": 8,
            "elements": [
                "chisel:blockplatinum@4"
            ]
        },
        {
            "x": -1,
            "y": 12,
            "z": 0,
            "elements": [
                "chisel:blockplatinum@4"
            ]
        },
        {
            "x": -8,
            "y": 9,
            "z": 9,
            "elements": [
                "chisel:blockplatinum@4"
            ]
        },
        {
            "x": 11,
            "y": -2,
            "z": -1,
            "elements": [
                "chisel:blockplatinum@4"
            ]
        },
        {
            "x": -7,
            "y": 6,
            "z": 5,
            "elements": [
                "chisel:blockelectrum@4"
            ]
        },
        {
            "x": -12,
            "y": 1,
            "z": 1,
            "elements": [
                "chisel:blockplatinum@4"
            ]
        },
        {
            "x": -9,
            "y": 22,
            "z": -1,
            "elements": [
                "chisel:blockplatinum@4"
            ]
        },
        {
            "x": 1,
            "y": 21,
            "z": 8,
            "elements": [
                "chisel:blockplatinum@4"
            ]
        },
        {
            "x": -12,
            "y": 0,
            "z": 1,
            "elements": [
                "chisel:blockplatinum@4"
            ]
        },
        {
            "x": -5,
            "y": 0,
            "z": 0,
            "elements": [
                "minecraft:quartz_block@3"
            ]
        },
        {
            "x": -8,
            "y": 11,
            "z": 9,
            "elements": [
                "chisel:blockplatinum@4"
            ]
        },
        {
            "x": 5,
            "y": 6,
            "z": 17,
            "elements": [
                "chisel:blockelectrum@4"
            ]
        },
        {
            "x": 1,
            "y": -1,
            "z": 12,
            "elements": [
                "chisel:blockplatinum@4"
            ]
        },
        {
            "x": -10,
            "y": 16,
            "z": 0,
            "elements": [
                "minecraft:quartz_block@2"
            ]
        },
        {
            "x": 11,
            "y": 22,
            "z": 21,
            "elements": [
                "chisel:blockplatinum@4"
            ]
        },
        {
            "x": 8,
            "y": 20,
            "z": 21,
            "elements": [
                "chisel:blockplatinum@4"
            ]
        },
        {
            "x": -10,
            "y": 10,
            "z": 20,
            "elements": [
                "casings_parallel"
            ]
        },
        {
            "x": -8,
            "y": -1,
            "z": 21,
            "elements": [
                "chisel:blockplatinum@4"
            ]
        },
        {
            "x": -1,
            "y": 1,
            "z": 12,
            "elements": [
                "chisel:blockplatinum@4"
            ]
        },
        {
            "x": -8,
            "y": 1,
            "z": 21,
            "elements": [
                "chisel:blockplatinum@4"
            ]
        },
        {
            "x": -7,
            "y": 4,
            "z": 5,
            "elements": [
                "chisel:blockelectrum@4"
            ]
        },
        {
            "x": 9,
            "y": 18,
            "z": 21,
            "elements": [
                "chisel:blockplatinum@4"
            ]
        },
        {
            "x": 1,
            "y": 20,
            "z": 8,
            "elements": [
                "chisel:blockplatinum@4"
            ]
        },
        {
            "x": -1,
            "y": 0,
            "z": 12,
            "elements": [
                "chisel:blockplatinum@4"
            ]
        },
        {
            "x": -9,
            "y": 12,
            "z": 10,
            "elements": [
                "chisel:blockplatinum@4"
            ]
        },
        {
            "x": -1,
            "y": 8,
            "z": 0,
            "elements": [
                "chisel:blockplatinum@4"
            ]
        },
        {
            "x": -10,
            "y": 14,
            "z": 0,
            "elements": [
                "minecraft:quartz_block@2"
            ]
        },
        {
            "x": 1,
            "y": 12,
            "z": 0,
            "elements": [
                "chisel:blockplatinum@4"
            ]
        },
        {
            "x": -12,
            "y": 10,
            "z": 10,
            "elements": [
                "minecraft:stained_glass@3"
            ]
        },
        {
            "x": 0,
            "y": 2,
            "z": 10,
            "elements": [
                "minecraft:stained_glass@3"
            ]
        },
        {
            "x": -10,
            "y": 4,
            "z": 0,
            "elements": [
                "minecraft:quartz_block@2"
            ]
        },
        {
            "x": 0,
            "y": 1,
            "z": 8,
            "elements": [
                "chisel:blockplatinum@4"
            ]
        },
        {
            "x": 2,
            "y": 9,
            "z": 19,
            "elements": [
                "chisel:blockplatinum@4"
            ]
        },
        {
            "x": -7,
            "y": 16,
            "z": 15,
            "elements": [
                "chisel:blockelectrum@4"
            ]
        },
        {
            "x": 6,
            "y": 3,
            "z": 14,
            "elements": [
                "chisel:blockelectrum@4"
            ]
        },
        {
            "x": -4,
            "y": 15,
            "z": 17,
            "elements": [
                "chisel:blockelectrum@4"
            ]
        },
        {
            "x": 8,
            "y": 0,
            "z": 0,
            "elements": [
                "minecraft:stained_glass@3"
            ]
        },
        {
            "x": -9,
            "y": 21,
            "z": -2,
            "elements": [
                "chisel:blockplatinum@4"
            ]
        },
        {
            "x": 9,
            "y": 9,
            "z": 12,
            "elements": [
                "chisel:blockplatinum@4"
            ]
        },
        {
            "x": -5,
            "y": 7,
            "z": 4,
            "elements": [
                "chisel:blockelectrum@4"
            ]
        },
        {
            "x": -4,
            "y": 14,
            "z": 17,
            "elements": [
                "chisel:blockelectrum@4"
            ]
        },
        {
            "x": 12,
            "y": 19,
            "z": 0,
            "elements": [
                "chisel:blockplatinum@4"
            ]
        },
        {
            "x": -7,
            "y": 0,
            "z": 0,
            "elements": [
                "minecraft:quartz_block@3"
            ]
        },
        {
            "x": -9,
            "y": 18,
            "z": 20,
            "elements": [
                "chisel:blockplatinum@4"
            ]
        },
        {
            "x": 12,
            "y": 1,
            "z": 20,
            "elements": [
                "chisel:blockplatinum@4"
            ]
        },
        {
            "x": -7,
            "y": 5,
            "z": 4,
            "elements": [
                "chisel:blockelectrum@4"
            ]
        },
        {
            "x": 8,
            "y": 0,
            "z": 19,
            "elements": [
                "chisel:blockplatinum@4"
            ]
        },
        {
            "x": 12,
            "y": 11,
            "z": 10,
            "elements": [
                "chisel:blockplatinum@4"
            ]
        },
        {
            "x": 9,
            "y": 11,
            "z": 12,
            "elements": [
                "chisel:blockplatinum@4"
            ]
        },
        {
            "x": 9,
            "y": 20,
            "z": -2,
            "elements": [
                "chisel:blockplatinum@4"
            ]
        },
        {
            "x": -2,
            "y": 20,
            "z": 0,
            "elements": [
                "minecraft:quartz_block@3"
            ]
        },
        {
            "x": 8,
            "y": 8,
            "z": 12,
            "elements": [
                "minecraft:quartz_block@1"
            ]
        },
        {
            "x": -4,
            "y": 16,
            "z": 17,
            "elements": [
                "chisel:blockelectrum@4"
            ]
        },
        {
            "x": 9,
            "y": 19,
            "z": -2,
            "elements": [
                "chisel:blockplatinum@4"
            ]
        },
        {
            "x": 9,
            "y": 10,
            "z": 12,
            "elements": [
                "chisel:blockplatinum@4"
            ]
        },
        {
            "x": -6,
            "y": 16,
            "z": 13,
            "elements": [
                "chisel:blockelectrum@4"
            ]
        },
        {
            "x": -12,
            "y": 9,
            "z": 9,
            "elements": [
                "chisel:blockplatinum@4"
            ]
        },
        {
            "x": -3,
            "y": 17,
            "z": 13,
            "elements": [
                "minecraft:quartz_block@1"
            ]
        },
        {
            "x": 0,
            "y": 21,
            "z": 12,
            "elements": [
                "chisel:blockplatinum@4"
            ]
        },
        {
            "x": -5,
            "y": 3,
            "z": 4,
            "elements": [
                "chisel:blockelectrum@4"
            ]
        },
        {
            "x": -10,
            "y": 8,
            "z": 0,
            "elements": [
                "minecraft:quartz_block@2"
            ]
        },
        {
            "x": -3,
            "y": 0,
            "z": 20,
            "elements": [
                "minecraft:quartz_block@3"
            ]
        },
        {
            "x": 8,
            "y": 1,
            "z": 19,
            "elements": [
                "chisel:blockplatinum@4"
            ]
        },
        {
            "x": 6,
            "y": 7,
            "z": 14,
            "elements": [
                "chisel:blockelectrum@4"
            ]
        },
        {
            "x": 2,
            "y": 11,
            "z": 19,
            "elements": [
                "chisel:blockplatinum@4"
            ]
        },
        {
            "x": -12,
            "y": 11,
            "z": 9,
            "elements": [
                "chisel:blockplatinum@4"
            ]
        },
        {
            "x": -10,
            "y": 20,
            "z": 3,
            "elements": [
                "minecraft:quartz_block@4"
            ]
        },
        {
            "x": -10,
            "y": 2,
            "z": 0,
            "elements": [
                "minecraft:stained_glass@3"
            ]
        },
        {
            "x": 9,
            "y": -2,
            "z": 0,
            "elements": [
                "chisel:blockplatinum@4"
            ]
        },
        {
            "x": 1,
            "y": 2,
            "z": 10,
            "elements": [
                "chisel:blockplatinum@4"
            ]
        },
        {
            "x": -3,
            "y": 16,
            "z": 14,
            "elements": [
                "chisel:blockelectrum@4"
            ]
        },
        {
            "x": 7,
            "y": 0,
            "z": 0,
            "elements": [
                "minecraft:quartz_block@3"
            ]
        },
        {
            "x": -1,
            "y": -1,
            "z": 8,
            "elements": [
                "chisel:blockplatinum@4"
            ]
        },
        {
            "x": -1,
            "y": 12,
            "z": 19,
            "elements": [
                "chisel:blockplatinum@4"
            ]
        },
        {
            "x": -12,
            "y": 20,
            "z": 20,
            "elements": [
                "minecraft:stained_glass@3"
            ]
        },
        {
            "x": -7,
            "y": 14,
            "z": 15,
            "elements": [
                "chisel:blockelectrum@4"
            ]
        },
        {
            "x": 0,
            "y": 20,
            "z": 12,
            "elements": [
                "minecraft:stained_glass@3"
            ]
        },
        {
            "x": -10,
            "y": 6,
            "z": 0,
            "elements": [
                "minecraft:quartz_block@2"
            ]
        },
        {
            "x": -12,
            "y": 1,
            "z": 21,
            "elements": [
                "chisel:blockplatinum@4"
            ]
        },
        {
            "x": -4,
            "y": 3,
            "z": 4,
            "elements": [
                "chisel:blockelectrum@4"
            ]
        },
        {
            "x": -10,
            "y": 20,
            "z": 15,
            "elements": [
                "minecraft:quartz_block@4"
            ]
        },
        {
            "x": 11,
            "y": 21,
            "z": 22,
            "elements": [
                "chisel:blockplatinum@4"
            ]
        },
        {
            "x": 2,
            "y": 10,
            "z": 19,
            "elements": [
                "chisel:blockplatinum@4"
            ]
        },
        {
            "x": 12,
            "y": 21,
            "z": 0,
            "elements": [
                "chisel:blockplatinum@4"
            ]
        },
        {
            "x": 9,
            "y": 8,
            "z": 11,
            "elements": [
                "chisel:blockplatinum@4"
            ]
        },
        {
            "x": 0,
            "y": 0,
            "z": 8,
            "elements": [
                "minecraft:stained_glass@3"
            ]
        },
        {
            "x": -6,
            "y": 7,
            "z": 4,
            "elements": [
                "chisel:blockelectrum@4"
            ]
        },
        {
            "x": -4,
            "y": 0,
            "z": 0,
            "elements": [
                "minecraft:quartz_block@3"
            ]
        },
        {
            "x": 3,
            "y": 3,
            "z": 13,
            "elements": [
                "minecraft:quartz_block@1"
            ]
        },
        {
            "x": 9,
            "y": 12,
            "z": 11,
            "elements": [
                "chisel:blockplatinum@4"
            ]
        },
        {
            "x": 10,
            "y": 21,
            "z": 2,
            "elements": [
                "chisel:blockplatinum@4"
            ]
        },
        {
            "x": -10,
            "y": -2,
            "z": -1,
            "elements": [
                "chisel:blockplatinum@4"
            ]
        },
        {
            "x": 10,
            "y": 18,
            "z": 1,
            "elements": [
                "chisel:blockplatinum@4"
            ]
        },
        {
            "x": 3,
            "y": 0,
            "z": 20,
            "elements": [
                "minecraft:quartz_block@3"
            ]
        },
        {
            "x": -1,
            "y": 20,
            "z": 12,
            "elements": [
                "chisel:blockplatinum@4"
            ]
        },
        {
            "x": -11,
            "y": 0,
            "z": 22,
            "elements": [
                "chisel:blockplatinum@4"
            ]
        },
        {
            "x": -6,
            "y": 6,
            "z": 3,
            "elements": [
                "chisel:blockelectrum@4"
            ]
        },
        {
            "x": 3,
            "y": 5,
            "z": 14,
            "elements": [
                "chisel:blockelectrum@4"
            ]
        },
        {
            "x": 8,
            "y": 2,
            "z": 18,
            "elements": [
                "minecraft:quartz_block@1"
            ]
        },
        {
            "x": -10,
            "y": 21,
            "z": 18,
            "elements": [
                "chisel:blockplatinum@4"
            ]
        },
        {
            "x": -1,
            "y": 11,
            "z": 18,
            "elements": [
                "chisel:blockplatinum@4"
            ]
        },
        {
            "x": 9,
            "y": 21,
            "z": 22,
            "elements": [
                "chisel:blockplatinum@4"
            ]
        },
        {
            "x": -6,
            "y": 4,
            "z": 3,
            "elements": [
                "chisel:blockelectrum@4"
            ]
        },
        {
            "x": 0,
            "y": -2,
            "z": 10,
            "elements": [
                "minecraft:stained_glass@3"
            ]
        },
        {
            "x": 10,
            "y": 4,
            "z": 0,
            "elements": [
                "minecraft:quartz_block@2"
            ]
        },
        {
            "x": 10,
            "y": 20,
            "z": 2,
            "elements": [
                "minecraft:stained_glass@3"
            ]
        },
        {
            "x": 0,
            "y": 19,
            "z": 12,
            "elements": [
                "chisel:blockplatinum@4"
            ]
        },
        {
            "x": 11,
            "y": 19,
            "z": 22,
            "elements": [
                "chisel:blockplatinum@4"
            ]
        },
        {
            "x": -2,
            "y": 0,
            "z": 10,
            "elements": [
                "minecraft:stained_glass@3"
            ]
        },
        {
            "x": 10,
            "y": 20,
            "z": 16,
            "elements": [
                "minecraft:quartz_block@4"
            ]
        },
        {
            "x": 3,
            "y": 6,
            "z": 14,
            "elements": [
                "chisel:blockelectrum@4"
            ]
        },
        {
            "x": 3,
            "y": 17,
            "z": 7,
            "elements": [
                "minecraft:quartz_block@1"
            ]
        },
        {
            "x": -10,
            "y": 19,
            "z": 18,
            "elements": [
                "chisel:blockplatinum@4"
            ]
        },
        {
            "x": 12,
            "y": 1,
            "z": 1,
            "elements": [
                "chisel:blockplatinum@4"
            ]
        },
        {
            "x": 0,
            "y": 0,
            "z": 20,
            "elements": [
                "casings_all"
            ]
        },
        {
            "x": 1,
            "y": 20,
            "z": 0,
            "elements": [
                "minecraft:quartz_block@3"
            ]
        },
        {
            "x": -10,
            "y": 20,
            "z": 18,
            "elements": [
                "minecraft:stained_glass@3"
            ]
        },
        {
            "x": 9,
            "y": 22,
            "z": -1,
            "elements": [
                "chisel:blockplatinum@4"
            ]
        },
        {
            "x": 2,
            "y": -1,
            "z": 11,
            "elements": [
                "chisel:blockplatinum@4"
            ]
        },
        {
            "x": -10,
            "y": 20,
            "z": 5,
            "elements": [
                "minecraft:quartz_block@4"
            ]
        },
        {
            "x": 8,
            "y": 21,
            "z": 20,
            "elements": [
                "chisel:blockplatinum@4"
            ]
        },
        {
            "x": -9,
            "y": 0,
            "z": 2,
            "elements": [
                "chisel:blockplatinum@4"
            ]
        },
        {
            "x": 5,
            "y": 5,
            "z": 13,
            "elements": [
                "minecraft:stained_glass@4"
            ]
        },
        {
            "x": 5,
            "y": 4,
            "z": 13,
            "elements": [
                "chisel:blockelectrum@4"
            ]
        },
        {
            "x": 12,
            "y": 19,
            "z": -1,
            "elements": [
                "chisel:blockplatinum@4"
            ]
        },
        {
            "x": 8,
            "y": -1,
            "z": 20,
            "elements": [
                "chisel:blockplatinum@4"
            ]
        },
        {
            "x": -10,
            "y": 0,
            "z": 22,
            "elements": [
                "minecraft:stained_glass@3"
            ]
        },
        {
            "x": -1,
            "y": 9,
            "z": 18,
            "elements": [
                "chisel:blockplatinum@4"
            ]
        },
        {
            "x": -11,
            "y": -2,
            "z": 0,
            "elements": [
                "chisel:blockplatinum@4"
            ]
        },
        {
            "x": 5,
            "y": 6,
            "z": 13,
            "elements": [
                "chisel:blockelectrum@4"
            ]
        },
        {
            "x": -10,
            "y": 20,
            "z": 17,
            "elements": [
                "minecraft:quartz_block@4"
            ]
        },
        {
            "x": -9,
            "y": 1,
            "z": 2,
            "elements": [
                "chisel:blockplatinum@4"
            ]
        },
        {
            "x": 10,
            "y": 2,
            "z": 0,
            "elements": [
                "minecraft:stained_glass@3"
            ]
        },
        {
            "x": 9,
            "y": 2,
            "z": 1,
            "elements": [
                "chisel:blockplatinum@4"
            ]
        },
        {
            "x": -10,
            "y": 22,
            "z": 19,
            "elements": [
                "chisel:blockplatinum@4"
            ]
        },
        {
            "x": 12,
            "y": 0,
            "z": 1,
            "elements": [
                "chisel:blockplatinum@4"
            ]
        },
        {
            "x": -12,
            "y": 19,
            "z": 21,
            "elements": [
                "chisel:blockplatinum@4"
            ]
        },
        {
            "x": 0,
            "y": 8,
            "z": 20,
            "elements": [
                "minecraft:stained_glass@3"
            ]
        },
        {
            "x": 1,
            "y": 8,
            "z": 0,
            "elements": [
                "chisel:blockplatinum@4"
            ]
        },
        {
            "x": -4,
            "y": 7,
            "z": 4,
            "elements": [
                "chisel:blockelectrum@4"
            ]
        },
        {
            "x": 3,
            "y": 4,
            "z": 14,
            "elements": [
                "chisel:blockelectrum@4"
            ]
        },
        {
            "x": -2,
            "y": 10,
            "z": 0,
            "elements": [
                "minecraft:stained_glass@3"
            ]
        },
        {
            "x": 2,
            "y": 8,
            "z": 18,
            "elements": [
                "minecraft:quartz_block@1"
            ]
        },
        {
            "x": 11,
            "y": 1,
            "z": 18,
            "elements": [
                "chisel:blockplatinum@4"
            ]
        },
        {
            "x": -1,
            "y": 10,
            "z": 18,
            "elements": [
                "chisel:blockplatinum@4"
            ]
        },
        {
            "x": -12,
            "y": 1,
            "z": -1,
            "elements": [
                "chisel:blockplatinum@4"
            ]
        },
        {
            "x": 8,
            "y": 19,
            "z": 20,
            "elements": [
                "chisel:blockplatinum@4"
            ]
        },
        {
            "x": 12,
            "y": 10,
            "z": 11,
            "elements": [
                "chisel:blockplatinum@4"
            ]
        },
        {
            "x": 6,
            "y": 5,
            "z": 13,
            "elements": [
                "chisel:blockelectrum@4"
            ]
        },
        {
            "x": -7,
            "y": 17,
            "z": 17,
            "elements": [
                "minecraft:quartz_block@1"
            ]
        },
        {
            "x": 11,
            "y": 12,
            "z": 11,
            "elements": [
                "chisel:blockplatinum@4"
            ]
        },
        {
            "x": 11,
            "y": -1,
            "z": -2,
            "elements": [
                "chisel:blockplatinum@4"
            ]
        },
        {
            "x": 6,
            "y": 14,
            "z": 7,
            "elements": [
                "chisel:blockelectrum@4"
            ]
        },
        {
            "x": -12,
            "y": 0,
            "z": -1,
            "elements": [
                "chisel:blockplatinum@4"
            ]
        },
        {
            "x": 0,
            "y": 9,
            "z": -2,
            "elements": [
                "chisel:blockplatinum@4"
            ]
        },
        {
            "x": 11,
            "y": 0,
            "z": 18,
            "elements": [
                "chisel:blockplatinum@4"
            ]
        },
        {
            "x": -4,
            "y": 6,
            "z": 3,
            "elements": [
                "chisel:blockelectrum@4"
            ]
        },
        {
            "x": 11,
            "y": -2,
            "z": 1,
            "elements": [
                "chisel:blockplatinum@4"
            ]
        },
        {
            "x": -9,
            "y": 0,
            "z": 22,
            "elements": [
                "chisel:blockplatinum@4"
            ]
        },
        {
            "x": 10,
            "y": 21,
            "z": 22,
            "elements": [
                "chisel:blockplatinum@4"
            ]
        },
        {
            "x": 9,
            "y": 1,
            "z": -2,
            "elements": [
                "chisel:blockplatinum@4"
            ]
        },
        {
            "x": -5,
            "y": 4,
            "z": 3,
            "elements": [
                "chisel:blockelectrum@4"
            ]
        },
        {
            "x": -10,
            "y": 0,
            "z": 15,
            "elements": [
                "minecraft:quartz_block@4"
            ]
        },
        {
            "x": 6,
            "y": 13,
            "z": 6,
            "elements": [
                "chisel:blockelectrum@4"
            ]
        },
        {
            "x": 6,
            "y": 15,
            "z": 7,
            "elements": [
                "chisel:blockelectrum@4"
            ]
        },
        {
            "x": 6,
            "y": 6,
            "z": 13,
            "elements": [
                "chisel:blockelectrum@4"
            ]
        },
        {
            "x": 10,
            "y": 19,
            "z": 22,
            "elements": [
                "chisel:blockplatinum@4"
            ]
        },
        {
            "x": 0,
            "y": 10,
            "z": -2,
            "elements": [
                "minecraft:stained_glass@3"
            ]
        },
        {
            "x": 9,
            "y": 18,
            "z": -1,
            "elements": [
                "chisel:blockplatinum@4"
            ]
        },
        {
            "x": -5,
            "y": 20,
            "z": 0,
            "elements": [
                "minecraft:quartz_block@3"
            ]
        },
        {
            "x": -10,
            "y": -1,
            "z": 2,
            "elements": [
                "chisel:blockplatinum@4"
            ]
        },
        {
            "x": 9,
            "y": 0,
            "z": -2,
            "elements": [
                "chisel:blockplatinum@4"
            ]
        },
        {
            "x": 10,
            "y": -1,
            "z": 18,
            "elements": [
                "chisel:blockplatinum@4"
            ]
        },
        {
            "x": -2,
            "y": -1,
            "z": 9,
            "elements": [
                "chisel:blockplatinum@4"
            ]
        },
        {
            "x": 3,
            "y": 16,
            "z": 6,
            "elements": [
                "chisel:blockelectrum@4"
            ]
        },
        {
            "x": 11,
            "y": 2,
            "z": 21,
            "elements": [
                "chisel:blockplatinum@4"
            ]
        },
        {
            "x": 9,
            "y": 21,
            "z": -2,
            "elements": [
                "chisel:blockplatinum@4"
            ]
        },
        {
            "x": 10,
            "y": 20,
            "z": 9,
            "elements": [
                "minecraft:quartz_block@4"
            ]
        },
        {
            "x": 10,
            "y": 8,
            "z": 0,
            "elements": [
                "minecraft:quartz_block@2"
            ]
        },
        {
            "x": 6,
            "y": 16,
            "z": 7,
            "elements": [
                "chisel:blockelectrum@4"
            ]
        },
        {
            "x": 10,
            "y": 19,
            "z": 2,
            "elements": [
                "chisel:blockplatinum@4"
            ]
        },
        {
            "x": -1,
            "y": 21,
            "z": 12,
            "elements": [
                "chisel:blockplatinum@4"
            ]
        },
        {
            "x": -4,
            "y": 4,
            "z": 3,
            "elements": [
                "chisel:blockelectrum@4"
            ]
        },
        {
            "x": -5,
            "y": 6,
            "z": 3,
            "elements": [
                "chisel:blockelectrum@4"
            ]
        },
        {
            "x": -6,
            "y": 0,
            "z": 20,
            "elements": [
                "minecraft:quartz_block@3"
            ]
        },
        {
            "x": 3,
            "y": 15,
            "z": 6,
            "elements": [
                "chisel:blockelectrum@4"
            ]
        },
        {
            "x": 12,
            "y": 9,
            "z": 10,
            "elements": [
                "chisel:blockplatinum@4"
            ]
        },
        {
            "x": -1,
            "y": 19,
            "z": 12,
            "elements": [
                "chisel:blockplatinum@4"
            ]
        },
        {
            "x": -11,
            "y": 22,
            "z": 0,
            "elements": [
                "chisel:blockplatinum@4"
            ]
        },
        {
            "x": 6,
            "y": 4,
            "z": 13,
            "elements": [
                "chisel:blockelectrum@4"
            ]
        },
        {
            "x": -8,
            "y": 20,
            "z": 0,
            "elements": [
                "minecraft:stained_glass@3"
            ]
        },
        {
            "x": -11,
            "y": 8,
            "z": 10,
            "elements": [
                "chisel:blockplatinum@4"
            ]
        },
        {
            "x": 10,
            "y": 6,
            "z": 0,
            "elements": [
                "minecraft:quartz_block@2"
            ]
        },
        {
            "x": 0,
            "y": 11,
            "z": -2,
            "elements": [
                "chisel:blockplatinum@4"
            ]
        },
        {
            "x": -2,
            "y": 21,
            "z": 10,
            "elements": [
                "chisel:blockplatinum@4"
            ]
        },
        {
            "x": 11,
            "y": -2,
            "z": 21,
            "elements": [
                "chisel:blockplatinum@4"
            ]
        },
        {
            "x": -9,
            "y": 22,
            "z": 20,
            "elements": [
                "chisel:blockplatinum@4"
            ]
        },
        {
            "x": 0,
            "y": 18,
            "z": 10,
            "elements": [
                "minecraft:stained_glass@3"
            ]
        },
        {
            "x": 4,
            "y": 17,
            "z": 5,
            "elements": [
                "chisel:blockelectrum@4"
            ]
        },
        {
            "x": 10,
            "y": 21,
            "z": 18,
            "elements": [
                "chisel:blockplatinum@4"
            ]
        },
        {
            "x": 5,
            "y": 20,
            "z": 0,
            "elements": [
                "minecraft:quartz_block@3"
            ]
        },
        {
            "x": 10,
            "y": 0,
            "z": 10,
            "elements": [
                "casings_all"
            ]
        },
        {
            "x": 9,
            "y": 2,
            "z": 21,
            "elements": [
                "chisel:blockplatinum@4"
            ]
        },
        {
            "x": -12,
            "y": 19,
            "z": 19,
            "elements": [
                "chisel:blockplatinum@4"
            ]
        },
        {
            "x": 7,
            "y": 14,
            "z": 5,
            "elements": [
                "chisel:blockelectrum@4"
            ]
        },
        {
            "x": -1,
            "y": -1,
            "z": 12,
            "elements": [
                "chisel:blockplatinum@4"
            ]
        },
        {
            "x": -8,
            "y": 0,
            "z": 1,
            "elements": [
                "chisel:blockplatinum@4"
            ]
        },
        {
            "x": -11,
            "y": 2,
            "z": 1,
            "elements": [
                "chisel:blockplatinum@4"
            ]
        },
        {
            "x": 1,
            "y": 12,
            "z": 1,
            "elements": [
                "chisel:blockplatinum@4"
            ]
        },
        {
            "x": 10,
            "y": -2,
            "z": 21,
            "elements": [
                "chisel:blockplatinum@4"
            ]
        },
        {
            "x": -6,
            "y": 20,
            "z": 20,
            "elements": [
                "minecraft:quartz_block@3"
            ]
        },
        {
            "x": -3,
            "y": 20,
            "z": 20,
            "elements": [
                "minecraft:quartz_block@3"
            ]
        },
        {
            "x": 7,
            "y": 17,
            "z": 3,
            "elements": [
                "minecraft:quartz_block@1"
            ]
        },
        {
            "x": -7,
            "y": 15,
            "z": 14,
            "elements": [
                "chisel:blockelectrum@4"
            ]
        },
        {
            "x": 1,
            "y": 18,
            "z": 10,
            "elements": [
                "chisel:blockplatinum@4"
            ]
        },
        {
            "x": 5,
            "y": 17,
            "z": 5,
            "elements": [
                "minecraft:stained_glass@4"
            ]
        },
        {
            "x": -9,
            "y": -2,
            "z": 1,
            "elements": [
                "chisel:blockplatinum@4"
            ]
        },
        {
            "x": -9,
            "y": 0,
            "z": 18,
            "elements": [
                "chisel:blockplatinum@4"
            ]
        },
        {
            "x": 8,
            "y": 1,
            "z": -1,
            "elements": [
                "chisel:blockplatinum@4"
            ]
        },
        {
            "x": 10,
            "y": 19,
            "z": 18,
            "elements": [
                "chisel:blockplatinum@4"
            ]
        },
        {
            "x": 6,
            "y": 3,
            "z": 15,
            "elements": [
                "chisel:blockelectrum@4"
            ]
        },
        {
            "x": -10,
            "y": 2,
            "z": 1,
            "elements": [
                "chisel:blockplatinum@4"
            ]
        },
        {
            "x": -11,
            "y": 20,
            "z": -2,
            "elements": [
                "chisel:blockplatinum@4"
            ]
        },
        {
            "x": 10,
            "y": 22,
            "z": -1,
            "elements": [
                "chisel:blockplatinum@4"
            ]
        },
        {
            "x": 3,
            "y": 5,
            "z": 16,
            "elements": [
                "chisel:blockelectrum@4"
            ]
        },
        {
            "x": -12,
            "y": 20,
            "z": 21,
            "elements": [
                "chisel:blockplatinum@4"
            ]
        },
        {
            "x": -9,
            "y": 18,
            "z": 21,
            "elements": [
                "chisel:blockplatinum@4"
            ]
        },
        {
            "x": -8,
            "y": -1,
            "z": -1,
            "elements": [
                "chisel:blockplatinum@4"
            ]
        },
        {
            "x": 5,
            "y": 0,
            "z": 20,
            "elements": [
                "minecraft:quartz_block@3"
            ]
        },
        {
            "x": 0,
            "y": 12,
            "z": 1,
            "elements": [
                "chisel:blockplatinum@4"
            ]
        },
        {
            "x": 0,
            "y": 1,
            "z": 12,
            "elements": [
                "chisel:blockplatinum@4"
            ]
        },
        {
            "x": 0,
            "y": 12,
            "z": 21,
            "elements": [
                "chisel:blockplatinum@4"
            ]
        },
        {
            "x": 2,
            "y": 11,
            "z": -1,
            "elements": [
                "chisel:blockplatinum@4"
            ]
        },
        {
            "x": -2,
            "y": 2,
            "z": 8,
            "elements": [
                "minecraft:quartz_block@1"
            ]
        },
        {
            "x": 0,
            "y": 2,
            "z": 9,
            "elements": [
                "chisel:blockplatinum@4"
            ]
        },
        {
            "x": 3,
            "y": 4,
            "z": 16,
            "elements": [
                "chisel:blockelectrum@4"
            ]
        },
        {
            "x": 1,
            "y": 0,
            "z": 8,
            "elements": [
                "chisel:blockplatinum@4"
            ]
        },
        {
            "x": 12,
            "y": 20,
            "z": -1,
            "elements": [
                "chisel:blockplatinum@4"
            ]
        },
        {
            "x": 12,
            "y": 19,
            "z": 1,
            "elements": [
                "chisel:blockplatinum@4"
            ]
        },
        {
            "x": -9,
            "y": 11,
            "z": 12,
            "elements": [
                "chisel:blockplatinum@4"
            ]
        },
        {
            "x": 2,
            "y": -1,
            "z": 9,
            "elements": [
                "chisel:blockplatinum@4"
            ]
        },
        {
            "x": -10,
            "y": 20,
            "z": 8,
            "elements": [
                "minecraft:quartz_block@4"
            ]
        },
        {
            "x": -4,
            "y": 5,
            "z": 7,
            "elements": [
                "chisel:blockelectrum@4"
            ]
        },
        {
            "x": 10,
            "y": 20,
            "z": 17,
            "elements": [
                "minecraft:quartz_block@4"
            ]
        },
        {
            "x": 4,
            "y": 13,
            "z": 5,
            "elements": [
                "chisel:blockelectrum@4"
            ]
        },
        {
            "x": 2,
            "y": 9,
            "z": -1,
            "elements": [
                "chisel:blockplatinum@4"
            ]
        },
        {
            "x": 1,
            "y": 8,
            "z": 1,
            "elements": [
                "chisel:blockplatinum@4"
            ]
        },
        {
            "x": 1,
            "y": 22,
            "z": 10,
            "elements": [
                "chisel:blockplatinum@4"
            ]
        },
        {
            "x": -12,
            "y": 21,
            "z": 21,
            "elements": [
                "chisel:blockplatinum@4"
            ]
        },
        {
            "x": 12,
            "y": 0,
            "z": 21,
            "elements": [
                "chisel:blockplatinum@4"
            ]
        },
        {
            "x": -4,
            "y": 20,
            "z": 20,
            "elements": [
                "minecraft:quartz_block@3"
            ]
        },
        {
            "x": 9,
            "y": 8,
            "z": 10,
            "elements": [
                "chisel:blockplatinum@4"
            ]
        },
        {
            "x": -4,
            "y": 16,
            "z": 13,
            "elements": [
                "chisel:blockelectrum@4"
            ]
        },
        {
            "x": -9,
            "y": 9,
            "z": 12,
            "elements": [
                "chisel:blockplatinum@4"
            ]
        },
        {
            "x": 1,
            "y": 10,
            "z": -2,
            "elements": [
                "chisel:blockplatinum@4"
            ]
        },
        {
            "x": -9,
            "y": 22,
            "z": 21,
            "elements": [
                "chisel:blockplatinum@4"
            ]
        },
        {
            "x": 10,
            "y": 20,
            "z": 4,
            "elements": [
                "minecraft:quartz_block@4"
            ]
        },
        {
            "x": 9,
            "y": 19,
            "z": 22,
            "elements": [
                "chisel:blockplatinum@4"
            ]
        },
        {
            "x": -11,
            "y": 21,
            "z": 2,
            "elements": [
                "chisel:blockplatinum@4"
            ]
        },
        {
            "x": 6,
            "y": 0,
            "z": 20,
            "elements": [
                "minecraft:quartz_block@3"
            ]
        },
        {
            "x": 0,
            "y": 12,
            "z": 20,
            "elements": [
                "minecraft:stained_glass@3"
            ]
        },
        {
            "x": -10,
            "y": 20,
            "z": 6,
            "elements": [
                "minecraft:quartz_block@4"
            ]
        },
        {
            "x": 2,
            "y": 9,
            "z": 20,
            "elements": [
                "chisel:blockplatinum@4"
            ]
        },
        {
            "x": -1,
            "y": -2,
            "z": 9,
            "elements": [
                "chisel:blockplatinum@4"
            ]
        },
        {
            "x": 11,
            "y": -2,
            "z": 19,
            "elements": [
                "chisel:blockplatinum@4"
            ]
        },
        {
            "x": -10,
            "y": 0,
            "z": 18,
            "elements": [
                "minecraft:stained_glass@3"
            ]
        },
        {
            "x": -10,
            "y": 18,
            "z": 20,
            "elements": [
                "minecraft:stained_glass@3"
            ]
        },
        {
            "x": -6,
            "y": 17,
            "z": 16,
            "elements": [
                "chisel:blockelectrum@4"
            ]
        },
        {
            "x": -2,
            "y": 19,
            "z": 11,
            "elements": [
                "chisel:blockplatinum@4"
            ]
        },
        {
            "x": -10,
            "y": 19,
            "z": 2,
            "elements": [
                "chisel:blockplatinum@4"
            ]
        },
        {
            "x": 9,
            "y": -2,
            "z": 1,
            "elements": [
                "chisel:blockplatinum@4"
            ]
        },
        {
            "x": -4,
            "y": 17,
            "z": 14,
            "elements": [
                "chisel:blockelectrum@4"
            ]
        },
        {
            "x": 11,
            "y": 2,
            "z": 0,
            "elements": [
                "chisel:blockplatinum@4"
            ]
        },
        {
            "x": -1,
            "y": 0,
            "z": 8,
            "elements": [
                "chisel:blockplatinum@4"
            ]
        },
        {
            "x": 0,
            "y": 8,
            "z": 21,
            "elements": [
                "chisel:blockplatinum@4"
            ]
        },
        {
            "x": -10,
            "y": 17,
            "z": 20,
            "elements": [
                "minecraft:quartz_block@2"
            ]
        },
        {
            "x": -11,
            "y": 10,
            "z": 8,
            "elements": [
                "chisel:blockplatinum@4"
            ]
        },
        {
            "x": 2,
            "y": 10,
            "z": 20,
            "elements": [
                "minecraft:stained_glass@3"
            ]
        },
        {
            "x": -4,
            "y": 14,
            "z": 13,
            "elements": [
                "chisel:blockelectrum@4"
            ]
        },
        {
            "x": 11,
            "y": 19,
            "z": 18,
            "elements": [
                "chisel:blockplatinum@4"
            ]
        },
        {
            "x": -12,
            "y": -1,
            "z": 0,
            "elements": [
                "chisel:blockplatinum@4"
            ]
        },
        {
            "x": -10,
            "y": 20,
            "z": -2,
            "elements": [
                "minecraft:stained_glass@3"
            ]
        },
        {
            "x": -1,
            "y": 12,
            "z": 20,
            "elements": [
                "chisel:blockplatinum@4"
            ]
        },
        {
            "x": 12,
            "y": 21,
            "z": 1,
            "elements": [
                "chisel:blockplatinum@4"
            ]
        },
        {
            "x": 12,
            "y": 0,
            "z": 19,
            "elements": [
                "chisel:blockplatinum@4"
            ]
        },
        {
            "x": 10,
            "y": 20,
            "z": 14,
            "elements": [
                "minecraft:quartz_block@4"
            ]
        },
        {
            "x": -12,
            "y": -1,
            "z": 19,
            "elements": [
                "chisel:blockplatinum@4"
            ]
        },
        {
            "x": -1,
            "y": 12,
            "z": 21,
            "elements": [
                "chisel:blockplatinum@4"
            ]
        },
        {
            "x": -11,
            "y": 19,
            "z": 2,
            "elements": [
                "chisel:blockplatinum@4"
            ]
        },
        {
            "x": 4,
            "y": 13,
            "z": 4,
            "elements": [
                "chisel:blockelectrum@4"
            ]
        },
        {
            "x": 8,
            "y": 1,
            "z": 20,
            "elements": [
                "chisel:blockplatinum@4"
            ]
        },
        {
            "x": 2,
            "y": 11,
            "z": 20,
            "elements": [
                "chisel:blockplatinum@4"
            ]
        },
        {
            "x": 11,
            "y": 2,
            "z": 20,
            "elements": [
                "chisel:blockplatinum@4"
            ]
        },
        {
            "x": 11,
            "y": 21,
            "z": 18,
            "elements": [
                "chisel:blockplatinum@4"
            ]
        },
        {
            "x": 8,
            "y": 0,
            "z": 20,
            "elements": [
                "minecraft:stained_glass@3"
            ]
        },
        {
            "x": 9,
            "y": 2,
            "z": 19,
            "elements": [
                "chisel:blockplatinum@4"
            ]
        },
        {
            "x": 10,
            "y": 20,
            "z": 7,
            "elements": [
                "minecraft:quartz_block@4"
            ]
        },
        {
            "x": 2,
            "y": 9,
            "z": 21,
            "elements": [
                "chisel:blockplatinum@4"
            ]
        },
        {
            "x": -10,
            "y": 10,
            "z": 8,
            "elements": [
                "minecraft:stained_glass@3"
            ]
        },
        {
            "x": 7,
            "y": 16,
            "z": 5,
            "elements": [
                "chisel:blockelectrum@4"
            ]
        },
        {
            "x": 10,
            "y": 0,
            "z": 11,
            "elements": [
                "minecraft:quartz_block@4"
            ]
        },
        {
            "x": -10,
            "y": 22,
            "z": 20,
            "elements": [
                "minecraft:stained_glass@3"
            ]
        },
        {
            "x": -7,
            "y": 20,
            "z": 20,
            "elements": [
                "minecraft:quartz_block@3"
            ]
        },
        {
            "x": 10,
            "y": 8,
            "z": 10,
            "elements": [
                "minecraft:stained_glass@3"
            ]
        },
        {
            "x": 10,
            "y": 20,
            "z": 3,
            "elements": [
                "minecraft:quartz_block@4"
            ]
        },
        {
            "x": 10,
            "y": 2,
            "z": 1,
            "elements": [
                "chisel:blockplatinum@4"
            ]
        },
        {
            "x": 0,
            "y": 20,
            "z": 20,
            "elements": [
                "casings_all"
            ]
        },
        {
            "x": -1,
            "y": 8,
            "z": 20,
            "elements": [
                "chisel:blockplatinum@4"
            ]
        },
        {
            "x": 7,
            "y": 15,
            "z": 5,
            "elements": [
                "minecraft:stained_glass@4"
            ]
        },
        {
            "x": -6,
            "y": 14,
            "z": 13,
            "elements": [
                "chisel:blockelectrum@4"
            ]
        },
        {
            "x": -6,
            "y": 13,
            "z": 16,
            "elements": [
                "chisel:blockelectrum@4"
            ]
        },
        {
            "x": -8,
            "y": 21,
            "z": -1,
            "elements": [
                "chisel:blockplatinum@4"
            ]
        },
        {
            "x": -8,
            "y": 8,
            "z": 8,
            "elements": [
                "minecraft:quartz_block@1"
            ]
        },
        {
            "x": -2,
            "y": 19,
            "z": 10,
            "elements": [
                "chisel:blockplatinum@4"
            ]
        },
        {
            "x": -1,
            "y": 20,
            "z": 20,
            "elements": [
                "minecraft:quartz_block@3"
            ]
        },
        {
            "x": -2,
            "y": 10,
            "z": 1,
            "elements": [
                "chisel:blockplatinum@4"
            ]
        },
        {
            "x": -12,
            "y": 21,
            "z": 19,
            "elements": [
                "chisel:blockplatinum@4"
            ]
        },
        {
            "x": -9,
            "y": 10,
            "z": 8,
            "elements": [
                "chisel:blockplatinum@4"
            ]
        },
        {
            "x": 2,
            "y": 0,
            "z": 20,
            "elements": [
                "minecraft:quartz_block@3"
            ]
        },
        {
            "x": 5,
            "y": 3,
            "z": 14,
            "elements": [
                "chisel:blockelectrum@4"
            ]
        },
        {
            "x": -4,
            "y": 13,
            "z": 14,
            "elements": [
                "chisel:blockelectrum@4"
            ]
        },
        {
            "x": 10,
            "y": -2,
            "z": 20,
            "elements": [
                "minecraft:stained_glass@3"
            ]
        },
        {
            "x": 8,
            "y": 0,
            "z": 21,
            "elements": [
                "chisel:blockplatinum@4"
            ]
        },
        {
            "x": -9,
            "y": 19,
            "z": 2,
            "elements": [
                "chisel:blockplatinum@4"
            ]
        },
        {
            "x": -2,
            "y": 21,
            "z": 11,
            "elements": [
                "chisel:blockplatinum@4"
            ]
        },
        {
            "x": -10,
            "y": 20,
            "z": 13,
            "elements": [
                "minecraft:quartz_block@4"
            ]
        },
        {
            "x": 10,
            "y": -2,
            "z": 0,
            "elements": [
                "minecraft:stained_glass@3"
            ]
        },
        {
            "x": -9,
            "y": -2,
            "z": 0,
            "elements": [
                "chisel:blockplatinum@4"
            ]
        },
        {
            "x": 2,
            "y": 10,
            "z": 21,
            "elements": [
                "chisel:blockplatinum@4"
            ]
        },
        {
            "x": 2,
            "y": 11,
            "z": 21,
            "elements": [
                "chisel:blockplatinum@4"
            ]
        },
        {
            "x": -8,
            "y": 0,
            "z": 0,
            "elements": [
                "minecraft:stained_glass@3"
            ]
        },
        {
            "x": -10,
            "y": 0,
            "z": 6,
            "elements": [
                "minecraft:quartz_block@4"
            ]
        },
        {
            "x": 10,
            "y": 0,
            "z": 4,
            "elements": [
                "minecraft:quartz_block@4"
            ]
        },
        {
            "x": -2,
            "y": 20,
            "z": 10,
            "elements": [
                "minecraft:stained_glass@3"
            ]
        },
        {
            "x": -1,
            "y": 8,
            "z": 21,
            "elements": [
                "chisel:blockplatinum@4"
            ]
        },
        {
            "x": 10,
            "y": 18,
            "z": -1,
            "elements": [
                "chisel:blockplatinum@4"
            ]
        },
        {
            "x": 10,
            "y": 12,
            "z": 10,
            "elements": [
                "minecraft:stained_glass@3"
            ]
        },
        {
            "x": -11,
            "y": 2,
            "z": 0,
            "elements": [
                "chisel:blockplatinum@4"
            ]
        },
        {
            "x": 8,
            "y": 1,
            "z": 0,
            "elements": [
                "chisel:blockplatinum@4"
            ]
        },
        {
            "x": 11,
            "y": 10,
            "z": 12,
            "elements": [
                "chisel:blockplatinum@4"
            ]
        },
        {
            "x": 8,
            "y": -1,
            "z": 21,
            "elements": [
                "chisel:blockplatinum@4"
            ]
        },
        {
            "x": 1,
            "y": 18,
            "z": 11,
            "elements": [
                "chisel:blockplatinum@4"
            ]
        },
        {
            "x": -9,
            "y": 20,
            "z": -2,
            "elements": [
                "chisel:blockplatinum@4"
            ]
        },
        {
            "x": -2,
            "y": 20,
            "z": 11,
            "elements": [
                "chisel:blockplatinum@4"
            ]
        },
        {
            "x": 8,
            "y": 1,
            "z": 21,
            "elements": [
                "chisel:blockplatinum@4"
            ]
        },
        {
            "x": -3,
            "y": 4,
            "z": 6,
            "elements": [
                "chisel:blockelectrum@4"
            ]
        },
        {
            "x": -1,
            "y": 0,
            "z": 20,
            "elements": [
                "minecraft:quartz_block@3"
            ]
        },
        {
            "x": 10,
            "y": 22,
            "z": 19,
            "elements": [
                "chisel:blockplatinum@4"
            ]
        },
        {
            "x": 11,
            "y": 22,
            "z": 0,
            "elements": [
                "chisel:blockplatinum@4"
            ]
        },
        {
            "x": 10,
            "y": 20,
            "z": 12,
            "elements": [
                "minecraft:quartz_block@4"
            ]
        },
        {
            "x": -2,
            "y": 21,
            "z": 9,
            "elements": [
                "chisel:blockplatinum@4"
            ]
        },
        {
            "x": 11,
            "y": 0,
            "z": -2,
            "elements": [
                "chisel:blockplatinum@4"
            ]
        },
        {
            "x": 10,
            "y": 19,
            "z": -2,
            "elements": [
                "chisel:blockplatinum@4"
            ]
        },
        {
            "x": 7,
            "y": 16,
            "z": 4,
            "elements": [
                "chisel:blockelectrum@4"
            ]
        },
        {
            "x": 12,
            "y": 20,
            "z": 19,
            "elements": [
                "chisel:blockplatinum@4"
            ]
        },
        {
            "x": -11,
            "y": 22,
            "z": 1,
            "elements": [
                "chisel:blockplatinum@4"
            ]
        },
        {
            "x": -8,
            "y": -1,
            "z": 19,
            "elements": [
                "chisel:blockplatinum@4"
            ]
        },
        {
            "x": -9,
            "y": 19,
            "z": 22,
            "elements": [
                "chisel:blockplatinum@4"
            ]
        },
        {
            "x": -8,
            "y": 20,
            "z": 1,
            "elements": [
                "chisel:blockplatinum@4"
            ]
        },
        {
            "x": -5,
            "y": 15,
            "z": 17,
            "elements": [
                "minecraft:stained_glass@4"
            ]
        },
        {
            "x": 1,
            "y": 18,
            "z": 9,
            "elements": [
                "chisel:blockplatinum@4"
            ]
        },
        {
            "x": 2,
            "y": 9,
            "z": 0,
            "elements": [
                "chisel:blockplatinum@4"
            ]
        },
        {
            "x": 9,
            "y": 22,
            "z": 19,
            "elements": [
                "chisel:blockplatinum@4"
            ]
        },
        {
            "x": 9,
            "y": 1,
            "z": 22,
            "elements": [
                "chisel:blockplatinum@4"
            ]
        },
        {
            "x": -4,
            "y": 0,
            "z": 20,
            "elements": [
                "minecraft:quartz_block@3"
            ]
        },
        {
            "x": -1,
            "y": 10,
            "z": -2,
            "elements": [
                "chisel:blockplatinum@4"
            ]
        },
        {
            "x": 2,
            "y": 11,
            "z": 0,
            "elements": [
                "chisel:blockplatinum@4"
            ]
        },
        {
            "x": 7,
            "y": 15,
            "z": 4,
            "elements": [
                "chisel:blockelectrum@4"
            ]
        },
        {
            "x": -9,
            "y": 21,
            "z": 2,
            "elements": [
                "chisel:blockplatinum@4"
            ]
        },
        {
            "x": -10,
            "y": 12,
            "z": 20,
            "elements": [
                "minecraft:quartz_block@2"
            ]
        },
        {
            "x": 1,
            "y": 22,
            "z": 11,
            "elements": [
                "chisel:blockplatinum@4"
            ]
        },
        {
            "x": -8,
            "y": 19,
            "z": -1,
            "elements": [
                "chisel:blockplatinum@4"
            ]
        },
        {
            "x": 9,
            "y": 0,
            "z": 22,
            "elements": [
                "chisel:blockplatinum@4"
            ]
        },
        {
            "x": 2,
            "y": 10,
            "z": 0,
            "elements": [
                "minecraft:stained_glass@3"
            ]
        },
        {
            "x": -9,
            "y": 20,
            "z": 18,
            "elements": [
                "chisel:blockplatinum@4"
            ]
        },
        {
            "x": -10,
            "y": 13,
            "z": 20,
            "elements": [
                "minecraft:quartz_block@2"
            ]
        },
        {
            "x": 0,
            "y": 22,
            "z": 9,
            "elements": [
                "chisel:blockplatinum@4"
            ]
        },
        {
            "x": 0,
            "y": -1,
            "z": 12,
            "elements": [
                "chisel:blockplatinum@4"
            ]
        },
        {
            "x": 10,
            "y": 8,
            "z": 9,
            "elements": [
                "chisel:blockplatinum@4"
            ]
        },
        {
            "x": 7,
            "y": 14,
            "z": 4,
            "elements": [
                "chisel:blockelectrum@4"
            ]
        },
        {
            "x": 10,
            "y": 11,
            "z": 8,
            "elements": [
                "chisel:blockplatinum@4"
            ]
        },
        {
            "x": 10,
            "y": 20,
            "z": 11,
            "elements": [
                "minecraft:quartz_block@4"
            ]
        },
        {
            "x": 10,
            "y": 8,
            "z": 11,
            "elements": [
                "chisel:blockplatinum@4"
            ]
        },
        {
            "x": -11,
            "y": 18,
            "z": 1,
            "elements": [
                "chisel:blockplatinum@4"
            ]
        },
        {
            "x": -1,
            "y": 20,
            "z": 0,
            "elements": [
                "minecraft:quartz_block@3"
            ]
        },
        {
            "x": -10,
            "y": 0,
            "z": 13,
            "elements": [
                "minecraft:quartz_block@4"
            ]
        },
        {
            "x": -12,
            "y": 21,
            "z": -1,
            "elements": [
                "chisel:blockplatinum@4"
            ]
        },
        {
            "x": -3,
            "y": 6,
            "z": 6,
            "elements": [
                "chisel:blockelectrum@4"
            ]
        },
        {
            "x": 10,
            "y": 0,
            "z": 17,
            "elements": [
                "minecraft:quartz_block@4"
            ]
        },
        {
            "x": 11,
            "y": 18,
            "z": 19,
            "elements": [
                "chisel:blockplatinum@4"
            ]
        },
        {
            "x": -10,
            "y": 14,
            "z": 20,
            "elements": [
                "minecraft:quartz_block@2"
            ]
        },
        {
            "x": -8,
            "y": 1,
            "z": 19,
            "elements": [
                "chisel:blockplatinum@4"
            ]
        },
        {
            "x": 10,
            "y": 9,
            "z": 8,
            "elements": [
                "chisel:blockplatinum@4"
            ]
        },
        {
            "x": 10,
            "y": 20,
            "z": 10,
            "elements": [
                "casings_all"
            ]
        },
        {
            "x": -10,
            "y": 15,
            "z": 20,
            "elements": [
                "minecraft:quartz_block@2"
            ]
        },
        {
            "x": 11,
            "y": 22,
            "z": 19,
            "elements": [
                "chisel:blockplatinum@4"
            ]
        },
        {
            "x": 12,
            "y": 20,
            "z": 21,
            "elements": [
                "chisel:blockplatinum@4"
            ]
        },
        {
            "x": -6,
            "y": 13,
            "z": 15,
            "elements": [
                "chisel:blockelectrum@4"
            ]
        },
        {
            "x": 11,
            "y": -1,
            "z": 22,
            "elements": [
                "chisel:blockplatinum@4"
            ]
        },
        {
            "x": -2,
            "y": 20,
            "z": 9,
            "elements": [
                "chisel:blockplatinum@4"
            ]
        },
        {
            "x": 12,
            "y": 21,
            "z": 21,
            "elements": [
                "chisel:blockplatinum@4"
            ]
        },
        {
            "x": -11,
            "y": 20,
            "z": 18,
            "elements": [
                "chisel:blockplatinum@4"
            ]
        },
        {
            "x": 10,
            "y": 0,
            "z": 3,
            "elements": [
                "minecraft:quartz_block@4"
            ]
        },
        {
            "x": 4,
            "y": 17,
            "z": 4,
            "elements": [
                "chisel:blockelectrum@4"
            ]
        },
        {
            "x": -10,
            "y": 18,
            "z": 1,
            "elements": [
                "chisel:blockplatinum@4"
            ]
        },
        {
            "x": -4,
            "y": 20,
            "z": 0,
            "elements": [
                "minecraft:quartz_block@3"
            ]
        },
        {
            "x": -11,
            "y": 1,
            "z": 2,
            "elements": [
                "chisel:blockplatinum@4"
            ]
        },
        {
            "x": -2,
            "y": 19,
            "z": 9,
            "elements": [
                "chisel:blockplatinum@4"
            ]
        },
        {
            "x": 0,
            "y": 18,
            "z": 9,
            "elements": [
                "chisel:blockplatinum@4"
            ]
        },
        {
            "x": 4,
            "y": 5,
            "z": 17,
            "elements": [
                "chisel:blockelectrum@4"
            ]
        },
        {
            "x": -10,
            "y": 16,
            "z": 20,
            "elements": [
                "minecraft:quartz_block@2"
            ]
        },
        {
            "x": 10,
            "y": 21,
            "z": -2,
            "elements": [
                "chisel:blockplatinum@4"
            ]
        },
        {
            "x": 8,
            "y": 20,
            "z": 0,
            "elements": [
                "minecraft:stained_glass@3"
            ]
        },
        {
            "x": -3,
            "y": 14,
            "z": 16,
            "elements": [
                "chisel:blockelectrum@4"
            ]
        },
        {
            "x": -9,
            "y": 0,
            "z": -2,
            "elements": [
                "chisel:blockplatinum@4"
            ]
        },
        {
            "x": 6,
            "y": 7,
            "z": 15,
            "elements": [
                "chisel:blockelectrum@4"
            ]
        },
        {
            "x": -7,
            "y": 4,
            "z": 6,
            "elements": [
                "chisel:blockelectrum@4"
            ]
        },
        {
            "x": 1,
            "y": 9,
            "z": 2,
            "elements": [
                "chisel:blockplatinum@4"
            ]
        },
        {
            "x": -3,
            "y": 16,
            "z": 15,
            "elements": [
                "chisel:blockelectrum@4"
            ]
        },
        {
            "x": -9,
            "y": 18,
            "z": 1,
            "elements": [
                "chisel:blockplatinum@4"
            ]
        },
        {
            "x": -3,
            "y": 15,
            "z": 15,
            "elements": [
                "minecraft:stained_glass@4"
            ]
        },
        {
            "x": 10,
            "y": 12,
            "z": 9,
            "elements": [
                "chisel:blockplatinum@4"
            ]
        },
        {
            "x": -10,
            "y": 9,
            "z": 12,
            "elements": [
                "chisel:blockplatinum@4"
            ]
        },
        {
            "x": -3,
            "y": 15,
            "z": 16,
            "elements": [
                "chisel:blockelectrum@4"
            ]
        },
        {
            "x": -7,
            "y": 7,
            "z": 7,
            "elements": [
                "minecraft:quartz_block@1"
            ]
        },
        {
            "x": -6,
            "y": 17,
            "z": 15,
            "elements": [
                "chisel:blockelectrum@4"
            ]
        },
        {
            "x": -11,
            "y": 11,
            "z": 12,
            "elements": [
                "chisel:blockplatinum@4"
            ]
        },
        {
            "x": -6,
            "y": 5,
            "z": 7,
            "elements": [
                "chisel:blockelectrum@4"
            ]
        },
        {
            "x": 0,
            "y": 9,
            "z": 22,
            "elements": [
                "chisel:blockplatinum@4"
            ]
        },
        {
            "x": 9,
            "y": 18,
            "z": 19,
            "elements": [
                "chisel:blockplatinum@4"
            ]
        },
        {
            "x": 8,
            "y": 20,
            "z": 19,
            "elements": [
                "chisel:blockplatinum@4"
            ]
        },
        {
            "x": 1,
            "y": 11,
            "z": 2,
            "elements": [
                "chisel:blockplatinum@4"
            ]
        },
        {
            "x": 4,
            "y": 15,
            "z": 3,
            "elements": [
                "chisel:blockelectrum@4"
            ]
        },
        {
            "x": -12,
            "y": 20,
            "z": 1,
            "elements": [
                "chisel:blockplatinum@4"
            ]
        },
        {
            "x": 0,
            "y": 10,
            "z": 22,
            "elements": [
                "minecraft:stained_glass@3"
            ]
        },
        {
            "x": -11,
            "y": 9,
            "z": 12,
            "elements": [
                "chisel:blockplatinum@4"
            ]
        },
        {
            "x": 3,
            "y": 6,
            "z": 16,
            "elements": [
                "chisel:blockelectrum@4"
            ]
        },
        {
            "x": 11,
            "y": 20,
            "z": 2,
            "elements": [
                "chisel:blockplatinum@4"
            ]
        },
        {
            "x": -11,
            "y": -2,
            "z": 20,
            "elements": [
                "chisel:blockplatinum@4"
            ]
        },
        {
            "x": 4,
            "y": 14,
            "z": 3,
            "elements": [
                "chisel:blockelectrum@4"
            ]
        },
        {
            "x": 0,
            "y": 11,
            "z": 22,
            "elements": [
                "chisel:blockplatinum@4"
            ]
        },
        {
            "x": 10,
            "y": 0,
            "z": 5,
            "elements": [
                "minecraft:quartz_block@4"
            ]
        },
        {
            "x": -8,
            "y": -1,
            "z": 20,
            "elements": [
                "chisel:blockplatinum@4"
            ]
        },
        {
            "x": -3,
            "y": 16,
            "z": 16,
            "elements": [
                "chisel:blockelectrum@4"
            ]
        },
        {
            "x": -5,
            "y": 5,
            "z": 7,
            "elements": [
                "minecraft:stained_glass@4"
            ]
        },
        {
            "x": -9,
            "y": -1,
            "z": 2,
            "elements": [
                "chisel:blockplatinum@4"
            ]
        },
        {
            "x": 2,
            "y": 20,
            "z": 0,
            "elements": [
                "minecraft:quartz_block@3"
            ]
        },
        {
            "x": 0,
            "y": 8,
            "z": 1,
            "elements": [
                "chisel:blockplatinum@4"
            ]
        },
        {
            "x": 9,
            "y": 12,
            "z": 9,
            "elements": [
                "chisel:blockplatinum@4"
            ]
        },
        {
            "x": 6,
            "y": 7,
            "z": 16,
            "elements": [
                "chisel:blockelectrum@4"
            ]
        },
        {
            "x": -10,
            "y": 11,
            "z": 12,
            "elements": [
                "chisel:blockplatinum@4"
            ]
        },
        {
            "x": -9,
            "y": 21,
            "z": 22,
            "elements": [
                "chisel:blockplatinum@4"
            ]
        },
        {
            "x": -2,
            "y": 11,
            "z": -1,
            "elements": [
                "chisel:blockplatinum@4"
            ]
        },
        {
            "x": 3,
            "y": 5,
            "z": 15,
            "elements": [
                "minecraft:stained_glass@4"
            ]
        },
        {
            "x": 0,
            "y": 11,
            "z": 2,
            "elements": [
                "chisel:blockplatinum@4"
            ]
        },
        {
            "x": 6,
            "y": 3,
            "z": 16,
            "elements": [
                "chisel:blockelectrum@4"
            ]
        },
        {
            "x": -10,
            "y": 0,
            "z": 8,
            "elements": [
                "minecraft:quartz_block@4"
            ]
        },
        {
            "x": -7,
            "y": 0,
            "z": 20,
            "elements": [
                "minecraft:quartz_block@3"
            ]
        },
        {
            "x": -9,
            "y": 20,
            "z": 22,
            "elements": [
                "chisel:blockplatinum@4"
            ]
        },
        {
            "x": 3,
            "y": 6,
            "z": 15,
            "elements": [
                "chisel:blockelectrum@4"
            ]
        },
        {
            "x": 3,
            "y": 4,
            "z": 15,
            "elements": [
                "chisel:blockelectrum@4"
            ]
        },
        {
            "x": -3,
            "y": 3,
            "z": 7,
            "elements": [
                "minecraft:quartz_block@1"
            ]
        },
        {
            "x": -2,
            "y": 9,
            "z": -1,
            "elements": [
                "chisel:blockplatinum@4"
            ]
        },
        {
            "x": 4,
            "y": 16,
            "z": 3,
            "elements": [
                "chisel:blockelectrum@4"
            ]
        },
        {
            "x": -9,
            "y": 22,
            "z": 1,
            "elements": [
                "chisel:blockplatinum@4"
            ]
        },
        {
            "x": -10,
            "y": 0,
            "z": -2,
            "elements": [
                "minecraft:stained_glass@3"
            ]
        },
        {
            "x": 9,
            "y": 1,
            "z": 2,
            "elements": [
                "chisel:blockplatinum@4"
            ]
        },
        {
            "x": 9,
            "y": 19,
            "z": 18,
            "elements": [
                "chisel:blockplatinum@4"
            ]
        },
        {
            "x": 10,
            "y": 12,
            "z": 11,
            "elements": [
                "chisel:blockplatinum@4"
            ]
        },
        {
            "x": -3,
            "y": 14,
            "z": 15,
            "elements": [
                "chisel:blockelectrum@4"
            ]
        },
        {
            "x": -11,
            "y": 0,
            "z": 18,
            "elements": [
                "chisel:blockplatinum@4"
            ]
        },
        {
            "x": 1,
            "y": 22,
            "z": 9,
            "elements": [
                "chisel:blockplatinum@4"
            ]
        },
        {
            "x": 9,
            "y": -1,
            "z": 2,
            "elements": [
                "chisel:blockplatinum@4"
            ]
        },
        {
            "x": -12,
            "y": 1,
            "z": 19,
            "elements": [
                "chisel:blockplatinum@4"
            ]
        },
        {
            "x": 9,
            "y": 8,
            "z": 9,
            "elements": [
                "chisel:blockplatinum@4"
            ]
        },
        {
            "x": -7,
            "y": 6,
            "z": 6,
            "elements": [
                "chisel:blockelectrum@4"
            ]
        },
        {
            "x": 8,
            "y": 19,
            "z": 0,
            "elements": [
                "chisel:blockplatinum@4"
            ]
        },
        {
            "x": 0,
            "y": 9,
            "z": 2,
            "elements": [
                "chisel:blockplatinum@4"
            ]
        },
        {
            "x": 8,
            "y": 21,
            "z": 0,
            "elements": [
                "chisel:blockplatinum@4"
            ]
        },
        {
            "x": -5,
            "y": 7,
            "z": 5,
            "elements": [
                "minecraft:stained_glass@4"
            ]
        },
        {
            "x": 9,
            "y": 20,
            "z": 2,
            "elements": [
                "chisel:blockplatinum@4"
            ]
        },
        {
            "x": 11,
            "y": 18,
            "z": 0,
