{
    "registryname": "abyss_ceremony_executant",
    "localizedname": "§dLV3 - 深渊仪式执行者",
    "requires-blueprint": false,
    "failure-action": "still",
    "color": "000000",
    "parts": [
        {
            "x": 0,
            "y": 0,
            "z": 0,
            "elements": [
                "modularmachinery:blockcontroller@2"
            ]
        },
        {
            "x": 6,
            "y": 4,
            "z": -4,
            "elements": [
                "abyssalcraft:ethaxiumbrickslab1@0"
            ]
        },
        {
            "x": -1,
            "y": 2,
            "z": 0,
            "elements": [
                "abyssalcraft:abyssalsandglass@0"
            ]
        },
        {
            "x": 0,
            "y": 5,
            "z": 2,
            "elements": [
                "abyssalcraft:abyssalsandglass@0"
            ]
        },
        {
            "x": 20,
            "y": 9,
            "z": 1,
            "elements": [
                "abyssalcraft:ethaxiumbrickslab1@0"
            ]
        },
        {
            "x": 3,
            "y": 1,
            "z": -2,
            "elements": [
                "abyssalcraft:ethaxiumbrickslab1@8"
            ]
        },
        {
            "x": 0,
            "y": 6,
            "z": 2,
            "elements": [
                "abyssalcraft:abyssalsandglass@0"
            ]
        },
        {
            "x": 7,
            "y": 5,
            "z": 1,
            "elements": [
                "abyssalcraft:ethaxiumbrickstairs@5"
            ]
        },
        {
            "x": 4,
            "y": 3,
            "z": -2,
            "elements": [
                "abyssalcraft:ethaxiumbrickslab1@0"
            ]
        },
        {
            "x": 6,
            "y": 3,
            "z": -4,
            "elements": [
                "abyssalcraft:ethaxiumbrick@0"
            ]
        },
        {
            "x": -1,
            "y": 1,
            "z": 0,
            "elements": [
                "abyssalcraft:abyssalsandglass@0"
            ]
        },
        {
            "x": -15,
            "y": 8,
            "z": 1,
            "elements": [
                "abyssalcraft:ethaxiumbrick@0"
            ]
        },
        {
            "x": -2,
            "y": 3,
            "z": 0,
            "elements": [
                "abyssalcraft:abyssalsandglass@0"
            ]
        },
        {
            "x": 0,
            "y": 4,
            "z": 2,
            "elements": [
                "abyssalcraft:stone@6"
            ]
        },
        {
            "x": -9,
            "y": 5,
            "z": 1,
            "elements": [
                "abyssalcraft:ethaxiumbrickstairs@4"
            ]
        },
        {
            "x": -14,
            "y": 7,
            "z": 1,
            "elements": [
                "abyssalcraft:ethaxiumbrickslab1@8"
            ]
        },
        {
            "x": 4,
            "y": 2,
            "z": -2,
            "elements": [
                "abyssalcraft:ethaxiumbrick@0"
            ]
        },
        {
            "x": 1,
            "y": 0,
            "z": 0,
            "elements": [
                "abyssalcraft:darkethaxiumbrick@1"
            ]
        },
        {
            "x": 15,
            "y": 9,
            "z": 1,
            "elements": [
                "abyssalcraft:ethaxiumbrickslab1@0"
            ]
        },
        {
            "x": -12,
            "y": 9,
            "z": 1,
            "elements": [
                "abyssalcraft:ethaxiumbrickslab1@0"
            ]
        },
        {
            "x": -9,
            "y": 7,
            "z": 1,
            "elements": [
                "abyssalcraft:ethaxiumbrick@0"
            ]
        },
        {
            "x": -1,
            "y": 4,
            "z": 0,
            "elements": [
                "abyssalcraft:abyssalsandglass@0"
            ]
        },
        {
            "x": -2,
            "y": 1,
            "z": 0,
            "elements": [
                "abyssalcraft:ethaxiumbrickslab1@0"
            ]
        },
        {
            "x": -12,
            "y": 8,
            "z": 1,
            "elements": [
                "abyssalcraft:ethaxiumbrick@0"
            ]
        },
        {
            "x": 15,
            "y": 8,
            "z": 1,
            "elements": [
                "abyssalcraft:ethaxiumbrick@0"
            ]
        },
        {
            "x": 1,
            "y": -1,
            "z": 0,
            "elements": [
                "abyssalcraft:ethaxiumbrickslab1@8"
            ]
        },
        {
            "x": 2,
            "y": 4,
            "z": 1,
            "elements": [
                "abyssalcraft:abyssalsandglass@0"
            ]
        },
        {
            "x": -9,
            "y": 6,
            "z": 1,
            "elements": [
                "abyssalcraft:ethaxiumbrick@0"
            ]
        },
        {
            "x": 1,
            "y": 4,
            "z": 2,
            "elements": [
                "abyssalcraft:abyssalsandglass@0"
            ]
        },
        {
            "x": 3,
            "y": 2,
            "z": -2,
            "elements": [
                "abyssalcraft:darkethaxiumbrick@1"
            ]
        },
        {
            "x": -3,
            "y": 1,
            "z": -2,
            "elements": [
                "abyssalcraft:ethaxiumbrickslab1@8"
            ]
        },
        {
            "x": 18,
            "y": 9,
            "z": 1,
            "elements": [
                "abyssalcraft:ethaxiumbrickslab1@0"
            ]
        },
        {
            "x": 4,
            "y": 3,
            "z": -3,
            "elements": [
                "abyssalcraft:darkethaxiumbrick@1"
            ]
        },
        {
            "x": 2,
            "y": 0,
            "z": 0,
            "elements": [
                "casings_upgrade"
            ]
        },
        {
            "x": -12,
            "y": 7,
            "z": 1,
            "elements": [
                "abyssalcraft:ethaxiumbrick@0"
            ]
        },
        {
            "x": -13,
            "y": 9,
            "z": 1,
            "elements": [
                "abyssalcraft:ethaxiumbrickslab1@0"
            ]
        },
        {
            "x": 1,
            "y": 2,
            "z": 0,
            "elements": [
                "abyssalcraft:abyssalsandglass@0"
            ]
        },
        {
            "x": 0,
            "y": 1,
            "z": 2,
            "elements": [
                "abyssalcraft:abyssalsandglass@0"
            ]
        },
        {
            "x": 5,
            "y": 5,
            "z": 1,
            "elements": [
                "abyssalcraft:ethaxiumbrick@0"
            ]
        },
        {
            "x": -13,
            "y": 8,
            "z": 1,
            "elements": [
                "abyssalcraft:ethaxiumbrick@0"
            ]
        },
        {
            "x": 18,
            "y": 8,
            "z": 1,
            "elements": [
                "abyssalcraft:ethaxiumbrickslab1@8"
            ]
        },
        {
            "x": 1,
            "y": 1,
            "z": 0,
            "elements": [
                "abyssalcraft:abyssalsandglass@0"
            ]
        },
        {
            "x": 4,
            "y": 6,
            "z": 1,
            "elements": [
                "abyssalcraft:ethaxiumbrick@0"
            ]
        },
        {
            "x": 0,
            "y": 0,
            "z": 2,
            "elements": [
                "abyssalcraft:abyssalsandglass@0"
            ]
        },
        {
            "x": -1,
            "y": 3,
            "z": 3,
            "elements": [
                "abyssalcraft:abyssalsandglass@0"
            ]
        },
        {
            "x": 5,
            "y": 4,
            "z": 1,
            "elements": [
                "abyssalcraft:ethaxiumbrickstairs@4"
            ]
        },
        {
            "x": -1,
            "y": 0,
            "z": 0,
            "elements": [
                "abyssalcraft:darkethaxiumbrick@1"
            ]
        },
        {
            "x": 17,
            "y": 9,
            "z": 1,
            "elements": [
                "abyssalcraft:ethaxiumbrickslab1@0"
            ]
        },
        {
            "x": 0,
            "y": 3,
            "z": 2,
            "elements": [
                "abyssalcraft:stone@6"
            ]
        },
        {
            "x": -11,
            "y": 7,
            "z": 1,
            "elements": [
                "abyssalcraft:ethaxiumbrick@0"
            ]
        },
        {
            "x": -14,
            "y": 9,
            "z": 1,
            "elements": [
                "abyssalcraft:ethaxiumbrickslab1@0"
            ]
        },
        {
            "x": 0,
            "y": 4,
            "z": 3,
            "elements": [
                "abyssalcraft:abyssalsandglass@0"
            ]
        },
        {
            "x": -11,
            "y": 6,
            "z": 1,
            "elements": [
                "abyssalcraft:ethaxiumbrickslab1@8"
            ]
        },
        {
            "x": 17,
            "y": 8,
            "z": 1,
            "elements": [
                "abyssalcraft:ethaxiumbrickslab1@8"
            ]
        },
        {
            "x": 1,
            "y": 4,
            "z": 0,
            "elements": [
                "abyssalcraft:abyssalsandglass@0"
            ]
        },
        {
            "x": 4,
            "y": 5,
            "z": 1,
            "elements": [
                "abyssalcraft:ethaxiumbrick@0"
            ]
        },
        {
            "x": -14,
            "y": 8,
            "z": 1,
            "elements": [
                "abyssalcraft:ethaxiumbrick@0"
            ]
        },
        {
            "x": -3,
            "y": 2,
            "z": -2,
            "elements": [
                "abyssalcraft:darkethaxiumbrick@1"
            ]
        },
        {
            "x": 4,
            "y": 2,
            "z": -3,
            "elements": [
                "abyssalcraft:ethaxiumbrickslab1@8"
            ]
        },
        {
            "x": -5,
            "y": 3,
            "z": -3,
            "elements": [
                "abyssalcraft:ethaxiumbrick@0"
            ]
        },
        {
            "x": 1,
            "y": 3,
            "z": 0,
            "elements": [
                "abyssalcraft:stone@6"
            ]
        },
        {
            "x": 5,
            "y": 6,
            "z": 1,
            "elements": [
                "abyssalcraft:ethaxiumbrick@0"
            ]
        },
        {
            "x": 0,
            "y": 2,
            "z": 2,
            "elements": [
                "abyssalcraft:stone@6"
            ]
        },
        {
            "x": 0,
            "y": 3,
            "z": 3,
            "elements": [
                "abyssalcraft:abyssalsandglass@0"
            ]
        },
        {
            "x": -6,
            "y": 3,
            "z": -4,
            "elements": [
                "abyssalcraft:ethaxiumbrick@0"
            ]
        },
        {
            "x": -5,
            "y": 5,
            "z": 1,
            "elements": [
                "abyssalcraft:ethaxiumbrick@0"
            ]
        },
        {
            "x": 8,
            "y": 8,
            "z": 1,
            "elements": [
                "abyssalcraft:ethaxiumbrickslab1@0"
            ]
        },
        {
            "x": -1,
            "y": 3,
            "z": 2,
            "elements": [
                "abyssalcraft:stone@6"
            ]
        },
        {
            "x": -5,
            "y": 4,
            "z": 1,
            "elements": [
                "abyssalcraft:ethaxiumbrickstairs@5"
            ]
        },
        {
            "x": 1,
            "y": 0,
            "z": 1,
            "elements": [
                "abyssalcraft:abyssalsandglass@0"
            ]
        },
        {
            "x": -11,
            "y": 8,
            "z": 1,
            "elements": [
                "abyssalcraft:ethaxiumbrick@0"
            ]
        },
        {
            "x": -6,
            "y": 4,
            "z": -4,
            "elements": [
                "abyssalcraft:ethaxiumbrickslab1@0"
            ]
        },
        {
            "x": -1,
            "y": 2,
            "z": 2,
            "elements": [
                "abyssalcraft:abyssalsandglass@0"
            ]
        },
        {
            "x": 2,
            "y": 3,
            "z": 0,
            "elements": [
                "abyssalcraft:abyssalsandglass@0"
            ]
        },
        {
            "x": 1,
            "y": 1,
            "z": 1,
            "elements": [
                "abyssalcraft:abyssalsandglass@0"
            ]
        },
        {
            "x": 5,
            "y": 3,
            "z": -3,
            "elements": [
                "abyssalcraft:ethaxiumbrick@0"
            ]
        },
        {
            "x": 1,
            "y": 3,
            "z": 1,
            "elements": [
                "abyssalcraft:stone@6"
            ]
        },
        {
            "x": 11,
            "y": 8,
            "z": 1,
            "elements": [
                "abyssalcraft:ethaxiumbrick@0"
            ]
        },
        {
            "x": -2,
            "y": 3,
            "z": 2,
            "elements": [
                "abyssalcraft:abyssalsandglass@0"
            ]
        },
        {
            "x": 1,
            "y": 2,
            "z": 1,
            "elements": [
                "abyssalcraft:stone@6"
            ]
        },
        {
            "x": -1,
            "y": 1,
            "z": 2,
            "elements": [
                "abyssalcraft:abyssalsandglass@0"
            ]
        },
        {
            "x": -5,
            "y": 6,
            "z": 1,
            "elements": [
                "abyssalcraft:ethaxiumbrick@0"
            ]
        },
        {
            "x": 2,
            "y": 1,
            "z": 0,
            "elements": [
                "abyssalcraft:ethaxiumbrickslab1@0"
            ]
        },
        {
            "x": -8,
            "y": 8,
            "z": 1,
            "elements": [
                "abyssalcraft:ethaxiumbrickslab1@0"
            ]
        },
        {
            "x": -2,
            "y": 4,
            "z": 1,
            "elements": [
                "abyssalcraft:abyssalsandglass@0"
            ]
        },
        {
            "x": 6,
            "y": 3,
            "z": -6,
            "elements": [
                "abyssalcraft:ethaxiumbrickslab1@8"
            ]
        },
        {
            "x": 6,
            "y": 4,
            "z": -6,
            "elements": [
                "abyssalcraft:darkethaxiumbrick@1"
            ]
        },
        {
            "x": -2,
            "y": 0,
            "z": 0,
            "elements": [
                "casings_parallel"
            ]
        },
        {
            "x": 14,
            "y": 7,
            "z": 1,
            "elements": [
                "abyssalcraft:ethaxiumbrickslab1@8"
            ]
        },
        {
            "x": -8,
            "y": 7,
            "z": 1,
            "elements": [
                "abyssalcraft:ethaxiumbrick@0"
            ]
        },
        {
            "x": -17,
            "y": 9,
            "z": 1,
            "elements": [
                "abyssalcraft:ethaxiumbrickslab1@0"
            ]
        },
        {
            "x": 1,
            "y": 5,
            "z": 1,
            "elements": [
                "abyssalcraft:abyssalsandglass@0"
            ]
        },
        {
            "x": 7,
            "y": 6,
            "z": 1,
            "elements": [
                "abyssalcraft:ethaxiumbrick@0"
            ]
        },
        {
            "x": -5,
            "y": 3,
            "z": -5,
            "elements": [
                "abyssalcraft:ethaxiumbrick@0"
            ]
        },
        {
            "x": 1,
            "y": 3,
            "z": 2,
            "elements": [
                "abyssalcraft:stone@6"
            ]
        },
        {
            "x": 4,
            "y": 3,
            "z": -4,
            "elements": [
                "abyssalcraft:ethaxiumbrick@0"
            ]
        },
        {
            "x": -17,
            "y": 8,
            "z": 1,
            "elements": [
                "abyssalcraft:ethaxiumbrickslab1@8"
            ]
        },
        {
            "x": 7,
            "y": 5,
            "z": -6,
            "elements": [
                "abyssalcraft:tieredenergypedestal@3"
            ]
        },
        {
            "x": 14,
            "y": 8,
            "z": 1,
            "elements": [
                "abyssalcraft:ethaxiumbrick@0"
            ]
        },
        {
            "x": 1,
            "y": 4,
            "z": 1,
            "elements": [
                "abyssalcraft:stone@6"
            ]
        },
        {
            "x": -8,
            "y": 6,
            "z": 1,
            "elements": [
                "abyssalcraft:ethaxiumbrickslab1@8"
            ]
        },
        {
            "x": -2,
            "y": 2,
            "z": -2,
            "elements": [
                "abyssalcraft:ethaxiumbrickslab1@0"
            ]
        },
        {
            "x": 7,
            "y": 7,
            "z": 1,
            "elements": [
                "abyssalcraft:ethaxiumbrick@0"
            ]
        },
        {
            "x": 7,
            "y": 4,
            "z": -6,
            "elements": [
                "abyssalcraft:ingotblock@3"
            ]
        },
        {
            "x": 3,
            "y": 1,
            "z": -1,
            "elements": [
                "casings_all"
            ]
        },
        {
            "x": 1,
            "y": 2,
            "z": 2,
            "elements": [
                "abyssalcraft:abyssalsandglass@0"
            ]
        },
        {
            "x": 14,
            "y": 9,
            "z": 1,
            "elements": [
                "abyssalcraft:ethaxiumbrickslab1@0"
            ]
        },
        {
            "x": -1,
            "y": 5,
            "z": 0,
            "elements": [
                "abyssalcraft:abyssalsandglass@0"
            ]
        },
        {
            "x": -18,
            "y": 9,
            "z": 1,
            "elements": [
                "abyssalcraft:ethaxiumbrickslab1@0"
            ]
        },
        {
            "x": -2,
            "y": 1,
            "z": -2,
            "elements": [
                "casings_all"
            ]
        },
        {
            "x": 0,
            "y": 4,
            "z": -1,
            "elements": [
                "abyssalcraft:abyssalsandglass@0"
            ]
        },
        {
            "x": 8,
            "y": 6,
            "z": 1,
            "elements": [
                "abyssalcraft:ethaxiumbrickslab1@8"
            ]
        },
        {
            "x": 1,
            "y": 1,
            "z": 2,
            "elements": [
                "abyssalcraft:abyssalsandglass@0"
            ]
        },
        {
            "x": 3,
            "y": 2,
            "z": -1,
            "elements": [
                "abyssalcraft:ethaxiumbrickslab1@0"
            ]
        },
        {
            "x": -18,
            "y": 8,
            "z": 1,
            "elements": [
                "abyssalcraft:ethaxiumbrickslab1@8"
            ]
        },
        {
            "x": 8,
            "y": 7,
            "z": 1,
            "elements": [
                "abyssalcraft:ethaxiumbrick@0"
            ]
        },
        {
            "x": -7,
            "y": 4,
            "z": -6,
            "elements": [
                "abyssalcraft:ingotblock@3"
            ]
        },
        {
            "x": -5,
            "y": 4,
            "z": -5,
            "elements": [
                "abyssalcraft:ethaxiumbrickslab1@0"
            ]
        },
        {
            "x": -7,
            "y": 5,
            "z": -6,
            "elements": [
                "abyssalcraft:tieredenergypedestal@3"
            ]
        },
        {
            "x": 1,
            "y": 6,
            "z": 1,
            "elements": [
                "abyssalcraft:abyssalsandglass@0"
            ]
        },
        {
            "x": -1,
            "y": 5,
            "z": 1,
            "elements": [
                "abyssalcraft:abyssalsandglass@0"
            ]
        },
        {
            "x": -6,
            "y": 7,
            "z": 1,
            "elements": [
                "abyssalcraft:ethaxiumbrick@0"
            ]
        },
        {
            "x": 0,
            "y": 3,
            "z": 1,
            "elements": [
                "abyssalcraft:stone@6"
            ]
        },
        {
            "x": 7,
            "y": 4,
            "z": -5,
            "elements": [
                "abyssalcraft:darkethaxiumbrick@1"
            ]
        },
        {
            "x": -4,
            "y": 3,
            "z": -2,
            "elements": [
                "abyssalcraft:ethaxiumbrickslab1@0"
            ]
        },
        {
            "x": 2,
            "y": 1,
            "z": -1,
            "elements": [
                "abyssalcraft:darkethaxiumbrick@1"
            ]
        },
        {
            "x": 12,
            "y": 8,
            "z": 1,
            "elements": [
                "abyssalcraft:ethaxiumbrick@0"
            ]
        },
        {
            "x": 0,
            "y": 2,
            "z": 1,
            "elements": [
                "abyssalcraft:stone@6"
            ]
        },
        {
            "x": -6,
            "y": 4,
            "z": -6,
            "elements": [
                "abyssalcraft:darkethaxiumbrick@1"
            ]
        },
        {
            "x": -4,
            "y": 2,
            "z": -2,
            "elements": [
                "abyssalcraft:ethaxiumbrick@0"
            ]
        },
        {
            "x": -3,
            "y": 2,
            "z": -1,
            "elements": [
                "abyssalcraft:ethaxiumbrickslab1@0"
            ]
        },
        {
            "x": 2,
            "y": 0,
            "z": -1,
            "elements": [
                "abyssalcraft:ethaxiumbrickslab1@8"
            ]
        },
        {
            "x": -6,
            "y": 6,
            "z": 1,
            "elements": [
                "abyssalcraft:ethaxiumbrick@0"
            ]
        },
        {
            "x": -1,
            "y": 4,
            "z": 1,
            "elements": [
                "abyssalcraft:stone@6"
            ]
        },
        {
            "x": 0,
            "y": 3,
            "z": -1,
            "elements": [
                "abyssalcraft:abyssalsandglass@0"
            ]
        },
        {
            "x": -7,
            "y": 8,
            "z": 1,
            "elements": [
                "abyssalcraft:ethaxiumbrickslab1@0"
            ]
        },
        {
            "x": 1,
            "y": 3,
            "z": 3,
            "elements": [
                "abyssalcraft:abyssalsandglass@0"
            ]
        },
        {
            "x": 13,
            "y": 7,
            "z": 1,
            "elements": [
                "abyssalcraft:ethaxiumbrickslab1@8"
            ]
        },
        {
            "x": 12,
            "y": 9,
            "z": 1,
            "elements": [
                "abyssalcraft:ethaxiumbrickslab1@0"
            ]
        },
        {
            "x": -3,
            "y": 1,
            "z": -1,
            "elements": [
                "casings_all"
            ]
        },
        {
            "x": -6,
            "y": 5,
            "z": 1,
            "elements": [
                "abyssalcraft:ethaxiumbrick@0"
            ]
        },
        {
            "x": 7,
            "y": 8,
            "z": 1,
            "elements": [
                "abyssalcraft:ethaxiumbrickslab1@0"
            ]
        },
        {
            "x": 2,
            "y": 3,
            "z": 2,
            "elements": [
                "abyssalcraft:abyssalsandglass@0"
            ]
        },
        {
            "x": 10,
            "y": 6,
            "z": 1,
            "elements": [
                "abyssalcraft:ethaxiumbrickstairs@5"
            ]
        },
        {
            "x": -6,
            "y": 4,
            "z": 1,
            "elements": [
                "abyssalcraft:ethaxiumbrickstairs@4"
            ]
        },
        {
            "x": 0,
            "y": 0,
            "z": 1,
            "elements": [
                "abyssalcraft:stone@6"
            ]
        },
        {
            "x": -7,
            "y": 4,
            "z": -5,
            "elements": [
                "abyssalcraft:darkethaxiumbrick@1"
            ]
        },
        {
            "x": 10,
            "y": 7,
            "z": 1,
            "elements": [
                "abyssalcraft:ethaxiumbrick@0"
            ]
        },
        {
            "x": -3,
            "y": 3,
            "z": 1,
            "elements": [
                "casings_all"
            ]
        },
        {
            "x": 7,
            "y": 3,
            "z": -5,
            "elements": [
                "abyssalcraft:ethaxiumbrickslab1@8"
            ]
        },
        {
            "x": -20,
            "y": 9,
            "z": 1,
            "elements": [
                "abyssalcraft:ethaxiumbrickslab1@0"
            ]
        },
        {
            "x": -1,
            "y": 6,
            "z": 1,
            "elements": [
                "abyssalcraft:abyssalsandglass@0"
            ]
        },
        {
            "x": 0,
            "y": 1,
            "z": 1,
            "elements": [
                "abyssalcraft:stone@6"
            ]
        },
        {
            "x": 11,
            "y": 6,
            "z": 1,
            "elements": [
                "abyssalcraft:ethaxiumbrickslab1@8"
            ]
        },
        {
            "x": -1,
            "y": 0,
            "z": 1,
            "elements": [
                "abyssalcraft:abyssalsandglass@0"
            ]
        },
        {
            "x": 5,
            "y": 4,
            "z": -5,
            "elements": [
                "abyssalcraft:ethaxiumbrickslab1@0"
            ]
        },
        {
            "x": -3,
            "y": 5,
            "z": 1,
            "elements": [
                "casings_all"
            ]
        },
        {
            "x": -2,
            "y": 2,
            "z": 1,
            "elements": [
                "abyssalcraft:abyssalsandglass@0"
            ]
        },
        {
            "x": 10,
            "y": 8,
            "z": 1,
            "elements": [
                "abyssalcraft:ethaxiumbrick@0"
            ]
        },
        {
            "x": -4,
            "y": 6,
            "z": 1,
            "elements": [
                "abyssalcraft:ethaxiumbrick@0"
            ]
        },
        {
            "x": 11,
            "y": 7,
            "z": 1,
            "elements": [
                "abyssalcraft:ethaxiumbrick@0"
            ]
        },
        {
            "x": -6,
            "y": 4,
            "z": -5,
            "elements": [
                "abyssalcraft:ethaxiumbrick@0"
            ]
        },
        {
            "x": 3,
            "y": 2,
            "z": -3,
            "elements": [
                "abyssalcraft:ethaxiumbrick@0"
            ]
        },
        {
            "x": -3,
            "y": 4,
            "z": 1,
            "elements": [
                "casings_all"
            ]
        },
        {
            "x": -4,
            "y": 3,
            "z": -3,
            "elements": [
                "abyssalcraft:darkethaxiumbrick@1"
            ]
        },
        {
            "x": 2,
            "y": 2,
            "z": -2,
            "elements": [
                "abyssalcraft:ethaxiumbrickslab1@0"
            ]
        },
        {
            "x": -2,
            "y": 3,
            "z": 1,
            "elements": [
                "abyssalcraft:abyssalsandglass@0"
            ]
        },
        {
            "x": -1,
            "y": 1,
            "z": 1,
            "elements": [
                "abyssalcraft:abyssalsandglass@0"
            ]
        },
        {
            "x": 0,
            "y": -2,
            "z": 1,
            "elements": [
                "abyssalcraft:abyssalsandglass@0"
            ]
        },
        {
            "x": 3,
            "y": 3,
            "z": -3,
            "elements": [
                "abyssalcraft:ethaxiumbrickslab1@0"
            ]
        },
        {
            "x": -1,
            "y": 5,
            "z": 2,
            "elements": [
                "abyssalcraft:abyssalsandglass@0"
            ]
        },
        {
            "x": -1,
            "y": 1,
            "z": -1,
            "elements": [
                "abyssalcraft:ethaxiumbrickslab1@0"
            ]
        },
        {
            "x": -4,
            "y": 5,
            "z": 1,
            "elements": [
                "abyssalcraft:ethaxiumbrick@0"
            ]
        },
        {
            "x": -1,
            "y": 3,
            "z": 1,
            "elements": [
                "abyssalcraft:stone@6"
            ]
        },
        {
            "x": 2,
            "y": 1,
            "z": -2,
            "elements": [
                "casings_all"
            ]
        },
        {
            "x": -6,
            "y": 3,
            "z": -5,
            "elements": [
                "abyssalcraft:ethaxiumbrickslab1@8"
            ]
        },
        {
            "x": -1,
            "y": 2,
            "z": 1,
            "elements": [
                "abyssalcraft:stone@6"
            ]
        },
        {
            "x": 9,
            "y": 8,
            "z": 1,
            "elements": [
                "abyssalcraft:ethaxiumbrick@0"
            ]
        },
        {
            "x": -4,
            "y": 2,
            "z": -3,
            "elements": [
                "abyssalcraft:ethaxiumbrickslab1@8"
            ]
        },
        {
            "x": 0,
            "y": -1,
            "z": 1,
            "elements": [
                "abyssalcraft:abyssalsandglass@0"
            ]
        },
        {
            "x": -1,
            "y": 0,
            "z": -1,
            "elements": [
                "casings_all"
            ]
        },
        {
            "x": -1,
            "y": 4,
            "z": 2,
            "elements": [
                "abyssalcraft:abyssalsandglass@0"
            ]
        },
        {
            "x": 0,
            "y": 2,
            "z": -1,
            "elements": [
                "abyssalcraft:abyssalsandglass@0"
            ]
        },
        {
            "x": -1,
            "y": 3,
            "z": -1,
            "elements": [
                "abyssalcraft:abyssalsandglass@0"
            ]
        },
        {
            "x": 5,
            "y": 3,
            "z": -5,
            "elements": [
                "abyssalcraft:ethaxiumbrick@0"
            ]
        },
        {
            "x": 12,
            "y": 7,
            "z": 1,
            "elements": [
                "abyssalcraft:ethaxiumbrick@0"
            ]
        },
        {
            "x": -2,
            "y": 1,
            "z": -1,
            "elements": [
                "abyssalcraft:darkethaxiumbrick@1"
            ]
        },
        {
            "x": 16,
            "y": 9,
            "z": 1,
            "elements": [
                "abyssalcraft:ethaxiumbrickslab1@0"
            ]
        },
        {
            "x": -10,
            "y": 7,
            "z": 1,
            "elements": [
                "abyssalcraft:ethaxiumbrick@0"
            ]
        },
        {
            "x": 9,
            "y": 6,
            "z": 1,
            "elements": [
                "abyssalcraft:ethaxiumbrick@0"
            ]
        },
        {
            "x": -10,
            "y": 6,
            "z": 1,
            "elements": [
                "abyssalcraft:ethaxiumbrickstairs@4"
            ]
        },
        {
            "x": 3,
            "y": 5,
            "z": 1,
            "elements": [
                "casings_all"
            ]
        },
        {
            "x": 16,
            "y": 8,
            "z": 1,
            "elements": [
                "abyssalcraft:ethaxiumbrick@0"
            ]
        },
        {
            "x": -3,
            "y": 2,
            "z": -3,
            "elements": [
                "abyssalcraft:ethaxiumbrick@0"
            ]
        },
        {
            "x": -2,
            "y": 0,
            "z": -1,
            "elements": [
                "abyssalcraft:ethaxiumbrickslab1@8"
            ]
        },
        {
            "x": 9,
            "y": 7,
            "z": 1,
            "elements": [
                "abyssalcraft:ethaxiumbrick@0"
            ]
        },
        {
            "x": 3,
            "y": 4,
            "z": 1,
            "elements": [
                "casings_all"
            ]
        },
        {
            "x": 5,
            "y": 2,
            "z": -4,
            "elements": [
                "abyssalcraft:ethaxiumbrickslab1@8"
            ]
        },
        {
            "x": 6,
            "y": 6,
            "z": 1,
            "elements": [
                "abyssalcraft:ethaxiumbrick@0"
            ]
        },
        {
            "x": -19,
            "y": 9,
            "z": 1,
            "elements": [
                "abyssalcraft:ethaxiumbrickslab1@0"
            ]
        },
        {
            "x": 1,
            "y": 5,
            "z": 0,
            "elements": [
                "abyssalcraft:abyssalsandglass@0"
            ]
        },
        {
            "x": -16,
            "y": 9,
            "z": 1,
            "elements": [
                "abyssalcraft:ethaxiumbrickslab1@0"
            ]
        },
        {
            "x": 1,
            "y": 1,
            "z": -1,
            "elements": [
                "abyssalcraft:ethaxiumbrickslab1@0"
            ]
        },
        {
            "x": 19,
            "y": 9,
            "z": 1,
            "elements": [
                "abyssalcraft:ethaxiumbrickslab1@0"
            ]
        },
        {
            "x": 6,
            "y": 5,
            "z": 1,
            "elements": [
                "abyssalcraft:ethaxiumbrick@0"
            ]
        },
        {
            "x": -16,
            "y": 8,
            "z": 1,
            "elements": [
                "abyssalcraft:ethaxiumbrick@0"
            ]
        },
        {
            "x": 5,
            "y": 3,
            "z": -4,
            "elements": [
                "abyssalcraft:darkethaxiumbrick@1"
            ]
        },
        {
            "x": 0,
            "y": 6,
            "z": 0,
            "elements": [
                "abyssalcraft:abyssalsandglass@0"
            ]
        },
        {
            "x": 0,
            "y": 2,
            "z": 3,
            "elements": [
                "abyssalcraft:abyssalsandglass@0"
            ]
        },
        {
            "x": 1,
            "y": 0,
            "z": -1,
            "elements": [
                "casings_all"
            ]
        },
        {
            "x": 6,
            "y": 7,
            "z": 1,
            "elements": [
                "abyssalcraft:ethaxiumbrick@0"
            ]
        },
        {
            "x": 1,
            "y": 3,
            "z": -1,
            "elements": [
                "abyssalcraft:abyssalsandglass@0"
            ]
        },
        {
            "x": -3,
            "y": 3,
            "z": -3,
            "elements": [
                "abyssalcraft:ethaxiumbrickslab1@0"
            ]
        },
        {
            "x": -13,
            "y": 7,
            "z": 1,
            "elements": [
                "abyssalcraft:ethaxiumbrickslab1@8"
            ]
        },
        {
            "x": 6,
            "y": 4,
            "z": 1,
            "elements": [
                "abyssalcraft:ethaxiumbrickstairs@5"
            ]
        },
        {
            "x": 0,
            "y": 5,
            "z": 0,
            "elements": [
                "abyssalcraft:abyssalsandglass@0"
            ]
        },
        {
            "x": -4,
            "y": 3,
            "z": -4,
            "elements": [
                "abyssalcraft:ethaxiumbrick@0"
            ]
        },
        {
            "x": 2,
            "y": 3,
            "z": 1,
            "elements": [
                "abyssalcraft:abyssalsandglass@0"
            ]
        },
        {
            "x": 0,
            "y": 4,
            "z": 0,
            "elements": [
                "abyssalcraft:stone@6"
            ]
        },
        {
            "x": 9,
            "y": 5,
            "z": 1,
            "elements": [
                "abyssalcraft:ethaxiumbrickstairs@5"
            ]
        },
        {
            "x": -5,
            "y": 2,
            "z": -4,
            "elements": [
                "abyssalcraft:ethaxiumbrickslab1@8"
            ]
        },
        {
            "x": 2,
            "y": 2,
            "z": 1,
            "elements": [
                "abyssalcraft:abyssalsandglass@0"
            ]
        },
        {
            "x": -9,
            "y": 8,
            "z": 1,
            "elements": [
                "abyssalcraft:ethaxiumbrick@0"
            ]
        },
        {
            "x": 0,
            "y": 3,
            "z": 0,
            "elements": [
                "abyssalcraft:stone@6"
            ]
        },
        {
            "x": -7,
            "y": 5,
            "z": 1,
            "elements": [
                "abyssalcraft:ethaxiumbrickstairs@4"
            ]
        },
        {
            "x": 1,
            "y": 5,
            "z": 2,
            "elements": [
                "abyssalcraft:abyssalsandglass@0"
            ]
        },
        {
            "x": 6,
            "y": 3,
            "z": -5,
            "elements": [
                "abyssalcraft:ethaxiumbrickslab1@8"
            ]
        },
        {
            "x": 0,
            "y": 6,
            "z": 1,
            "elements": [
                "abyssalcraft:stone@6"
            ]
        },
        {
            "x": -7,
            "y": 7,
            "z": 1,
            "elements": [
                "abyssalcraft:ethaxiumbrick@0"
            ]
        },
        {
            "x": 0,
            "y": 5,
            "z": 1,
            "elements": [
                "abyssalcraft:stone@6"
            ]
        },
        {
            "x": 0,
            "y": 2,
            "z": 0,
            "elements": [
                "abyssalcraft:stone@6"
            ]
        },
        {
            "x": -5,
            "y": 3,
            "z": -4,
            "elements": [
                "abyssalcraft:darkethaxiumbrick@1"
            ]
        },
        {
            "x": 3,
            "y": 3,
            "z": 1,
            "elements": [
                "casings_all"
            ]
        },
        {
            "x": 6,
            "y": 4,
            "z": -5,
            "elements": [
                "abyssalcraft:ethaxiumbrick@0"
            ]
        },
        {
            "x": 13,
            "y": 8,
            "z": 1,
            "elements": [
                "abyssalcraft:ethaxiumbrick@0"
            ]
        },
        {
            "x": 0,
            "y": 1,
            "z": 0,
            "elements": [
                "abyssalcraft:abyssalsandglass@0"
            ]
        },
        {
            "x": -1,
            "y": -1,
            "z": 0,
            "elements": [
                "abyssalcraft:ethaxiumbrickslab1@8"
            ]
        },
        {
            "x": -7,
            "y": 6,
            "z": 1,
            "elements": [
                "abyssalcraft:ethaxiumbrick@0"
            ]
        },
        {
            "x": -10,
            "y": 8,
            "z": 1,
            "elements": [
                "abyssalcraft:ethaxiumbrick@0"
            ]
        },
        {
            "x": 0,
            "y": 4,
            "z": 1,
            "elements": [
                "abyssalcraft:stone@6"
            ]
        },
        {
            "x": 13,
            "y": 9,
            "z": 1,
            "elements": [
                "abyssalcraft:ethaxiumbrickslab1@0"
            ]
        },
        {
            "x": -15,
            "y": 9,
            "z": 1,
            "elements": [
                "abyssalcraft:ethaxiumbrickslab1@0"
            ]
        }
    ]}