{
    "registryname": "chromasteel_forge",
    "localizedname": "§dLV3 - 炫钢熔合机",
    "requires-blueprint": false,
    "failure-action": "still",
    "color": "cccccc",
    "modifiers": [
        {
            "elements": "modularmachinery:blockcasing@1",
            "x": 0,
            "y": 1,
            "z": 0,
            "description": "将控制器上方紧挨着的方块换成此方块以降低配方制作时间至80%！",
            "modifier": {
                "io": "input",
                "target": "modularmachinery:duration",
                "operation": 1,
                "multiplier": 0.80
            }
        },
        {
            "elements": "modularmachinery:blockcasing@2",
            "x": 0,
            "y": 1,
            "z": 0,
            "description": "将控制器上方紧挨着的方块换成此方块以降低配方制作时间至70%！",
            "modifier": {
                "io": "input",
                "target": "modularmachinery:duration",
                "operation": 1,
                "multiplier": 0.70
            }
        },
        {
            "elements": "modularmachinery:blockcasing@3",
            "x": 0,
            "y": 1,
            "z": 0,
            "description": "将控制器上方紧挨着的方块换成此方块以降低配方制作时间至60%！",
            "modifier": {
                "io": "input",
                "target": "modularmachinery:duration",
                "operation": 1,
                "multiplier": 0.60
            }
        },
        {
            "elements": "modularmachinery:blockcasing@5",
            "x": 0,
            "y": 1,
            "z": 0,
            "description": "将控制器上方紧挨着的方块换成此方块以降低配方制作时间至50%！",
            "modifier": {
                "io": "input",
                "target": "modularmachinery:duration",
                "operation": 1,
                "multiplier": 0.50
            }
        }
    ],
    "parts": [
        {
            "x": 0,
            "y": 0,
            "z": 0,
            "elements": [
                "modularmachinery:blockcontroller@2"
            ]
        },
        {
            "x": -5,
            "y": 11,
            "z": 11,
            "elements": [
                "minecraft:lava@0"
            ]
        },
        {
            "x": -5,
            "y": 4,
            "z": 10,
            "elements": [
                "minecraft:lava@0"
            ]
        },
        {
            "x": -6,
            "y": 8,
            "z": 5,
            "elements": [
                "minecraft:lava@0"
            ]
        },
        {
            "x": -1,
            "y": 2,
            "z": 0,
            "elements": [
                "minecraft:quartz_stairs@2"
            ]
        },
        {
            "x": 0,
            "y": -2,
            "z": 0,
            "elements": [
                "botania:bifrostperm@0"
            ]
        },
        {
            "x": -6,
            "y": 13,
            "z": 7,
            "elements": [
                "minecraft:lava@0"
            ]
        },
        {
            "x": -3,
            "y": 6,
            "z": 7,
            "elements": [
                "minecraft:lava@0"
            ]
        },
        {
            "x": -13,
            "y": 7,
            "z": 12,
            "elements": [
                "casings_all"
            ]
        },
        {
            "x": -5,
            "y": 6,
            "z": 5,
            "elements": [
                "minecraft:lava@0"
            ]
        },
        {
            "x": -4,
            "y": 4,
            "z": 5,
            "elements": [
                "enderio:block_alloy@6"
            ]
        },
        {
            "x": -8,
            "y": 9,
            "z": 11,
            "elements": [
                "minecraft:lava@0"
            ]
        },
        {
            "x": -3,
            "y": 7,
            "z": 7,
            "elements": [
                "minecraft:lava@0"
            ]
        },
        {
            "x": -2,
            "y": 11,
            "z": 9,
            "elements": [
                "thermalfoundation:glass@3"
            ]
        },
        {
            "x": -10,
            "y": 12,
            "z": 10,
            "elements": [
                "minecraft:lava@0"
            ]
        },
        {
            "x": -5,
            "y": 13,
            "z": 9,
            "elements": [
                "minecraft:lava@0"
            ]
        },
        {
            "x": -8,
            "y": 8,
            "z": 10,
            "elements": [
                "minecraft:lava@0"
            ]
        },
        {
            "x": -6,
            "y": 12,
            "z": 7,
            "elements": [
                "minecraft:lava@0"
            ]
        },
        {
            "x": -3,
            "y": 8,
            "z": 7,
            "elements": [
                "minecraft:lava@0"
            ]
        },
        {
            "x": -9,
            "y": 12,
            "z": 5,
            "elements": [
                "minecraft:lava@0"
            ]
        },
        {
            "x": -11,
            "y": 10,
            "z": 10,
            "elements": [
                "minecraft:lava@0"
            ]
        },
        {
            "x": -6,
            "y": 4,
            "z": 10,
            "elements": [
                "minecraft:lava@0"
            ]
        },
        {
            "x": 1,
            "y": 0,
            "z": 0,
            "elements": [
                "minecraft:stone_slab@7"
            ]
        },
        {
            "x": -7,
            "y": 6,
            "z": 10,
            "elements": [
                "minecraft:lava@0"
            ]
        },
        {
            "x": -7,
            "y": 8,
            "z": 5,
            "elements": [
                "minecraft:lava@0"
            ]
        },
        {
            "x": -6,
            "y": 11,
            "z": 7,
            "elements": [
                "minecraft:lava@0"
            ]
        },
        {
            "x": -5,
            "y": 4,
            "z": 5,
            "elements": [
                "minecraft:lava@0"
            ]
        },
        {
            "x": -3,
            "y": 9,
            "z": 7,
            "elements": [
                "minecraft:lava@0"
            ]
        },
        {
            "x": -4,
            "y": 6,
            "z": 5,
            "elements": [
                "minecraft:lava@0"
            ]
        },
        {
            "x": -5,
            "y": 9,
            "z": 11,
            "elements": [
                "minecraft:lava@0"
            ]
        },
        {
            "x": -8,
            "y": 11,
            "z": 11,
            "elements": [
                "minecraft:lava@0"
            ]
        },
        {
            "x": -11,
            "y": 13,
            "z": 11,
            "elements": [
                "enderio:block_alloy_endergy@0"
            ]
        },
        {
            "x": -6,
            "y": 2,
            "z": 10,
            "elements": [
                "thermalfoundation:glass@3"
            ]
        },
        {
            "x": -9,
            "y": 14,
            "z": 5,
            "elements": [
                "thermalfoundation:glass@3"
            ]
        },
        {
            "x": -2,
            "y": 7,
            "z": 11,
            "elements": [
                "thermalfoundation:glass@3"
            ]
        },
        {
            "x": -11,
            "y": 12,
            "z": 10,
            "elements": [
                "minecraft:lava@0"
            ]
        },
        {
            "x": -9,
            "y": 8,
            "z": 10,
            "elements": [
                "minecraft:lava@0"
            ]
        },
        {
            "x": -2,
            "y": 9,
            "z": 9,
            "elements": [
                "thermalfoundation:glass@3"
            ]
        },
        {
            "x": -10,
            "y": 12,
            "z": 5,
            "elements": [
                "minecraft:lava@0"
            ]
        },
        {
            "x": -6,
            "y": 10,
            "z": 7,
            "elements": [
                "minecraft:lava@0"
            ]
        },
        {
            "x": -10,
            "y": 10,
            "z": 10,
            "elements": [
                "minecraft:lava@0"
            ]
        },
        {
            "x": -7,
            "y": 10,
            "z": 5,
            "elements": [
                "minecraft:lava@0"
            ]
        },
        {
            "x": -4,
            "y": 8,
            "z": 5,
            "elements": [
                "minecraft:lava@0"
            ]
        },
        {
            "x": -9,
            "y": 10,
            "z": 5,
            "elements": [
                "minecraft:lava@0"
            ]
        },
        {
            "x": -8,
            "y": 13,
            "z": 11,
            "elements": [
                "minecraft:lava@0"
            ]
        },
        {
            "x": -7,
            "y": 4,
            "z": 10,
            "elements": [
                "minecraft:lava@0"
            ]
        },
        {
            "x": -3,
            "y": 6,
            "z": 5,
            "elements": [
                "enderio:block_alloy_endergy@0"
            ]
        },
        {
            "x": -10,
            "y": 6,
            "z": 10,
            "elements": [
                "minecraft:lava@0"
            ]
        },
        {
            "x": -3,
            "y": 11,
            "z": 7,
            "elements": [
                "minecraft:lava@0"
            ]
        },
        {
            "x": -6,
            "y": 4,
            "z": 5,
            "elements": [
                "minecraft:lava@0"
            ]
        },
        {
            "x": -12,
            "y": 5,
            "z": 4,
            "elements": [
                "enderio:block_alloy@6"
            ]
        },
        {
            "x": -7,
            "y": 2,
            "z": 10,
            "elements": [
                "thermalfoundation:glass@3"
            ]
        },
        {
            "x": -5,
            "y": 7,
            "z": 11,
            "elements": [
                "minecraft:lava@0"
            ]
        },
        {
            "x": -6,
            "y": 10,
            "z": 5,
            "elements": [
                "minecraft:lava@0"
            ]
        },
        {
            "x": -8,
            "y": 12,
            "z": 10,
            "elements": [
                "minecraft:lava@0"
            ]
        },
        {
            "x": -14,
            "y": 9,
            "z": 11,
            "elements": [
                "thermalfoundation:glass@3"
            ]
        },
        {
            "x": -9,
            "y": 14,
            "z": 7,
            "elements": [
                "thermalfoundation:glass@3"
            ]
        },
        {
            "x": -10,
            "y": 8,
            "z": 10,
            "elements": [
                "minecraft:lava@0"
            ]
        },
        {
            "x": -14,
            "y": 5,
            "z": 9,
            "elements": [
                "thermalfoundation:glass@3"
            ]
        },
        {
            "x": -3,
            "y": 10,
            "z": 7,
            "elements": [
                "minecraft:lava@0"
            ]
        },
        {
            "x": -7,
            "y": 12,
            "z": 5,
            "elements": [
                "minecraft:lava@0"
            ]
        },
        {
            "x": -13,
            "y": 10,
            "z": 10,
            "elements": [
                "minecraft:lava@0"
            ]
        },
        {
            "x": -1,
            "y": 0,
            "z": 0,
            "elements": [
                "minecraft:quartz_stairs@4"
            ]
        },
        {
            "x": -12,
            "y": 5,
            "z": 11,
            "elements": [
                "minecraft:lava@0"
            ]
        },
        {
            "x": -11,
            "y": 3,
            "z": 9,
            "elements": [
                "minecraft:lava@0"
            ]
        },
        {
            "x": -9,
            "y": 3,
            "z": 11,
            "elements": [
                "minecraft:lava@0"
            ]
        },
        {
            "x": 3,
            "y": -2,
            "z": 0,
            "elements": [
                "botania:bifrostperm@0"
            ]
        },
        {
            "x": -4,
            "y": 4,
            "z": 10,
            "elements": [
                "enderio:block_alloy@6"
            ]
        },
        {
            "x": -14,
            "y": 7,
            "z": 9,
            "elements": [
                "thermalfoundation:glass@3"
            ]
        },
        {
            "x": -9,
            "y": 8,
            "z": 5,
            "elements": [
                "minecraft:lava@0"
            ]
        },
        {
            "x": -6,
            "y": 6,
            "z": 5,
            "elements": [
                "minecraft:lava@0"
            ]
        },
        {
            "x": -3,
            "y": 4,
            "z": 5,
            "elements": [
                "minecraft:iron_block@0"
            ]
        },
        {
            "x": -6,
            "y": 14,
            "z": 7,
            "elements": [
                "thermalfoundation:glass@3"
            ]
        },
        {
            "x": -8,
            "y": 10,
            "z": 10,
            "elements": [
                "minecraft:lava@0"
            ]
        },
        {
            "x": -7,
            "y": 14,
            "z": 5,
            "elements": [
                "thermalfoundation:glass@3"
            ]
        },
        {
            "x": -3,
            "y": 12,
            "z": 7,
            "elements": [
                "casings_all"
            ]
        },
        {
            "x": -10,
            "y": 13,
            "z": 11,
            "elements": [
                "enderio:block_alloy_endergy@0"
            ]
        },
        {
            "x": -5,
            "y": 5,
            "z": 11,
            "elements": [
                "minecraft:lava@0"
            ]
        },
        {
            "x": -14,
            "y": 9,
            "z": 9,
            "elements": [
                "thermalfoundation:glass@3"
            ]
        },
        {
            "x": -12,
            "y": 7,
            "z": 11,
            "elements": [
                "minecraft:lava@0"
            ]
        },
        {
            "x": -11,
            "y": 7,
            "z": 9,
            "elements": [
                "minecraft:lava@0"
            ]
        },
        {
            "x": -7,
            "y": 8,
            "z": 10,
            "elements": [
                "minecraft:lava@0"
            ]
        },
        {
            "x": -12,
            "y": 12,
            "z": 5,
            "elements": [
                "enderio:block_alloy@6"
            ]
        },
        {
            "x": -12,
            "y": 6,
            "z": 10,
            "elements": [
                "minecraft:lava@0"
            ]
        },
        {
            "x": -6,
            "y": 5,
            "z": 4,
            "elements": [
                "minecraft:lava@0"
            ]
        },
        {
            "x": -12,
            "y": 3,
            "z": 7,
            "elements": [
                "casings_all"
            ]
        },
        {
            "x": -8,
            "y": 3,
            "z": 11,
            "elements": [
                "minecraft:lava@0"
            ]
        },
        {
            "x": -3,
            "y": 11,
            "z": 6,
            "elements": [
                "enderio:block_alloy_endergy@0"
            ]
        },
        {
            "x": -4,
            "y": 11,
            "z": 12,
            "elements": [
                "enderio:block_alloy@6"
            ]
        },
        {
            "x": -12,
            "y": 9,
            "z": 4,
            "elements": [
                "minecraft:lava@0"
            ]
        },
        {
            "x": -9,
            "y": 7,
            "z": 4,
            "elements": [
                "minecraft:lava@0"
            ]
        },
        {
            "x": -10,
            "y": 8,
            "z": 5,
            "elements": [
                "minecraft:lava@0"
            ]
        },
        {
            "x": -6,
            "y": 12,
            "z": 10,
            "elements": [
                "minecraft:lava@0"
            ]
        },
        {
            "x": -9,
            "y": 11,
            "z": 11,
            "elements": [
                "minecraft:lava@0"
            ]
        },
        {
            "x": -9,
            "y": 14,
            "z": 10,
            "elements": [
                "thermalfoundation:glass@3"
            ]
        },
        {
            "x": -3,
            "y": 3,
            "z": 4,
            "elements": [
                "tcomplement:scorched_block@5"
            ]
        },
        {
            "x": -9,
            "y": 4,
            "z": 10,
            "elements": [
                "minecraft:lava@0"
            ]
        },
        {
            "x": -3,
            "y": 10,
            "z": 6,
            "elements": [
                "minecraft:lava@0"
            ]
        },
        {
            "x": -12,
            "y": 9,
            "z": 11,
            "elements": [
                "minecraft:lava@0"
            ]
        },
        {
            "x": -7,
            "y": 2,
            "z": 5,
            "elements": [
                "thermalfoundation:glass@3"
            ]
        },
        {
            "x": -11,
            "y": 7,
            "z": 11,
            "elements": [
                "minecraft:lava@0"
            ]
        },
        {
            "x": -9,
            "y": 2,
            "z": 10,
            "elements": [
                "thermalfoundation:glass@3"
            ]
        },
        {
            "x": -6,
            "y": 5,
            "z": 11,
            "elements": [
                "minecraft:lava@0"
            ]
        },
        {
            "x": -5,
            "y": 3,
            "z": 11,
            "elements": [
                "enderio:block_alloy_endergy@0"
            ]
        },
        {
            "x": -12,
            "y": 8,
            "z": 10,
            "elements": [
                "minecraft:lava@0"
            ]
        },
        {
            "x": -12,
            "y": 2,
            "z": 7,
            "elements": [
                "enderio:block_alloy_endergy@0"
            ]
        },
        {
            "x": -4,
            "y": 10,
            "z": 5,
            "elements": [
                "minecraft:lava@0"
            ]
        },
        {
            "x": -12,
            "y": 5,
            "z": 7,
            "elements": [
                "minecraft:lava@0"
            ]
        },
        {
            "x": -3,
            "y": 8,
            "z": 5,
            "elements": [
                "minecraft:lava@0"
            ]
        },
        {
            "x": -10,
            "y": 10,
            "z": 5,
            "elements": [
                "minecraft:lava@0"
            ]
        },
        {
            "x": -14,
            "y": 11,
            "z": 9,
            "elements": [
                "thermalfoundation:glass@3"
            ]
        },
        {
            "x": -11,
            "y": 5,
            "z": 9,
            "elements": [
                "minecraft:lava@0"
            ]
        },
        {
            "x": -3,
            "y": 5,
            "z": 4,
            "elements": [
                "minecraft:iron_block@0"
            ]
        },
        {
            "x": -6,
            "y": 14,
            "z": 6,
            "elements": [
                "thermalfoundation:glass@3"
            ]
        },
        {
            "x": -12,
            "y": 11,
            "z": 11,
            "elements": [
                "minecraft:lava@0"
            ]
        },
        {
            "x": -8,
            "y": 14,
            "z": 10,
            "elements": [
                "thermalfoundation:glass@3"
            ]
        },
        {
            "x": -12,
            "y": 8,
            "z": 3,
            "elements": [
                "casings_all"
            ]
        },
        {
            "x": -10,
            "y": 4,
            "z": 10,
            "elements": [
                "minecraft:lava@0"
            ]
        },
        {
            "x": -9,
            "y": 9,
            "z": 11,
            "elements": [
                "minecraft:lava@0"
            ]
        },
        {
            "x": -12,
            "y": 7,
            "z": 4,
            "elements": [
                "minecraft:lava@0"
            ]
        },
        {
            "x": -6,
            "y": 3,
            "z": 4,
            "elements": [
                "minecraft:iron_block@0"
            ]
        },
        {
            "x": -12,
            "y": 4,
            "z": 7,
            "elements": [
                "minecraft:lava@0"
            ]
        },
        {
            "x": -9,
            "y": 4,
            "z": 3,
            "elements": [
                "casings_all"
            ]
        },
        {
            "x": -8,
            "y": 13,
            "z": 9,
            "elements": [
                "minecraft:lava@0"
            ]
        },
        {
            "x": -6,
            "y": 10,
            "z": 10,
            "elements": [
                "minecraft:lava@0"
            ]
        },
        {
            "x": -10,
            "y": 2,
            "z": 10,
            "elements": [
                "thermalfoundation:glass@3"
            ]
        },
        {
            "x": -6,
            "y": 7,
            "z": 11,
            "elements": [
                "minecraft:lava@0"
            ]
        },
        {
            "x": -9,
            "y": 9,
            "z": 4,
            "elements": [
                "minecraft:lava@0"
            ]
        },
        {
            "x": -6,
            "y": 12,
            "z": 5,
            "elements": [
                "minecraft:lava@0"
            ]
        },
        {
            "x": -3,
            "y": 10,
            "z": 5,
            "elements": [
                "enderio:block_alloy_endergy@0"
            ]
        },
        {
            "x": -11,
            "y": 5,
            "z": 11,
            "elements": [
                "minecraft:lava@0"
            ]
        },
        {
            "x": -13,
            "y": 10,
            "z": 5,
            "elements": [
                "enderio:block_alloy_endergy@0"
            ]
        },
        {
            "x": -8,
            "y": 9,
            "z": 9,
            "elements": [
                "minecraft:lava@0"
            ]
        },
        {
            "x": -7,
            "y": 6,
            "z": 5,
            "elements": [
                "minecraft:lava@0"
            ]
        },
        {
            "x": -11,
            "y": 11,
            "z": 11,
            "elements": [
                "minecraft:lava@0"
            ]
        },
        {
            "x": -9,
            "y": 3,
            "z": 4,
            "elements": [
                "casings_all"
            ]
        },
        {
            "x": -2,
            "y": 5,
            "z": 9,
            "elements": [
                "thermalfoundation:glass@3"
            ]
        },
        {
            "x": -10,
            "y": 4,
            "z": 5,
            "elements": [
                "minecraft:lava@0"
            ]
        },
        {
            "x": -5,
            "y": 7,
            "z": 9,
            "elements": [
                "minecraft:lava@0"
            ]
        },
        {
            "x": -9,
            "y": 10,
            "z": 10,
            "elements": [
                "minecraft:lava@0"
            ]
        },
        {
            "x": -11,
            "y": 6,
            "z": 3,
            "elements": [
                "enderio:block_alloy_endergy@0"
            ]
        },
        {
            "x": -10,
            "y": 9,
            "z": 11,
            "elements": [
                "minecraft:lava@0"
            ]
        },
        {
            "x": -12,
            "y": 12,
            "z": 10,
            "elements": [
                "enderio:block_alloy@6"
            ]
        },
        {
            "x": -9,
            "y": 7,
            "z": 11,
            "elements": [
                "minecraft:lava@0"
            ]
        },
        {
            "x": -3,
            "y": 7,
            "z": 4,
            "elements": [
                "casings_all"
            ]
        },
        {
            "x": -3,
            "y": 6,
            "z": 10,
            "elements": [
                "minecraft:lava@0"
            ]
        },
        {
            "x": -8,
            "y": 5,
            "z": 11,
            "elements": [
                "minecraft:lava@0"
            ]
        },
        {
            "x": -5,
            "y": 9,
            "z": 9,
            "elements": [
                "minecraft:lava@0"
            ]
        },
        {
            "x": -11,
            "y": 13,
            "z": 9,
            "elements": [
                "minecraft:lava@0"
            ]
        },
        {
            "x": -6,
            "y": 8,
            "z": 10,
            "elements": [
                "minecraft:lava@0"
            ]
        },
        {
            "x": -8,
            "y": 11,
            "z": 9,
            "elements": [
                "minecraft:lava@0"
            ]
        },
        {
            "x": -11,
            "y": 9,
            "z": 9,
            "elements": [
                "minecraft:lava@0"
            ]
        },
        {
            "x": -5,
            "y": 5,
            "z": 9,
            "elements": [
                "minecraft:lava@0"
            ]
        },
        {
            "x": -9,
            "y": 6,
            "z": 10,
            "elements": [
                "minecraft:lava@0"
            ]
        },
        {
            "x": -10,
            "y": 11,
            "z": 11,
            "elements": [
                "minecraft:lava@0"
            ]
        },
        {
            "x": -2,
            "y": 7,
            "z": 9,
            "elements": [
                "thermalfoundation:glass@3"
            ]
        },
        {
            "x": -13,
            "y": 8,
            "z": 5,
            "elements": [
                "minecraft:lava@0"
            ]
        },
        {
            "x": -10,
            "y": 6,
            "z": 5,
            "elements": [
                "minecraft:lava@0"
            ]
        },
        {
            "x": -9,
            "y": 5,
            "z": 4,
            "elements": [
                "minecraft:lava@0"
            ]
        },
        {
            "x": -11,
            "y": 9,
            "z": 11,
            "elements": [
                "minecraft:lava@0"
            ]
        },
        {
            "x": -12,
            "y": 11,
            "z": 4,
            "elements": [
                "enderio:block_alloy@6"
            ]
        },
        {
            "x": -7,
            "y": 4,
            "z": 5,
            "elements": [
                "minecraft:lava@0"
            ]
        },
        {
            "x": -3,
            "y": 8,
            "z": 10,
            "elements": [
                "minecraft:lava@0"
            ]
        },
        {
            "x": 3,
            "y": 0,
            "z": -1,
            "elements": [
                "minecraft:quartz_stairs@1"
            ]
        },
        {
            "x": -9,
            "y": 12,
            "z": 10,
            "elements": [
                "minecraft:lava@0"
            ]
        },
        {
            "x": -8,
            "y": 7,
            "z": 11,
            "elements": [
                "minecraft:lava@0"
            ]
        },
        {
            "x": -9,
            "y": 5,
            "z": 11,
            "elements": [
                "minecraft:lava@0"
            ]
        },
        {
            "x": -12,
            "y": 10,
            "z": 10,
            "elements": [
                "minecraft:lava@0"
            ]
        },
        {
            "x": -6,
            "y": 6,
            "z": 10,
            "elements": [
                "minecraft:lava@0"
            ]
        },
        {
            "x": -3,
            "y": 9,
            "z": 4,
            "elements": [
                "casings_all"
            ]
        },
        {
            "x": -5,
            "y": 11,
            "z": 9,
            "elements": [
                "minecraft:lava@0"
            ]
        },
        {
            "x": -6,
            "y": 3,
            "z": 11,
            "elements": [
                "enderio:block_alloy_endergy@0"
            ]
        },
        {
            "x": -12,
            "y": 10,
            "z": 8,
            "elements": [
                "minecraft:lava@0"
            ]
        },
        {
            "x": -8,
            "y": 10,
            "z": 3,
            "elements": [
                "minecraft:lava@0"
            ]
        },
        {
            "x": -9,
            "y": 8,
            "z": 8,
            "elements": [
                "minecraft:lava@0"
            ]
        },
        {
            "x": -6,
            "y": 13,
            "z": 11,
            "elements": [
                "enderio:block_alloy_endergy@0"
            ]
        },
        {
            "x": -5,
            "y": 8,
            "z": 3,
            "elements": [
                "minecraft:lava@0"
            ]
        },
        {
            "x": -5,
            "y": 3,
            "z": 9,
            "elements": [
                "minecraft:lava@0"
            ]
        },
        {
            "x": -8,
            "y": 5,
            "z": 9,
            "elements": [
                "minecraft:lava@0"
            ]
        },
        {
            "x": -10,
            "y": 9,
            "z": 9,
            "elements": [
                "minecraft:lava@0"
            ]
        },
        {
            "x": -7,
            "y": 3,
            "z": 4,
            "elements": [
                "casings_all"
            ]
        },
        {
            "x": -9,
            "y": 7,
            "z": 8,
            "elements": [
                "minecraft:lava@0"
            ]
        },
        {
            "x": -6,
            "y": 5,
            "z": 8,
            "elements": [
                "minecraft:lava@0"
            ]
        },
        {
            "x": -7,
            "y": 7,
            "z": 9,
            "elements": [
                "minecraft:lava@0"
            ]
        },
        {
            "x": -11,
            "y": 11,
            "z": 4,
            "elements": [
                "minecraft:lava@0"
            ]
        },
        {
            "x": -12,
            "y": 9,
            "z": 8,
            "elements": [
                "minecraft:lava@0"
            ]
        },
        {
            "x": -5,
            "y": 7,
            "z": 4,
            "elements": [
                "minecraft:lava@0"
            ]
        },
        {
            "x": -3,
            "y": 10,
            "z": 10,
            "elements": [
                "minecraft:lava@0"
            ]
        },
        {
            "x": -8,
            "y": 9,
            "z": 4,
            "elements": [
                "minecraft:lava@0"
            ]
        },
        {
            "x": -12,
            "y": 4,
            "z": 5,
            "elements": [
                "enderio:block_alloy@6"
            ]
        },
        {
            "x": -10,
            "y": 11,
            "z": 9,
            "elements": [
                "minecraft:lava@0"
            ]
        },
        {
            "x": -6,
            "y": 6,
            "z": 8,
            "elements": [
                "minecraft:lava@0"
            ]
        },
        {
            "x": -3,
            "y": 4,
            "z": 8,
            "elements": [
                "casings_all"
            ]
        },
        {
            "x": -6,
            "y": 8,
            "z": 8,
            "elements": [
                "minecraft:lava@0"
            ]
        },
        {
            "x": -7,
            "y": 5,
            "z": 9,
            "elements": [
                "minecraft:lava@0"
            ]
        },
        {
            "x": -7,
            "y": 5,
            "z": 4,
            "elements": [
                "minecraft:lava@0"
            ]
        },
        {
            "x": -12,
            "y": 13,
            "z": 8,
            "elements": [
                "casings_all"
            ]
        },
        {
            "x": -9,
            "y": 9,
            "z": 9,
            "elements": [
                "minecraft:lava@0"
            ]
        },
        {
            "x": -8,
            "y": 8,
            "z": 3,
            "elements": [
                "minecraft:lava@0"
            ]
        },
        {
            "x": -8,
            "y": 7,
            "z": 4,
            "elements": [
                "minecraft:lava@0"
            ]
        },
        {
            "x": -8,
            "y": 7,
            "z": 9,
            "elements": [
                "minecraft:lava@0"
            ]
        },
        {
            "x": -12,
            "y": 12,
            "z": 8,
            "elements": [
                "minecraft:lava@0"
            ]
        },
        {
            "x": -9,
            "y": 5,
            "z": 8,
            "elements": [
                "minecraft:lava@0"
            ]
        },
        {
            "x": -12,
            "y": 11,
            "z": 8,
            "elements": [
                "minecraft:lava@0"
            ]
        },
        {
            "x": -5,
            "y": 9,
            "z": 4,
            "elements": [
                "minecraft:lava@0"
            ]
        },
        {
            "x": -12,
            "y": 6,
            "z": 5,
            "elements": [
                "minecraft:lava@0"
            ]
        },
        {
            "x": -7,
            "y": 7,
            "z": 4,
            "elements": [
                "minecraft:lava@0"
            ]
        },
        {
            "x": -6,
            "y": 7,
            "z": 8,
            "elements": [
                "minecraft:lava@0"
            ]
        },
        {
            "x": -2,
            "y": 10,
            "z": 10,
            "elements": [
                "thermalfoundation:glass@3"
            ]
        },
        {
            "x": -9,
            "y": 6,
            "z": 8,
            "elements": [
                "minecraft:lava@0"
            ]
        },
        {
            "x": -11,
            "y": 11,
            "z": 9,
            "elements": [
                "minecraft:lava@0"
            ]
        },
        {
            "x": -6,
            "y": 3,
            "z": 9,
            "elements": [
                "minecraft:lava@0"
            ]
        },
        {
            "x": -9,
            "y": 13,
            "z": 8,
            "elements": [
                "minecraft:lava@0"
            ]
        },
        {
            "x": -12,
            "y": 13,
            "z": 9,
            "elements": [
                "casings_all"
            ]
        },
        {
            "x": -12,
            "y": 9,
            "z": 9,
            "elements": [
                "minecraft:lava@0"
            ]
        },
        {
            "x": -5,
            "y": 10,
            "z": 3,
            "elements": [
                "enderio:block_alloy_endergy@0"
            ]
        },
        {
            "x": -6,
            "y": 11,
            "z": 4,
            "elements": [
                "minecraft:lava@0"
            ]
        },
        {
            "x": -12,
            "y": 5,
            "z": 8,
            "elements": [
                "minecraft:lava@0"
            ]
        },
        {
            "x": -6,
            "y": 5,
            "z": 9,
            "elements": [
                "minecraft:lava@0"
            ]
        },
        {
            "x": -3,
            "y": 8,
            "z": 8,
            "elements": [
                "minecraft:lava@0"
            ]
        },
        {
            "x": -9,
            "y": 7,
            "z": 9,
            "elements": [
                "minecraft:lava@0"
            ]
        },
        {
            "x": -9,
            "y": 3,
            "z": 8,
            "elements": [
                "minecraft:lava@0"
            ]
        },
        {
            "x": -9,
            "y": 4,
            "z": 8,
            "elements": [
                "minecraft:lava@0"
            ]
        },
        {
            "x": -4,
            "y": 5,
            "z": 4,
            "elements": [
                "enderio:block_alloy@6"
            ]
        },
        {
            "x": -6,
            "y": 10,
            "z": 8,
            "elements": [
                "minecraft:lava@0"
            ]
        },
        {
            "x": -9,
            "y": 14,
            "z": 8,
            "elements": [
                "thermalfoundation:glass@3"
            ]
        },
        {
            "x": -11,
            "y": 8,
            "z": 3,
            "elements": [
                "minecraft:lava@0"
            ]
        },
        {
            "x": -12,
            "y": 8,
            "z": 5,
            "elements": [
                "minecraft:lava@0"
            ]
        },
        {
            "x": -3,
            "y": 7,
            "z": 8,
            "elements": [
                "minecraft:lava@0"
            ]
        },
        {
            "x": -8,
            "y": 6,
            "z": 3,
            "elements": [
                "minecraft:lava@0"
            ]
        },
        {
            "x": -6,
            "y": 9,
            "z": 11,
            "elements": [
                "minecraft:lava@0"
            ]
        },
        {
            "x": -5,
            "y": 3,
            "z": 4,
            "elements": [
                "minecraft:iron_block@0"
            ]
        },
        {
            "x": -6,
            "y": 9,
            "z": 4,
            "elements": [
                "minecraft:lava@0"
            ]
        },
        {
            "x": -8,
            "y": 4,
            "z": 3,
            "elements": [
                "casings_all"
            ]
        },
        {
            "x": -6,
            "y": 9,
            "z": 8,
            "elements": [
                "minecraft:lava@0"
            ]
        },
        {
            "x": -2,
            "y": 8,
            "z": 10,
            "elements": [
                "thermalfoundation:glass@3"
            ]
        },
        {
            "x": -6,
            "y": 12,
            "z": 8,
            "elements": [
                "minecraft:lava@0"
            ]
        },
        {
            "x": -5,
            "y": 10,
            "z": 10,
            "elements": [
                "minecraft:lava@0"
            ]
        },
        {
            "x": -8,
            "y": 13,
            "z": 4,
            "elements": [
                "casings_all"
            ]
        },
        {
            "x": -6,
            "y": 13,
            "z": 8,
            "elements": [
                "minecraft:lava@0"
            ]
        },
        {
            "x": -12,
            "y": 11,
            "z": 9,
            "elements": [
                "minecraft:lava@0"
            ]
        },
        {
            "x": -9,
            "y": 11,
            "z": 4,
            "elements": [
                "minecraft:lava@0"
            ]
        },
        {
            "x": -3,
            "y": 6,
            "z": 8,
            "elements": [
                "minecraft:lava@0"
            ]
        },
        {
            "x": -12,
            "y": 6,
            "z": 8,
            "elements": [
                "minecraft:lava@0"
            ]
        },
        {
            "x": -5,
            "y": 5,
            "z": 4,
            "elements": [
                "minecraft:lava@0"
            ]
        },
        {
            "x": -9,
            "y": 13,
            "z": 11,
            "elements": [
                "minecraft:lava@0"
            ]
        },
        {
            "x": -11,
            "y": 10,
            "z": 3,
            "elements": [
                "enderio:block_alloy_endergy@0"
            ]
        },
        {
            "x": -12,
            "y": 10,
            "z": 5,
            "elements": [
                "minecraft:lava@0"
            ]
        },
        {
            "x": -7,
            "y": 9,
            "z": 9,
            "elements": [
                "minecraft:lava@0"
            ]
        },
        {
            "x": -9,
            "y": 5,
            "z": 9,
            "elements": [
                "minecraft:lava@0"
            ]
        },
        {
            "x": -3,
            "y": 5,
            "z": 8,
            "elements": [
                "minecraft:lava@0"
            ]
        },
        {
            "x": -12,
            "y": 7,
            "z": 8,
            "elements": [
                "minecraft:lava@0"
            ]
        },
        {
            "x": -5,
            "y": 12,
            "z": 10,
            "elements": [
                "minecraft:lava@0"
            ]
        },
        {
            "x": -4,
            "y": 3,
            "z": 4,
            "elements": [
                "tcomplement:scorched_block@6"
            ]
        },
        {
            "x": -6,
            "y": 14,
            "z": 10,
            "elements": [
                "thermalfoundation:glass@3"
            ]
        },
        {
            "x": -9,
            "y": 6,
            "z": 3,
            "elements": [
                "minecraft:lava@0"
            ]
        },
        {
            "x": -6,
            "y": 7,
            "z": 9,
            "elements": [
                "minecraft:lava@0"
            ]
        },
        {
            "x": -6,
            "y": 11,
            "z": 11,
            "elements": [
                "minecraft:lava@0"
            ]
        },
        {
            "x": -7,
            "y": 9,
            "z": 4,
            "elements": [
                "minecraft:lava@0"
            ]
        },
        {
            "x": -9,
            "y": 2,
            "z": 8,
            "elements": [
                "thermalfoundation:glass@3"
            ]
        },
        {
            "x": -9,
            "y": 13,
            "z": 4,
            "elements": [
                "casings_all"
            ]
        },
        {
            "x": -6,
            "y": 7,
            "z": 4,
            "elements": [
                "minecraft:lava@0"
            ]
        },
        {
            "x": -4,
            "y": 12,
            "z": 5,
            "elements": [
                "enderio:block_alloy@6"
            ]
        },
        {
            "x": -9,
            "y": 11,
            "z": 9,
            "elements": [
                "minecraft:lava@0"
            ]
        },
        {
            "x": -8,
            "y": 3,
            "z": 9,
            "elements": [
                "minecraft:lava@0"
            ]
        },
        {
            "x": -6,
            "y": 11,
            "z": 8,
            "elements": [
                "minecraft:lava@0"
            ]
        },
        {
            "x": -12,
            "y": 8,
            "z": 8,
            "elements": [
                "minecraft:lava@0"
            ]
        },
        {
            "x": -8,
            "y": 11,
            "z": 4,
            "elements": [
                "minecraft:lava@0"
            ]
        },
        {
            "x": -10,
            "y": 13,
            "z": 9,
            "elements": [
                "minecraft:lava@0"
            ]
        },
        {
            "x": -2,
            "y": 6,
            "z": 10,
            "elements": [
                "thermalfoundation:glass@3"
            ]
        },
        {
            "x": -4,
            "y": 5,
            "z": 9,
            "elements": [
                "minecraft:lava@0"
            ]
        },
        {
            "x": -7,
            "y": 12,
            "z": 3,
            "elements": [
                "casings_all"
            ]
        },
        {
            "x": -13,
            "y": 11,
            "z": 9,
            "elements": [
                "minecraft:lava@0"
            ]
        },
        {
            "x": -7,
            "y": 13,
            "z": 4,
            "elements": [
                "casings_all"
            ]
        },
        {
            "x": -9,
            "y": 8,
            "z": 3,
            "elements": [
                "minecraft:lava@0"
            ]
        },
        {
            "x": -3,
            "y": 7,
            "z": 9,
            "elements": [
                "minecraft:lava@0"
            ]
        },
        {
            "x": -6,
            "y": 6,
            "z": 3,
            "elements": [
                "minecraft:lava@0"
            ]
        },
        {
            "x": -3,
            "y": 4,
            "z": 3,
            "elements": [
                "tcomplement:scorched_block@5"
            ]
        },
        {
            "x": -6,
            "y": 4,
            "z": 3,
            "elements": [
                "minecraft:iron_block@0"
            ]
        },
        {
            "x": -9,
            "y": 6,
            "z": 5,
            "elements": [
                "minecraft:lava@0"
            ]
        },
        {
            "x": -3,
            "y": 7,
            "z": 11,
            "elements": [
                "minecraft:lava@0"
            ]
        },
        {
            "x": -3,
            "y": 2,
            "z": 3,
            "elements": [
                "minecraft:quartz_block@2"
            ]
        },
        {
            "x": -4,
            "y": 9,
            "z": 4,
            "elements": [
                "minecraft:lava@0"
            ]
        },
        {
            "x": -9,
            "y": 13,
            "z": 9,
            "elements": [
                "minecraft:lava@0"
            ]
        },
        {
            "x": -1,
            "y": -1,
            "z": -3,
            "elements": [
                "botania:bifrostperm@0"
            ]
        },
        {
            "x": -5,
            "y": 6,
            "z": 10,
            "elements": [
                "minecraft:lava@0"
            ]
        },
        {
            "x": -6,
            "y": 11,
            "z": 9,
            "elements": [
                "minecraft:lava@0"
            ]
        },
        {
            "x": -7,
            "y": 11,
            "z": 4,
            "elements": [
                "minecraft:lava@0"
            ]
        },
        {
            "x": -4,
            "y": 8,
            "z": 3,
            "elements": [
                "casings_all"
            ]
        },
        {
            "x": -12,
            "y": 7,
            "z": 2,
            "elements": [
                "enderio:block_alloy_endergy@0"
            ]
        },
        {
            "x": -11,
            "y": 6,
            "z": 10,
            "elements": [
                "minecraft:lava@0"
            ]
        },
        {
            "x": -9,
            "y": 10,
            "z": 3,
            "elements": [
                "minecraft:lava@0"
            ]
        },
        {
            "x": -13,
            "y": 9,
            "z": 9,
            "elements": [
                "minecraft:lava@0"
            ]
        },
        {
            "x": -3,
            "y": 5,
            "z": 9,
            "elements": [
                "minecraft:lava@0"
            ]
        },
        {
            "x": -11,
            "y": 3,
            "z": 11,
            "elements": [
                "enderio:block_alloy_endergy@0"
            ]
        },
        {
            "x": -12,
            "y": 3,
            "z": 8,
            "elements": [
                "casings_all"
            ]
        },
        {
            "x": -4,
            "y": 7,
            "z": 9,
            "elements": [
                "minecraft:lava@0"
            ]
        },
        {
            "x": -3,
            "y": 10,
            "z": 8,
            "elements": [
                "minecraft:lava@0"
            ]
        },
        {
            "x": -6,
            "y": 14,
            "z": 8,
            "elements": [
                "thermalfoundation:glass@3"
            ]
        },
        {
            "x": -11,
            "y": 5,
            "z": 4,
            "elements": [
                "minecraft:lava@0"
            ]
        },
        {
            "x": -9,
            "y": 4,
            "z": 5,
            "elements": [
                "minecraft:lava@0"
            ]
        },
        {
            "x": -10,
            "y": 11,
            "z": 4,
            "elements": [
                "minecraft:lava@0"
            ]
        },
        {
            "x": -7,
            "y": 11,
            "z": 9,
            "elements": [
                "minecraft:lava@0"
            ]
        },
        {
            "x": -12,
            "y": 4,
            "z": 8,
            "elements": [
                "minecraft:lava@0"
            ]
        },
        {
            "x": -3,
            "y": 5,
            "z": 11,
            "elements": [
                "enderio:block_alloy_endergy@0"
            ]
        },
        {
            "x": -4,
            "y": 7,
            "z": 4,
            "elements": [
                "minecraft:lava@0"
            ]
        },
        {
            "x": -3,
            "y": 9,
            "z": 8,
            "elements": [
                "minecraft:lava@0"
            ]
        },
        {
            "x": -14,
            "y": 10,
            "z": 10,
            "elements": [
                "thermalfoundation:glass@3"
            ]
        },
        {
            "x": -6,
            "y": 9,
            "z": 9,
            "elements": [
                "minecraft:lava@0"
            ]
        },
        {
            "x": 2,
            "y": -1,
            "z": -3,
            "elements": [
                "casings_all"
            ]
        },
        {
            "x": -5,
            "y": 8,
            "z": 10,
            "elements": [
                "minecraft:lava@0"
            ]
        },
        {
            "x": -14,
            "y": 7,
            "z": 11,
            "elements": [
                "thermalfoundation:glass@3"
            ]
        },
        {
            "x": -10,
            "y": 3,
            "z": 9,
            "elements": [
                "minecraft:lava@0"
            ]
        },
        {
            "x": -3,
            "y": 11,
            "z": 11,
            "elements": [
                "enderio:block_alloy_endergy@0"
            ]
        },
        {
            "x": -14,
            "y": 6,
            "z": 10,
            "elements": [
                "thermalfoundation:glass@3"
            ]
        },
        {
            "x": -9,
            "y": 12,
            "z": 3,
            "elements": [
                "casings_all"
            ]
        },
        {
            "x": -8,
            "y": 5,
            "z": 4,
            "elements": [
                "minecraft:lava@0"
            ]
        },
        {
            "x": -10,
            "y": 5,
            "z": 9,
            "elements": [
                "minecraft:lava@0"
            ]
        },
        {
            "x": -7,
            "y": 8,
            "z": 3,
            "elements": [
                "minecraft:lava@0"
            ]
        },
        {
            "x": -13,
            "y": 7,
            "z": 9,
            "elements": [
                "minecraft:lava@0"
            ]
        },
        {
            "x": -4,
            "y": 6,
            "z": 3,
            "elements": [
                "minecraft:iron_block@0"
            ]
        },
        {
            "x": -5,
            "y": 4,
            "z": 3,
            "elements": [
                "minecraft:iron_block@0"
            ]
        },
        {
            "x": 2,
            "y": 1,
            "z": 4,
            "elements": [
                "botania:bifrostperm@0"
            ]
        },
        {
            "x": -11,
            "y": 7,
            "z": 4,
            "elements": [
                "minecraft:lava@0"
            ]
        },
        {
            "x": -11,
            "y": 4,
            "z": 10,
            "elements": [
                "minecraft:lava@0"
            ]
        },
        {
            "x": -10,
            "y": 9,
            "z": 4,
            "elements": [
                "minecraft:lava@0"
            ]
        },
        {
            "x": 1,
            "y": -1,
            "z": -3,
            "elements": [
                "additions:electronium_block@0"
            ]
        },
        {
            "x": -9,
            "y": 2,
            "z": 5,
            "elements": [
                "thermalfoundation:glass@3"
            ]
        },
        {
            "x": -7,
            "y": 3,
            "z": 9,
            "elements": [
                "minecraft:lava@0"
            ]
        },
        {
            "x": -6,
            "y": 8,
            "z": 3,
            "elements": [
                "minecraft:lava@0"
            ]
        },
        {
            "x": -6,
            "y": 10,
            "z": 3,
            "elements": [
                "minecraft:lava@0"
            ]
        },
        {
            "x": -8,
            "y": 4,
            "z": 10,
            "elements": [
                "minecraft:lava@0"
            ]
        },
        {
            "x": -7,
            "y": 10,
            "z": 3,
            "elements": [
                "minecraft:lava@0"
            ]
        },
        {
            "x": -8,
            "y": 12,
            "z": 3,
            "elements": [
                "casings_all"
            ]
        },
        {
            "x": -10,
            "y": 7,
            "z": 9,
            "elements": [
                "minecraft:lava@0"
            ]
        },
        {
            "x": -3,
            "y": 11,
            "z": 8,
            "elements": [
                "minecraft:lava@0"
            ]
        },
        {
            "x": -4,
            "y": 3,
            "z": 9,
            "elements": [
                "casings_all"
            ]
        },
        {
            "x": -14,
            "y": 8,
            "z": 10,
            "elements": [
                "thermalfoundation:glass@3"
            ]
        },
        {
            "x": -10,
            "y": 7,
            "z": 4,
            "elements": [
                "minecraft:lava@0"
            ]
        },
        {
            "x": -12,
            "y": 2,
            "z": 8,
            "elements": [
                "enderio:block_alloy_endergy@0"
            ]
        },
        {
            "x": -8,
            "y": 3,
            "z": 4,
            "elements": [
                "casings_all"
            ]
        },
        {
            "x": -3,
            "y": 9,
            "z": 11,
            "elements": [
                "minecraft:lava@0"
            ]
        },
        {
            "x": -5,
            "y": 6,
            "z": 3,
            "elements": [
                "enderio:block_alloy_endergy@0"
            ]
        },
        {
            "x": -4,
            "y": 4,
            "z": 3,
            "elements": [
                "tcomplement:scorched_block@6"
            ]
        },
        {
            "x": -2,
            "y": 2,
            "z": 3,
            "elements": [
                "minecraft:quartz_stairs@7"
            ]
        },
        {
            "x": -6,
            "y": 13,
            "z": 9,
            "elements": [
                "minecraft:lava@0"
            ]
        },
        {
            "x": -11,
            "y": 9,
            "z": 4,
            "elements": [
                "minecraft:lava@0"
            ]
        },
        {
            "x": -8,
            "y": 2,
            "z": 10,
            "elements": [
                "thermalfoundation:glass@3"
            ]
        },
        {
            "x": -3,
            "y": 12,
            "z": 8,
            "elements": [
                "casings_all"
            ]
        },
        {
            "x": -4,
            "y": 11,
            "z": 4,
            "elements": [
                "enderio:block_alloy@6"
            ]
        },
        {
            "x": -11,
            "y": 8,
            "z": 10,
            "elements": [
                "minecraft:lava@0"
            ]
        },
        {
            "x": -13,
            "y": 5,
            "z": 9,
            "elements": [
                "minecraft:lava@0"
            ]
        },
        {
            "x": -4,
            "y": 7,
            "z": 14,
            "elements": [
                "enderio:block_alloy_endergy@0"
            ]
        },
        {
            "x": -9,
            "y": 13,
            "z": 12,
            "elements": [
                "casings_all"
            ]
        },
        {
            "x": -11,
            "y": 2,
            "z": 8,
            "elements": [
                "thermalfoundation:glass@3"
            ]
        },
        {
            "x": -4,
            "y": 10,
            "z": 8,
            "elements": [
                "minecraft:lava@0"
            ]
        },
        {
            "x": -12,
            "y": 5,
            "z": 12,
            "elements": [
                "enderio:block_alloy@6"
            ]
        },
        {
            "x": -4,
            "y": 9,
            "z": 7,
            "elements": [
                "minecraft:lava@0"
            ]
        },
        {
            "x": -7,
            "y": 12,
            "z": 8,
            "elements": [
                "minecraft:lava@0"
            ]
        },
        {
            "x": -3,
            "y": 10,
            "z": 9,
            "elements": [
                "minecraft:lava@0"
            ]
        },
        {
            "x": -4,
            "y": 12,
            "z": 6,
            "elements": [
                "enderio:block_alloy@6"
            ]
        },
        {
            "x": -7,
            "y": 14,
            "z": 8,
            "elements": [
                "thermalfoundation:glass@3"
            ]
        },
        {
            "x": -11,
            "y": 4,
            "z": 8,
            "elements": [
                "minecraft:lava@0"
            ]
        },
        {
            "x": -14,
            "y": 6,
            "z": 8,
            "elements": [
                "thermalfoundation:glass@3"
            ]
        },
        {
            "x": -13,
            "y": 11,
            "z": 7,
            "elements": [
                "minecraft:lava@0"
            ]
        },
        {
            "x": 3,
            "y": 0,
            "z": -2,
            "elements": [
                "minecraft:quartz_stairs@1"
            ]
        },
        {
            "x": -7,
            "y": 10,
            "z": 6,
            "elements": [
                "minecraft:lava@0"
            ]
        },
        {
            "x": -8,
            "y": 2,
            "z": 8,
            "elements": [
                "thermalfoundation:glass@3"
            ]
        },
        {
            "x": -4,
            "y": 12,
            "z": 8,
            "elements": [
                "minecraft:lava@0"
            ]
        },
        {
            "x": -3,
            "y": 9,
            "z": 9,
            "elements": [
                "minecraft:lava@0"
            ]
        },
        {
            "x": -1,
            "y": 3,
            "z": 7,
            "elements": [
                "botania:bifrostperm@0"
            ]
        },
        {
            "x": -6,
            "y": 9,
            "z": 12,
            "elements": [
                "minecraft:lava@0"
            ]
        },
        {
            "x": -10,
            "y": 5,
            "z": 7,
            "elements": [
                "minecraft:lava@0"
            ]
        },
        {
            "x": -3,
            "y": 12,
            "z": 9,
            "elements": [
                "casings_all"
            ]
        },
        {
            "x": -10,
            "y": 14,
            "z": 8,
            "elements": [
                "thermalfoundation:glass@3"
            ]
        },
        {
            "x": -12,
            "y": 7,
            "z": 12,
            "elements": [
                "minecraft:lava@0"
            ]
        },
        {
            "x": -10,
            "y": 14,
            "z": 6,
            "elements": [
                "thermalfoundation:glass@3"
            ]
        },
        {
            "x": -7,
            "y": 10,
            "z": 8,
            "elements": [
                "minecraft:lava@0"
            ]
        },
        {
            "x": -4,
            "y": 9,
            "z": 14,
            "elements": [
                "enderio:block_alloy_endergy@0"
            ]
        },
        {
            "x": -8,
            "y": 4,
            "z": 8,
            "elements": [
                "minecraft:lava@0"
            ]
        },
        {
            "x": -3,
            "y": 11,
            "z": 9,
            "elements": [
                "minecraft:lava@0"
            ]
        },
        {
            "x": -7,
            "y": 12,
            "z": 6,
            "elements": [
                "minecraft:lava@0"
            ]
        },
        {
            "x": -4,
            "y": 7,
            "z": 7,
            "elements": [
                "minecraft:lava@0"
            ]
        },
        {
            "x": -4,
            "y": 10,
            "z": 6,
            "elements": [
                "minecraft:lava@0"
            ]
        },
        {
            "x": -14,
            "y": 8,
            "z": 8,
            "elements": [
                "thermalfoundation:glass@3"
            ]
        },
        {
            "x": -6,
            "y": 11,
            "z": 12,
            "elements": [
                "minecraft:lava@0"
            ]
        },
        {
            "x": -10,
            "y": 6,
            "z": 6,
            "elements": [
                "minecraft:lava@0"
            ]
        },
        {
            "x": -11,
            "y": 8,
            "z": 8,
            "elements": [
                "minecraft:lava@0"
            ]
        },
        {
            "x": -10,
            "y": 3,
            "z": 7,
            "elements": [
                "minecraft:lava@0"
            ]
        },
        {
            "x": -4,
            "y": 6,
            "z": 8,
            "elements": [
                "minecraft:lava@0"
            ]
        },
        {
            "x": -12,
            "y": 9,
            "z": 2,
            "elements": [
                "enderio:block_alloy_endergy@0"
            ]
        },
        {
            "x": -14,
            "y": 10,
            "z": 8,
            "elements": [
                "thermalfoundation:glass@3"
            ]
        },
        {
            "x": -9,
            "y": 7,
            "z": 2,
            "elements": [
                "thermalfoundation:glass@3"
            ]
        },
        {
            "x": -14,
            "y": 9,
            "z": 4,
            "elements": [
                "enderio:block_alloy_endergy@0"
            ]
        },
        {
            "x": -3,
            "y": 3,
            "z": 2,
            "elements": [
                "minecraft:quartz_block@4"
            ]
        },
        {
            "x": -3,
            "y": 0,
            "z": -2,
            "elements": [
                "botania:bifrostperm@0"
            ]
        },
        {
            "x": -6,
            "y": 5,
            "z": 12,
            "elements": [
                "minecraft:lava@0"
            ]
        },
        {
            "x": -13,
            "y": 12,
            "z": 8,
            "elements": [
                "casings_all"
            ]
        },
        {
            "x": -7,
            "y": 14,
            "z": 6,
            "elements": [
                "thermalfoundation:glass@3"
            ]
        },
        {
            "x": -12,
            "y": 9,
            "z": 12,
            "elements": [
                "minecraft:lava@0"
            ]
        },
        {
            "x": -3,
            "y": 7,
            "z": 12,
            "elements": [
                "casings_all"
            ]
        },
        {
            "x": -10,
            "y": 9,
            "z": 7,
            "elements": [
                "minecraft:lava@0"
            ]
        },
        {
            "x": -9,
            "y": 11,
            "z": 12,
            "elements": [
                "minecraft:lava@0"
            ]
        },
        {
            "x": -9,
            "y": 9,
            "z": 2,
            "elements": [
                "thermalfoundation:glass@3"
            ]
        },
        {
            "x": -4,
            "y": 5,
            "z": 7,
            "elements": [
                "minecraft:lava@0"
            ]
        },
        {
            "x": -13,
            "y": 7,
            "z": 7,
            "elements": [
                "minecraft:lava@0"
            ]
        },
        {
            "x": -13,
            "y": 10,
            "z": 6,
            "elements": [
                "minecraft:lava@0"
            ]
        },
        {
            "x": -4,
            "y": 8,
            "z": 6,
            "elements": [
                "minecraft:lava@0"
            ]
        },
        {
            "x": -4,
            "y": 8,
            "z": 8,
            "elements": [
                "minecraft:lava@0"
            ]
        },
        {
            "x": -7,
            "y": 3,
            "z": 7,
            "elements": [
                "minecraft:lava@0"
            ]
        },
        {
            "x": -6,
            "y": 7,
            "z": 2,
            "elements": [
                "thermalfoundation:glass@3"
            ]
        },
        {
            "x": -13,
            "y": 10,
            "z": 8,
            "elements": [
                "minecraft:lava@0"
            ]
        },
        {
            "x": -9,
            "y": 5,
            "z": 2,
            "elements": [
                "thermalfoundation:glass@3"
            ]
        },
        {
            "x": -3,
            "y": 8,
            "z": 9,
            "elements": [
                "minecraft:lava@0"
            ]
        },
        {
            "x": -14,
            "y": 12,
            "z": 8,
            "elements": [
                "enderio:block_alloy_endergy@0"
            ]
        },
        {
            "x": -14,
            "y": 7,
            "z": 4,
            "elements": [
                "enderio:block_alloy_endergy@0"
            ]
        },
        {
            "x": 2,
            "y": -2,
            "z": -2,
            "elements": [
                "minecraft:quartz_block@0"
            ]
        },
        {
            "x": -6,
            "y": 7,
            "z": 12,
            "elements": [
                "minecraft:lava@0"
            ]
        },
        {
            "x": -9,
            "y": 9,
            "z": 12,
            "elements": [
                "minecraft:lava@0"
            ]
        },
        {
            "x": -11,
            "y": 6,
            "z": 8,
            "elements": [
                "minecraft:lava@0"
            ]
        },
        {
            "x": -13,
            "y": 9,
            "z": 7,
            "elements": [
                "minecraft:lava@0"
            ]
        },
        {
            "x": -2,
            "y": 4,
            "z": 8,
            "elements": [
                "enderio:block_alloy_endergy@0"
            ]
        },
        {
            "x": -4,
            "y": 3,
            "z": 7,
            "elements": [
                "casings_all"
            ]
        },
        {
            "x": -4,
            "y": 6,
            "z": 6,
            "elements": [
                "minecraft:lava@0"
            ]
        },
        {
            "x": -10,
            "y": 7,
            "z": 7,
            "elements": [
                "minecraft:lava@0"
            ]
        },
        {
            "x": -7,
            "y": 5,
            "z": 7,
            "elements": [
                "minecraft:lava@0"
            ]
        },
        {
            "x": -12,
            "y": 11,
            "z": 12,
            "elements": [
                "enderio:block_alloy@6"
            ]
        },
        {
            "x": -14,
            "y": 8,
            "z": 4,
            "elements": [
                "enderio:block_alloy_endergy@0"
            ]
        },
        {
            "x": -9,
            "y": 11,
            "z": 2,
            "elements": [
                "thermalfoundation:glass@3"
            ]
        },
        {
            "x": -5,
            "y": 8,
            "z": 8,
            "elements": [
                "minecraft:lava@0"
            ]
        },
        {
            "x": -13,
            "y": 5,
            "z": 7,
            "elements": [
                "minecraft:lava@0"
            ]
        },
        {
            "x": -1,
            "y": 3,
            "z": 2,
            "elements": [
                "minecraft:quartz_stairs@1"
            ]
        },
        {
            "x": -13,
            "y": 8,
            "z": 6,
            "elements": [
                "minecraft:lava@0"
            ]
        },
        {
            "x": -11,
            "y": 14,
            "z": 8,
            "elements": [
                "thermalfoundation:glass@3"
            ]
        },
        {
            "x": -7,
            "y": 9,
            "z": 14,
            "elements": [
                "thermalfoundation:glass@3"
            ]
        },
        {
            "x": -9,
            "y": 4,
            "z": 9,
            "elements": [
                "minecraft:lava@0"
            ]
        },
        {
            "x": -8,
            "y": 10,
            "z": 8,
            "elements": [
                "minecraft:lava@0"
            ]
        },
        {
            "x": -2,
            "y": 1,
            "z": 2,
            "elements": [
                "minecraft:quartz_stairs@4"
            ]
        },
        {
            "x": -11,
            "y": 12,
            "z": 8,
            "elements": [
                "minecraft:lava@0"
            ]
        },
        {
            "x": 1,
            "y": -2,
            "z": -2,
            "elements": [
                "minecraft:quartz_stairs@4"
            ]
        },
        {
            "x": 1,
            "y": 0,
            "z": 1,
            "elements": [
                "additions:aeonsteel_block@0"
            ]
        },
        {
            "x": -4,
            "y": 2,
            "z": 8,
            "elements": [
                "enderio:block_alloy_endergy@0"
            ]
        },
        {
            "x": -6,
            "y": 10,
            "z": 13,
            "elements": [
                "minecraft:lava@0"
            ]
        },
        {
            "x": -12,
            "y": 6,
            "z": 9,
            "elements": [
                "minecraft:lava@0"
            ]
        },
        {
            "x": -10,
            "y": 2,
            "z": 6,
            "elements": [
                "thermalfoundation:glass@3"
            ]
        },
        {
            "x": -7,
            "y": 9,
            "z": 2,
            "elements": [
                "thermalfoundation:glass@3"
            ]
        },
        {
            "x": -9,
            "y": 3,
            "z": 9,
            "elements": [
                "minecraft:lava@0"
            ]
        },
        {
            "x": -12,
            "y": 5,
            "z": 9,
            "elements": [
                "minecraft:lava@0"
            ]
        },
        {
            "x": -4,
            "y": 7,
            "z": 2,
            "elements": [
                "enderio:block_alloy_endergy@0"
            ]
        },
        {
            "x": -10,
            "y": 6,
            "z": 8,
            "elements": [
                "minecraft:lava@0"
            ]
        },
        {
            "x": -7,
            "y": 4,
            "z": 8,
            "elements": [
                "minecraft:lava@0"
            ]
        },
        {
            "x": -7,
            "y": 12,
            "z": 13,
            "elements": [
                "casings_all"
            ]
        },
        {
            "x": -12,
            "y": 7,
            "z": 9,
            "elements": [
                "minecraft:lava@0"
            ]
        },
        {
            "x": -11,
            "y": 10,
            "z": 8,
            "elements": [
                "minecraft:lava@0"
            ]
        },
        {
            "x": -2,
            "y": 11,
            "z": 7,
            "elements": [
                "thermalfoundation:glass@3"
            ]
        },
        {
            "x": -10,
            "y": 8,
            "z": 8,
            "elements": [
                "minecraft:lava@0"
            ]
        },
        {
            "x": -5,
            "y": 6,
            "z": 8,
            "elements": [
                "minecraft:lava@0"
            ]
        },
        {
            "x": -7,
            "y": 7,
            "z": 14,
            "elements": [
                "thermalfoundation:glass@3"
            ]
        },
        {
            "x": -8,
            "y": 12,
            "z": 8,
            "elements": [
                "minecraft:lava@0"
            ]
        },
        {
            "x": -2,
            "y": 3,
            "z": 2,
            "elements": [
                "casings_parallel"
            ]
        },
        {
            "x": -9,
            "y": 2,
            "z": 9,
            "elements": [
                "thermalfoundation:glass@3"
            ]
        },
        {
            "x": -13,
            "y": 6,
            "z": 6,
            "elements": [
                "minecraft:lava@0"
            ]
        },
        {
            "x": -10,
            "y": 4,
            "z": 6,
            "elements": [
                "minecraft:lava@0"
            ]
        },
        {
            "x": -1,
            "y": 1,
            "z": 2,
            "elements": [
                "minecraft:quartz_stairs@7"
            ]
        },
        {
            "x": -7,
            "y": 11,
            "z": 2,
            "elements": [
                "thermalfoundation:glass@3"
            ]
        },
        {
            "x": -7,
            "y": 2,
            "z": 8,
            "elements": [
                "thermalfoundation:glass@3"
            ]
        },
        {
            "x": -3,
            "y": 9,
            "z": 12,
            "elements": [
                "casings_all"
            ]
        },
        {
            "x": -5,
            "y": 7,
            "z": 2,
            "elements": [
                "thermalfoundation:glass@3"
            ]
        },
        {
            "x": -12,
            "y": 8,
            "z": 9,
            "elements": [
                "minecraft:lava@0"
            ]
        },
        {
            "x": -4,
            "y": 4,
            "z": 8,
            "elements": [
                "minecraft:lava@0"
            ]
        },
        {
            "x": -6,
            "y": 9,
            "z": 2,
            "elements": [
                "thermalfoundation:glass@3"
            ]
        },
        {
            "x": -4,
            "y": 13,
            "z": 7,
            "elements": [
                "casings_all"
            ]
        },
        {
            "x": -7,
            "y": 8,
            "z": 8,
            "elements": [
                "minecraft:lava@0"
            ]
        },
        {
            "x": -10,
            "y": 10,
            "z": 8,
            "elements": [
                "minecraft:lava@0"
            ]
        },
        {
            "x": -12,
            "y": 2,
            "z": 9,
            "elements": [
                "enderio:block_alloy_endergy@0"
            ]
        },
        {
            "x": -9,
            "y": 12,
            "z": 8,
            "elements": [
                "minecraft:lava@0"
            ]
        },
        {
            "x": -5,
            "y": 12,
            "z": 4,
            "elements": [
                "enderio:block_alloy@6"
            ]
        },
        {
            "x": -2,
            "y": -1,
            "z": 2,
            "elements": [
                "botania:bifrostperm@0"
            ]
        },
        {
            "x": -8,
            "y": 11,
            "z": 2,
            "elements": [
                "thermalfoundation:glass@3"
            ]
        },
        {
            "x": 3,
            "y": -2,
            "z": -2,
            "elements": [
                "minecraft:quartz_stairs@5"
            ]
        },
        {
            "x": 1,
            "y": 0,
            "z": -2,
            "elements": [
                "minecraft:quartz_stairs@0"
            ]
        },
        {
            "x": -6,
            "y": 2,
            "z": 8,
            "elements": [
                "thermalfoundation:glass@3"
            ]
        },
        {
            "x": -5,
            "y": 11,
            "z": 4,
            "elements": [
                "minecraft:lava@0"
            ]
        },
        {
            "x": -8,
            "y": 6,
            "z": 8,
            "elements": [
                "minecraft:lava@0"
            ]
        },
        {
            "x": -2,
            "y": 9,
            "z": 4,
            "elements": [
                "enderio:block_alloy_endergy@0"
            ]
        },
        {
            "x": -5,
            "y": 4,
            "z": 8,
            "elements": [
                "minecraft:lava@0"
            ]
        },
        {
            "x": -5,
            "y": 9,
            "z": 2,
            "elements": [
                "thermalfoundation:glass@3"
            ]
        },
        {
            "x": -7,
            "y": 11,
            "z": 14,
            "elements": [
                "thermalfoundation:glass@3"
            ]
        },
        {
            "x": -9,
            "y": 10,
            "z": 8,
            "elements": [
                "minecraft:lava@0"
            ]
        },
        {
            "x": -2,
            "y": 8,
            "z": 4,
            "elements": [
                "enderio:block_alloy_endergy@0"
            ]
        },
        {
            "x": -8,
            "y": 8,
            "z": 8,
            "elements": [
                "minecraft:lava@0"
            ]
        },
        {
            "x": -10,
            "y": 12,
            "z": 8,
            "elements": [
                "minecraft:lava@0"
            ]
        },
        {
            "x": -12,
            "y": 4,
            "z": 6,
            "elements": [
                "enderio:block_alloy@6"
            ]
        },
        {
            "x": -12,
            "y": 4,
            "z": 9,
            "elements": [
                "minecraft:lava@0"
            ]
        },
        {
            "x": -4,
            "y": 11,
            "z": 7,
            "elements": [
                "minecraft:lava@0"
            ]
        },
        {
            "x": -12,
            "y": 14,
            "z": 8,
            "elements": [
                "enderio:block_alloy_endergy@0"
            ]
        },
        {
            "x": -2,
            "y": 0,
            "z": -2,
            "elements": [
                "botania:bifrostperm@0"
            ]
        },
        {
            "x": -5,
            "y": 2,
            "z": 8,
            "elements": [
                "thermalfoundation:glass@3"
            ]
        },
        {
            "x": -2,
            "y": 7,
            "z": 4,
            "elements": [
                "enderio:block_alloy_endergy@0"
            ]
        },
        {
            "x": -4,
            "y": 8,
            "z": 13,
            "elements": [
                "casings_all"
            ]
        },
        {
            "x": -7,
            "y": 6,
            "z": 8,
            "elements": [
                "minecraft:lava@0"
            ]
        },
        {
            "x": -8,
            "y": 9,
            "z": 2,
            "elements": [
                "thermalfoundation:glass@3"
            ]
        },
        {
            "x": -12,
            "y": 3,
            "z": 9,
            "elements": [
                "casings_all"
            ]
        },
        {
            "x": -6,
            "y": 4,
            "z": 8,
            "elements": [
                "minecraft:lava@0"
            ]
        },
        {
            "x": -3,
            "y": 4,
            "z": 6,
            "elements": [
                "minecraft:iron_block@0"
            ]
        },
        {
            "x": -12,
            "y": 6,
            "z": 6,
            "elements": [
                "minecraft:lava@0"
            ]
        },
        {
            "x": 2,
            "y": -1,
            "z": -1,
            "elements": [
                "minecraft:quartz_block@0"
            ]
        },
        {
            "x": -11,
            "y": 9,
            "z": 14,
            "elements": [
                "thermalfoundation:glass@3"
            ]
        },
        {
            "x": -8,
            "y": 3,
            "z": 7,
            "elements": [
                "minecraft:lava@0"
            ]
        },
        {
            "x": -6,
            "y": 2,
            "z": 6,
            "elements": [
                "thermalfoundation:glass@3"
            ]
        },
        {
            "x": -5,
            "y": 11,
            "z": 7,
            "elements": [
                "minecraft:lava@0"
            ]
        },
        {
            "x": -7,
            "y": 6,
            "z": 13,
            "elements": [
                "minecraft:lava@0"
            ]
        },
        {
            "x": 0,
            "y": 2,
            "z": 1,
            "elements": [
                "minecraft:quartz_stairs@1"
            ]
        },
        {
            "x": -14,
            "y": 8,
            "z": 5,
            "elements": [
                "thermalfoundation:glass@3"
            ]
        },
        {
            "x": -8,
            "y": 5,
            "z": 2,
            "elements": [
                "thermalfoundation:glass@3"
            ]
        },
        {
            "x": -5,
            "y": 7,
            "z": 12,
            "elements": [
                "minecraft:lava@0"
            ]
        },
        {
            "x": -4,
            "y": 5,
            "z": 12,
            "elements": [
                "enderio:block_alloy@6"
            ]
        },
        {
            "x": -12,
            "y": 9,
            "z": 7,
            "elements": [
                "minecraft:lava@0"
            ]
        },
        {
            "x": -6,
            "y": 8,
            "z": 6,
            "elements": [
                "minecraft:lava@0"
            ]
        },
        {
            "x": -12,
            "y": 12,
            "z": 6,
            "elements": [
                "enderio:block_alloy@6"
            ]
        },
        {
            "x": -10,
            "y": 10,
            "z": 13,
            "elements": [
                "minecraft:lava@0"
            ]
        },
        {
            "x": -14,
            "y": 9,
            "z": 12,
            "elements": [
                "enderio:block_alloy_endergy@0"
            ]
        },
        {
            "x": -2,
            "y": 5,
            "z": 7,
            "elements": [
                "thermalfoundation:glass@3"
            ]
        },
        {
            "x": -11,
            "y": 7,
            "z": 7,
            "elements": [
                "minecraft:lava@0"
            ]
        },
        {
            "x": -7,
            "y": 11,
            "z": 12,
            "elements": [
                "minecraft:lava@0"
            ]
        },
        {
            "x": -14,
            "y": 7,
            "z": 5,
            "elements": [
                "thermalfoundation:glass@3"
            ]
        },
        {
            "x": -6,
            "y": 4,
            "z": 6,
            "elements": [
                "minecraft:lava@0"
            ]
        },
        {
            "x": -11,
            "y": 7,
            "z": 14,
            "elements": [
                "thermalfoundation:glass@3"
            ]
        },
        {
            "x": -8,
            "y": 5,
            "z": 14,
            "elements": [
                "thermalfoundation:glass@3"
            ]
        },
        {
            "x": -10,
            "y": 6,
            "z": 13,
            "elements": [
                "minecraft:lava@0"
            ]
        },
        {
            "x": -9,
            "y": 6,
            "z": 6,
            "elements": [
                "minecraft:lava@0"
            ]
        },
        {
            "x": -9,
            "y": 3,
            "z": 7,
            "elements": [
                "minecraft:lava@0"
            ]
        },
        {
            "x": -7,
            "y": 4,
            "z": 13,
            "elements": [
                "casings_all"
            ]
        },
        {
            "x": -12,
            "y": 9,
            "z": 14,
            "elements": [
                "enderio:block_alloy_endergy@0"
            ]
        },
        {
            "x": -12,
            "y": 8,
            "z": 6,
            "elements": [
                "minecraft:lava@0"
            ]
        },
        {
            "x": -8,
            "y": 7,
            "z": 2,
            "elements": [
                "thermalfoundation:glass@3"
            ]
        },
        {
            "x": -5,
            "y": 13,
            "z": 7,
            "elements": [
                "minecraft:lava@0"
            ]
        },
        {
            "x": -5,
            "y": 5,
            "z": 12,
            "elements": [
                "minecraft:lava@0"
            ]
        },
        {
            "x": 0,
            "y": 0,
            "z": 1,
            "elements": [
                "minecraft:quartz_stairs@7"
            ]
        },
        {
            "x": -1,
            "y": -1,
            "z": -1,
            "elements": [
                "minecraft:quartz_stairs@4"
            ]
        },
        {
            "x": -14,
            "y": 11,
            "z": 7,
            "elements": [
                "thermalfoundation:glass@3"
            ]
        },
        {
            "x": -4,
            "y": 7,
            "z": 12,
            "elements": [
                "minecraft:lava@0"
            ]
        },
        {
            "x": -11,
            "y": 9,
            "z": 7,
            "elements": [
                "minecraft:lava@0"
            ]
        },
        {
            "x": 0,
            "y": 2,
            "z": 6,
            "elements": [
                "botania:bifrostperm@0"
            ]
        },
        {
            "x": -14,
            "y": 9,
            "z": 5,
            "elements": [
                "thermalfoundation:glass@3"
            ]
        },
        {
            "x": -1,
            "y": 0,
            "z": 1,
            "elements": [
                "minecraft:quartz_stairs@7"
            ]
        },
        {
            "x": -11,
            "y": 5,
            "z": 5,
            "elements": [
                "minecraft:lava@0"
            ]
        },
        {
            "x": -9,
            "y": 8,
            "z": 6,
            "elements": [
                "minecraft:lava@0"
            ]
        },
        {
            "x": -9,
            "y": 5,
            "z": 14,
            "elements": [
                "thermalfoundation:glass@3"
            ]
        },
        {
            "x": -12,
            "y": 7,
            "z": 7,
            "elements": [
                "minecraft:lava@0"
            ]
        },
        {
            "x": -7,
            "y": 9,
            "z": 12,
            "elements": [
                "minecraft:lava@0"
            ]
        },
        {
            "x": -12,
            "y": 10,
            "z": 6,
            "elements": [
                "minecraft:lava@0"
            ]
        },
        {
            "x": -9,
            "y": 5,
            "z": 7,
            "elements": [
                "minecraft:lava@0"
            ]
        },
        {
            "x": 0,
            "y": -1,
            "z": -1,
            "elements": [
                "additions:aeonsteel_block@0"
            ]
        },
        {
            "x": -10,
            "y": 7,
            "z": 14,
            "elements": [
                "thermalfoundation:glass@3"
            ]
        },
        {
            "x": 0,
            "y": 1,
            "z": -1,
            "elements": [
                "minecraft:quartz_stairs@1"
            ]
        },
        {
            "x": -7,
            "y": 13,
            "z": 12,
            "elements": [
                "casings_all"
            ]
        },
        {
            "x": -8,
            "y": 13,
            "z": 7,
            "elements": [
                "minecraft:lava@0"
            ]
        },
        {
            "x": -1,
            "y": -2,
            "z": 1,
            "elements": [
                "botania:bifrostperm@0"
            ]
        },
        {
            "x": -2,
            "y": 9,
            "z": 7,
            "elements": [
                "thermalfoundation:glass@3"
            ]
        },
        {
            "x": -6,
            "y": 8,
            "z": 13,
            "elements": [
                "minecraft:lava@0"
            ]
        },
        {
            "x": -2,
            "y": 2,
            "z": 1,
            "elements": [
                "minecraft:quartz_block@4"
            ]
        },
        {
            "x": -11,
            "y": 7,
            "z": 12,
            "elements": [
                "minecraft:lava@0"
            ]
        },
        {
            "x": -11,
            "y": 6,
            "z": 5,
            "elements": [
                "minecraft:lava@0"
            ]
        },
        {
            "x": -11,
            "y": 11,
            "z": 7,
            "elements": [
                "minecraft:lava@0"
            ]
        },
        {
            "x": -9,
            "y": 4,
            "z": 6,
            "elements": [
                "minecraft:lava@0"
            ]
        },
        {
            "x": -6,
            "y": 12,
            "z": 6,
            "elements": [
                "minecraft:lava@0"
            ]
        },
        {
            "x": -5,
            "y": 7,
            "z": 7,
            "elements": [
                "minecraft:lava@0"
            ]
        },
        {
            "x": -5,
            "y": 10,
            "z": 6,
            "elements": [
                "minecraft:lava@0"
            ]
        },
        {
            "x": -10,
            "y": 2,
            "z": 8,
            "elements": [
                "thermalfoundation:glass@3"
            ]
        },
        {
            "x": -3,
            "y": 6,
            "z": 6,
            "elements": [
                "minecraft:lava@0"
            ]
        },
        {
            "x": -11,
            "y": 3,
            "z": 5,
            "elements": [
                "enderio:block_alloy_endergy@0"
            ]
        },
        {
            "x": -4,
            "y": 9,
            "z": 12,
            "elements": [
                "minecraft:lava@0"
            ]
        },
        {
            "x": -9,
            "y": 12,
            "z": 13,
            "elements": [
                "casings_all"
            ]
        },
        {
            "x": 1,
            "y": -1,
            "z": -1,
            "elements": [
                "chisel:quartz1@10"
            ]
        },
        {
            "x": -8,
            "y": 14,
            "z": 8,
            "elements": [
                "thermalfoundation:glass@3"
            ]
        },
        {
            "x": -1,
            "y": 2,
            "z": 1,
            "elements": [
                "casings_upgrade"
            ]
        },
        {
            "x": -8,
            "y": 14,
            "z": 6,
            "elements": [
                "thermalfoundation:glass@3"
            ]
        },
        {
            "x": -10,
            "y": 9,
            "z": 14,
            "elements": [
                "thermalfoundation:glass@3"
            ]
        },
        {
            "x": -8,
            "y": 3,
            "z": 12,
            "elements": [
                "casings_all"
            ]
        },
        {
            "x": -1,
            "y": 1,
            "z": -1,
            "elements": [
                "minecraft:quartz_stairs@2"
            ]
        },
        {
            "x": -11,
            "y": 13,
            "z": 7,
            "elements": [
                "minecraft:lava@0"
            ]
        },
        {
            "x": -7,
            "y": 8,
            "z": 13,
