{
    "registryname": "aspect_crafter",
    "localizedname": "§bLV5 - 要素合成机",
    "requires-blueprint": false,
    "failure-action": "still",
    "color": "E8CD62",
    "parts": [
        {
            "x": 0,
            "y": 0,
            "z": 0,
            "elements": [
                "modularmachinery:blockcontroller@2"
            ]
        },
        {
            "x": 0,
            "y": 5,
            "z": 2,
            "elements": [
                "mekanism:slickplasticblock@14"
            ]
        },
        {
            "x": -4,
            "y": -2,
            "z": 2,
            "elements": [
                "mekanism:slickplasticblock@14"
            ]
        },
        {
            "x": -1,
            "y": 2,
            "z": 0,
            "elements": [
                "tcomplement:scorched_block@5"
            ]
        },
        {
            "x": 0,
            "y": -2,
            "z": 0,
            "elements": [
                "tcomplement:scorched_block@5"
            ]
        },
        {
            "x": 7,
            "y": 4,
            "z": 2,
            "elements": [
                "casings_all"
            ]
        },
        {
            "x": 5,
            "y": 1,
            "z": 1,
            "elements": [
                "mekanism:slickplasticblock@14"
            ]
        },
        {
            "x": -2,
            "y": 4,
            "z": 0,
            "elements": [
                "tconstruct:metal@5"
            ]
        },
        {
            "x": 1,
            "y": -4,
            "z": 0,
            "elements": [
                "tcomplement:scorched_block@5"
            ]
        },
        {
            "x": 7,
            "y": 5,
            "z": 1,
            "elements": [
                "tconstruct:metal@5"
            ]
        },
        {
            "x": 5,
            "y": 0,
            "z": 1,
            "elements": [
                "mekanism:slickplasticblock@14"
            ]
        },
        {
            "x": -5,
            "y": -1,
            "z": 3,
            "elements": [
                "tconstruct:metal@5"
            ]
        },
        {
            "x": 0,
            "y": -1,
            "z": 0,
            "elements": [
                "tconstruct:metal@5"
            ]
        },
        {
            "x": 6,
            "y": 5,
            "z": 3,
            "elements": [
                "tconstruct:metal@5"
            ]
        },
        {
            "x": -4,
            "y": 0,
            "z": 3,
            "elements": [
                "tcomplement:scorched_block@5"
            ]
        },
        {
            "x": -2,
            "y": 3,
            "z": 0,
            "elements": [
                "tcomplement:scorched_block@5"
            ]
        },
        {
            "x": 1,
            "y": -5,
            "z": 3,
            "elements": [
                "tconstruct:metal@5"
            ]
        },
        {
            "x": -5,
            "y": -3,
            "z": 2,
            "elements": [
                "mekanism:slickplasticblock@14"
            ]
        },
        {
            "x": 1,
            "y": -4,
            "z": 3,
            "elements": [
                "tcomplement:scorched_block@5"
            ]
        },
        {
            "x": 7,
            "y": 5,
            "z": 2,
            "elements": [
                "tconstruct:metal@5"
            ]
        },
        {
            "x": 1,
            "y": 0,
            "z": 0,
            "elements": [
                "tconstruct:metal@5"
            ]
        },
        {
            "x": -3,
            "y": -5,
            "z": 1,
            "elements": [
                "mekanism:slickplasticblock@14"
            ]
        },
        {
            "x": 5,
            "y": -1,
            "z": 1,
            "elements": [
                "mekanism:slickplasticblock@14"
            ]
        },
        {
            "x": -2,
            "y": -5,
            "z": 2,
            "elements": [
                "mekanism:slickplasticblock@14"
            ]
        },
        {
            "x": 7,
            "y": 4,
            "z": 1,
            "elements": [
                "casings_all"
            ]
        },
        {
            "x": 5,
            "y": 3,
            "z": 1,
            "elements": [
                "mekanism:slickplasticblock@14"
            ]
        },
        {
            "x": 1,
            "y": -2,
            "z": 0,
            "elements": [
                "tcomplement:scorched_block@5"
            ]
        },
        {
            "x": -4,
            "y": 1,
            "z": 3,
            "elements": [
                "tcomplement:scorched_block@5"
            ]
        },
        {
            "x": -2,
            "y": -4,
            "z": 3,
            "elements": [
                "tcomplement:scorched_block@5"
            ]
        },
        {
            "x": 6,
            "y": 4,
            "z": 3,
            "elements": [
                "thaumcraft:metal_void@0"
            ]
        },
        {
            "x": 3,
            "y": 1,
            "z": 2,
            "elements": [
                "gct_ores:rainboquartz_block@0"
            ]
        },
        {
            "x": -6,
            "y": -3,
            "z": 1,
            "elements": [
                "mekanism:slickplasticblock@14"
            ]
        },
        {
            "x": -1,
            "y": 4,
            "z": 0,
            "elements": [
                "tcomplement:scorched_block@5"
            ]
        },
        {
            "x": 0,
            "y": -4,
            "z": 0,
            "elements": [
                "tcomplement:scorched_block@5"
            ]
        },
        {
            "x": 2,
            "y": 5,
            "z": 1,
            "elements": [
                "mekanism:slickplasticblock@14"
            ]
        },
        {
            "x": -2,
            "y": -5,
            "z": 3,
            "elements": [
                "tconstruct:metal@5"
            ]
        },
        {
            "x": -2,
            "y": 1,
            "z": 0,
            "elements": [
                "tcomplement:scorched_block@5"
            ]
        },
        {
            "x": -4,
            "y": 2,
            "z": 3,
            "elements": [
                "tconstruct:metal@5"
            ]
        },
        {
            "x": -5,
            "y": -1,
            "z": 2,
            "elements": [
                "mekanism:slickplasticblock@14"
            ]
        },
        {
            "x": 6,
            "y": 3,
            "z": 3,
            "elements": [
                "tconstruct:metal@5"
            ]
        },
        {
            "x": 1,
            "y": -2,
            "z": 3,
            "elements": [
                "tcomplement:scorched_block@5"
            ]
        },
        {
            "x": 3,
            "y": 0,
            "z": 2,
            "elements": [
                "gct_ores:rainboquartz_block@0"
            ]
        },
        {
            "x": -5,
            "y": -4,
            "z": 3,
            "elements": [
                "thaumcraft:metal_void@0"
            ]
        },
        {
            "x": 2,
            "y": 0,
            "z": 0,
            "elements": [
                "tcomplement:scorched_block@5"
            ]
        },
        {
            "x": 2,
            "y": -2,
            "z": 2,
            "elements": [
                "gct_ores:rainboquartz_block@0"
            ]
        },
        {
            "x": 6,
            "y": 3,
            "z": 1,
            "elements": [
                "mekanism:slickplasticblock@14"
            ]
        },
        {
            "x": 1,
            "y": 2,
            "z": 0,
            "elements": [
                "tcomplement:scorched_block@5"
            ]
        },
        {
            "x": 3,
            "y": -4,
            "z": 0,
            "elements": [
                "tconstruct:metal@5"
            ]
        },
        {
            "x": -1,
            "y": 4,
            "z": 3,
            "elements": [
                "tcomplement:scorched_block@5"
            ]
        },
        {
            "x": 4,
            "y": -3,
            "z": 3,
            "elements": [
                "tconstruct:metal@5"
            ]
        },
        {
            "x": -6,
            "y": -5,
            "z": 1,
            "elements": [
                "mekanism:slickplasticblock@14"
            ]
        },
        {
            "x": -7,
            "y": -3,
            "z": 1,
            "elements": [
                "tconstruct:metal@5"
            ]
        },
        {
            "x": 0,
            "y": 1,
            "z": 2,
            "elements": [
                "gct_ores:rainboquartz_block@0"
            ]
        },
        {
            "x": 5,
            "y": 5,
            "z": 1,
            "elements": [
                "mekanism:slickplasticblock@14"
            ]
        },
        {
            "x": -7,
            "y": -4,
            "z": 1,
            "elements": [
                "casings_all"
            ]
        },
        {
            "x": 4,
            "y": -2,
            "z": 3,
            "elements": [
                "tconstruct:metal@5"
            ]
        },
        {
            "x": -4,
            "y": 3,
            "z": 0,
            "elements": [
                "tconstruct:metal@5"
            ]
        },
        {
            "x": -2,
            "y": -1,
            "z": 0,
            "elements": [
                "tcomplement:scorched_block@5"
            ]
        },
        {
            "x": 3,
            "y": -3,
            "z": 0,
            "elements": [
                "tcomplement:scorched_block@5"
            ]
        },
        {
            "x": 2,
            "y": 0,
            "z": 3,
            "elements": [
                "tcomplement:scorched_block@5"
            ]
        },
        {
            "x": 0,
            "y": 5,
            "z": 3,
            "elements": [
                "tconstruct:metal@5"
            ]
        },
        {
            "x": 2,
            "y": 1,
            "z": 3,
            "elements": [
                "tcomplement:scorched_block@5"
            ]
        },
        {
            "x": -5,
            "y": -5,
            "z": 3,
            "elements": [
                "tconstruct:metal@5"
            ]
        },
        {
            "x": -3,
            "y": 0,
            "z": 2,
            "elements": [
                "gct_ores:rainboquartz_block@0"
            ]
        },
        {
            "x": -1,
            "y": 0,
            "z": 0,
            "elements": [
                "tconstruct:metal@5"
            ]
        },
        {
            "x": -4,
            "y": 2,
            "z": 0,
            "elements": [
                "tconstruct:metal@5"
            ]
        },
        {
            "x": 3,
            "y": -2,
            "z": 0,
            "elements": [
                "tcomplement:scorched_block@5"
            ]
        },
        {
            "x": 7,
            "y": 3,
            "z": 1,
            "elements": [
                "tconstruct:metal@5"
            ]
        },
        {
            "x": 0,
            "y": 3,
            "z": 2,
            "elements": [
                "gct_ores:rainboquartz_block@0"
            ]
        },
        {
            "x": 2,
            "y": -1,
            "z": 3,
            "elements": [
                "tcomplement:scorched_block@5"
            ]
        },
        {
            "x": 2,
            "y": -4,
            "z": 2,
            "elements": [
                "mekanism:slickplasticblock@14"
            ]
        },
        {
            "x": 5,
            "y": -1,
            "z": 2,
            "elements": [
                "mekanism:slickplasticblock@14"
            ]
        },
        {
            "x": 0,
            "y": 4,
            "z": 3,
            "elements": [
                "tcomplement:scorched_block@5"
            ]
        },
        {
            "x": -3,
            "y": 1,
            "z": 2,
            "elements": [
                "gct_ores:rainboquartz_block@0"
            ]
        },
        {
            "x": -5,
            "y": -5,
            "z": 1,
            "elements": [
                "mekanism:slickplasticblock@14"
            ]
        },
        {
            "x": 1,
            "y": 4,
            "z": 0,
            "elements": [
                "tcomplement:scorched_block@5"
            ]
        },
        {
            "x": -2,
            "y": -4,
            "z": 0,
            "elements": [
                "tcomplement:scorched_block@5"
            ]
        },
        {
            "x": 4,
            "y": 5,
            "z": 1,
            "elements": [
                "mekanism:slickplasticblock@14"
            ]
        },
        {
            "x": -5,
            "y": -3,
            "z": 3,
            "elements": [
                "tconstruct:metal@5"
            ]
        },
        {
            "x": -1,
            "y": 5,
            "z": 3,
            "elements": [
                "tconstruct:metal@5"
            ]
        },
        {
            "x": 1,
            "y": -5,
            "z": 0,
            "elements": [
                "tconstruct:metal@5"
            ]
        },
        {
            "x": 4,
            "y": -2,
            "z": 0,
            "elements": [
                "tconstruct:metal@5"
            ]
        },
        {
            "x": 4,
            "y": 0,
            "z": 0,
            "elements": [
                "tcomplement:scorched_block@5"
            ]
        },
        {
            "x": 5,
            "y": 4,
            "z": 3,
            "elements": [
                "thaumcraft:metal_void@0"
            ]
        },
        {
            "x": -1,
            "y": 3,
            "z": 2,
            "elements": [
                "gct_ores:rainboquartz_block@0"
            ]
        },
        {
            "x": 2,
            "y": 4,
            "z": 0,
            "elements": [
                "tcomplement:scorched_block@5"
            ]
        },
        {
            "x": -3,
            "y": -4,
            "z": 0,
            "elements": [
                "tcomplement:scorched_block@5"
            ]
        },
        {
            "x": -4,
            "y": -5,
            "z": 1,
            "elements": [
                "mekanism:slickplasticblock@14"
            ]
        },
        {
            "x": -4,
            "y": 1,
            "z": 0,
            "elements": [
                "tcomplement:scorched_block@5"
            ]
        },
        {
            "x": 1,
            "y": 0,
            "z": 1,
            "elements": [
                "gct_ores:rainboquartz_block@0"
            ]
        },
        {
            "x": 0,
            "y": -1,
            "z": 2,
            "elements": [
                "gct_ores:rainboquartz_block@0"
            ]
        },
        {
            "x": -1,
            "y": -3,
            "z": 2,
            "elements": [
                "gct_ores:rainboquartz_block@0"
            ]
        },
        {
            "x": 2,
            "y": 5,
            "z": 3,
            "elements": [
                "tconstruct:metal@5"
            ]
        },
        {
            "x": -6,
            "y": -3,
            "z": 3,
            "elements": [
                "tconstruct:metal@5"
            ]
        },
        {
            "x": 4,
            "y": 2,
            "z": 1,
            "elements": [
                "mekanism:slickplasticblock@14"
            ]
        },
        {
            "x": -3,
            "y": -3,
            "z": 0,
            "elements": [
                "tcomplement:scorched_block@5"
            ]
        },
        {
            "x": 1,
            "y": 1,
            "z": 1,
            "elements": [
                "gct_ores:rainboquartz_block@0"
            ]
        },
        {
            "x": 5,
            "y": 3,
            "z": 3,
            "elements": [
                "tconstruct:metal@5"
            ]
        },
        {
            "x": -6,
            "y": -4,
            "z": 3,
            "elements": [
                "thaumcraft:metal_void@0"
            ]
        },
        {
            "x": 5,
            "y": 0,
            "z": 0,
            "elements": [
                "tconstruct:metal@5"
            ]
        },
        {
            "x": 4,
            "y": -1,
            "z": 3,
            "elements": [
                "tcomplement:scorched_block@5"
            ]
        },
        {
            "x": -3,
            "y": -2,
            "z": 0,
            "elements": [
                "tcomplement:scorched_block@5"
            ]
        },
        {
            "x": 1,
            "y": 3,
            "z": 1,
            "elements": [
                "gct_ores:rainboquartz_block@0"
            ]
        },
        {
            "x": 5,
            "y": 5,
            "z": 3,
            "elements": [
                "tconstruct:metal@5"
            ]
        },
        {
            "x": 2,
            "y": 4,
            "z": 3,
            "elements": [
                "tcomplement:scorched_block@5"
            ]
        },
        {
            "x": 3,
            "y": 2,
            "z": 3,
            "elements": [
                "tcomplement:scorched_block@5"
            ]
        },
        {
            "x": -5,
            "y": 1,
            "z": 0,
            "elements": [
                "tconstruct:metal@5"
            ]
        },
        {
            "x": -7,
            "y": -5,
            "z": 1,
            "elements": [
                "tconstruct:metal@5"
            ]
        },
        {
            "x": 4,
            "y": -1,
            "z": 0,
            "elements": [
                "tcomplement:scorched_block@5"
            ]
        },
        {
            "x": 5,
            "y": 0,
            "z": 3,
            "elements": [
                "tconstruct:metal@5"
            ]
        },
        {
            "x": -1,
            "y": 1,
            "z": 2,
            "elements": [
                "gct_ores:rainboquartz_block@0"
            ]
        },
        {
            "x": -3,
            "y": 4,
            "z": 2,
            "elements": [
                "mekanism:slickplasticblock@14"
            ]
        },
        {
            "x": 2,
            "y": 1,
            "z": 0,
            "elements": [
                "tcomplement:scorched_block@5"
            ]
        },
        {
            "x": -1,
            "y": -1,
            "z": 2,
            "elements": [
                "gct_ores:rainboquartz_block@0"
            ]
        },
        {
            "x": 4,
            "y": -3,
            "z": 0,
            "elements": [
                "tconstruct:metal@5"
            ]
        },
        {
            "x": -2,
            "y": 4,
            "z": 1,
            "elements": [
                "mekanism:slickplasticblock@14"
            ]
        },
        {
            "x": 0,
            "y": -3,
            "z": 2,
            "elements": [
                "gct_ores:rainboquartz_block@0"
            ]
        },
        {
            "x": -2,
            "y": 2,
            "z": 2,
            "elements": [
                "gct_ores:rainboquartz_block@0"
            ]
        },
        {
            "x": -6,
            "y": -5,
            "z": 3,
            "elements": [
                "tconstruct:metal@5"
            ]
        },
        {
            "x": 1,
            "y": -5,
            "z": 2,
            "elements": [
                "mekanism:slickplasticblock@14"
            ]
        },
        {
            "x": -1,
            "y": 0,
            "z": 2,
            "elements": [
                "gct_ores:rainboquartz_block@0"
            ]
        },
        {
            "x": -2,
            "y": 0,
            "z": 0,
            "elements": [
                "tcomplement:scorched_block@5"
            ]
        },
        {
            "x": 5,
            "y": -1,
            "z": 3,
            "elements": [
                "tconstruct:metal@5"
            ]
        },
        {
            "x": 1,
            "y": 5,
            "z": 1,
            "elements": [
                "mekanism:slickplasticblock@14"
            ]
        },
        {
            "x": -5,
            "y": 0,
            "z": 1,
            "elements": [
                "mekanism:slickplasticblock@14"
            ]
        },
        {
            "x": -2,
            "y": -2,
            "z": 2,
            "elements": [
                "gct_ores:rainboquartz_block@0"
            ]
        },
        {
            "x": 1,
            "y": 3,
            "z": 2,
            "elements": [
                "gct_ores:rainboquartz_block@0"
            ]
        },
        {
            "x": 3,
            "y": 4,
            "z": 3,
            "elements": [
                "tcomplement:scorched_block@5"
            ]
        },
        {
            "x": -2,
            "y": 4,
            "z": 2,
            "elements": [
                "mekanism:slickplasticblock@14"
            ]
        },
        {
            "x": -5,
            "y": 1,
            "z": 1,
            "elements": [
                "mekanism:slickplasticblock@14"
            ]
        },
        {
            "x": 4,
            "y": 5,
            "z": 3,
            "elements": [
                "tconstruct:metal@5"
            ]
        },
        {
            "x": 3,
            "y": 3,
            "z": 3,
            "elements": [
                "tcomplement:scorched_block@5"
            ]
        },
        {
            "x": 1,
            "y": -3,
            "z": 2,
            "elements": [
                "gct_ores:rainboquartz_block@0"
            ]
        },
        {
            "x": 5,
            "y": 1,
            "z": 0,
            "elements": [
                "tconstruct:metal@5"
            ]
        },
        {
            "x": -4,
            "y": -2,
            "z": 1,
            "elements": [
                "mekanism:slickplasticblock@14"
            ]
        },
        {
            "x": -1,
            "y": 5,
            "z": 0,
            "elements": [
                "tconstruct:metal@5"
            ]
        },
        {
            "x": -5,
            "y": 0,
            "z": 0,
            "elements": [
                "tconstruct:metal@5"
            ]
        },
        {
            "x": 0,
            "y": -5,
            "z": 0,
            "elements": [
                "tconstruct:metal@5"
            ]
        },
        {
            "x": 3,
            "y": -1,
            "z": 1,
            "elements": [
                "gct_ores:rainboquartz_block@0"
            ]
        },
        {
            "x": 2,
            "y": 5,
            "z": 0,
            "elements": [
                "tconstruct:metal@5"
            ]
        },
        {
            "x": -3,
            "y": -5,
            "z": 0,
            "elements": [
                "tconstruct:metal@5"
            ]
        },
        {
            "x": -1,
            "y": -5,
            "z": 1,
            "elements": [
                "mekanism:slickplasticblock@14"
            ]
        },
        {
            "x": 4,
            "y": 4,
            "z": 3,
            "elements": [
                "thaumcraft:metal_void@0"
            ]
        },
        {
            "x": 3,
            "y": -4,
            "z": 1,
            "elements": [
                "mekanism:slickplasticblock@14"
            ]
        },
        {
            "x": -4,
            "y": 3,
            "z": 2,
            "elements": [
                "mekanism:slickplasticblock@14"
            ]
        },
        {
            "x": 1,
            "y": 1,
            "z": 2,
            "elements": [
                "gct_ores:rainboquartz_block@0"
            ]
        },
        {
            "x": 1,
            "y": -1,
            "z": 2,
            "elements": [
                "gct_ores:rainboquartz_block@0"
            ]
        },
        {
            "x": 5,
            "y": 4,
            "z": 0,
            "elements": [
                "thaumcraft:metal_void@0"
            ]
        },
        {
            "x": -6,
            "y": -4,
            "z": 0,
            "elements": [
                "thaumcraft:metal_void@0"
            ]
        },
        {
            "x": 3,
            "y": 5,
            "z": 3,
            "elements": [
                "tconstruct:metal@5"
            ]
        },
        {
            "x": 4,
            "y": 3,
            "z": 3,
            "elements": [
                "tconstruct:metal@5"
            ]
        },
        {
            "x": 5,
            "y": 1,
            "z": 3,
            "elements": [
                "tconstruct:metal@5"
            ]
        },
        {
            "x": -7,
            "y": -4,
            "z": 3,
            "elements": [
                "tconstruct:metal@5"
            ]
        },
        {
            "x": -4,
            "y": 2,
            "z": 2,
            "elements": [
                "mekanism:slickplasticblock@14"
            ]
        },
        {
            "x": 5,
            "y": 3,
            "z": 0,
            "elements": [
                "tconstruct:metal@5"
            ]
        },
        {
            "x": -2,
            "y": -3,
            "z": 2,
            "elements": [
                "gct_ores:rainboquartz_block@0"
            ]
        },
        {
            "x": -6,
            "y": -3,
            "z": 0,
            "elements": [
                "tconstruct:metal@5"
            ]
        },
        {
            "x": -1,
            "y": -5,
            "z": 2,
            "elements": [
                "mekanism:slickplasticblock@14"
            ]
        },
        {
            "x": 1,
            "y": 0,
            "z": 2,
            "elements": [
                "gct_ores:rainboquartz_block@0"
            ]
        },
        {
            "x": -3,
            "y": 0,
            "z": 1,
            "elements": [
                "gct_ores:rainboquartz_block@0"
            ]
        },
        {
            "x": -1,
            "y": 5,
            "z": 1,
            "elements": [
                "mekanism:slickplasticblock@14"
            ]
        },
        {
            "x": -6,
            "y": -5,
            "z": 0,
            "elements": [
                "tconstruct:metal@5"
            ]
        },
        {
            "x": 5,
            "y": 5,
            "z": 0,
            "elements": [
                "tconstruct:metal@5"
            ]
        },
        {
            "x": 0,
            "y": -5,
            "z": 1,
            "elements": [
                "mekanism:slickplasticblock@14"
            ]
        },
        {
            "x": 0,
            "y": 3,
            "z": 1,
            "elements": [
                "gct_ores:rainboquartz_block@0"
            ]
        },
        {
            "x": 3,
            "y": -4,
            "z": 2,
            "elements": [
                "mekanism:slickplasticblock@14"
            ]
        },
        {
            "x": 2,
            "y": -4,
            "z": 1,
            "elements": [
                "mekanism:slickplasticblock@14"
            ]
        },
        {
            "x": 1,
            "y": 4,
            "z": 3,
            "elements": [
                "tcomplement:scorched_block@5"
            ]
        },
        {
            "x": 4,
            "y": 2,
            "z": 3,
            "elements": [
                "tconstruct:metal@5"
            ]
        },
        {
            "x": 6,
            "y": 4,
            "z": 0,
            "elements": [
                "thaumcraft:metal_void@0"
            ]
        },
        {
            "x": -7,
            "y": -4,
            "z": 0,
            "elements": [
                "tconstruct:metal@5"
            ]
        },
        {
            "x": 4,
            "y": 0,
            "z": 3,
            "elements": [
                "tcomplement:scorched_block@5"
            ]
        },
        {
            "x": -3,
            "y": -1,
            "z": 1,
            "elements": [
                "gct_ores:rainboquartz_block@0"
            ]
        },
        {
            "x": 4,
            "y": 1,
            "z": 3,
            "elements": [
                "tcomplement:scorched_block@5"
            ]
        },
        {
            "x": 6,
            "y": 3,
            "z": 0,
            "elements": [
                "tconstruct:metal@5"
            ]
        },
        {
            "x": 4,
            "y": -2,
            "z": 2,
            "elements": [
                "mekanism:slickplasticblock@14"
            ]
        },
        {
            "x": -7,
            "y": -3,
            "z": 0,
            "elements": [
                "tconstruct:metal@5"
            ]
        },
        {
            "x": -3,
            "y": 1,
            "z": 1,
            "elements": [
                "gct_ores:rainboquartz_block@0"
            ]
        },
        {
            "x": -7,
            "y": -5,
            "z": 3,
            "elements": [
                "tconstruct:metal@5"
            ]
        },
        {
            "x": -5,
            "y": 0,
            "z": 2,
            "elements": [
                "mekanism:slickplasticblock@14"
            ]
        },
        {
            "x": 4,
            "y": 5,
            "z": 0,
            "elements": [
                "tconstruct:metal@5"
            ]
        },
        {
            "x": 2,
            "y": -2,
            "z": 1,
            "elements": [
                "gct_ores:rainboquartz_block@0"
            ]
        },
        {
            "x": -5,
            "y": -5,
            "z": 0,
            "elements": [
                "tconstruct:metal@5"
            ]
        },
        {
            "x": 2,
            "y": 3,
            "z": 2,
            "elements": [
                "gct_ores:rainboquartz_block@0"
            ]
        },
        {
            "x": 0,
            "y": -1,
            "z": 3,
            "elements": [
                "tconstruct:metal@5"
            ]
        },
        {
            "x": 3,
            "y": -1,
            "z": 2,
            "elements": [
                "gct_ores:rainboquartz_block@0"
            ]
        },
        {
            "x": -2,
            "y": 4,
            "z": 3,
            "elements": [
                "tconstruct:metal@5"
            ]
        },
        {
            "x": -7,
            "y": -3,
            "z": 3,
            "elements": [
                "tconstruct:metal@5"
            ]
        },
        {
            "x": 4,
            "y": -3,
            "z": 2,
            "elements": [
                "mekanism:slickplasticblock@14"
            ]
        },
        {
            "x": -5,
            "y": 1,
            "z": 2,
            "elements": [
                "mekanism:slickplasticblock@14"
            ]
        },
        {
            "x": 7,
            "y": 4,
            "z": 0,
            "elements": [
                "tconstruct:metal@5"
            ]
        },
        {
            "x": 1,
            "y": 5,
            "z": 3,
            "elements": [
                "tconstruct:metal@5"
            ]
        },
        {
            "x": 2,
            "y": 2,
            "z": 2,
            "elements": [
                "gct_ores:rainboquartz_block@0"
            ]
        },
        {
            "x": 1,
            "y": 0,
            "z": 3,
            "elements": [
                "tconstruct:metal@5"
            ]
        },
        {
            "x": -2,
            "y": 3,
            "z": 3,
            "elements": [
                "tcomplement:scorched_block@5"
            ]
        },
        {
            "x": 3,
            "y": 5,
            "z": 0,
            "elements": [
                "tconstruct:metal@5"
            ]
        },
        {
            "x": 0,
            "y": 1,
            "z": 1,
            "elements": [
                "gct_ores:rainboquartz_block@0"
            ]
        },
        {
            "x": 7,
            "y": 3,
            "z": 0,
            "elements": [
                "tconstruct:metal@5"
            ]
        },
        {
            "x": -3,
            "y": -5,
            "z": 2,
            "elements": [
                "mekanism:slickplasticblock@14"
            ]
        },
        {
            "x": -4,
            "y": -5,
            "z": 0,
            "elements": [
                "tconstruct:metal@5"
            ]
        },
        {
            "x": -1,
            "y": 0,
            "z": 1,
            "elements": [
                "gct_ores:rainboquartz_block@0"
            ]
        },
        {
            "x": 5,
            "y": 3,
            "z": 2,
            "elements": [
                "mekanism:slickplasticblock@14"
            ]
        },
        {
            "x": 7,
            "y": 4,
            "z": 3,
            "elements": [
                "tconstruct:metal@5"
            ]
        },
        {
            "x": -2,
            "y": 2,
            "z": 1,
            "elements": [
                "gct_ores:rainboquartz_block@0"
            ]
        },
        {
            "x": -5,
            "y": 1,
            "z": 3,
            "elements": [
                "tconstruct:metal@5"
            ]
        },
        {
            "x": 4,
            "y": 4,
            "z": 0,
            "elements": [
                "thaumcraft:metal_void@0"
            ]
        },
        {
            "x": -5,
            "y": -4,
            "z": 0,
            "elements": [
                "thaumcraft:metal_void@0"
            ]
        },
        {
            "x": 7,
            "y": 3,
            "z": 3,
            "elements": [
                "tconstruct:metal@5"
            ]
        },
        {
            "x": -1,
            "y": -1,
            "z": 1,
            "elements": [
                "gct_ores:rainboquartz_block@0"
            ]
        },
        {
            "x": -4,
            "y": -3,
            "z": 3,
            "elements": [
                "tconstruct:metal@5"
            ]
        },
        {
            "x": -3,
            "y": 4,
            "z": 1,
            "elements": [
                "mekanism:slickplasticblock@14"
            ]
        },
        {
            "x": -4,
            "y": -2,
            "z": 3,
            "elements": [
                "tconstruct:metal@5"
            ]
        },
        {
            "x": 0,
            "y": -3,
            "z": 1,
            "elements": [
                "gct_ores:rainboquartz_block@0"
            ]
        },
        {
            "x": 3,
            "y": -4,
            "z": 3,
            "elements": [
                "tconstruct:metal@5"
            ]
        },
        {
            "x": 4,
            "y": 3,
            "z": 0,
            "elements": [
                "tconstruct:metal@5"
            ]
        },
        {
            "x": -5,
            "y": -3,
            "z": 0,
            "elements": [
                "tconstruct:metal@5"
            ]
        },
        {
            "x": -1,
            "y": 1,
            "z": 1,
            "elements": [
                "gct_ores:rainboquartz_block@0"
            ]
        },
        {
            "x": 0,
            "y": -5,
            "z": 2,
            "elements": [
                "mekanism:slickplasticblock@14"
            ]
        },
        {
            "x": 5,
            "y": 5,
            "z": 2,
            "elements": [
                "mekanism:slickplasticblock@14"
            ]
        },
        {
            "x": -4,
            "y": -4,
            "z": 3,
            "elements": [
                "thaumcraft:metal_void@0"
            ]
        },
        {
            "x": -1,
            "y": 5,
            "z": 2,
            "elements": [
                "mekanism:slickplasticblock@14"
            ]
        },
        {
            "x": 5,
            "y": 1,
            "z": 2,
            "elements": [
                "mekanism:slickplasticblock@14"
            ]
        },
        {
            "x": 6,
            "y": 5,
            "z": 0,
            "elements": [
                "tconstruct:metal@5"
            ]
        },
        {
            "x": -7,
            "y": -5,
            "z": 0,
            "elements": [
                "tconstruct:metal@5"
            ]
        },
        {
            "x": -1,
            "y": 3,
            "z": 1,
            "elements": [
                "gct_ores:rainboquartz_block@0"
            ]
        },
        {
            "x": 4,
            "y": 2,
            "z": 0,
            "elements": [
                "tconstruct:metal@5"
            ]
        },
        {
            "x": 7,
            "y": 5,
            "z": 3,
            "elements": [
                "tconstruct:metal@5"
            ]
        },
        {
            "x": 1,
            "y": 2,
            "z": 3,
            "elements": [
                "tcomplement:scorched_block@5"
            ]
        },
        {
            "x": 3,
            "y": -3,
            "z": 3,
            "elements": [
                "tcomplement:scorched_block@5"
            ]
        },
        {
            "x": 0,
            "y": -1,
            "z": 1,
            "elements": [
                "gct_ores:rainboquartz_block@0"
            ]
        },
        {
            "x": -3,
            "y": -1,
            "z": 2,
            "elements": [
                "gct_ores:rainboquartz_block@0"
            ]
        },
        {
            "x": -4,
            "y": -5,
            "z": 3,
            "elements": [
                "tconstruct:metal@5"
            ]
        },
        {
            "x": 4,
            "y": 1,
            "z": 0,
            "elements": [
                "tcomplement:scorched_block@5"
            ]
        },
        {
            "x": -5,
            "y": -1,
            "z": 0,
            "elements": [
                "tconstruct:metal@5"
            ]
        },
        {
            "x": -1,
            "y": -3,
            "z": 1,
            "elements": [
                "gct_ores:rainboquartz_block@0"
            ]
        },
        {
            "x": -5,
            "y": 0,
            "z": 3,
            "elements": [
                "tconstruct:metal@5"
            ]
        },
        {
            "x": 5,
            "y": 0,
            "z": 2,
            "elements": [
                "mekanism:slickplasticblock@14"
            ]
        },
        {
            "x": 3,
            "y": -2,
            "z": 3,
            "elements": [
                "tcomplement:scorched_block@5"
            ]
        },
        {
            "x": 2,
            "y": 5,
            "z": 2,
            "elements": [
                "mekanism:slickplasticblock@14"
            ]
        },
        {
            "x": -4,
            "y": 0,
            "z": 0,
            "elements": [
                "tcomplement:scorched_block@5"
            ]
        },
        {
            "x": -6,
            "y": -3,
            "z": 2,
            "elements": [
                "mekanism:slickplasticblock@14"
            ]
        },
        {
            "x": -5,
            "y": -5,
            "z": 2,
            "elements": [
                "mekanism:slickplasticblock@14"
            ]
        },
        {
            "x": -3,
            "y": -4,
            "z": 3,
            "elements": [
                "tcomplement:scorched_block@5"
            ]
        },
        {
            "x": 3,
            "y": 2,
            "z": 0,
            "elements": [
                "tcomplement:scorched_block@5"
            ]
        },
        {
            "x": -4,
            "y": -2,
            "z": 0,
            "elements": [
                "tconstruct:metal@5"
            ]
        },
        {
            "x": -5,
            "y": -3,
            "z": 1,
            "elements": [
                "mekanism:slickplasticblock@14"
            ]
        },
        {
            "x": -3,
            "y": 4,
            "z": 3,
            "elements": [
                "tconstruct:metal@5"
            ]
        },
        {
            "x": 3,
            "y": 5,
            "z": 1,
            "elements": [
                "mekanism:slickplasticblock@14"
            ]
        },
        {
            "x": 2,
            "y": -3,
            "z": 3,
            "elements": [
                "tcomplement:scorched_block@5"
            ]
        },
        {
            "x": -4,
            "y": 2,
            "z": 1,
            "elements": [
                "mekanism:slickplasticblock@14"
            ]
        },
        {
            "x": -3,
            "y": 2,
            "z": 3,
            "elements": [
                "tcomplement:scorched_block@5"
            ]
        },
        {
            "x": 1,
            "y": -1,
            "z": 1,
            "elements": [
                "gct_ores:rainboquartz_block@0"
            ]
        },
        {
            "x": -3,
            "y": -5,
            "z": 3,
            "elements": [
                "tconstruct:metal@5"
            ]
        },
        {
            "x": 0,
            "y": 0,
            "z": 3,
            "elements": [
                "casings_upgrade"
            ]
        },
        {
            "x": -4,
            "y": -1,
            "z": 0,
            "elements": [
                "tcomplement:scorched_block@5"
            ]
        },
        {
            "x": 3,
            "y": 5,
            "z": 2,
            "elements": [
                "mekanism:slickplasticblock@14"
            ]
        },
        {
            "x": -4,
            "y": 3,
            "z": 1,
            "elements": [
                "mekanism:slickplasticblock@14"
            ]
        },
        {
            "x": 1,
            "y": 5,
            "z": 0,
            "elements": [
                "tconstruct:metal@5"
            ]
        },
        {
            "x": -2,
            "y": -5,
            "z": 0,
            "elements": [
                "tconstruct:metal@5"
            ]
        },
        {
            "x": 0,
            "y": 1,
            "z": 3,
            "elements": [
                "tconstruct:metal@5"
            ]
        },
        {
            "x": 6,
            "y": 3,
            "z": 2,
            "elements": [
                "mekanism:slickplasticblock@14"
            ]
        },
        {
            "x": -6,
            "y": -5,
            "z": 2,
            "elements": [
                "mekanism:slickplasticblock@14"
            ]
        },
        {
            "x": 1,
            "y": -5,
            "z": 1,
            "elements": [
                "mekanism:slickplasticblock@14"
            ]
        },
        {
            "x": -2,
            "y": -2,
            "z": 1,
            "elements": [
                "gct_ores:rainboquartz_block@0"
            ]
        },
        {
            "x": -2,
            "y": -3,
            "z": 1,
            "elements": [
                "gct_ores:rainboquartz_block@0"
            ]
        },
        {
            "x": 6,
            "y": 5,
            "z": 1,
            "elements": [
                "mekanism:slickplasticblock@14"
            ]
        },
        {
            "x": -4,
            "y": -1,
            "z": 3,
            "elements": [
                "tcomplement:scorched_block@5"
            ]
        },
        {
            "x": 3,
            "y": 4,
            "z": 0,
            "elements": [
                "tcomplement:scorched_block@5"
            ]
        },
        {
            "x": -4,
            "y": -4,
            "z": 0,
            "elements": [
                "thaumcraft:metal_void@0"
            ]
        },
        {
            "x": -7,
            "y": -4,
            "z": 2,
            "elements": [
                "casings_all"
            ]
        },
        {
            "x": 0,
            "y": 2,
            "z": 3,
            "elements": [
                "tcomplement:scorched_block@5"
            ]
        },
        {
            "x": -3,
            "y": -3,
            "z": 3,
            "elements": [
                "tcomplement:scorched_block@5"
            ]
        },
        {
            "x": 1,
            "y": -3,
            "z": 1,
            "elements": [
                "gct_ores:rainboquartz_block@0"
            ]
        },
        {
            "x": -3,
            "y": -2,
            "z": 3,
            "elements": [
                "tcomplement:scorched_block@5"
            ]
        },
        {
            "x": 2,
            "y": -4,
            "z": 3,
            "elements": [
                "tconstruct:metal@5"
            ]
        },
        {
            "x": 4,
            "y": 5,
            "z": 2,
            "elements": [
                "mekanism:slickplasticblock@14"
            ]
        },
        {
            "x": 3,
            "y": 3,
            "z": 0,
            "elements": [
                "tcomplement:scorched_block@5"
            ]
        },
        {
            "x": -4,
            "y": -3,
            "z": 0,
            "elements": [
                "tconstruct:metal@5"
            ]
        },
        {
            "x": 0,
            "y": 5,
            "z": 0,
            "elements": [
                "tconstruct:metal@5"
            ]
        },
        {
            "x": -1,
            "y": -5,
            "z": 0,
            "elements": [
                "tconstruct:metal@5"
            ]
        },
        {
            "x": -4,
            "y": 3,
            "z": 3,
            "elements": [
                "tconstruct:metal@5"
            ]
        },
        {
            "x": -2,
            "y": -5,
            "z": 1,
            "elements": [
                "mekanism:slickplasticblock@14"
            ]
        },
        {
            "x": -3,
            "y": 2,
            "z": 0,
            "elements": [
                "tcomplement:scorched_block@5"
            ]
        },
        {
            "x": -7,
            "y": -5,
            "z": 2,
            "elements": [
                "tconstruct:metal@5"
            ]
        },
        {
            "x": 7,
            "y": 5,
            "z": 0,
            "elements": [
                "tconstruct:metal@5"
            ]
        },
        {
            "x": -1,
            "y": -4,
            "z": 3,
            "elements": [
                "tcomplement:scorched_block@5"
            ]
        },
        {
            "x": 2,
            "y": 3,
            "z": 1,
            "elements": [
                "gct_ores:rainboquartz_block@0"
            ]
        },
        {
            "x": 0,
            "y": 4,
            "z": 0,
            "elements": [
                "tcomplement:scorched_block@5"
            ]
        },
        {
            "x": -1,
            "y": -4,
            "z": 0,
            "elements": [
                "tcomplement:scorched_block@5"
            ]
        },
        {
            "x": 5,
            "y": -1,
            "z": 0,
            "elements": [
                "tconstruct:metal@5"
            ]
        },
        {
            "x": 3,
            "y": 0,
            "z": 1,
            "elements": [
                "gct_ores:rainboquartz_block@0"
            ]
        },
        {
            "x": -1,
            "y": -5,
            "z": 3,
            "elements": [
                "tconstruct:metal@5"
            ]
        },
        {
            "x": -1,
            "y": 2,
            "z": 3,
            "elements": [
                "tcomplement:scorched_block@5"
            ]
        },
        {
            "x": 4,
            "y": -3,
            "z": 1,
            "elements": [
                "mekanism:slickplasticblock@14"
            ]
        },
        {
            "x": 2,
            "y": 2,
            "z": 1,
            "elements": [
                "gct_ores:rainboquartz_block@0"
            ]
        },
        {
            "x": -5,
            "y": -1,
            "z": 1,
            "elements": [
                "mekanism:slickplasticblock@14"
            ]
        },
        {
            "x": 3,
            "y": 1,
            "z": 1,
            "elements": [
                "gct_ores:rainboquartz_block@0"
            ]
        },
        {
            "x": 1,
            "y": 5,
            "z": 2,
            "elements": [
                "mekanism:slickplasticblock@14"
            ]
        },
        {
            "x": -2,
            "y": 0,
            "z": 3,
            "elements": [
                "tcomplement:scorched_block@5"
            ]
        },
        {
            "x": 0,
            "y": -2,
            "z": 3,
            "elements": [
                "tcomplement:scorched_block@5"
            ]
        },
        {
            "x": -7,
            "y": -3,
            "z": 2,
            "elements": [
                "tconstruct:metal@5"
            ]
        },
        {
            "x": 4,
            "y": -2,
            "z": 1,
            "elements": [
                "mekanism:slickplasticblock@14"
            ]
        },
        {
            "x": -4,
            "y": -5,
            "z": 2,
            "elements": [
                "mekanism:slickplasticblock@14"
            ]
        },
        {
            "x": -3,
            "y": 3,
            "z": 3,
            "elements": [
                "tcomplement:scorched_block@5"
            ]
        },
        {
            "x": 0,
            "y": 5,
            "z": 1,
            "elements": [
                "mekanism:slickplasticblock@14"
            ]
        },
        {
            "x": 0,
            "y": -4,
            "z": 3,
            "elements": [
                "tcomplement:scorched_block@5"
            ]
        },
        {
            "x": 0,
            "y": 2,
            "z": 0,
            "elements": [
                "tcomplement:scorched_block@5"
            ]
        },
        {
            "x": -1,
            "y": -2,
            "z": 0,
            "elements": [
                "tcomplement:scorched_block@5"
            ]
        },
        {
            "x": -2,
            "y": 1,
            "z": 3,
            "elements": [
                "tcomplement:scorched_block@5"
            ]
        },
        {
            "x": -2,
            "y": -1,
            "z": 3,
            "elements": [
                "tcomplement:scorched_block@5"
            ]
        },
        {
            "x": -3,
            "y": 4,
            "z": 0,
            "elements": [
                "tconstruct:metal@5"
            ]
        },
        {
            "x": 2,
            "y": -4,
            "z": 0,
            "elements": [
                "tconstruct:metal@5"
            ]
        },
        {
            "x": 2,
            "y": -1,
            "z": 0,
            "elements": [
                "tcomplement:scorched_block@5"
            ]
        },
        {
            "x": 0,
            "y": 1,
            "z": 0,
            "elements": [
                "tconstruct:metal@5"
            ]
        },
        {
            "x": -1,
            "y": 0,
            "z": 3,
            "elements": [
                "tconstruct:metal@5"
            ]
        },
        {
            "x": -3,
            "y": 3,
            "z": 0,
            "elements": [
                "tcomplement:scorched_block@5"
            ]
        },
        {
            "x": 2,
            "y": -3,
            "z": 0,
            "elements": [
                "tcomplement:scorched_block@5"
            ]
        },
        {
            "x": 0,
            "y": -5,
            "z": 3,
            "elements": [
                "tconstruct:metal@5"
            ]
        },
        {
            "x": 4,
            "y": 2,
            "z": 2,
            "elements": [
                "mekanism:slickplasticblock@14"
            ]
        },
        {
            "x": -1,
            "y": -2,
            "z": 3,
            "elements": [
                "tcomplement:scorched_block@5"
            ]
        },
        {
            "x": 7,
            "y": 3,
            "z": 2,
            "elements": [
                "tconstruct:metal@5"
            ]
        },
        {
            "x": 6,
            "y": 5,
            "z": 2,
            "elements": [
                "mekanism:slickplasticblock@14"
            ]
        }
    ]}