{
    "registryname": "ion_exchange_column",
    "localizedname": "§bLV5 - 大型离子交换柱",
    "requires-blueprint": false,
    "failure-action": "still",
    "color": "738c88",
    "parts": [
        {
            "x": 0,
            "y": 0,
            "z": 0,
            "elements": [
                "modularmachinery:blockcontroller@2"
            ]
        },
        {
            "x": -3,
            "y": 15,
            "z": 3,
            "elements": [
                "nuclearcraft:material_block@0"
            ]
        },
        {
            "x": 3,
            "y": 11,
            "z": 7,
            "elements": [
                "nuclearcraft:material_block@0"
            ]
        },
        {
            "x": -3,
            "y": 25,
            "z": 6,
            "elements": [
                "nuclearcraft:material_block@0"
            ]
        },
        {
            "x": -3,
            "y": 0,
            "z": 5,
            "elements": [
                "chisel:factory@12"
            ]
        },
        {
            "x": -3,
            "y": 21,
            "z": 7,
            "elements": [
                "nuclearcraft:material_block@0"
            ]
        },
        {
            "x": 0,
            "y": 11,
            "z": 4,
            "elements": [
                "thermalfoundation:glass_alloy@1"
            ]
        },
        {
            "x": 0,
            "y": 19,
            "z": 6,
            "elements": [
                "casings_all"
            ]
        },
        {
            "x": -3,
            "y": 6,
            "z": 7,
            "elements": [
                "nuclearcraft:material_block@0"
            ]
        },
        {
            "x": -3,
            "y": 12,
            "z": 3,
            "elements": [
                "nuclearcraft:material_block@0"
            ]
        },
        {
            "x": 0,
            "y": 10,
            "z": 4,
            "elements": [
                "thermalfoundation:glass_alloy@1"
            ]
        },
        {
            "x": 3,
            "y": 7,
            "z": 3,
            "elements": [
                "nuclearcraft:material_block@0"
            ]
        },
        {
            "x": 0,
            "y": 12,
            "z": 4,
            "elements": [
                "thermalfoundation:glass_alloy@1"
            ]
        },
        {
            "x": -3,
            "y": 7,
            "z": 7,
            "elements": [
                "nuclearcraft:material_block@0"
            ]
        },
        {
            "x": -3,
            "y": 20,
            "z": 7,
            "elements": [
                "nuclearcraft:material_block@0"
            ]
        },
        {
            "x": 3,
            "y": 10,
            "z": 7,
            "elements": [
                "nuclearcraft:material_block@0"
            ]
        },
        {
            "x": -1,
            "y": 17,
            "z": 4,
            "elements": [
                "thermalfoundation:glass_alloy@1"
            ]
        },
        {
            "x": 0,
            "y": 18,
            "z": 6,
            "elements": [
                "casings_all"
            ]
        },
        {
            "x": -3,
            "y": 13,
            "z": 3,
            "elements": [
                "nuclearcraft:material_block@0"
            ]
        },
        {
            "x": 3,
            "y": 8,
            "z": 3,
            "elements": [
                "nuclearcraft:material_block@0"
            ]
        },
        {
            "x": 1,
            "y": 0,
            "z": 0,
            "elements": [
                "chisel:factory@12"
            ]
        },
        {
            "x": 0,
            "y": 9,
            "z": 4,
            "elements": [
                "thermalfoundation:glass_alloy@1"
            ]
        },
        {
            "x": 0,
            "y": 21,
            "z": 6,
            "elements": [
                "casings_all"
            ]
        },
        {
            "x": -3,
            "y": 8,
            "z": 7,
            "elements": [
                "nuclearcraft:material_block@0"
            ]
        },
        {
            "x": 0,
            "y": 13,
            "z": 4,
            "elements": [
                "thermalfoundation:glass_alloy@1"
            ]
        },
        {
            "x": -3,
            "y": 18,
            "z": 7,
            "elements": [
                "nuclearcraft:material_block@0"
            ]
        },
        {
            "x": 3,
            "y": 9,
            "z": 3,
            "elements": [
                "nuclearcraft:material_block@0"
            ]
        },
        {
            "x": -2,
            "y": 0,
            "z": 5,
            "elements": [
                "modularmachinery:blockcasing@4"
            ]
        },
        {
            "x": -1,
            "y": 15,
            "z": 4,
            "elements": [
                "thermalfoundation:glass_alloy@1"
            ]
        },
        {
            "x": 0,
            "y": 8,
            "z": 4,
            "elements": [
                "thermalfoundation:glass_alloy@1"
            ]
        },
        {
            "x": -3,
            "y": 9,
            "z": 7,
            "elements": [
                "nuclearcraft:material_block@0"
            ]
        },
        {
            "x": -3,
            "y": 14,
            "z": 3,
            "elements": [
                "nuclearcraft:material_block@0"
            ]
        },
        {
            "x": 0,
            "y": 7,
            "z": 4,
            "elements": [
                "thermalfoundation:glass_alloy@1"
            ]
        },
        {
            "x": 0,
            "y": 22,
            "z": 6,
            "elements": [
                "casings_all"
            ]
        },
        {
            "x": 0,
            "y": 20,
            "z": 6,
            "elements": [
                "casings_all"
            ]
        },
        {
            "x": -2,
            "y": 2,
            "z": 5,
            "elements": [
                "thermalfoundation:glass_alloy@1"
            ]
        },
        {
            "x": -3,
            "y": 24,
            "z": 6,
            "elements": [
                "jaopca:block.polytetrafluoroethene@0"
            ]
        },
        {
            "x": 3,
            "y": 10,
            "z": 3,
            "elements": [
                "nuclearcraft:material_block@0"
            ]
        },
        {
            "x": -1,
            "y": 16,
            "z": 4,
            "elements": [
                "thermalfoundation:glass_alloy@1"
            ]
        },
        {
            "x": -2,
            "y": 1,
            "z": 5,
            "elements": [
                "thermalfoundation:glass_alloy@1"
            ]
        },
        {
            "x": 3,
            "y": 11,
            "z": 3,
            "elements": [
                "nuclearcraft:material_block@0"
            ]
        },
        {
            "x": -3,
            "y": 19,
            "z": 7,
            "elements": [
                "nuclearcraft:material_block@0"
            ]
        },
        {
            "x": 0,
            "y": 14,
            "z": 4,
            "elements": [
                "thermalfoundation:glass_alloy@1"
            ]
        },
        {
            "x": -1,
            "y": 13,
            "z": 4,
            "elements": [
                "thermalfoundation:glass_alloy@1"
            ]
        },
        {
            "x": 3,
            "y": 6,
            "z": 7,
            "elements": [
                "nuclearcraft:material_block@0"
            ]
        },
        {
            "x": 2,
            "y": 0,
            "z": 0,
            "elements": [
                "chisel:factory@12"
            ]
        },
        {
            "x": -3,
            "y": 8,
            "z": 3,
            "elements": [
                "nuclearcraft:material_block@0"
            ]
        },
        {
            "x": 3,
            "y": 1,
            "z": 3,
            "elements": [
                "nuclearcraft:material_block@0"
            ]
        },
        {
            "x": 3,
            "y": 15,
            "z": 3,
            "elements": [
                "nuclearcraft:material_block@0"
            ]
        },
        {
            "x": 1,
            "y": 0,
            "z": 6,
            "elements": [
                "casings_all"
            ]
        },
        {
            "x": 3,
            "y": 12,
            "z": 7,
            "elements": [
                "nuclearcraft:material_block@0"
            ]
        },
        {
            "x": -3,
            "y": 11,
            "z": 7,
            "elements": [
                "nuclearcraft:material_block@0"
            ]
        },
        {
            "x": -3,
            "y": 16,
            "z": 7,
            "elements": [
                "nuclearcraft:material_block@0"
            ]
        },
        {
            "x": 3,
            "y": 7,
            "z": 7,
            "elements": [
                "nuclearcraft:material_block@0"
            ]
        },
        {
            "x": 3,
            "y": 25,
            "z": 6,
            "elements": [
                "nuclearcraft:material_block@0"
            ]
        },
        {
            "x": 3,
            "y": 12,
            "z": 3,
            "elements": [
                "nuclearcraft:material_block@0"
            ]
        },
        {
            "x": -3,
            "y": 7,
            "z": 3,
            "elements": [
                "nuclearcraft:material_block@0"
            ]
        },
        {
            "x": 3,
            "y": 14,
            "z": 3,
            "elements": [
                "nuclearcraft:material_block@0"
            ]
        },
        {
            "x": 2,
            "y": 9,
            "z": 4,
            "elements": [
                "nuclearcraft:ingot_block@10"
            ]
        },
        {
            "x": -3,
            "y": 17,
            "z": 7,
            "elements": [
                "nuclearcraft:material_block@0"
            ]
        },
        {
            "x": -3,
            "y": 10,
            "z": 7,
            "elements": [
                "nuclearcraft:material_block@0"
            ]
        },
        {
            "x": -1,
            "y": 14,
            "z": 4,
            "elements": [
                "thermalfoundation:glass_alloy@1"
            ]
        },
        {
            "x": -1,
            "y": 0,
            "z": 0,
            "elements": [
                "chisel:factory@12"
            ]
        },
        {
            "x": 1,
            "y": 1,
            "z": 6,
            "elements": [
                "thermalfoundation:glass_alloy@1"
            ]
        },
        {
            "x": 3,
            "y": 13,
            "z": 7,
            "elements": [
                "nuclearcraft:material_block@0"
            ]
        },
        {
            "x": 3,
            "y": 13,
            "z": 3,
            "elements": [
                "nuclearcraft:material_block@0"
            ]
        },
        {
            "x": -3,
            "y": 13,
            "z": 7,
            "elements": [
                "nuclearcraft:material_block@0"
            ]
        },
        {
            "x": -1,
            "y": 11,
            "z": 4,
            "elements": [
                "thermalfoundation:glass_alloy@1"
            ]
        },
        {
            "x": 0,
            "y": 14,
            "z": 6,
            "elements": [
                "casings_all"
            ]
        },
        {
            "x": 3,
            "y": 9,
            "z": 7,
            "elements": [
                "nuclearcraft:material_block@0"
            ]
        },
        {
            "x": 0,
            "y": 0,
            "z": 5,
            "elements": [
                "modularmachinery:blockcasing@4"
            ]
        },
        {
            "x": 0,
            "y": 15,
            "z": 6,
            "elements": [
                "casings_all"
            ]
        },
        {
            "x": 0,
            "y": 2,
            "z": 5,
            "elements": [
                "darkutils:slime_dyed@0"
            ]
        },
        {
            "x": 0,
            "y": 17,
            "z": 6,
            "elements": [
                "casings_all"
            ]
        },
        {
            "x": -3,
            "y": 14,
            "z": 7,
            "elements": [
                "nuclearcraft:material_block@0"
            ]
        },
        {
            "x": 2,
            "y": 8,
            "z": 4,
            "elements": [
                "nuclearcraft:ingot_block@10"
            ]
        },
        {
            "x": -3,
            "y": 9,
            "z": 3,
            "elements": [
                "nuclearcraft:material_block@0"
            ]
        },
        {
            "x": 3,
            "y": 0,
            "z": 3,
            "elements": [
                "chisel:factory@12"
            ]
        },
        {
            "x": 2,
            "y": 7,
            "z": 4,
            "elements": [
                "nuclearcraft:ingot_block@10"
            ]
        },
        {
            "x": -3,
            "y": 11,
            "z": 3,
            "elements": [
                "nuclearcraft:material_block@0"
            ]
        },
        {
            "x": -3,
            "y": 12,
            "z": 7,
            "elements": [
                "nuclearcraft:material_block@0"
            ]
        },
        {
            "x": -1,
            "y": 12,
            "z": 4,
            "elements": [
                "thermalfoundation:glass_alloy@1"
            ]
        },
        {
            "x": 3,
            "y": 24,
            "z": 6,
            "elements": [
                "jaopca:block.polytetrafluoroethene@0"
            ]
        },
        {
            "x": 3,
            "y": 8,
            "z": 7,
            "elements": [
                "nuclearcraft:material_block@0"
            ]
        },
        {
            "x": 0,
            "y": 16,
            "z": 6,
            "elements": [
                "casings_all"
            ]
        },
        {
            "x": -3,
            "y": 10,
            "z": 3,
            "elements": [
                "nuclearcraft:material_block@0"
            ]
        },
        {
            "x": -3,
            "y": 15,
            "z": 7,
            "elements": [
                "nuclearcraft:material_block@0"
            ]
        },
        {
            "x": 0,
            "y": 1,
            "z": 5,
            "elements": [
                "darkutils:slime_dyed@0"
            ]
        },
        {
            "x": -2,
            "y": 9,
            "z": 6,
            "elements": [
                "nuclearcraft:ingot_block@10"
            ]
        },
        {
            "x": -1,
            "y": 6,
            "z": 5,
            "elements": [
                "darkutils:slime_dyed@0"
            ]
        },
        {
            "x": 1,
            "y": 4,
            "z": 6,
            "elements": [
                "thermalfoundation:glass_alloy@1"
            ]
        },
        {
            "x": -3,
            "y": 22,
            "z": 3,
            "elements": [
                "nuclearcraft:material_block@0"
            ]
        },
        {
            "x": 2,
            "y": 25,
            "z": 4,
            "elements": [
                "nuclearcraft:ingot_block@10"
            ]
        },
        {
            "x": 0,
            "y": 4,
            "z": 5,
            "elements": [
                "darkutils:slime_dyed@0"
            ]
        },
        {
            "x": 0,
            "y": 12,
            "z": 6,
            "elements": [
                "casings_all"
            ]
        },
        {
            "x": 3,
            "y": 2,
            "z": 7,
            "elements": [
                "nuclearcraft:material_block@0"
            ]
        },
        {
            "x": -1,
            "y": 27,
            "z": 4,
            "elements": [
                "erebus:slab_amber_bricks@1"
            ]
        },
        {
            "x": 0,
            "y": 1,
            "z": 4,
            "elements": [
                "thermalfoundation:glass_alloy@1"
            ]
        },
        {
            "x": -3,
            "y": 23,
            "z": 3,
            "elements": [
                "nuclearcraft:material_block@0"
            ]
        },
        {
            "x": 0,
            "y": 13,
            "z": 6,
            "elements": [
                "casings_all"
            ]
        },
        {
            "x": -1,
            "y": 5,
            "z": 5,
            "elements": [
                "darkutils:slime_dyed@0"
            ]
        },
        {
            "x": 0,
            "y": 3,
            "z": 5,
            "elements": [
                "darkutils:slime_dyed@0"
            ]
        },
        {
            "x": 0,
            "y": 2,
            "z": 4,
            "elements": [
                "thermalfoundation:glass_alloy@1"
            ]
        },
        {
            "x": 2,
            "y": 26,
            "z": 4,
            "elements": [
                "nuclearcraft:ingot_block@10"
            ]
        },
        {
            "x": -2,
            "y": 8,
            "z": 6,
            "elements": [
                "nuclearcraft:ingot_block@10"
            ]
        },
        {
            "x": 3,
            "y": 0,
            "z": 4,
            "elements": [
                "chisel:factory@12"
            ]
        },
        {
            "x": 3,
            "y": 3,
            "z": 7,
            "elements": [
                "nuclearcraft:material_block@0"
            ]
        },
        {
            "x": 1,
            "y": 2,
            "z": 6,
            "elements": [
                "thermalfoundation:glass_alloy@1"
            ]
        },
        {
            "x": 3,
            "y": 4,
            "z": 7,
            "elements": [
                "nuclearcraft:material_block@0"
            ]
        },
        {
            "x": 2,
            "y": 23,
            "z": 4,
            "elements": [
                "nuclearcraft:ingot_block@10"
            ]
        },
        {
            "x": -3,
            "y": 0,
            "z": 4,
            "elements": [
                "chisel:factory@12"
            ]
        },
        {
            "x": 0,
            "y": 6,
            "z": 5,
            "elements": [
                "darkutils:slime_dyed@0"
            ]
        },
        {
            "x": 1,
            "y": 5,
            "z": 6,
            "elements": [
                "thermalfoundation:glass_alloy@1"
            ]
        },
        {
            "x": -1,
            "y": 4,
            "z": 5,
            "elements": [
                "darkutils:slime_dyed@0"
            ]
        },
        {
            "x": 2,
            "y": 0,
            "z": 5,
            "elements": [
                "modularmachinery:blockcasing@4"
            ]
        },
        {
            "x": 2,
            "y": 2,
            "z": 5,
            "elements": [
                "thermalfoundation:glass_alloy@1"
            ]
        },
        {
            "x": -2,
            "y": 7,
            "z": 6,
            "elements": [
                "nuclearcraft:ingot_block@10"
            ]
        },
        {
            "x": 3,
            "y": 2,
            "z": 3,
            "elements": [
                "nuclearcraft:material_block@0"
            ]
        },
        {
            "x": -3,
            "y": 21,
            "z": 3,
            "elements": [
                "nuclearcraft:material_block@0"
            ]
        },
        {
            "x": 3,
            "y": 5,
            "z": 7,
            "elements": [
                "nuclearcraft:material_block@0"
            ]
        },
        {
            "x": 0,
            "y": 10,
            "z": 6,
            "elements": [
                "casings_all"
            ]
        },
        {
            "x": 0,
            "y": 5,
            "z": 5,
            "elements": [
                "darkutils:slime_dyed@0"
            ]
        },
        {
            "x": 1,
            "y": 3,
            "z": 6,
            "elements": [
                "thermalfoundation:glass_alloy@1"
            ]
        },
        {
            "x": 2,
            "y": 24,
            "z": 4,
            "elements": [
                "nuclearcraft:ingot_block@10"
            ]
        },
        {
            "x": -2,
            "y": 6,
            "z": 6,
            "elements": [
                "nuclearcraft:ingot_block@10"
            ]
        },
        {
            "x": 0,
            "y": 0,
            "z": 4,
            "elements": [
                "modularmachinery:blockcasing@4"
            ]
        },
        {
            "x": 2,
            "y": 1,
            "z": 5,
            "elements": [
                "thermalfoundation:glass_alloy@1"
            ]
        },
        {
            "x": -3,
            "y": 20,
            "z": 3,
            "elements": [
                "nuclearcraft:material_block@0"
            ]
        },
        {
            "x": 0,
            "y": 11,
            "z": 6,
            "elements": [
                "casings_all"
            ]
        },
        {
            "x": -2,
            "y": 0,
            "z": 0,
            "elements": [
                "chisel:factory@12"
            ]
        },
        {
            "x": -1,
            "y": 3,
            "z": 5,
            "elements": [
                "darkutils:slime_dyed@0"
            ]
        },
        {
            "x": 0,
            "y": 9,
            "z": 6,
            "elements": [
                "casings_all"
            ]
        },
        {
            "x": 0,
            "y": 6,
            "z": 4,
            "elements": [
                "thermalfoundation:glass_alloy@1"
            ]
        },
        {
            "x": 3,
            "y": 4,
            "z": 3,
            "elements": [
                "nuclearcraft:material_block@0"
            ]
        },
        {
            "x": -1,
            "y": 0,
            "z": 5,
            "elements": [
                "modularmachinery:blockcasing@4"
            ]
        },
        {
            "x": 1,
            "y": 7,
            "z": 6,
            "elements": [
                "thermalfoundation:glass_alloy@1"
            ]
        },
        {
            "x": -1,
            "y": 22,
            "z": 4,
            "elements": [
                "thermalfoundation:glass_alloy@1"
            ]
        },
        {
            "x": -3,
            "y": 19,
            "z": 3,
            "elements": [
                "nuclearcraft:material_block@0"
            ]
        },
        {
            "x": -2,
            "y": 12,
            "z": 6,
            "elements": [
                "nuclearcraft:ingot_block@10"
            ]
        },
        {
            "x": -1,
            "y": 2,
            "z": 5,
            "elements": [
                "darkutils:slime_dyed@0"
            ]
        },
        {
            "x": 0,
            "y": 8,
            "z": 6,
            "elements": [
                "casings_all"
            ]
        },
        {
            "x": 0,
            "y": 7,
            "z": 5,
            "elements": [
                "darkutils:slime_dyed@0"
            ]
        },
        {
            "x": 3,
            "y": 0,
            "z": 7,
            "elements": [
                "chisel:factory@12"
            ]
        },
        {
            "x": 3,
            "y": 3,
            "z": 3,
            "elements": [
                "nuclearcraft:material_block@0"
            ]
        },
        {
            "x": -2,
            "y": 13,
            "z": 6,
            "elements": [
                "nuclearcraft:ingot_block@10"
            ]
        },
        {
            "x": 0,
            "y": 5,
            "z": 4,
            "elements": [
                "thermalfoundation:glass_alloy@1"
            ]
        },
        {
            "x": -3,
            "y": 18,
            "z": 3,
            "elements": [
                "nuclearcraft:material_block@0"
            ]
        },
        {
            "x": -1,
            "y": 21,
            "z": 4,
            "elements": [
                "thermalfoundation:glass_alloy@1"
            ]
        },
        {
            "x": -1,
            "y": 1,
            "z": 5,
            "elements": [
                "darkutils:slime_dyed@0"
            ]
        },
        {
            "x": 1,
            "y": 6,
            "z": 6,
            "elements": [
                "thermalfoundation:glass_alloy@1"
            ]
        },
        {
            "x": 0,
            "y": 3,
            "z": 4,
            "elements": [
                "thermalfoundation:glass_alloy@1"
            ]
        },
        {
            "x": 3,
            "y": 6,
            "z": 3,
            "elements": [
                "nuclearcraft:material_block@0"
            ]
        },
        {
            "x": -3,
            "y": 17,
            "z": 3,
            "elements": [
                "nuclearcraft:material_block@0"
            ]
        },
        {
            "x": 1,
            "y": 9,
            "z": 6,
            "elements": [
                "thermalfoundation:glass_alloy@1"
            ]
        },
        {
            "x": -1,
            "y": 20,
            "z": 4,
            "elements": [
                "thermalfoundation:glass_alloy@1"
            ]
        },
        {
            "x": 0,
            "y": 7,
            "z": 6,
            "elements": [
                "casings_all"
            ]
        },
        {
            "x": 1,
            "y": 8,
            "z": 6,
            "elements": [
                "thermalfoundation:glass_alloy@1"
            ]
        },
        {
            "x": -2,
            "y": 10,
            "z": 6,
            "elements": [
                "nuclearcraft:ingot_block@10"
            ]
        },
        {
            "x": 3,
            "y": 5,
            "z": 3,
            "elements": [
                "nuclearcraft:material_block@0"
            ]
        },
        {
            "x": -3,
            "y": 16,
            "z": 3,
            "elements": [
                "nuclearcraft:material_block@0"
            ]
        },
        {
            "x": -1,
            "y": 19,
            "z": 4,
            "elements": [
                "thermalfoundation:glass_alloy@1"
            ]
        },
        {
            "x": 0,
            "y": 4,
            "z": 4,
            "elements": [
                "thermalfoundation:glass_alloy@1"
            ]
        },
        {
            "x": 3,
            "y": 1,
            "z": 7,
            "elements": [
                "nuclearcraft:material_block@0"
            ]
        },
        {
            "x": -2,
            "y": 11,
            "z": 6,
            "elements": [
                "nuclearcraft:ingot_block@10"
            ]
        },
        {
            "x": 0,
            "y": 6,
            "z": 6,
            "elements": [
                "casings_all"
            ]
        },
        {
            "x": -2,
            "y": 16,
            "z": 6,
            "elements": [
                "nuclearcraft:ingot_block@10"
            ]
        },
        {
            "x": 2,
            "y": 24,
            "z": 7,
            "elements": [
                "jaopca:block.polytetrafluoroethene@0"
            ]
        },
        {
            "x": -2,
            "y": 5,
            "z": 4,
            "elements": [
                "nuclearcraft:ingot_block@10"
            ]
        },
        {
            "x": 2,
            "y": 23,
            "z": 6,
            "elements": [
                "nuclearcraft:ingot_block@10"
            ]
        },
        {
            "x": -1,
            "y": 11,
            "z": 5,
            "elements": [
                "darkutils:slime_dyed@0"
            ]
        },
        {
            "x": 1,
            "y": 17,
            "z": 6,
            "elements": [
                "thermalfoundation:glass_alloy@1"
            ]
        },
        {
            "x": -2,
            "y": 6,
            "z": 4,
            "elements": [
                "nuclearcraft:ingot_block@10"
            ]
        },
        {
            "x": 0,
            "y": 9,
            "z": 5,
            "elements": [
                "darkutils:slime_dyed@0"
            ]
        },
        {
            "x": 1,
            "y": 10,
            "z": 6,
            "elements": [
                "thermalfoundation:glass_alloy@1"
            ]
        },
        {
            "x": 2,
            "y": 25,
            "z": 7,
            "elements": [
                "nuclearcraft:material_block@0"
            ]
        },
        {
            "x": -1,
            "y": 12,
            "z": 5,
            "elements": [
                "darkutils:slime_dyed@0"
            ]
        },
        {
            "x": 2,
            "y": 24,
            "z": 6,
            "elements": [
                "nuclearcraft:ingot_block@10"
            ]
        },
        {
            "x": -1,
            "y": 0,
            "z": 4,
            "elements": [
                "modularmachinery:blockcasing@4"
            ]
        },
        {
            "x": 0,
            "y": 10,
            "z": 5,
            "elements": [
                "darkutils:slime_dyed@0"
            ]
        },
        {
            "x": 1,
            "y": 16,
            "z": 6,
            "elements": [
                "thermalfoundation:glass_alloy@1"
            ]
        },
        {
            "x": 1,
            "y": 11,
            "z": 6,
            "elements": [
                "thermalfoundation:glass_alloy@1"
            ]
        },
        {
            "x": 2,
            "y": 0,
            "z": 2,
            "elements": [
                "chisel:factory@12"
            ]
        },
        {
            "x": -1,
            "y": 13,
            "z": 5,
            "elements": [
                "darkutils:slime_dyed@0"
            ]
        },
        {
            "x": 3,
            "y": 24,
            "z": 7,
            "elements": [
                "nuclearcraft:material_block@0"
            ]
        },
        {
            "x": -2,
            "y": 3,
            "z": 4,
            "elements": [
                "nuclearcraft:ingot_block@10"
            ]
        },
        {
            "x": -2,
            "y": 14,
            "z": 6,
            "elements": [
                "nuclearcraft:ingot_block@10"
            ]
        },
        {
            "x": -1,
            "y": 14,
            "z": 5,
            "elements": [
                "darkutils:slime_dyed@0"
            ]
        },
        {
            "x": -1,
            "y": 1,
            "z": 4,
            "elements": [
                "thermalfoundation:glass_alloy@1"
            ]
        },
        {
            "x": 1,
            "y": 12,
            "z": 6,
            "elements": [
                "thermalfoundation:glass_alloy@1"
            ]
        },
        {
            "x": 2,
            "y": 25,
            "z": 6,
            "elements": [
                "nuclearcraft:ingot_block@10"
            ]
        },
        {
            "x": 3,
            "y": 23,
            "z": 7,
            "elements": [
                "nuclearcraft:material_block@0"
            ]
        },
        {
            "x": -2,
            "y": 17,
            "z": 6,
            "elements": [
                "nuclearcraft:ingot_block@10"
            ]
        },
        {
            "x": -1,
            "y": 27,
            "z": 6,
            "elements": [
                "erebus:slab_amber_bricks@1"
            ]
        },
        {
            "x": -2,
            "y": 4,
            "z": 4,
            "elements": [
                "nuclearcraft:ingot_block@10"
            ]
        },
        {
            "x": 1,
            "y": 13,
            "z": 6,
            "elements": [
                "thermalfoundation:glass_alloy@1"
            ]
        },
        {
            "x": 1,
            "y": 0,
            "z": 3,
            "elements": [
                "chisel:factory@12"
            ]
        },
        {
            "x": -2,
            "y": 15,
            "z": 6,
            "elements": [
                "nuclearcraft:ingot_block@10"
            ]
        },
        {
            "x": -1,
            "y": 2,
            "z": 4,
            "elements": [
                "thermalfoundation:glass_alloy@1"
            ]
        },
        {
            "x": 3,
            "y": 22,
            "z": 7,
            "elements": [
                "nuclearcraft:material_block@0"
            ]
        },
        {
            "x": 0,
            "y": 8,
            "z": 5,
            "elements": [
                "darkutils:slime_dyed@0"
            ]
        },
        {
            "x": 2,
            "y": 26,
            "z": 6,
            "elements": [
                "nuclearcraft:ingot_block@10"
            ]
        },
        {
            "x": 1,
            "y": 14,
            "z": 6,
            "elements": [
                "thermalfoundation:glass_alloy@1"
            ]
        },
        {
            "x": -2,
            "y": 1,
            "z": 4,
            "elements": [
                "nuclearcraft:ingot_block@10"
            ]
        },
        {
            "x": -2,
            "y": 19,
            "z": 6,
            "elements": [
                "nuclearcraft:ingot_block@10"
            ]
        },
        {
            "x": 2,
            "y": 9,
            "z": 5,
            "elements": [
                "thermalfoundation:glass_alloy@1"
            ]
        },
        {
            "x": 2,
            "y": 4,
            "z": 5,
            "elements": [
                "thermalfoundation:glass_alloy@1"
            ]
        },
        {
            "x": 3,
            "y": 0,
            "z": 5,
            "elements": [
                "chisel:factory@12"
            ]
        },
        {
            "x": 1,
            "y": 15,
            "z": 6,
            "elements": [
                "thermalfoundation:glass_alloy@1"
            ]
        },
        {
            "x": 2,
            "y": 10,
            "z": 5,
            "elements": [
                "thermalfoundation:glass_alloy@1"
            ]
        },
        {
            "x": 2,
            "y": 3,
            "z": 5,
            "elements": [
                "thermalfoundation:glass_alloy@1"
            ]
        },
        {
            "x": -2,
            "y": 18,
            "z": 6,
            "elements": [
                "nuclearcraft:ingot_block@10"
            ]
        },
        {
            "x": -2,
            "y": 2,
            "z": 4,
            "elements": [
                "nuclearcraft:ingot_block@10"
            ]
        },
        {
            "x": -1,
            "y": 8,
            "z": 5,
            "elements": [
                "darkutils:slime_dyed@0"
            ]
        },
        {
            "x": 2,
            "y": 6,
            "z": 5,
            "elements": [
                "thermalfoundation:glass_alloy@1"
            ]
        },
        {
            "x": -2,
            "y": 21,
            "z": 6,
            "elements": [
                "nuclearcraft:ingot_block@10"
            ]
        },
        {
            "x": -1,
            "y": 9,
            "z": 5,
            "elements": [
                "darkutils:slime_dyed@0"
            ]
        },
        {
            "x": 2,
            "y": 7,
            "z": 5,
            "elements": [
                "thermalfoundation:glass_alloy@1"
            ]
        },
        {
            "x": -2,
            "y": 22,
            "z": 6,
            "elements": [
                "nuclearcraft:ingot_block@10"
            ]
        },
        {
            "x": -1,
            "y": 7,
            "z": 5,
            "elements": [
                "darkutils:slime_dyed@0"
            ]
        },
        {
            "x": 2,
            "y": 5,
            "z": 5,
            "elements": [
                "thermalfoundation:glass_alloy@1"
            ]
        },
        {
            "x": -2,
            "y": 20,
            "z": 6,
            "elements": [
                "nuclearcraft:ingot_block@10"
            ]
        },
        {
            "x": -2,
            "y": 0,
            "z": 4,
            "elements": [
                "casings_all"
            ]
        },
        {
            "x": -1,
            "y": 10,
            "z": 5,
            "elements": [
                "darkutils:slime_dyed@0"
            ]
        },
        {
            "x": 2,
            "y": 8,
            "z": 5,
            "elements": [
                "thermalfoundation:glass_alloy@1"
            ]
        },
        {
            "x": -1,
            "y": 8,
            "z": 4,
            "elements": [
                "thermalfoundation:glass_alloy@1"
            ]
        },
        {
            "x": -2,
            "y": 23,
            "z": 6,
            "elements": [
                "nuclearcraft:ingot_block@10"
            ]
        },
        {
            "x": -1,
            "y": 21,
            "z": 6,
            "elements": [
                "thermalfoundation:glass_alloy@1"
            ]
        },
        {
            "x": -3,
            "y": 1,
            "z": 3,
            "elements": [
                "nuclearcraft:material_block@0"
            ]
        },
        {
            "x": 3,
            "y": 16,
            "z": 7,
            "elements": [
                "nuclearcraft:material_block@0"
            ]
        },
        {
            "x": -2,
            "y": 25,
            "z": 7,
            "elements": [
                "nuclearcraft:material_block@0"
            ]
        },
        {
            "x": -1,
            "y": 7,
            "z": 4,
            "elements": [
                "thermalfoundation:glass_alloy@1"
            ]
        },
        {
            "x": 1,
            "y": 25,
            "z": 6,
            "elements": [
                "thermalfoundation:glass_alloy@1"
            ]
        },
        {
            "x": 0,
            "y": 23,
            "z": 7,
            "elements": [
                "jaopca:block.breedum@0"
            ]
        },
        {
            "x": -3,
            "y": 4,
            "z": 3,
            "elements": [
                "nuclearcraft:material_block@0"
            ]
        },
        {
            "x": 2,
            "y": 14,
            "z": 5,
            "elements": [
                "thermalfoundation:glass_alloy@1"
            ]
        },
        {
            "x": 0,
            "y": 27,
            "z": 6,
            "elements": [
                "erebus:slab_amber_bricks@1"
            ]
        },
        {
            "x": 2,
            "y": 6,
            "z": 4,
            "elements": [
                "nuclearcraft:ingot_block@10"
            ]
        },
        {
            "x": -1,
            "y": 22,
            "z": 6,
            "elements": [
                "thermalfoundation:glass_alloy@1"
            ]
        },
        {
            "x": -3,
            "y": 2,
            "z": 3,
            "elements": [
                "nuclearcraft:material_block@0"
            ]
        },
        {
            "x": 0,
            "y": 0,
            "z": 3,
            "elements": [
                "casings_parallel"
            ]
        },
        {
            "x": -2,
            "y": 24,
            "z": 6,
            "elements": [
                "nuclearcraft:ingot_block@10"
            ]
        },
        {
            "x": -1,
            "y": 20,
            "z": 6,
            "elements": [
                "thermalfoundation:glass_alloy@1"
            ]
        },
        {
            "x": -1,
            "y": 19,
            "z": 5,
            "elements": [
                "darkutils:slime_dyed@0"
            ]
        },
        {
            "x": 2,
            "y": 5,
            "z": 4,
            "elements": [
                "nuclearcraft:ingot_block@10"
            ]
        },
        {
            "x": 3,
            "y": 17,
            "z": 7,
            "elements": [
                "nuclearcraft:material_block@0"
            ]
        },
        {
            "x": 1,
            "y": 26,
            "z": 6,
            "elements": [
                "nuclearcraft:ingot_block@10"
            ]
        },
        {
            "x": 2,
            "y": 13,
            "z": 5,
            "elements": [
                "thermalfoundation:glass_alloy@1"
            ]
        },
        {
            "x": 2,
            "y": 14,
            "z": 6,
            "elements": [
                "nuclearcraft:ingot_block@10"
            ]
        },
        {
            "x": -1,
            "y": 23,
            "z": 7,
            "elements": [
                "jaopca:block.breedum@0"
            ]
        },
        {
            "x": -1,
            "y": 10,
            "z": 4,
            "elements": [
                "thermalfoundation:glass_alloy@1"
            ]
        },
        {
            "x": 2,
            "y": 11,
            "z": 5,
            "elements": [
                "thermalfoundation:glass_alloy@1"
            ]
        },
        {
            "x": 1,
            "y": 23,
            "z": 6,
            "elements": [
                "thermalfoundation:glass_alloy@1"
            ]
        },
        {
            "x": 2,
            "y": 3,
            "z": 4,
            "elements": [
                "nuclearcraft:ingot_block@10"
            ]
        },
        {
            "x": -1,
            "y": 19,
            "z": 6,
            "elements": [
                "thermalfoundation:glass_alloy@1"
            ]
        },
        {
            "x": -2,
            "y": 25,
            "z": 6,
            "elements": [
                "nuclearcraft:ingot_block@10"
            ]
        },
        {
            "x": -3,
            "y": 6,
            "z": 3,
            "elements": [
                "nuclearcraft:material_block@0"
            ]
        },
        {
            "x": 2,
            "y": 17,
            "z": 6,
            "elements": [
                "nuclearcraft:ingot_block@10"
            ]
        },
        {
            "x": 3,
            "y": 14,
            "z": 7,
            "elements": [
                "nuclearcraft:material_block@0"
            ]
        },
        {
            "x": 2,
            "y": 12,
            "z": 5,
            "elements": [
                "thermalfoundation:glass_alloy@1"
            ]
        },
        {
            "x": -1,
            "y": 25,
            "z": 7,
            "elements": [
                "jaopca:block.porpezite@0"
            ]
        },
        {
            "x": 2,
            "y": 15,
            "z": 6,
            "elements": [
                "nuclearcraft:ingot_block@10"
            ]
        },
        {
            "x": 3,
            "y": 15,
            "z": 7,
            "elements": [
                "nuclearcraft:material_block@0"
            ]
        },
        {
            "x": 2,
            "y": 4,
            "z": 4,
            "elements": [
                "nuclearcraft:ingot_block@10"
            ]
        },
        {
            "x": -1,
            "y": 18,
            "z": 6,
            "elements": [
                "thermalfoundation:glass_alloy@1"
            ]
        },
        {
            "x": 1,
            "y": 24,
            "z": 6,
            "elements": [
                "thermalfoundation:glass_alloy@1"
            ]
        },
        {
            "x": -3,
            "y": 0,
            "z": 3,
            "elements": [
                "chisel:factory@12"
            ]
        },
        {
            "x": -3,
            "y": 5,
            "z": 3,
            "elements": [
                "nuclearcraft:material_block@0"
            ]
        },
        {
            "x": -2,
            "y": 26,
            "z": 6,
            "elements": [
                "nuclearcraft:ingot_block@10"
            ]
        },
        {
            "x": 2,
            "y": 16,
            "z": 6,
            "elements": [
                "nuclearcraft:ingot_block@10"
            ]
        },
        {
            "x": -1,
            "y": 9,
            "z": 4,
            "elements": [
                "thermalfoundation:glass_alloy@1"
            ]
        },
        {
            "x": 1,
            "y": 21,
            "z": 6,
            "elements": [
                "thermalfoundation:glass_alloy@1"
            ]
        },
        {
            "x": -1,
            "y": 3,
            "z": 4,
            "elements": [
                "thermalfoundation:glass_alloy@1"
            ]
        },
        {
            "x": 0,
            "y": 23,
            "z": 6,
            "elements": [
                "thermalfoundation:glass_alloy@1"
            ]
        },
        {
            "x": 2,
            "y": 19,
            "z": 6,
            "elements": [
                "nuclearcraft:ingot_block@10"
            ]
        },
        {
            "x": 2,
            "y": 18,
            "z": 5,
            "elements": [
                "thermalfoundation:glass_alloy@1"
            ]
        },
        {
            "x": -1,
            "y": 25,
            "z": 6,
            "elements": [
                "thermalfoundation:glass_alloy@1"
            ]
        },
        {
            "x": 3,
            "y": 21,
            "z": 7,
            "elements": [
                "nuclearcraft:material_block@0"
            ]
        },
        {
            "x": 1,
            "y": 20,
            "z": 6,
            "elements": [
                "thermalfoundation:glass_alloy@1"
            ]
        },
        {
            "x": 2,
            "y": 1,
            "z": 4,
            "elements": [
                "nuclearcraft:ingot_block@10"
            ]
        },
        {
            "x": -1,
            "y": 16,
            "z": 5,
            "elements": [
                "darkutils:slime_dyed@0"
            ]
        },
        {
            "x": -1,
            "y": 21,
            "z": 5,
            "elements": [
                "darkutils:slime_dyed@0"
            ]
        },
        {
            "x": 0,
            "y": 25,
            "z": 7,
            "elements": [
                "jaopca:block.porpezite@0"
            ]
        },
        {
            "x": 2,
            "y": 2,
            "z": 4,
            "elements": [
                "nuclearcraft:ingot_block@10"
            ]
        },
        {
            "x": 3,
            "y": 20,
            "z": 7,
            "elements": [
                "nuclearcraft:material_block@0"
            ]
        },
        {
            "x": 1,
            "y": 22,
            "z": 6,
            "elements": [
                "thermalfoundation:glass_alloy@1"
            ]
        },
        {
            "x": -1,
            "y": 22,
            "z": 5,
            "elements": [
                "darkutils:slime_dyed@0"
            ]
        },
        {
            "x": 2,
            "y": 17,
            "z": 5,
            "elements": [
                "thermalfoundation:glass_alloy@1"
            ]
        },
        {
            "x": -1,
            "y": 4,
            "z": 4,
            "elements": [
                "thermalfoundation:glass_alloy@1"
            ]
        },
        {
            "x": 2,
            "y": 18,
            "z": 6,
            "elements": [
                "nuclearcraft:ingot_block@10"
            ]
        },
        {
            "x": 0,
            "y": 24,
            "z": 6,
            "elements": [
                "thermalfoundation:glass_alloy@1"
            ]
        },
        {
            "x": 1,
            "y": 0,
            "z": 4,
            "elements": [
                "modularmachinery:blockcasing@4"
            ]
        },
        {
            "x": -1,
            "y": 26,
            "z": 6,
            "elements": [
                "nuclearcraft:ingot_block@10"
            ]
        },
        {
            "x": -2,
            "y": 0,
            "z": 3,
            "elements": [
                "chisel:factory@12"
            ]
        },
        {
            "x": -3,
            "y": 24,
            "z": 7,
            "elements": [
                "nuclearcraft:material_block@0"
            ]
        },
        {
            "x": -1,
            "y": 15,
            "z": 5,
            "elements": [
                "darkutils:slime_dyed@0"
            ]
        },
        {
            "x": 2,
            "y": 16,
            "z": 5,
            "elements": [
                "thermalfoundation:glass_alloy@1"
            ]
        },
        {
            "x": 1,
            "y": 19,
            "z": 6,
            "elements": [
                "thermalfoundation:glass_alloy@1"
            ]
        },
        {
            "x": -3,
            "y": 3,
            "z": 3,
            "elements": [
                "nuclearcraft:material_block@0"
            ]
        },
        {
            "x": -1,
            "y": 23,
            "z": 6,
            "elements": [
                "thermalfoundation:glass_alloy@1"
            ]
        },
        {
            "x": -1,
            "y": 18,
            "z": 5,
            "elements": [
                "darkutils:slime_dyed@0"
            ]
        },
        {
            "x": -1,
            "y": 5,
            "z": 4,
            "elements": [
                "thermalfoundation:glass_alloy@1"
            ]
        },
        {
            "x": 3,
            "y": 19,
            "z": 7,
            "elements": [
                "nuclearcraft:material_block@0"
            ]
        },
        {
            "x": -1,
            "y": 6,
            "z": 4,
            "elements": [
                "thermalfoundation:glass_alloy@1"
            ]
        },
        {
            "x": -3,
            "y": 23,
            "z": 7,
            "elements": [
                "nuclearcraft:material_block@0"
            ]
        },
        {
            "x": 0,
            "y": 25,
            "z": 6,
            "elements": [
                "thermalfoundation:glass_alloy@1"
            ]
        },
        {
            "x": 1,
            "y": 1,
            "z": 4,
            "elements": [
                "thermalfoundation:glass_alloy@1"
            ]
        },
        {
            "x": 2,
            "y": 22,
            "z": 6,
            "elements": [
                "nuclearcraft:ingot_block@10"
            ]
        },
        {
            "x": 1,
            "y": 2,
            "z": 4,
            "elements": [
                "thermalfoundation:glass_alloy@1"
            ]
        },
        {
            "x": 2,
            "y": 20,
            "z": 6,
            "elements": [
                "nuclearcraft:ingot_block@10"
            ]
        },
        {
            "x": -1,
            "y": 17,
            "z": 5,
            "elements": [
                "darkutils:slime_dyed@0"
            ]
        },
        {
            "x": -1,
            "y": 0,
            "z": 3,
            "elements": [
                "chisel:factory@12"
            ]
        },
        {
            "x": 3,
            "y": 18,
            "z": 7,
            "elements": [
                "nuclearcraft:material_block@0"
            ]
        },
        {
            "x": -3,
            "y": 22,
            "z": 7,
            "elements": [
                "nuclearcraft:material_block@0"
            ]
        },
        {
            "x": -1,
            "y": 24,
            "z": 6,
            "elements": [
                "thermalfoundation:glass_alloy@1"
            ]
        },
        {
            "x": 1,
            "y": 18,
            "z": 6,
            "elements": [
                "thermalfoundation:glass_alloy@1"
            ]
        },
        {
            "x": -1,
            "y": 20,
            "z": 5,
            "elements": [
                "darkutils:slime_dyed@0"
            ]
        },
        {
            "x": 2,
            "y": 0,
            "z": 4,
            "elements": [
                "casings_all"
            ]
        },
        {
            "x": 0,
            "y": 26,
            "z": 6,
            "elements": [
                "nuclearcraft:ingot_block@10"
            ]
        },
        {
            "x": 2,
            "y": 15,
            "z": 5,
            "elements": [
                "thermalfoundation:glass_alloy@1"
            ]
        },
        {
            "x": 2,
            "y": 21,
            "z": 6,
            "elements": [
                "nuclearcraft:ingot_block@10"
            ]
        },
        {
            "x": 1,
            "y": 3,
            "z": 4,
            "elements": [
                "thermalfoundation:glass_alloy@1"
            ]
        },
        {
            "x": 0,
            "y": 23,
            "z": 5,
            "elements": [
                "darkutils:slime_dyed@0"
            ]
        },
        {
            "x": 2,
            "y": 2,
            "z": 6,
            "elements": [
                "nuclearcraft:ingot_block@10"
            ]
        },
        {
            "x": 2,
            "y": 9,
            "z": 6,
            "elements": [
                "nuclearcraft:ingot_block@10"
            ]
        },
        {
            "x": 1,
            "y": 25,
            "z": 3,
            "elements": [
                "jaopca:block.porpezite@0"
            ]
        },
        {
            "x": -1,
            "y": 26,
            "z": 5,
            "elements": [
                "darkutils:slime_dyed@0"
            ]
        },
        {
            "x": 2,
            "y": 19,
            "z": 5,
            "elements": [
                "thermalfoundation:glass_alloy@1"
            ]
        },
        {
            "x": 1,
            "y": 21,
            "z": 5,
            "elements": [
                "darkutils:slime_dyed@0"
            ]
        },
        {
            "x": -1,
            "y": 7,
            "z": 6,
            "elements": [
                "thermalfoundation:glass_alloy@1"
            ]
        },
        {
            "x": -2,
            "y": 24,
            "z": 3,
            "elements": [
                "jaopca:block.polytetrafluoroethene@0"
            ]
        },
        {
            "x": 2,
            "y": 8,
            "z": 6,
            "elements": [
                "nuclearcraft:ingot_block@10"
            ]
        },
        {
            "x": 1,
            "y": 4,
            "z": 4,
            "elements": [
                "thermalfoundation:glass_alloy@1"
            ]
        },
        {
            "x": 1,
            "y": 22,
            "z": 5,
            "elements": [
                "darkutils:slime_dyed@0"
            ]
        },
        {
            "x": 0,
            "y": 24,
            "z": 5,
            "elements": [
                "darkutils:slime_dyed@0"
            ]
        },
        {
            "x": 2,
            "y": 3,
            "z": 6,
            "elements": [
                "nuclearcraft:ingot_block@10"
            ]
        },
        {
            "x": -1,
            "y": 6,
            "z": 6,
            "elements": [
                "thermalfoundation:glass_alloy@1"
            ]
        },
        {
            "x": -1,
            "y": 25,
            "z": 5,
            "elements": [
                "darkutils:slime_dyed@0"
            ]
        },
        {
            "x": -2,
            "y": 25,
            "z": 3,
            "elements": [
                "nuclearcraft:material_block@0"
            ]
        },
        {
            "x": -1,
            "y": 9,
            "z": 6,
            "elements": [
                "thermalfoundation:glass_alloy@1"
            ]
        },
        {
            "x": 2,
            "y": 20,
            "z": 5,
            "elements": [
                "thermalfoundation:glass_alloy@1"
            ]
        },
        {
            "x": 1,
            "y": 23,
            "z": 3,
            "elements": [
                "jaopca:block.breedum@0"
            ]
        },
        {
            "x": -1,
            "y": 23,
            "z": 5,
            "elements": [
                "darkutils:slime_dyed@0"
            ]
        },
        {
            "x": 0,
            "y": 26,
            "z": 5,
            "elements": [
                "darkutils:slime_dyed@0"
            ]
        },
        {
            "x": 2,
            "y": 21,
            "z": 5,
            "elements": [
                "thermalfoundation:glass_alloy@1"
            ]
        },
        {
            "x": 2,
            "y": 7,
            "z": 6,
            "elements": [
                "nuclearcraft:ingot_block@10"
            ]
        },
        {
            "x": 1,
            "y": 19,
            "z": 5,
            "elements": [
                "darkutils:slime_dyed@0"
            ]
        },
        {
            "x": 1,
            "y": 6,
            "z": 4,
            "elements": [
                "thermalfoundation:glass_alloy@1"
            ]
        },
        {
            "x": 2,
            "y": 22,
            "z": 5,
            "elements": [
                "thermalfoundation:glass_alloy@1"
            ]
        },
        {
            "x": -1,
            "y": 8,
            "z": 6,
            "elements": [
                "thermalfoundation:glass_alloy@1"
            ]
        },
        {
            "x": 2,
            "y": 0,
            "z": 7,
            "elements": [
                "chisel:factory@12"
            ]
        },
        {
            "x": -1,
            "y": 24,
            "z": 5,
            "elements": [
                "darkutils:slime_dyed@0"
            ]
        },
        {
            "x": 1,
            "y": 5,
            "z": 4,
            "elements": [
                "thermalfoundation:glass_alloy@1"
            ]
        },
        {
            "x": 0,
            "y": 25,
            "z": 5,
            "elements": [
                "darkutils:slime_dyed@0"
            ]
        },
        {
            "x": 2,
            "y": 6,
            "z": 6,
            "elements": [
                "nuclearcraft:ingot_block@10"
            ]
        },
        {
            "x": 3,
            "y": 0,
            "z": 2,
            "elements": [
                "chisel:factory@12"
            ]
        },
        {
            "x": 1,
            "y": 20,
            "z": 5,
            "elements": [
                "darkutils:slime_dyed@0"
            ]
        },
        {
            "x": -3,
            "y": 25,
            "z": 5,
            "elements": [
                "jaopca:block.porpezite@0"
            ]
        },
        {
            "x": -1,
            "y": 4,
            "z": 6,
            "elements": [
                "thermalfoundation:glass_alloy@1"
            ]
        },
        {
            "x": 2,
            "y": 23,
            "z": 5,
            "elements": [
                "thermalfoundation:glass_alloy@1"
            ]
        },
        {
            "x": 0,
            "y": 19,
            "z": 5,
            "elements": [
                "darkutils:slime_dyed@0"
            ]
        },
        {
            "x": 1,
            "y": 8,
            "z": 4,
            "elements": [
                "thermalfoundation:glass_alloy@1"
            ]
        },
        {
            "x": 2,
            "y": 24,
            "z": 5,
            "elements": [
                "thermalfoundation:glass_alloy@1"
            ]
        },
        {
            "x": 2,
            "y": 12,
            "z": 6,
            "elements": [
                "nuclearcraft:ingot_block@10"
            ]
        },
        {
            "x": -1,
            "y": 17,
            "z": 6,
            "elements": [
                "thermalfoundation:glass_alloy@1"
            ]
        },
        {
            "x": 1,
            "y": 27,
            "z": 6,
            "elements": [
                "erebus:slab_amber_bricks@1"
            ]
        },
        {
            "x": -1,
            "y": 0,
            "z": 7,
            "elements": [
                "chisel:factory@12"
            ]
        },
        {
            "x": 1,
            "y": 7,
            "z": 4,
            "elements": [
                "thermalfoundation:glass_alloy@1"
            ]
        },
        {
            "x": 2,
            "y": 13,
            "z": 6,
            "elements": [
                "nuclearcraft:ingot_block@10"
            ]
        },
        {
            "x": -2,
            "y": 12,
            "z": 4,
            "elements": [
                "nuclearcraft:ingot_block@10"
            ]
        },
        {
            "x": 2,
            "y": 0,
            "z": 3,
            "elements": [
                "chisel:factory@12"
            ]
        },
        {
            "x": 0,
            "y": 20,
            "z": 5,
            "elements": [
                "darkutils:slime_dyed@0"
            ]
        },
        {
            "x": 0,
            "y": 0,
            "z": 2,
            "elements": [
                "modularmachinery:blockcasing@4"
            ]
        },
        {
            "x": -2,
            "y": 13,
            "z": 4,
            "elements": [
                "nuclearcraft:ingot_block@10"
            ]
        },
        {
            "x": -3,
            "y": 23,
            "z": 5,
            "elements": [
                "jaopca:block.breedum@0"
            ]
        },
        {
            "x": -3,
            "y": 0,
            "z": 2,
            "elements": [
                "chisel:factory@12"
            ]
        },
        {
            "x": 2,
            "y": 26,
            "z": 5,
            "elements": [
                "nuclearcraft:ingot_block@10"
            ]
        },
        {
            "x": -1,
            "y": 5,
            "z": 6,
            "elements": [
                "thermalfoundation:glass_alloy@1"
            ]
        },
        {
            "x": 1,
            "y": 10,
            "z": 4,
            "elements": [
                "thermalfoundation:glass_alloy@1"
            ]
        },
        {
            "x": 0,
            "y": 21,
            "z": 5,
            "elements": [
                "darkutils:slime_dyed@0"
            ]
        },
        {
            "x": 1,
            "y": 23,
            "z": 7,
            "elements": [
                "jaopca:block.breedum@0"
            ]
        },
        {
            "x": 2,
            "y": 0,
            "z": 6,
            "elements": [
                "casings_all"
            ]
        },
        {
            "x": 2,
            "y": 10,
            "z": 6,
            "elements": [
                "nuclearcraft:ingot_block@10"
            ]
        },
        {
            "x": -1,
            "y": 2,
            "z": 6,
            "elements": [
                "thermalfoundation:glass_alloy@1"
            ]
        },
        {
            "x": -2,
            "y": 14,
            "z": 4,
            "elements": [
                "nuclearcraft:ingot_block@10"
            ]
        },
        {
            "x": 1,
            "y": 25,
            "z": 7,
            "elements": [
                "jaopca:block.porpezite@0"
            ]
        },
        {
            "x": 0,
            "y": 22,
            "z": 5,
            "elements": [
                "darkutils:slime_dyed@0"
            ]
        },
        {
            "x": -1,
            "y": 3,
            "z": 6,
            "elements": [
                "thermalfoundation:glass_alloy@1"
            ]
        },
        {
            "x": -1,
            "y": 27,
            "z": 5,
            "elements": [
                "erebus:slab_amber_bricks@1"
            ]
        },
        {
            "x": 1,
            "y": 9,
            "z": 4,
            "elements": [
                "thermalfoundation:glass_alloy@1"
            ]
        },
        {
            "x": 2,
            "y": 11,
            "z": 6,
            "elements": [
                "nuclearcraft:ingot_block@10"
            ]
        },
        {
            "x": 2,
            "y": 25,
            "z": 5,
            "elements": [
                "thermalfoundation:glass_alloy@1"
            ]
        },
        {
            "x": -2,
            "y": 24,
            "z": 7,
            "elements": [
                "jaopca:block.polytetrafluoroethene@0"
            ]
        },
        {
            "x": 2,
            "y": 1,
            "z": 6,
            "elements": [
                "nuclearcraft:ingot_block@10"
            ]
        },
        {
            "x": 1,
            "y": 13,
            "z": 4,
            "elements": [
                "thermalfoundation:glass_alloy@1"
            ]
        },
        {
            "x": 1,
            "y": 16,
            "z": 5,
            "elements": [
                "darkutils:slime_dyed@0"
            ]
        },
        {
            "x": -2,
            "y": 0,
            "z": 2,
            "elements": [
                "chisel:factory@12"
            ]
        },
        {
            "x": -1,
            "y": 14,
            "z": 6,
            "elements": [
                "thermalfoundation:glass_alloy@1"
            ]
        },
        {
            "x": 0,
            "y": 18,
            "z": 5,
            "elements": [
                "darkutils:slime_dyed@0"
            ]
        },
        {
            "x": -2,
            "y": 15,
            "z": 4,
            "elements": [
                "nuclearcraft:ingot_block@10"
            ]
        },
        {
            "x": 1,
            "y": 0,
            "z": 1,
            "elements": [
                "modularmachinery:blockcasing@4"
            ]
        },
        {
            "x": -1,
            "y": 15,
            "z": 6,
            "elements": [
                "thermalfoundation:glass_alloy@1"
            ]
        },
        {
            "x": 0,
            "y": 17,
            "z": 5,
            "elements": [
                "darkutils:slime_dyed@0"
            ]
        },
        {
            "x": -2,
            "y": 20,
            "z": 5,
            "elements": [
                "thermalfoundation:glass_alloy@1"
            ]
        },
        {
            "x": -2,
            "y": 16,
            "z": 4,
            "elements": [
                "nuclearcraft:ingot_block@10"
            ]
        },
        {
            "x": 1,
            "y": 14,
            "z": 4,
            "elements": [
                "thermalfoundation:glass_alloy@1"
            ]
        },
        {
            "x": 1,
            "y": 15,
            "z": 5,
            "elements": [
                "darkutils:slime_dyed@0"
            ]
        },
        {
            "x": -1,
            "y": 16,
            "z": 6,
            "elements": [
                "thermalfoundation:glass_alloy@1"
            ]
        },
        {
            "x": 0,
            "y": 16,
            "z": 5,
            "elements": [
                "darkutils:slime_dyed@0"
            ]
        },
        {
            "x": -2,
            "y": 18,
            "z": 4,
            "elements": [
                "nuclearcraft:ingot_block@10"
            ]
        },
        {
            "x": 1,
            "y": 11,
            "z": 4,
            "elements": [
                "thermalfoundation:glass_alloy@1"
            ]
        },
        {
            "x": 1,
            "y": 18,
            "z": 5,
            "elements": [
                "darkutils:slime_dyed@0"
            ]
        },
        {
            "x": -2,
            "y": 21,
            "z": 5,
            "elements": [
                "thermalfoundation:glass_alloy@1"
            ]
        },
        {
            "x": 1,
            "y": 12,
            "z": 4,
            "elements": [
                "thermalfoundation:glass_alloy@1"
            ]
        },
        {
            "x": 1,
            "y": 17,
            "z": 5,
            "elements": [
                "darkutils:slime_dyed@0"
            ]
        },
        {
            "x": -2,
            "y": 17,
            "z": 4,
            "elements": [
                "nuclearcraft:ingot_block@10"
            ]
        },
        {
            "x": -2,
            "y": 19,
            "z": 5,
            "elements": [
                "thermalfoundation:glass_alloy@1"
            ]
        },
        {
            "x": -2,
            "y": 22,
            "z": 5,
            "elements": [
                "thermalfoundation:glass_alloy@1"
            ]
        },
        {
            "x": -1,
            "y": 0,
            "z": 2,
            "elements": [
                "modularmachinery:blockcasing@4"
            ]
        },
        {
            "x": -2,
            "y": 11,
            "z": 4,
            "elements": [
                "nuclearcraft:ingot_block@10"
            ]
        },
        {
            "x": 0,
            "y": 15,
            "z": 5,
            "elements": [
                "darkutils:slime_dyed@0"
            ]
        },
        {
            "x": 1,
            "y": 27,
            "z": 5,
            "elements": [
                "erebus:slab_amber_bricks@1"
            ]
        },
        {
            "x": 1,
            "y": 18,
            "z": 4,
            "elements": [
                "thermalfoundation:glass_alloy@1"
            ]
        },
        {
            "x": 1,
            "y": 26,
            "z": 5,
            "elements": [
                "darkutils:slime_dyed@0"
            ]
        },
        {
            "x": 0,
            "y": 13,
            "z": 5,
            "elements": [
                "darkutils:slime_dyed@0"
            ]
        },
        {
            "x": -2,
            "y": 23,
            "z": 5,
            "elements": [
                "thermalfoundation:glass_alloy@1"
            ]
        },
        {
            "x": -2,
            "y": 20,
            "z": 4,
            "elements": [
                "nuclearcraft:ingot_block@10"
            ]
        },
        {
            "x": -2,
            "y": 10,
            "z": 4,
            "elements": [
                "nuclearcraft:ingot_block@10"
            ]
        },
        {
            "x": 2,
            "y": 5,
            "z": 6,
            "elements": [
                "nuclearcraft:ingot_block@10"
            ]
        },
        {
            "x": 0,
            "y": 14,
            "z": 5,
            "elements": [
                "darkutils:slime_dyed@0"
            ]
        },
        {
            "x": -1,
            "y": 10,
            "z": 6,
            "elements": [
                "thermalfoundation:glass_alloy@1"
            ]
        },
        {
            "x": 1,
            "y": 17,
            "z": 4,
            "elements": [
                "thermalfoundation:glass_alloy@1"
            ]
        },
        {
            "x": -2,
            "y": 24,
            "z": 5,
            "elements": [
                "thermalfoundation:glass_alloy@1"
            ]
        },
        {
            "x": -2,
            "y": 19,
            "z": 4,
            "elements": [
                "nuclearcraft:ingot_block@10"
            ]
        },
        {
            "x": 1,
            "y": 25,
            "z": 5,
            "elements": [
                "darkutils:slime_dyed@0"
            ]
        },
        {
            "x": 2,
            "y": 4,
            "z": 6,
            "elements": [
                "nuclearcraft:ingot_block@10"
            ]
        },
        {
            "x": -2,
            "y": 9,
            "z": 4,
            "elements": [
                "nuclearcraft:ingot_block@10"
            ]
        },
        {
            "x": -1,
            "y": 11,
            "z": 6,
            "elements": [
                "thermalfoundation:glass_alloy@1"
            ]
        },
        {
            "x": -2,
            "y": 25,
            "z": 5,
            "elements": [
                "thermalfoundation:glass_alloy@1"
            ]
        },
        {
            "x": -2,
            "y": 8,
            "z": 4,
            "elements": [
                "nuclearcraft:ingot_block@10"
            ]
        },
        {
            "x": -2,
            "y": 26,
            "z": 5,
            "elements": [
                "nuclearcraft:ingot_block@10"
            ]
        },
        {
            "x": 1,
            "y": 16,
            "z": 4,
            "elements": [
                "thermalfoundation:glass_alloy@1"
            ]
        },
        {
            "x": 1,
            "y": 23,
            "z": 5,
            "elements": [
                "darkutils:slime_dyed@0"
            ]
        },
        {
            "x": 0,
            "y": 11,
            "z": 5,
            "elements": [
                "darkutils:slime_dyed@0"
            ]
        },
        {
            "x": -1,
            "y": 12,
            "z": 6,
            "elements": [
                "thermalfoundation:glass_alloy@1"
            ]
        },
        {
            "x": 1,
            "y": 15,
            "z": 4,
            "elements": [
                "thermalfoundation:glass_alloy@1"
            ]
        },
        {
            "x": -2,
            "y": 22,
            "z": 4,
            "elements": [
                "nuclearcraft:ingot_block@10"
            ]
        },
        {
            "x": 0,
            "y": 12,
            "z": 5,
            "elements": [
                "darkutils:slime_dyed@0"
            ]
        },
        {
            "x": 1,
            "y": 24,
            "z": 5,
            "elements": [
                "darkutils:slime_dyed@0"
            ]
        },
        {
            "x": -2,
            "y": 7,
            "z": 4,
            "elements": [
                "nuclearcraft:ingot_block@10"
            ]
        },
        {
            "x": -2,
            "y": 21,
            "z": 4,
            "elements": [
                "nuclearcraft:ingot_block@10"
            ]
        },
        {
            "x": -1,
            "y": 13,
            "z": 6,
            "elements": [
                "thermalfoundation:glass_alloy@1"
            ]
        },
        {
            "x": 1,
            "y": 0,
            "z": 2,
            "elements": [
                "modularmachinery:blockcasing@4"
            ]
        },
        {
            "x": -2,
            "y": 25,
            "z": 4,
            "elements": [
                "nuclearcraft:ingot_block@10"
            ]
        },
        {
            "x": -3,
            "y": 0,
            "z": 1,
            "elements": [
                "chisel:factory@12"
            ]
        },
        {
            "x": -2,
            "y": 13,
            "z": 5,
            "elements": [
                "thermalfoundation:glass_alloy@1"
            ]
        },
        {
            "x": 1,
            "y": 23,
            "z": 4,
            "elements": [
                "thermalfoundation:glass_alloy@1"
            ]
        },
        {
            "x": 2,
            "y": 16,
            "z": 4,
            "elements": [
                "nuclearcraft:ingot_block@10"
            ]
        },
        {
            "x": 2,
            "y": 15,
            "z": 4,
            "elements": [
                "nuclearcraft:ingot_block@10"
            ]
        },
        {
            "x": -2,
            "y": 14,
            "z": 5,
            "elements": [
                "thermalfoundation:glass_alloy@1"
            ]
        },
        {
            "x": 0,
            "y": 5,
            "z": 6,
            "elements": [
                "casings_all"
            ]
        },
        {
            "x": 3,
            "y": 0,
            "z": 6,
            "elements": [
                "chisel:factory@12"
            ]
        },
        {
            "x": 1,
            "y": 0,
            "z": 7,
            "elements": [
                "chisel:factory@12"
            ]
        },
        {
            "x": 2,
            "y": 0,
            "z": -1,
            "elements": [
                "erebus:slab_amber_bricks@1"
            ]
        },
        {
            "x": 1,
            "y": 24,
            "z": 4,
            "elements": [
                "thermalfoundation:glass_alloy@1"
            ]
        },
        {
            "x": -2,
            "y": 26,
            "z": 4,
            "elements": [
                "nuclearcraft:ingot_block@10"
            ]
        },
        {
            "x": 1,
            "y": 8,
            "z": 5,
            "elements": [
                "darkutils:slime_dyed@0"
            ]
        },
        {
            "x": 1,
            "y": 21,
            "z": 4,
            "elements": [
                "thermalfoundation:glass_alloy@1"
            ]
        },
        {
            "x": -2,
            "y": 23,
            "z": 4,
            "elements": [
                "nuclearcraft:ingot_block@10"
            ]
        },
        {
            "x": 2,
            "y": 18,
            "z": 4,
            "elements": [
                "nuclearcraft:ingot_block@10"
            ]
        },
        {
            "x": 1,
            "y": 9,
            "z": 5,
            "elements": [
                "darkutils:slime_dyed@0"
            ]
        },
        {
            "x": 1,
            "y": 25,
            "z": 4,
            "elements": [
                "thermalfoundation:glass_alloy@1"
            ]
        },
        {
            "x": -2,
            "y": 11,
            "z": 5,
            "elements": [
                "thermalfoundation:glass_alloy@1"
            ]
        },
        {
            "x": 1,
            "y": 20,
            "z": 4,
            "elements": [
                "thermalfoundation:glass_alloy@1"
            ]
        },
        {
            "x": 0,
            "y": 0,
            "z": 6,
            "elements": [
                "casings_all"
            ]
        },
        {
            "x": 0,
            "y": 27,
            "z": 4,
            "elements": [
                "erebus:slab_amber_bricks@1"
            ]
        },
        {
            "x": 0,
            "y": 0,
            "z": 1,
            "elements": [
                "modularmachinery:blockcasing@4"
            ]
        },
        {
            "x": -2,
            "y": 24,
            "z": 4,
            "elements": [
                "nuclearcraft:ingot_block@10"
            ]
        },
        {
            "x": 2,
            "y": 17,
            "z": 4,
            "elements": [
                "nuclearcraft:ingot_block@10"
            ]
        },
        {
            "x": 1,
            "y": 7,
            "z": 5,
            "elements": [
                "darkutils:slime_dyed@0"
            ]
        },
        {
            "x": -2,
            "y": 12,
            "z": 5,
            "elements": [
                "thermalfoundation:glass_alloy@1"
            ]
        },
        {
            "x": 1,
            "y": 10,
            "z": 5,
            "elements": [
                "darkutils:slime_dyed@0"
            ]
        },
        {
            "x": 1,
            "y": 19,
            "z": 4,
            "elements": [
                "thermalfoundation:glass_alloy@1"
            ]
        },
        {
            "x": 0,
            "y": 1,
            "z": 6,
            "elements": [
                "casings_all"
            ]
        },
        {
            "x": 1,
            "y": 26,
            "z": 4,
            "elements": [
                "nuclearcraft:ingot_block@10"
            ]
        },
        {
            "x": 0,
            "y": 2,
            "z": 6,
            "elements": [
                "casings_all"
            ]
        },
        {
            "x": -1,
            "y": 0,
            "z": 1,
            "elements": [
                "modularmachinery:blockcasing@4"
            ]
        },
        {
            "x": -1,
            "y": 23,
            "z": 4,
            "elements": [
                "thermalfoundation:glass_alloy@1"
            ]
        },
        {
            "x": -2,
            "y": 18,
            "z": 5,
            "elements": [
                "thermalfoundation:glass_alloy@1"
            ]
        },
        {
            "x": 1,
            "y": 11,
            "z": 5,
            "elements": [
                "darkutils:slime_dyed@0"
            ]
        },
        {
            "x": 0,
            "y": 25,
            "z": 4,
            "elements": [
                "thermalfoundation:glass_alloy@1"
            ]
        },
        {
            "x": 2,
            "y": 20,
            "z": 4,
            "elements": [
                "nuclearcraft:ingot_block@10"
            ]
        },
        {
            "x": 0,
            "y": 3,
            "z": 6,
            "elements": [
                "casings_all"
            ]
        },
        {
            "x": -2,
            "y": 17,
            "z": 5,
            "elements": [
                "thermalfoundation:glass_alloy@1"
            ]
        },
        {
            "x": 0,
            "y": 0,
            "z": -1,
            "elements": [
                "erebus:slab_amber_bricks@1"
            ]
        },
        {
            "x": 2,
            "y": 22,
            "z": 4,
            "elements": [
                "nuclearcraft:ingot_block@10"
            ]
        },
        {
            "x": 1,
            "y": 12,
            "z": 5,
            "elements": [
                "darkutils:slime_dyed@0"
            ]
        },
        {
            "x": 3,
            "y": 24,
            "z": 3,
            "elements": [
                "nuclearcraft:material_block@0"
            ]
        },
        {
            "x": -1,
            "y": 24,
            "z": 4,
            "elements": [
                "thermalfoundation:glass_alloy@1"
            ]
        },
        {
            "x": 0,
            "y": 26,
            "z": 4,
            "elements": [
                "nuclearcraft:ingot_block@10"
            ]
        },
        {
            "x": 2,
            "y": 19,
            "z": 4,
            "elements": [
                "nuclearcraft:ingot_block@10"
            ]
        },
        {
            "x": -1,
            "y": 23,
            "z": 3,
            "elements": [
                "jaopca:block.breedum@0"
            ]
        },
        {
            "x": -2,
            "y": 0,
            "z": 1,
            "elements": [
                "chisel:factory@12"
            ]
        },
        {
            "x": 0,
            "y": 23,
            "z": 4,
            "elements": [
                "thermalfoundation:glass_alloy@1"
            ]
        },
        {
            "x": 0,
            "y": 4,
            "z": 6,
            "elements": [
                "casings_all"
            ]
        },
        {
            "x": 1,
            "y": 14,
            "z": 5,
            "elements": [
                "darkutils:slime_dyed@0"
            ]
        },
        {
            "x": -1,
            "y": 25,
            "z": 4,
            "elements": [
                "thermalfoundation:glass_alloy@1"
            ]
        },
        {
            "x": -3,
            "y": 24,
            "z": 3,
            "elements": [
                "nuclearcraft:material_block@0"
            ]
        },
        {
            "x": -2,
            "y": 16,
            "z": 5,
            "elements": [
                "thermalfoundation:glass_alloy@1"
            ]
        },
        {
            "x": -1,
            "y": 0,
            "z": -1,
            "elements": [
                "erebus:slab_amber_bricks@1"
            ]
        },
        {
            "x": 1,
            "y": 22,
            "z": 4,
            "elements": [
                "thermalfoundation:glass_alloy@1"
            ]
        },
        {
            "x": 0,
            "y": 24,
            "z": 4,
            "elements": [
                "thermalfoundation:glass_alloy@1"
            ]
        },
        {
            "x": -1,
            "y": 26,
            "z": 4,
            "elements": [
                "nuclearcraft:ingot_block@10"
            ]
        },
        {
            "x": -2,
            "y": 15,
            "z": 5,
            "elements": [
                "thermalfoundation:glass_alloy@1"
            ]
        },
        {
            "x": 1,
            "y": 13,
            "z": 5,
            "elements": [
                "darkutils:slime_dyed@0"
            ]
        },
        {
            "x": 2,
            "y": 21,
            "z": 4,
            "elements": [
                "nuclearcraft:ingot_block@10"
            ]
        },
        {
            "x": -2,
            "y": 8,
            "z": 5,
            "elements": [
                "thermalfoundation:glass_alloy@1"
            ]
        },
        {
            "x": -3,
            "y": 1,
            "z": 7,
            "elements": [
                "nuclearcraft:material_block@0"
            ]
        },
        {
            "x": 0,
            "y": 20,
            "z": 4,
            "elements": [
                "thermalfoundation:glass_alloy@1"
            ]
        },
        {
            "x": 2,
            "y": 24,
            "z": 3,
            "elements": [
                "jaopca:block.polytetrafluoroethene@0"
            ]
        },
        {
            "x": 0,
            "y": 22,
            "z": 4,
            "elements": [
                "thermalfoundation:glass_alloy@1"
            ]
        },
        {
            "x": 1,
            "y": 2,
            "z": 5,
            "elements": [
                "darkutils:slime_dyed@0"
            ]
        },
        {
            "x": 1,
            "y": 0,
            "z": 5,
            "elements": [
                "modularmachinery:blockcasing@4"
            ]
        },
        {
            "x": -1,
            "y": 0,
            "z": 6,
            "elements": [
                "casings_all"
            ]
        },
        {
            "x": -3,
            "y": 0,
            "z": 7,
            "elements": [
                "chisel:factory@12"
            ]
        },
        {
            "x": -2,
            "y": 7,
            "z": 5,
            "elements": [
                "thermalfoundation:glass_alloy@1"
            ]
        },
        {
            "x": -2,
            "y": 0,
            "z": -1,
            "elements": [
                "erebus:slab_amber_bricks@1"
            ]
        },
        {
            "x": 3,
            "y": 19,
            "z": 3,
            "elements": [
                "nuclearcraft:material_block@0"
            ]
        },
        {
            "x": -2,
            "y": 2,
            "z": 6,
            "elements": [
                "nuclearcraft:ingot_block@10"
            ]
        },
        {
            "x": -2,
            "y": 3,
            "z": 6,
            "elements": [
                "nuclearcraft:ingot_block@10"
            ]
        },
        {
            "x": -3,
            "y": 24,
            "z": 4,
            "elements": [
                "jaopca:block.polytetrafluoroethene@0"
            ]
        },
        {
            "x": 0,
            "y": 19,
            "z": 4,
            "elements": [
                "thermalfoundation:glass_alloy@1"
            ]
        },
        {
            "x": 1,
            "y": 1,
            "z": 5,
            "elements": [
                "darkutils:slime_dyed@0"
            ]
        },
        {
            "x": 3,
            "y": 18,
            "z": 3,
            "elements": [
                "nuclearcraft:material_block@0"
            ]
        },
        {
            "x": -1,
            "y": 1,
            "z": 6,
            "elements": [
                "thermalfoundation:glass_alloy@1"
            ]
        },
        {
            "x": -3,
            "y": 0,
            "z": 0,
            "elements": [
                "erebus:slab_amber_bricks@1"
            ]
        },
        {
            "x": 3,
            "y": 25,
            "z": 5,
            "elements": [
                "jaopca:block.porpezite@0"
            ]
        },
        {
            "x": 2,
            "y": 25,
            "z": 3,
            "elements": [
                "nuclearcraft:material_block@0"
            ]
        },
        {
            "x": 3,
            "y": 23,
            "z": 5,
            "elements": [
                "jaopca:block.breedum@0"
            ]
        },
        {
            "x": -3,
            "y": 25,
            "z": 4,
            "elements": [
                "nuclearcraft:material_block@0"
            ]
        },
        {
            "x": -2,
            "y": 4,
            "z": 6,
            "elements": [
                "nuclearcraft:ingot_block@10"
            ]
        },
        {
            "x": 3,
            "y": 17,
            "z": 3,
            "elements": [
                "nuclearcraft:material_block@0"
            ]
        },
        {
            "x": -2,
            "y": 0,
            "z": 7,
            "elements": [
                "chisel:factory@12"
            ]
        },
        {
            "x": 1,
            "y": 0,
            "z": -1,
            "elements": [
                "erebus:slab_amber_bricks@1"
            ]
        },
        {
            "x": 2,
            "y": 10,
            "z": 4,
            "elements": [
                "nuclearcraft:ingot_block@10"
            ]
        },
        {
            "x": -2,
            "y": 5,
            "z": 6,
            "elements": [
                "nuclearcraft:ingot_block@10"
            ]
        },
        {
            "x": 3,
            "y": 16,
            "z": 3,
            "elements": [
                "nuclearcraft:material_block@0"
            ]
        },
        {
            "x": -1,
            "y": 25,
            "z": 3,
            "elements": [
                "jaopca:block.porpezite@0"
            ]
        },
        {
            "x": 0,
            "y": 21,
            "z": 4,
            "elements": [
                "thermalfoundation:glass_alloy@1"
            ]
        },
        {
            "x": 0,
            "y": 23,
            "z": 3,
            "elements": [
                "jaopca:block.breedum@0"
            ]
        },
        {
            "x": 1,
            "y": 6,
            "z": 5,
            "elements": [
                "darkutils:slime_dyed@0"
            ]
        },
        {
            "x": -2,
            "y": 4,
            "z": 5,
            "elements": [
                "thermalfoundation:glass_alloy@1"
            ]
        },
        {
            "x": 2,
            "y": 11,
            "z": 4,
            "elements": [
                "nuclearcraft:ingot_block@10"
            ]
        },
        {
            "x": -3,
            "y": 0,
            "z": 6,
            "elements": [
                "chisel:factory@12"
            ]
        },
        {
            "x": 3,
            "y": 22,
            "z": 3,
            "elements": [
                "nuclearcraft:material_block@0"
            ]
        },
        {
            "x": 3,
            "y": 0,
            "z": 1,
            "elements": [
                "chisel:factory@12"
            ]
        },
        {
            "x": 0,
            "y": 15,
            "z": 4,
            "elements": [
                "thermalfoundation:glass_alloy@1"
            ]
        },
        {
            "x": 1,
            "y": 27,
            "z": 4,
            "elements": [
                "erebus:slab_amber_bricks@1"
            ]
        },
        {
            "x": -2,
            "y": 9,
            "z": 5,
            "elements": [
                "thermalfoundation:glass_alloy@1"
            ]
        },
        {
            "x": 2,
            "y": 12,
            "z": 4,
            "elements": [
                "nuclearcraft:ingot_block@10"
            ]
        },
        {
            "x": 0,
            "y": 27,
            "z": 5,
            "elements": [
                "additions:finallium_block@0"
            ]
        },
        {
            "x": 1,
            "y": 5,
            "z": 5,
            "elements": [
                "darkutils:slime_dyed@0"
            ]
        },
        {
            "x": 3,
            "y": 24,
            "z": 4,
            "elements": [
                "jaopca:block.polytetrafluoroethene@0"
            ]
        },
        {
            "x": 3,
            "y": 23,
            "z": 3,
            "elements": [
                "nuclearcraft:material_block@0"
            ]
        },
        {
            "x": -3,
            "y": 3,
            "z": 7,
            "elements": [
                "nuclearcraft:material_block@0"
            ]
        },
        {
            "x": 0,
            "y": 16,
            "z": 4,
            "elements": [
                "thermalfoundation:glass_alloy@1"
            ]
        },
        {
            "x": -2,
            "y": 10,
            "z": 5,
            "elements": [
                "thermalfoundation:glass_alloy@1"
            ]
        },
        {
            "x": -2,
            "y": 3,
            "z": 5,
            "elements": [
                "thermalfoundation:glass_alloy@1"
            ]
        },
        {
            "x": 3,
            "y": 0,
            "z": 0,
            "elements": [
                "erebus:slab_amber_bricks@1"
            ]
        },
        {
            "x": 0,
            "y": 18,
            "z": 4,
            "elements": [
                "thermalfoundation:glass_alloy@1"
            ]
        },
        {
            "x": 0,
            "y": 25,
            "z": 3,
            "elements": [
                "jaopca:block.porpezite@0"
            ]
        },
        {
            "x": -2,
            "y": 6,
            "z": 5,
            "elements": [
                "thermalfoundation:glass_alloy@1"
            ]
        },
        {
            "x": 3,
            "y": 20,
            "z": 3,
            "elements": [
                "nuclearcraft:material_block@0"
            ]
        },
        {
            "x": 3,
            "y": 25,
            "z": 4,
            "elements": [
                "nuclearcraft:material_block@0"
            ]
        },
        {
            "x": -2,
            "y": 0,
            "z": 6,
            "elements": [
                "casings_all"
            ]
        },
        {
            "x": 1,
            "y": 4,
            "z": 5,
            "elements": [
                "darkutils:slime_dyed@0"
            ]
        },
        {
            "x": 2,
            "y": 0,
            "z": 1,
            "elements": [
                "chisel:factory@12"
            ]
        },
        {
            "x": -3,
            "y": 4,
            "z": 7,
            "elements": [
                "nuclearcraft:material_block@0"
            ]
        },
        {
            "x": 2,
            "y": 13,
            "z": 4,
            "elements": [
                "nuclearcraft:ingot_block@10"
            ]
        },
        {
            "x": 0,
            "y": 0,
            "z": 7,
            "elements": [
                "casings_upgrade"
            ]
        },
        {
            "x": 0,
            "y": 17,
            "z": 4,
            "elements": [
                "thermalfoundation:glass_alloy@1"
            ]
        },
        {
            "x": -3,
            "y": 2,
            "z": 7,
            "elements": [
                "nuclearcraft:material_block@0"
            ]
        },
        {
            "x": -3,
            "y": 5,
            "z": 7,
            "elements": [
                "nuclearcraft:material_block@0"
            ]
        },
        {
            "x": 1,
            "y": 3,
            "z": 5,
            "elements": [
                "darkutils:slime_dyed@0"
            ]
        },
        {
            "x": -2,
            "y": 5,
            "z": 5,
            "elements": [
                "thermalfoundation:glass_alloy@1"
            ]
        },
        {
            "x": 3,
            "y": 21,
            "z": 3,
            "elements": [
                "nuclearcraft:material_block@0"
            ]
        },
        {
            "x": 2,
            "y": 14,
            "z": 4,
            "elements": [
                "nuclearcraft:ingot_block@10"
            ]
        },
        {
            "x": -2,
            "y": 1,
            "z": 6,
            "elements": [
                "nuclearcraft:ingot_block@10"
            ]
        },
        {
            "x": -1,
            "y": 18,
            "z": 4,
            "elements": [
                "thermalfoundation:glass_alloy@1"
            ]
        }
    ]}