{
    "registryname": "ion_exchange_column",
    "localizedname": "§bLV5 - 大型离子交换柱",
    "requires-blueprint": false,
    "failure-action": "still",
    "color": "738c88",
    "parts": [
        {
            "x": 0,
            "y": 0,
            "z": 0,
            "elements": [
                "modularmachinery:blockcontroller@2"
            ]
        },
        {
            "x": -3,
            "y": 0,
            "z": 5,
            "elements": [
                "chisel:factory@12"
            ]
        },
        {
            "x": 1,
            "y": 0,
            "z": 0,
            "elements": [
                "chisel:factory@12"
            ]
        },
        {
            "x": -2,
            "y": 0,
            "z": 5,
            "elements": [
                "modularmachinery:blockcasing@4"
            ]
        },
        {
            "x": 2,
            "y": 0,
            "z": 0,
            "elements": [
                "chisel:factory@12"
            ]
        },
        {
            "x": 1,
            "y": 0,
            "z": 6,
            "elements": [
                "casings_all"
            ]
        },
        {
            "x": -1,
            "y": 0,
            "z": 0,
            "elements": [
                "chisel:factory@12"
            ]
        },
        {
            "x": 0,
            "y": 0,
            "z": 5,
            "elements": [
                "modularmachinery:blockcasing@4"
            ]
        },
        {
            "x": 3,
            "y": 0,
            "z": 3,
            "elements": [
                "chisel:factory@12"
            ]
        },
        {
            "x": 3,
            "y": 0,
            "z": 4,
            "elements": [
                "chisel:factory@12"
            ]
        },
        {
            "x": -3,
            "y": 0,
            "z": 4,
            "elements": [
                "chisel:factory@12"
            ]
        },
        {
            "x": 2,
            "y": 0,
            "z": 5,
            "elements": [
                "modularmachinery:blockcasing@4"
            ]
        },
        {
            "x": 0,
            "y": 0,
            "z": 4,
            "elements": [
                "modularmachinery:blockcasing@4"
            ]
        },
        {
            "x": -2,
            "y": 0,
            "z": 0,
            "elements": [
                "chisel:factory@12"
            ]
        },
        {
            "x": -1,
            "y": 0,
            "z": 5,
            "elements": [
                "modularmachinery:blockcasing@4"
            ]
        },
        {
            "x": 3,
            "y": 0,
            "z": 7,
            "elements": [
                "chisel:factory@12"
            ]
        },
        {
            "x": -1,
            "y": 0,
            "z": 4,
            "elements": [
                "modularmachinery:blockcasing@4"
            ]
        },
        {
            "x": 2,
            "y": 0,
            "z": 2,
            "elements": [
                "chisel:factory@12"
            ]
        },
        {
            "x": 1,
            "y": 0,
            "z": 3,
            "elements": [
                "chisel:factory@12"
            ]
        },
        {
            "x": 3,
            "y": 0,
            "z": 5,
            "elements": [
                "chisel:factory@12"
            ]
        },
        {
            "x": -2,
            "y": 0,
            "z": 4,
            "elements": [
                "casings_all"
            ]
        },
        {
            "x": 0,
            "y": 0,
            "z": 3,
            "elements": [
                "casings_parallel"
            ]
        },
        {
            "x": -3,
            "y": 0,
            "z": 3,
            "elements": [
                "chisel:factory@12"
            ]
        },
        {
            "x": 1,
            "y": 0,
            "z": 4,
            "elements": [
                "modularmachinery:blockcasing@4"
            ]
        },
        {
            "x": -2,
            "y": 0,
            "z": 3,
            "elements": [
                "chisel:factory@12"
            ]
        },
        {
            "x": -1,
            "y": 0,
            "z": 3,
            "elements": [
                "chisel:factory@12"
            ]
        },
        {
            "x": 2,
            "y": 0,
            "z": 4,
            "elements": [
                "casings_all"
            ]
        },
        {
            "x": 2,
            "y": 0,
            "z": 7,
            "elements": [
                "chisel:factory@12"
            ]
        },
        {
            "x": 3,
            "y": 0,
            "z": 2,
            "elements": [
                "chisel:factory@12"
            ]
        },
        {
            "x": -1,
            "y": 0,
            "z": 7,
            "elements": [
                "chisel:factory@12"
            ]
        },
        {
            "x": 2,
            "y": 0,
            "z": 3,
            "elements": [
                "chisel:factory@12"
            ]
        },
        {
            "x": 0,
            "y": 0,
            "z": 2,
            "elements": [
                "modularmachinery:blockcasing@4"
            ]
        },
        {
            "x": -3,
            "y": 0,
            "z": 2,
            "elements": [
                "chisel:factory@12"
            ]
        },
        {
            "x": 2,
            "y": 0,
            "z": 6,
            "elements": [
                "casings_all"
            ]
        },
        {
            "x": -2,
            "y": 0,
            "z": 2,
            "elements": [
                "chisel:factory@12"
            ]
        },
        {
            "x": 1,
            "y": 0,
            "z": 1,
            "elements": [
                "modularmachinery:blockcasing@4"
            ]
        },
        {
            "x": -1,
            "y": 0,
            "z": 2,
            "elements": [
                "modularmachinery:blockcasing@4"
            ]
        },
        {
            "x": 1,
            "y": 0,
            "z": 2,
            "elements": [
                "modularmachinery:blockcasing@4"
            ]
        },
        {
            "x": -3,
            "y": 0,
            "z": 1,
            "elements": [
                "chisel:factory@12"
            ]
        },
        {
            "x": 3,
            "y": 0,
            "z": 6,
            "elements": [
                "chisel:factory@12"
            ]
        },
        {
            "x": 1,
            "y": 0,
            "z": 7,
            "elements": [
                "chisel:factory@12"
            ]
        },
        {
            "x": 2,
            "y": 0,
            "z": -1,
            "elements": [
                "erebus:slab_amber_bricks@1"
            ]
        },
        {
            "x": 0,
            "y": 0,
            "z": 6,
            "elements": [
                "casings_all"
            ]
        },
        {
            "x": 0,
            "y": 0,
            "z": 1,
            "elements": [
                "modularmachinery:blockcasing@4"
            ]
        },
        {
            "x": -1,
            "y": 0,
            "z": 1,
            "elements": [
                "modularmachinery:blockcasing@4"
            ]
        },
        {
            "x": 0,
            "y": 0,
            "z": -1,
            "elements": [
                "erebus:slab_amber_bricks@1"
            ]
        },
        {
            "x": -2,
            "y": 0,
            "z": 1,
            "elements": [
                "chisel:factory@12"
            ]
        },
        {
            "x": -1,
            "y": 0,
            "z": -1,
            "elements": [
                "erebus:slab_amber_bricks@1"
            ]
        },
        {
            "x": 1,
            "y": 0,
            "z": 5,
            "elements": [
                "modularmachinery:blockcasing@4"
            ]
        },
        {
            "x": -1,
            "y": 0,
            "z": 6,
            "elements": [
                "casings_all"
            ]
        },
        {
            "x": -3,
            "y": 0,
            "z": 7,
            "elements": [
                "chisel:factory@12"
            ]
        },
        {
            "x": -2,
            "y": 0,
            "z": -1,
            "elements": [
                "erebus:slab_amber_bricks@1"
            ]
        },
        {
            "x": -3,
            "y": 0,
            "z": 0,
            "elements": [
                "erebus:slab_amber_bricks@1"
            ]
        },
        {
            "x": -2,
            "y": 0,
            "z": 7,
            "elements": [
                "chisel:factory@12"
            ]
        },
        {
            "x": 1,
            "y": 0,
            "z": -1,
            "elements": [
                "erebus:slab_amber_bricks@1"
            ]
        },
        {
            "x": -3,
            "y": 0,
            "z": 6,
            "elements": [
                "chisel:factory@12"
            ]
        },
        {
            "x": 3,
            "y": 0,
            "z": 1,
            "elements": [
                "chisel:factory@12"
            ]
        },
        {
            "x": 3,
            "y": 0,
            "z": 0,
            "elements": [
                "erebus:slab_amber_bricks@1"
            ]
        },
        {
            "x": -2,
            "y": 0,
            "z": 6,
            "elements": [
                "casings_all"
            ]
        },
        {
            "x": 2,
            "y": 0,
            "z": 1,
            "elements": [
                "chisel:factory@12"
            ]
        },
        {
            "x": 0,
            "y": 0,
            "z": 7,
            "elements": [
                "casings_upgrade"
            ]
        }
    ],
    "dynamic-patterns": [
        {
            "name": "column",
            "faces": [
                "up"
            ],
            "minSize": 5,
            "maxSize": 200,
            "structure-size-offset-start": {
                "x": 0,
                "y": 1,
                "z": 0
            },
            "structure-size-offset": {
                "x": 0,
                "y": 1,
                "z": 0
            },
            "parts": [
                {
                    "x": -2,
                    "y": 0,
                    "z": 5,
                    "elements": [
                        "thermalfoundation:glass_alloy@1"
                    ]
                },
                {
                    "x": 3,
                    "y": 0,
                    "z": 3,
                    "elements": [
                        "nuclearcraft:material_block@0"
                    ]
                },
                {
                    "x": 1,
                    "y": 0,
                    "z": 6,
                    "elements": [
                        "thermalfoundation:glass_alloy@1"
                    ]
                },
                {
                    "x": 0,
                    "y": 0,
                    "z": 5,
                    "elements": [
                        "darkutils:slime_dyed@0"
                    ]
                },
                {
                    "x": 0,
                    "y": 0,
                    "z": 4,
                    "elements": [
                        "thermalfoundation:glass_alloy@1"
                    ]
                },
                {
                    "x": 2,
                    "y": 0,
                    "z": 5,
                    "elements": [
                        "thermalfoundation:glass_alloy@1"
                    ]
                },
                {
                    "x": -1,
                    "y": 0,
                    "z": 5,
                    "elements": [
                        "darkutils:slime_dyed@0"
                    ]
                },
                {
                    "x": 3,
                    "y": 0,
                    "z": 7,
                    "elements": [
                        "nuclearcraft:material_block@0"
                    ]
                },
                {
                    "x": -1,
                    "y": 0,
                    "z": 4,
                    "elements": [
                        "thermalfoundation:glass_alloy@1"
                    ]
                },
                {
                    "x": -2,
                    "y": 0,
                    "z": 4,
                    "elements": [
                        "nuclearcraft:ingot_block@10"
                    ]
                },
                {
                    "x": -3,
                    "y": 0,
                    "z": 3,
                    "elements": [
                        "nuclearcraft:material_block@0"
                    ]
                },
                {
                    "x": 2,
                    "y": 0,
                    "z": 4,
                    "elements": [
                        "nuclearcraft:ingot_block@10"
                    ]
                },
                {
                    "x": 1,
                    "y": 0,
                    "z": 4,
                    "elements": [
                        "thermalfoundation:glass_alloy@1"
                    ]
                },
                {
                    "x": 2,
                    "y": 0,
                    "z": 6,
                    "elements": [
                        "nuclearcraft:ingot_block@10"
                    ]
                },
                {
                    "x": 0,
                    "y": 0,
                    "z": 6,
                    "elements": [
                        "casings_all"
                    ]
                },
                {
                    "x": -3,
                    "y": 0,
                    "z": 7,
                    "elements": [
                        "nuclearcraft:material_block@0"
                    ]
                },
                {
                    "x": 1,
                    "y": 0,
                    "z": 5,
                    "elements": [
                        "darkutils:slime_dyed@0"
                    ]
                },
                {
                    "x": -1,
                    "y": 0,
                    "z": 6,
                    "elements": [
                        "thermalfoundation:glass_alloy@1"
                    ]
                },
                {
                    "x": -2,
                    "y": 0,
                    "z": 6,
                    "elements": [
                        "nuclearcraft:ingot_block@10"
                    ]
                }
            ],
            "parts-end": [
                {
                    "x": -3,
                    "y": 2,
                    "z": 6,
                    "elements": [
                        "nuclearcraft:material_block@0"
                    ]
                },
                {
                    "x": -3,
                    "y": 1,
                    "z": 6,
                    "elements": [
                        "jaopca:block.polytetrafluoroethene@0"
                    ]
                },
                {
                    "x": 3,
                    "y": 2,
                    "z": 6,
                    "elements": [
                        "nuclearcraft:material_block@0"
                    ]
                },
                {
                    "x": 3,
                    "y": 1,
                    "z": 6,
                    "elements": [
                        "jaopca:block.polytetrafluoroethene@0"
                    ]
                },
                {
                    "x": 2,
                    "y": 2,
                    "z": 4,
                    "elements": [
                        "nuclearcraft:ingot_block@10"
                    ]
                },
                {
                    "x": -1,
                    "y": 4,
                    "z": 4,
                    "elements": [
                        "erebus:slab_amber_bricks@1"
                    ]
                },
                {
                    "x": -3,
                    "y": 0,
                    "z": 3,
                    "elements": [
                        "nuclearcraft:material_block@0"
                    ]
                },
                {
                    "x": 2,
                    "y": 3,
                    "z": 4,
                    "elements": [
                        "nuclearcraft:ingot_block@10"
                    ]
                },
                {
                    "x": 2,
                    "y": 0,
                    "z": 4,
                    "elements": [
                        "nuclearcraft:ingot_block@10"
                    ]
                },
                {
                    "x": 2,
                    "y": 1,
                    "z": 4,
                    "elements": [
                        "nuclearcraft:ingot_block@10"
                    ]
                },
                {
                    "x": 2,
                    "y": 1,
                    "z": 7,
                    "elements": [
                        "jaopca:block.polytetrafluoroethene@0"
                    ]
                },
                {
                    "x": 2,
                    "y": 0,
                    "z": 6,
                    "elements": [
                        "nuclearcraft:ingot_block@10"
                    ]
                },
                {
                    "x": 2,
                    "y": 2,
                    "z": 7,
                    "elements": [
                        "nuclearcraft:material_block@0"
                    ]
                },
                {
                    "x": 2,
                    "y": 1,
                    "z": 6,
                    "elements": [
                        "nuclearcraft:ingot_block@10"
                    ]
                },
                {
                    "x": 3,
                    "y": 1,
                    "z": 7,
                    "elements": [
                        "nuclearcraft:material_block@0"
                    ]
                },
                {
                    "x": 2,
                    "y": 2,
                    "z": 6,
                    "elements": [
                        "nuclearcraft:ingot_block@10"
                    ]
                },
                {
                    "x": 3,
                    "y": 0,
                    "z": 7,
                    "elements": [
                        "nuclearcraft:material_block@0"
                    ]
                },
                {
                    "x": -1,
                    "y": 4,
                    "z": 6,
                    "elements": [
                        "erebus:slab_amber_bricks@1"
                    ]
                },
                {
                    "x": 2,
                    "y": 3,
                    "z": 6,
                    "elements": [
                        "nuclearcraft:ingot_block@10"
                    ]
                },
                {
                    "x": -2,
                    "y": 0,
                    "z": 6,
                    "elements": [
                        "nuclearcraft:ingot_block@10"
                    ]
                },
                {
                    "x": -2,
                    "y": 2,
                    "z": 7,
                    "elements": [
                        "nuclearcraft:material_block@0"
                    ]
                },
                {
                    "x": 1,
                    "y": 2,
                    "z": 6,
                    "elements": [
                        "thermalfoundation:glass_alloy@1"
                    ]
                },
                {
                    "x": 0,
                    "y": 0,
                    "z": 7,
                    "elements": [
                        "jaopca:block.breedum@0"
                    ]
                },
                {
                    "x": 0,
                    "y": 4,
                    "z": 6,
                    "elements": [
                        "erebus:slab_amber_bricks@1"
                    ]
                },
                {
                    "x": -2,
                    "y": 1,
                    "z": 6,
                    "elements": [
                        "nuclearcraft:ingot_block@10"
                    ]
                },
                {
                    "x": 1,
                    "y": 3,
                    "z": 6,
                    "elements": [
                        "nuclearcraft:ingot_block@10"
                    ]
                },
                {
                    "x": -1,
                    "y": 0,
                    "z": 7,
                    "elements": [
                        "jaopca:block.breedum@0"
                    ]
                },
                {
                    "x": 1,
                    "y": 0,
                    "z": 6,
                    "elements": [
                        "thermalfoundation:glass_alloy@1"
                    ]
                },
                {
                    "x": -2,
                    "y": 2,
                    "z": 6,
                    "elements": [
                        "nuclearcraft:ingot_block@10"
                    ]
                },
                {
                    "x": -1,
                    "y": 2,
                    "z": 7,
                    "elements": [
                        "jaopca:block.porpezite@0"
                    ]
                },
                {
                    "x": 1,
                    "y": 1,
                    "z": 6,
                    "elements": [
                        "thermalfoundation:glass_alloy@1"
                    ]
                },
                {
                    "x": -2,
                    "y": 3,
                    "z": 6,
                    "elements": [
                        "nuclearcraft:ingot_block@10"
                    ]
                },
                {
                    "x": 0,
                    "y": 0,
                    "z": 6,
                    "elements": [
                        "thermalfoundation:glass_alloy@1"
                    ]
                },
                {
                    "x": -1,
                    "y": 2,
                    "z": 6,
                    "elements": [
                        "thermalfoundation:glass_alloy@1"
                    ]
                },
                {
                    "x": 0,
                    "y": 2,
                    "z": 7,
                    "elements": [
                        "jaopca:block.porpezite@0"
                    ]
                },
                {
                    "x": 0,
                    "y": 1,
                    "z": 6,
                    "elements": [
                        "thermalfoundation:glass_alloy@1"
                    ]
                },
                {
                    "x": -1,
                    "y": 3,
                    "z": 6,
                    "elements": [
                        "nuclearcraft:ingot_block@10"
                    ]
                },
                {
                    "x": -3,
                    "y": 1,
                    "z": 7,
                    "elements": [
                        "nuclearcraft:material_block@0"
                    ]
                },
                {
                    "x": -1,
                    "y": 0,
                    "z": 6,
                    "elements": [
                        "thermalfoundation:glass_alloy@1"
                    ]
                },
                {
                    "x": -3,
                    "y": 0,
                    "z": 7,
                    "elements": [
                        "nuclearcraft:material_block@0"
                    ]
                },
                {
                    "x": 0,
                    "y": 2,
                    "z": 6,
                    "elements": [
                        "thermalfoundation:glass_alloy@1"
                    ]
                },
                {
                    "x": -1,
                    "y": 1,
                    "z": 6,
                    "elements": [
                        "thermalfoundation:glass_alloy@1"
                    ]
                },
                {
                    "x": 0,
                    "y": 3,
                    "z": 6,
                    "elements": [
                        "nuclearcraft:ingot_block@10"
                    ]
                },
                {
                    "x": 0,
                    "y": 0,
                    "z": 5,
                    "elements": [
                        "darkutils:slime_dyed@0"
                    ]
                },
                {
                    "x": 1,
                    "y": 2,
                    "z": 3,
                    "elements": [
                        "jaopca:block.porpezite@0"
                    ]
                },
                {
                    "x": -1,
                    "y": 3,
                    "z": 5,
                    "elements": [
                        "darkutils:slime_dyed@0"
                    ]
                },
                {
                    "x": -2,
                    "y": 1,
                    "z": 3,
                    "elements": [
                        "jaopca:block.polytetrafluoroethene@0"
                    ]
                },
                {
                    "x": 0,
                    "y": 1,
                    "z": 5,
                    "elements": [
                        "darkutils:slime_dyed@0"
                    ]
                },
                {
                    "x": -1,
                    "y": 2,
                    "z": 5,
                    "elements": [
                        "darkutils:slime_dyed@0"
                    ]
                },
                {
                    "x": -2,
                    "y": 2,
                    "z": 3,
                    "elements": [
                        "nuclearcraft:material_block@0"
                    ]
                },
                {
                    "x": 1,
                    "y": 0,
                    "z": 3,
                    "elements": [
                        "jaopca:block.breedum@0"
                    ]
                },
                {
                    "x": -1,
                    "y": 0,
                    "z": 5,
                    "elements": [
                        "darkutils:slime_dyed@0"
                    ]
                },
                {
                    "x": 0,
                    "y": 3,
                    "z": 5,
                    "elements": [
                        "darkutils:slime_dyed@0"
                    ]
                },
                {
                    "x": -1,
                    "y": 1,
                    "z": 5,
                    "elements": [
                        "darkutils:slime_dyed@0"
                    ]
                },
                {
                    "x": 0,
                    "y": 2,
                    "z": 5,
                    "elements": [
                        "darkutils:slime_dyed@0"
                    ]
                },
                {
                    "x": -3,
                    "y": 2,
                    "z": 5,
                    "elements": [
                        "jaopca:block.porpezite@0"
                    ]
                },
                {
                    "x": 2,
                    "y": 0,
                    "z": 5,
                    "elements": [
                        "thermalfoundation:glass_alloy@1"
                    ]
                },
                {
                    "x": 2,
                    "y": 1,
                    "z": 5,
                    "elements": [
                        "thermalfoundation:glass_alloy@1"
                    ]
                },
                {
                    "x": 1,
                    "y": 4,
                    "z": 6,
                    "elements": [
                        "erebus:slab_amber_bricks@1"
                    ]
                },
                {
                    "x": -3,
                    "y": 0,
                    "z": 5,
                    "elements": [
                        "jaopca:block.breedum@0"
                    ]
                },
                {
                    "x": 2,
                    "y": 3,
                    "z": 5,
                    "elements": [
                        "nuclearcraft:ingot_block@10"
                    ]
                },
                {
                    "x": 1,
                    "y": 0,
                    "z": 7,
                    "elements": [
                        "jaopca:block.breedum@0"
                    ]
                },
                {
                    "x": 1,
                    "y": 2,
                    "z": 7,
                    "elements": [
                        "jaopca:block.porpezite@0"
                    ]
                },
                {
                    "x": -1,
                    "y": 4,
                    "z": 5,
                    "elements": [
                        "erebus:slab_amber_bricks@1"
                    ]
                },
                {
                    "x": 2,
                    "y": 2,
                    "z": 5,
                    "elements": [
                        "thermalfoundation:glass_alloy@1"
                    ]
                },
                {
                    "x": -2,
                    "y": 1,
                    "z": 7,
                    "elements": [
                        "jaopca:block.polytetrafluoroethene@0"
                    ]
                },
                {
                    "x": 1,
                    "y": 4,
                    "z": 5,
                    "elements": [
                        "erebus:slab_amber_bricks@1"
                    ]
                },
                {
                    "x": 1,
                    "y": 3,
                    "z": 5,
                    "elements": [
                        "darkutils:slime_dyed@0"
                    ]
                },
                {
                    "x": -2,
                    "y": 0,
                    "z": 5,
                    "elements": [
                        "thermalfoundation:glass_alloy@1"
                    ]
                },
                {
                    "x": -2,
                    "y": 1,
                    "z": 5,
                    "elements": [
                        "thermalfoundation:glass_alloy@1"
                    ]
                },
                {
                    "x": 1,
                    "y": 2,
                    "z": 5,
                    "elements": [
                        "darkutils:slime_dyed@0"
                    ]
                },
                {
                    "x": -2,
                    "y": 2,
                    "z": 5,
                    "elements": [
                        "thermalfoundation:glass_alloy@1"
                    ]
                },
                {
                    "x": -2,
                    "y": 3,
                    "z": 5,
                    "elements": [
                        "nuclearcraft:ingot_block@10"
                    ]
                },
                {
                    "x": 1,
                    "y": 0,
                    "z": 5,
                    "elements": [
                        "darkutils:slime_dyed@0"
                    ]
                },
                {
                    "x": 1,
                    "y": 1,
                    "z": 5,
                    "elements": [
                        "darkutils:slime_dyed@0"
                    ]
                },
                {
                    "x": -2,
                    "y": 2,
                    "z": 4,
                    "elements": [
                        "nuclearcraft:ingot_block@10"
                    ]
                },
                {
                    "x": 1,
                    "y": 0,
                    "z": 4,
                    "elements": [
                        "thermalfoundation:glass_alloy@1"
                    ]
                },
                {
                    "x": 1,
                    "y": 1,
                    "z": 4,
                    "elements": [
                        "thermalfoundation:glass_alloy@1"
                    ]
                },
                {
                    "x": -2,
                    "y": 3,
                    "z": 4,
                    "elements": [
                        "nuclearcraft:ingot_block@10"
                    ]
                },
                {
                    "x": -2,
                    "y": 0,
                    "z": 4,
                    "elements": [
                        "nuclearcraft:ingot_block@10"
                    ]
                },
                {
                    "x": 1,
                    "y": 2,
                    "z": 4,
                    "elements": [
                        "thermalfoundation:glass_alloy@1"
                    ]
                },
                {
                    "x": 0,
                    "y": 4,
                    "z": 4,
                    "elements": [
                        "erebus:slab_amber_bricks@1"
                    ]
                },
                {
                    "x": -2,
                    "y": 1,
                    "z": 4,
                    "elements": [
                        "nuclearcraft:ingot_block@10"
                    ]
                },
                {
                    "x": 1,
                    "y": 3,
                    "z": 4,
                    "elements": [
                        "nuclearcraft:ingot_block@10"
                    ]
                },
                {
                    "x": -1,
                    "y": 0,
                    "z": 4,
                    "elements": [
                        "thermalfoundation:glass_alloy@1"
                    ]
                },
                {
                    "x": 0,
                    "y": 2,
                    "z": 4,
                    "elements": [
                        "thermalfoundation:glass_alloy@1"
                    ]
                },
                {
                    "x": 3,
                    "y": 1,
                    "z": 3,
                    "elements": [
                        "nuclearcraft:material_block@0"
                    ]
                },
                {
                    "x": -1,
                    "y": 1,
                    "z": 4,
                    "elements": [
                        "thermalfoundation:glass_alloy@1"
                    ]
                },
                {
                    "x": 0,
                    "y": 3,
                    "z": 4,
                    "elements": [
                        "nuclearcraft:ingot_block@10"
                    ]
                },
                {
                    "x": -1,
                    "y": 0,
                    "z": 3,
                    "elements": [
                        "jaopca:block.breedum@0"
                    ]
                },
                {
                    "x": 0,
                    "y": 0,
                    "z": 4,
                    "elements": [
                        "thermalfoundation:glass_alloy@1"
                    ]
                },
                {
                    "x": -1,
                    "y": 2,
                    "z": 4,
                    "elements": [
                        "thermalfoundation:glass_alloy@1"
                    ]
                },
                {
                    "x": -3,
                    "y": 1,
                    "z": 3,
                    "elements": [
                        "nuclearcraft:material_block@0"
                    ]
                },
                {
                    "x": 0,
                    "y": 1,
                    "z": 4,
                    "elements": [
                        "thermalfoundation:glass_alloy@1"
                    ]
                },
                {
                    "x": -1,
                    "y": 3,
                    "z": 4,
                    "elements": [
                        "nuclearcraft:ingot_block@10"
                    ]
                },
                {
                    "x": 2,
                    "y": 1,
                    "z": 3,
                    "elements": [
                        "jaopca:block.polytetrafluoroethene@0"
                    ]
                },
                {
                    "x": -3,
                    "y": 1,
                    "z": 4,
                    "elements": [
                        "jaopca:block.polytetrafluoroethene@0"
                    ]
                },
                {
                    "x": 3,
                    "y": 2,
                    "z": 5,
                    "elements": [
                        "jaopca:block.porpezite@0"
                    ]
                },
                {
                    "x": 2,
                    "y": 2,
                    "z": 3,
                    "elements": [
                        "nuclearcraft:material_block@0"
                    ]
                },
                {
                    "x": 3,
                    "y": 0,
                    "z": 5,
                    "elements": [
                        "jaopca:block.breedum@0"
                    ]
                },
                {
                    "x": -3,
                    "y": 2,
                    "z": 4,
                    "elements": [
                        "nuclearcraft:material_block@0"
                    ]
                },
                {
                    "x": -1,
                    "y": 2,
                    "z": 3,
                    "elements": [
                        "jaopca:block.porpezite@0"
                    ]
                },
                {
                    "x": 0,
                    "y": 0,
                    "z": 3,
                    "elements": [
                        "jaopca:block.breedum@0"
                    ]
                },
                {
                    "x": 1,
                    "y": 4,
                    "z": 4,
                    "elements": [
                        "erebus:slab_amber_bricks@1"
                    ]
                },
                {
                    "x": 0,
                    "y": 4,
                    "z": 5,
                    "elements": [
                        "additions:finallium_block@0"
                    ]
                },
                {
                    "x": 3,
                    "y": 1,
                    "z": 4,
                    "elements": [
                        "jaopca:block.polytetrafluoroethene@0"
                    ]
                },
                {
                    "x": 3,
                    "y": 0,
                    "z": 3,
                    "elements": [
                        "nuclearcraft:material_block@0"
                    ]
                },
                {
                    "x": 0,
                    "y": 2,
                    "z": 3,
                    "elements": [
                        "jaopca:block.porpezite@0"
                    ]
                },
                {
                    "x": 3,
                    "y": 2,
                    "z": 4,
                    "elements": [
                        "nuclearcraft:material_block@0"
                    ]
                }
            ]
        }
    ]
}
