{
    "registryname": "radiation_cleaner",
    "localizedname": "§bLV5 - 辐射清洁器",
    "requires-blueprint": false,
    "failure-action": "still",
    "color": "B48648",
    "modifiers": [
        {
            "elements": "modularmachinery:blockcasing@1",
            "x": 0,
            "y": 1,
            "z": 0,
            "description": "将控制器上方紧挨着的方块换成此方块以降低配方制作时间至75%！",
            "modifier": {
                "io": "input",
                "target": "modularmachinery:duration",
                "operation": 1,
                "multiplier": 0.75
            }
        },
        {
            "elements": "modularmachinery:blockcasing@2",
            "x": 0,
            "y": 1,
            "z": 0,
            "description": "将控制器上方紧挨着的方块换成此方块以降低配方制作时间至56%！",
            "modifier": {
                "io": "input",
                "target": "modularmachinery:duration",
                "operation": 1,
                "multiplier": 0.56
            }
        },
        {
            "elements": "modularmachinery:blockcasing@3",
            "x": 0,
            "y": 1,
            "z": 0,
            "description": "将控制器上方紧挨着的方块换成此方块以降低配方制作时间至42%！",
            "modifier": {
                "io": "input",
                "target": "modularmachinery:duration",
                "operation": 1,
                "multiplier": 0.42
            }
        },
        {
            "elements": "modularmachinery:blockcasing@5",
            "x": 0,
            "y": 1,
            "z": 0,
            "description": "将控制器上方紧挨着的方块换成此方块以降低配方制作时间至32%！",
            "modifier": {
                "io": "input",
                "target": "modularmachinery:duration",
                "operation": 1,
                "multiplier": 0.32
            }
        },
        {
            "elements": "mmce_complement:blockcasing@0",
            "x": 0,
            "y": 1,
            "z": 0,
            "description": "将控制器上方紧挨着的方块换成此方块以降低配方制作时间至24%！",
            "modifier": {
                "io": "input",
                "target": "modularmachinery:duration",
                "operation": 1,
                "multiplier": 0.24
            }
        },
        {
            "elements": "mmce_complement:blockcasing@1",
            "x": 0,
            "y": 1,
            "z": 0,
            "description": "将控制器上方紧挨着的方块换成此方块以降低配方制作时间至18%！",
            "modifier": {
                "io": "input",
                "target": "modularmachinery:duration",
                "operation": 1,
                "multiplier": 0.18
            }
        },
        {
            "elements": "mmce_complement:blockcasing@2",
            "x": 0,
            "y": 1,
            "z": 0,
            "description": "将控制器上方紧挨着的方块换成此方块以降低配方制作时间至13%！",
            "modifier": {
                "io": "input",
                "target": "modularmachinery:duration",
                "operation": 1,
                "multiplier": 0.13
            }
        },
        {
            "elements": "mmce_complement:blockcasing@3",
            "x": 0,
            "y": 1,
            "z": 0,
            "description": "将控制器上方紧挨着的方块换成此方块以降低配方制作时间至10%！",
            "modifier": {
                "io": "input",
                "target": "modularmachinery:duration",
                "operation": 1,
                "multiplier": 0.10
            }
        },
        {
            "elements": "mmce_complement:blockcasing@4",
            "x": 0,
            "y": 1,
            "z": 0,
            "description": "将控制器上方紧挨着的方块换成此方块以降低配方制作时间至8%！",
            "modifier": {
                "io": "input",
                "target": "modularmachinery:duration",
                "operation": 1,
                "multiplier": 0.08
            }
        },
        {
            "elements": "mmce_complement:blockcasing@5",
            "x": 0,
            "y": 1,
            "z": 0,
            "description": "将控制器上方紧挨着的方块换成此方块以降低配方制作时间至6%！",
            "modifier": {
                "io": "input",
                "target": "modularmachinery:duration",
                "operation": 1,
                "multiplier": 0.06
            }
        }
    ],
    "parts": [
        {
            "x": 0,
            "y": 0,
            "z": 0,
            "elements": [
                "modularmachinery:blockcontroller@2"
            ]
        },
        {
            "x": -1,
            "y": 10,
            "z": 1,
            "elements": [
                "minecraft:sponge@0"
            ]
        },
        {
            "x": 0,
            "y": 11,
            "z": 4,
            "elements": [
                "nuclearcraft:machine_frame@0"
            ]
        },
        {
            "x": -2,
            "y": 10,
            "z": 2,
            "elements": [
                "nuclearcraft:machine_frame@0"
            ]
        },
        {
            "x": -1,
            "y": 2,
            "z": 0,
            "elements": [
                "nuclearcraft:machine_glass@0"
            ]
        },
        {
            "x": 0,
            "y": 5,
            "z": 2,
            "elements": [
                "nuclearcraft:ingot_block@8"
            ]
        },
        {
            "x": 2,
            "y": 7,
            "z": -1,
            "elements": [
                "abyssalcraft:abyssalsandglass@0"
            ]
        },
        {
            "x": 0,
            "y": 6,
            "z": 2,
            "elements": [
                "nuclearcraft:fertile_isotope@0"
            ]
        },
        {
            "x": 0,
            "y": 10,
            "z": 4,
            "elements": [
                "nuclearcraft:machine_frame@0"
            ]
        },
        {
            "x": -2,
            "y": 12,
            "z": 1,
            "elements": [
                "nuclearcraft:machine_frame@0"
            ]
        },
        {
            "x": 2,
            "y": 6,
            "z": -1,
            "elements": [
                "abyssalcraft:abyssalsandglass@0"
            ]
        },
        {
            "x": 0,
            "y": 9,
            "z": 3,
            "elements": [
                "jaopca:block.heavyalloy@0"
            ]
        },
        {
            "x": 0,
            "y": 12,
            "z": 4,
            "elements": [
                "nuclearcraft:machine_frame@0"
            ]
        },
        {
            "x": -1,
            "y": 1,
            "z": 0,
            "elements": [
                "nuclearcraft:machine_glass@0"
            ]
        },
        {
            "x": 1,
            "y": 8,
            "z": -1,
            "elements": [
                "abyssalcraft:abyssalsandglass@0"
            ]
        },
        {
            "x": -1,
            "y": 11,
            "z": 1,
            "elements": [
                "minecraft:sponge@0"
            ]
        },
        {
            "x": 0,
            "y": 4,
            "z": 2,
            "elements": [
                "nuclearcraft:ingot_block@8"
            ]
        },
        {
            "x": -2,
            "y": 11,
            "z": 2,
            "elements": [
                "nuclearcraft:machine_frame@0"
            ]
        },
        {
            "x": 0,
            "y": 11,
            "z": 3,
            "elements": [
                "jaopca:block.heavyalloy@0"
            ]
        },
        {
            "x": 0,
            "y": 10,
            "z": 3,
            "elements": [
                "jaopca:block.heavyalloy@0"
            ]
        },
        {
            "x": 0,
            "y": 9,
            "z": 4,
            "elements": [
                "nuclearcraft:machine_frame@0"
            ]
        },
        {
            "x": 0,
            "y": 7,
            "z": 2,
            "elements": [
                "nuclearcraft:ingot_block@8"
            ]
        },
        {
            "x": 1,
            "y": 0,
            "z": 0,
            "elements": [
                "casings_all"
            ]
        },
        {
            "x": 1,
            "y": 12,
            "z": 1,
            "elements": [
                "betternether:cincinnasite_slab_half@0"
            ]
        },
        {
            "x": -1,
            "y": 4,
            "z": 0,
            "elements": [
                "nuclearcraft:fertile_isotope@0"
            ]
        },
        {
            "x": 0,
            "y": 8,
            "z": 4,
            "elements": [
                "nuclearcraft:machine_glass@0"
            ]
        },
        {
            "x": 1,
            "y": 6,
            "z": 4,
            "elements": [
                "nuclearcraft:machine_glass@0"
            ]
        },
        {
            "x": -2,
            "y": 8,
            "z": 2,
            "elements": [
                "nuclearcraft:machine_glass@0"
            ]
        },
        {
            "x": 0,
            "y": 7,
            "z": 4,
            "elements": [
                "nuclearcraft:machine_glass@0"
            ]
        },
        {
            "x": 0,
            "y": 7,
            "z": 3,
            "elements": [
                "minecraft:sponge@0"
            ]
        },
        {
            "x": -1,
            "y": 9,
            "z": 1,
            "elements": [
                "minecraft:sponge@0"
            ]
        },
        {
            "x": -2,
            "y": 9,
            "z": 2,
            "elements": [
                "nuclearcraft:machine_frame@0"
            ]
        },
        {
            "x": -1,
            "y": 3,
            "z": 0,
            "elements": [
                "nuclearcraft:machine_glass@0"
            ]
        },
        {
            "x": 1,
            "y": 4,
            "z": 2,
            "elements": [
                "minecraft:sponge@0"
            ]
        },
        {
            "x": 2,
            "y": 5,
            "z": -1,
            "elements": [
                "abyssalcraft:abyssalsandglass@0"
            ]
        },
        {
            "x": 0,
            "y": 8,
            "z": 3,
            "elements": [
                "minecraft:sponge@0"
            ]
        },
        {
            "x": -2,
            "y": 7,
            "z": 0,
            "elements": [
                "nuclearcraft:fertile_isotope@0"
            ]
        },
        {
            "x": 0,
            "y": 6,
            "z": 3,
            "elements": [
                "nuclearcraft:fertile_isotope@0"
            ]
        },
        {
            "x": 1,
            "y": 2,
            "z": 0,
            "elements": [
                "nuclearcraft:machine_glass@0"
            ]
        },
        {
            "x": 1,
            "y": 10,
            "z": 1,
            "elements": [
                "minecraft:sponge@0"
            ]
        },
        {
            "x": 0,
            "y": 12,
            "z": 1,
            "elements": [
                "betternether:cincinnasite_slab_half@0"
            ]
        },
        {
            "x": 2,
            "y": 2,
            "z": 3,
            "elements": [
                "nuclearcraft:machine_glass@0"
            ]
        },
        {
            "x": -1,
            "y": 4,
            "z": 3,
            "elements": [
                "nuclearcraft:machine_glass@0"
            ]
        },
        {
            "x": 0,
            "y": 1,
            "z": 2,
            "elements": [
                "nuclearcraft:ingot_block@8"
            ]
        },
        {
            "x": 1,
            "y": 1,
            "z": 0,
            "elements": [
                "nuclearcraft:machine_glass@0"
            ]
        },
        {
            "x": 2,
            "y": 9,
            "z": 1,
            "elements": [
                "nuclearcraft:machine_glass@0"
            ]
        },
        {
            "x": 2,
            "y": 0,
            "z": 3,
            "elements": [
                "casings_all"
            ]
        },
        {
            "x": 0,
            "y": 5,
            "z": 3,
            "elements": [
                "minecraft:sponge@0"
            ]
        },
        {
            "x": 1,
            "y": 11,
            "z": 1,
            "elements": [
                "minecraft:sponge@0"
            ]
        },
        {
            "x": -1,
            "y": 3,
            "z": 3,
            "elements": [
                "minecraft:sponge@0"
            ]
        },
        {
            "x": 1,
            "y": 12,
            "z": 2,
            "elements": [
                "betternether:cincinnasite_slab_half@0"
            ]
        },
        {
            "x": 0,
            "y": 0,
            "z": 2,
            "elements": [
                "betternether:cincinnasite_slab_half@1"
            ]
        },
        {
            "x": -1,
            "y": 0,
            "z": 0,
            "elements": [
                "casings_all"
            ]
        },
        {
            "x": -1,
            "y": 11,
            "z": 4,
            "elements": [
                "nuclearcraft:machine_glass@0"
            ]
        },
        {
            "x": 2,
            "y": 1,
            "z": 3,
            "elements": [
                "nuclearcraft:machine_glass@0"
            ]
        },
        {
            "x": 1,
            "y": 8,
            "z": 1,
            "elements": [
                "nuclearcraft:machine_glass@0"
            ]
        },
        {
            "x": 0,
            "y": 3,
            "z": 2,
            "elements": [
                "nuclearcraft:ingot_block@8"
            ]
        },
        {
            "x": 2,
            "y": 10,
            "z": 1,
            "elements": [
                "nuclearcraft:machine_glass@0"
            ]
        },
        {
            "x": -1,
            "y": 6,
            "z": 3,
            "elements": [
                "nuclearcraft:machine_glass@0"
            ]
        },
        {
            "x": 0,
            "y": 4,
            "z": 3,
            "elements": [
                "minecraft:sponge@0"
            ]
        },
        {
            "x": 1,
            "y": 10,
            "z": 4,
            "elements": [
                "nuclearcraft:machine_glass@0"
            ]
        },
        {
            "x": -1,
            "y": 12,
            "z": 1,
            "elements": [
                "betternether:cincinnasite_slab_half@0"
            ]
        },
        {
            "x": 1,
            "y": 4,
            "z": 0,
            "elements": [
                "nuclearcraft:fertile_isotope@0"
            ]
        },
        {
            "x": -2,
            "y": 6,
            "z": 0,
            "elements": [
                "nuclearcraft:fertile_isotope@0"
            ]
        },
        {
            "x": 1,
            "y": 9,
            "z": 1,
            "elements": [
                "minecraft:sponge@0"
            ]
        },
        {
            "x": -1,
            "y": 12,
            "z": 4,
            "elements": [
                "nuclearcraft:machine_frame@0"
            ]
        },
        {
            "x": 1,
            "y": 9,
            "z": 4,
            "elements": [
                "nuclearcraft:machine_glass@0"
            ]
        },
        {
            "x": -1,
            "y": 5,
            "z": 3,
            "elements": [
                "nuclearcraft:machine_glass@0"
            ]
        },
        {
            "x": 1,
            "y": 3,
            "z": 0,
            "elements": [
                "nuclearcraft:machine_glass@0"
            ]
        },
        {
            "x": -2,
            "y": 12,
            "z": 2,
            "elements": [
                "nuclearcraft:machine_frame@0"
            ]
        },
        {
            "x": 2,
            "y": 11,
            "z": 1,
            "elements": [
                "nuclearcraft:machine_glass@0"
            ]
        },
        {
            "x": 0,
            "y": 2,
            "z": 2,
            "elements": [
                "nuclearcraft:ingot_block@8"
            ]
        },
        {
            "x": -2,
            "y": 5,
            "z": 0,
            "elements": [
                "nuclearcraft:fertile_isotope@0"
            ]
        },
        {
            "x": 0,
            "y": 3,
            "z": 3,
            "elements": [
                "jaopca:block.heavyalloy@0"
            ]
        },
        {
            "x": -1,
            "y": 8,
            "z": 3,
            "elements": [
                "nuclearcraft:machine_glass@0"
            ]
        },
        {
            "x": -2,
            "y": 0,
            "z": 2,
            "elements": [
                "casings_all"
            ]
        },
        {
            "x": -1,
            "y": 3,
            "z": 2,
            "elements": [
                "jaopca:block.heavyalloy@0"
            ]
        },
        {
            "x": -1,
            "y": 9,
            "z": 0,
            "elements": [
                "nuclearcraft:machine_glass@0"
            ]
        },
        {
            "x": 1,
            "y": 12,
            "z": 3,
            "elements": [
                "betternether:cincinnasite_slab_half@0"
            ]
        },
        {
            "x": -2,
            "y": 1,
            "z": 2,
            "elements": [
                "casings_all"
            ]
        },
        {
            "x": 0,
            "y": 1,
            "z": 4,
            "elements": [
                "casings_all"
            ]
        },
        {
            "x": 2,
            "y": 12,
            "z": 1,
            "elements": [
                "nuclearcraft:machine_frame@0"
            ]
        },
        {
            "x": 1,
            "y": 0,
            "z": 1,
            "elements": [
                "betternether:cincinnasite_slab_half@1"
            ]
        },
        {
            "x": -1,
            "y": 7,
            "z": 3,
            "elements": [
                "nuclearcraft:machine_glass@0"
            ]
        },
        {
            "x": -1,
            "y": 10,
            "z": 0,
            "elements": [
                "nuclearcraft:machine_glass@0"
            ]
        },
        {
            "x": -1,
            "y": 2,
            "z": 2,
            "elements": [
                "jaopca:block.heavyalloy@0"
            ]
        },
        {
            "x": 1,
            "y": 1,
            "z": 1,
            "elements": [
                "minecraft:sponge@0"
            ]
        },
        {
            "x": 0,
            "y": 2,
            "z": 4,
            "elements": [
                "casings_all"
            ]
        },
        {
            "x": 1,
            "y": 11,
            "z": 4,
            "elements": [
                "nuclearcraft:machine_glass@0"
            ]
        },
        {
            "x": 1,
            "y": 3,
            "z": 1,
            "elements": [
                "minecraft:sponge@0"
            ]
        },
        {
            "x": -2,
            "y": 12,
            "z": 3,
            "elements": [
                "nuclearcraft:machine_frame@0"
            ]
        },
        {
            "x": 1,
            "y": 2,
            "z": 1,
            "elements": [
                "minecraft:sponge@0"
            ]
        },
        {
            "x": -2,
            "y": 3,
            "z": 2,
            "elements": [
                "casings_all"
            ]
        },
        {
            "x": -1,
            "y": 9,
            "z": 3,
            "elements": [
                "minecraft:sponge@0"
            ]
        },
        {
            "x": -1,
            "y": 11,
            "z": 0,
            "elements": [
                "nuclearcraft:machine_glass@0"
            ]
        },
        {
            "x": -1,
            "y": 1,
            "z": 2,
            "elements": [
                "jaopca:block.heavyalloy@0"
            ]
        },
        {
            "x": 1,
            "y": 12,
            "z": 4,
            "elements": [
                "nuclearcraft:machine_frame@0"
            ]
        },
        {
            "x": 0,
            "y": 8,
            "z": -1,
            "elements": [
                "abyssalcraft:abyssalsandglass@0"
            ]
        },
        {
            "x": -1,
            "y": 11,
            "z": 3,
            "elements": [
                "minecraft:sponge@0"
            ]
        },
        {
            "x": 2,
            "y": 3,
            "z": 3,
            "elements": [
                "nuclearcraft:machine_glass@0"
            ]
        },
        {
            "x": -2,
            "y": 2,
            "z": 2,
            "elements": [
                "casings_all"
            ]
        },
        {
            "x": 0,
            "y": 0,
            "z": 4,
            "elements": [
                "casings_all"
            ]
        },
        {
            "x": -1,
            "y": 10,
            "z": 3,
            "elements": [
                "minecraft:sponge@0"
            ]
        },
        {
            "x": -1,
            "y": 0,
            "z": 2,
            "elements": [
                "betternether:cincinnasite_slab_half@1"
            ]
        },
        {
            "x": -1,
            "y": 12,
            "z": 0,
            "elements": [
                "nuclearcraft:machine_frame@0"
            ]
        },
        {
            "x": 1,
            "y": 5,
            "z": 1,
            "elements": [
                "nuclearcraft:machine_glass@0"
            ]
        },
        {
            "x": 0,
            "y": 6,
            "z": 4,
            "elements": [
                "nuclearcraft:fertile_isotope@0"
            ]
        },
        {
            "x": 2,
            "y": 7,
            "z": 0,
            "elements": [
                "nuclearcraft:fertile_isotope@0"
            ]
        },
        {
            "x": 1,
            "y": 3,
            "z": 2,
            "elements": [
                "jaopca:block.heavyalloy@0"
            ]
        },
        {
            "x": -2,
            "y": 5,
            "z": 2,
            "elements": [
                "nuclearcraft:machine_glass@0"
            ]
        },
        {
            "x": -1,
            "y": 12,
            "z": 3,
            "elements": [
                "betternether:cincinnasite_slab_half@0"
            ]
        },
        {
            "x": 2,
            "y": 9,
            "z": 3,
            "elements": [
                "nuclearcraft:machine_glass@0"
            ]
        },
        {
            "x": -2,
            "y": 6,
            "z": 2,
            "elements": [
                "nuclearcraft:machine_glass@0"
            ]
        },
        {
            "x": 1,
            "y": 7,
            "z": 3,
            "elements": [
                "nuclearcraft:machine_glass@0"
            ]
        },
        {
            "x": 1,
            "y": 4,
            "z": 1,
            "elements": [
                "nuclearcraft:machine_glass@0"
            ]
        },
        {
            "x": -2,
            "y": 4,
            "z": 2,
            "elements": [
                "nuclearcraft:machine_glass@0"
            ]
        },
        {
            "x": -1,
            "y": 6,
            "z": 0,
            "elements": [
                "minecraft:sponge@0"
            ]
        },
        {
            "x": -2,
            "y": 9,
            "z": 1,
            "elements": [
                "nuclearcraft:machine_glass@0"
            ]
        },
        {
            "x": 0,
            "y": 5,
            "z": 4,
            "elements": [
                "nuclearcraft:machine_glass@0"
            ]
        },
        {
            "x": 2,
            "y": 11,
            "z": 3,
            "elements": [
                "nuclearcraft:machine_glass@0"
            ]
        },
        {
            "x": 2,
            "y": 10,
            "z": 3,
            "elements": [
                "nuclearcraft:machine_glass@0"
            ]
        },
        {
            "x": -2,
            "y": 7,
            "z": 2,
            "elements": [
                "nuclearcraft:machine_glass@0"
            ]
        },
        {
            "x": 1,
            "y": 2,
            "z": 2,
            "elements": [
                "jaopca:block.heavyalloy@0"
            ]
        },
        {
            "x": 0,
            "y": 3,
            "z": 4,
            "elements": [
                "casings_upgrade"
            ]
        },
        {
            "x": -1,
            "y": 5,
            "z": 0,
            "elements": [
                "nuclearcraft:ingot_block@8"
            ]
        },
        {
            "x": -1,
            "y": 8,
            "z": 1,
            "elements": [
                "nuclearcraft:machine_glass@0"
            ]
        },
        {
            "x": 1,
            "y": 8,
            "z": 3,
            "elements": [
                "nuclearcraft:machine_glass@0"
            ]
        },
        {
            "x": 2,
            "y": 5,
            "z": 0,
            "elements": [
                "nuclearcraft:fertile_isotope@0"
            ]
        },
        {
            "x": -1,
            "y": 7,
            "z": 0,
            "elements": [
                "nuclearcraft:ingot_block@8"
            ]
        },
        {
            "x": -2,
            "y": 10,
            "z": 1,
            "elements": [
                "nuclearcraft:machine_glass@0"
            ]
        },
        {
            "x": 0,
            "y": 4,
            "z": -1,
            "elements": [
                "abyssalcraft:abyssalsandglass@0"
            ]
        },
        {
            "x": 1,
            "y": 7,
            "z": 1,
            "elements": [
                "nuclearcraft:machine_glass@0"
            ]
        },
        {
            "x": 1,
            "y": 1,
            "z": 2,
            "elements": [
                "jaopca:block.heavyalloy@0"
            ]
        },
        {
            "x": 0,
            "y": 12,
            "z": 3,
            "elements": [
                "betternether:cincinnasite_slab_half@0"
            ]
        },
        {
            "x": 1,
            "y": 9,
            "z": 3,
            "elements": [
                "minecraft:sponge@0"
            ]
        },
        {
            "x": 2,
            "y": 6,
            "z": 0,
            "elements": [
                "nuclearcraft:fertile_isotope@0"
            ]
        },
        {
            "x": 0,
            "y": 4,
            "z": 4,
            "elements": [
                "nuclearcraft:machine_glass@0"
            ]
        },
        {
            "x": -1,
            "y": 8,
            "z": 0,
            "elements": [
                "nuclearcraft:fertile_isotope@0"
            ]
        },
        {
            "x": -2,
            "y": 11,
            "z": 1,
            "elements": [
                "nuclearcraft:machine_glass@0"
            ]
        },
        {
            "x": 1,
            "y": 11,
            "z": 3,
            "elements": [
                "minecraft:sponge@0"
            ]
        },
        {
            "x": 1,
            "y": 10,
            "z": 3,
            "elements": [
                "minecraft:sponge@0"
            ]
        },
        {
            "x": 1,
            "y": 6,
            "z": 1,
            "elements": [
                "nuclearcraft:machine_glass@0"
            ]
        },
        {
            "x": 1,
            "y": 0,
            "z": 2,
            "elements": [
                "betternether:cincinnasite_slab_half@1"
            ]
        },
        {
            "x": 1,
            "y": 1,
            "z": 3,
            "elements": [
                "minecraft:sponge@0"
            ]
        },
        {
            "x": 1,
            "y": 12,
            "z": 0,
            "elements": [
                "nuclearcraft:machine_frame@0"
            ]
        },
        {
            "x": -1,
            "y": 5,
            "z": 1,
            "elements": [
                "nuclearcraft:machine_glass@0"
            ]
        },
        {
            "x": -1,
            "y": 4,
            "z": -1,
            "elements": [
                "abyssalcraft:abyssalsandglass@0"
            ]
        },
        {
            "x": 0,
            "y": 3,
            "z": 1,
            "elements": [
                "jaopca:block.heavyalloy@0"
            ]
        },
        {
            "x": 1,
            "y": 4,
            "z": 3,
            "elements": [
                "nuclearcraft:machine_glass@0"
            ]
        },
        {
            "x": 2,
            "y": 1,
            "z": 2,
            "elements": [
                "casings_all"
            ]
        },
        {
            "x": 0,
            "y": 2,
            "z": 1,
            "elements": [
                "jaopca:block.heavyalloy@0"
            ]
        },
        {
            "x": -1,
            "y": 5,
            "z": -1,
            "elements": [
                "minecraft:sponge@0"
            ]
        },
        {
            "x": 1,
            "y": 11,
            "z": 0,
            "elements": [
                "nuclearcraft:machine_glass@0"
            ]
        },
        {
            "x": -1,
            "y": 4,
            "z": 1,
            "elements": [
                "nuclearcraft:machine_glass@0"
            ]
        },
        {
            "x": -1,
            "y": 0,
            "z": 4,
            "elements": [
                "casings_all"
            ]
        },
        {
            "x": 1,
            "y": 3,
            "z": 3,
            "elements": [
                "minecraft:sponge@0"
            ]
        },
        {
            "x": 2,
            "y": 0,
            "z": 2,
            "elements": [
                "casings_all"
            ]
        },
        {
            "x": 1,
            "y": 6,
            "z": 3,
            "elements": [
                "nuclearcraft:machine_glass@0"
            ]
        },
        {
            "x": 2,
            "y": 3,
            "z": 2,
            "elements": [
                "casings_all"
            ]
        },
        {
            "x": -1,
            "y": 1,
            "z": 4,
            "elements": [
                "nuclearcraft:machine_glass@0"
            ]
        },
        {
            "x": -1,
            "y": 6,
            "z": 2,
            "elements": [
                "minecraft:sponge@0"
            ]
        },
        {
            "x": 2,
            "y": 12,
            "z": 3,
            "elements": [
                "nuclearcraft:machine_frame@0"
            ]
        },
        {
            "x": 0,
            "y": 0,
            "z": 1,
            "elements": [
                "betternether:cincinnasite_slab_half@1"
            ]
        },
        {
            "x": -1,
            "y": 7,
            "z": 1,
            "elements": [
                "nuclearcraft:machine_glass@0"
            ]
        },
        {
            "x": 1,
            "y": 5,
            "z": 3,
            "elements": [
                "nuclearcraft:machine_glass@0"
            ]
        },
        {
            "x": 2,
            "y": 2,
            "z": 2,
            "elements": [
                "casings_all"
            ]
        },
        {
            "x": 1,
            "y": 0,
            "z": 3,
            "elements": [
                "betternether:cincinnasite_slab_half@1"
            ]
        },
        {
            "x": -1,
            "y": 7,
            "z": 2,
            "elements": [
                "minecraft:sponge@0"
            ]
        },
        {
            "x": -1,
            "y": 2,
            "z": 4,
            "elements": [
                "nuclearcraft:machine_glass@0"
            ]
        },
        {
            "x": -1,
            "y": 7,
            "z": -1,
            "elements": [
                "minecraft:sponge@0"
            ]
        },
        {
            "x": -2,
            "y": 3,
            "z": 3,
            "elements": [
                "nuclearcraft:machine_glass@0"
            ]
        },
        {
            "x": -1,
            "y": 6,
            "z": 1,
            "elements": [
                "nuclearcraft:machine_glass@0"
            ]
        },
        {
            "x": 0,
            "y": 1,
            "z": 1,
            "elements": [
                "jaopca:block.heavyalloy@0"
            ]
        },
        {
            "x": -1,
            "y": 0,
            "z": 1,
            "elements": [
                "betternether:cincinnasite_slab_half@1"
            ]
        },
        {
            "x": -2,
            "y": 2,
            "z": 1,
            "elements": [
                "nuclearcraft:machine_glass@0"
            ]
        },
        {
            "x": -2,
            "y": 9,
            "z": 3,
            "elements": [
                "nuclearcraft:machine_glass@0"
            ]
        },
        {
            "x": 0,
            "y": 11,
            "z": 0,
            "elements": [
                "nuclearcraft:machine_frame@0"
            ]
        },
        {
            "x": -1,
            "y": 8,
            "z": 2,
            "elements": [
                "minecraft:sponge@0"
            ]
        },
        {
            "x": 2,
            "y": 6,
            "z": 2,
            "elements": [
                "nuclearcraft:machine_glass@0"
            ]
        },
        {
            "x": -1,
            "y": 9,
            "z": 2,
            "elements": [
                "jaopca:block.heavyalloy@0"
            ]
        },
        {
            "x": 2,
            "y": 4,
            "z": 2,
            "elements": [
                "nuclearcraft:machine_glass@0"
            ]
        },
        {
            "x": -2,
            "y": 11,
            "z": 3,
            "elements": [
                "nuclearcraft:machine_glass@0"
            ]
        },
        {
            "x": -2,
            "y": 3,
            "z": 1,
            "elements": [
                "nuclearcraft:machine_glass@0"
            ]
        },
        {
            "x": -2,
            "y": 10,
            "z": 3,
            "elements": [
                "nuclearcraft:machine_glass@0"
            ]
        },
        {
            "x": -1,
            "y": 1,
            "z": 1,
            "elements": [
                "minecraft:sponge@0"
            ]
        },
        {
            "x": 2,
            "y": 7,
            "z": 2,
            "elements": [
                "nuclearcraft:machine_glass@0"
            ]
        },
        {
            "x": -2,
            "y": 0,
            "z": 1,
            "elements": [
                "casings_all"
            ]
        },
        {
            "x": 0,
            "y": 12,
            "z": 0,
            "elements": [
                "nuclearcraft:machine_frame@0"
            ]
        },
        {
            "x": -1,
            "y": 5,
            "z": 2,
            "elements": [
                "minecraft:sponge@0"
            ]
        },
        {
            "x": -1,
            "y": 10,
            "z": 2,
            "elements": [
                "jaopca:block.heavyalloy@0"
            ]
        },
        {
            "x": -1,
            "y": 3,
            "z": 1,
            "elements": [
                "minecraft:sponge@0"
            ]
        },
        {
            "x": -1,
            "y": 2,
            "z": 1,
            "elements": [
                "minecraft:sponge@0"
            ]
        },
        {
            "x": 0,
            "y": 9,
            "z": 0,
            "elements": [
                "nuclearcraft:machine_frame@0"
            ]
        },
        {
            "x": 1,
            "y": 2,
            "z": 3,
            "elements": [
                "minecraft:sponge@0"
            ]
        },
        {
            "x": -1,
            "y": 4,
            "z": 2,
            "elements": [
                "minecraft:sponge@0"
            ]
        },
        {
            "x": -1,
            "y": 11,
            "z": 2,
            "elements": [
                "jaopca:block.heavyalloy@0"
            ]
        },
        {
            "x": 2,
            "y": 5,
            "z": 2,
            "elements": [
                "nuclearcraft:machine_glass@0"
            ]
        },
        {
            "x": -2,
            "y": 1,
            "z": 1,
            "elements": [
                "nuclearcraft:machine_glass@0"
            ]
        },
        {
            "x": 0,
            "y": 10,
            "z": 0,
            "elements": [
                "nuclearcraft:machine_frame@0"
            ]
        },
        {
            "x": 0,
            "y": 7,
            "z": 0,
            "elements": [
                "minecraft:sponge@0"
            ]
        },
        {
            "x": 1,
            "y": 8,
            "z": 2,
            "elements": [
                "minecraft:sponge@0"
            ]
        },
        {
            "x": 2,
            "y": 10,
            "z": 2,
            "elements": [
                "nuclearcraft:machine_frame@0"
            ]
        },
        {
            "x": 2,
            "y": 11,
            "z": 2,
            "elements": [
                "nuclearcraft:machine_frame@0"
            ]
        },
        {
            "x": 1,
            "y": 6,
            "z": 0,
            "elements": [
                "minecraft:sponge@0"
            ]
        },
        {
            "x": -2,
            "y": 6,
            "z": -1,
            "elements": [
                "abyssalcraft:abyssalsandglass@0"
            ]
        },
        {
            "x": 1,
            "y": 9,
            "z": 2,
            "elements": [
                "jaopca:block.heavyalloy@0"
            ]
        },
        {
            "x": 0,
            "y": 9,
            "z": 1,
            "elements": [
                "jaopca:block.heavyalloy@0"
            ]
        },
        {
            "x": 0,
            "y": 8,
            "z": 0,
            "elements": [
                "nuclearcraft:fertile_isotope@0"
            ]
        },
        {
            "x": 0,
            "y": 0,
            "z": 3,
            "elements": [
                "betternether:cincinnasite_slab_half@1"
            ]
        },
        {
            "x": -1,
            "y": 12,
            "z": 2,
            "elements": [
                "betternether:cincinnasite_slab_half@0"
            ]
        },
        {
            "x": -2,
            "y": 7,
            "z": -1,
            "elements": [
                "abyssalcraft:abyssalsandglass@0"
            ]
        },
        {
            "x": 1,
            "y": 5,
            "z": 0,
            "elements": [
                "nuclearcraft:ingot_block@8"
            ]
        },
        {
            "x": 0,
            "y": 1,
            "z": 3,
            "elements": [
                "jaopca:block.heavyalloy@0"
            ]
        },
        {
            "x": 2,
            "y": 8,
            "z": 2,
            "elements": [
                "nuclearcraft:machine_glass@0"
            ]
        },
        {
            "x": 1,
            "y": 7,
            "z": 0,
            "elements": [
                "nuclearcraft:ingot_block@8"
            ]
        },
        {
            "x": 1,
            "y": 10,
            "z": 2,
            "elements": [
                "jaopca:block.heavyalloy@0"
            ]
        },
        {
            "x": 0,
            "y": 10,
            "z": 1,
            "elements": [
                "jaopca:block.heavyalloy@0"
            ]
        },
        {
            "x": -1,
            "y": 10,
            "z": 4,
            "elements": [
                "nuclearcraft:machine_glass@0"
            ]
        },
        {
            "x": 1,
            "y": 11,
            "z": 2,
            "elements": [
                "jaopca:block.heavyalloy@0"
            ]
        },
        {
            "x": -2,
            "y": 5,
            "z": -1,
            "elements": [
                "abyssalcraft:abyssalsandglass@0"
            ]
        },
        {
            "x": 0,
            "y": 2,
            "z": 3,
            "elements": [
                "jaopca:block.heavyalloy@0"
            ]
        },
        {
            "x": 1,
            "y": 8,
            "z": 0,
            "elements": [
                "nuclearcraft:fertile_isotope@0"
            ]
        },
        {
            "x": 0,
            "y": 11,
            "z": 1,
            "elements": [
                "jaopca:block.heavyalloy@0"
            ]
        },
        {
            "x": 2,
            "y": 9,
            "z": 2,
            "elements": [
                "nuclearcraft:machine_frame@0"
            ]
        },
        {
            "x": 0,
            "y": 12,
            "z": 2,
            "elements": [
                "betternether:cincinnasite_slab_half@0"
            ]
        },
        {
            "x": 0,
            "y": 8,
            "z": 1,
            "elements": [
                "minecraft:sponge@0"
            ]
        },
        {
            "x": -1,
            "y": 9,
            "z": 4,
            "elements": [
                "nuclearcraft:machine_glass@0"
            ]
        },
        {
            "x": 0,
            "y": 5,
            "z": 0,
            "elements": [
                "minecraft:sponge@0"
            ]
        },
        {
            "x": 1,
            "y": 4,
            "z": -1,
            "elements": [
                "abyssalcraft:abyssalsandglass@0"
            ]
        },
        {
            "x": -1,
            "y": 3,
            "z": 4,
            "elements": [
                "nuclearcraft:machine_glass@0"
            ]
        },
        {
            "x": 0,
            "y": 7,
            "z": 1,
            "elements": [
                "minecraft:sponge@0"
            ]
        },
        {
            "x": 2,
            "y": 3,
            "z": 1,
            "elements": [
                "nuclearcraft:machine_glass@0"
            ]
        },
        {
            "x": 0,
            "y": 10,
            "z": 2,
            "elements": [
                "nuclearcraft:ingot_block@8"
            ]
        },
        {
            "x": 1,
            "y": 9,
            "z": 0,
            "elements": [
                "nuclearcraft:machine_glass@0"
            ]
        },
        {
            "x": -1,
            "y": 1,
            "z": 3,
            "elements": [
                "minecraft:sponge@0"
            ]
        },
        {
            "x": 0,
            "y": 11,
            "z": 2,
            "elements": [
                "nuclearcraft:ingot_block@8"
            ]
        },
        {
            "x": 0,
            "y": 4,
            "z": 0,
            "elements": [
                "nuclearcraft:fertile_isotope@0"
            ]
        },
        {
            "x": -1,
            "y": 2,
            "z": 3,
            "elements": [
                "minecraft:sponge@0"
            ]
        },
        {
            "x": 2,
            "y": 2,
            "z": 1,
            "elements": [
                "nuclearcraft:machine_glass@0"
            ]
        },
        {
            "x": -1,
            "y": 8,
            "z": -1,
            "elements": [
                "abyssalcraft:abyssalsandglass@0"
            ]
        },
        {
            "x": 0,
            "y": 3,
            "z": 0,
            "elements": [
                "casings_parallel"
            ]
        },
        {
            "x": 1,
            "y": 0,
            "z": 4,
            "elements": [
                "casings_all"
            ]
        },
        {
            "x": 1,
            "y": 5,
            "z": 2,
            "elements": [
                "minecraft:sponge@0"
            ]
        },
        {
            "x": -2,
            "y": 0,
            "z": 3,
            "elements": [
                "casings_all"
            ]
        },
        {
            "x": 0,
            "y": 6,
            "z": 1,
            "elements": [
                "nuclearcraft:fertile_isotope@0"
            ]
        },
        {
            "x": 1,
            "y": 10,
            "z": 0,
            "elements": [
                "nuclearcraft:machine_glass@0"
            ]
        },
        {
            "x": 1,
            "y": 5,
            "z": -1,
            "elements": [
                "minecraft:sponge@0"
            ]
        },
        {
            "x": 0,
            "y": 5,
            "z": 1,
            "elements": [
                "minecraft:sponge@0"
            ]
        },
        {
            "x": 0,
            "y": 2,
            "z": 0,
            "elements": [
                "casings_all"
            ]
        },
        {
            "x": -2,
            "y": 1,
            "z": 3,
            "elements": [
                "nuclearcraft:machine_glass@0"
            ]
        },
        {
            "x": -1,
            "y": 6,
            "z": 4,
            "elements": [
                "nuclearcraft:machine_glass@0"
            ]
        },
        {
            "x": 1,
            "y": 6,
            "z": 2,
            "elements": [
                "minecraft:sponge@0"
            ]
        },
        {
            "x": 2,
            "y": 0,
            "z": 1,
            "elements": [
                "casings_all"
            ]
        },
        {
            "x": 0,
            "y": 8,
            "z": 2,
            "elements": [
                "nuclearcraft:ingot_block@8"
            ]
        },
        {
            "x": 1,
            "y": 1,
            "z": 4,
            "elements": [
                "nuclearcraft:machine_glass@0"
            ]
        },
        {
            "x": -2,
            "y": 2,
            "z": 3,
            "elements": [
                "nuclearcraft:machine_glass@0"
            ]
        },
        {
            "x": 0,
            "y": 9,
            "z": 2,
            "elements": [
                "nuclearcraft:ingot_block@8"
            ]
        },
        {
            "x": 0,
            "y": 1,
            "z": 0,
            "elements": [
                "casings_all"
            ]
        },
        {
            "x": 1,
            "y": 2,
            "z": 4,
            "elements": [
                "nuclearcraft:machine_glass@0"
            ]
        },
        {
            "x": -1,
            "y": 0,
            "z": 3,
            "elements": [
                "betternether:cincinnasite_slab_half@1"
            ]
        },
        {
            "x": 0,
            "y": 4,
            "z": 1,
            "elements": [
                "minecraft:sponge@0"
            ]
        },
        {
            "x": 1,
            "y": 7,
            "z": -1,
            "elements": [
                "minecraft:sponge@0"
            ]
        },
        {
            "x": 2,
            "y": 1,
            "z": 1,
            "elements": [
                "nuclearcraft:machine_glass@0"
            ]
        },
        {
            "x": 2,
            "y": 12,
            "z": 2,
            "elements": [
                "nuclearcraft:machine_frame@0"
            ]
        },
        {
            "x": 1,
            "y": 7,
            "z": 2,
            "elements": [
                "minecraft:sponge@0"
            ]
        },
        {
            "x": 1,
            "y": 3,
            "z": 4,
            "elements": [
                "nuclearcraft:machine_glass@0"
            ]
        }
    ]}